Workbook

Sheet 資料儲存
A1: 時段 | B1: 臨近路段 | C1: 開始時刻 | D1: 停車在臨近車道上的車輛總數(0秒) | E1: 停車在臨近車道上的車輛總數(15秒) | F1: 停車在臨近車道上的車輛總數(30秒) | G1: 停車在臨近車道上的車輛總數(45秒) | H1: 臨近車道上的流量(總數) | I1: 臨近車道上的流量(未受阻) | J1: 臨近車道上的流量(受阻)
A2: 平日晨峰(0630-0830) | B2: A | C2: 0.27083333 | D2: 0 | E2: 0 | F2: 0 | G2: 0 | H2: 0 | I2: 0 | J2: 0
A3: 平日晨峰(0630-0830) | B3: A | C3: 0.27152778 | D3: 0 | E3: 0 | F3: 0 | G3: 0 | H3: 0 | I3: 0 | J3: 0
A4: 平日晨峰(0630-0830) | B4: A | C4: 0.27222222 | D4: 0 | E4: 0 | F4: 0 | G4: 0 | H4: 0 | I4: 0 | J4: 0
A5: 平日晨峰(0630-0830) | B5: A | C5: 0.27291667 | D5: 0 | E5: 0 | F5: 0 | G5: 0 | H5: 0 | I5: 0 | J5: 0
A6: 平日晨峰(0630-0830) | B6: A | C6: 0.27361111 | D6: 0 | E6: 0 | F6: 0 | G6: 0 | H6: 0 | I6: 0 | J6: 0
A7: 平日晨峰(0630-0830) | B7: A | C7: 0.27430556 | D7: 0 | E7: 0 | F7: 0 | G7: 0 | H7: 0 | I7: 0 | J7: 0
A8: 平日晨峰(0630-0830) | B8: A | C8: 0.275 | D8: 0 | E8: 0 | F8: 0 | G8: 0 | H8: 0 | I8: 0 | J8: 0
A9: 平日晨峰(0630-0830) | B9: A | C9: 0.27569444 | D9: 0 | E9: 0 | F9: 0 | G9: 0 | H9: 0 | I9: 0 | J9: 0
A10: 平日晨峰(0630-0830) | B10: A | C10: 0.27638889 | D10: 0 | E10: 0 | F10: 0 | G10: 0 | H10: 0 | I10: 0 | J10: 0
A11: 平日晨峰(0630-0830) | B11: A | C11: 0.27708333 | D11: 0 | E11: 0 | F11: 0 | G11: 0 | H11: 0 | I11: 0 | J11: 0
A12: 平日晨峰(0630-0830) | B12: A | C12: 0.27777778 | D12: 0 | E12: 0 | F12: 0 | G12: 0 | H12: 0 | I12: 0 | J12: 0
A13: 平日晨峰(0630-0830) | B13: A | C13: 0.27847222 | D13: 0 | E13: 0 | F13: 0 | G13: 0 | H13: 0 | I13: 0 | J13: 0
... A7561: 假日(16-20) | B7561: F | C7561: 0.83263889 | D7561: 0 | E7561: 0 | F7561: 0 | G7561: 0 | H7561: 0 | I7561: 0 | J7561: 0

Sheet 基本資料
A4: 業主名稱：
A5: 專案編號：
R6: 往北
A7: TC編號： | C7: (例：TC240) | R7: 往東
A8: 路口名稱： | R8: 往南
A9: 行政區域： | C9: (例：東區) | R9: 往西南
R10: 往西北
B11: 平日晨峰(0630-0830) | C11: 平日晨峰(07-09) | D11: 平日中午(11-13) | E11: 平日中午(12-14) | F11: 平日昏峰(17-19) | G11: 假日(11-12) | H11: 假日(1430-1530) | I11: 假日(1730-1830) | J11: 假日(16-18) | K11: 假日(17-19) | L11: 假日(16-20) | R11: 往東北
A12: 日期： | B12: YYYY/MM/DD | C12: YYYY/MM/DD | D12: YYYY/MM/DD | E12: YYYY/MM/DD | F12: YYYY/MM/DD | G12: YYYY/MM/DD | H12: YYYY/MM/DD | I12: YYYY/MM/DD | J12: YYYY/MM/DD | K12: YYYY/MM/DD | L12: YYYY/MM/DD | R12: 往東南
A13: 天候：
R14: 往西
A16: 路口類型： | B16: 六叉路口
A18: 方 向： | B18: A | C18: B | D18: C | E18: D | F18: E | G18: F
A19: 路段名：
A20: 行車方向：
A21: 車道數： | B21: - | C21: - | D21: - | E21: - | F21: - | G21: -
A25: 簡圖：
C26: =F20 -> 0 | E26: =G20 -> 0
C27: E | E27: F
A30: =E20 -> 0 | B30: D | F30: A | G30: =B20 -> 0
C33: C | E33: B
C34: =D20 -> 0 | E34: =C20 -> 0

Sheet 平日晨峰(0630-0830)
A1: =基本資料!B11 -> 平日晨峰(0630-0830) | J1: =基本資料!B11 -> 平日晨峰(0630-0830) | S1: =基本資料!B11 -> 平日晨峰(0630-0830) | AB1: =基本資料!B11 -> 平日晨峰(0630-0830) | AK1: =基本資料!B11 -> 平日晨峰(0630-0830) | AT1: =基本資料!B11 -> 平日晨峰(0630-0830)
A2: =CONCATENATE(基本資料!B18,"方向：",基本資料!B19,基本資料!B20) -> A方向： | J2: =CONCATENATE(基本資料!C18,"方向：",基本資料!C19,基本資料!C20) -> B方向： | S2: =CONCATENATE(基本資料!D18,"方向：",基本資料!D19,基本資料!D20) -> C方向： | AB2: =CONCATENATE(基本資料!E18,"方向：",基本資料!E19,基本資料!E20) -> D方向： | AK2: =CONCATENATE(基本資料!F18,"方向：",基本資料!F19,基本資料!F20) -> E方向： | AT2: =CONCATENATE(基本資料!G18,"方向：",基本資料!G19,基本資料!G20) -> F方向：
A3: 06:30~06:45 | J3: 06:30~06:45 | S3: 06:30~06:45 | AB3: 06:30~06:45 | AK3: 06:30~06:45 | AT3: 06:30~06:45
A4: 開始時刻 | B4: 停車在臨近車道上的車輛總數 | F4: 臨近車道上的流量 | J4: 開始時刻 | K4: 停車在臨近車道上的車輛總數 | O4: 臨近車道上的流量 | S4: 開始時刻 | T4: 停車在臨近車道上的車輛總數 | X4: 臨近車道上的流量 | AB4: 開始時刻 | AC4: 停車在臨近車道上的車輛總數 | AG4: 臨近車道上的流量 | AK4: 開始時刻 | AL4: 停車在臨近車道上的車輛總數 | AP4: 臨近車道上的流量 | AT4: 開始時刻 | AU4: 停車在臨近車道上的車輛總數 | AY4: 臨近車道上的流量
A5: 0.27083333 | B5: 0秒 | C5: 15秒 | D5: 30秒 | E5: 45秒 | F5: 總數 | G5: 未受阻 | H5: 受阻 | J5: 0.27083333 | K5: 0秒 | L5: 15秒 | M5: 30秒 | N5: 45秒 | O5: 總數 | P5: 未受阻 | Q5: 受阻 | S5: 0.27083333 | T5: 0秒 | U5: 15秒 | V5: 30秒 | W5: 45秒 | X5: 總數 | Y5: 未受阻 | Z5: 受阻 | AB5: 0.27083333 | AC5: 0秒 | AD5: 15秒 | AE5: 30秒 | AF5: 45秒 | AG5: 總數 | AH5: 未受阻 | AI5: 受阻 | AK5: 0.27083333 | AL5: 0秒 | AM5: 15秒 | AN5: 30秒 | AO5: 45秒 | AP5: 總數 | AQ5: 未受阻 | AR5: 受阻 | AT5: 0.27083333 | AU5: 0秒 | AV5: 15秒 | AW5: 30秒 | AX5: 45秒 | AY5: 總數 | AZ5: 未受阻 | BA5: 受阻
A6: 31 | B6: =資料儲存!D2 -> 0 | C6: =資料儲存!E2 -> 0 | D6: =資料儲存!F2 -> 0 | E6: =資料儲存!G2 -> 0 | F6: =資料儲存!H2 -> 0 | G6: =資料儲存!I2 -> 0 | H6: =資料儲存!J2 -> 0 | J6: 31 | K6: =資料儲存!D122 -> 0 | L6: =資料儲存!E122 -> 0 | M6: =資料儲存!F122 -> 0 | N6: =資料儲存!G122 -> 0 | O6: =資料儲存!H122 -> 0 | P6: =資料儲存!I122 -> 0 | Q6: =資料儲存!J122 -> 0 | S6: 31 | T6: =資料儲存!D242 -> 0 | U6: =資料儲存!E242 -> 0 | V6: =資料儲存!F242 -> 0 | W6: =資料儲存!G242 -> 0 | X6: =資料儲存!H242 -> 0 | Y6: =資料儲存!I242 -> 0 | Z6: =資料儲存!J242 -> 0 | AB6: 31 | AC6: =資料儲存!D362 -> 0 | AD6: =資料儲存!E362 -> 0 | AE6: =資料儲存!F362 -> 0 | AF6: =資料儲存!G362 -> 0 | AG6: =資料儲存!H362 -> 0 | AH6: =資料儲存!I362 -> 0 | AI6: =資料儲存!J362 -> 0 | AK6: 31 | AL6: =資料儲存!D482 -> 0 | AM6: =資料儲存!E482 -> 0 | AN6: =資料儲存!F482 -> 0 | AO6: =資料儲存!G482 -> 0 | AP6: =資料儲存!H482 -> 0 | AQ6: =資料儲存!I482 -> 0 | AR6: =資料儲存!J482 -> 0 | AT6: 31 | AU6: =資料儲存!D602 -> 0 | AV6: =資料儲存!E602 -> 0 | AW6: =資料儲存!F602 -> 0 | AX6: =資料儲存!G602 -> 0 | AY6: =資料儲存!H602 -> 0 | AZ6: =資料儲存!I602 -> 0 | BA6: =資料儲存!J602 -> 0
A7: 32 | B7: =資料儲存!D3 -> 0 | C7: =資料儲存!E3 -> 0 | D7: =資料儲存!F3 -> 0 | E7: =資料儲存!G3 -> 0 | F7: =資料儲存!H3 -> 0 | G7: =資料儲存!I3 -> 0 | H7: =資料儲存!J3 -> 0 | J7: 32 | K7: =資料儲存!D123 -> 0 | L7: =資料儲存!E123 -> 0 | M7: =資料儲存!F123 -> 0 | N7: =資料儲存!G123 -> 0 | O7: =資料儲存!H123 -> 0 | P7: =資料儲存!I123 -> 0 | Q7: =資料儲存!J123 -> 0 | S7: 32 | T7: =資料儲存!D243 -> 0 | U7: =資料儲存!E243 -> 0 | V7: =資料儲存!F243 -> 0 | W7: =資料儲存!G243 -> 0 | X7: =資料儲存!H243 -> 0 | Y7: =資料儲存!I243 -> 0 | Z7: =資料儲存!J243 -> 0 | AB7: 32 | AC7: =資料儲存!D363 -> 0 | AD7: =資料儲存!E363 -> 0 | AE7: =資料儲存!F363 -> 0 | AF7: =資料儲存!G363 -> 0 | AG7: =資料儲存!H363 -> 0 | AH7: =資料儲存!I363 -> 0 | AI7: =資料儲存!J363 -> 0 | AK7: 32 | AL7: =資料儲存!D483 -> 0 | AM7: =資料儲存!E483 -> 0 | AN7: =資料儲存!F483 -> 0 | AO7: =資料儲存!G483 -> 0 | AP7: =資料儲存!H483 -> 0 | AQ7: =資料儲存!I483 -> 0 | AR7: =資料儲存!J483 -> 0 | AT7: 32 | AU7: =資料儲存!D603 -> 0 | AV7: =資料儲存!E603 -> 0 | AW7: =資料儲存!F603 -> 0 | AX7: =資料儲存!G603 -> 0 | AY7: =資料儲存!H603 -> 0 | AZ7: =資料儲存!I603 -> 0 | BA7: =資料儲存!J603 -> 0
A8: 33 | B8: =資料儲存!D4 -> 0 | C8: =資料儲存!E4 -> 0 | D8: =資料儲存!F4 -> 0 | E8: =資料儲存!G4 -> 0 | F8: =資料儲存!H4 -> 0 | G8: =資料儲存!I4 -> 0 | H8: =資料儲存!J4 -> 0 | J8: 33 | K8: =資料儲存!D124 -> 0 | L8: =資料儲存!E124 -> 0 | M8: =資料儲存!F124 -> 0 | N8: =資料儲存!G124 -> 0 | O8: =資料儲存!H124 -> 0 | P8: =資料儲存!I124 -> 0 | Q8: =資料儲存!J124 -> 0 | S8: 33 | T8: =資料儲存!D244 -> 0 | U8: =資料儲存!E244 -> 0 | V8: =資料儲存!F244 -> 0 | W8: =資料儲存!G244 -> 0 | X8: =資料儲存!H244 -> 0 | Y8: =資料儲存!I244 -> 0 | Z8: =資料儲存!J244 -> 0 | AB8: 33 | AC8: =資料儲存!D364 -> 0 | AD8: =資料儲存!E364 -> 0 | AE8: =資料儲存!F364 -> 0 | AF8: =資料儲存!G364 -> 0 | AG8: =資料儲存!H364 -> 0 | AH8: =資料儲存!I364 -> 0 | AI8: =資料儲存!J364 -> 0 | AK8: 33 | AL8: =資料儲存!D484 -> 0 | AM8: =資料儲存!E484 -> 0 | AN8: =資料儲存!F484 -> 0 | AO8: =資料儲存!G484 -> 0 | AP8: =資料儲存!H484 -> 0 | AQ8: =資料儲存!I484 -> 0 | AR8: =資料儲存!J484 -> 0 | AT8: 33 | AU8: =資料儲存!D604 -> 0 | AV8: =資料儲存!E604 -> 0 | AW8: =資料儲存!F604 -> 0 | AX8: =資料儲存!G604 -> 0 | AY8: =資料儲存!H604 -> 0 | AZ8: =資料儲存!I604 -> 0 | BA8: =資料儲存!J604 -> 0
A9: 34 | B9: =資料儲存!D5 -> 0 | C9: =資料儲存!E5 -> 0 | D9: =資料儲存!F5 -> 0 | E9: =資料儲存!G5 -> 0 | F9: =資料儲存!H5 -> 0 | G9: =資料儲存!I5 -> 0 | H9: =資料儲存!J5 -> 0 | J9: 34 | K9: =資料儲存!D125 -> 0 | L9: =資料儲存!E125 -> 0 | M9: =資料儲存!F125 -> 0 | N9: =資料儲存!G125 -> 0 | O9: =資料儲存!H125 -> 0 | P9: =資料儲存!I125 -> 0 | Q9: =資料儲存!J125 -> 0 | S9: 34 | T9: =資料儲存!D245 -> 0 | U9: =資料儲存!E245 -> 0 | V9: =資料儲存!F245 -> 0 | W9: =資料儲存!G245 -> 0 | X9: =資料儲存!H245 -> 0 | Y9: =資料儲存!I245 -> 0 | Z9: =資料儲存!J245 -> 0 | AB9: 34 | AC9: =資料儲存!D365 -> 0 | AD9: =資料儲存!E365 -> 0 | AE9: =資料儲存!F365 -> 0 | AF9: =資料儲存!G365 -> 0 | AG9: =資料儲存!H365 -> 0 | AH9: =資料儲存!I365 -> 0 | AI9: =資料儲存!J365 -> 0 | AK9: 34 | AL9: =資料儲存!D485 -> 0 | AM9: =資料儲存!E485 -> 0 | AN9: =資料儲存!F485 -> 0 | AO9: =資料儲存!G485 -> 0 | AP9: =資料儲存!H485 -> 0 | AQ9: =資料儲存!I485 -> 0 | AR9: =資料儲存!J485 -> 0 | AT9: 34 | AU9: =資料儲存!D605 -> 0 | AV9: =資料儲存!E605 -> 0 | AW9: =資料儲存!F605 -> 0 | AX9: =資料儲存!G605 -> 0 | AY9: =資料儲存!H605 -> 0 | AZ9: =資料儲存!I605 -> 0 | BA9: =資料儲存!J605 -> 0
A10: 35 | B10: =資料儲存!D6 -> 0 | C10: =資料儲存!E6 -> 0 | D10: =資料儲存!F6 -> 0 | E10: =資料儲存!G6 -> 0 | F10: =資料儲存!H6 -> 0 | G10: =資料儲存!I6 -> 0 | H10: =資料儲存!J6 -> 0 | J10: 35 | K10: =資料儲存!D126 -> 0 | L10: =資料儲存!E126 -> 0 | M10: =資料儲存!F126 -> 0 | N10: =資料儲存!G126 -> 0 | O10: =資料儲存!H126 -> 0 | P10: =資料儲存!I126 -> 0 | Q10: =資料儲存!J126 -> 0 | S10: 35 | T10: =資料儲存!D246 -> 0 | U10: =資料儲存!E246 -> 0 | V10: =資料儲存!F246 -> 0 | W10: =資料儲存!G246 -> 0 | X10: =資料儲存!H246 -> 0 | Y10: =資料儲存!I246 -> 0 | Z10: =資料儲存!J246 -> 0 | AB10: 35 | AC10: =資料儲存!D366 -> 0 | AD10: =資料儲存!E366 -> 0 | AE10: =資料儲存!F366 -> 0 | AF10: =資料儲存!G366 -> 0 | AG10: =資料儲存!H366 -> 0 | AH10: =資料儲存!I366 -> 0 | AI10: =資料儲存!J366 -> 0 | AK10: 35 | AL10: =資料儲存!D486 -> 0 | AM10: =資料儲存!E486 -> 0 | AN10: =資料儲存!F486 -> 0 | AO10: =資料儲存!G486 -> 0 | AP10: =資料儲存!H486 -> 0 | AQ10: =資料儲存!I486 -> 0 | AR10: =資料儲存!J486 -> 0 | AT10: 35 | AU10: =資料儲存!D606 -> 0 | AV10: =資料儲存!E606 -> 0 | AW10: =資料儲存!F606 -> 0 | AX10: =資料儲存!G606 -> 0 | AY10: =資料儲存!H606 -> 0 | AZ10: =資料儲存!I606 -> 0 | BA10: =資料儲存!J606 -> 0
A11: 36 | B11: =資料儲存!D7 -> 0 | C11: =資料儲存!E7 -> 0 | D11: =資料儲存!F7 -> 0 | E11: =資料儲存!G7 -> 0 | F11: =資料儲存!H7 -> 0 | G11: =資料儲存!I7 -> 0 | H11: =資料儲存!J7 -> 0 | J11: 36 | K11: =資料儲存!D127 -> 0 | L11: =資料儲存!E127 -> 0 | M11: =資料儲存!F127 -> 0 | N11: =資料儲存!G127 -> 0 | O11: =資料儲存!H127 -> 0 | P11: =資料儲存!I127 -> 0 | Q11: =資料儲存!J127 -> 0 | S11: 36 | T11: =資料儲存!D247 -> 0 | U11: =資料儲存!E247 -> 0 | V11: =資料儲存!F247 -> 0 | W11: =資料儲存!G247 -> 0 | X11: =資料儲存!H247 -> 0 | Y11: =資料儲存!I247 -> 0 | Z11: =資料儲存!J247 -> 0 | AB11: 36 | AC11: =資料儲存!D367 -> 0 | AD11: =資料儲存!E367 -> 0 | AE11: =資料儲存!F367 -> 0 | AF11: =資料儲存!G367 -> 0 | AG11: =資料儲存!H367 -> 0 | AH11: =資料儲存!I367 -> 0 | AI11: =資料儲存!J367 -> 0 | AK11: 36 | AL11: =資料儲存!D487 -> 0 | AM11: =資料儲存!E487 -> 0 | AN11: =資料儲存!F487 -> 0 | AO11: =資料儲存!G487 -> 0 | AP11: =資料儲存!H487 -> 0 | AQ11: =資料儲存!I487 -> 0 | AR11: =資料儲存!J487 -> 0 | AT11: 36 | AU11: =資料儲存!D607 -> 0 | AV11: =資料儲存!E607 -> 0 | AW11: =資料儲存!F607 -> 0 | AX11: =資料儲存!G607 -> 0 | AY11: =資料儲存!H607 -> 0 | AZ11: =資料儲存!I607 -> 0 | BA11: =資料儲存!J607 -> 0
A12: 37 | B12: =資料儲存!D8 -> 0 | C12: =資料儲存!E8 -> 0 | D12: =資料儲存!F8 -> 0 | E12: =資料儲存!G8 -> 0 | F12: =資料儲存!H8 -> 0 | G12: =資料儲存!I8 -> 0 | H12: =資料儲存!J8 -> 0 | J12: 37 | K12: =資料儲存!D128 -> 0 | L12: =資料儲存!E128 -> 0 | M12: =資料儲存!F128 -> 0 | N12: =資料儲存!G128 -> 0 | O12: =資料儲存!H128 -> 0 | P12: =資料儲存!I128 -> 0 | Q12: =資料儲存!J128 -> 0 | S12: 37 | T12: =資料儲存!D248 -> 0 | U12: =資料儲存!E248 -> 0 | V12: =資料儲存!F248 -> 0 | W12: =資料儲存!G248 -> 0 | X12: =資料儲存!H248 -> 0 | Y12: =資料儲存!I248 -> 0 | Z12: =資料儲存!J248 -> 0 | AB12: 37 | AC12: =資料儲存!D368 -> 0 | AD12: =資料儲存!E368 -> 0 | AE12: =資料儲存!F368 -> 0 | AF12: =資料儲存!G368 -> 0 | AG12: =資料儲存!H368 -> 0 | AH12: =資料儲存!I368 -> 0 | AI12: =資料儲存!J368 -> 0 | AK12: 37 | AL12: =資料儲存!D488 -> 0 | AM12: =資料儲存!E488 -> 0 | AN12: =資料儲存!F488 -> 0 | AO12: =資料儲存!G488 -> 0 | AP12: =資料儲存!H488 -> 0 | AQ12: =資料儲存!I488 -> 0 | AR12: =資料儲存!J488 -> 0 | AT12: 37 | AU12: =資料儲存!D608 -> 0 | AV12: =資料儲存!E608 -> 0 | AW12: =資料儲存!F608 -> 0 | AX12: =資料儲存!G608 -> 0 | AY12: =資料儲存!H608 -> 0 | AZ12: =資料儲存!I608 -> 0 | BA12: =資料儲存!J608 -> 0
A13: 38 | B13: =資料儲存!D9 -> 0 | C13: =資料儲存!E9 -> 0 | D13: =資料儲存!F9 -> 0 | E13: =資料儲存!G9 -> 0 | F13: =資料儲存!H9 -> 0 | G13: =資料儲存!I9 -> 0 | H13: =資料儲存!J9 -> 0 | J13: 38 | K13: =資料儲存!D129 -> 0 | L13: =資料儲存!E129 -> 0 | M13: =資料儲存!F129 -> 0 | N13: =資料儲存!G129 -> 0 | O13: =資料儲存!H129 -> 0 | P13: =資料儲存!I129 -> 0 | Q13: =資料儲存!J129 -> 0 | S13: 38 | T13: =資料儲存!D249 -> 0 | U13: =資料儲存!E249 -> 0 | V13: =資料儲存!F249 -> 0 | W13: =資料儲存!G249 -> 0 | X13: =資料儲存!H249 -> 0 | Y13: =資料儲存!I249 -> 0 | Z13: =資料儲存!J249 -> 0 | AB13: 38 | AC13: =資料儲存!D369 -> 0 | AD13: =資料儲存!E369 -> 0 | AE13: =資料儲存!F369 -> 0 | AF13: =資料儲存!G369 -> 0 | AG13: =資料儲存!H369 -> 0 | AH13: =資料儲存!I369 -> 0 | AI13: =資料儲存!J369 -> 0 | AK13: 38 | AL13: =資料儲存!D489 -> 0 | AM13: =資料儲存!E489 -> 0 | AN13: =資料儲存!F489 -> 0 | AO13: =資料儲存!G489 -> 0 | AP13: =資料儲存!H489 -> 0 | AQ13: =資料儲存!I489 -> 0 | AR13: =資料儲存!J489 -> 0 | AT13: 38 | AU13: =資料儲存!D609 -> 0 | AV13: =資料儲存!E609 -> 0 | AW13: =資料儲存!F609 -> 0 | AX13: =資料儲存!G609 -> 0 | AY13: =資料儲存!H609 -> 0 | AZ13: =資料儲存!I609 -> 0 | BA13: =資料儲存!J609 -> 0
A14: 39 | B14: =資料儲存!D10 -> 0 | C14: =資料儲存!E10 -> 0 | D14: =資料儲存!F10 -> 0 | E14: =資料儲存!G10 -> 0 | F14: =資料儲存!H10 -> 0 | G14: =資料儲存!I10 -> 0 | H14: =資料儲存!J10 -> 0 | J14: 39 | K14: =資料儲存!D130 -> 0 | L14: =資料儲存!E130 -> 0 | M14: =資料儲存!F130 -> 0 | N14: =資料儲存!G130 -> 0 | O14: =資料儲存!H130 -> 0 | P14: =資料儲存!I130 -> 0 | Q14: =資料儲存!J130 -> 0 | S14: 39 | T14: =資料儲存!D250 -> 0 | U14: =資料儲存!E250 -> 0 | V14: =資料儲存!F250 -> 0 | W14: =資料儲存!G250 -> 0 | X14: =資料儲存!H250 -> 0 | Y14: =資料儲存!I250 -> 0 | Z14: =資料儲存!J250 -> 0 | AB14: 39 | AC14: =資料儲存!D370 -> 0 | AD14: =資料儲存!E370 -> 0 | AE14: =資料儲存!F370 -> 0 | AF14: =資料儲存!G370 -> 0 | AG14: =資料儲存!H370 -> 0 | AH14: =資料儲存!I370 -> 0 | AI14: =資料儲存!J370 -> 0 | AK14: 39 | AL14: =資料儲存!D490 -> 0 | AM14: =資料儲存!E490 -> 0 | AN14: =資料儲存!F490 -> 0 | AO14: =資料儲存!G490 -> 0 | AP14: =資料儲存!H490 -> 0 | AQ14: =資料儲存!I490 -> 0 | AR14: =資料儲存!J490 -> 0 | AT14: 39 | AU14: =資料儲存!D610 -> 0 | AV14: =資料儲存!E610 -> 0 | AW14: =資料儲存!F610 -> 0 | AX14: =資料儲存!G610 -> 0 | AY14: =資料儲存!H610 -> 0 | AZ14: =資料儲存!I610 -> 0 | BA14: =資料儲存!J610 -> 0
A15: 40 | B15: =資料儲存!D11 -> 0 | C15: =資料儲存!E11 -> 0 | D15: =資料儲存!F11 -> 0 | E15: =資料儲存!G11 -> 0 | F15: =資料儲存!H11 -> 0 | G15: =資料儲存!I11 -> 0 | H15: =資料儲存!J11 -> 0 | J15: 40 | K15: =資料儲存!D131 -> 0 | L15: =資料儲存!E131 -> 0 | M15: =資料儲存!F131 -> 0 | N15: =資料儲存!G131 -> 0 | O15: =資料儲存!H131 -> 0 | P15: =資料儲存!I131 -> 0 | Q15: =資料儲存!J131 -> 0 | S15: 40 | T15: =資料儲存!D251 -> 0 | U15: =資料儲存!E251 -> 0 | V15: =資料儲存!F251 -> 0 | W15: =資料儲存!G251 -> 0 | X15: =資料儲存!H251 -> 0 | Y15: =資料儲存!I251 -> 0 | Z15: =資料儲存!J251 -> 0 | AB15: 40 | AC15: =資料儲存!D371 -> 0 | AD15: =資料儲存!E371 -> 0 | AE15: =資料儲存!F371 -> 0 | AF15: =資料儲存!G371 -> 0 | AG15: =資料儲存!H371 -> 0 | AH15: =資料儲存!I371 -> 0 | AI15: =資料儲存!J371 -> 0 | AK15: 40 | AL15: =資料儲存!D491 -> 0 | AM15: =資料儲存!E491 -> 0 | AN15: =資料儲存!F491 -> 0 | AO15: =資料儲存!G491 -> 0 | AP15: =資料儲存!H491 -> 0 | AQ15: =資料儲存!I491 -> 0 | AR15: =資料儲存!J491 -> 0 | AT15: 40 | AU15: =資料儲存!D611 -> 0 | AV15: =資料儲存!E611 -> 0 | AW15: =資料儲存!F611 -> 0 | AX15: =資料儲存!G611 -> 0 | AY15: =資料儲存!H611 -> 0 | AZ15: =資料儲存!I611 -> 0 | BA15: =資料儲存!J611 -> 0
A16: 41 | B16: =資料儲存!D12 -> 0 | C16: =資料儲存!E12 -> 0 | D16: =資料儲存!F12 -> 0 | E16: =資料儲存!G12 -> 0 | F16: =資料儲存!H12 -> 0 | G16: =資料儲存!I12 -> 0 | H16: =資料儲存!J12 -> 0 | J16: 41 | K16: =資料儲存!D132 -> 0 | L16: =資料儲存!E132 -> 0 | M16: =資料儲存!F132 -> 0 | N16: =資料儲存!G132 -> 0 | O16: =資料儲存!H132 -> 0 | P16: =資料儲存!I132 -> 0 | Q16: =資料儲存!J132 -> 0 | S16: 41 | T16: =資料儲存!D252 -> 0 | U16: =資料儲存!E252 -> 0 | V16: =資料儲存!F252 -> 0 | W16: =資料儲存!G252 -> 0 | X16: =資料儲存!H252 -> 0 | Y16: =資料儲存!I252 -> 0 | Z16: =資料儲存!J252 -> 0 | AB16: 41 | AC16: =資料儲存!D372 -> 0 | AD16: =資料儲存!E372 -> 0 | AE16: =資料儲存!F372 -> 0 | AF16: =資料儲存!G372 -> 0 | AG16: =資料儲存!H372 -> 0 | AH16: =資料儲存!I372 -> 0 | AI16: =資料儲存!J372 -> 0 | AK16: 41 | AL16: =資料儲存!D492 -> 0 | AM16: =資料儲存!E492 -> 0 | AN16: =資料儲存!F492 -> 0 | AO16: =資料儲存!G492 -> 0 | AP16: =資料儲存!H492 -> 0 | AQ16: =資料儲存!I492 -> 0 | AR16: =資料儲存!J492 -> 0 | AT16: 41 | AU16: =資料儲存!D612 -> 0 | AV16: =資料儲存!E612 -> 0 | AW16: =資料儲存!F612 -> 0 | AX16: =資料儲存!G612 -> 0 | AY16: =資料儲存!H612 -> 0 | AZ16: =資料儲存!I612 -> 0 | BA16: =資料儲存!J612 -> 0
A17: 42 | B17: =資料儲存!D13 -> 0 | C17: =資料儲存!E13 -> 0 | D17: =資料儲存!F13 -> 0 | E17: =資料儲存!G13 -> 0 | F17: =資料儲存!H13 -> 0 | G17: =資料儲存!I13 -> 0 | H17: =資料儲存!J13 -> 0 | J17: 42 | K17: =資料儲存!D133 -> 0 | L17: =資料儲存!E133 -> 0 | M17: =資料儲存!F133 -> 0 | N17: =資料儲存!G133 -> 0 | O17: =資料儲存!H133 -> 0 | P17: =資料儲存!I133 -> 0 | Q17: =資料儲存!J133 -> 0 | S17: 42 | T17: =資料儲存!D253 -> 0 | U17: =資料儲存!E253 -> 0 | V17: =資料儲存!F253 -> 0 | W17: =資料儲存!G253 -> 0 | X17: =資料儲存!H253 -> 0 | Y17: =資料儲存!I253 -> 0 | Z17: =資料儲存!J253 -> 0 | AB17: 42 | AC17: =資料儲存!D373 -> 0 | AD17: =資料儲存!E373 -> 0 | AE17: =資料儲存!F373 -> 0 | AF17: =資料儲存!G373 -> 0 | AG17: =資料儲存!H373 -> 0 | AH17: =資料儲存!I373 -> 0 | AI17: =資料儲存!J373 -> 0 | AK17: 42 | AL17: =資料儲存!D493 -> 0 | AM17: =資料儲存!E493 -> 0 | AN17: =資料儲存!F493 -> 0 | AO17: =資料儲存!G493 -> 0 | AP17: =資料儲存!H493 -> 0 | AQ17: =資料儲存!I493 -> 0 | AR17: =資料儲存!J493 -> 0 | AT17: 42 | AU17: =資料儲存!D613 -> 0 | AV17: =資料儲存!E613 -> 0 | AW17: =資料儲存!F613 -> 0 | AX17: =資料儲存!G613 -> 0 | AY17: =資料儲存!H613 -> 0 | AZ17: =資料儲存!I613 -> 0 | BA17: =資料儲存!J613 -> 0
... A20: 45 | B20: =資料儲存!D16 -> 0 | C20: =資料儲存!E16 -> 0 | D20: =資料儲存!F16 -> 0 | E20: =資料儲存!G16 -> 0 | F20: =資料儲存!H16 -> 0 | G20: =資料儲存!I16 -> 0 | H20: =資料儲存!J16 -> 0 | J20: 45 | K20: =資料儲存!D136 -> 0 | L20: =資料儲存!E136 -> 0 | M20: =資料儲存!F136 -> 0 | N20: =資料儲存!G136 -> 0 | O20: =資料儲存!H136 -> 0 | P20: =資料儲存!I136 -> 0 | Q20: =資料儲存!J136 -> 0 | S20: 45 | T20: =資料儲存!D256 -> 0 | U20: =資料儲存!E256 -> 0 | V20: =資料儲存!F256 -> 0 | W20: =資料儲存!G256 -> 0 | X20: =資料儲存!H256 -> 0 | Y20: =資料儲存!I256 -> 0 | Z20: =資料儲存!J256 -> 0 | AB20: 45 | AC20: =資料儲存!D376 -> 0 | AD20: =資料儲存!E376 -> 0 | AE20: =資料儲存!F376 -> 0 | AF20: =資料儲存!G376 -> 0 | AG20: =資料儲存!H376 -> 0 | AH20: =資料儲存!I376 -> 0 | AI20: =資料儲存!J376 -> 0 | AK20: 45 | AL20: =資料儲存!D496 -> 0 | AM20: =資料儲存!E496 -> 0 | AN20: =資料儲存!F496 -> 0 | AO20: =資料儲存!G496 -> 0 | AP20: =資料儲存!H496 -> 0 | AQ20: =資料儲存!I496 -> 0 | AR20: =資料儲存!J496 -> 0 | AT20: 45 | AU20: =資料儲存!D616 -> 0 | AV20: =資料儲存!E616 -> 0 | AW20: =資料儲存!F616 -> 0 | AX20: =資料儲存!G616 -> 0 | AY20: =資料儲存!H616 -> 0 | AZ20: =資料儲存!I616 -> 0 | BA20: =資料儲存!J616 -> 0
A21: 總 計 | B21: =SUM(B6:E20) -> 0 | F21: =F20 -> 0 | G21: =G20 -> 0 | H21: =H20 -> 0 | J21: 總 計 | K21: =SUM(K6:N20) -> 0 | O21: =O20 -> 0 | P21: =P20 -> 0 | Q21: =Q20 -> 0 | S21: 總 計 | T21: =SUM(T6:W20) -> 0 | X21: =X20 -> 0 | Y21: =Y20 -> 0 | Z21: =Z20 -> 0 | AB21: 總 計 | AC21: =SUM(AC6:AF20) -> 0 | AG21: =AG20 -> 0 | AH21: =AH20 -> 0 | AI21: =AI20 -> 0 | AK21: 總 計 | AL21: =SUM(AL6:AO20) -> 0 | AP21: =AP20 -> 0 | AQ21: =AQ20 -> 0 | AR21: =AR20 -> 0 | AT21: 總 計 | AU21: =SUM(AU6:AX20) -> 0 | AY21: =AY20 -> 0 | AZ21: =AZ20 -> 0 | BA21: =BA20 -> 0
A22: 06:45~07:00 | J22: 06:45~07:00 | S22: 06:45~07:00 | AB22: 06:45~07:00 | AK22: 06:45~07:00 | AT22: 06:45~07:00
A23: 開始時刻 | B23: 停車在臨近車道上的車輛總數 | F23: 臨近車道上的流量 | J23: 開始時刻 | K23: 停車在臨近車道上的車輛總數 | O23: 臨近車道上的流量 | S23: 開始時刻 | T23: 停車在臨近車道上的車輛總數 | X23: 臨近車道上的流量 | AB23: 開始時刻 | AC23: 停車在臨近車道上的車輛總數 | AG23: 臨近車道上的流量 | AK23: 開始時刻 | AL23: 停車在臨近車道上的車輛總數 | AP23: 臨近車道上的流量 | AT23: 開始時刻 | AU23: 停車在臨近車道上的車輛總數 | AY23: 臨近車道上的流量
A24: 0.28125 | B24: 0秒 | C24: 15秒 | D24: 30秒 | E24: 45秒 | F24: 總數 | G24: 未受阻 | H24: 受阻 | J24: 0.28125 | K24: 0秒 | L24: 15秒 | M24: 30秒 | N24: 45秒 | O24: 總數 | P24: 未受阻 | Q24: 受阻 | S24: 0.28125 | T24: 0秒 | U24: 15秒 | V24: 30秒 | W24: 45秒 | X24: 總數 | Y24: 未受阻 | Z24: 受阻 | AB24: 0.28125 | AC24: 0秒 | AD24: 15秒 | AE24: 30秒 | AF24: 45秒 | AG24: 總數 | AH24: 未受阻 | AI24: 受阻 | AK24: 0.28125 | AL24: 0秒 | AM24: 15秒 | AN24: 30秒 | AO24: 45秒 | AP24: 總數 | AQ24: 未受阻 | AR24: 受阻 | AT24: 0.28125 | AU24: 0秒 | AV24: 15秒 | AW24: 30秒 | AX24: 45秒 | AY24: 總數 | AZ24: 未受阻 | BA24: 受阻
A25: 46 | B25: =資料儲存!D17 -> 0 | C25: =資料儲存!E17 -> 0 | D25: =資料儲存!F17 -> 0 | E25: =資料儲存!G17 -> 0 | F25: =資料儲存!H17 -> 0 | G25: =資料儲存!I17 -> 0 | H25: =資料儲存!J17 -> 0 | J25: 46 | K25: =資料儲存!D137 -> 0 | L25: =資料儲存!E137 -> 0 | M25: =資料儲存!F137 -> 0 | N25: =資料儲存!G137 -> 0 | O25: =資料儲存!H137 -> 0 | P25: =資料儲存!I137 -> 0 | Q25: =資料儲存!J137 -> 0 | S25: 46 | T25: =資料儲存!D257 -> 0 | U25: =資料儲存!E257 -> 0 | V25: =資料儲存!F257 -> 0 | W25: =資料儲存!G257 -> 0 | X25: =資料儲存!H257 -> 0 | Y25: =資料儲存!I257 -> 0 | Z25: =資料儲存!J257 -> 0 | AB25: 46 | AC25: =資料儲存!D377 -> 0 | AD25: =資料儲存!E377 -> 0 | AE25: =資料儲存!F377 -> 0 | AF25: =資料儲存!G377 -> 0 | AG25: =資料儲存!H377 -> 0 | AH25: =資料儲存!I377 -> 0 | AI25: =資料儲存!J377 -> 0 | AK25: 46 | AL25: =資料儲存!D497 -> 0 | AM25: =資料儲存!E497 -> 0 | AN25: =資料儲存!F497 -> 0 | AO25: =資料儲存!G497 -> 0 | AP25: =資料儲存!H497 -> 0 | AQ25: =資料儲存!I497 -> 0 | AR25: =資料儲存!J497 -> 0 | AT25: 46 | AU25: =資料儲存!D617 -> 0 | AV25: =資料儲存!E617 -> 0 | AW25: =資料儲存!F617 -> 0 | AX25: =資料儲存!G617 -> 0 | AY25: =資料儲存!H617 -> 0 | AZ25: =資料儲存!I617 -> 0 | BA25: =資料儲存!J617 -> 0
A26: 47 | B26: =資料儲存!D18 -> 0 | C26: =資料儲存!E18 -> 0 | D26: =資料儲存!F18 -> 0 | E26: =資料儲存!G18 -> 0 | F26: =資料儲存!H18 -> 0 | G26: =資料儲存!I18 -> 0 | H26: =資料儲存!J18 -> 0 | J26: 47 | K26: =資料儲存!D138 -> 0 | L26: =資料儲存!E138 -> 0 | M26: =資料儲存!F138 -> 0 | N26: =資料儲存!G138 -> 0 | O26: =資料儲存!H138 -> 0 | P26: =資料儲存!I138 -> 0 | Q26: =資料儲存!J138 -> 0 | S26: 47 | T26: =資料儲存!D258 -> 0 | U26: =資料儲存!E258 -> 0 | V26: =資料儲存!F258 -> 0 | W26: =資料儲存!G258 -> 0 | X26: =資料儲存!H258 -> 0 | Y26: =資料儲存!I258 -> 0 | Z26: =資料儲存!J258 -> 0 | AB26: 47 | AC26: =資料儲存!D378 -> 0 | AD26: =資料儲存!E378 -> 0 | AE26: =資料儲存!F378 -> 0 | AF26: =資料儲存!G378 -> 0 | AG26: =資料儲存!H378 -> 0 | AH26: =資料儲存!I378 -> 0 | AI26: =資料儲存!J378 -> 0 | AK26: 47 | AL26: =資料儲存!D498 -> 0 | AM26: =資料儲存!E498 -> 0 | AN26: =資料儲存!F498 -> 0 | AO26: =資料儲存!G498 -> 0 | AP26: =資料儲存!H498 -> 0 | AQ26: =資料儲存!I498 -> 0 | AR26: =資料儲存!J498 -> 0 | AT26: 47 | AU26: =資料儲存!D618 -> 0 | AV26: =資料儲存!E618 -> 0 | AW26: =資料儲存!F618 -> 0 | AX26: =資料儲存!G618 -> 0 | AY26: =資料儲存!H618 -> 0 | AZ26: =資料儲存!I618 -> 0 | BA26: =資料儲存!J618 -> 0
A27: 48 | B27: =資料儲存!D19 -> 0 | C27: =資料儲存!E19 -> 0 | D27: =資料儲存!F19 -> 0 | E27: =資料儲存!G19 -> 0 | F27: =資料儲存!H19 -> 0 | G27: =資料儲存!I19 -> 0 | H27: =資料儲存!J19 -> 0 | J27: 48 | K27: =資料儲存!D139 -> 0 | L27: =資料儲存!E139 -> 0 | M27: =資料儲存!F139 -> 0 | N27: =資料儲存!G139 -> 0 | O27: =資料儲存!H139 -> 0 | P27: =資料儲存!I139 -> 0 | Q27: =資料儲存!J139 -> 0 | S27: 48 | T27: =資料儲存!D259 -> 0 | U27: =資料儲存!E259 -> 0 | V27: =資料儲存!F259 -> 0 | W27: =資料儲存!G259 -> 0 | X27: =資料儲存!H259 -> 0 | Y27: =資料儲存!I259 -> 0 | Z27: =資料儲存!J259 -> 0 | AB27: 48 | AC27: =資料儲存!D379 -> 0 | AD27: =資料儲存!E379 -> 0 | AE27: =資料儲存!F379 -> 0 | AF27: =資料儲存!G379 -> 0 | AG27: =資料儲存!H379 -> 0 | AH27: =資料儲存!I379 -> 0 | AI27: =資料儲存!J379 -> 0 | AK27: 48 | AL27: =資料儲存!D499 -> 0 | AM27: =資料儲存!E499 -> 0 | AN27: =資料儲存!F499 -> 0 | AO27: =資料儲存!G499 -> 0 | AP27: =資料儲存!H499 -> 0 | AQ27: =資料儲存!I499 -> 0 | AR27: =資料儲存!J499 -> 0 | AT27: 48 | AU27: =資料儲存!D619 -> 0 | AV27: =資料儲存!E619 -> 0 | AW27: =資料儲存!F619 -> 0 | AX27: =資料儲存!G619 -> 0 | AY27: =資料儲存!H619 -> 0 | AZ27: =資料儲存!I619 -> 0 | BA27: =資料儲存!J619 -> 0
A28: 49 | B28: =資料儲存!D20 -> 0 | C28: =資料儲存!E20 -> 0 | D28: =資料儲存!F20 -> 0 | E28: =資料儲存!G20 -> 0 | F28: =資料儲存!H20 -> 0 | G28: =資料儲存!I20 -> 0 | H28: =資料儲存!J20 -> 0 | J28: 49 | K28: =資料儲存!D140 -> 0 | L28: =資料儲存!E140 -> 0 | M28: =資料儲存!F140 -> 0 | N28: =資料儲存!G140 -> 0 | O28: =資料儲存!H140 -> 0 | P28: =資料儲存!I140 -> 0 | Q28: =資料儲存!J140 -> 0 | S28: 49 | T28: =資料儲存!D260 -> 0 | U28: =資料儲存!E260 -> 0 | V28: =資料儲存!F260 -> 0 | W28: =資料儲存!G260 -> 0 | X28: =資料儲存!H260 -> 0 | Y28: =資料儲存!I260 -> 0 | Z28: =資料儲存!J260 -> 0 | AB28: 49 | AC28: =資料儲存!D380 -> 0 | AD28: =資料儲存!E380 -> 0 | AE28: =資料儲存!F380 -> 0 | AF28: =資料儲存!G380 -> 0 | AG28: =資料儲存!H380 -> 0 | AH28: =資料儲存!I380 -> 0 | AI28: =資料儲存!J380 -> 0 | AK28: 49 | AL28: =資料儲存!D500 -> 0 | AM28: =資料儲存!E500 -> 0 | AN28: =資料儲存!F500 -> 0 | AO28: =資料儲存!G500 -> 0 | AP28: =資料儲存!H500 -> 0 | AQ28: =資料儲存!I500 -> 0 | AR28: =資料儲存!J500 -> 0 | AT28: 49 | AU28: =資料儲存!D620 -> 0 | AV28: =資料儲存!E620 -> 0 | AW28: =資料儲存!F620 -> 0 | AX28: =資料儲存!G620 -> 0 | AY28: =資料儲存!H620 -> 0 | AZ28: =資料儲存!I620 -> 0 | BA28: =資料儲存!J620 -> 0
A29: 50 | B29: =資料儲存!D21 -> 0 | C29: =資料儲存!E21 -> 0 | D29: =資料儲存!F21 -> 0 | E29: =資料儲存!G21 -> 0 | F29: =資料儲存!H21 -> 0 | G29: =資料儲存!I21 -> 0 | H29: =資料儲存!J21 -> 0 | J29: 50 | K29: =資料儲存!D141 -> 0 | L29: =資料儲存!E141 -> 0 | M29: =資料儲存!F141 -> 0 | N29: =資料儲存!G141 -> 0 | O29: =資料儲存!H141 -> 0 | P29: =資料儲存!I141 -> 0 | Q29: =資料儲存!J141 -> 0 | S29: 50 | T29: =資料儲存!D261 -> 0 | U29: =資料儲存!E261 -> 0 | V29: =資料儲存!F261 -> 0 | W29: =資料儲存!G261 -> 0 | X29: =資料儲存!H261 -> 0 | Y29: =資料儲存!I261 -> 0 | Z29: =資料儲存!J261 -> 0 | AB29: 50 | AC29: =資料儲存!D381 -> 0 | AD29: =資料儲存!E381 -> 0 | AE29: =資料儲存!F381 -> 0 | AF29: =資料儲存!G381 -> 0 | AG29: =資料儲存!H381 -> 0 | AH29: =資料儲存!I381 -> 0 | AI29: =資料儲存!J381 -> 0 | AK29: 50 | AL29: =資料儲存!D501 -> 0 | AM29: =資料儲存!E501 -> 0 | AN29: =資料儲存!F501 -> 0 | AO29: =資料儲存!G501 -> 0 | AP29: =資料儲存!H501 -> 0 | AQ29: =資料儲存!I501 -> 0 | AR29: =資料儲存!J501 -> 0 | AT29: 50 | AU29: =資料儲存!D621 -> 0 | AV29: =資料儲存!E621 -> 0 | AW29: =資料儲存!F621 -> 0 | AX29: =資料儲存!G621 -> 0 | AY29: =資料儲存!H621 -> 0 | AZ29: =資料儲存!I621 -> 0 | BA29: =資料儲存!J621 -> 0
A30: 51 | B30: =資料儲存!D22 -> 0 | C30: =資料儲存!E22 -> 0 | D30: =資料儲存!F22 -> 0 | E30: =資料儲存!G22 -> 0 | F30: =資料儲存!H22 -> 0 | G30: =資料儲存!I22 -> 0 | H30: =資料儲存!J22 -> 0 | J30: 51 | K30: =資料儲存!D142 -> 0 | L30: =資料儲存!E142 -> 0 | M30: =資料儲存!F142 -> 0 | N30: =資料儲存!G142 -> 0 | O30: =資料儲存!H142 -> 0 | P30: =資料儲存!I142 -> 0 | Q30: =資料儲存!J142 -> 0 | S30: 51 | T30: =資料儲存!D262 -> 0 | U30: =資料儲存!E262 -> 0 | V30: =資料儲存!F262 -> 0 | W30: =資料儲存!G262 -> 0 | X30: =資料儲存!H262 -> 0 | Y30: =資料儲存!I262 -> 0 | Z30: =資料儲存!J262 -> 0 | AB30: 51 | AC30: =資料儲存!D382 -> 0 | AD30: =資料儲存!E382 -> 0 | AE30: =資料儲存!F382 -> 0 | AF30: =資料儲存!G382 -> 0 | AG30: =資料儲存!H382 -> 0 | AH30: =資料儲存!I382 -> 0 | AI30: =資料儲存!J382 -> 0 | AK30: 51 | AL30: =資料儲存!D502 -> 0 | AM30: =資料儲存!E502 -> 0 | AN30: =資料儲存!F502 -> 0 | AO30: =資料儲存!G502 -> 0 | AP30: =資料儲存!H502 -> 0 | AQ30: =資料儲存!I502 -> 0 | AR30: =資料儲存!J502 -> 0 | AT30: 51 | AU30: =資料儲存!D622 -> 0 | AV30: =資料儲存!E622 -> 0 | AW30: =資料儲存!F622 -> 0 | AX30: =資料儲存!G622 -> 0 | AY30: =資料儲存!H622 -> 0 | AZ30: =資料儲存!I622 -> 0 | BA30: =資料儲存!J622 -> 0
A31: 52 | B31: =資料儲存!D23 -> 0 | C31: =資料儲存!E23 -> 0 | D31: =資料儲存!F23 -> 0 | E31: =資料儲存!G23 -> 0 | F31: =資料儲存!H23 -> 0 | G31: =資料儲存!I23 -> 0 | H31: =資料儲存!J23 -> 0 | J31: 52 | K31: =資料儲存!D143 -> 0 | L31: =資料儲存!E143 -> 0 | M31: =資料儲存!F143 -> 0 | N31: =資料儲存!G143 -> 0 | O31: =資料儲存!H143 -> 0 | P31: =資料儲存!I143 -> 0 | Q31: =資料儲存!J143 -> 0 | S31: 52 | T31: =資料儲存!D263 -> 0 | U31: =資料儲存!E263 -> 0 | V31: =資料儲存!F263 -> 0 | W31: =資料儲存!G263 -> 0 | X31: =資料儲存!H263 -> 0 | Y31: =資料儲存!I263 -> 0 | Z31: =資料儲存!J263 -> 0 | AB31: 52 | AC31: =資料儲存!D383 -> 0 | AD31: =資料儲存!E383 -> 0 | AE31: =資料儲存!F383 -> 0 | AF31: =資料儲存!G383 -> 0 | AG31: =資料儲存!H383 -> 0 | AH31: =資料儲存!I383 -> 0 | AI31: =資料儲存!J383 -> 0 | AK31: 52 | AL31: =資料儲存!D503 -> 0 | AM31: =資料儲存!E503 -> 0 | AN31: =資料儲存!F503 -> 0 | AO31: =資料儲存!G503 -> 0 | AP31: =資料儲存!H503 -> 0 | AQ31: =資料儲存!I503 -> 0 | AR31: =資料儲存!J503 -> 0 | AT31: 52 | AU31: =資料儲存!D623 -> 0 | AV31: =資料儲存!E623 -> 0 | AW31: =資料儲存!F623 -> 0 | AX31: =資料儲存!G623 -> 0 | AY31: =資料儲存!H623 -> 0 | AZ31: =資料儲存!I623 -> 0 | BA31: =資料儲存!J623 -> 0
A32: 53 | B32: =資料儲存!D24 -> 0 | C32: =資料儲存!E24 -> 0 | D32: =資料儲存!F24 -> 0 | E32: =資料儲存!G24 -> 0 | F32: =資料儲存!H24 -> 0 | G32: =資料儲存!I24 -> 0 | H32: =資料儲存!J24 -> 0 | J32: 53 | K32: =資料儲存!D144 -> 0 | L32: =資料儲存!E144 -> 0 | M32: =資料儲存!F144 -> 0 | N32: =資料儲存!G144 -> 0 | O32: =資料儲存!H144 -> 0 | P32: =資料儲存!I144 -> 0 | Q32: =資料儲存!J144 -> 0 | S32: 53 | T32: =資料儲存!D264 -> 0 | U32: =資料儲存!E264 -> 0 | V32: =資料儲存!F264 -> 0 | W32: =資料儲存!G264 -> 0 | X32: =資料儲存!H264 -> 0 | Y32: =資料儲存!I264 -> 0 | Z32: =資料儲存!J264 -> 0 | AB32: 53 | AC32: =資料儲存!D384 -> 0 | AD32: =資料儲存!E384 -> 0 | AE32: =資料儲存!F384 -> 0 | AF32: =資料儲存!G384 -> 0 | AG32: =資料儲存!H384 -> 0 | AH32: =資料儲存!I384 -> 0 | AI32: =資料儲存!J384 -> 0 | AK32: 53 | AL32: =資料儲存!D504 -> 0 | AM32: =資料儲存!E504 -> 0 | AN32: =資料儲存!F504 -> 0 | AO32: =資料儲存!G504 -> 0 | AP32: =資料儲存!H504 -> 0 | AQ32: =資料儲存!I504 -> 0 | AR32: =資料儲存!J504 -> 0 | AT32: 53 | AU32: =資料儲存!D624 -> 0 | AV32: =資料儲存!E624 -> 0 | AW32: =資料儲存!F624 -> 0 | AX32: =資料儲存!G624 -> 0 | AY32: =資料儲存!H624 -> 0 | AZ32: =資料儲存!I624 -> 0 | BA32: =資料儲存!J624 -> 0
A33: 54 | B33: =資料儲存!D25 -> 0 | C33: =資料儲存!E25 -> 0 | D33: =資料儲存!F25 -> 0 | E33: =資料儲存!G25 -> 0 | F33: =資料儲存!H25 -> 0 | G33: =資料儲存!I25 -> 0 | H33: =資料儲存!J25 -> 0 | J33: 54 | K33: =資料儲存!D145 -> 0 | L33: =資料儲存!E145 -> 0 | M33: =資料儲存!F145 -> 0 | N33: =資料儲存!G145 -> 0 | O33: =資料儲存!H145 -> 0 | P33: =資料儲存!I145 -> 0 | Q33: =資料儲存!J145 -> 0 | S33: 54 | T33: =資料儲存!D265 -> 0 | U33: =資料儲存!E265 -> 0 | V33: =資料儲存!F265 -> 0 | W33: =資料儲存!G265 -> 0 | X33: =資料儲存!H265 -> 0 | Y33: =資料儲存!I265 -> 0 | Z33: =資料儲存!J265 -> 0 | AB33: 54 | AC33: =資料儲存!D385 -> 0 | AD33: =資料儲存!E385 -> 0 | AE33: =資料儲存!F385 -> 0 | AF33: =資料儲存!G385 -> 0 | AG33: =資料儲存!H385 -> 0 | AH33: =資料儲存!I385 -> 0 | AI33: =資料儲存!J385 -> 0 | AK33: 54 | AL33: =資料儲存!D505 -> 0 | AM33: =資料儲存!E505 -> 0 | AN33: =資料儲存!F505 -> 0 | AO33: =資料儲存!G505 -> 0 | AP33: =資料儲存!H505 -> 0 | AQ33: =資料儲存!I505 -> 0 | AR33: =資料儲存!J505 -> 0 | AT33: 54 | AU33: =資料儲存!D625 -> 0 | AV33: =資料儲存!E625 -> 0 | AW33: =資料儲存!F625 -> 0 | AX33: =資料儲存!G625 -> 0 | AY33: =資料儲存!H625 -> 0 | AZ33: =資料儲存!I625 -> 0 | BA33: =資料儲存!J625 -> 0
A34: 55 | B34: =資料儲存!D26 -> 0 | C34: =資料儲存!E26 -> 0 | D34: =資料儲存!F26 -> 0 | E34: =資料儲存!G26 -> 0 | F34: =資料儲存!H26 -> 0 | G34: =資料儲存!I26 -> 0 | H34: =資料儲存!J26 -> 0 | J34: 55 | K34: =資料儲存!D146 -> 0 | L34: =資料儲存!E146 -> 0 | M34: =資料儲存!F146 -> 0 | N34: =資料儲存!G146 -> 0 | O34: =資料儲存!H146 -> 0 | P34: =資料儲存!I146 -> 0 | Q34: =資料儲存!J146 -> 0 | S34: 55 | T34: =資料儲存!D266 -> 0 | U34: =資料儲存!E266 -> 0 | V34: =資料儲存!F266 -> 0 | W34: =資料儲存!G266 -> 0 | X34: =資料儲存!H266 -> 0 | Y34: =資料儲存!I266 -> 0 | Z34: =資料儲存!J266 -> 0 | AB34: 55 | AC34: =資料儲存!D386 -> 0 | AD34: =資料儲存!E386 -> 0 | AE34: =資料儲存!F386 -> 0 | AF34: =資料儲存!G386 -> 0 | AG34: =資料儲存!H386 -> 0 | AH34: =資料儲存!I386 -> 0 | AI34: =資料儲存!J386 -> 0 | AK34: 55 | AL34: =資料儲存!D506 -> 0 | AM34: =資料儲存!E506 -> 0 | AN34: =資料儲存!F506 -> 0 | AO34: =資料儲存!G506 -> 0 | AP34: =資料儲存!H506 -> 0 | AQ34: =資料儲存!I506 -> 0 | AR34: =資料儲存!J506 -> 0 | AT34: 55 | AU34: =資料儲存!D626 -> 0 | AV34: =資料儲存!E626 -> 0 | AW34: =資料儲存!F626 -> 0 | AX34: =資料儲存!G626 -> 0 | AY34: =資料儲存!H626 -> 0 | AZ34: =資料儲存!I626 -> 0 | BA34: =資料儲存!J626 -> 0
A35: 56 | B35: =資料儲存!D27 -> 0 | C35: =資料儲存!E27 -> 0 | D35: =資料儲存!F27 -> 0 | E35: =資料儲存!G27 -> 0 | F35: =資料儲存!H27 -> 0 | G35: =資料儲存!I27 -> 0 | H35: =資料儲存!J27 -> 0 | J35: 56 | K35: =資料儲存!D147 -> 0 | L35: =資料儲存!E147 -> 0 | M35: =資料儲存!F147 -> 0 | N35: =資料儲存!G147 -> 0 | O35: =資料儲存!H147 -> 0 | P35: =資料儲存!I147 -> 0 | Q35: =資料儲存!J147 -> 0 | S35: 56 | T35: =資料儲存!D267 -> 0 | U35: =資料儲存!E267 -> 0 | V35: =資料儲存!F267 -> 0 | W35: =資料儲存!G267 -> 0 | X35: =資料儲存!H267 -> 0 | Y35: =資料儲存!I267 -> 0 | Z35: =資料儲存!J267 -> 0 | AB35: 56 | AC35: =資料儲存!D387 -> 0 | AD35: =資料儲存!E387 -> 0 | AE35: =資料儲存!F387 -> 0 | AF35: =資料儲存!G387 -> 0 | AG35: =資料儲存!H387 -> 0 | AH35: =資料儲存!I387 -> 0 | AI35: =資料儲存!J387 -> 0 | AK35: 56 | AL35: =資料儲存!D507 -> 0 | AM35: =資料儲存!E507 -> 0 | AN35: =資料儲存!F507 -> 0 | AO35: =資料儲存!G507 -> 0 | AP35: =資料儲存!H507 -> 0 | AQ35: =資料儲存!I507 -> 0 | AR35: =資料儲存!J507 -> 0 | AT35: 56 | AU35: =資料儲存!D627 -> 0 | AV35: =資料儲存!E627 -> 0 | AW35: =資料儲存!F627 -> 0 | AX35: =資料儲存!G627 -> 0 | AY35: =資料儲存!H627 -> 0 | AZ35: =資料儲存!I627 -> 0 | BA35: =資料儲存!J627 -> 0
A36: 57 | B36: =資料儲存!D28 -> 0 | C36: =資料儲存!E28 -> 0 | D36: =資料儲存!F28 -> 0 | E36: =資料儲存!G28 -> 0 | F36: =資料儲存!H28 -> 0 | G36: =資料儲存!I28 -> 0 | H36: =資料儲存!J28 -> 0 | J36: 57 | K36: =資料儲存!D148 -> 0 | L36: =資料儲存!E148 -> 0 | M36: =資料儲存!F148 -> 0 | N36: =資料儲存!G148 -> 0 | O36: =資料儲存!H148 -> 0 | P36: =資料儲存!I148 -> 0 | Q36: =資料儲存!J148 -> 0 | S36: 57 | T36: =資料儲存!D268 -> 0 | U36: =資料儲存!E268 -> 0 | V36: =資料儲存!F268 -> 0 | W36: =資料儲存!G268 -> 0 | X36: =資料儲存!H268 -> 0 | Y36: =資料儲存!I268 -> 0 | Z36: =資料儲存!J268 -> 0 | AB36: 57 | AC36: =資料儲存!D388 -> 0 | AD36: =資料儲存!E388 -> 0 | AE36: =資料儲存!F388 -> 0 | AF36: =資料儲存!G388 -> 0 | AG36: =資料儲存!H388 -> 0 | AH36: =資料儲存!I388 -> 0 | AI36: =資料儲存!J388 -> 0 | AK36: 57 | AL36: =資料儲存!D508 -> 0 | AM36: =資料儲存!E508 -> 0 | AN36: =資料儲存!F508 -> 0 | AO36: =資料儲存!G508 -> 0 | AP36: =資料儲存!H508 -> 0 | AQ36: =資料儲存!I508 -> 0 | AR36: =資料儲存!J508 -> 0 | AT36: 57 | AU36: =資料儲存!D628 -> 0 | AV36: =資料儲存!E628 -> 0 | AW36: =資料儲存!F628 -> 0 | AX36: =資料儲存!G628 -> 0 | AY36: =資料儲存!H628 -> 0 | AZ36: =資料儲存!I628 -> 0 | BA36: =資料儲存!J628 -> 0
... A39: 60 | B39: =資料儲存!D31 -> 0 | C39: =資料儲存!E31 -> 0 | D39: =資料儲存!F31 -> 0 | E39: =資料儲存!G31 -> 0 | F39: =資料儲存!H31 -> 0 | G39: =資料儲存!I31 -> 0 | H39: =資料儲存!J31 -> 0 | J39: 60 | K39: =資料儲存!D151 -> 0 | L39: =資料儲存!E151 -> 0 | M39: =資料儲存!F151 -> 0 | N39: =資料儲存!G151 -> 0 | O39: =資料儲存!H151 -> 0 | P39: =資料儲存!I151 -> 0 | Q39: =資料儲存!J151 -> 0 | S39: 60 | T39: =資料儲存!D271 -> 0 | U39: =資料儲存!E271 -> 0 | V39: =資料儲存!F271 -> 0 | W39: =資料儲存!G271 -> 0 | X39: =資料儲存!H271 -> 0 | Y39: =資料儲存!I271 -> 0 | Z39: =資料儲存!J271 -> 0 | AB39: 60 | AC39: =資料儲存!D391 -> 0 | AD39: =資料儲存!E391 -> 0 | AE39: =資料儲存!F391 -> 0 | AF39: =資料儲存!G391 -> 0 | AG39: =資料儲存!H391 -> 0 | AH39: =資料儲存!I391 -> 0 | AI39: =資料儲存!J391 -> 0 | AK39: 60 | AL39: =資料儲存!D511 -> 0 | AM39: =資料儲存!E511 -> 0 | AN39: =資料儲存!F511 -> 0 | AO39: =資料儲存!G511 -> 0 | AP39: =資料儲存!H511 -> 0 | AQ39: =資料儲存!I511 -> 0 | AR39: =資料儲存!J511 -> 0 | AT39: 60 | AU39: =資料儲存!D631 -> 0 | AV39: =資料儲存!E631 -> 0 | AW39: =資料儲存!F631 -> 0 | AX39: =資料儲存!G631 -> 0 | AY39: =資料儲存!H631 -> 0 | AZ39: =資料儲存!I631 -> 0 | BA39: =資料儲存!J631 -> 0
A40: 總 計 | B40: =SUM(B25:E39) -> 0 | F40: =F39 -> 0 | G40: =G39 -> 0 | H40: =H39 -> 0 | J40: 總 計 | K40: =SUM(K25:N39) -> 0 | O40: =O39 -> 0 | P40: =P39 -> 0 | Q40: =Q39 -> 0 | S40: 總 計 | T40: =SUM(T25:W39) -> 0 | X40: =X39 -> 0 | Y40: =Y39 -> 0 | Z40: =Z39 -> 0 | AB40: 總 計 | AC40: =SUM(AC25:AF39) -> 0 | AG40: =AG39 -> 0 | AH40: =AH39 -> 0 | AI40: =AI39 -> 0 | AK40: 總 計 | AL40: =SUM(AL25:AO39) -> 0 | AP40: =AP39 -> 0 | AQ40: =AQ39 -> 0 | AR40: =AR39 -> 0 | AT40: 總 計 | AU40: =SUM(AU25:AX39) -> 0 | AY40: =AY39 -> 0 | AZ40: =AZ39 -> 0 | BA40: =BA39 -> 0
A41: 07:00~07:15 | J41: 07:00~07:15 | S41: 07:00~07:15 | AB41: 07:00~07:15 | AK41: 07:00~07:15 | AT41: 07:00~07:15
A42: 開始時刻 | B42: 停車在臨近車道上的車輛總數 | F42: 臨近車道上的流量 | J42: 開始時刻 | K42: 停車在臨近車道上的車輛總數 | O42: 臨近車道上的流量 | S42: 開始時刻 | T42: 停車在臨近車道上的車輛總數 | X42: 臨近車道上的流量 | AB42: 開始時刻 | AC42: 停車在臨近車道上的車輛總數 | AG42: 臨近車道上的流量 | AK42: 開始時刻 | AL42: 停車在臨近車道上的車輛總數 | AP42: 臨近車道上的流量 | AT42: 開始時刻 | AU42: 停車在臨近車道上的車輛總數 | AY42: 臨近車道上的流量
A43: 07:00 | B43: 0秒 | C43: 15秒 | D43: 30秒 | E43: 45秒 | F43: 總數 | G43: 未受阻 | H43: 受阻 | J43: 07:00 | K43: 0秒 | L43: 15秒 | M43: 30秒 | N43: 45秒 | O43: 總數 | P43: 未受阻 | Q43: 受阻 | S43: 07:00 | T43: 0秒 | U43: 15秒 | V43: 30秒 | W43: 45秒 | X43: 總數 | Y43: 未受阻 | Z43: 受阻 | AB43: 07:00 | AC43: 0秒 | AD43: 15秒 | AE43: 30秒 | AF43: 45秒 | AG43: 總數 | AH43: 未受阻 | AI43: 受阻 | AK43: 07:00 | AL43: 0秒 | AM43: 15秒 | AN43: 30秒 | AO43: 45秒 | AP43: 總數 | AQ43: 未受阻 | AR43: 受阻 | AT43: 07:00 | AU43: 0秒 | AV43: 15秒 | AW43: 30秒 | AX43: 45秒 | AY43: 總數 | AZ43: 未受阻 | BA43: 受阻
A44: 1 | B44: =資料儲存!D32 -> 0 | C44: =資料儲存!E32 -> 0 | D44: =資料儲存!F32 -> 0 | E44: =資料儲存!G32 -> 0 | F44: =資料儲存!H32 -> 0 | G44: =資料儲存!I32 -> 0 | H44: =資料儲存!J32 -> 0 | J44: 1 | K44: =資料儲存!D152 -> 0 | L44: =資料儲存!E152 -> 0 | M44: =資料儲存!F152 -> 0 | N44: =資料儲存!G152 -> 0 | O44: =資料儲存!H152 -> 0 | P44: =資料儲存!I152 -> 0 | Q44: =資料儲存!J152 -> 0 | S44: 1 | T44: =資料儲存!D272 -> 0 | U44: =資料儲存!E272 -> 0 | V44: =資料儲存!F272 -> 0 | W44: =資料儲存!G272 -> 0 | X44: =資料儲存!H272 -> 0 | Y44: =資料儲存!I272 -> 0 | Z44: =資料儲存!J272 -> 0 | AB44: 1 | AC44: =資料儲存!D392 -> 0 | AD44: =資料儲存!E392 -> 0 | AE44: =資料儲存!F392 -> 0 | AF44: =資料儲存!G392 -> 0 | AG44: =資料儲存!H392 -> 0 | AH44: =資料儲存!I392 -> 0 | AI44: =資料儲存!J392 -> 0 | AK44: 1 | AL44: =資料儲存!D512 -> 0 | AM44: =資料儲存!E512 -> 0 | AN44: =資料儲存!F512 -> 0 | AO44: =資料儲存!G512 -> 0 | AP44: =資料儲存!H512 -> 0 | AQ44: =資料儲存!I512 -> 0 | AR44: =資料儲存!J512 -> 0 | AT44: 1 | AU44: =資料儲存!D632 -> 0 | AV44: =資料儲存!E632 -> 0 | AW44: =資料儲存!F632 -> 0 | AX44: =資料儲存!G632 -> 0 | AY44: =資料儲存!H632 -> 0 | AZ44: =資料儲存!I632 -> 0 | BA44: =資料儲存!J632 -> 0
...

Sheet 假日(16-20)
A1: =基本資料!L11 -> 假日(16-20) | J1: =基本資料!L11 -> 假日(16-20) | S1: =基本資料!L11 -> 假日(16-20) | AB1: =基本資料!L11 -> 假日(16-20) | AK1: =基本資料!L11 -> 假日(16-20) | AT1: =基本資料!L11 -> 假日(16-20)
A2: =CONCATENATE(基本資料!B18,"方向：",基本資料!B19,基本資料!B20) -> A方向： | J2: =CONCATENATE(基本資料!C18,"方向：",基本資料!C19,基本資料!C20) -> B方向： | S2: =CONCATENATE(基本資料!D18,"方向：",基本資料!D19,基本資料!D20) -> C方向： | AB2: =CONCATENATE(基本資料!E18,"方向：",基本資料!E19,基本資料!E20) -> D方向： | AK2: =CONCATENATE(基本資料!F18,"方向：",基本資料!F19,基本資料!F20) -> E方向： | AT2: =CONCATENATE(基本資料!G18,"方向：",基本資料!G19,基本資料!G20) -> F方向：
A3: 16:00~16:15 | J3: 16:00~16:15 | S3: 16:00~16:15 | AB3: 16:00~16:15 | AK3: 16:00~16:15 | AT3: 16:00~16:15
A4: 開始時刻 | B4: 停車在臨近車道上的車輛總數 | F4: 臨近車道上的流量 | J4: 開始時刻 | K4: 停車在臨近車道上的車輛總數 | O4: 臨近車道上的流量 | S4: 開始時刻 | T4: 停車在臨近車道上的車輛總數 | X4: 臨近車道上的流量 | AB4: 開始時刻 | AC4: 停車在臨近車道上的車輛總數 | AG4: 臨近車道上的流量 | AK4: 開始時刻 | AL4: 停車在臨近車道上的車輛總數 | AP4: 臨近車道上的流量 | AT4: 開始時刻 | AU4: 停車在臨近車道上的車輛總數 | AY4: 臨近車道上的流量
A5: 0.66666667 | B5: 0秒 | C5: 15秒 | D5: 30秒 | E5: 45秒 | F5: 總數 | G5: 未受阻 | H5: 受阻 | J5: 0.66666667 | K5: 0秒 | L5: 15秒 | M5: 30秒 | N5: 45秒 | O5: 總數 | P5: 未受阻 | Q5: 受阻 | S5: 0.66666667 | T5: 0秒 | U5: 15秒 | V5: 30秒 | W5: 45秒 | X5: 總數 | Y5: 未受阻 | Z5: 受阻 | AB5: 0.66666667 | AC5: 0秒 | AD5: 15秒 | AE5: 30秒 | AF5: 45秒 | AG5: 總數 | AH5: 未受阻 | AI5: 受阻 | AK5: 0.66666667 | AL5: 0秒 | AM5: 15秒 | AN5: 30秒 | AO5: 45秒 | AP5: 總數 | AQ5: 未受阻 | AR5: 受阻 | AT5: 0.66666667 | AU5: 0秒 | AV5: 15秒 | AW5: 30秒 | AX5: 45秒 | AY5: 總數 | AZ5: 未受阻 | BA5: 受阻
A6: 1 | B6: =資料儲存!D6122 -> 0 | C6: =資料儲存!E6122 -> 0 | D6: =資料儲存!F6122 -> 0 | E6: =資料儲存!G6122 -> 0 | F6: =資料儲存!H6122 -> 0 | G6: =資料儲存!I6122 -> 0 | H6: =資料儲存!J6122 -> 0 | J6: 1 | K6: =資料儲存!D6362 -> 0 | L6: =資料儲存!E6362 -> 0 | M6: =資料儲存!F6362 -> 0 | N6: =資料儲存!G6362 -> 0 | O6: =資料儲存!H6362 -> 0 | P6: =資料儲存!I6362 -> 0 | Q6: =資料儲存!J6362 -> 0 | S6: 1 | T6: =資料儲存!D6602 -> 0 | U6: =資料儲存!E6602 -> 0 | V6: =資料儲存!F6602 -> 0 | W6: =資料儲存!G6602 -> 0 | X6: =資料儲存!H6602 -> 0 | Y6: =資料儲存!I6602 -> 0 | Z6: =資料儲存!J6602 -> 0 | AB6: 1 | AC6: =資料儲存!D6842 -> 0 | AD6: =資料儲存!E6842 -> 0 | AE6: =資料儲存!F6842 -> 0 | AF6: =資料儲存!G6842 -> 0 | AG6: =資料儲存!H6842 -> 0 | AH6: =資料儲存!I6842 -> 0 | AI6: =資料儲存!J6842 -> 0 | AK6: 1 | AL6: =資料儲存!D7082 -> 0 | AM6: =資料儲存!E7082 -> 0 | AN6: =資料儲存!F7082 -> 0 | AO6: =資料儲存!G7082 -> 0 | AP6: =資料儲存!H7082 -> 0 | AQ6: =資料儲存!I7082 -> 0 | AR6: =資料儲存!J7082 -> 0 | AT6: 1 | AU6: =資料儲存!D7322 -> 0 | AV6: =資料儲存!E7322 -> 0 | AW6: =資料儲存!F7322 -> 0 | AX6: =資料儲存!G7322 -> 0 | AY6: =資料儲存!H7322 -> 0 | AZ6: =資料儲存!I7322 -> 0 | BA6: =資料儲存!J7322 -> 0
A7: 2 | B7: =資料儲存!D6123 -> 0 | C7: =資料儲存!E6123 -> 0 | D7: =資料儲存!F6123 -> 0 | E7: =資料儲存!G6123 -> 0 | F7: =資料儲存!H6123 -> 0 | G7: =資料儲存!I6123 -> 0 | H7: =資料儲存!J6123 -> 0 | J7: 2 | K7: =資料儲存!D6363 -> 0 | L7: =資料儲存!E6363 -> 0 | M7: =資料儲存!F6363 -> 0 | N7: =資料儲存!G6363 -> 0 | O7: =資料儲存!H6363 -> 0 | P7: =資料儲存!I6363 -> 0 | Q7: =資料儲存!J6363 -> 0 | S7: 2 | T7: =資料儲存!D6603 -> 0 | U7: =資料儲存!E6603 -> 0 | V7: =資料儲存!F6603 -> 0 | W7: =資料儲存!G6603 -> 0 | X7: =資料儲存!H6603 -> 0 | Y7: =資料儲存!I6603 -> 0 | Z7: =資料儲存!J6603 -> 0 | AB7: 2 | AC7: =資料儲存!D6843 -> 0 | AD7: =資料儲存!E6843 -> 0 | AE7: =資料儲存!F6843 -> 0 | AF7: =資料儲存!G6843 -> 0 | AG7: =資料儲存!H6843 -> 0 | AH7: =資料儲存!I6843 -> 0 | AI7: =資料儲存!J6843 -> 0 | AK7: 2 | AL7: =資料儲存!D7083 -> 0 | AM7: =資料儲存!E7083 -> 0 | AN7: =資料儲存!F7083 -> 0 | AO7: =資料儲存!G7083 -> 0 | AP7: =資料儲存!H7083 -> 0 | AQ7: =資料儲存!I7083 -> 0 | AR7: =資料儲存!J7083 -> 0 | AT7: 2 | AU7: =資料儲存!D7323 -> 0 | AV7: =資料儲存!E7323 -> 0 | AW7: =資料儲存!F7323 -> 0 | AX7: =資料儲存!G7323 -> 0 | AY7: =資料儲存!H7323 -> 0 | AZ7: =資料儲存!I7323 -> 0 | BA7: =資料儲存!J7323 -> 0
A8: 3 | B8: =資料儲存!D6124 -> 0 | C8: =資料儲存!E6124 -> 0 | D8: =資料儲存!F6124 -> 0 | E8: =資料儲存!G6124 -> 0 | F8: =資料儲存!H6124 -> 0 | G8: =資料儲存!I6124 -> 0 | H8: =資料儲存!J6124 -> 0 | J8: 3 | K8: =資料儲存!D6364 -> 0 | L8: =資料儲存!E6364 -> 0 | M8: =資料儲存!F6364 -> 0 | N8: =資料儲存!G6364 -> 0 | O8: =資料儲存!H6364 -> 0 | P8: =資料儲存!I6364 -> 0 | Q8: =資料儲存!J6364 -> 0 | S8: 3 | T8: =資料儲存!D6604 -> 0 | U8: =資料儲存!E6604 -> 0 | V8: =資料儲存!F6604 -> 0 | W8: =資料儲存!G6604 -> 0 | X8: =資料儲存!H6604 -> 0 | Y8: =資料儲存!I6604 -> 0 | Z8: =資料儲存!J6604 -> 0 | AB8: 3 | AC8: =資料儲存!D6844 -> 0 | AD8: =資料儲存!E6844 -> 0 | AE8: =資料儲存!F6844 -> 0 | AF8: =資料儲存!G6844 -> 0 | AG8: =資料儲存!H6844 -> 0 | AH8: =資料儲存!I6844 -> 0 | AI8: =資料儲存!J6844 -> 0 | AK8: 3 | AL8: =資料儲存!D7084 -> 0 | AM8: =資料儲存!E7084 -> 0 | AN8: =資料儲存!F7084 -> 0 | AO8: =資料儲存!G7084 -> 0 | AP8: =資料儲存!H7084 -> 0 | AQ8: =資料儲存!I7084 -> 0 | AR8: =資料儲存!J7084 -> 0 | AT8: 3 | AU8: =資料儲存!D7324 -> 0 | AV8: =資料儲存!E7324 -> 0 | AW8: =資料儲存!F7324 -> 0 | AX8: =資料儲存!G7324 -> 0 | AY8: =資料儲存!H7324 -> 0 | AZ8: =資料儲存!I7324 -> 0 | BA8: =資料儲存!J7324 -> 0
A9: 4 | B9: =資料儲存!D6125 -> 0 | C9: =資料儲存!E6125 -> 0 | D9: =資料儲存!F6125 -> 0 | E9: =資料儲存!G6125 -> 0 | F9: =資料儲存!H6125 -> 0 | G9: =資料儲存!I6125 -> 0 | H9: =資料儲存!J6125 -> 0 | J9: 4 | K9: =資料儲存!D6365 -> 0 | L9: =資料儲存!E6365 -> 0 | M9: =資料儲存!F6365 -> 0 | N9: =資料儲存!G6365 -> 0 | O9: =資料儲存!H6365 -> 0 | P9: =資料儲存!I6365 -> 0 | Q9: =資料儲存!J6365 -> 0 | S9: 4 | T9: =資料儲存!D6605 -> 0 | U9: =資料儲存!E6605 -> 0 | V9: =資料儲存!F6605 -> 0 | W9: =資料儲存!G6605 -> 0 | X9: =資料儲存!H6605 -> 0 | Y9: =資料儲存!I6605 -> 0 | Z9: =資料儲存!J6605 -> 0 | AB9: 4 | AC9: =資料儲存!D6845 -> 0 | AD9: =資料儲存!E6845 -> 0 | AE9: =資料儲存!F6845 -> 0 | AF9: =資料儲存!G6845 -> 0 | AG9: =資料儲存!H6845 -> 0 | AH9: =資料儲存!I6845 -> 0 | AI9: =資料儲存!J6845 -> 0 | AK9: 4 | AL9: =資料儲存!D7085 -> 0 | AM9: =資料儲存!E7085 -> 0 | AN9: =資料儲存!F7085 -> 0 | AO9: =資料儲存!G7085 -> 0 | AP9: =資料儲存!H7085 -> 0 | AQ9: =資料儲存!I7085 -> 0 | AR9: =資料儲存!J7085 -> 0 | AT9: 4 | AU9: =資料儲存!D7325 -> 0 | AV9: =資料儲存!E7325 -> 0 | AW9: =資料儲存!F7325 -> 0 | AX9: =資料儲存!G7325 -> 0 | AY9: =資料儲存!H7325 -> 0 | AZ9: =資料儲存!I7325 -> 0 | BA9: =資料儲存!J7325 -> 0
A10: 5 | B10: =資料儲存!D6126 -> 0 | C10: =資料儲存!E6126 -> 0 | D10: =資料儲存!F6126 -> 0 | E10: =資料儲存!G6126 -> 0 | F10: =資料儲存!H6126 -> 0 | G10: =資料儲存!I6126 -> 0 | H10: =資料儲存!J6126 -> 0 | J10: 5 | K10: =資料儲存!D6366 -> 0 | L10: =資料儲存!E6366 -> 0 | M10: =資料儲存!F6366 -> 0 | N10: =資料儲存!G6366 -> 0 | O10: =資料儲存!H6366 -> 0 | P10: =資料儲存!I6366 -> 0 | Q10: =資料儲存!J6366 -> 0 | S10: 5 | T10: =資料儲存!D6606 -> 0 | U10: =資料儲存!E6606 -> 0 | V10: =資料儲存!F6606 -> 0 | W10: =資料儲存!G6606 -> 0 | X10: =資料儲存!H6606 -> 0 | Y10: =資料儲存!I6606 -> 0 | Z10: =資料儲存!J6606 -> 0 | AB10: 5 | AC10: =資料儲存!D6846 -> 0 | AD10: =資料儲存!E6846 -> 0 | AE10: =資料儲存!F6846 -> 0 | AF10: =資料儲存!G6846 -> 0 | AG10: =資料儲存!H6846 -> 0 | AH10: =資料儲存!I6846 -> 0 | AI10: =資料儲存!J6846 -> 0 | AK10: 5 | AL10: =資料儲存!D7086 -> 0 | AM10: =資料儲存!E7086 -> 0 | AN10: =資料儲存!F7086 -> 0 | AO10: =資料儲存!G7086 -> 0 | AP10: =資料儲存!H7086 -> 0 | AQ10: =資料儲存!I7086 -> 0 | AR10: =資料儲存!J7086 -> 0 | AT10: 5 | AU10: =資料儲存!D7326 -> 0 | AV10: =資料儲存!E7326 -> 0 | AW10: =資料儲存!F7326 -> 0 | AX10: =資料儲存!G7326 -> 0 | AY10: =資料儲存!H7326 -> 0 | AZ10: =資料儲存!I7326 -> 0 | BA10: =資料儲存!J7326 -> 0
A11: 6 | B11: =資料儲存!D6127 -> 0 | C11: =資料儲存!E6127 -> 0 | D11: =資料儲存!F6127 -> 0 | E11: =資料儲存!G6127 -> 0 | F11: =資料儲存!H6127 -> 0 | G11: =資料儲存!I6127 -> 0 | H11: =資料儲存!J6127 -> 0 | J11: 6 | K11: =資料儲存!D6367 -> 0 | L11: =資料儲存!E6367 -> 0 | M11: =資料儲存!F6367 -> 0 | N11: =資料儲存!G6367 -> 0 | O11: =資料儲存!H6367 -> 0 | P11: =資料儲存!I6367 -> 0 | Q11: =資料儲存!J6367 -> 0 | S11: 6 | T11: =資料儲存!D6607 -> 0 | U11: =資料儲存!E6607 -> 0 | V11: =資料儲存!F6607 -> 0 | W11: =資料儲存!G6607 -> 0 | X11: =資料儲存!H6607 -> 0 | Y11: =資料儲存!I6607 -> 0 | Z11: =資料儲存!J6607 -> 0 | AB11: 6 | AC11: =資料儲存!D6847 -> 0 | AD11: =資料儲存!E6847 -> 0 | AE11: =資料儲存!F6847 -> 0 | AF11: =資料儲存!G6847 -> 0 | AG11: =資料儲存!H6847 -> 0 | AH11: =資料儲存!I6847 -> 0 | AI11: =資料儲存!J6847 -> 0 | AK11: 6 | AL11: =資料儲存!D7087 -> 0 | AM11: =資料儲存!E7087 -> 0 | AN11: =資料儲存!F7087 -> 0 | AO11: =資料儲存!G7087 -> 0 | AP11: =資料儲存!H7087 -> 0 | AQ11: =資料儲存!I7087 -> 0 | AR11: =資料儲存!J7087 -> 0 | AT11: 6 | AU11: =資料儲存!D7327 -> 0 | AV11: =資料儲存!E7327 -> 0 | AW11: =資料儲存!F7327 -> 0 | AX11: =資料儲存!G7327 -> 0 | AY11: =資料儲存!H7327 -> 0 | AZ11: =資料儲存!I7327 -> 0 | BA11: =資料儲存!J7327 -> 0
A12: 7 | B12: =資料儲存!D6128 -> 0 | C12: =資料儲存!E6128 -> 0 | D12: =資料儲存!F6128 -> 0 | E12: =資料儲存!G6128 -> 0 | F12: =資料儲存!H6128 -> 0 | G12: =資料儲存!I6128 -> 0 | H12: =資料儲存!J6128 -> 0 | J12: 7 | K12: =資料儲存!D6368 -> 0 | L12: =資料儲存!E6368 -> 0 | M12: =資料儲存!F6368 -> 0 | N12: =資料儲存!G6368 -> 0 | O12: =資料儲存!H6368 -> 0 | P12: =資料儲存!I6368 -> 0 | Q12: =資料儲存!J6368 -> 0 | S12: 7 | T12: =資料儲存!D6608 -> 0 | U12: =資料儲存!E6608 -> 0 | V12: =資料儲存!F6608 -> 0 | W12: =資料儲存!G6608 -> 0 | X12: =資料儲存!H6608 -> 0 | Y12: =資料儲存!I6608 -> 0 | Z12: =資料儲存!J6608 -> 0 | AB12: 7 | AC12: =資料儲存!D6848 -> 0 | AD12: =資料儲存!E6848 -> 0 | AE12: =資料儲存!F6848 -> 0 | AF12: =資料儲存!G6848 -> 0 | AG12: =資料儲存!H6848 -> 0 | AH12: =資料儲存!I6848 -> 0 | AI12: =資料儲存!J6848 -> 0 | AK12: 7 | AL12: =資料儲存!D7088 -> 0 | AM12: =資料儲存!E7088 -> 0 | AN12: =資料儲存!F7088 -> 0 | AO12: =資料儲存!G7088 -> 0 | AP12: =資料儲存!H7088 -> 0 | AQ12: =資料儲存!I7088 -> 0 | AR12: =資料儲存!J7088 -> 0 | AT12: 7 | AU12: =資料儲存!D7328 -> 0 | AV12: =資料儲存!E7328 -> 0 | AW12: =資料儲存!F7328 -> 0 | AX12: =資料儲存!G7328 -> 0 | AY12: =資料儲存!H7328 -> 0 | AZ12: =資料儲存!I7328 -> 0 | BA12: =資料儲存!J7328 -> 0
A13: 8 | B13: =資料儲存!D6129 -> 0 | C13: =資料儲存!E6129 -> 0 | D13: =資料儲存!F6129 -> 0 | E13: =資料儲存!G6129 -> 0 | F13: =資料儲存!H6129 -> 0 | G13: =資料儲存!I6129 -> 0 | H13: =資料儲存!J6129 -> 0 | J13: 8 | K13: =資料儲存!D6369 -> 0 | L13: =資料儲存!E6369 -> 0 | M13: =資料儲存!F6369 -> 0 | N13: =資料儲存!G6369 -> 0 | O13: =資料儲存!H6369 -> 0 | P13: =資料儲存!I6369 -> 0 | Q13: =資料儲存!J6369 -> 0 | S13: 8 | T13: =資料儲存!D6609 -> 0 | U13: =資料儲存!E6609 -> 0 | V13: =資料儲存!F6609 -> 0 | W13: =資料儲存!G6609 -> 0 | X13: =資料儲存!H6609 -> 0 | Y13: =資料儲存!I6609 -> 0 | Z13: =資料儲存!J6609 -> 0 | AB13: 8 | AC13: =資料儲存!D6849 -> 0 | AD13: =資料儲存!E6849 -> 0 | AE13: =資料儲存!F6849 -> 0 | AF13: =資料儲存!G6849 -> 0 | AG13: =資料儲存!H6849 -> 0 | AH13: =資料儲存!I6849 -> 0 | AI13: =資料儲存!J6849 -> 0 | AK13: 8 | AL13: =資料儲存!D7089 -> 0 | AM13: =資料儲存!E7089 -> 0 | AN13: =資料儲存!F7089 -> 0 | AO13: =資料儲存!G7089 -> 0 | AP13: =資料儲存!H7089 -> 0 | AQ13: =資料儲存!I7089 -> 0 | AR13: =資料儲存!J7089 -> 0 | AT13: 8 | AU13: =資料儲存!D7329 -> 0 | AV13: =資料儲存!E7329 -> 0 | AW13: =資料儲存!F7329 -> 0 | AX13: =資料儲存!G7329 -> 0 | AY13: =資料儲存!H7329 -> 0 | AZ13: =資料儲存!I7329 -> 0 | BA13: =資料儲存!J7329 -> 0
A14: 9 | B14: =資料儲存!D6130 -> 0 | C14: =資料儲存!E6130 -> 0 | D14: =資料儲存!F6130 -> 0 | E14: =資料儲存!G6130 -> 0 | F14: =資料儲存!H6130 -> 0 | G14: =資料儲存!I6130 -> 0 | H14: =資料儲存!J6130 -> 0 | J14: 9 | K14: =資料儲存!D6370 -> 0 | L14: =資料儲存!E6370 -> 0 | M14: =資料儲存!F6370 -> 0 | N14: =資料儲存!G6370 -> 0 | O14: =資料儲存!H6370 -> 0 | P14: =資料儲存!I6370 -> 0 | Q14: =資料儲存!J6370 -> 0 | S14: 9 | T14: =資料儲存!D6610 -> 0 | U14: =資料儲存!E6610 -> 0 | V14: =資料儲存!F6610 -> 0 | W14: =資料儲存!G6610 -> 0 | X14: =資料儲存!H6610 -> 0 | Y14: =資料儲存!I6610 -> 0 | Z14: =資料儲存!J6610 -> 0 | AB14: 9 | AC14: =資料儲存!D6850 -> 0 | AD14: =資料儲存!E6850 -> 0 | AE14: =資料儲存!F6850 -> 0 | AF14: =資料儲存!G6850 -> 0 | AG14: =資料儲存!H6850 -> 0 | AH14: =資料儲存!I6850 -> 0 | AI14: =資料儲存!J6850 -> 0 | AK14: 9 | AL14: =資料儲存!D7090 -> 0 | AM14: =資料儲存!E7090 -> 0 | AN14: =資料儲存!F7090 -> 0 | AO14: =資料儲存!G7090 -> 0 | AP14: =資料儲存!H7090 -> 0 | AQ14: =資料儲存!I7090 -> 0 | AR14: =資料儲存!J7090 -> 0 | AT14: 9 | AU14: =資料儲存!D7330 -> 0 | AV14: =資料儲存!E7330 -> 0 | AW14: =資料儲存!F7330 -> 0 | AX14: =資料儲存!G7330 -> 0 | AY14: =資料儲存!H7330 -> 0 | AZ14: =資料儲存!I7330 -> 0 | BA14: =資料儲存!J7330 -> 0
A15: 10 | B15: =資料儲存!D6131 -> 0 | C15: =資料儲存!E6131 -> 0 | D15: =資料儲存!F6131 -> 0 | E15: =資料儲存!G6131 -> 0 | F15: =資料儲存!H6131 -> 0 | G15: =資料儲存!I6131 -> 0 | H15: =資料儲存!J6131 -> 0 | J15: 10 | K15: =資料儲存!D6371 -> 0 | L15: =資料儲存!E6371 -> 0 | M15: =資料儲存!F6371 -> 0 | N15: =資料儲存!G6371 -> 0 | O15: =資料儲存!H6371 -> 0 | P15: =資料儲存!I6371 -> 0 | Q15: =資料儲存!J6371 -> 0 | S15: 10 | T15: =資料儲存!D6611 -> 0 | U15: =資料儲存!E6611 -> 0 | V15: =資料儲存!F6611 -> 0 | W15: =資料儲存!G6611 -> 0 | X15: =資料儲存!H6611 -> 0 | Y15: =資料儲存!I6611 -> 0 | Z15: =資料儲存!J6611 -> 0 | AB15: 10 | AC15: =資料儲存!D6851 -> 0 | AD15: =資料儲存!E6851 -> 0 | AE15: =資料儲存!F6851 -> 0 | AF15: =資料儲存!G6851 -> 0 | AG15: =資料儲存!H6851 -> 0 | AH15: =資料儲存!I6851 -> 0 | AI15: =資料儲存!J6851 -> 0 | AK15: 10 | AL15: =資料儲存!D7091 -> 0 | AM15: =資料儲存!E7091 -> 0 | AN15: =資料儲存!F7091 -> 0 | AO15: =資料儲存!G7091 -> 0 | AP15: =資料儲存!H7091 -> 0 | AQ15: =資料儲存!I7091 -> 0 | AR15: =資料儲存!J7091 -> 0 | AT15: 10 | AU15: =資料儲存!D7331 -> 0 | AV15: =資料儲存!E7331 -> 0 | AW15: =資料儲存!F7331 -> 0 | AX15: =資料儲存!G7331 -> 0 | AY15: =資料儲存!H7331 -> 0 | AZ15: =資料儲存!I7331 -> 0 | BA15: =資料儲存!J7331 -> 0
A16: 11 | B16: =資料儲存!D6132 -> 0 | C16: =資料儲存!E6132 -> 0 | D16: =資料儲存!F6132 -> 0 | E16: =資料儲存!G6132 -> 0 | F16: =資料儲存!H6132 -> 0 | G16: =資料儲存!I6132 -> 0 | H16: =資料儲存!J6132 -> 0 | J16: 11 | K16: =資料儲存!D6372 -> 0 | L16: =資料儲存!E6372 -> 0 | M16: =資料儲存!F6372 -> 0 | N16: =資料儲存!G6372 -> 0 | O16: =資料儲存!H6372 -> 0 | P16: =資料儲存!I6372 -> 0 | Q16: =資料儲存!J6372 -> 0 | S16: 11 | T16: =資料儲存!D6612 -> 0 | U16: =資料儲存!E6612 -> 0 | V16: =資料儲存!F6612 -> 0 | W16: =資料儲存!G6612 -> 0 | X16: =資料儲存!H6612 -> 0 | Y16: =資料儲存!I6612 -> 0 | Z16: =資料儲存!J6612 -> 0 | AB16: 11 | AC16: =資料儲存!D6852 -> 0 | AD16: =資料儲存!E6852 -> 0 | AE16: =資料儲存!F6852 -> 0 | AF16: =資料儲存!G6852 -> 0 | AG16: =資料儲存!H6852 -> 0 | AH16: =資料儲存!I6852 -> 0 | AI16: =資料儲存!J6852 -> 0 | AK16: 11 | AL16: =資料儲存!D7092 -> 0 | AM16: =資料儲存!E7092 -> 0 | AN16: =資料儲存!F7092 -> 0 | AO16: =資料儲存!G7092 -> 0 | AP16: =資料儲存!H7092 -> 0 | AQ16: =資料儲存!I7092 -> 0 | AR16: =資料儲存!J7092 -> 0 | AT16: 11 | AU16: =資料儲存!D7332 -> 0 | AV16: =資料儲存!E7332 -> 0 | AW16: =資料儲存!F7332 -> 0 | AX16: =資料儲存!G7332 -> 0 | AY16: =資料儲存!H7332 -> 0 | AZ16: =資料儲存!I7332 -> 0 | BA16: =資料儲存!J7332 -> 0
A17: 12 | B17: =資料儲存!D6133 -> 0 | C17: =資料儲存!E6133 -> 0 | D17: =資料儲存!F6133 -> 0 | E17: =資料儲存!G6133 -> 0 | F17: =資料儲存!H6133 -> 0 | G17: =資料儲存!I6133 -> 0 | H17: =資料儲存!J6133 -> 0 | J17: 12 | K17: =資料儲存!D6373 -> 0 | L17: =資料儲存!E6373 -> 0 | M17: =資料儲存!F6373 -> 0 | N17: =資料儲存!G6373 -> 0 | O17: =資料儲存!H6373 -> 0 | P17: =資料儲存!I6373 -> 0 | Q17: =資料儲存!J6373 -> 0 | S17: 12 | T17: =資料儲存!D6613 -> 0 | U17: =資料儲存!E6613 -> 0 | V17: =資料儲存!F6613 -> 0 | W17: =資料儲存!G6613 -> 0 | X17: =資料儲存!H6613 -> 0 | Y17: =資料儲存!I6613 -> 0 | Z17: =資料儲存!J6613 -> 0 | AB17: 12 | AC17: =資料儲存!D6853 -> 0 | AD17: =資料儲存!E6853 -> 0 | AE17: =資料儲存!F6853 -> 0 | AF17: =資料儲存!G6853 -> 0 | AG17: =資料儲存!H6853 -> 0 | AH17: =資料儲存!I6853 -> 0 | AI17: =資料儲存!J6853 -> 0 | AK17: 12 | AL17: =資料儲存!D7093 -> 0 | AM17: =資料儲存!E7093 -> 0 | AN17: =資料儲存!F7093 -> 0 | AO17: =資料儲存!G7093 -> 0 | AP17: =資料儲存!H7093 -> 0 | AQ17: =資料儲存!I7093 -> 0 | AR17: =資料儲存!J7093 -> 0 | AT17: 12 | AU17: =資料儲存!D7333 -> 0 | AV17: =資料儲存!E7333 -> 0 | AW17: =資料儲存!F7333 -> 0 | AX17: =資料儲存!G7333 -> 0 | AY17: =資料儲存!H7333 -> 0 | AZ17: =資料儲存!I7333 -> 0 | BA17: =資料儲存!J7333 -> 0
... A20: 15 | B20: =資料儲存!D6136 -> 0 | C20: =資料儲存!E6136 -> 0 | D20: =資料儲存!F6136 -> 0 | E20: =資料儲存!G6136 -> 0 | F20: =資料儲存!H6136 -> 0 | G20: =資料儲存!I6136 -> 0 | H20: =資料儲存!J6136 -> 0 | J20: 15 | K20: =資料儲存!D6376 -> 0 | L20: =資料儲存!E6376 -> 0 | M20: =資料儲存!F6376 -> 0 | N20: =資料儲存!G6376 -> 0 | O20: =資料儲存!H6376 -> 0 | P20: =資料儲存!I6376 -> 0 | Q20: =資料儲存!J6376 -> 0 | S20: 15 | T20: =資料儲存!D6616 -> 0 | U20: =資料儲存!E6616 -> 0 | V20: =資料儲存!F6616 -> 0 | W20: =資料儲存!G6616 -> 0 | X20: =資料儲存!H6616 -> 0 | Y20: =資料儲存!I6616 -> 0 | Z20: =資料儲存!J6616 -> 0 | AB20: 15 | AC20: =資料儲存!D6856 -> 0 | AD20: =資料儲存!E6856 -> 0 | AE20: =資料儲存!F6856 -> 0 | AF20: =資料儲存!G6856 -> 0 | AG20: =資料儲存!H6856 -> 0 | AH20: =資料儲存!I6856 -> 0 | AI20: =資料儲存!J6856 -> 0 | AK20: 15 | AL20: =資料儲存!D7096 -> 0 | AM20: =資料儲存!E7096 -> 0 | AN20: =資料儲存!F7096 -> 0 | AO20: =資料儲存!G7096 -> 0 | AP20: =資料儲存!H7096 -> 0 | AQ20: =資料儲存!I7096 -> 0 | AR20: =資料儲存!J7096 -> 0 | AT20: 15 | AU20: =資料儲存!D7336 -> 0 | AV20: =資料儲存!E7336 -> 0 | AW20: =資料儲存!F7336 -> 0 | AX20: =資料儲存!G7336 -> 0 | AY20: =資料儲存!H7336 -> 0 | AZ20: =資料儲存!I7336 -> 0 | BA20: =資料儲存!J7336 -> 0
A21: 總 計 | B21: =SUM(B6:E20) -> 0 | F21: =F20 -> 0 | G21: =G20 -> 0 | H21: =H20 -> 0 | J21: 總 計 | K21: =SUM(K6:N20) -> 0 | O21: =O20 -> 0 | P21: =P20 -> 0 | Q21: =Q20 -> 0 | S21: 總 計 | T21: =SUM(T6:W20) -> 0 | X21: =X20 -> 0 | Y21: =Y20 -> 0 | Z21: =Z20 -> 0 | AB21: 總 計 | AC21: =SUM(AC6:AF20) -> 0 | AG21: =AG20 -> 0 | AH21: =AH20 -> 0 | AI21: =AI20 -> 0 | AK21: 總 計 | AL21: =SUM(AL6:AO20) -> 0 | AP21: =AP20 -> 0 | AQ21: =AQ20 -> 0 | AR21: =AR20 -> 0 | AT21: 總 計 | AU21: =SUM(AU6:AX20) -> 0 | AY21: =AY20 -> 0 | AZ21: =AZ20 -> 0 | BA21: =BA20 -> 0
A22: 16:15~16:30 | J22: 16:15~16:30 | S22: 16:15~16:30 | AB22: 16:15~16:30 | AK22: 16:15~16:30 | AT22: 16:15~16:30
A23: 開始時刻 | B23: 停車在臨近車道上的車輛總數 | F23: 臨近車道上的流量 | J23: 開始時刻 | K23: 停車在臨近車道上的車輛總數 | O23: 臨近車道上的流量 | S23: 開始時刻 | T23: 停車在臨近車道上的車輛總數 | X23: 臨近車道上的流量 | AB23: 開始時刻 | AC23: 停車在臨近車道上的車輛總數 | AG23: 臨近車道上的流量 | AK23: 開始時刻 | AL23: 停車在臨近車道上的車輛總數 | AP23: 臨近車道上的流量 | AT23: 開始時刻 | AU23: 停車在臨近車道上的車輛總數 | AY23: 臨近車道上的流量
A24: 0.67708333 | B24: 0秒 | C24: 15秒 | D24: 30秒 | E24: 45秒 | F24: 總數 | G24: 未受阻 | H24: 受阻 | J24: 0.67708333 | K24: 0秒 | L24: 15秒 | M24: 30秒 | N24: 45秒 | O24: 總數 | P24: 未受阻 | Q24: 受阻 | S24: 0.67708333 | T24: 0秒 | U24: 15秒 | V24: 30秒 | W24: 45秒 | X24: 總數 | Y24: 未受阻 | Z24: 受阻 | AB24: 0.67708333 | AC24: 0秒 | AD24: 15秒 | AE24: 30秒 | AF24: 45秒 | AG24: 總數 | AH24: 未受阻 | AI24: 受阻 | AK24: 0.67708333 | AL24: 0秒 | AM24: 15秒 | AN24: 30秒 | AO24: 45秒 | AP24: 總數 | AQ24: 未受阻 | AR24: 受阻 | AT24: 0.67708333 | AU24: 0秒 | AV24: 15秒 | AW24: 30秒 | AX24: 45秒 | AY24: 總數 | AZ24: 未受阻 | BA24: 受阻
A25: 16 | B25: =資料儲存!D6137 -> 0 | C25: =資料儲存!E6137 -> 0 | D25: =資料儲存!F6137 -> 0 | E25: =資料儲存!G6137 -> 0 | F25: =資料儲存!H6137 -> 0 | G25: =資料儲存!I6137 -> 0 | H25: =資料儲存!J6137 -> 0 | J25: 16 | K25: =資料儲存!D6377 -> 0 | L25: =資料儲存!E6377 -> 0 | M25: =資料儲存!F6377 -> 0 | N25: =資料儲存!G6377 -> 0 | O25: =資料儲存!H6377 -> 0 | P25: =資料儲存!I6377 -> 0 | Q25: =資料儲存!J6377 -> 0 | S25: 16 | T25: =資料儲存!D6617 -> 0 | U25: =資料儲存!E6617 -> 0 | V25: =資料儲存!F6617 -> 0 | W25: =資料儲存!G6617 -> 0 | X25: =資料儲存!H6617 -> 0 | Y25: =資料儲存!I6617 -> 0 | Z25: =資料儲存!J6617 -> 0 | AB25: 16 | AC25: =資料儲存!D6857 -> 0 | AD25: =資料儲存!E6857 -> 0 | AE25: =資料儲存!F6857 -> 0 | AF25: =資料儲存!G6857 -> 0 | AG25: =資料儲存!H6857 -> 0 | AH25: =資料儲存!I6857 -> 0 | AI25: =資料儲存!J6857 -> 0 | AK25: 16 | AL25: =資料儲存!D7097 -> 0 | AM25: =資料儲存!E7097 -> 0 | AN25: =資料儲存!F7097 -> 0 | AO25: =資料儲存!G7097 -> 0 | AP25: =資料儲存!H7097 -> 0 | AQ25: =資料儲存!I7097 -> 0 | AR25: =資料儲存!J7097 -> 0 | AT25: 16 | AU25: =資料儲存!D7337 -> 0 | AV25: =資料儲存!E7337 -> 0 | AW25: =資料儲存!F7337 -> 0 | AX25: =資料儲存!G7337 -> 0 | AY25: =資料儲存!H7337 -> 0 | AZ25: =資料儲存!I7337 -> 0 | BA25: =資料儲存!J7337 -> 0
A26: 17 | B26: =資料儲存!D6138 -> 0 | C26: =資料儲存!E6138 -> 0 | D26: =資料儲存!F6138 -> 0 | E26: =資料儲存!G6138 -> 0 | F26: =資料儲存!H6138 -> 0 | G26: =資料儲存!I6138 -> 0 | H26: =資料儲存!J6138 -> 0 | J26: 17 | K26: =資料儲存!D6378 -> 0 | L26: =資料儲存!E6378 -> 0 | M26: =資料儲存!F6378 -> 0 | N26: =資料儲存!G6378 -> 0 | O26: =資料儲存!H6378 -> 0 | P26: =資料儲存!I6378 -> 0 | Q26: =資料儲存!J6378 -> 0 | S26: 17 | T26: =資料儲存!D6618 -> 0 | U26: =資料儲存!E6618 -> 0 | V26: =資料儲存!F6618 -> 0 | W26: =資料儲存!G6618 -> 0 | X26: =資料儲存!H6618 -> 0 | Y26: =資料儲存!I6618 -> 0 | Z26: =資料儲存!J6618 -> 0 | AB26: 17 | AC26: =資料儲存!D6858 -> 0 | AD26: =資料儲存!E6858 -> 0 | AE26: =資料儲存!F6858 -> 0 | AF26: =資料儲存!G6858 -> 0 | AG26: =資料儲存!H6858 -> 0 | AH26: =資料儲存!I6858 -> 0 | AI26: =資料儲存!J6858 -> 0 | AK26: 17 | AL26: =資料儲存!D7098 -> 0 | AM26: =資料儲存!E7098 -> 0 | AN26: =資料儲存!F7098 -> 0 | AO26: =資料儲存!G7098 -> 0 | AP26: =資料儲存!H7098 -> 0 | AQ26: =資料儲存!I7098 -> 0 | AR26: =資料儲存!J7098 -> 0 | AT26: 17 | AU26: =資料儲存!D7338 -> 0 | AV26: =資料儲存!E7338 -> 0 | AW26: =資料儲存!F7338 -> 0 | AX26: =資料儲存!G7338 -> 0 | AY26: =資料儲存!H7338 -> 0 | AZ26: =資料儲存!I7338 -> 0 | BA26: =資料儲存!J7338 -> 0
A27: 18 | B27: =資料儲存!D6139 -> 0 | C27: =資料儲存!E6139 -> 0 | D27: =資料儲存!F6139 -> 0 | E27: =資料儲存!G6139 -> 0 | F27: =資料儲存!H6139 -> 0 | G27: =資料儲存!I6139 -> 0 | H27: =資料儲存!J6139 -> 0 | J27: 18 | K27: =資料儲存!D6379 -> 0 | L27: =資料儲存!E6379 -> 0 | M27: =資料儲存!F6379 -> 0 | N27: =資料儲存!G6379 -> 0 | O27: =資料儲存!H6379 -> 0 | P27: =資料儲存!I6379 -> 0 | Q27: =資料儲存!J6379 -> 0 | S27: 18 | T27: =資料儲存!D6619 -> 0 | U27: =資料儲存!E6619 -> 0 | V27: =資料儲存!F6619 -> 0 | W27: =資料儲存!G6619 -> 0 | X27: =資料儲存!H6619 -> 0 | Y27: =資料儲存!I6619 -> 0 | Z27: =資料儲存!J6619 -> 0 | AB27: 18 | AC27: =資料儲存!D6859 -> 0 | AD27: =資料儲存!E6859 -> 0 | AE27: =資料儲存!F6859 -> 0 | AF27: =資料儲存!G6859 -> 0 | AG27: =資料儲存!H6859 -> 0 | AH27: =資料儲存!I6859 -> 0 | AI27: =資料儲存!J6859 -> 0 | AK27: 18 | AL27: =資料儲存!D7099 -> 0 | AM27: =資料儲存!E7099 -> 0 | AN27: =資料儲存!F7099 -> 0 | AO27: =資料儲存!G7099 -> 0 | AP27: =資料儲存!H7099 -> 0 | AQ27: =資料儲存!I7099 -> 0 | AR27: =資料儲存!J7099 -> 0 | AT27: 18 | AU27: =資料儲存!D7339 -> 0 | AV27: =資料儲存!E7339 -> 0 | AW27: =資料儲存!F7339 -> 0 | AX27: =資料儲存!G7339 -> 0 | AY27: =資料儲存!H7339 -> 0 | AZ27: =資料儲存!I7339 -> 0 | BA27: =資料儲存!J7339 -> 0
A28: 19 | B28: =資料儲存!D6140 -> 0 | C28: =資料儲存!E6140 -> 0 | D28: =資料儲存!F6140 -> 0 | E28: =資料儲存!G6140 -> 0 | F28: =資料儲存!H6140 -> 0 | G28: =資料儲存!I6140 -> 0 | H28: =資料儲存!J6140 -> 0 | J28: 19 | K28: =資料儲存!D6380 -> 0 | L28: =資料儲存!E6380 -> 0 | M28: =資料儲存!F6380 -> 0 | N28: =資料儲存!G6380 -> 0 | O28: =資料儲存!H6380 -> 0 | P28: =資料儲存!I6380 -> 0 | Q28: =資料儲存!J6380 -> 0 | S28: 19 | T28: =資料儲存!D6620 -> 0 | U28: =資料儲存!E6620 -> 0 | V28: =資料儲存!F6620 -> 0 | W28: =資料儲存!G6620 -> 0 | X28: =資料儲存!H6620 -> 0 | Y28: =資料儲存!I6620 -> 0 | Z28: =資料儲存!J6620 -> 0 | AB28: 19 | AC28: =資料儲存!D6860 -> 0 | AD28: =資料儲存!E6860 -> 0 | AE28: =資料儲存!F6860 -> 0 | AF28: =資料儲存!G6860 -> 0 | AG28: =資料儲存!H6860 -> 0 | AH28: =資料儲存!I6860 -> 0 | AI28: =資料儲存!J6860 -> 0 | AK28: 19 | AL28: =資料儲存!D7100 -> 0 | AM28: =資料儲存!E7100 -> 0 | AN28: =資料儲存!F7100 -> 0 | AO28: =資料儲存!G7100 -> 0 | AP28: =資料儲存!H7100 -> 0 | AQ28: =資料儲存!I7100 -> 0 | AR28: =資料儲存!J7100 -> 0 | AT28: 19 | AU28: =資料儲存!D7340 -> 0 | AV28: =資料儲存!E7340 -> 0 | AW28: =資料儲存!F7340 -> 0 | AX28: =資料儲存!G7340 -> 0 | AY28: =資料儲存!H7340 -> 0 | AZ28: =資料儲存!I7340 -> 0 | BA28: =資料儲存!J7340 -> 0
A29: 20 | B29: =資料儲存!D6141 -> 0 | C29: =資料儲存!E6141 -> 0 | D29: =資料儲存!F6141 -> 0 | E29: =資料儲存!G6141 -> 0 | F29: =資料儲存!H6141 -> 0 | G29: =資料儲存!I6141 -> 0 | H29: =資料儲存!J6141 -> 0 | J29: 20 | K29: =資料儲存!D6381 -> 0 | L29: =資料儲存!E6381 -> 0 | M29: =資料儲存!F6381 -> 0 | N29: =資料儲存!G6381 -> 0 | O29: =資料儲存!H6381 -> 0 | P29: =資料儲存!I6381 -> 0 | Q29: =資料儲存!J6381 -> 0 | S29: 20 | T29: =資料儲存!D6621 -> 0 | U29: =資料儲存!E6621 -> 0 | V29: =資料儲存!F6621 -> 0 | W29: =資料儲存!G6621 -> 0 | X29: =資料儲存!H6621 -> 0 | Y29: =資料儲存!I6621 -> 0 | Z29: =資料儲存!J6621 -> 0 | AB29: 20 | AC29: =資料儲存!D6861 -> 0 | AD29: =資料儲存!E6861 -> 0 | AE29: =資料儲存!F6861 -> 0 | AF29: =資料儲存!G6861 -> 0 | AG29: =資料儲存!H6861 -> 0 | AH29: =資料儲存!I6861 -> 0 | AI29: =資料儲存!J6861 -> 0 | AK29: 20 | AL29: =資料儲存!D7101 -> 0 | AM29: =資料儲存!E7101 -> 0 | AN29: =資料儲存!F7101 -> 0 | AO29: =資料儲存!G7101 -> 0 | AP29: =資料儲存!H7101 -> 0 | AQ29: =資料儲存!I7101 -> 0 | AR29: =資料儲存!J7101 -> 0 | AT29: 20 | AU29: =資料儲存!D7341 -> 0 | AV29: =資料儲存!E7341 -> 0 | AW29: =資料儲存!F7341 -> 0 | AX29: =資料儲存!G7341 -> 0 | AY29: =資料儲存!H7341 -> 0 | AZ29: =資料儲存!I7341 -> 0 | BA29: =資料儲存!J7341 -> 0
A30: 21 | B30: =資料儲存!D6142 -> 0 | C30: =資料儲存!E6142 -> 0 | D30: =資料儲存!F6142 -> 0 | E30: =資料儲存!G6142 -> 0 | F30: =資料儲存!H6142 -> 0 | G30: =資料儲存!I6142 -> 0 | H30: =資料儲存!J6142 -> 0 | J30: 21 | K30: =資料儲存!D6382 -> 0 | L30: =資料儲存!E6382 -> 0 | M30: =資料儲存!F6382 -> 0 | N30: =資料儲存!G6382 -> 0 | O30: =資料儲存!H6382 -> 0 | P30: =資料儲存!I6382 -> 0 | Q30: =資料儲存!J6382 -> 0 | S30: 21 | T30: =資料儲存!D6622 -> 0 | U30: =資料儲存!E6622 -> 0 | V30: =資料儲存!F6622 -> 0 | W30: =資料儲存!G6622 -> 0 | X30: =資料儲存!H6622 -> 0 | Y30: =資料儲存!I6622 -> 0 | Z30: =資料儲存!J6622 -> 0 | AB30: 21 | AC30: =資料儲存!D6862 -> 0 | AD30: =資料儲存!E6862 -> 0 | AE30: =資料儲存!F6862 -> 0 | AF30: =資料儲存!G6862 -> 0 | AG30: =資料儲存!H6862 -> 0 | AH30: =資料儲存!I6862 -> 0 | AI30: =資料儲存!J6862 -> 0 | AK30: 21 | AL30: =資料儲存!D7102 -> 0 | AM30: =資料儲存!E7102 -> 0 | AN30: =資料儲存!F7102 -> 0 | AO30: =資料儲存!G7102 -> 0 | AP30: =資料儲存!H7102 -> 0 | AQ30: =資料儲存!I7102 -> 0 | AR30: =資料儲存!J7102 -> 0 | AT30: 21 | AU30: =資料儲存!D7342 -> 0 | AV30: =資料儲存!E7342 -> 0 | AW30: =資料儲存!F7342 -> 0 | AX30: =資料儲存!G7342 -> 0 | AY30: =資料儲存!H7342 -> 0 | AZ30: =資料儲存!I7342 -> 0 | BA30: =資料儲存!J7342 -> 0
A31: 22 | B31: =資料儲存!D6143 -> 0 | C31: =資料儲存!E6143 -> 0 | D31: =資料儲存!F6143 -> 0 | E31: =資料儲存!G6143 -> 0 | F31: =資料儲存!H6143 -> 0 | G31: =資料儲存!I6143 -> 0 | H31: =資料儲存!J6143 -> 0 | J31: 22 | K31: =資料儲存!D6383 -> 0 | L31: =資料儲存!E6383 -> 0 | M31: =資料儲存!F6383 -> 0 | N31: =資料儲存!G6383 -> 0 | O31: =資料儲存!H6383 -> 0 | P31: =資料儲存!I6383 -> 0 | Q31: =資料儲存!J6383 -> 0 | S31: 22 | T31: =資料儲存!D6623 -> 0 | U31: =資料儲存!E6623 -> 0 | V31: =資料儲存!F6623 -> 0 | W31: =資料儲存!G6623 -> 0 | X31: =資料儲存!H6623 -> 0 | Y31: =資料儲存!I6623 -> 0 | Z31: =資料儲存!J6623 -> 0 | AB31: 22 | AC31: =資料儲存!D6863 -> 0 | AD31: =資料儲存!E6863 -> 0 | AE31: =資料儲存!F6863 -> 0 | AF31: =資料儲存!G6863 -> 0 | AG31: =資料儲存!H6863 -> 0 | AH31: =資料儲存!I6863 -> 0 | AI31: =資料儲存!J6863 -> 0 | AK31: 22 | AL31: =資料儲存!D7103 -> 0 | AM31: =資料儲存!E7103 -> 0 | AN31: =資料儲存!F7103 -> 0 | AO31: =資料儲存!G7103 -> 0 | AP31: =資料儲存!H7103 -> 0 | AQ31: =資料儲存!I7103 -> 0 | AR31: =資料儲存!J7103 -> 0 | AT31: 22 | AU31: =資料儲存!D7343 -> 0 | AV31: =資料儲存!E7343 -> 0 | AW31: =資料儲存!F7343 -> 0 | AX31: =資料儲存!G7343 -> 0 | AY31: =資料儲存!H7343 -> 0 | AZ31: =資料儲存!I7343 -> 0 | BA31: =資料儲存!J7343 -> 0
