Workbook

Sheet 資料儲存
A1: 時段 | B1: 臨近路段 | C1: 開始時刻 | D1: 停車在臨近車道上的車輛總數(0秒) | E1: 停車在臨近車道上的車輛總數(15秒) | F1: 停車在臨近車道上的車輛總數(30秒) | G1: 停車在臨近車道上的車輛總數(45秒) | H1: 臨近車道上的流量(總數) | I1: 臨近車道上的流量(未受阻) | J1: 臨近車道上的流量(受阻)
A2: 平日晨峰(0630-0830) | B2: A | C2: 0.27083333 | D2: 0 | E2: 0 | F2: 0 | G2: 0 | H2: 0 | I2: 0 | J2: 0
A3: 平日晨峰(0630-0830) | B3: A | C3: 0.27152778 | D3: 0 | E3: 0 | F3: 0 | G3: 0 | H3: 0 | I3: 0 | J3: 0
A4: 平日晨峰(0630-0830) | B4: A | C4: 0.27222222 | D4: 0 | E4: 0 | F4: 0 | G4: 0 | H4: 0 | I4: 0 | J4: 0
A5: 平日晨峰(0630-0830) | B5: A | C5: 0.27291667 | D5: 0 | E5: 0 | F5: 0 | G5: 0 | H5: 0 | I5: 0 | J5: 0
A6: 平日晨峰(0630-0830) | B6: A | C6: 0.27361111 | D6: 0 | E6: 0 | F6: 0 | G6: 0 | H6: 0 | I6: 0 | J6: 0
A7: 平日晨峰(0630-0830) | B7: A | C7: 0.27430556 | D7: 0 | E7: 0 | F7: 0 | G7: 0 | H7: 0 | I7: 0 | J7: 0
A8: 平日晨峰(0630-0830) | B8: A | C8: 0.275 | D8: 0 | E8: 0 | F8: 0 | G8: 0 | H8: 0 | I8: 0 | J8: 0
A9: 平日晨峰(0630-0830) | B9: A | C9: 0.27569444 | D9: 0 | E9: 0 | F9: 0 | G9: 0 | H9: 0 | I9: 0 | J9: 0
A10: 平日晨峰(0630-0830) | B10: A | C10: 0.27638889 | D10: 0 | E10: 0 | F10: 0 | G10: 0 | H10: 0 | I10: 0 | J10: 0
A11: 平日晨峰(0630-0830) | B11: A | C11: 0.27708333 | D11: 0 | E11: 0 | F11: 0 | G11: 0 | H11: 0 | I11: 0 | J11: 0
A12: 平日晨峰(0630-0830) | B12: A | C12: 0.27777778 | D12: 0 | E12: 0 | F12: 0 | G12: 0 | H12: 0 | I12: 0 | J12: 0
A13: 平日晨峰(0630-0830) | B13: A | C13: 0.27847222 | D13: 0 | E13: 0 | F13: 0 | G13: 0 | H13: 0 | I13: 0 | J13: 0
... A5041: 假日(16-20) | B5041: D | C5041: 0.83263889 | D5041: 0 | E5041: 0 | F5041: 0 | G5041: 0 | H5041: 0 | I5041: 0 | J5041: 0

Sheet 基本資料
A4: 業主名稱：
A5: 專案編號：
R6: 往北
A7: TC編號： | C7: (例：TC240) | R7: 往東
A8: 路口名稱： | R8: 往南
A9: 行政區域： | C9: (例：東區) | R9: 往西南
R10: 往西北
B11: 平日晨峰(0630-0830) | C11: 平日晨峰(07-09) | D11: 平日中午(11-13) | E11: 平日中午(12-14) | F11: 平日昏峰(17-19) | G11: 假日(11-12) | H11: 假日(1430-1530) | I11: 假日(1730-1830) | J11: 假日(16-18) | K11: 假日(17-19) | L11: 假日(16-20) | R11: 往東北
A12: 日期： | B12: YYYY/MM/DD | C12: YYYY/MM/DD | D12: YYYY/MM/DD | E12: YYYY/MM/DD | F12: YYYY/MM/DD | G12: YYYY/MM/DD | H12: YYYY/MM/DD | I12: YYYY/MM/DD | J12: YYYY/MM/DD | K12: YYYY/MM/DD | L12: YYYY/MM/DD | R12: 往東南
A13: 天候：
R14: 往西
A16: 路口類型： | B16: 六叉路口
A18: 方 向： | B18: A | C18: B | D18: C | E18: D
A19: 路段名：
A20: 行車方向：
A21: 車道數： | B21: - | C21: - | D21: - | E21: -
A25: 簡圖：
C26: =E19 -> 0
C27: D
A30: =D19 -> 0 | B30: C | D30: A | E30: =B19 -> 0
C33: B
C34: =C19 -> 0

Sheet 資料分析
B1: 平日晨峰(0630-0830) | I1: 平日晨峰(07-09) | P1: 平日中午(11-13) | W1: 平日中午(12-14) | AD1: 平日昏峰(17-19) | AK1: 假日(11-12) | AR1: 假日(1430~1530) | AY1: 假日(1730~1830) | BF1: 假日(16-18) | BM1: 假日(17-19) | BT1: 假日(16-20)
B2: ='平日晨峰(07-09)'!$A$2 -> A方向： | I2: ='平日晨峰(07-09)'!$A$2 -> A方向： | P2: ='平日中午(11-13)'!$A$2 -> A方向： | W2: ='平日中午(12-14)'!$A$2 -> A方向： | AD2: ='平日昏峰(17-19)'!$A$2 -> A方向： | AK2: ='假日(11-12)'!$A$2 -> A方向： | AR2: ='假日(1430-1530)'!$A$2 -> A方向： | AY2: ='假日(1730-1830)'!$A$2 -> A方向： | BF2: ='假日(16-18)'!$A$2 -> A方向： | BM2: ='假日(17-19)'!$A$2 -> A方向： | BT2: ='假日(16-18)'!$A$2 -> A方向：
B3: 時間 | C3: 平均延滯 | D3: 平均停等延滯 | E3: 總延滯 | F3: 車輛總數 | G3: 停等車輛數 | I3: 時間 | J3: 平均延滯 | L3: 總延滯 | M3: 車輛總數 | N3: 停等車輛數 | P3: 時間 | Q3: 平均延滯 | R3: 平均停等延滯 | S3: 總延滯 | T3: 車輛總數 | U3: 停等車輛數 | W3: 時間 | X3: 平均延滯 | Y3: 平均停等延滯 | Z3: 總延滯 | AA3: 車輛總數 | AB3: 停等車輛數 | AD3: 時間 | AE3: 平均延滯 | AF3: 平均停等延滯 | AG3: 總延滯 | AH3: 車輛總數 | AI3: 停等車輛數 | AK3: 時間 | AL3: 平均延滯 | AM3: 平均停等延滯 | AN3: 總延滯 | AO3: 車輛總數 | AP3: 停等車輛數 | AR3: 時間 | AS3: 平均延滯 | AT3: 平均停等延滯 | AU3: 總延滯 | AV3: 車輛總數 | AW3: 停等車輛數 | AY3: 時間 | AZ3: 平均延滯 | BA3: 平均停等延滯 | BB3: 總延滯 | BC3: 車輛總數 | BD3: 停等車輛數 | BF3: 時間 | BG3: 平均延滯 | BH3: 平均停等延滯 | BI3: 總延滯 | BJ3: 車輛總數 | BK3: 停等車輛數 | BM3: 時間 | BN3: 平均延滯 | BO3: 平均停等延滯 | BP3: 總延滯 | BQ3: 車輛總數 | BR3: 停等車輛數 | BT3: 時間 | BU3: 平均延滯 | BV3: 平均停等延滯 | BW3: 總延滯 | BX3: 車輛總數 | BY3: 停等車輛數
B4: 06:30~07:30 | C4: =IF(ISERROR($E4/F4),"-",$E4/F4) -> - | D4: =IF(ISERROR($E4/G4),"-",$E4/G4) -> - | E4: =('平日晨峰(0630-0830)'!$B$21+'平日晨峰(0630-0830)'!$B$40+'平日晨峰(0630-0830)'!$B$59+'平日晨峰(0630-0830)'!$B$78)*15 -> 0 | F4: ='平日晨峰(0630-0830)'!$F$21+'平日晨峰(0630-0830)'!$F$40+'平日晨峰(0630-0830)'!$F$59+'平日晨峰(0630-0830)'!$F$78 -> 0 | G4: ='平日晨峰(0630-0830)'!$H$21+'平日晨峰(0630-0830)'!$H$40+'平日晨峰(0630-0830)'!$H$59+'平日晨峰(0630-0830)'!$H$78 -> 0 | I4: 07:00~08:00 | J4: =IF(ISERROR($L4/M4),"-",$L4/M4) -> - | K4: =IF(ISERROR($L4/N4),"-",$L4/N4) -> - | L4: =('平日晨峰(07-09)'!$B$21+'平日晨峰(07-09)'!$B$40+'平日晨峰(07-09)'!$B$59+'平日晨峰(07-09)'!$B$78)*15 -> 0 | M4: ='平日晨峰(07-09)'!$F$21+'平日晨峰(07-09)'!$F$40+'平日晨峰(07-09)'!$F$59+'平日晨峰(07-09)'!$F$78 -> 0 | N4: ='平日晨峰(07-09)'!$H$21+'平日晨峰(07-09)'!$H$40+'平日晨峰(07-09)'!$H$59+'平日晨峰(07-09)'!$H$78 -> 0 | P4: 11:00~12:00 | Q4: =IF(ISERROR($S4/T4),"-",$S4/T4) -> - | R4: =IF(ISERROR($T4/U4),"-",$T4/U4) -> - | S4: =('平日中午(11-13)'!$B$21+'平日中午(11-13)'!$B$40+'平日中午(11-13)'!$B$59+'平日中午(11-13)'!$B$78)*15 -> 0 | T4: ='平日中午(11-13)'!$F$21+'平日中午(11-13)'!$F$40+'平日中午(11-13)'!$F$59+'平日中午(11-13)'!$F$78 -> 0 | U4: ='平日中午(11-13)'!$H$21+'平日中午(11-13)'!$H$40+'平日中午(11-13)'!$H$59+'平日中午(11-13)'!$H$78 -> 0 | W4: 1200~13:00 | X4: =IF(ISERROR($Z4/AA4),"-",$Z4/AA4) -> - | Y4: =IF(ISERROR($Z4/AB4),"-",$Z4/AB4) -> - | Z4: =('平日中午(12-14)'!$B$21+'平日中午(12-14)'!$B$40+'平日中午(12-14)'!$B$59+'平日中午(12-14)'!$B$78)*15 -> 0 | AA4: ='平日中午(12-14)'!$F$21+'平日中午(12-14)'!$F$40+'平日中午(12-14)'!$F$59+'平日中午(12-14)'!$F$78 -> 0 | AB4: ='平日中午(12-14)'!$H$21+'平日中午(12-14)'!$H$40+'平日中午(12-14)'!$H$59+'平日中午(12-14)'!$H$78 -> 0 | AD4: 17:00~18:00 | AE4: =IF(ISERROR($AG4/AH4),"-",$AG4/AH4) -> - | AF4: =IF(ISERROR($AG4/AI4),"-",$AG4/AI4) -> - | AG4: =('平日昏峰(17-19)'!$B$21+'平日昏峰(17-19)'!$B$40+'平日昏峰(17-19)'!$B$59+'平日昏峰(17-19)'!$B$78)*15 -> 0 | AH4: ='平日昏峰(17-19)'!$F$21+'平日昏峰(17-19)'!$F$40+'平日昏峰(17-19)'!$F$59+'平日昏峰(17-19)'!$F$78 -> 0 | AI4: ='平日昏峰(17-19)'!$H$21+'平日昏峰(17-19)'!$H$40+'平日昏峰(17-19)'!$H$59+'平日昏峰(17-19)'!$H$78 -> 0 | AK4: 11:00~12:00 | AL4: =IF(ISERROR($AN4/AO4),"-",$AN4/AO4) -> - | AM4: =IF(ISERROR($AN4/AP4),"-",$AN4/AP4) -> - | AN4: =('假日(11-12)'!$B$21+'假日(11-12)'!$B$40+'假日(11-12)'!$B$59+'假日(11-12)'!$B$78)*15 -> 0 | AO4: ='假日(11-12)'!$F$21+'假日(11-12)'!$F$40+'假日(11-12)'!$F$59+'假日(11-12)'!$F$78 -> 0 | AP4: ='假日(11-12)'!$H$21+'假日(11-12)'!$H$40+'假日(11-12)'!$H$59+'假日(11-12)'!$H$78 -> 0 | AR4: 14:30~15:30 | AS4: =IF(ISERROR($AU4/AV4),"-",$AU4/AV4) -> - | AT4: =IF(ISERROR($AU4/AW4),"-",$AU4/AW4) -> - | AU4: =('假日(1430-1530)'!$B$21+'假日(1430-1530)'!$B$40+'假日(1430-1530)'!$B$59+'假日(1430-1530)'!$B$78)*15 -> 0 | AV4: ='假日(1430-1530)'!$F$21+'假日(1430-1530)'!$F$40+'假日(1430-1530)'!$F$59+'假日(1430-1530)'!$F$78 -> 0 | AW4: ='假日(1430-1530)'!$H$21+'假日(1430-1530)'!$H$40+'假日(1430-1530)'!$H$59+'假日(1430-1530)'!$H$78 -> 0 | AY4: 17:30~18:30 | AZ4: =IF(ISERROR($BB4/BC4),"-",$BB4/BC4) -> - | BA4: =IF(ISERROR($BB4/BD4),"-",$BB4/BD4) -> - | BB4: =('假日(1730-1830)'!$B$21+'假日(1730-1830)'!$B$40+'假日(1730-1830)'!$B$59+'假日(1730-1830)'!$B$78)*15 -> 0 | BC4: ='假日(1730-1830)'!$F$21+'假日(1730-1830)'!$F$40+'假日(1730-1830)'!$F$59+'假日(1730-1830)'!$F$78 -> 0 | BD4: ='假日(1730-1830)'!$H$21+'假日(1730-1830)'!$H$40+'假日(1730-1830)'!$H$59+'假日(1730-1830)'!$H$78 -> 0 | BF4: 16:00~17:00 | BG4: =IF(ISERROR($BI4/BJ4),"-",$BI4/BJ4) -> - | BH4: =IF(ISERROR($BI4/BK4),"-",$BI4/BK4) -> - | BI4: =('假日(16-18)'!$B$21+'假日(16-18)'!$B$40+'假日(16-18)'!$B$59+'假日(16-18)'!$B$78)*15 -> 0 | BJ4: ='假日(16-18)'!$F$21+'假日(16-18)'!$F$40+'假日(16-18)'!$F$59+'假日(16-18)'!$F$78 -> 0 | BK4: ='假日(16-18)'!$H$21+'假日(16-18)'!$H$40+'假日(16-18)'!$H$59+'假日(16-18)'!$H$78 -> 0 | BM4: 17:00~18:00 | BN4: =IF(ISERROR($BP4/BQ4),"-",$BP4/BQ4) -> - | BO4: =IF(ISERROR($BP4/BR4),"-",$BP4/BR4) -> - | BP4: =('假日(17-19)'!$B$21+'假日(17-19)'!$B$40+'假日(17-19)'!$B$59+'假日(17-19)'!$B$78)*15 -> 0 | BQ4: ='假日(17-19)'!$F$21+'假日(17-19)'!$F$40+'假日(17-19)'!$F$59+'假日(17-19)'!$F$78 -> 0 | BR4: ='假日(17-19)'!$H$21+'假日(17-19)'!$H$40+'假日(17-19)'!$H$59+'假日(17-19)'!$H$78 -> 0 | BT4: 16:00~17:00 | BU4: =IF(ISERROR($BW4/BX4),"-",$BW4/BX4) -> - | BV4: =IF(ISERROR($BW4/BY4),"-",$BW4/BY4) -> - | BW4: =('假日(16-20)'!$B$21+'假日(16-20)'!$B$40+'假日(16-20)'!$B$59+'假日(16-20)'!$B$78)*15 -> 0 | BX4: ='假日(16-20)'!$F$21+'假日(16-20)'!$F$40+'假日(16-20)'!$F$59+'假日(16-20)'!$F$78 -> 0 | BY4: ='假日(16-20)'!$H$21+'假日(16-20)'!$H$40+'假日(16-20)'!$H$59+'假日(16-20)'!$H$78 -> 0
B5: 06:45~07:45 | C5: =IF(ISERROR($E5/F5),"-",$E5/F5) -> - | D5: =IF(ISERROR($E5/G5),"-",$E5/G5) -> - | E5: =('平日晨峰(0630-0830)'!$B$40+'平日晨峰(0630-0830)'!$B$59+'平日晨峰(0630-0830)'!$B$78+'平日晨峰(0630-0830)'!$B$97)*15 -> 0 | F5: ='平日晨峰(0630-0830)'!$F$40+'平日晨峰(0630-0830)'!$F$59+'平日晨峰(0630-0830)'!$F$78+'平日晨峰(0630-0830)'!$F$97 -> 0 | G5: ='平日晨峰(0630-0830)'!$H$40+'平日晨峰(0630-0830)'!$H$59+'平日晨峰(0630-0830)'!$H$78+'平日晨峰(0630-0830)'!$H$97 -> 0 | I5: 07:15~08:15 | J5: =IF(ISERROR($L5/M5),"-",$L5/M5) -> - | K5: =IF(ISERROR($L5/N5),"-",$L5/N5) -> - | L5: =('平日晨峰(07-09)'!$B$40+'平日晨峰(07-09)'!$B$59+'平日晨峰(07-09)'!$B$78+'平日晨峰(07-09)'!$B$97)*15 -> 0 | M5: ='平日晨峰(07-09)'!$F$40+'平日晨峰(07-09)'!$F$59+'平日晨峰(07-09)'!$F$78+'平日晨峰(07-09)'!$F$97 -> 0 | N5: ='平日晨峰(07-09)'!$H$40+'平日晨峰(07-09)'!$H$59+'平日晨峰(07-09)'!$H$78+'平日晨峰(07-09)'!$H$97 -> 0 | P5: 11:15~12:15 | Q5: =IF(ISERROR($S5/T5),"-",$S5/T5) -> - | R5: =IF(ISERROR($T5/U5),"-",$T5/U5) -> - | S5: =('平日中午(11-13)'!$B$40+'平日中午(11-13)'!$B$59+'平日中午(11-13)'!$B$78+'平日中午(11-13)'!$B$97)*15 -> 0 | T5: ='平日中午(11-13)'!$F$40+'平日中午(11-13)'!$F$59+'平日中午(11-13)'!$F$78+'平日中午(11-13)'!$F$97 -> 0 | U5: ='平日中午(11-13)'!$H$40+'平日中午(11-13)'!$H$59+'平日中午(11-13)'!$H$78+'平日中午(11-13)'!$H$97 -> 0 | W5: 12:15~13:15 | X5: =IF(ISERROR($Z5/AA5),"-",$Z5/AA5) -> - | Y5: =IF(ISERROR($Z5/AB5),"-",$Z5/AB5) -> - | Z5: =('平日中午(12-14)'!$B$40+'平日中午(12-14)'!$B$59+'平日中午(12-14)'!$B$78+'平日中午(12-14)'!$B$97)*15 -> 0 | AA5: ='平日中午(12-14)'!$F$40+'平日中午(12-14)'!$F$59+'平日中午(12-14)'!$F$78+'平日中午(12-14)'!$F$97 -> 0 | AB5: ='平日中午(12-14)'!$H$40+'平日中午(12-14)'!$H$59+'平日中午(12-14)'!$H$78+'平日中午(12-14)'!$H$97 -> 0 | AD5: 17:15~18:15 | AE5: =IF(ISERROR($AG5/AH5),"-",$AG5/AH5) -> - | AF5: =IF(ISERROR($AG5/AI5),"-",$AG5/AI5) -> - | AG5: =('平日昏峰(17-19)'!$B$40+'平日昏峰(17-19)'!$B$59+'平日昏峰(17-19)'!$B$78+'平日昏峰(17-19)'!$B$97)*15 -> 0 | AH5: ='平日昏峰(17-19)'!$F$40+'平日昏峰(17-19)'!$F$59+'平日昏峰(17-19)'!$F$78+'平日昏峰(17-19)'!$F$97 -> 0 | AI5: ='平日昏峰(17-19)'!$H$40+'平日昏峰(17-19)'!$H$59+'平日昏峰(17-19)'!$H$78+'平日昏峰(17-19)'!$H$97 -> 0 | AL5: =IF(ISERROR($AN5/AO5),"-",$AN5/AO5) -> - | AM5: =IF(ISERROR($AN5/AP5),"-",$AN5/AP5) -> - | AS5: =IF(ISERROR($AU5/AV5),"-",$AU5/AV5) -> - | AT5: =IF(ISERROR($AU5/AW5),"-",$AU5/AW5) -> - | AZ5: =IF(ISERROR($BB5/BC5),"-",$BB5/BC5) -> - | BA5: =IF(ISERROR($BB5/BD5),"-",$BB5/BD5) -> - | BF5: 16:15~17:15 | BG5: =IF(ISERROR($BI5/BJ5),"-",$BI5/BJ5) -> - | BH5: =IF(ISERROR($BI5/BK5),"-",$BI5/BK5) -> - | BI5: =('假日(16-18)'!$B$40+'假日(16-18)'!$B$59+'假日(16-18)'!$B$78+'假日(16-18)'!$B$97)*15 -> 0 | BJ5: ='假日(16-18)'!$F$40+'假日(16-18)'!$F$59+'假日(16-18)'!$F$78+'假日(16-18)'!$F$97 -> 0 | BK5: ='假日(16-18)'!$H$40+'假日(16-18)'!$H$59+'假日(16-18)'!$H$78+'假日(16-18)'!$H$97 -> 0 | BM5: 17:15~18:15 | BN5: =IF(ISERROR($BP5/BQ5),"-",$BP5/BQ5) -> - | BO5: =IF(ISERROR($BP5/BR5),"-",$BP5/BR5) -> - | BP5: =('假日(17-19)'!$B$40+'假日(17-19)'!$B$59+'假日(17-19)'!$B$78+'假日(17-19)'!$B$97)*15 -> 0 | BQ5: ='假日(17-19)'!$F$40+'假日(17-19)'!$F$59+'假日(17-19)'!$F$78+'假日(17-19)'!$F$97 -> 0 | BR5: ='假日(17-19)'!$H$40+'假日(17-19)'!$H$59+'假日(17-19)'!$H$78+'假日(17-19)'!$H$97 -> 0 | BT5: 16:15~17:15 | BU5: =IF(ISERROR($BW5/BX5),"-",$BW5/BX5) -> - | BV5: =IF(ISERROR($BW5/BY5),"-",$BW5/BY5) -> - | BW5: =('假日(16-20)'!$B$40+'假日(16-20)'!$B$59+'假日(16-20)'!$B$78+'假日(16-20)'!$B$97)*15 -> 0 | BX5: ='假日(16-20)'!$F$40+'假日(16-20)'!$F$59+'假日(16-20)'!$F$78+'假日(16-20)'!$F$97 -> 0 | BY5: ='假日(16-20)'!$H$40+'假日(16-20)'!$H$59+'假日(16-20)'!$H$78+'假日(16-20)'!$H$97 -> 0
B6: 07:00~08:00 | C6: =IF(ISERROR($E6/F6),"-",$E6/F6) -> - | D6: =IF(ISERROR($E6/G6),"-",$E6/G6) -> - | E6: =('平日晨峰(0630-0830)'!$B$59+'平日晨峰(0630-0830)'!$B$78+'平日晨峰(0630-0830)'!$B$97+'平日晨峰(0630-0830)'!$B$116)*15 -> 0 | F6: ='平日晨峰(0630-0830)'!$F$59+'平日晨峰(0630-0830)'!$F$78+'平日晨峰(0630-0830)'!$F$97+'平日晨峰(0630-0830)'!$F$116 -> 0 | G6: ='平日晨峰(0630-0830)'!$H$59+'平日晨峰(0630-0830)'!$H$78+'平日晨峰(0630-0830)'!$H$97+'平日晨峰(0630-0830)'!$H$116 -> 0 | I6: 07:30~08:30 | J6: =IF(ISERROR($L6/M6),"-",$L6/M6) -> - | K6: =IF(ISERROR($L6/N6),"-",$L6/N6) -> - | L6: =('平日晨峰(07-09)'!$B$59+'平日晨峰(07-09)'!$B$78+'平日晨峰(07-09)'!$B$97+'平日晨峰(07-09)'!$B$116)*15 -> 0 | M6: ='平日晨峰(07-09)'!$F$59+'平日晨峰(07-09)'!$F$78+'平日晨峰(07-09)'!$F$97+'平日晨峰(07-09)'!$F$116 -> 0 | N6: ='平日晨峰(07-09)'!$H$59+'平日晨峰(07-09)'!$H$78+'平日晨峰(07-09)'!$H$97+'平日晨峰(07-09)'!$H$116 -> 0 | P6: 11:30~12:30 | Q6: =IF(ISERROR($S6/T6),"-",$S6/T6) -> - | R6: =IF(ISERROR($T6/U6),"-",$T6/U6) -> - | S6: =('平日中午(11-13)'!$B$59+'平日中午(11-13)'!$B$78+'平日中午(11-13)'!$B$97+'平日中午(11-13)'!$B$116)*15 -> 0 | T6: ='平日中午(11-13)'!$F$59+'平日中午(11-13)'!$F$78+'平日中午(11-13)'!$F$97+'平日中午(11-13)'!$F$116 -> 0 | U6: ='平日中午(11-13)'!$H$59+'平日中午(11-13)'!$H$78+'平日中午(11-13)'!$H$97+'平日中午(11-13)'!$H$116 -> 0 | W6: 12:30~13:30 | X6: =IF(ISERROR($Z6/AA6),"-",$Z6/AA6) -> - | Y6: =IF(ISERROR($Z6/AB6),"-",$Z6/AB6) -> - | Z6: =('平日中午(12-14)'!$B$59+'平日中午(12-14)'!$B$78+'平日中午(12-14)'!$B$97+'平日中午(12-14)'!$B$116)*15 -> 0 | AA6: ='平日中午(12-14)'!$F$59+'平日中午(12-14)'!$F$78+'平日中午(12-14)'!$F$97+'平日中午(12-14)'!$F$116 -> 0 | AB6: ='平日中午(12-14)'!$H$59+'平日中午(12-14)'!$H$78+'平日中午(12-14)'!$H$97+'平日中午(12-14)'!$H$116 -> 0 | AD6: 17:30~18:30 | AE6: =IF(ISERROR($AG6/AH6),"-",$AG6/AH6) -> - | AF6: =IF(ISERROR($AG6/AI6),"-",$AG6/AI6) -> - | AG6: =('平日昏峰(17-19)'!$B$59+'平日昏峰(17-19)'!$B$78+'平日昏峰(17-19)'!$B$97+'平日昏峰(17-19)'!$B$116)*15 -> 0 | AH6: ='平日昏峰(17-19)'!$F$59+'平日昏峰(17-19)'!$F$78+'平日昏峰(17-19)'!$F$97+'平日昏峰(17-19)'!$F$116 -> 0 | AI6: ='平日昏峰(17-19)'!$H$59+'平日昏峰(17-19)'!$H$78+'平日昏峰(17-19)'!$H$97+'平日昏峰(17-19)'!$H$116 -> 0 | AL6: =IF(ISERROR($AN6/AO6),"-",$AN6/AO6) -> - | AM6: =IF(ISERROR($AN6/AP6),"-",$AN6/AP6) -> - | AS6: =IF(ISERROR($AU6/AV6),"-",$AU6/AV6) -> - | AT6: =IF(ISERROR($AU6/AW6),"-",$AU6/AW6) -> - | AZ6: =IF(ISERROR($BB6/BC6),"-",$BB6/BC6) -> - | BA6: =IF(ISERROR($BB6/BD6),"-",$BB6/BD6) -> - | BF6: 16:30~17:30 | BG6: =IF(ISERROR($BI6/BJ6),"-",$BI6/BJ6) -> - | BH6: =IF(ISERROR($BI6/BK6),"-",$BI6/BK6) -> - | BI6: =('假日(16-18)'!$B$59+'假日(16-18)'!$B$78+'假日(16-18)'!$B$97+'假日(16-18)'!$B$116)*15 -> 0 | BJ6: ='假日(16-18)'!$F$59+'假日(16-18)'!$F$78+'假日(16-18)'!$F$97+'假日(16-18)'!$F$116 -> 0 | BK6: ='假日(16-18)'!$H$59+'假日(16-18)'!$H$78+'假日(16-18)'!$H$97+'假日(16-18)'!$H$116 -> 0 | BM6: 17:30~18:30 | BN6: =IF(ISERROR($BP6/BQ6),"-",$BP6/BQ6) -> - | BO6: =IF(ISERROR($BP6/BR6),"-",$BP6/BR6) -> - | BP6: =('假日(17-19)'!$B$59+'假日(17-19)'!$B$78+'假日(17-19)'!$B$97+'假日(17-19)'!$B$116)*15 -> 0 | BQ6: ='假日(17-19)'!$F$59+'假日(17-19)'!$F$78+'假日(17-19)'!$F$97+'假日(17-19)'!$F$116 -> 0 | BR6: ='假日(17-19)'!$H$59+'假日(17-19)'!$H$78+'假日(17-19)'!$H$97+'假日(17-19)'!$H$116 -> 0 | BT6: 16:30~17:30 | BU6: =IF(ISERROR($BW6/BX6),"-",$BW6/BX6) -> - | BV6: =IF(ISERROR($BW6/BY6),"-",$BW6/BY6) -> - | BW6: =('假日(16-20)'!$B$59+'假日(16-20)'!$B$78+'假日(16-20)'!$B$97+'假日(16-20)'!$B$116)*15 -> 0 | BX6: ='假日(16-20)'!$F$59+'假日(16-20)'!$F$78+'假日(16-20)'!$F$97+'假日(16-20)'!$F$116 -> 0 | BY6: ='假日(16-20)'!$H$59+'假日(16-20)'!$H$78+'假日(16-20)'!$H$97+'假日(16-20)'!$H$116 -> 0
B7: 07:15~08:15 | C7: =IF(ISERROR($E7/F7),"-",$E7/F7) -> - | D7: =IF(ISERROR($E7/G7),"-",$E7/G7) -> - | E7: =('平日晨峰(0630-0830)'!$B$78+'平日晨峰(0630-0830)'!$B$97+'平日晨峰(0630-0830)'!$B$116+'平日晨峰(0630-0830)'!$B$135)*15 -> 0 | F7: ='平日晨峰(0630-0830)'!$F$78+'平日晨峰(0630-0830)'!$F$97+'平日晨峰(0630-0830)'!$F$116+'平日晨峰(0630-0830)'!$F$135 -> 0 | G7: ='平日晨峰(0630-0830)'!$H$78+'平日晨峰(0630-0830)'!$H$97+'平日晨峰(0630-0830)'!$H$116+'平日晨峰(0630-0830)'!$H$135 -> 0 | I7: 07:45~08:45 | J7: =IF(ISERROR($L7/M7),"-",$L7/M7) -> - | K7: =IF(ISERROR($L7/N7),"-",$L7/N7) -> - | L7: =('平日晨峰(07-09)'!$B$78+'平日晨峰(07-09)'!$B$97+'平日晨峰(07-09)'!$B$116+'平日晨峰(07-09)'!$B$135)*15 -> 0 | M7: ='平日晨峰(07-09)'!$F$78+'平日晨峰(07-09)'!$F$97+'平日晨峰(07-09)'!$F$116+'平日晨峰(07-09)'!$F$135 -> 0 | N7: ='平日晨峰(07-09)'!$H$78+'平日晨峰(07-09)'!$H$97+'平日晨峰(07-09)'!$H$116+'平日晨峰(07-09)'!$H$135 -> 0 | P7: 11:45~12:45 | Q7: =IF(ISERROR($S7/T7),"-",$S7/T7) -> - | R7: =IF(ISERROR($T7/U7),"-",$T7/U7) -> - | S7: =('平日中午(11-13)'!$B$78+'平日中午(11-13)'!$B$97+'平日中午(11-13)'!$B$116+'平日中午(11-13)'!$B$135)*15 -> 0 | T7: ='平日中午(11-13)'!$F$78+'平日中午(11-13)'!$F$97+'平日中午(11-13)'!$F$116+'平日中午(11-13)'!$F$135 -> 0 | U7: ='平日中午(11-13)'!$H$78+'平日中午(11-13)'!$H$97+'平日中午(11-13)'!$H$116+'平日中午(11-13)'!$H$135 -> 0 | W7: 12:45~13:45 | X7: =IF(ISERROR($Z7/AA7),"-",$Z7/AA7) -> - | Y7: =IF(ISERROR($Z7/AB7),"-",$Z7/AB7) -> - | Z7: =('平日中午(12-14)'!$B$78+'平日中午(12-14)'!$B$97+'平日中午(12-14)'!$B$116+'平日中午(12-14)'!$B$135)*15 -> 0 | AA7: ='平日中午(12-14)'!$F$78+'平日中午(12-14)'!$F$97+'平日中午(12-14)'!$F$116+'平日中午(12-14)'!$F$135 -> 0 | AB7: ='平日中午(12-14)'!$H$78+'平日中午(12-14)'!$H$97+'平日中午(12-14)'!$H$116+'平日中午(12-14)'!$H$135 -> 0 | AD7: 17:45~18:45 | AE7: =IF(ISERROR($AG7/AH7),"-",$AG7/AH7) -> - | AF7: =IF(ISERROR($AG7/AI7),"-",$AG7/AI7) -> - | AG7: =('平日昏峰(17-19)'!$B$78+'平日昏峰(17-19)'!$B$97+'平日昏峰(17-19)'!$B$116+'平日昏峰(17-19)'!$B$135)*15 -> 0 | AH7: ='平日昏峰(17-19)'!$F$78+'平日昏峰(17-19)'!$F$97+'平日昏峰(17-19)'!$F$116+'平日昏峰(17-19)'!$F$135 -> 0 | AI7: ='平日昏峰(17-19)'!$H$78+'平日昏峰(17-19)'!$H$97+'平日昏峰(17-19)'!$H$116+'平日昏峰(17-19)'!$H$135 -> 0 | AL7: =IF(ISERROR($AN7/AO7),"-",$AN7/AO7) -> - | AM7: =IF(ISERROR($AN7/AP7),"-",$AN7/AP7) -> - | AS7: =IF(ISERROR($AU7/AV7),"-",$AU7/AV7) -> - | AT7: =IF(ISERROR($AU7/AW7),"-",$AU7/AW7) -> - | AZ7: =IF(ISERROR($BB7/BC7),"-",$BB7/BC7) -> - | BA7: =IF(ISERROR($BB7/BD7),"-",$BB7/BD7) -> - | BF7: 16:45~17:45 | BG7: =IF(ISERROR($BI7/BJ7),"-",$BI7/BJ7) -> - | BH7: =IF(ISERROR($BI7/BK7),"-",$BI7/BK7) -> - | BI7: =('假日(16-18)'!$B$78+'假日(16-18)'!$B$97+'假日(16-18)'!$B$116+'假日(16-18)'!$B$135)*15 -> 0 | BJ7: ='假日(16-18)'!$F$78+'假日(16-18)'!$F$97+'假日(16-18)'!$F$116+'假日(16-18)'!$F$135 -> 0 | BK7: ='假日(16-18)'!$H$78+'假日(16-18)'!$H$97+'假日(16-18)'!$H$116+'假日(16-18)'!$H$135 -> 0 | BM7: 17:45~18:45 | BN7: =IF(ISERROR($BP7/BQ7),"-",$BP7/BQ7) -> - | BO7: =IF(ISERROR($BP7/BR7),"-",$BP7/BR7) -> - | BP7: =('假日(17-19)'!$B$78+'假日(17-19)'!$B$97+'假日(17-19)'!$B$116+'假日(17-19)'!$B$135)*15 -> 0 | BQ7: ='假日(17-19)'!$F$78+'假日(17-19)'!$F$97+'假日(17-19)'!$F$116+'假日(17-19)'!$F$135 -> 0 | BR7: ='假日(17-19)'!$H$78+'假日(17-19)'!$H$97+'假日(17-19)'!$H$116+'假日(17-19)'!$H$135 -> 0 | BT7: 16:45~17:45 | BU7: =IF(ISERROR($BW7/BX7),"-",$BW7/BX7) -> - | BV7: =IF(ISERROR($BW7/BY7),"-",$BW7/BY7) -> - | BW7: =('假日(16-20)'!$B$78+'假日(16-20)'!$B$97+'假日(16-20)'!$B$116+'假日(16-20)'!$B$135)*15 -> 0 | BX7: ='假日(16-20)'!$F$78+'假日(16-20)'!$F$97+'假日(16-20)'!$F$116+'假日(16-20)'!$F$135 -> 0 | BY7: ='假日(16-20)'!$H$78+'假日(16-20)'!$H$97+'假日(16-20)'!$H$116+'假日(16-20)'!$H$135 -> 0
B8: 07:30~08:30 | C8: =IF(ISERROR($E8/F8),"-",$E8/F8) -> - | D8: =IF(ISERROR($E8/G8),"-",$E8/G8) -> - | E8: =('平日晨峰(0630-0830)'!$B$97+'平日晨峰(0630-0830)'!$B$116+'平日晨峰(0630-0830)'!$B$135+'平日晨峰(0630-0830)'!$B$154)*15 -> 0 | F8: ='平日晨峰(0630-0830)'!$F$97+'平日晨峰(0630-0830)'!$F$116+'平日晨峰(0630-0830)'!$F$135+'平日晨峰(0630-0830)'!$F$154 -> 0 | G8: ='平日晨峰(0630-0830)'!$H$97+'平日晨峰(0630-0830)'!$H$116+'平日晨峰(0630-0830)'!$H$135+'平日晨峰(0630-0830)'!$H$154 -> 0 | I8: 08:00~09:00 | J8: =IF(ISERROR($L8/M8),"-",$L8/M8) -> - | K8: =IF(ISERROR($L8/N8),"-",$L8/N8) -> - | L8: =('平日晨峰(07-09)'!$B$97+'平日晨峰(07-09)'!$B$116+'平日晨峰(07-09)'!$B$135+'平日晨峰(07-09)'!$B$154)*15 -> 0 | M8: ='平日晨峰(07-09)'!$F$97+'平日晨峰(07-09)'!$F$116+'平日晨峰(07-09)'!$F$135+'平日晨峰(07-09)'!$F$154 -> 0 | N8: ='平日晨峰(07-09)'!$H$97+'平日晨峰(07-09)'!$H$116+'平日晨峰(07-09)'!$H$135+'平日晨峰(07-09)'!$H$154 -> 0 | P8: 12:00~13:00 | Q8: =IF(ISERROR($S8/T8),"-",$S8/T8) -> - | R8: =IF(ISERROR($T8/U8),"-",$T8/U8) -> - | S8: =('平日中午(11-13)'!$B$97+'平日中午(11-13)'!$B$116+'平日中午(11-13)'!$B$135+'平日中午(11-13)'!$B$154)*15 -> 0 | T8: ='平日中午(11-13)'!$F$97+'平日中午(11-13)'!$F$116+'平日中午(11-13)'!$F$135+'平日中午(11-13)'!$F$154 -> 0 | U8: ='平日中午(11-13)'!$H$97+'平日中午(11-13)'!$H$116+'平日中午(11-13)'!$H$135+'平日中午(11-13)'!$H$154 -> 0 | W8: 13:00~14:00 | X8: =IF(ISERROR($Z8/AA8),"-",$Z8/AA8) -> - | Y8: =IF(ISERROR($Z8/AB8),"-",$Z8/AB8) -> - | Z8: =('平日中午(12-14)'!$B$97+'平日中午(12-14)'!$B$116+'平日中午(12-14)'!$B$135+'平日中午(12-14)'!$B$154)*15 -> 0 | AA8: ='平日中午(12-14)'!$F$97+'平日中午(12-14)'!$F$116+'平日中午(12-14)'!$F$135+'平日中午(12-14)'!$F$154 -> 0 | AB8: ='平日中午(12-14)'!$H$97+'平日中午(12-14)'!$H$116+'平日中午(12-14)'!$H$135+'平日中午(12-14)'!$H$154 -> 0 | AD8: 18:00~19:00 | AE8: =IF(ISERROR($AG8/AH8),"-",$AG8/AH8) -> - | AF8: =IF(ISERROR($AG8/AI8),"-",$AG8/AI8) -> - | AG8: =('平日昏峰(17-19)'!$B$97+'平日昏峰(17-19)'!$B$116+'平日昏峰(17-19)'!$B$135+'平日昏峰(17-19)'!$B$154)*15 -> 0 | AH8: ='平日昏峰(17-19)'!$F$97+'平日昏峰(17-19)'!$F$116+'平日昏峰(17-19)'!$F$135+'平日昏峰(17-19)'!$F$154 -> 0 | AI8: ='平日昏峰(17-19)'!$H$97+'平日昏峰(17-19)'!$H$116+'平日昏峰(17-19)'!$H$135+'平日昏峰(17-19)'!$H$154 -> 0 | AL8: =IF(ISERROR($AN8/AO8),"-",$AN8/AO8) -> - | AM8: =IF(ISERROR($AN8/AP8),"-",$AN8/AP8) -> - | AS8: =IF(ISERROR($AU8/AV8),"-",$AU8/AV8) -> - | AT8: =IF(ISERROR($AU8/AW8),"-",$AU8/AW8) -> - | AZ8: =IF(ISERROR($BB8/BC8),"-",$BB8/BC8) -> - | BA8: =IF(ISERROR($BB8/BD8),"-",$BB8/BD8) -> - | BF8: 17:00~18:00 | BG8: =IF(ISERROR($BI8/BJ8),"-",$BI8/BJ8) -> - | BH8: =IF(ISERROR($BI8/BK8),"-",$BI8/BK8) -> - | BI8: =('假日(16-18)'!$B$97+'假日(16-18)'!$B$116+'假日(16-18)'!$B$135+'假日(16-18)'!$B$154)*15 -> 0 | BJ8: ='假日(16-18)'!$F$97+'假日(16-18)'!$F$116+'假日(16-18)'!$F$135+'假日(16-18)'!$F$154 -> 0 | BK8: ='假日(16-18)'!$H$97+'假日(16-18)'!$H$116+'假日(16-18)'!$H$135+'假日(16-18)'!$H$154 -> 0 | BM8: 18:00~19:00 | BN8: =IF(ISERROR($BP8/BQ8),"-",$BP8/BQ8) -> - | BO8: =IF(ISERROR($BP8/BR8),"-",$BP8/BR8) -> - | BP8: =('假日(17-19)'!$B$97+'假日(17-19)'!$B$116+'假日(17-19)'!$B$135+'假日(17-19)'!$B$154)*15 -> 0 | BQ8: ='假日(17-19)'!$F$97+'假日(17-19)'!$F$116+'假日(17-19)'!$F$135+'假日(17-19)'!$F$154 -> 0 | BR8: ='假日(17-19)'!$H$97+'假日(17-19)'!$H$116+'假日(17-19)'!$H$135+'假日(17-19)'!$H$154 -> 0 | BT8: 17:00~18:00 | BU8: =IF(ISERROR($BW8/BX8),"-",$BW8/BX8) -> - | BV8: =IF(ISERROR($BW8/BY8),"-",$BW8/BY8) -> - | BW8: =('假日(16-20)'!$B$97+'假日(16-20)'!$B$116+'假日(16-20)'!$B$135+'假日(16-20)'!$B$154)*15 -> 0 | BX8: ='假日(16-20)'!$F$97+'假日(16-20)'!$F$116+'假日(16-20)'!$F$135+'假日(16-20)'!$F$154 -> 0 | BY8: ='假日(16-20)'!$H$97+'假日(16-20)'!$H$116+'假日(16-20)'!$H$135+'假日(16-20)'!$H$154 -> 0
B9: =CONCATENATE(基本資料!$B$18,"方向","平均延滯") -> A方向平均延滯 | C9: =IF(ISERROR(VLOOKUP($F$45,B4:C8,2,1)),"-",VLOOKUP($F$45,B4:C8,2,1)) -> - | I9: =CONCATENATE(基本資料!$B$18,"方向","平均延滯") -> A方向平均延滯 | J9: =IF(ISERROR(VLOOKUP($M$45,I4:J8,2,1)),"-",VLOOKUP($M$45,I4:J8,2,1)) -> - | P9: =CONCATENATE(基本資料!$B$18,"方向","平均延滯") -> A方向平均延滯 | Q9: =IF(ISERROR(VLOOKUP($T$45,P4:Q8,2,1)),"-",VLOOKUP($T$45,P4:Q8,2,1)) -> - | W9: =CONCATENATE(基本資料!$B$18,"方向","平均延滯") -> A方向平均延滯 | X9: =IF(ISERROR(VLOOKUP($AA$45,W4:X8,2,1)),"-",VLOOKUP($AA$45,W4:X8,2,1)) -> - | AD9: =CONCATENATE(基本資料!$B$18,"方向","平均延滯") -> A方向平均延滯 | AE9: =IF(ISERROR(VLOOKUP($AH$45,AD4:AE8,2,1)),"-",VLOOKUP($AH$45,AD4:AE8,2,1)) -> - | AK9: =CONCATENATE(基本資料!$B$18,"方向","平均延滯") -> A方向平均延滯 | AL9: =IF(ISERROR(VLOOKUP($AO$45,AK4:AL8,2,1)),"-",VLOOKUP($AO$45,AK4:AL8,2,1)) -> - | AR9: =CONCATENATE(基本資料!$B$18,"方向","平均延滯") -> A方向平均延滯 | AS9: =IF(ISERROR(VLOOKUP($AV$45,AR4:AS8,2,1)),"-",VLOOKUP($AV$45,AR4:AS8,2,1)) -> - | AY9: =CONCATENATE(基本資料!$B$18,"方向","平均延滯") -> A方向平均延滯 | AZ9: =IF(ISERROR(VLOOKUP($BC$45,AY4:AZ8,2,1)),"-",VLOOKUP($BC$45,AY4:AZ8,2,1)) -> - | BF9: =CONCATENATE(基本資料!$B$18,"方向","平均延滯") -> A方向平均延滯 | BG9: =IF(ISERROR(VLOOKUP($BJ$45,BF4:BG8,2,1)),"-",VLOOKUP($BJ$45,BF4:BG8,2,1)) -> - | BM9: =CONCATENATE(基本資料!$B$18,"方向","平均延滯") -> A方向平均延滯 | BN9: =IF(ISERROR(VLOOKUP($BQ$45,BM4:BN8,2,1)),"-",VLOOKUP($BQ$45,BM4:BN8,2,1)) -> - | BT9: 17:15~18:15 | BU9: =IF(ISERROR($BW9/BX9),"-",$BW9/BX9) -> - | BV9: =IF(ISERROR($BW9/BY9),"-",$BW9/BY9) -> - | BW9: =('假日(16-20)'!$B$116+'假日(16-20)'!$B$135+'假日(16-20)'!$B$154+'假日(16-20)'!$B$173)*15 -> 0 | BX9: ='假日(16-20)'!$F$116+'假日(16-20)'!$F$135+'假日(16-20)'!$F$154+'假日(16-20)'!$F$173 -> 0 | BY9: ='假日(16-20)'!$H$116+'假日(16-20)'!$H$135+'假日(16-20)'!$H$154+'假日(16-20)'!$H$173 -> 0
B10: =CONCATENATE(基本資料!$B$18,"方向","平均停等車輛延滯") -> A方向平均停等車輛延滯 | D10: =IF(ISERROR(VLOOKUP($F$46,B4:D8,3,1)),"-",VLOOKUP($F$46,B4:D8,3,1)) -> - | I10: =CONCATENATE(基本資料!$B$18,"方向","平均停等車輛延滯") -> A方向平均停等車輛延滯 | K10: =IF(ISERROR(VLOOKUP($M$46,I4:K8,3,1)),"-",VLOOKUP($M$46,I4:K8,3,1)) -> - | P10: =CONCATENATE(基本資料!$B$18,"方向","平均停等車輛延滯") -> A方向平均停等車輛延滯 | R10: =IF(ISERROR(VLOOKUP($T$46,P4:R8,3,1)),"-",VLOOKUP($T$46,P4:R8,3,1)) -> - | W10: =CONCATENATE(基本資料!$B$18,"方向","平均停等車輛延滯") -> A方向平均停等車輛延滯 | Y10: =IF(ISERROR(VLOOKUP($AA$46,W4:Y8,3,1)),"-",VLOOKUP($AA$46,W4:Y8,3,1)) -> - | AD10: =CONCATENATE(基本資料!$B$18,"方向","平均停等車輛延滯") -> A方向平均停等車輛延滯 | AF10: =IF(ISERROR(VLOOKUP($AH$46,AD4:AF8,3,1)),"-",VLOOKUP($AH$46,AD4:AF8,3,1)) -> - | AK10: =CONCATENATE(基本資料!$B$18,"方向","平均停等車輛延滯") -> A方向平均停等車輛延滯 | AM10: =IF(ISERROR(VLOOKUP($AO$46,AK4:AM8,3,1)),"-",VLOOKUP($AO$46,AK4:AM8,3,1)) -> - | AR10: =CONCATENATE(基本資料!$B$18,"方向","平均停等車輛延滯") -> A方向平均停等車輛延滯 | AT10: =IF(ISERROR(VLOOKUP($AV$46,AR4:AT8,3,1)),"-",VLOOKUP($AV$46,AR4:AT8,3,1)) -> - | AY10: =CONCATENATE(基本資料!$B$18,"方向","平均停等車輛延滯") -> A方向平均停等車輛延滯 | BA10: =IF(ISERROR(VLOOKUP($BC$46,AY4:BA8,3,1)),"-",VLOOKUP($BC$46,AY4:BA8,3,1)) -> - | BF10: =CONCATENATE(基本資料!$B$18,"方向","平均停等車輛延滯") -> A方向平均停等車輛延滯 | BH10: =IF(ISERROR(VLOOKUP($BJ$46,BF4:BH8,3,1)),"-",VLOOKUP($BJ$46,BF4:BH8,3,1)) -> - | BM10: =CONCATENATE(基本資料!$B$18,"方向","平均停等車輛延滯") -> A方向平均停等車輛延滯 | BO10: =IF(ISERROR(VLOOKUP($BQ$46,BM4:BO8,3,1)),"-",VLOOKUP($BQ$46,BM4:BO8,3,1)) -> - | BT10: 17:30~18:30 | BU10: =IF(ISERROR($BW10/BX10),"-",$BW10/BX10) -> - | BV10: =IF(ISERROR($BW10/BY10),"-",$BW10/BY10) -> - | BW10: =('假日(16-20)'!$B$135+'假日(16-20)'!$B$154+'假日(16-20)'!$B$173+'假日(16-20)'!$B$192)*15 -> 0 | BX10: ='假日(16-20)'!$F$135+'假日(16-20)'!$F$154+'假日(16-20)'!$F$173+'假日(16-20)'!$F$192 -> 0 | BY10: ='假日(16-20)'!$H$135+'假日(16-20)'!$H$154+'假日(16-20)'!$H$173+'假日(16-20)'!$H$192 -> 0
B11: ='平日晨峰(07-09)'!$J$2 -> B方向： | I11: ='平日晨峰(07-09)'!$J$2 -> B方向： | P11: ='平日中午(11-13)'!$J$2 -> B方向： | W11: ='平日中午(11-13)'!$J$2 -> B方向： | AD11: ='平日昏峰(17-19)'!$J$2 -> B方向： | AK11: ='假日(11-12)'!$J$2 -> B方向： | AR11: ='假日(1430-1530)'!$J$2 -> B方向： | AY11: ='假日(1730-1830)'!$J$2 -> B方向： | BF11: ='假日(16-18)'!$J$2 -> B方向： | BM11: ='假日(17-19)'!$J$2 -> B方向： | BT11: 17:45~18:45 | BU11: =IF(ISERROR($BW11/BX11),"-",$BW11/BX11) -> - | BV11: =IF(ISERROR($BW11/BY11),"-",$BW11/BY11) -> - | BW11: =('假日(16-20)'!$B$154+'假日(16-20)'!$B$173+'假日(16-20)'!$B$192+'假日(16-20)'!$B$211)*15 -> 0 | BX11: ='假日(16-20)'!$F$154+'假日(16-20)'!$F$173+'假日(16-20)'!$F$192+'假日(16-20)'!$F$211 -> 0 | BY11: ='假日(16-20)'!$H$154+'假日(16-20)'!$H$173+'假日(16-20)'!$H$192+'假日(16-20)'!$H$211 -> 0
B12: 時間 | C12: 平均延滯 | D12: 平均停等延滯 | E12: 總延滯 | F12: 車輛總數 | G12: 停等車輛數 | I12: 時間 | J12: 平均延滯 | K12: 平均停等延滯 | L12: 總延滯 | M12: 車輛總數 | N12: 停等車輛數 | P12: 時間 | Q12: 平均延滯 | R12: 平均停等延滯 | S12: 總延滯 | T12: 車輛總數 | U12: 停等車輛數 | W12: 時間 | X12: 平均延滯 | Y12: 平均停等延滯 | Z12: 總延滯 | AA12: 車輛總數 | AB12: 停等車輛數 | AD12: 時間 | AE12: 平均延滯 | AF12: 平均停等延滯 | AG12: 總延滯 | AH12: 車輛總數 | AI12: 停等車輛數 | AK12: 時間 | AL12: 平均延滯 | AM12: 平均停等延滯 | AN12: 總延滯 | AO12: 車輛總數 | AP12: 停等車輛數 | AR12: 時間 | AS12: 平均延滯 | AT12: 平均停等延滯 | AU12: 總延滯 | AV12: 車輛總數 | AW12: 停等車輛數 | AY12: 時間 | AZ12: 平均延滯 | BA12: 平均停等延滯 | BB12: 總延滯 | BC12: 車輛總數 | BD12: 停等車輛數 | BF12: 時間 | BG12: 平均延滯 | BH12: 平均停等延滯 | BI12: 總延滯 | BJ12: 車輛總數 | BK12: 停等車輛數 | BM12: 時間 | BN12: 平均延滯 | BO12: 平均停等延滯 | BP12: 總延滯 | BQ12: 車輛總數 | BR12: 停等車輛數 | BT12: 18:00~19:00 | BU12: =IF(ISERROR($BW12/BX12),"-",$BW12/BX12) -> - | BV12: =IF(ISERROR($BW12/BY12),"-",$BW12/BY12) -> - | BW12: =('假日(16-20)'!$B$173+'假日(16-20)'!$B$192+'假日(16-20)'!$B$211+'假日(16-20)'!$B$230)*15 -> 0 | BX12: ='假日(16-20)'!$F$173+'假日(16-20)'!$F$192+'假日(16-20)'!$F$211+'假日(16-20)'!$F$230 -> 0 | BY12: ='假日(16-20)'!$H$173+'假日(16-20)'!$H$192+'假日(16-20)'!$H$211+'假日(16-20)'!$H$230 -> 0
B13: 06:30~07:30 | C13: =IF(ISERROR($E13/F13),"-",$E13/F13) -> - | D13: =IF(ISERROR($E13/G13),"-",$E13/G13) -> - | E13: =('平日晨峰(0630-0830)'!$K$21+'平日晨峰(0630-0830)'!$K$40+'平日晨峰(0630-0830)'!$K$59+'平日晨峰(0630-0830)'!$K$78)*15 -> 0 | F13: ='平日晨峰(0630-0830)'!$O$21+'平日晨峰(0630-0830)'!$O$40+'平日晨峰(0630-0830)'!$O$59+'平日晨峰(0630-0830)'!$O$78 -> 0 | G13: ='平日晨峰(0630-0830)'!$Q$21+'平日晨峰(0630-0830)'!$Q$40+'平日晨峰(0630-0830)'!$Q$59+'平日晨峰(0630-0830)'!$Q$78 -> 0 | I13: =$I$4 -> 07:00~08:00 | J13: =IF(ISERROR($L13/M13),"-",$L13/M13) -> - | K13: =IF(ISERROR($L13/N13),"-",$L13/N13) -> - | L13: =('平日晨峰(07-09)'!$K$21+'平日晨峰(07-09)'!$K$40+'平日晨峰(07-09)'!$K$59+'平日晨峰(07-09)'!$K$78)*15 -> 0 | M13: ='平日晨峰(07-09)'!$O$21+'平日晨峰(07-09)'!$O$40+'平日晨峰(07-09)'!$O$59+'平日晨峰(07-09)'!$O$78 -> 0 | N13: ='平日晨峰(07-09)'!$Q$21+'平日晨峰(07-09)'!$Q$40+'平日晨峰(07-09)'!$Q$59+'平日晨峰(07-09)'!$Q$78 -> 0 | P13: =P4 -> 11:00~12:00 | Q13: =IF(ISERROR($S13/T13),"-",$S13/T13) -> - | R13: =IF(ISERROR($T13/U13),"-",$T13/U13) -> - | S13: =('平日中午(11-13)'!$K$21+'平日中午(11-13)'!$K$40+'平日中午(11-13)'!$K$59+'平日中午(11-13)'!$K$78)*15 -> 0 | T13: ='平日中午(11-13)'!$O$21+'平日中午(11-13)'!$O$40+'平日中午(11-13)'!$O$59+'平日中午(11-13)'!$O$78 -> 0 | U13: ='平日中午(11-13)'!$Q$21+'平日中午(11-13)'!$Q$40+'平日中午(11-13)'!$Q$59+'平日中午(11-13)'!$Q$78 -> 0 | W13: =W4 -> 1200~13:00 | X13: =IF(ISERROR($Z13/AA13),"-",$Z13/AA13) -> - | Y13: =IF(ISERROR($Z13/AB13),"-",$Z13/AB13) -> - | Z13: =('平日中午(12-14)'!$K$21+'平日中午(12-14)'!$K$40+'平日中午(12-14)'!$K$59+'平日中午(12-14)'!$K$78)*15 -> 0 | AA13: ='平日中午(12-14)'!$O$21+'平日中午(12-14)'!$O$40+'平日中午(12-14)'!$O$59+'平日中午(12-14)'!$O$78 -> 0 | AB13: ='平日中午(12-14)'!$Q$21+'平日中午(12-14)'!$Q$40+'平日中午(12-14)'!$Q$59+'平日中午(12-14)'!$Q$78 -> 0 | AD13: =$AD$4 -> 17:00~18:00 | AE13: =IF(ISERROR($AG13/AH13),"-",$AG13/AH13) -> - | AF13: =IF(ISERROR($AG13/AI13),"-",$AG13/AI13) -> - | AG13: =('平日昏峰(17-19)'!$K$21+'平日昏峰(17-19)'!$K$40+'平日昏峰(17-19)'!$K$59+'平日昏峰(17-19)'!$K$78)*15 -> 0 | AH13: ='平日昏峰(17-19)'!$O$21+'平日昏峰(17-19)'!$O$40+'平日昏峰(17-19)'!$O$59+'平日昏峰(17-19)'!$O$78 -> 0 | AI13: ='平日昏峰(17-19)'!$Q$21+'平日昏峰(17-19)'!$Q$40+'平日昏峰(17-19)'!$Q$59+'平日昏峰(17-19)'!$Q$78 -> 0 | AK13: =$AK$4 -> 11:00~12:00 | AL13: =IF(ISERROR($AN13/AO13),"-",$AN13/AO13) -> - | AM13: =IF(ISERROR($AN13/AP13),"-",$AN13/AP13) -> - | AN13: =('假日(11-12)'!$K$21+'假日(11-12)'!$K$40+'假日(11-12)'!$K$59+'假日(11-12)'!$K$78)*15 -> 0 | AO13: ='假日(11-12)'!$O$21+'假日(11-12)'!$O$40+'假日(11-12)'!$O$59+'假日(11-12)'!$O$78 -> 0 | AP13: ='假日(11-12)'!$Q$21+'假日(11-12)'!$Q$40+'假日(11-12)'!$Q$59+'假日(11-12)'!$Q$78 -> 0 | AR13: =$AR$4 -> 14:30~15:30 | AS13: =IF(ISERROR($AU13/AV13),"-",$AU13/AV13) -> - | AT13: =IF(ISERROR($AU13/AW13),"-",$AU13/AW13) -> - | AU13: =('假日(1430-1530)'!$K$21+'假日(1430-1530)'!$K$40+'假日(1430-1530)'!$K$59+'假日(1430-1530)'!$K$78)*15 -> 0 | AV13: ='假日(1430-1530)'!$O$21+'假日(1430-1530)'!$O$40+'假日(1430-1530)'!$O$59+'假日(1430-1530)'!$O$78 -> 0 | AW13: ='假日(1430-1530)'!$Q$21+'假日(1430-1530)'!$Q$40+'假日(1430-1530)'!$Q$59+'假日(1430-1530)'!$Q$78 -> 0 | AY13: =AY4 -> 17:30~18:30 | AZ13: =IF(ISERROR($BB13/BC13),"-",$BB13/BC13) -> - | BA13: =IF(ISERROR($BB13/BD13),"-",$BB13/BD13) -> - | BB13: =('假日(1730-1830)'!$K$21+'假日(1730-1830)'!$K$40+'假日(1730-1830)'!$K$59+'假日(1730-1830)'!$K$78)*15 -> 0 | BC13: ='假日(1730-1830)'!$O$21+'假日(1730-1830)'!$O$40+'假日(1730-1830)'!$O$59+'假日(1730-1830)'!$O$78 -> 0 | BD13: ='假日(1730-1830)'!$Q$21+'假日(1730-1830)'!$Q$40+'假日(1730-1830)'!$Q$59+'假日(1730-1830)'!$Q$78 -> 0 | BF13: =BF4 -> 16:00~17:00 | BG13: =IF(ISERROR($BI13/BJ13),"-",$BI13/BJ13) -> - | BH13: =IF(ISERROR($BI13/BK13),"-",$BI13/BK13) -> - | BI13: =('假日(16-18)'!$K$21+'假日(16-18)'!$K$40+'假日(16-18)'!$K$59+'假日(16-18)'!$K$78)*15 -> 0 | BJ13: ='假日(16-18)'!$O$21+'假日(16-18)'!$O$40+'假日(16-18)'!$O$59+'假日(16-18)'!$O$78 -> 0 | BK13: ='假日(16-18)'!$Q$21+'假日(16-18)'!$Q$40+'假日(16-18)'!$Q$59+'假日(16-18)'!$Q$78 -> 0 | BM13: =BM4 -> 17:00~18:00 | BN13: =IF(ISERROR($BP13/BQ13),"-",$BP13/BQ13) -> - | BO13: =IF(ISERROR($BP13/BR13),"-",$BP13/BR13) -> - | BP13: =('假日(17-19)'!$K$21+'假日(17-19)'!$K$40+'假日(17-19)'!$K$59+'假日(17-19)'!$K$78)*15 -> 0 | BQ13: ='假日(17-19)'!$O$21+'假日(17-19)'!$O$40+'假日(17-19)'!$O$59+'假日(17-19)'!$O$78 -> 0 | BR13: ='假日(17-19)'!$Q$21+'假日(17-19)'!$Q$40+'假日(17-19)'!$Q$59+'假日(17-19)'!$Q$78 -> 0 | BT13: 18:15~19:15 | BU13: =IF(ISERROR($BW13/BX13),"-",$BW13/BX13) -> - | BV13: =IF(ISERROR($BW13/BY13),"-",$BW13/BY13) -> - | BW13: =('假日(16-20)'!$B$192+'假日(16-20)'!$B$211+'假日(16-20)'!$B$230+'假日(16-20)'!$B$249)*15 -> 0 | BX13: ='假日(16-20)'!$F$192+'假日(16-20)'!$F$211+'假日(16-20)'!$F$230+'假日(16-20)'!$F$249 -> 0 | BY13: ='假日(16-20)'!$H$192+'假日(16-20)'!$H$211+'假日(16-20)'!$H$230+'假日(16-20)'!$H$249 -> 0
B14: 06:45~07:45 | C14: =IF(ISERROR($E14/F14),"-",$E14/F14) -> - | D14: =IF(ISERROR($E14/G14),"-",$E14/G14) -> - | E14: =('平日晨峰(0630-0830)'!$K$40+'平日晨峰(0630-0830)'!$K$59+'平日晨峰(0630-0830)'!$K$78+'平日晨峰(0630-0830)'!$K$97)*15 -> 0 | F14: ='平日晨峰(0630-0830)'!$O$40+'平日晨峰(0630-0830)'!$O$59+'平日晨峰(0630-0830)'!$O$78+'平日晨峰(0630-0830)'!$O$97 -> 0 | G14: ='平日晨峰(0630-0830)'!$Q$40+'平日晨峰(0630-0830)'!$Q$59+'平日晨峰(0630-0830)'!$Q$78+'平日晨峰(0630-0830)'!$Q$97 -> 0 | I14: =$I$5 -> 07:15~08:15 | J14: =IF(ISERROR($L14/M14),"-",$L14/M14) -> - | K14: =IF(ISERROR($L14/N14),"-",$L14/N14) -> - | L14: =('平日晨峰(07-09)'!$K$40+'平日晨峰(07-09)'!$K$59+'平日晨峰(07-09)'!$K$78+'平日晨峰(07-09)'!$K$97)*15 -> 0 | M14: ='平日晨峰(07-09)'!$O$40+'平日晨峰(07-09)'!$O$59+'平日晨峰(07-09)'!$O$78+'平日晨峰(07-09)'!$O$97 -> 0 | N14: ='平日晨峰(07-09)'!$Q$40+'平日晨峰(07-09)'!$Q$59+'平日晨峰(07-09)'!$Q$78+'平日晨峰(07-09)'!$Q$97 -> 0 | P14: =P5 -> 11:15~12:15 | Q14: =IF(ISERROR($S14/T14),"-",$S14/T14) -> - | R14: =IF(ISERROR($T14/U14),"-",$T14/U14) -> - | S14: =('平日中午(11-13)'!$K$40+'平日中午(11-13)'!$K$59+'平日中午(11-13)'!$K$78+'平日中午(11-13)'!$K$97)*15 -> 0 | T14: ='平日中午(11-13)'!$O$40+'平日中午(11-13)'!$O$59+'平日中午(11-13)'!$O$78+'平日中午(11-13)'!$O$97 -> 0 | U14: ='平日中午(11-13)'!$Q$40+'平日中午(11-13)'!$Q$59+'平日中午(11-13)'!$Q$78+'平日中午(11-13)'!$Q$97 -> 0 | W14: =W5 -> 12:15~13:15 | X14: =IF(ISERROR($Z14/AA14),"-",$Z14/AA14) -> - | Y14: =IF(ISERROR($Z14/AB14),"-",$Z14/AB14) -> - | Z14: =('平日中午(12-14)'!$K$40+'平日中午(12-14)'!$K$59+'平日中午(12-14)'!$K$78+'平日中午(12-14)'!$K$97)*15 -> 0 | AA14: ='平日中午(12-14)'!$O$40+'平日中午(12-14)'!$O$59+'平日中午(12-14)'!$O$78+'平日中午(12-14)'!$O$97 -> 0 | AB14: ='平日中午(12-14)'!$Q$40+'平日中午(12-14)'!$Q$59+'平日中午(12-14)'!$Q$78+'平日中午(12-14)'!$Q$97 -> 0 | AD14: =$AD$5 -> 17:15~18:15 | AE14: =IF(ISERROR($AG14/AH14),"-",$AG14/AH14) -> - | AF14: =IF(ISERROR($AG14/AI14),"-",$AG14/AI14) -> - | AG14: =('平日昏峰(17-19)'!$K$40+'平日昏峰(17-19)'!$K$59+'平日昏峰(17-19)'!$K$78+'平日昏峰(17-19)'!$K$97)*15 -> 0 | AH14: ='平日昏峰(17-19)'!$O$40+'平日昏峰(17-19)'!$O$59+'平日昏峰(17-19)'!$O$78+'平日昏峰(17-19)'!$O$97 -> 0 | AI14: ='平日昏峰(17-19)'!$Q$40+'平日昏峰(17-19)'!$Q$59+'平日昏峰(17-19)'!$Q$78+'平日昏峰(17-19)'!$Q$97 -> 0 | AK14: =$AK$5 -> 0 | AL14: =IF(ISERROR($AN14/AO14),"-",$AN14/AO14) -> - | AM14: =IF(ISERROR($AN14/AP14),"-",$AN14/AP14) -> - | AR14: =$AR$5 -> 0 | AS14: =IF(ISERROR($AU14/AV14),"-",$AU14/AV14) -> - | AT14: =IF(ISERROR($AU14/AW14),"-",$AU14/AW14) -> - | AY14: =AY5 -> 0 | AZ14: =IF(ISERROR($BB14/BC14),"-",$BB14/BC14) -> - | BA14: =IF(ISERROR($BB14/BD14),"-",$BB14/BD14) -> - | BF14: =BF5 -> 16:15~17:15 | BG14: =IF(ISERROR($BI14/BJ14),"-",$BI14/BJ14) -> - | BH14: =IF(ISERROR($BI14/BK14),"-",$BI14/BK14) -> - | BI14: =('假日(16-18)'!$K$40+'假日(16-18)'!$K$59+'假日(16-18)'!$K$78+'假日(16-18)'!$K$97)*15 -> 0 | BJ14: ='假日(16-18)'!$O$40+'假日(16-18)'!$O$59+'假日(16-18)'!$O$78+'假日(16-18)'!$O$97 -> 0 | BK14: ='假日(16-18)'!$Q$40+'假日(16-18)'!$Q$59+'假日(16-18)'!$Q$78+'假日(16-18)'!$Q$97 -> 0 | BM14: =BM5 -> 17:15~18:15 | BN14: =IF(ISERROR($BP14/BQ14),"-",$BP14/BQ14) -> - | BO14: =IF(ISERROR($BP14/BR14),"-",$BP14/BR14) -> - | BP14: =('假日(17-19)'!$K$40+'假日(17-19)'!$K$59+'假日(17-19)'!$K$78+'假日(17-19)'!$K$97)*15 -> 0 | BQ14: ='假日(17-19)'!$O$40+'假日(17-19)'!$O$59+'假日(17-19)'!$O$78+'假日(17-19)'!$O$97 -> 0 | BR14: ='假日(17-19)'!$Q$40+'假日(17-19)'!$Q$59+'假日(17-19)'!$Q$78+'假日(17-19)'!$Q$97 -> 0 | BT14: 18:30~19:30 | BU14: =IF(ISERROR($BW14/BX14),"-",$BW14/BX14) -> - | BV14: =IF(ISERROR($BW14/BY14),"-",$BW14/BY14) -> - | BW14: =('假日(16-20)'!$B$211+'假日(16-20)'!$B$230+'假日(16-20)'!$B$249+'假日(16-20)'!$B$268)*15 -> 0 | BX14: ='假日(16-20)'!$F$211+'假日(16-20)'!$F$230+'假日(16-20)'!$F$249+'假日(16-20)'!$F$268 -> 0 | BY14: ='假日(16-20)'!$H$211+'假日(16-20)'!$H$230+'假日(16-20)'!$H$249+'假日(16-20)'!$H$268 -> 0
B15: 07:00~08:00 | C15: =IF(ISERROR($E15/F15),"-",$E15/F15) -> - | D15: =IF(ISERROR($E15/G15),"-",$E15/G15) -> - | E15: =('平日晨峰(0630-0830)'!$K$59+'平日晨峰(0630-0830)'!$K$78+'平日晨峰(0630-0830)'!$K$97+'平日晨峰(0630-0830)'!$K$116)*15 -> 0 | F15: ='平日晨峰(0630-0830)'!$O$59+'平日晨峰(0630-0830)'!$O$78+'平日晨峰(0630-0830)'!$O$97+'平日晨峰(0630-0830)'!$O$116 -> 0 | G15: ='平日晨峰(0630-0830)'!$Q$59+'平日晨峰(0630-0830)'!$Q$78+'平日晨峰(0630-0830)'!$Q$97+'平日晨峰(0630-0830)'!$Q$116 -> 0 | I15: =$I$6 -> 07:30~08:30 | J15: =IF(ISERROR($L15/M15),"-",$L15/M15) -> - | K15: =IF(ISERROR($L15/N15),"-",$L15/N15) -> - | L15: =('平日晨峰(07-09)'!$K$59+'平日晨峰(07-09)'!$K$78+'平日晨峰(07-09)'!$K$97+'平日晨峰(07-09)'!$K$116)*15 -> 0 | M15: ='平日晨峰(07-09)'!$O$59+'平日晨峰(07-09)'!$O$78+'平日晨峰(07-09)'!$O$97+'平日晨峰(07-09)'!$O$116 -> 0 | N15: ='平日晨峰(07-09)'!$Q$59+'平日晨峰(07-09)'!$Q$78+'平日晨峰(07-09)'!$Q$97+'平日晨峰(07-09)'!$Q$116 -> 0 | P15: =P6 -> 11:30~12:30 | Q15: =IF(ISERROR($S15/T15),"-",$S15/T15) -> - | R15: =IF(ISERROR($T15/U15),"-",$T15/U15) -> - | S15: =('平日中午(11-13)'!$K$59+'平日中午(11-13)'!$K$78+'平日中午(11-13)'!$K$97+'平日中午(11-13)'!$K$116)*15 -> 0 | T15: ='平日中午(11-13)'!$O$59+'平日中午(11-13)'!$O$78+'平日中午(11-13)'!$O$97+'平日中午(11-13)'!$O$116 -> 0 | U15: ='平日中午(11-13)'!$Q$59+'平日中午(11-13)'!$Q$78+'平日中午(11-13)'!$Q$97+'平日中午(11-13)'!$Q$116 -> 0 | W15: =W6 -> 12:30~13:30 | X15: =IF(ISERROR($Z15/AA15),"-",$Z15/AA15) -> - | Y15: =IF(ISERROR($Z15/AB15),"-",$Z15/AB15) -> - | Z15: =('平日中午(12-14)'!$K$59+'平日中午(12-14)'!$K$78+'平日中午(12-14)'!$K$97+'平日中午(12-14)'!$K$116)*15 -> 0 | AA15: ='平日中午(12-14)'!$O$59+'平日中午(12-14)'!$O$78+'平日中午(12-14)'!$O$97+'平日中午(12-14)'!$O$116 -> 0 | AB15: ='平日中午(12-14)'!$Q$59+'平日中午(12-14)'!$Q$78+'平日中午(12-14)'!$Q$97+'平日中午(12-14)'!$Q$116 -> 0 | AD15: =$AD$6 -> 17:30~18:30 | AE15: =IF(ISERROR($AG15/AH15),"-",$AG15/AH15) -> - | AF15: =IF(ISERROR($AG15/AI15),"-",$AG15/AI15) -> - | AG15: =('平日昏峰(17-19)'!$K$59+'平日昏峰(17-19)'!$K$78+'平日昏峰(17-19)'!$K$97+'平日昏峰(17-19)'!$K$116)*15 -> 0 | AH15: ='平日昏峰(17-19)'!$O$59+'平日昏峰(17-19)'!$O$78+'平日昏峰(17-19)'!$O$97+'平日昏峰(17-19)'!$O$116 -> 0 | AI15: ='平日昏峰(17-19)'!$Q$59+'平日昏峰(17-19)'!$Q$78+'平日昏峰(17-19)'!$Q$97+'平日昏峰(17-19)'!$Q$116 -> 0 | AK15: =$AK$6 -> 0 | AL15: =IF(ISERROR($AN15/AO15),"-",$AN15/AO15) -> - | AM15: =IF(ISERROR($AN15/AP15),"-",$AN15/AP15) -> - | AR15: =$AR$6 -> 0 | AS15: =IF(ISERROR($AU15/AV15),"-",$AU15/AV15) -> - | AT15: =IF(ISERROR($AU15/AW15),"-",$AU15/AW15) -> - | AY15: =AY6 -> 0 | AZ15: =IF(ISERROR($BB15/BC15),"-",$BB15/BC15) -> - | BA15: =IF(ISERROR($BB15/BD15),"-",$BB15/BD15) -> - | BF15: =BF6 -> 16:30~17:30 | BG15: =IF(ISERROR($BI15/BJ15),"-",$BI15/BJ15) -> - | BH15: =IF(ISERROR($BI15/BK15),"-",$BI15/BK15) -> - | BI15: =('假日(16-18)'!$K$59+'假日(16-18)'!$K$78+'假日(16-18)'!$K$97+'假日(16-18)'!$K$116)*15 -> 0 | BJ15: ='假日(16-18)'!$O$59+'假日(16-18)'!$O$78+'假日(16-18)'!$O$97+'假日(16-18)'!$O$116 -> 0 | BK15: ='假日(16-18)'!$Q$59+'假日(16-18)'!$Q$78+'假日(16-18)'!$Q$97+'假日(16-18)'!$Q$116 -> 0 | BM15: =BM6 -> 17:30~18:30 | BN15: =IF(ISERROR($BP15/BQ15),"-",$BP15/BQ15) -> - | BO15: =IF(ISERROR($BP15/BR15),"-",$BP15/BR15) -> - | BP15: =('假日(17-19)'!$K$59+'假日(17-19)'!$K$78+'假日(17-19)'!$K$97+'假日(17-19)'!$K$116)*15 -> 0 | BQ15: ='假日(17-19)'!$O$59+'假日(17-19)'!$O$78+'假日(17-19)'!$O$97+'假日(17-19)'!$O$116 -> 0 | BR15: ='假日(17-19)'!$Q$59+'假日(17-19)'!$Q$78+'假日(17-19)'!$Q$97+'假日(17-19)'!$Q$116 -> 0 | BT15: 18:45~19:45 | BU15: =IF(ISERROR($BW15/BX15),"-",$BW15/BX15) -> - | BV15: =IF(ISERROR($BW15/BY15),"-",$BW15/BY15) -> - | BW15: =('假日(16-20)'!$B$230+'假日(16-20)'!$B$249+'假日(16-20)'!$B$268+'假日(16-20)'!$B$287)*15 -> 0 | BX15: ='假日(16-20)'!$F$230+'假日(16-20)'!$F$249+'假日(16-20)'!$F$268+'假日(16-20)'!$F$287 -> 0 | BY15: ='假日(16-20)'!$H$230+'假日(16-20)'!$H$249+'假日(16-20)'!$H$268+'假日(16-20)'!$H$287 -> 0
B16: 07:15~08:15 | C16: =IF(ISERROR($E16/F16),"-",$E16/F16) -> - | D16: =IF(ISERROR($E16/G16),"-",$E16/G16) -> - | E16: =('平日晨峰(0630-0830)'!$K$78+'平日晨峰(0630-0830)'!$K$97+'平日晨峰(0630-0830)'!$K$116+'平日晨峰(0630-0830)'!$K$135)*15 -> 0 | F16: ='平日晨峰(0630-0830)'!$O$78+'平日晨峰(0630-0830)'!$O$97+'平日晨峰(0630-0830)'!$O$116+'平日晨峰(0630-0830)'!$O$135 -> 0 | G16: ='平日晨峰(0630-0830)'!$Q$78+'平日晨峰(0630-0830)'!$Q$97+'平日晨峰(0630-0830)'!$Q$116+'平日晨峰(0630-0830)'!$Q$135 -> 0 | I16: =$I$7 -> 07:45~08:45 | J16: =IF(ISERROR($L16/M16),"-",$L16/M16) -> - | K16: =IF(ISERROR($L16/N16),"-",$L16/N16) -> - | L16: =('平日晨峰(07-09)'!$K$78+'平日晨峰(07-09)'!$K$97+'平日晨峰(07-09)'!$K$116+'平日晨峰(07-09)'!$K$135)*15 -> 0 | M16: ='平日晨峰(07-09)'!$O$78+'平日晨峰(07-09)'!$O$97+'平日晨峰(07-09)'!$O$116+'平日晨峰(07-09)'!$O$135 -> 0 | N16: ='平日晨峰(07-09)'!$Q$78+'平日晨峰(07-09)'!$Q$97+'平日晨峰(07-09)'!$Q$116+'平日晨峰(07-09)'!$Q$135 -> 0 | P16: =P7 -> 11:45~12:45 | Q16: =IF(ISERROR($S16/T16),"-",$S16/T16) -> - | R16: =IF(ISERROR($T16/U16),"-",$T16/U16) -> - | S16: =('平日中午(11-13)'!$K$78+'平日中午(11-13)'!$K$97+'平日中午(11-13)'!$K$116+'平日中午(11-13)'!$K$135)*15 -> 0 | T16: ='平日中午(11-13)'!$O$78+'平日中午(11-13)'!$O$97+'平日中午(11-13)'!$O$116+'平日中午(11-13)'!$O$135 -> 0 | U16: ='平日中午(11-13)'!$Q$78+'平日中午(11-13)'!$Q$97+'平日中午(11-13)'!$Q$116+'平日中午(11-13)'!$Q$135 -> 0 | W16: =W7 -> 12:45~13:45 | X16: =IF(ISERROR($Z16/AA16),"-",$Z16/AA16) -> - | Y16: =IF(ISERROR($Z16/AB16),"-",$Z16/AB16) -> - | Z16: =('平日中午(12-14)'!$K$78+'平日中午(12-14)'!$K$97+'平日中午(12-14)'!$K$116+'平日中午(12-14)'!$K$135)*15 -> 0 | AA16: ='平日中午(12-14)'!$O$78+'平日中午(12-14)'!$O$97+'平日中午(12-14)'!$O$116+'平日中午(12-14)'!$O$135 -> 0 | AB16: ='平日中午(12-14)'!$Q$78+'平日中午(12-14)'!$Q$97+'平日中午(12-14)'!$Q$116+'平日中午(12-14)'!$Q$135 -> 0 | AD16: =$AD$7 -> 17:45~18:45 | AE16: =IF(ISERROR($AG16/AH16),"-",$AG16/AH16) -> - | AF16: =IF(ISERROR($AG16/AI16),"-",$AG16/AI16) -> - | AG16: =('平日昏峰(17-19)'!$K$78+'平日昏峰(17-19)'!$K$97+'平日昏峰(17-19)'!$K$116+'平日昏峰(17-19)'!$K$135)*15 -> 0 | AH16: ='平日昏峰(17-19)'!$O$78+'平日昏峰(17-19)'!$O$97+'平日昏峰(17-19)'!$O$116+'平日昏峰(17-19)'!$O$135 -> 0 | AI16: ='平日昏峰(17-19)'!$Q$78+'平日昏峰(17-19)'!$Q$97+'平日昏峰(17-19)'!$Q$116+'平日昏峰(17-19)'!$Q$135 -> 0 | AK16: =$AK$7 -> 0 | AL16: =IF(ISERROR($AN16/AO16),"-",$AN16/AO16) -> - | AM16: =IF(ISERROR($AN16/AP16),"-",$AN16/AP16) -> - | AR16: =$AR$7 -> 0 | AS16: =IF(ISERROR($AU16/AV16),"-",$AU16/AV16) -> - | AT16: =IF(ISERROR($AU16/AW16),"-",$AU16/AW16) -> - | AY16: =AY7 -> 0 | AZ16: =IF(ISERROR($BB16/BC16),"-",$BB16/BC16) -> - | BA16: =IF(ISERROR($BB16/BD16),"-",$BB16/BD16) -> - | BF16: =BF7 -> 16:45~17:45 | BG16: =IF(ISERROR($BI16/BJ16),"-",$BI16/BJ16) -> - | BH16: =IF(ISERROR($BI16/BK16),"-",$BI16/BK16) -> - | BI16: =('假日(16-18)'!$K$78+'假日(16-18)'!$K$97+'假日(16-18)'!$K$116+'假日(16-18)'!$K$135)*15 -> 0 | BJ16: ='假日(16-18)'!$O$78+'假日(16-18)'!$O$97+'假日(16-18)'!$O$116+'假日(16-18)'!$O$135 -> 0 | BK16: ='假日(16-18)'!$Q$78+'假日(16-18)'!$Q$97+'假日(16-18)'!$Q$116+'假日(16-18)'!$Q$135 -> 0 | BM16: =BM7 -> 17:45~18:45 | BN16: =IF(ISERROR($BP16/BQ16),"-",$BP16/BQ16) -> - | BO16: =IF(ISERROR($BP16/BR16),"-",$BP16/BR16) -> - | BP16: =('假日(17-19)'!$K$78+'假日(17-19)'!$K$97+'假日(17-19)'!$K$116+'假日(17-19)'!$K$135)*15 -> 0 | BQ16: ='假日(17-19)'!$O$78+'假日(17-19)'!$O$97+'假日(17-19)'!$O$116+'假日(17-19)'!$O$135 -> 0 | BR16: ='假日(17-19)'!$Q$78+'假日(17-19)'!$Q$97+'假日(17-19)'!$Q$116+'假日(17-19)'!$Q$135 -> 0 | BT16: 19:00~20:00 | BU16: =IF(ISERROR($BW16/BX16),"-",$BW16/BX16) -> - | BV16: =IF(ISERROR($BW16/BY16),"-",$BW16/BY16) -> - | BW16: =('假日(16-20)'!$B$249+'假日(16-20)'!$B$268+'假日(16-20)'!$B$287+'假日(16-20)'!$B$306)*15 -> 0 | BX16: ='假日(16-20)'!$F$249+'假日(16-20)'!$F$268+'假日(16-20)'!$F$287+'假日(16-20)'!$F$306 -> 0 | BY16: ='假日(16-20)'!$H$249+'假日(16-20)'!$H$268+'假日(16-20)'!$H$287+'假日(16-20)'!$H$306 -> 0
B17: 07:30~08:30 | C17: =IF(ISERROR($E17/F17),"-",$E17/F17) -> - | D17: =IF(ISERROR($E17/G17),"-",$E17/G17) -> - | E17: =('平日晨峰(0630-0830)'!$K$97+'平日晨峰(0630-0830)'!$K$116+'平日晨峰(0630-0830)'!$K$135+'平日晨峰(0630-0830)'!$K$154)*15 -> 0 | F17: ='平日晨峰(0630-0830)'!$O$97+'平日晨峰(0630-0830)'!$O$116+'平日晨峰(0630-0830)'!$O$135+'平日晨峰(0630-0830)'!$O$154 -> 0 | G17: ='平日晨峰(0630-0830)'!$Q$97+'平日晨峰(0630-0830)'!$Q$116+'平日晨峰(0630-0830)'!$Q$135+'平日晨峰(0630-0830)'!$Q$154 -> 0 | I17: =$I$8 -> 08:00~09:00 | J17: =IF(ISERROR($L17/M17),"-",$L17/M17) -> - | K17: =IF(ISERROR($L17/N17),"-",$L17/N17) -> - | L17: =('平日晨峰(07-09)'!$K$97+'平日晨峰(07-09)'!$K$116+'平日晨峰(07-09)'!$K$135+'平日晨峰(07-09)'!$K$154)*15 -> 0 | M17: ='平日晨峰(07-09)'!$O$97+'平日晨峰(07-09)'!$O$116+'平日晨峰(07-09)'!$O$135+'平日晨峰(07-09)'!$O$154 -> 0 | N17: ='平日晨峰(07-09)'!$Q$97+'平日晨峰(07-09)'!$Q$116+'平日晨峰(07-09)'!$Q$135+'平日晨峰(07-09)'!$Q$154 -> 0 | P17: =P8 -> 12:00~13:00 | Q17: =IF(ISERROR($S17/T17),"-",$S17/T17) -> - | R17: =IF(ISERROR($T17/U17),"-",$T17/U17) -> - | S17: =('平日中午(11-13)'!$K$97+'平日中午(11-13)'!$K$116+'平日中午(11-13)'!$K$135+'平日中午(11-13)'!$K$154)*15 -> 0 | T17: ='平日中午(11-13)'!$O$97+'平日中午(11-13)'!$O$116+'平日中午(11-13)'!$O$135+'平日中午(11-13)'!$O$154 -> 0 | U17: ='平日中午(11-13)'!$Q$97+'平日中午(11-13)'!$Q$116+'平日中午(11-13)'!$Q$135+'平日中午(11-13)'!$Q$154 -> 0 | W17: =W8 -> 13:00~14:00 | X17: =IF(ISERROR($Z17/AA17),"-",$Z17/AA17) -> - | Y17: =IF(ISERROR($Z17/AB17),"-",$Z17/AB17) -> - | Z17: =('平日中午(12-14)'!$K$97+'平日中午(12-14)'!$K$116+'平日中午(12-14)'!$K$135+'平日中午(12-14)'!$K$154)*15 -> 0 | AA17: ='平日中午(12-14)'!$O$97+'平日中午(12-14)'!$O$116+'平日中午(12-14)'!$O$135+'平日中午(12-14)'!$O$154 -> 0 | AB17: ='平日中午(12-14)'!$Q$97+'平日中午(12-14)'!$Q$116+'平日中午(12-14)'!$Q$135+'平日中午(12-14)'!$Q$154 -> 0 | AD17: =$AD$8 -> 18:00~19:00 | AE17: =IF(ISERROR($AG17/AH17),"-",$AG17/AH17) -> - | AF17: =IF(ISERROR($AG17/AI17),"-",$AG17/AI17) -> - | AG17: =('平日昏峰(17-19)'!$K$97+'平日昏峰(17-19)'!$K$116+'平日昏峰(17-19)'!$K$135+'平日昏峰(17-19)'!$K$154)*15 -> 0 | AH17: ='平日昏峰(17-19)'!$O$97+'平日昏峰(17-19)'!$O$116+'平日昏峰(17-19)'!$O$135+'平日昏峰(17-19)'!$O$154 -> 0 | AI17: ='平日昏峰(17-19)'!$Q$97+'平日昏峰(17-19)'!$Q$116+'平日昏峰(17-19)'!$Q$135+'平日昏峰(17-19)'!$Q$154 -> 0 | AK17: =$AK$8 -> 0 | AL17: =IF(ISERROR($AN17/AO17),"-",$AN17/AO17) -> - | AM17: =IF(ISERROR($AN17/AP17),"-",$AN17/AP17) -> - | AR17: =$AR$8 -> 0 | AS17: =IF(ISERROR($AU17/AV17),"-",$AU17/AV17) -> - | AT17: =IF(ISERROR($AU17/AW17),"-",$AU17/AW17) -> - | AY17: =AY8 -> 0 | AZ17: =IF(ISERROR($BB17/BC17),"-",$BB17/BC17) -> - | BA17: =IF(ISERROR($BB17/BD17),"-",$BB17/BD17) -> - | BF17: =BF8 -> 17:00~18:00 | BG17: =IF(ISERROR($BI17/BJ17),"-",$BI17/BJ17) -> - | BH17: =IF(ISERROR($BI17/BK17),"-",$BI17/BK17) -> - | BI17: =('假日(16-18)'!$K$97+'假日(16-18)'!$K$116+'假日(16-18)'!$K$135+'假日(16-18)'!$K$154)*15 -> 0 | BJ17: ='假日(16-18)'!$O$97+'假日(16-18)'!$O$116+'假日(16-18)'!$O$135+'假日(16-18)'!$O$154 -> 0 | BK17: ='假日(16-18)'!$Q$97+'假日(16-18)'!$Q$116+'假日(16-18)'!$Q$135+'假日(16-18)'!$Q$154 -> 0 | BM17: =BM8 -> 18:00~19:00 | BN17: =IF(ISERROR($BP17/BQ17),"-",$BP17/BQ17) -> - | BO17: =IF(ISERROR($BP17/BR17),"-",$BP17/BR17) -> - | BP17: =('假日(17-19)'!$K$97+'假日(17-19)'!$K$116+'假日(17-19)'!$K$135+'假日(17-19)'!$K$154)*15 -> 0 | BQ17: ='假日(17-19)'!$O$97+'假日(17-19)'!$O$116+'假日(17-19)'!$O$135+'假日(17-19)'!$O$154 -> 0 | BR17: ='假日(17-19)'!$Q$97+'假日(17-19)'!$Q$116+'假日(17-19)'!$Q$135+'假日(17-19)'!$Q$154 -> 0 | BT17: =CONCATENATE(基本資料!$B$18,"方向","平均延滯") -> A方向平均延滯 | BU17: =IF(ISERROR(VLOOKUP($BX$85,資料分析!BT4:BU16,2,1)),"-",VLOOKUP($BX$85,BT4:BU16,2,1)) -> -
B18: =CONCATENATE(基本資料!$C$18,"方向","平均延滯") -> B方向平均延滯 | C18: =IF(ISERROR(VLOOKUP($F$45,B13:C17,2,1)),"-",VLOOKUP($F$45,B13:C17,2,1)) -> - | I18: =CONCATENATE(基本資料!$C$18,"方向","平均延滯") -> B方向平均延滯 | J18: =IF(ISERROR(VLOOKUP($M$45,I13:J17,2,1)),"-",VLOOKUP($M$45,I13:J17,2,1)) -> - | P18: =CONCATENATE(基本資料!$C$18,"方向","平均延滯") -> B方向平均延滯 | Q18: =IF(ISERROR(VLOOKUP($T$45,P13:Q17,2,1)),"-",VLOOKUP($T$45,P13:Q17,2,1)) -> - | W18: =CONCATENATE(基本資料!$C$18,"方向","平均延滯") -> B方向平均延滯 | X18: =IF(ISERROR(VLOOKUP($AA$45,W13:X17,2,1)),"-",VLOOKUP($AA$45,W13:X17,2,1)) -> - | AD18: =CONCATENATE(基本資料!$C$18,"方向","平均延滯") -> B方向平均延滯 | AE18: =IF(ISERROR(VLOOKUP($AH$45,AD13:AE17,2,1)),"-",VLOOKUP($AH$45,AD13:AE17,2,1)) -> - | AK18: =CONCATENATE(基本資料!$C$18,"方向","平均延滯") -> B方向平均延滯 | AL18: =IF(ISERROR(VLOOKUP($AO$45,AK13:AL17,2,1)),"-",VLOOKUP($AO$45,AK13:AL17,2,1)) -> - | AR18: =CONCATENATE(基本資料!$C$18,"方向","平均延滯") -> B方向平均延滯 | AS18: =IF(ISERROR(VLOOKUP($AV$45,AR13:AS17,2,1)),"-",VLOOKUP($AV$45,AR13:AS17,2,1)) -> - | AY18: =CONCATENATE(基本資料!$C$18,"方向","平均延滯") -> B方向平均延滯 | AZ18: =IF(ISERROR(VLOOKUP($BC$45,AY13:AZ17,2,1)),"-",VLOOKUP($BC$45,AY13:AZ17,2,1)) -> - | BF18: =CONCATENATE(基本資料!$C$18,"方向","平均延滯") -> B方向平均延滯 | BG18: =IF(ISERROR(VLOOKUP($BJ$45,BF13:BG17,2,1)),"-",VLOOKUP($BJ$45,BF13:BG17,2,1)) -> - | BM18: =CONCATENATE(基本資料!$C$18,"方向","平均延滯") -> B方向平均延滯 | BN18: =IF(ISERROR(VLOOKUP($BQ$45,BM13:BN17,2,1)),"-",VLOOKUP($BQ$45,BM13:BN17,2,1)) -> - | BT18: =CONCATENATE(基本資料!$B$18,"方向","平均停等車輛延滯") -> A方向平均停等車輛延滯 | BV18: =IF(ISERROR(VLOOKUP($BX$86,BT4:BV16,3,1)),"-",VLOOKUP($BX$86,BT4:BV16,3,1)) -> -
B19: =CONCATENATE(基本資料!$C$18,"方向","平均停等車輛延滯") -> B方向平均停等車輛延滯 | D19: =IF(ISERROR(VLOOKUP($F$46,B13:D17,3,1)),"-",VLOOKUP($F$46,B13:D17,3,1)) -> - | I19: =CONCATENATE(基本資料!$C$18,"方向","平均停等車輛延滯") -> B方向平均停等車輛延滯 | K19: =IF(ISERROR(VLOOKUP($M$46,I13:K17,3,1)),"-",VLOOKUP($M$46,I13:K17,3,1)) -> - | P19: =CONCATENATE(基本資料!$C$18,"方向","平均停等車輛延滯") -> B方向平均停等車輛延滯 | R19: =IF(ISERROR(VLOOKUP($T$46,P13:R17,3,1)),"-",VLOOKUP($T$46,P13:R17,3,1)) -> - | W19: =CONCATENATE(基本資料!$C$18,"方向","平均停等車輛延滯") -> B方向平均停等車輛延滯 | Y19: =IF(ISERROR(VLOOKUP($AA$46,W13:Y17,3,1)),"-",VLOOKUP($AA$46,W13:Y17,3,1)) -> - | AD19: =CONCATENATE(基本資料!$C$18,"方向","平均停等車輛延滯") -> B方向平均停等車輛延滯 | AF19: =IF(ISERROR(VLOOKUP($AH$46,AD13:AF17,3,1)),"-",VLOOKUP($AH$46,AD13:AF17,3,1)) -> - | AK19: =CONCATENATE(基本資料!$C$18,"方向","平均停等車輛延滯") -> B方向平均停等車輛延滯 | AM19: =IF(ISERROR(VLOOKUP($AO$46,AK13:AM17,3,1)),"-",VLOOKUP($AO$46,AK13:AM17,3,1)) -> - | AR19: =CONCATENATE(基本資料!$C$18,"方向","平均停等車輛延滯") -> B方向平均停等車輛延滯 | AT19: =IF(ISERROR(VLOOKUP($AV$46,AR13:AT17,3,1)),"-",VLOOKUP($AV$46,AR13:AT17,3,1)) -> - | AY19: =CONCATENATE(基本資料!$C$18,"方向","平均停等車輛延滯") -> B方向平均停等車輛延滯 | BA19: =IF(ISERROR(VLOOKUP($BC$46,AY13:BA17,3,1)),"-",VLOOKUP($BC$46,AY13:BA17,3,1)) -> - | BF19: =CONCATENATE(基本資料!$C$18,"方向","平均停等車輛延滯") -> B方向平均停等車輛延滯 | BH19: =IF(ISERROR(VLOOKUP($BJ$46,BF13:BH17,3,1)),"-",VLOOKUP($BJ$46,BF13:BH17,3,1)) -> - | BM19: =CONCATENATE(基本資料!$C$18,"方向","平均停等車輛延滯") -> B方向平均停等車輛延滯 | BO19: =IF(ISERROR(VLOOKUP($BQ$46,BM13:BO17,3,1)),"-",VLOOKUP($BQ$46,BM13:BO17,3,1)) -> - | BT19: ='假日(16-18)'!$J$2 -> B方向：
B20: ='平日晨峰(07-09)'!$S$2 -> C方向： | I20: ='平日晨峰(07-09)'!$S$2 -> C方向： | P20: ='平日中午(11-13)'!$S$2 -> C方向： | W20: ='平日中午(11-13)'!$S$2 -> C方向： | AD20: ='平日昏峰(17-19)'!$S$2 -> C方向： | AK20: ='假日(11-12)'!$S$2 -> C方向： | AR20: ='假日(1430-1530)'!$S$2 -> C方向： | AY20: ='假日(1730-1830)'!$S$2 -> C方向： | BF20: ='假日(16-18)'!$S$2 -> C方向： | BM20: ='假日(17-19)'!$S$2 -> C方向： | BT20: 時間 | BU20: 平均延滯 | BV20: 平均停等延滯 | BW20: 總延滯 | BX20: 車輛總數 | BY20: 停等車輛數
B21: 時間 | C21: 平均延滯 | D21: 平均停等延滯 | E21: 總延滯 | F21: 車輛總數 | G21: 停等車輛數 | I21: 時間 | J21: 平均延滯 | K21: 平均停等延滯 | L21: 總延滯 | M21: 車輛總數 | N21: 停等車輛數 | P21: 時間 | Q21: 平均延滯 | R21: 平均停等延滯 | S21: 總延滯 | T21: 車輛總數 | U21: 停等車輛數 | W21: 時間 | X21: 平均延滯 | Y21: 平均停等延滯 | Z21: 總延滯 | AA21: 車輛總數 | AB21: 停等車輛數 | AD21: 時間 | AE21: 平均延滯 | AF21: 平均停等延滯 | AG21: 總延滯 | AH21: 車輛總數 | AI21: 停等車輛數 | AK21: 時間 | AL21: 平均延滯 | AM21: 平均停等延滯 | AN21: 總延滯 | AO21: 車輛總數 | AP21: 停等車輛數 | AR21: 時間 | AS21: 平均延滯 | AT21: 平均停等延滯 | AU21: 總延滯 | AV21: 車輛總數 | AW21: 停等車輛數 | AY21: 時間 | AZ21: 平均延滯 | BA21: 平均停等延滯 | BB21: 總延滯 | BC21: 車輛總數 | BD21: 停等車輛數 | BF21: 時間 | BG21: 平均延滯 | BH21: 平均停等延滯 | BI21: 總延滯 | BJ21: 車輛總數 | BK21: 停等車輛數 | BM21: 時間 | BN21: 平均延滯 | BO21: 平均停等延滯 | BP21: 總延滯 | BQ21: 車輛總數 | BR21: 停等車輛數 | BT21: 16:00~17:00 | BU21: =IF(ISERROR($BW21/BX21),"-",$BW21/BX21) -> - | BV21: =IF(ISERROR($BW21/BY21),"-",$BW21/BY21) -> - | BW21: =('假日(16-20)'!$K$21+'假日(16-20)'!$K$40+'假日(16-20)'!$K$59+'假日(16-20)'!$K$78)*15 -> 0 | BX21: ='假日(16-20)'!$O$21+'假日(16-20)'!$O$40+'假日(16-20)'!$O$59+'假日(16-20)'!$O$78 -> 0 | BY21: ='假日(16-20)'!$Q$21+'假日(16-20)'!$Q$40+'假日(16-20)'!$Q$59+'假日(16-20)'!$Q$78 -> 0
B22: 06:30~07:30 | C22: =IF(ISERROR($E22/F22),"-",$E22/F22) -> - | D22: =IF(ISERROR($E22/G22),"-",$E22/G22) -> - | E22: =('平日晨峰(0630-0830)'!$T$21+'平日晨峰(0630-0830)'!$T$40+'平日晨峰(0630-0830)'!$T$59+'平日晨峰(0630-0830)'!$T$78)*15 -> 0 | F22: ='平日晨峰(0630-0830)'!$X$21+'平日晨峰(0630-0830)'!$X$40+'平日晨峰(0630-0830)'!$X$59+'平日晨峰(0630-0830)'!$X$78 -> 0 | G22: ='平日晨峰(0630-0830)'!$Z$21+'平日晨峰(0630-0830)'!$Z$40+'平日晨峰(0630-0830)'!$Z$59+'平日晨峰(0630-0830)'!$Z$78 -> 0 | I22: =$I$4 -> 07:00~08:00 | J22: =IF(ISERROR($L22/M22),"-",$L22/M22) -> - | K22: =IF(ISERROR($L22/N22),"-",$L22/N22) -> - | L22: =('平日晨峰(07-09)'!$T$21+'平日晨峰(07-09)'!$T$40+'平日晨峰(07-09)'!$T$59+'平日晨峰(07-09)'!$T$78)*15 -> 0 | M22: ='平日晨峰(07-09)'!$X$21+'平日晨峰(07-09)'!$X$40+'平日晨峰(07-09)'!$X$59+'平日晨峰(07-09)'!$X$78 -> 0 | N22: ='平日晨峰(07-09)'!$Z$21+'平日晨峰(07-09)'!$Z$40+'平日晨峰(07-09)'!$Z$59+'平日晨峰(07-09)'!$Z$78 -> 0 | P22: =P13 -> 11:00~12:00 | Q22: =IF(ISERROR($S22/T22),"-",$S22/T22) -> - | R22: =IF(ISERROR($T22/U22),"-",$T22/U22) -> - | S22: =('平日中午(11-13)'!$T$21+'平日中午(11-13)'!$T$40+'平日中午(11-13)'!$T$59+'平日中午(11-13)'!$T$78)*15 -> 0 | T22: ='平日中午(11-13)'!$X$21+'平日中午(11-13)'!$X$40+'平日中午(11-13)'!$X$59+'平日中午(11-13)'!$X$78 -> 0 | U22: ='平日中午(11-13)'!$Z$21+'平日中午(11-13)'!$Z$40+'平日中午(11-13)'!$Z$59+'平日中午(11-13)'!$Z$78 -> 0 | W22: =W13 -> 1200~13:00 | X22: =IF(ISERROR($Z22/AA22),"-",$Z22/AA22) -> - | Y22: =IF(ISERROR($Z22/AB22),"-",$Z22/AB22) -> - | Z22: =('平日中午(12-14)'!$T$21+'平日中午(12-14)'!$T$40+'平日中午(12-14)'!$T$59+'平日中午(12-14)'!$T$78)*15 -> 0 | AA22: ='平日中午(12-14)'!$X$21+'平日中午(12-14)'!$X$40+'平日中午(12-14)'!$X$59+'平日中午(12-14)'!$X$78 -> 0 | AB22: ='平日中午(12-14)'!$Z$21+'平日中午(12-14)'!$Z$40+'平日中午(12-14)'!$Z$59+'平日中午(12-14)'!$Z$78 -> 0 | AD22: =$AD$4 -> 17:00~18:00 | AE22: =IF(ISERROR($AG22/AH22),"-",$AG22/AH22) -> - | AF22: =IF(ISERROR($AG22/AI22),"-",$AG22/AI22) -> - | AG22: =('平日昏峰(17-19)'!$T$21+'平日昏峰(17-19)'!$T$40+'平日昏峰(17-19)'!$T$59+'平日昏峰(17-19)'!$T$78)*15 -> 0 | AH22: ='平日昏峰(17-19)'!$X$21+'平日昏峰(17-19)'!$X$40+'平日昏峰(17-19)'!$X$59+'平日昏峰(17-19)'!$X$78 -> 0 | AI22: ='平日昏峰(17-19)'!$Z$21+'平日昏峰(17-19)'!$Z$40+'平日昏峰(17-19)'!$Z$59+'平日昏峰(17-19)'!$Z$78 -> 0 | AK22: =$AK$4 -> 11:00~12:00 | AL22: =IF(ISERROR($AN22/AO22),"-",$AN22/AO22) -> - | AM22: =IF(ISERROR($AN22/AP22),"-",$AN22/AP22) -> - | AN22: =('假日(11-12)'!$T$21+'假日(11-12)'!$T$40+'假日(11-12)'!$T$59+'假日(11-12)'!$T$78)*15 -> 0 | AO22: ='假日(11-12)'!$X$21+'假日(11-12)'!$X$40+'假日(11-12)'!$X$59+'假日(11-12)'!$X$78 -> 0 | AP22: ='假日(11-12)'!$Z$21+'假日(11-12)'!$Z$40+'假日(11-12)'!$Z$59+'假日(11-12)'!$Z$78 -> 0 | AR22: =$AR$4 -> 14:30~15:30 | AS22: =IF(ISERROR($AU22/AV22),"-",$AU22/AV22) -> - | AT22: =IF(ISERROR($AU22/AW22),"-",$AU22/AW22) -> - | AU22: =('假日(1430-1530)'!$T$21+'假日(1430-1530)'!$T$40+'假日(1430-1530)'!$T$59+'假日(1430-1530)'!$T$78)*15 -> 0 | AV22: ='假日(1430-1530)'!$X$21+'假日(1430-1530)'!$X$40+'假日(1430-1530)'!$X$59+'假日(1430-1530)'!$X$78 -> 0 | AW22: ='假日(1430-1530)'!$Z$21+'假日(1430-1530)'!$Z$40+'假日(1430-1530)'!$Z$59+'假日(1430-1530)'!$Z$78 -> 0 | AY22: =AY13 -> 17:30~18:30 | AZ22: =IF(ISERROR($BB22/BC22),"-",$BB22/BC22) -> - | BA22: =IF(ISERROR($BB22/BD22),"-",$BB22/BD22) -> - | BB22: =('假日(1730-1830)'!$T$21+'假日(1730-1830)'!$T$40+'假日(1730-1830)'!$T$59+'假日(1730-1830)'!$T$78)*15 -> 0 | BC22: ='假日(1730-1830)'!$X$21+'假日(1730-1830)'!$X$40+'假日(1730-1830)'!$X$59+'假日(1730-1830)'!$X$78 -> 0 | BD22: ='假日(1730-1830)'!$Z$21+'假日(1730-1830)'!$Z$40+'假日(1730-1830)'!$Z$59+'假日(1730-1830)'!$Z$78 -> 0 | BF22: =BF13 -> 16:00~17:00 | BG22: =IF(ISERROR($BI22/BJ22),"-",$BI22/BJ22) -> - | BH22: =IF(ISERROR($BI22/BK22),"-",$BI22/BK22) -> - | BI22: =('假日(16-18)'!$T$21+'假日(16-18)'!$T$40+'假日(16-18)'!$T$59+'假日(16-18)'!$T$78)*15 -> 0 | BJ22: ='假日(16-18)'!$X$21+'假日(16-18)'!$X$40+'假日(16-18)'!$X$59+'假日(16-18)'!$X$78 -> 0 | BK22: ='假日(16-18)'!$Z$21+'假日(16-18)'!$Z$40+'假日(16-18)'!$Z$59+'假日(16-18)'!$Z$78 -> 0 | BM22: =BM13 -> 17:00~18:00 | BN22: =IF(ISERROR($BP22/BQ22),"-",$BP22/BQ22) -> - | BO22: =IF(ISERROR($BP22/BR22),"-",$BP22/BR22) -> - | BP22: =('假日(17-19)'!$T$21+'假日(17-19)'!$T$40+'假日(17-19)'!$T$59+'假日(17-19)'!$T$78)*15 -> 0 | BQ22: ='假日(17-19)'!$X$21+'假日(17-19)'!$X$40+'假日(17-19)'!$X$59+'假日(17-19)'!$X$78 -> 0 | BR22: ='假日(17-19)'!$Z$21+'假日(17-19)'!$Z$40+'假日(17-19)'!$Z$59+'假日(17-19)'!$Z$78 -> 0 | BT22: 16:15~17:15 | BU22: =IF(ISERROR($BW22/BX22),"-",$BW22/BX22) -> - | BV22: =IF(ISERROR($BW22/BY22),"-",$BW22/BY22) -> - | BW22: =('假日(16-20)'!$K$40+'假日(16-20)'!$K$59+'假日(16-20)'!$K$78+'假日(16-20)'!$K$97)*15 -> 0 | BX22: ='假日(16-20)'!$O$40+'假日(16-20)'!$O$59+'假日(16-20)'!$O$78+'假日(16-20)'!$O$97 -> 0 | BY22: ='假日(16-20)'!$Q$40+'假日(16-20)'!$Q$59+'假日(16-20)'!$Q$78+'假日(16-20)'!$Q$97 -> 0
B23: 06:45~07:45 | C23: =IF(ISERROR($E23/F23),"-",$E23/F23) -> - | D23: =IF(ISERROR($E23/G23),"-",$E23/G23) -> - | E23: =('平日晨峰(0630-0830)'!$T$40+'平日晨峰(0630-0830)'!$T$59+'平日晨峰(0630-0830)'!$T$78+'平日晨峰(0630-0830)'!$T$97)*15 -> 0 | F23: ='平日晨峰(0630-0830)'!$X$40+'平日晨峰(0630-0830)'!$X$59+'平日晨峰(0630-0830)'!$X$78+'平日晨峰(0630-0830)'!$X$97 -> 0 | G23: ='平日晨峰(0630-0830)'!$Z$40+'平日晨峰(0630-0830)'!$Z$59+'平日晨峰(0630-0830)'!$Z$78+'平日晨峰(0630-0830)'!$Z$97 -> 0 | I23: =$I$5 -> 07:15~08:15 | J23: =IF(ISERROR($L23/M23),"-",$L23/M23) -> - | K23: =IF(ISERROR($L23/N23),"-",$L23/N23) -> - | L23: =('平日晨峰(07-09)'!$T$40+'平日晨峰(07-09)'!$T$59+'平日晨峰(07-09)'!$T$78+'平日晨峰(07-09)'!$T$97)*15 -> 0 | M23: ='平日晨峰(07-09)'!$X$40+'平日晨峰(07-09)'!$X$59+'平日晨峰(07-09)'!$X$78+'平日晨峰(07-09)'!$X$97 -> 0 | N23: ='平日晨峰(07-09)'!$Z$40+'平日晨峰(07-09)'!$Z$59+'平日晨峰(07-09)'!$Z$78+'平日晨峰(07-09)'!$Z$97 -> 0 | P23: =P14 -> 11:15~12:15 | Q23: =IF(ISERROR($S23/T23),"-",$S23/T23) -> - | R23: =IF(ISERROR($T23/U23),"-",$T23/U23) -> - | S23: =('平日中午(11-13)'!$T$40+'平日中午(11-13)'!$T$59+'平日中午(11-13)'!$T$78+'平日中午(11-13)'!$T$97)*15 -> 0 | T23: ='平日中午(11-13)'!$X$40+'平日中午(11-13)'!$X$59+'平日中午(11-13)'!$X$78+'平日中午(11-13)'!$X$97 -> 0 | U23: ='平日中午(11-13)'!$Z$40+'平日中午(11-13)'!$Z$59+'平日中午(11-13)'!$Z$78+'平日中午(11-13)'!$Z$97 -> 0 | W23: =W14 -> 12:15~13:15 | X23: =IF(ISERROR($Z23/AA23),"-",$Z23/AA23) -> - | Y23: =IF(ISERROR($Z23/AB23),"-",$Z23/AB23) -> - | Z23: =('平日中午(12-14)'!$T$40+'平日中午(12-14)'!$T$59+'平日中午(12-14)'!$T$78+'平日中午(12-14)'!$T$97)*15 -> 0 | AA23: ='平日中午(12-14)'!$X$40+'平日中午(12-14)'!$X$59+'平日中午(12-14)'!$X$78+'平日中午(12-14)'!$X$97 -> 0 | AB23: ='平日中午(12-14)'!$Z$40+'平日中午(12-14)'!$Z$59+'平日中午(12-14)'!$Z$78+'平日中午(12-14)'!$Z$97 -> 0 | AD23: =$AD$5 -> 17:15~18:15 | AE23: =IF(ISERROR($AG23/AH23),"-",$AG23/AH23) -> - | AF23: =IF(ISERROR($AG23/AI23),"-",$AG23/AI23) -> - | AG23: =('平日昏峰(17-19)'!$T$40+'平日昏峰(17-19)'!$T$59+'平日昏峰(17-19)'!$T$78+'平日昏峰(17-19)'!$T$97)*15 -> 0 | AH23: ='平日昏峰(17-19)'!$X$40+'平日昏峰(17-19)'!$X$59+'平日昏峰(17-19)'!$X$78+'平日昏峰(17-19)'!$X$97 -> 0 | AI23: ='平日昏峰(17-19)'!$Z$40+'平日昏峰(17-19)'!$Z$59+'平日昏峰(17-19)'!$Z$78+'平日昏峰(17-19)'!$Z$97 -> 0 | AK23: =$AK$5 -> 0 | AL23: =IF(ISERROR($AN23/AO23),"-",$AN23/AO23) -> - | AM23: =IF(ISERROR($AN23/AP23),"-",$AN23/AP23) -> - | AR23: =$AR$5 -> 0 | AS23: =IF(ISERROR($AU23/AV23),"-",$AU23/AV23) -> - | AT23: =IF(ISERROR($AU23/AW23),"-",$AU23/AW23) -> - | AY23: =AY14 -> 0 | AZ23: =IF(ISERROR($BB23/BC23),"-",$BB23/BC23) -> - | BA23: =IF(ISERROR($BB23/BD23),"-",$BB23/BD23) -> - | BF23: =BF14 -> 16:15~17:15 | BG23: =IF(ISERROR($BI23/BJ23),"-",$BI23/BJ23) -> - | BH23: =IF(ISERROR($BI23/BK23),"-",$BI23/BK23) -> - | BI23: =('假日(16-18)'!$T$40+'假日(16-18)'!$T$59+'假日(16-18)'!$T$78+'假日(16-18)'!$T$97)*15 -> 0 | BJ23: ='假日(16-18)'!$X$40+'假日(16-18)'!$X$59+'假日(16-18)'!$X$78+'假日(16-18)'!$X$97 -> 0 | BK23: ='假日(16-18)'!$Z$40+'假日(16-18)'!$Z$59+'假日(16-18)'!$Z$78+'假日(16-18)'!$Z$97 -> 0 | BM23: =BM14 -> 17:15~18:15 | BN23: =IF(ISERROR($BP23/BQ23),"-",$BP23/BQ23) -> - | BO23: =IF(ISERROR($BP23/BR23),"-",$BP23/BR23) -> - | BP23: =('假日(17-19)'!$T$40+'假日(17-19)'!$T$59+'假日(17-19)'!$T$78+'假日(17-19)'!$T$97)*15 -> 0 | BQ23: ='假日(17-19)'!$X$40+'假日(17-19)'!$X$59+'假日(17-19)'!$X$78+'假日(17-19)'!$X$97 -> 0 | BR23: ='假日(17-19)'!$Z$40+'假日(17-19)'!$Z$59+'假日(17-19)'!$Z$78+'假日(17-19)'!$Z$97 -> 0 | BT23: 16:30~17:30 | BU23: =IF(ISERROR($BW23/BX23),"-",$BW23/BX23) -> - | BV23: =IF(ISERROR($BW23/BY23),"-",$BW23/BY23) -> - | BW23: =('假日(16-20)'!$K$59+'假日(16-20)'!$K$78+'假日(16-20)'!$K$97+'假日(16-20)'!$K$116)*15 -> 0 | BX23: ='假日(16-20)'!$O$59+'假日(16-20)'!$O$78+'假日(16-20)'!$O$97+'假日(16-20)'!$O$116 -> 0 | BY23: ='假日(16-20)'!$Q$59+'假日(16-20)'!$Q$78+'假日(16-20)'!$Q$97+'假日(16-20)'!$Q$116 -> 0
