Workbook
Name _PCU11: [1]基本!$B$35
Name _PCU12: [1]基本!$C$35
Name _PCU13: [1]基本!$D$35
Name _PCU14: [1]基本!$E$35
Name _PCU21: [1]基本!$F$35
Name _PCU22: [1]基本!$G$35
Name _PCU23: [1]基本!$H$35
Name _PCU31: [1]基本!$I$35
Name _PCU32: [1]基本!$J$35
Name _PCU33: [1]基本!$K$35
Name GAM: #REF!
Name GINFO: #REF!
Name GPM: #REF!
Name GRAPH: #REF!
Name HN: [1]集賢!$M$1
Name PCUa11: [2]計算!#REF!
Name PCUa12: [2]計算!#REF!
Name PCUa13: [2]計算!#REF!
Name PCUa14: [2]計算!#REF!
Name PCUa21: [2]計算!#REF!
Name PCUa22: [2]計算!#REF!
Name PCUa23: [2]計算!#REF!
Name PCUa31: [2]計算!#REF!
Name PCUa32: [2]計算!#REF!
Name PCUa33: [2]計算!#REF!
Name ROADNAME: [3]基本!$I$5,[3]基本!$G$9,[3]基本!$E$5,[3]基本!$G$1
Name TABLE: #REF!
Name 尖峰: #REF!
Name 夜間: #REF!
Name 時制A: #REF!,#REF!,#REF!,#REF!,#REF!
Name 時制B: #REF!,#REF!,#REF!,#REF!,#REF!
Name 假日: #REF!
Name 週五夜: #REF!
Name 離峰: #REF!

Sheet 轉向量
A1: 套用PCE | E1: 大車左轉 | F1: 大車直行 | G1: 大車右轉 | I1: 小車左轉 | J1: 小車直行 | K1: 小車右轉 | N1: 機車二段左轉 | O1: 機車左轉 | Q1: 機車直行 | S1: 機車右轉
E2: 2 | F2: 1.8 | G2: 2.7 | I2: 1.05 | J2: 1 | K2: 1.08 | N2: 0 | O2: 0.43 | Q2: 0.42 | S2: 0.45
A4: 臨近路段 | B4: 起始時間 | C4: 結束時間 | D4: 大車A | E4: 大車B | F4: 大車C | G4: 大車D | H4: 大車E | I4: 小車A | J4: 小車B | K4: 小車C | L4: 小車D | M4: 小車E | N4: 機車A | O4: 機車B | P4: 機車C | Q4: 機車D | R4: 機車E
A5: A | B5: 0 | C5: 0.010416667 | D5: - | E5: ='調查(集賢)'!S2+'調查(集賢)'!T2+'調查(集賢)'!U2+'調查(集賢)'!V2+'調查(集賢)'!W2+'調查(集賢)'!X2 -> 0 | F5: ='調查(集賢)'!AH2+'調查(集賢)'!AI2+'調查(集賢)'!AJ2+'調查(集賢)'!AK2+'調查(集賢)'!AL2+'調查(集賢)'!AM2 -> 0 | G5: ='調查(集賢)'!AW2+'調查(集賢)'!AX2+'調查(集賢)'!AY2+'調查(集賢)'!AZ2+'調查(集賢)'!BA2+'調查(集賢)'!BB2 -> 0 | H5: ='調查(集賢)'!BL2+'調查(集賢)'!BM2+'調查(集賢)'!BN2+'調查(集賢)'!BO2+'調查(集賢)'!BP2+'調查(集賢)'!BQ2 -> 0 | I5: - | J5: ='調查(集賢)'!Y2+'調查(集賢)'!Z2+'調查(集賢)'!AA2+'調查(集賢)'!AB2 -> 0 | K5: ='調查(集賢)'!AN2+'調查(集賢)'!AO2+'調查(集賢)'!AP2+'調查(集賢)'!AQ2 -> 0 | L5: ='調查(集賢)'!BC2+'調查(集賢)'!BD2+'調查(集賢)'!BE2+'調查(集賢)'!BF2 -> 0 | M5: ='調查(集賢)'!BR2+'調查(集賢)'!BS2+'調查(集賢)'!BT2+'調查(集賢)'!BU2 -> 0 | N5: - | O5: ='調查(集賢)'!AC2+'調查(集賢)'!AD2+'調查(集賢)'!AE2 -> 0 | P5: ='調查(集賢)'!AR2+'調查(集賢)'!AS2+'調查(集賢)'!AT2 -> 0 | Q5: ='調查(集賢)'!BG2+'調查(集賢)'!BH2+'調查(集賢)'!BI2 -> 0 | R5: ='調查(集賢)'!BV2+'調查(集賢)'!BW2+'調查(集賢)'!BX2 -> 0
A6: A | B6: 0.010416667 | C6: 0.020833333 | D6: - | E6: ='調查(集賢)'!S3+'調查(集賢)'!T3+'調查(集賢)'!U3+'調查(集賢)'!V3+'調查(集賢)'!W3+'調查(集賢)'!X3 -> 0 | F6: ='調查(集賢)'!AH3+'調查(集賢)'!AI3+'調查(集賢)'!AJ3+'調查(集賢)'!AK3+'調查(集賢)'!AL3+'調查(集賢)'!AM3 -> 0 | G6: ='調查(集賢)'!AW3+'調查(集賢)'!AX3+'調查(集賢)'!AY3+'調查(集賢)'!AZ3+'調查(集賢)'!BA3+'調查(集賢)'!BB3 -> 0 | H6: ='調查(集賢)'!BL3+'調查(集賢)'!BM3+'調查(集賢)'!BN3+'調查(集賢)'!BO3+'調查(集賢)'!BP3+'調查(集賢)'!BQ3 -> 0 | I6: - | J6: ='調查(集賢)'!Y3+'調查(集賢)'!Z3+'調查(集賢)'!AA3+'調查(集賢)'!AB3 -> 0 | K6: ='調查(集賢)'!AN3+'調查(集賢)'!AO3+'調查(集賢)'!AP3+'調查(集賢)'!AQ3 -> 0 | L6: ='調查(集賢)'!BC3+'調查(集賢)'!BD3+'調查(集賢)'!BE3+'調查(集賢)'!BF3 -> 0 | M6: ='調查(集賢)'!BR3+'調查(集賢)'!BS3+'調查(集賢)'!BT3+'調查(集賢)'!BU3 -> 0 | N6: - | O6: ='調查(集賢)'!AC3+'調查(集賢)'!AD3+'調查(集賢)'!AE3 -> 0 | P6: ='調查(集賢)'!AR3+'調查(集賢)'!AS3+'調查(集賢)'!AT3 -> 0 | Q6: ='調查(集賢)'!BG3+'調查(集賢)'!BH3+'調查(集賢)'!BI3 -> 0 | R6: ='調查(集賢)'!BV3+'調查(集賢)'!BW3+'調查(集賢)'!BX3 -> 0
A7: A | B7: 0.020833333 | C7: 0.03125 | D7: - | E7: ='調查(集賢)'!S4+'調查(集賢)'!T4+'調查(集賢)'!U4+'調查(集賢)'!V4+'調查(集賢)'!W4+'調查(集賢)'!X4 -> 0 | F7: ='調查(集賢)'!AH4+'調查(集賢)'!AI4+'調查(集賢)'!AJ4+'調查(集賢)'!AK4+'調查(集賢)'!AL4+'調查(集賢)'!AM4 -> 0 | G7: ='調查(集賢)'!AW4+'調查(集賢)'!AX4+'調查(集賢)'!AY4+'調查(集賢)'!AZ4+'調查(集賢)'!BA4+'調查(集賢)'!BB4 -> 0 | H7: ='調查(集賢)'!BL4+'調查(集賢)'!BM4+'調查(集賢)'!BN4+'調查(集賢)'!BO4+'調查(集賢)'!BP4+'調查(集賢)'!BQ4 -> 0 | I7: - | J7: ='調查(集賢)'!Y4+'調查(集賢)'!Z4+'調查(集賢)'!AA4+'調查(集賢)'!AB4 -> 0 | K7: ='調查(集賢)'!AN4+'調查(集賢)'!AO4+'調查(集賢)'!AP4+'調查(集賢)'!AQ4 -> 0 | L7: ='調查(集賢)'!BC4+'調查(集賢)'!BD4+'調查(集賢)'!BE4+'調查(集賢)'!BF4 -> 0 | M7: ='調查(集賢)'!BR4+'調查(集賢)'!BS4+'調查(集賢)'!BT4+'調查(集賢)'!BU4 -> 0 | N7: - | O7: ='調查(集賢)'!AC4+'調查(集賢)'!AD4+'調查(集賢)'!AE4 -> 0 | P7: ='調查(集賢)'!AR4+'調查(集賢)'!AS4+'調查(集賢)'!AT4 -> 0 | Q7: ='調查(集賢)'!BG4+'調查(集賢)'!BH4+'調查(集賢)'!BI4 -> 0 | R7: ='調查(集賢)'!BV4+'調查(集賢)'!BW4+'調查(集賢)'!BX4 -> 0
A8: A | B8: 0.03125 | C8: 0.041666667 | D8: - | E8: ='調查(集賢)'!S5+'調查(集賢)'!T5+'調查(集賢)'!U5+'調查(集賢)'!V5+'調查(集賢)'!W5+'調查(集賢)'!X5 -> 0 | F8: ='調查(集賢)'!AH5+'調查(集賢)'!AI5+'調查(集賢)'!AJ5+'調查(集賢)'!AK5+'調查(集賢)'!AL5+'調查(集賢)'!AM5 -> 0 | G8: ='調查(集賢)'!AW5+'調查(集賢)'!AX5+'調查(集賢)'!AY5+'調查(集賢)'!AZ5+'調查(集賢)'!BA5+'調查(集賢)'!BB5 -> 0 | H8: ='調查(集賢)'!BL5+'調查(集賢)'!BM5+'調查(集賢)'!BN5+'調查(集賢)'!BO5+'調查(集賢)'!BP5+'調查(集賢)'!BQ5 -> 0 | I8: - | J8: ='調查(集賢)'!Y5+'調查(集賢)'!Z5+'調查(集賢)'!AA5+'調查(集賢)'!AB5 -> 0 | K8: ='調查(集賢)'!AN5+'調查(集賢)'!AO5+'調查(集賢)'!AP5+'調查(集賢)'!AQ5 -> 0 | L8: ='調查(集賢)'!BC5+'調查(集賢)'!BD5+'調查(集賢)'!BE5+'調查(集賢)'!BF5 -> 0 | M8: ='調查(集賢)'!BR5+'調查(集賢)'!BS5+'調查(集賢)'!BT5+'調查(集賢)'!BU5 -> 0 | N8: - | O8: ='調查(集賢)'!AC5+'調查(集賢)'!AD5+'調查(集賢)'!AE5 -> 0 | P8: ='調查(集賢)'!AR5+'調查(集賢)'!AS5+'調查(集賢)'!AT5 -> 0 | Q8: ='調查(集賢)'!BG5+'調查(集賢)'!BH5+'調查(集賢)'!BI5 -> 0 | R8: ='調查(集賢)'!BV5+'調查(集賢)'!BW5+'調查(集賢)'!BX5 -> 0
A9: A | B9: 0.041666667 | C9: 0.052083333 | D9: - | E9: ='調查(集賢)'!S6+'調查(集賢)'!T6+'調查(集賢)'!U6+'調查(集賢)'!V6+'調查(集賢)'!W6+'調查(集賢)'!X6 -> 0 | F9: ='調查(集賢)'!AH6+'調查(集賢)'!AI6+'調查(集賢)'!AJ6+'調查(集賢)'!AK6+'調查(集賢)'!AL6+'調查(集賢)'!AM6 -> 0 | G9: ='調查(集賢)'!AW6+'調查(集賢)'!AX6+'調查(集賢)'!AY6+'調查(集賢)'!AZ6+'調查(集賢)'!BA6+'調查(集賢)'!BB6 -> 0 | H9: ='調查(集賢)'!BL6+'調查(集賢)'!BM6+'調查(集賢)'!BN6+'調查(集賢)'!BO6+'調查(集賢)'!BP6+'調查(集賢)'!BQ6 -> 0 | I9: - | J9: ='調查(集賢)'!Y6+'調查(集賢)'!Z6+'調查(集賢)'!AA6+'調查(集賢)'!AB6 -> 0 | K9: ='調查(集賢)'!AN6+'調查(集賢)'!AO6+'調查(集賢)'!AP6+'調查(集賢)'!AQ6 -> 0 | L9: ='調查(集賢)'!BC6+'調查(集賢)'!BD6+'調查(集賢)'!BE6+'調查(集賢)'!BF6 -> 0 | M9: ='調查(集賢)'!BR6+'調查(集賢)'!BS6+'調查(集賢)'!BT6+'調查(集賢)'!BU6 -> 0 | N9: - | O9: ='調查(集賢)'!AC6+'調查(集賢)'!AD6+'調查(集賢)'!AE6 -> 0 | P9: ='調查(集賢)'!AR6+'調查(集賢)'!AS6+'調查(集賢)'!AT6 -> 0 | Q9: ='調查(集賢)'!BG6+'調查(集賢)'!BH6+'調查(集賢)'!BI6 -> 0 | R9: ='調查(集賢)'!BV6+'調查(集賢)'!BW6+'調查(集賢)'!BX6 -> 0
A10: A | B10: 0.052083333 | C10: 0.0625 | D10: - | E10: ='調查(集賢)'!S7+'調查(集賢)'!T7+'調查(集賢)'!U7+'調查(集賢)'!V7+'調查(集賢)'!W7+'調查(集賢)'!X7 -> 0 | F10: ='調查(集賢)'!AH7+'調查(集賢)'!AI7+'調查(集賢)'!AJ7+'調查(集賢)'!AK7+'調查(集賢)'!AL7+'調查(集賢)'!AM7 -> 0 | G10: ='調查(集賢)'!AW7+'調查(集賢)'!AX7+'調查(集賢)'!AY7+'調查(集賢)'!AZ7+'調查(集賢)'!BA7+'調查(集賢)'!BB7 -> 0 | H10: ='調查(集賢)'!BL7+'調查(集賢)'!BM7+'調查(集賢)'!BN7+'調查(集賢)'!BO7+'調查(集賢)'!BP7+'調查(集賢)'!BQ7 -> 0 | I10: - | J10: ='調查(集賢)'!Y7+'調查(集賢)'!Z7+'調查(集賢)'!AA7+'調查(集賢)'!AB7 -> 0 | K10: ='調查(集賢)'!AN7+'調查(集賢)'!AO7+'調查(集賢)'!AP7+'調查(集賢)'!AQ7 -> 0 | L10: ='調查(集賢)'!BC7+'調查(集賢)'!BD7+'調查(集賢)'!BE7+'調查(集賢)'!BF7 -> 0 | M10: ='調查(集賢)'!BR7+'調查(集賢)'!BS7+'調查(集賢)'!BT7+'調查(集賢)'!BU7 -> 0 | N10: - | O10: ='調查(集賢)'!AC7+'調查(集賢)'!AD7+'調查(集賢)'!AE7 -> 0 | P10: ='調查(集賢)'!AR7+'調查(集賢)'!AS7+'調查(集賢)'!AT7 -> 0 | Q10: ='調查(集賢)'!BG7+'調查(集賢)'!BH7+'調查(集賢)'!BI7 -> 0 | R10: ='調查(集賢)'!BV7+'調查(集賢)'!BW7+'調查(集賢)'!BX7 -> 0
A11: A | B11: 0.0625 | C11: 0.072916667 | D11: - | E11: ='調查(集賢)'!S8+'調查(集賢)'!T8+'調查(集賢)'!U8+'調查(集賢)'!V8+'調查(集賢)'!W8+'調查(集賢)'!X8 -> 0 | F11: ='調查(集賢)'!AH8+'調查(集賢)'!AI8+'調查(集賢)'!AJ8+'調查(集賢)'!AK8+'調查(集賢)'!AL8+'調查(集賢)'!AM8 -> 0 | G11: ='調查(集賢)'!AW8+'調查(集賢)'!AX8+'調查(集賢)'!AY8+'調查(集賢)'!AZ8+'調查(集賢)'!BA8+'調查(集賢)'!BB8 -> 0 | H11: ='調查(集賢)'!BL8+'調查(集賢)'!BM8+'調查(集賢)'!BN8+'調查(集賢)'!BO8+'調查(集賢)'!BP8+'調查(集賢)'!BQ8 -> 0 | I11: - | J11: ='調查(集賢)'!Y8+'調查(集賢)'!Z8+'調查(集賢)'!AA8+'調查(集賢)'!AB8 -> 0 | K11: ='調查(集賢)'!AN8+'調查(集賢)'!AO8+'調查(集賢)'!AP8+'調查(集賢)'!AQ8 -> 0 | L11: ='調查(集賢)'!BC8+'調查(集賢)'!BD8+'調查(集賢)'!BE8+'調查(集賢)'!BF8 -> 0 | M11: ='調查(集賢)'!BR8+'調查(集賢)'!BS8+'調查(集賢)'!BT8+'調查(集賢)'!BU8 -> 0 | N11: - | O11: ='調查(集賢)'!AC8+'調查(集賢)'!AD8+'調查(集賢)'!AE8 -> 0 | P11: ='調查(集賢)'!AR8+'調查(集賢)'!AS8+'調查(集賢)'!AT8 -> 0 | Q11: ='調查(集賢)'!BG8+'調查(集賢)'!BH8+'調查(集賢)'!BI8 -> 0 | R11: ='調查(集賢)'!BV8+'調查(集賢)'!BW8+'調查(集賢)'!BX8 -> 0
A12: A | B12: 0.072916667 | C12: 0.083333333 | D12: - | E12: ='調查(集賢)'!S9+'調查(集賢)'!T9+'調查(集賢)'!U9+'調查(集賢)'!V9+'調查(集賢)'!W9+'調查(集賢)'!X9 -> 0 | F12: ='調查(集賢)'!AH9+'調查(集賢)'!AI9+'調查(集賢)'!AJ9+'調查(集賢)'!AK9+'調查(集賢)'!AL9+'調查(集賢)'!AM9 -> 0 | G12: ='調查(集賢)'!AW9+'調查(集賢)'!AX9+'調查(集賢)'!AY9+'調查(集賢)'!AZ9+'調查(集賢)'!BA9+'調查(集賢)'!BB9 -> 0 | H12: ='調查(集賢)'!BL9+'調查(集賢)'!BM9+'調查(集賢)'!BN9+'調查(集賢)'!BO9+'調查(集賢)'!BP9+'調查(集賢)'!BQ9 -> 0 | I12: - | J12: ='調查(集賢)'!Y9+'調查(集賢)'!Z9+'調查(集賢)'!AA9+'調查(集賢)'!AB9 -> 0 | K12: ='調查(集賢)'!AN9+'調查(集賢)'!AO9+'調查(集賢)'!AP9+'調查(集賢)'!AQ9 -> 0 | L12: ='調查(集賢)'!BC9+'調查(集賢)'!BD9+'調查(集賢)'!BE9+'調查(集賢)'!BF9 -> 0 | M12: ='調查(集賢)'!BR9+'調查(集賢)'!BS9+'調查(集賢)'!BT9+'調查(集賢)'!BU9 -> 0 | N12: - | O12: ='調查(集賢)'!AC9+'調查(集賢)'!AD9+'調查(集賢)'!AE9 -> 0 | P12: ='調查(集賢)'!AR9+'調查(集賢)'!AS9+'調查(集賢)'!AT9 -> 0 | Q12: ='調查(集賢)'!BG9+'調查(集賢)'!BH9+'調查(集賢)'!BI9 -> 0 | R12: ='調查(集賢)'!BV9+'調查(集賢)'!BW9+'調查(集賢)'!BX9 -> 0
A13: A | B13: 0.083333333 | C13: 0.09375 | D13: - | E13: ='調查(集賢)'!S10+'調查(集賢)'!T10+'調查(集賢)'!U10+'調查(集賢)'!V10+'調查(集賢)'!W10+'調查(集賢)'!X10 -> 0 | F13: ='調查(集賢)'!AH10+'調查(集賢)'!AI10+'調查(集賢)'!AJ10+'調查(集賢)'!AK10+'調查(集賢)'!AL10+'調查(集賢)'!AM10 -> 0 | G13: ='調查(集賢)'!AW10+'調查(集賢)'!AX10+'調查(集賢)'!AY10+'調查(集賢)'!AZ10+'調查(集賢)'!BA10+'調查(集賢)'!BB10 -> 0 | H13: ='調查(集賢)'!BL10+'調查(集賢)'!BM10+'調查(集賢)'!BN10+'調查(集賢)'!BO10+'調查(集賢)'!BP10+'調查(集賢)'!BQ10 -> 0 | I13: - | J13: ='調查(集賢)'!Y10+'調查(集賢)'!Z10+'調查(集賢)'!AA10+'調查(集賢)'!AB10 -> 0 | K13: ='調查(集賢)'!AN10+'調查(集賢)'!AO10+'調查(集賢)'!AP10+'調查(集賢)'!AQ10 -> 0 | L13: ='調查(集賢)'!BC10+'調查(集賢)'!BD10+'調查(集賢)'!BE10+'調查(集賢)'!BF10 -> 0 | M13: ='調查(集賢)'!BR10+'調查(集賢)'!BS10+'調查(集賢)'!BT10+'調查(集賢)'!BU10 -> 0 | N13: - | O13: ='調查(集賢)'!AC10+'調查(集賢)'!AD10+'調查(集賢)'!AE10 -> 0 | P13: ='調查(集賢)'!AR10+'調查(集賢)'!AS10+'調查(集賢)'!AT10 -> 0 | Q13: ='調查(集賢)'!BG10+'調查(集賢)'!BH10+'調查(集賢)'!BI10 -> 0 | R13: ='調查(集賢)'!BV10+'調查(集賢)'!BW10+'調查(集賢)'!BX10 -> 0
A14: A | B14: 0.09375 | C14: 0.10416667 | D14: - | E14: ='調查(集賢)'!S11+'調查(集賢)'!T11+'調查(集賢)'!U11+'調查(集賢)'!V11+'調查(集賢)'!W11+'調查(集賢)'!X11 -> 0 | F14: ='調查(集賢)'!AH11+'調查(集賢)'!AI11+'調查(集賢)'!AJ11+'調查(集賢)'!AK11+'調查(集賢)'!AL11+'調查(集賢)'!AM11 -> 0 | G14: ='調查(集賢)'!AW11+'調查(集賢)'!AX11+'調查(集賢)'!AY11+'調查(集賢)'!AZ11+'調查(集賢)'!BA11+'調查(集賢)'!BB11 -> 0 | H14: ='調查(集賢)'!BL11+'調查(集賢)'!BM11+'調查(集賢)'!BN11+'調查(集賢)'!BO11+'調查(集賢)'!BP11+'調查(集賢)'!BQ11 -> 0 | I14: - | J14: ='調查(集賢)'!Y11+'調查(集賢)'!Z11+'調查(集賢)'!AA11+'調查(集賢)'!AB11 -> 0 | K14: ='調查(集賢)'!AN11+'調查(集賢)'!AO11+'調查(集賢)'!AP11+'調查(集賢)'!AQ11 -> 0 | L14: ='調查(集賢)'!BC11+'調查(集賢)'!BD11+'調查(集賢)'!BE11+'調查(集賢)'!BF11 -> 0 | M14: ='調查(集賢)'!BR11+'調查(集賢)'!BS11+'調查(集賢)'!BT11+'調查(集賢)'!BU11 -> 0 | N14: - | O14: ='調查(集賢)'!AC11+'調查(集賢)'!AD11+'調查(集賢)'!AE11 -> 0 | P14: ='調查(集賢)'!AR11+'調查(集賢)'!AS11+'調查(集賢)'!AT11 -> 0 | Q14: ='調查(集賢)'!BG11+'調查(集賢)'!BH11+'調查(集賢)'!BI11 -> 0 | R14: ='調查(集賢)'!BV11+'調查(集賢)'!BW11+'調查(集賢)'!BX11 -> 0
A15: A | B15: 0.10416667 | C15: 0.11458333 | D15: - | E15: ='調查(集賢)'!S12+'調查(集賢)'!T12+'調查(集賢)'!U12+'調查(集賢)'!V12+'調查(集賢)'!W12+'調查(集賢)'!X12 -> 0 | F15: ='調查(集賢)'!AH12+'調查(集賢)'!AI12+'調查(集賢)'!AJ12+'調查(集賢)'!AK12+'調查(集賢)'!AL12+'調查(集賢)'!AM12 -> 0 | G15: ='調查(集賢)'!AW12+'調查(集賢)'!AX12+'調查(集賢)'!AY12+'調查(集賢)'!AZ12+'調查(集賢)'!BA12+'調查(集賢)'!BB12 -> 0 | H15: ='調查(集賢)'!BL12+'調查(集賢)'!BM12+'調查(集賢)'!BN12+'調查(集賢)'!BO12+'調查(集賢)'!BP12+'調查(集賢)'!BQ12 -> 0 | I15: - | J15: ='調查(集賢)'!Y12+'調查(集賢)'!Z12+'調查(集賢)'!AA12+'調查(集賢)'!AB12 -> 0 | K15: ='調查(集賢)'!AN12+'調查(集賢)'!AO12+'調查(集賢)'!AP12+'調查(集賢)'!AQ12 -> 0 | L15: ='調查(集賢)'!BC12+'調查(集賢)'!BD12+'調查(集賢)'!BE12+'調查(集賢)'!BF12 -> 0 | M15: ='調查(集賢)'!BR12+'調查(集賢)'!BS12+'調查(集賢)'!BT12+'調查(集賢)'!BU12 -> 0 | N15: - | O15: ='調查(集賢)'!AC12+'調查(集賢)'!AD12+'調查(集賢)'!AE12 -> 0 | P15: ='調查(集賢)'!AR12+'調查(集賢)'!AS12+'調查(集賢)'!AT12 -> 0 | Q15: ='調查(集賢)'!BG12+'調查(集賢)'!BH12+'調查(集賢)'!BI12 -> 0 | R15: ='調查(集賢)'!BV12+'調查(集賢)'!BW12+'調查(集賢)'!BX12 -> 0
A16: A | B16: 0.11458333 | C16: 0.125 | D16: - | E16: ='調查(集賢)'!S13+'調查(集賢)'!T13+'調查(集賢)'!U13+'調查(集賢)'!V13+'調查(集賢)'!W13+'調查(集賢)'!X13 -> 0 | F16: ='調查(集賢)'!AH13+'調查(集賢)'!AI13+'調查(集賢)'!AJ13+'調查(集賢)'!AK13+'調查(集賢)'!AL13+'調查(集賢)'!AM13 -> 0 | G16: ='調查(集賢)'!AW13+'調查(集賢)'!AX13+'調查(集賢)'!AY13+'調查(集賢)'!AZ13+'調查(集賢)'!BA13+'調查(集賢)'!BB13 -> 0 | H16: ='調查(集賢)'!BL13+'調查(集賢)'!BM13+'調查(集賢)'!BN13+'調查(集賢)'!BO13+'調查(集賢)'!BP13+'調查(集賢)'!BQ13 -> 0 | I16: - | J16: ='調查(集賢)'!Y13+'調查(集賢)'!Z13+'調查(集賢)'!AA13+'調查(集賢)'!AB13 -> 0 | K16: ='調查(集賢)'!AN13+'調查(集賢)'!AO13+'調查(集賢)'!AP13+'調查(集賢)'!AQ13 -> 0 | L16: ='調查(集賢)'!BC13+'調查(集賢)'!BD13+'調查(集賢)'!BE13+'調查(集賢)'!BF13 -> 0 | M16: ='調查(集賢)'!BR13+'調查(集賢)'!BS13+'調查(集賢)'!BT13+'調查(集賢)'!BU13 -> 0 | N16: - | O16: ='調查(集賢)'!AC13+'調查(集賢)'!AD13+'調查(集賢)'!AE13 -> 0 | P16: ='調查(集賢)'!AR13+'調查(集賢)'!AS13+'調查(集賢)'!AT13 -> 0 | Q16: ='調查(集賢)'!BG13+'調查(集賢)'!BH13+'調查(集賢)'!BI13 -> 0 | R16: ='調查(集賢)'!BV13+'調查(集賢)'!BW13+'調查(集賢)'!BX13 -> 0
... A99: A | B99: 0.97916667 | C99: 0.98958333 | D99: - | E99: ='調查(集賢)'!S96+'調查(集賢)'!T96+'調查(集賢)'!U96+'調查(集賢)'!V96+'調查(集賢)'!W96+'調查(集賢)'!X96 -> 0 | F99: ='調查(集賢)'!AH96+'調查(集賢)'!AI96+'調查(集賢)'!AJ96+'調查(集賢)'!AK96+'調查(集賢)'!AL96+'調查(集賢)'!AM96 -> 0 | G99: ='調查(集賢)'!AW96+'調查(集賢)'!AX96+'調查(集賢)'!AY96+'調查(集賢)'!AZ96+'調查(集賢)'!BA96+'調查(集賢)'!BB96 -> 0 | H99: ='調查(集賢)'!BL96+'調查(集賢)'!BM96+'調查(集賢)'!BN96+'調查(集賢)'!BO96+'調查(集賢)'!BP96+'調查(集賢)'!BQ96 -> 0 | I99: - | J99: ='調查(集賢)'!Y96+'調查(集賢)'!Z96+'調查(集賢)'!AA96+'調查(集賢)'!AB96 -> 0 | K99: ='調查(集賢)'!AN96+'調查(集賢)'!AO96+'調查(集賢)'!AP96+'調查(集賢)'!AQ96 -> 0 | L99: ='調查(集賢)'!BC96+'調查(集賢)'!BD96+'調查(集賢)'!BE96+'調查(集賢)'!BF96 -> 0 | M99: ='調查(集賢)'!BR96+'調查(集賢)'!BS96+'調查(集賢)'!BT96+'調查(集賢)'!BU96 -> 0 | N99: - | O99: ='調查(集賢)'!AC96+'調查(集賢)'!AD96+'調查(集賢)'!AE96 -> 0 | P99: ='調查(集賢)'!AR96+'調查(集賢)'!AS96+'調查(集賢)'!AT96 -> 0 | Q99: ='調查(集賢)'!BG96+'調查(集賢)'!BH96+'調查(集賢)'!BI96 -> 0 | R99: ='調查(集賢)'!BV96+'調查(集賢)'!BW96+'調查(集賢)'!BX96 -> 0
A100: A | B100: 0.98958333 | C100: 24:00 | D100: - | E100: ='調查(集賢)'!S97+'調查(集賢)'!T97+'調查(集賢)'!U97+'調查(集賢)'!V97+'調查(集賢)'!W97+'調查(集賢)'!X97 -> 0 | F100: ='調查(集賢)'!AH97+'調查(集賢)'!AI97+'調查(集賢)'!AJ97+'調查(集賢)'!AK97+'調查(集賢)'!AL97+'調查(集賢)'!AM97 -> 0 | G100: ='調查(集賢)'!AW97+'調查(集賢)'!AX97+'調查(集賢)'!AY97+'調查(集賢)'!AZ97+'調查(集賢)'!BA97+'調查(集賢)'!BB97 -> 0 | H100: ='調查(集賢)'!BL97+'調查(集賢)'!BM97+'調查(集賢)'!BN97+'調查(集賢)'!BO97+'調查(集賢)'!BP97+'調查(集賢)'!BQ97 -> 0 | I100: - | J100: ='調查(集賢)'!Y97+'調查(集賢)'!Z97+'調查(集賢)'!AA97+'調查(集賢)'!AB97 -> 0 | K100: ='調查(集賢)'!AN97+'調查(集賢)'!AO97+'調查(集賢)'!AP97+'調查(集賢)'!AQ97 -> 0 | L100: ='調查(集賢)'!BC97+'調查(集賢)'!BD97+'調查(集賢)'!BE97+'調查(集賢)'!BF97 -> 0 | M100: ='調查(集賢)'!BR97+'調查(集賢)'!BS97+'調查(集賢)'!BT97+'調查(集賢)'!BU97 -> 0 | N100: - | O100: ='調查(集賢)'!AC97+'調查(集賢)'!AD97+'調查(集賢)'!AE97 -> 0 | P100: ='調查(集賢)'!AR97+'調查(集賢)'!AS97+'調查(集賢)'!AT97 -> 0 | Q100: ='調查(集賢)'!BG97+'調查(集賢)'!BH97+'調查(集賢)'!BI97 -> 0 | R100: ='調查(集賢)'!BV97+'調查(集賢)'!BW97+'調查(集賢)'!BX97 -> 0
A101: B | B101: 0 | C101: 0.010416667 | D101: ='調查(集賢)'!D98+'調查(集賢)'!E98+'調查(集賢)'!F98+'調查(集賢)'!G98+'調查(集賢)'!H98+'調查(集賢)'!I98 -> 0 | E101: - | F101: ='調查(集賢)'!AH98+'調查(集賢)'!AI98+'調查(集賢)'!AJ98+'調查(集賢)'!AK98+'調查(集賢)'!AL98+'調查(集賢)'!AM98 -> 0 | G101: ='調查(集賢)'!AW98+'調查(集賢)'!AX98+'調查(集賢)'!AY98+'調查(集賢)'!AZ98+'調查(集賢)'!BA98+'調查(集賢)'!BB98 -> 0 | H101: ='調查(集賢)'!BL98+'調查(集賢)'!BM98+'調查(集賢)'!BN98+'調查(集賢)'!BO98+'調查(集賢)'!BP98+'調查(集賢)'!BQ98 -> 0 | I101: ='調查(集賢)'!J98+'調查(集賢)'!K98+'調查(集賢)'!L98+'調查(集賢)'!M98 -> 0 | J101: - | K101: ='調查(集賢)'!AN98+'調查(集賢)'!AO98+'調查(集賢)'!AP98+'調查(集賢)'!AQ98 -> 0 | L101: ='調查(集賢)'!BC98+'調查(集賢)'!BD98+'調查(集賢)'!BE98+'調查(集賢)'!BF98 -> 0 | M101: ='調查(集賢)'!BR98+'調查(集賢)'!BS98+'調查(集賢)'!BT98+'調查(集賢)'!BU98 -> 0 | N101: ='調查(集賢)'!N98+'調查(集賢)'!O98+'調查(集賢)'!P98 -> 0 | O101: - | P101: ='調查(集賢)'!AR98+'調查(集賢)'!AS98+'調查(集賢)'!AT98 -> 0 | Q101: ='調查(集賢)'!BG98+'調查(集賢)'!BH98+'調查(集賢)'!BI98 -> 0 | R101: ='調查(集賢)'!BV98+'調查(集賢)'!BW98+'調查(集賢)'!BX98 -> 0
A102: B | B102: 0.010416667 | C102: 0.020833333 | D102: ='調查(集賢)'!D99+'調查(集賢)'!E99+'調查(集賢)'!F99+'調查(集賢)'!G99+'調查(集賢)'!H99+'調查(集賢)'!I99 -> 0 | E102: - | F102: ='調查(集賢)'!AH99+'調查(集賢)'!AI99+'調查(集賢)'!AJ99+'調查(集賢)'!AK99+'調查(集賢)'!AL99+'調查(集賢)'!AM99 -> 0 | G102: ='調查(集賢)'!AW99+'調查(集賢)'!AX99+'調查(集賢)'!AY99+'調查(集賢)'!AZ99+'調查(集賢)'!BA99+'調查(集賢)'!BB99 -> 0 | H102: ='調查(集賢)'!BL99+'調查(集賢)'!BM99+'調查(集賢)'!BN99+'調查(集賢)'!BO99+'調查(集賢)'!BP99+'調查(集賢)'!BQ99 -> 0 | I102: ='調查(集賢)'!J99+'調查(集賢)'!K99+'調查(集賢)'!L99+'調查(集賢)'!M99 -> 0 | J102: - | K102: ='調查(集賢)'!AN99+'調查(集賢)'!AO99+'調查(集賢)'!AP99+'調查(集賢)'!AQ99 -> 0 | L102: ='調查(集賢)'!BC99+'調查(集賢)'!BD99+'調查(集賢)'!BE99+'調查(集賢)'!BF99 -> 0 | M102: ='調查(集賢)'!BR99+'調查(集賢)'!BS99+'調查(集賢)'!BT99+'調查(集賢)'!BU99 -> 0 | N102: ='調查(集賢)'!N99+'調查(集賢)'!O99+'調查(集賢)'!P99 -> 0 | O102: - | P102: ='調查(集賢)'!AR99+'調查(集賢)'!AS99+'調查(集賢)'!AT99 -> 0 | Q102: ='調查(集賢)'!BG99+'調查(集賢)'!BH99+'調查(集賢)'!BI99 -> 0 | R102: ='調查(集賢)'!BV99+'調查(集賢)'!BW99+'調查(集賢)'!BX99 -> 0
A103: B | B103: 0.020833333 | C103: 0.03125 | D103: ='調查(集賢)'!D100+'調查(集賢)'!E100+'調查(集賢)'!F100+'調查(集賢)'!G100+'調查(集賢)'!H100+'調查(集賢)'!I100 -> 0 | E103: - | F103: ='調查(集賢)'!AH100+'調查(集賢)'!AI100+'調查(集賢)'!AJ100+'調查(集賢)'!AK100+'調查(集賢)'!AL100+'調查(集賢)'!AM100 -> 0 | G103: ='調查(集賢)'!AW100+'調查(集賢)'!AX100+'調查(集賢)'!AY100+'調查(集賢)'!AZ100+'調查(集賢)'!BA100+'調查(集賢)'!BB100 -> 0 | H103: ='調查(集賢)'!BL100+'調查(集賢)'!BM100+'調查(集賢)'!BN100+'調查(集賢)'!BO100+'調查(集賢)'!BP100+'調查(集賢)'!BQ100 -> 0 | I103: ='調查(集賢)'!J100+'調查(集賢)'!K100+'調查(集賢)'!L100+'調查(集賢)'!M100 -> 0 | J103: - | K103: ='調查(集賢)'!AN100+'調查(集賢)'!AO100+'調查(集賢)'!AP100+'調查(集賢)'!AQ100 -> 0 | L103: ='調查(集賢)'!BC100+'調查(集賢)'!BD100+'調查(集賢)'!BE100+'調查(集賢)'!BF100 -> 0 | M103: ='調查(集賢)'!BR100+'調查(集賢)'!BS100+'調查(集賢)'!BT100+'調查(集賢)'!BU100 -> 0 | N103: ='調查(集賢)'!N100+'調查(集賢)'!O100+'調查(集賢)'!P100 -> 0 | O103: - | P103: ='調查(集賢)'!AR100+'調查(集賢)'!AS100+'調查(集賢)'!AT100 -> 0 | Q103: ='調查(集賢)'!BG100+'調查(集賢)'!BH100+'調查(集賢)'!BI100 -> 0 | R103: ='調查(集賢)'!BV100+'調查(集賢)'!BW100+'調查(集賢)'!BX100 -> 0
A104: B | B104: 0.03125 | C104: 0.041666667 | D104: ='調查(集賢)'!D101+'調查(集賢)'!E101+'調查(集賢)'!F101+'調查(集賢)'!G101+'調查(集賢)'!H101+'調查(集賢)'!I101 -> 0 | E104: - | F104: ='調查(集賢)'!AH101+'調查(集賢)'!AI101+'調查(集賢)'!AJ101+'調查(集賢)'!AK101+'調查(集賢)'!AL101+'調查(集賢)'!AM101 -> 0 | G104: ='調查(集賢)'!AW101+'調查(集賢)'!AX101+'調查(集賢)'!AY101+'調查(集賢)'!AZ101+'調查(集賢)'!BA101+'調查(集賢)'!BB101 -> 0 | H104: ='調查(集賢)'!BL101+'調查(集賢)'!BM101+'調查(集賢)'!BN101+'調查(集賢)'!BO101+'調查(集賢)'!BP101+'調查(集賢)'!BQ101 -> 0 | I104: ='調查(集賢)'!J101+'調查(集賢)'!K101+'調查(集賢)'!L101+'調查(集賢)'!M101 -> 0 | J104: - | K104: ='調查(集賢)'!AN101+'調查(集賢)'!AO101+'調查(集賢)'!AP101+'調查(集賢)'!AQ101 -> 0 | L104: ='調查(集賢)'!BC101+'調查(集賢)'!BD101+'調查(集賢)'!BE101+'調查(集賢)'!BF101 -> 0 | M104: ='調查(集賢)'!BR101+'調查(集賢)'!BS101+'調查(集賢)'!BT101+'調查(集賢)'!BU101 -> 0 | N104: ='調查(集賢)'!N101+'調查(集賢)'!O101+'調查(集賢)'!P101 -> 0 | O104: - | P104: ='調查(集賢)'!AR101+'調查(集賢)'!AS101+'調查(集賢)'!AT101 -> 0 | Q104: ='調查(集賢)'!BG101+'調查(集賢)'!BH101+'調查(集賢)'!BI101 -> 0 | R104: ='調查(集賢)'!BV101+'調查(集賢)'!BW101+'調查(集賢)'!BX101 -> 0
A105: B | B105: 0.041666667 | C105: 0.052083333 | D105: ='調查(集賢)'!D102+'調查(集賢)'!E102+'調查(集賢)'!F102+'調查(集賢)'!G102+'調查(集賢)'!H102+'調查(集賢)'!I102 -> 0 | E105: - | F105: ='調查(集賢)'!AH102+'調查(集賢)'!AI102+'調查(集賢)'!AJ102+'調查(集賢)'!AK102+'調查(集賢)'!AL102+'調查(集賢)'!AM102 -> 0 | G105: ='調查(集賢)'!AW102+'調查(集賢)'!AX102+'調查(集賢)'!AY102+'調查(集賢)'!AZ102+'調查(集賢)'!BA102+'調查(集賢)'!BB102 -> 0 | H105: ='調查(集賢)'!BL102+'調查(集賢)'!BM102+'調查(集賢)'!BN102+'調查(集賢)'!BO102+'調查(集賢)'!BP102+'調查(集賢)'!BQ102 -> 0 | I105: ='調查(集賢)'!J102+'調查(集賢)'!K102+'調查(集賢)'!L102+'調查(集賢)'!M102 -> 0 | J105: - | K105: ='調查(集賢)'!AN102+'調查(集賢)'!AO102+'調查(集賢)'!AP102+'調查(集賢)'!AQ102 -> 0 | L105: ='調查(集賢)'!BC102+'調查(集賢)'!BD102+'調查(集賢)'!BE102+'調查(集賢)'!BF102 -> 0 | M105: ='調查(集賢)'!BR102+'調查(集賢)'!BS102+'調查(集賢)'!BT102+'調查(集賢)'!BU102 -> 0 | N105: ='調查(集賢)'!N102+'調查(集賢)'!O102+'調查(集賢)'!P102 -> 0 | O105: - | P105: ='調查(集賢)'!AR102+'調查(集賢)'!AS102+'調查(集賢)'!AT102 -> 0 | Q105: ='調查(集賢)'!BG102+'調查(集賢)'!BH102+'調查(集賢)'!BI102 -> 0 | R105: ='調查(集賢)'!BV102+'調查(集賢)'!BW102+'調查(集賢)'!BX102 -> 0
A106: B | B106: 0.052083333 | C106: 0.0625 | D106: ='調查(集賢)'!D103+'調查(集賢)'!E103+'調查(集賢)'!F103+'調查(集賢)'!G103+'調查(集賢)'!H103+'調查(集賢)'!I103 -> 0 | E106: - | F106: ='調查(集賢)'!AH103+'調查(集賢)'!AI103+'調查(集賢)'!AJ103+'調查(集賢)'!AK103+'調查(集賢)'!AL103+'調查(集賢)'!AM103 -> 0 | G106: ='調查(集賢)'!AW103+'調查(集賢)'!AX103+'調查(集賢)'!AY103+'調查(集賢)'!AZ103+'調查(集賢)'!BA103+'調查(集賢)'!BB103 -> 0 | H106: ='調查(集賢)'!BL103+'調查(集賢)'!BM103+'調查(集賢)'!BN103+'調查(集賢)'!BO103+'調查(集賢)'!BP103+'調查(集賢)'!BQ103 -> 0 | I106: ='調查(集賢)'!J103+'調查(集賢)'!K103+'調查(集賢)'!L103+'調查(集賢)'!M103 -> 0 | J106: - | K106: ='調查(集賢)'!AN103+'調查(集賢)'!AO103+'調查(集賢)'!AP103+'調查(集賢)'!AQ103 -> 0 | L106: ='調查(集賢)'!BC103+'調查(集賢)'!BD103+'調查(集賢)'!BE103+'調查(集賢)'!BF103 -> 0 | M106: ='調查(集賢)'!BR103+'調查(集賢)'!BS103+'調查(集賢)'!BT103+'調查(集賢)'!BU103 -> 0 | N106: ='調查(集賢)'!N103+'調查(集賢)'!O103+'調查(集賢)'!P103 -> 0 | O106: - | P106: ='調查(集賢)'!AR103+'調查(集賢)'!AS103+'調查(集賢)'!AT103 -> 0 | Q106: ='調查(集賢)'!BG103+'調查(集賢)'!BH103+'調查(集賢)'!BI103 -> 0 | R106: ='調查(集賢)'!BV103+'調查(集賢)'!BW103+'調查(集賢)'!BX103 -> 0
A107: B | B107: 0.0625 | C107: 0.072916667 | D107: ='調查(集賢)'!D104+'調查(集賢)'!E104+'調查(集賢)'!F104+'調查(集賢)'!G104+'調查(集賢)'!H104+'調查(集賢)'!I104 -> 0 | E107: - | F107: ='調查(集賢)'!AH104+'調查(集賢)'!AI104+'調查(集賢)'!AJ104+'調查(集賢)'!AK104+'調查(集賢)'!AL104+'調查(集賢)'!AM104 -> 0 | G107: ='調查(集賢)'!AW104+'調查(集賢)'!AX104+'調查(集賢)'!AY104+'調查(集賢)'!AZ104+'調查(集賢)'!BA104+'調查(集賢)'!BB104 -> 0 | H107: ='調查(集賢)'!BL104+'調查(集賢)'!BM104+'調查(集賢)'!BN104+'調查(集賢)'!BO104+'調查(集賢)'!BP104+'調查(集賢)'!BQ104 -> 0 | I107: ='調查(集賢)'!J104+'調查(集賢)'!K104+'調查(集賢)'!L104+'調查(集賢)'!M104 -> 0 | J107: - | K107: ='調查(集賢)'!AN104+'調查(集賢)'!AO104+'調查(集賢)'!AP104+'調查(集賢)'!AQ104 -> 0 | L107: ='調查(集賢)'!BC104+'調查(集賢)'!BD104+'調查(集賢)'!BE104+'調查(集賢)'!BF104 -> 0 | M107: ='調查(集賢)'!BR104+'調查(集賢)'!BS104+'調查(集賢)'!BT104+'調查(集賢)'!BU104 -> 0 | N107: ='調查(集賢)'!N104+'調查(集賢)'!O104+'調查(集賢)'!P104 -> 0 | O107: - | P107: ='調查(集賢)'!AR104+'調查(集賢)'!AS104+'調查(集賢)'!AT104 -> 0 | Q107: ='調查(集賢)'!BG104+'調查(集賢)'!BH104+'調查(集賢)'!BI104 -> 0 | R107: ='調查(集賢)'!BV104+'調查(集賢)'!BW104+'調查(集賢)'!BX104 -> 0
A108: B | B108: 0.072916667 | C108: 0.083333333 | D108: ='調查(集賢)'!D105+'調查(集賢)'!E105+'調查(集賢)'!F105+'調查(集賢)'!G105+'調查(集賢)'!H105+'調查(集賢)'!I105 -> 0 | E108: - | F108: ='調查(集賢)'!AH105+'調查(集賢)'!AI105+'調查(集賢)'!AJ105+'調查(集賢)'!AK105+'調查(集賢)'!AL105+'調查(集賢)'!AM105 -> 0 | G108: ='調查(集賢)'!AW105+'調查(集賢)'!AX105+'調查(集賢)'!AY105+'調查(集賢)'!AZ105+'調查(集賢)'!BA105+'調查(集賢)'!BB105 -> 0 | H108: ='調查(集賢)'!BL105+'調查(集賢)'!BM105+'調查(集賢)'!BN105+'調查(集賢)'!BO105+'調查(集賢)'!BP105+'調查(集賢)'!BQ105 -> 0 | I108: ='調查(集賢)'!J105+'調查(集賢)'!K105+'調查(集賢)'!L105+'調查(集賢)'!M105 -> 0 | J108: - | K108: ='調查(集賢)'!AN105+'調查(集賢)'!AO105+'調查(集賢)'!AP105+'調查(集賢)'!AQ105 -> 0 | L108: ='調查(集賢)'!BC105+'調查(集賢)'!BD105+'調查(集賢)'!BE105+'調查(集賢)'!BF105 -> 0 | M108: ='調查(集賢)'!BR105+'調查(集賢)'!BS105+'調查(集賢)'!BT105+'調查(集賢)'!BU105 -> 0 | N108: ='調查(集賢)'!N105+'調查(集賢)'!O105+'調查(集賢)'!P105 -> 0 | O108: - | P108: ='調查(集賢)'!AR105+'調查(集賢)'!AS105+'調查(集賢)'!AT105 -> 0 | Q108: ='調查(集賢)'!BG105+'調查(集賢)'!BH105+'調查(集賢)'!BI105 -> 0 | R108: ='調查(集賢)'!BV105+'調查(集賢)'!BW105+'調查(集賢)'!BX105 -> 0
A109: B | B109: 0.083333333 | C109: 0.09375 | D109: ='調查(集賢)'!D106+'調查(集賢)'!E106+'調查(集賢)'!F106+'調查(集賢)'!G106+'調查(集賢)'!H106+'調查(集賢)'!I106 -> 0 | E109: - | F109: ='調查(集賢)'!AH106+'調查(集賢)'!AI106+'調查(集賢)'!AJ106+'調查(集賢)'!AK106+'調查(集賢)'!AL106+'調查(集賢)'!AM106 -> 0 | G109: ='調查(集賢)'!AW106+'調查(集賢)'!AX106+'調查(集賢)'!AY106+'調查(集賢)'!AZ106+'調查(集賢)'!BA106+'調查(集賢)'!BB106 -> 0 | H109: ='調查(集賢)'!BL106+'調查(集賢)'!BM106+'調查(集賢)'!BN106+'調查(集賢)'!BO106+'調查(集賢)'!BP106+'調查(集賢)'!BQ106 -> 0 | I109: ='調查(集賢)'!J106+'調查(集賢)'!K106+'調查(集賢)'!L106+'調查(集賢)'!M106 -> 0 | J109: - | K109: ='調查(集賢)'!AN106+'調查(集賢)'!AO106+'調查(集賢)'!AP106+'調查(集賢)'!AQ106 -> 0 | L109: ='調查(集賢)'!BC106+'調查(集賢)'!BD106+'調查(集賢)'!BE106+'調查(集賢)'!BF106 -> 0 | M109: ='調查(集賢)'!BR106+'調查(集賢)'!BS106+'調查(集賢)'!BT106+'調查(集賢)'!BU106 -> 0 | N109: ='調查(集賢)'!N106+'調查(集賢)'!O106+'調查(集賢)'!P106 -> 0 | O109: - | P109: ='調查(集賢)'!AR106+'調查(集賢)'!AS106+'調查(集賢)'!AT106 -> 0 | Q109: ='調查(集賢)'!BG106+'調查(集賢)'!BH106+'調查(集賢)'!BI106 -> 0 | R109: ='調查(集賢)'!BV106+'調查(集賢)'!BW106+'調查(集賢)'!BX106 -> 0
A110: B | B110: 0.09375 | C110: 0.10416667 | D110: ='調查(集賢)'!D107+'調查(集賢)'!E107+'調查(集賢)'!F107+'調查(集賢)'!G107+'調查(集賢)'!H107+'調查(集賢)'!I107 -> 0 | E110: - | F110: ='調查(集賢)'!AH107+'調查(集賢)'!AI107+'調查(集賢)'!AJ107+'調查(集賢)'!AK107+'調查(集賢)'!AL107+'調查(集賢)'!AM107 -> 0 | G110: ='調查(集賢)'!AW107+'調查(集賢)'!AX107+'調查(集賢)'!AY107+'調查(集賢)'!AZ107+'調查(集賢)'!BA107+'調查(集賢)'!BB107 -> 0 | H110: ='調查(集賢)'!BL107+'調查(集賢)'!BM107+'調查(集賢)'!BN107+'調查(集賢)'!BO107+'調查(集賢)'!BP107+'調查(集賢)'!BQ107 -> 0 | I110: ='調查(集賢)'!J107+'調查(集賢)'!K107+'調查(集賢)'!L107+'調查(集賢)'!M107 -> 0 | J110: - | K110: ='調查(集賢)'!AN107+'調查(集賢)'!AO107+'調查(集賢)'!AP107+'調查(集賢)'!AQ107 -> 0 | L110: ='調查(集賢)'!BC107+'調查(集賢)'!BD107+'調查(集賢)'!BE107+'調查(集賢)'!BF107 -> 0 | M110: ='調查(集賢)'!BR107+'調查(集賢)'!BS107+'調查(集賢)'!BT107+'調查(集賢)'!BU107 -> 0 | N110: ='調查(集賢)'!N107+'調查(集賢)'!O107+'調查(集賢)'!P107 -> 0 | O110: - | P110: ='調查(集賢)'!AR107+'調查(集賢)'!AS107+'調查(集賢)'!AT107 -> 0 | Q110: ='調查(集賢)'!BG107+'調查(集賢)'!BH107+'調查(集賢)'!BI107 -> 0 | R110: ='調查(集賢)'!BV107+'調查(集賢)'!BW107+'調查(集賢)'!BX107 -> 0
A111: B | B111: 0.10416667 | C111: 0.11458333 | D111: ='調查(集賢)'!D108+'調查(集賢)'!E108+'調查(集賢)'!F108+'調查(集賢)'!G108+'調查(集賢)'!H108+'調查(集賢)'!I108 -> 0 | E111: - | F111: ='調查(集賢)'!AH108+'調查(集賢)'!AI108+'調查(集賢)'!AJ108+'調查(集賢)'!AK108+'調查(集賢)'!AL108+'調查(集賢)'!AM108 -> 0 | G111: ='調查(集賢)'!AW108+'調查(集賢)'!AX108+'調查(集賢)'!AY108+'調查(集賢)'!AZ108+'調查(集賢)'!BA108+'調查(集賢)'!BB108 -> 0 | H111: ='調查(集賢)'!BL108+'調查(集賢)'!BM108+'調查(集賢)'!BN108+'調查(集賢)'!BO108+'調查(集賢)'!BP108+'調查(集賢)'!BQ108 -> 0 | I111: ='調查(集賢)'!J108+'調查(集賢)'!K108+'調查(集賢)'!L108+'調查(集賢)'!M108 -> 0 | J111: - | K111: ='調查(集賢)'!AN108+'調查(集賢)'!AO108+'調查(集賢)'!AP108+'調查(集賢)'!AQ108 -> 0 | L111: ='調查(集賢)'!BC108+'調查(集賢)'!BD108+'調查(集賢)'!BE108+'調查(集賢)'!BF108 -> 0 | M111: ='調查(集賢)'!BR108+'調查(集賢)'!BS108+'調查(集賢)'!BT108+'調查(集賢)'!BU108 -> 0 | N111: ='調查(集賢)'!N108+'調查(集賢)'!O108+'調查(集賢)'!P108 -> 0 | O111: - | P111: ='調查(集賢)'!AR108+'調查(集賢)'!AS108+'調查(集賢)'!AT108 -> 0 | Q111: ='調查(集賢)'!BG108+'調查(集賢)'!BH108+'調查(集賢)'!BI108 -> 0 | R111: ='調查(集賢)'!BV108+'調查(集賢)'!BW108+'調查(集賢)'!BX108 -> 0
A112: B | B112: 0.11458333 | C112: 0.125 | D112: ='調查(集賢)'!D109+'調查(集賢)'!E109+'調查(集賢)'!F109+'調查(集賢)'!G109+'調查(集賢)'!H109+'調查(集賢)'!I109 -> 0 | E112: - | F112: ='調查(集賢)'!AH109+'調查(集賢)'!AI109+'調查(集賢)'!AJ109+'調查(集賢)'!AK109+'調查(集賢)'!AL109+'調查(集賢)'!AM109 -> 0 | G112: ='調查(集賢)'!AW109+'調查(集賢)'!AX109+'調查(集賢)'!AY109+'調查(集賢)'!AZ109+'調查(集賢)'!BA109+'調查(集賢)'!BB109 -> 0 | H112: ='調查(集賢)'!BL109+'調查(集賢)'!BM109+'調查(集賢)'!BN109+'調查(集賢)'!BO109+'調查(集賢)'!BP109+'調查(集賢)'!BQ109 -> 0 | I112: ='調查(集賢)'!J109+'調查(集賢)'!K109+'調查(集賢)'!L109+'調查(集賢)'!M109 -> 0 | J112: - | K112: ='調查(集賢)'!AN109+'調查(集賢)'!AO109+'調查(集賢)'!AP109+'調查(集賢)'!AQ109 -> 0 | L112: ='調查(集賢)'!BC109+'調查(集賢)'!BD109+'調查(集賢)'!BE109+'調查(集賢)'!BF109 -> 0 | M112: ='調查(集賢)'!BR109+'調查(集賢)'!BS109+'調查(集賢)'!BT109+'調查(集賢)'!BU109 -> 0 | N112: ='調查(集賢)'!N109+'調查(集賢)'!O109+'調查(集賢)'!P109 -> 0 | O112: - | P112: ='調查(集賢)'!AR109+'調查(集賢)'!AS109+'調查(集賢)'!AT109 -> 0 | Q112: ='調查(集賢)'!BG109+'調查(集賢)'!BH109+'調查(集賢)'!BI109 -> 0 | R112: ='調查(集賢)'!BV109+'調查(集賢)'!BW109+'調查(集賢)'!BX109 -> 0
... A195: B | B195: 0.97916667 | C195: 0.98958333 | D195: ='調查(集賢)'!D192+'調查(集賢)'!E192+'調查(集賢)'!F192+'調查(集賢)'!G192+'調查(集賢)'!H192+'調查(集賢)'!I192 -> 0 | E195: - | F195: ='調查(集賢)'!AH192+'調查(集賢)'!AI192+'調查(集賢)'!AJ192+'調查(集賢)'!AK192+'調查(集賢)'!AL192+'調查(集賢)'!AM192 -> 0 | G195: ='調查(集賢)'!AW192+'調查(集賢)'!AX192+'調查(集賢)'!AY192+'調查(集賢)'!AZ192+'調查(集賢)'!BA192+'調查(集賢)'!BB192 -> 0 | H195: ='調查(集賢)'!BL192+'調查(集賢)'!BM192+'調查(集賢)'!BN192+'調查(集賢)'!BO192+'調查(集賢)'!BP192+'調查(集賢)'!BQ192 -> 0 | I195: ='調查(集賢)'!J192+'調查(集賢)'!K192+'調查(集賢)'!L192+'調查(集賢)'!M192 -> 0 | J195: - | K195: ='調查(集賢)'!AN192+'調查(集賢)'!AO192+'調查(集賢)'!AP192+'調查(集賢)'!AQ192 -> 0 | L195: ='調查(集賢)'!BC192+'調查(集賢)'!BD192+'調查(集賢)'!BE192+'調查(集賢)'!BF192 -> 0 | M195: ='調查(集賢)'!BR192+'調查(集賢)'!BS192+'調查(集賢)'!BT192+'調查(集賢)'!BU192 -> 0 | N195: ='調查(集賢)'!N192+'調查(集賢)'!O192+'調查(集賢)'!P192 -> 0 | O195: - | P195: ='調查(集賢)'!AR192+'調查(集賢)'!AS192+'調查(集賢)'!AT192 -> 0 | Q195: ='調查(集賢)'!BG192+'調查(集賢)'!BH192+'調查(集賢)'!BI192 -> 0 | R195: ='調查(集賢)'!BV192+'調查(集賢)'!BW192+'調查(集賢)'!BX192 -> 0
A196: B | B196: 0.98958333 | C196: 24:00 | D196: ='調查(集賢)'!D193+'調查(集賢)'!E193+'調查(集賢)'!F193+'調查(集賢)'!G193+'調查(集賢)'!H193+'調查(集賢)'!I193 -> 0 | E196: - | F196: ='調查(集賢)'!AH193+'調查(集賢)'!AI193+'調查(集賢)'!AJ193+'調查(集賢)'!AK193+'調查(集賢)'!AL193+'調查(集賢)'!AM193 -> 0 | G196: ='調查(集賢)'!AW193+'調查(集賢)'!AX193+'調查(集賢)'!AY193+'調查(集賢)'!AZ193+'調查(集賢)'!BA193+'調查(集賢)'!BB193 -> 0 | H196: ='調查(集賢)'!BL193+'調查(集賢)'!BM193+'調查(集賢)'!BN193+'調查(集賢)'!BO193+'調查(集賢)'!BP193+'調查(集賢)'!BQ193 -> 0 | I196: ='調查(集賢)'!J193+'調查(集賢)'!K193+'調查(集賢)'!L193+'調查(集賢)'!M193 -> 0 | J196: - | K196: ='調查(集賢)'!AN193+'調查(集賢)'!AO193+'調查(集賢)'!AP193+'調查(集賢)'!AQ193 -> 0 | L196: ='調查(集賢)'!BC193+'調查(集賢)'!BD193+'調查(集賢)'!BE193+'調查(集賢)'!BF193 -> 0 | M196: ='調查(集賢)'!BR193+'調查(集賢)'!BS193+'調查(集賢)'!BT193+'調查(集賢)'!BU193 -> 0 | N196: ='調查(集賢)'!N193+'調查(集賢)'!O193+'調查(集賢)'!P193 -> 0 | O196: - | P196: ='調查(集賢)'!AR193+'調查(集賢)'!AS193+'調查(集賢)'!AT193 -> 0 | Q196: ='調查(集賢)'!BG193+'調查(集賢)'!BH193+'調查(集賢)'!BI193 -> 0 | R196: ='調查(集賢)'!BV193+'調查(集賢)'!BW193+'調查(集賢)'!BX193 -> 0
A197: C | B197: 0 | C197: 0.010416667 | D197: ='調查(集賢)'!D194+'調查(集賢)'!E194+'調查(集賢)'!F194+'調查(集賢)'!G194+'調查(集賢)'!H194+'調查(集賢)'!I194 -> 0 | E197: ='調查(集賢)'!S194+'調查(集賢)'!T194+'調查(集賢)'!U194+'調查(集賢)'!V194+'調查(集賢)'!W194+'調查(集賢)'!X194 -> 0 | F197: - | G197: ='調查(集賢)'!AW194+'調查(集賢)'!AX194+'調查(集賢)'!AY194+'調查(集賢)'!AZ194+'調查(集賢)'!BA194+'調查(集賢)'!BB194 -> 0 | H197: ='調查(集賢)'!BL194+'調查(集賢)'!BM194+'調查(集賢)'!BN194+'調查(集賢)'!BO194+'調查(集賢)'!BP194+'調查(集賢)'!BQ194 -> 0 | I197: ='調查(集賢)'!J194+'調查(集賢)'!K194+'調查(集賢)'!L194+'調查(集賢)'!M194 -> 0 | J197: ='調查(集賢)'!Y194+'調查(集賢)'!Z194+'調查(集賢)'!AA194+'調查(集賢)'!AB194 -> 0 | K197: - | L197: ='調查(集賢)'!BC194+'調查(集賢)'!BD194+'調查(集賢)'!BE194+'調查(集賢)'!BF194 -> 0 | M197: ='調查(集賢)'!BR194+'調查(集賢)'!BS194+'調查(集賢)'!BT194+'調查(集賢)'!BU194 -> 0 | N197: ='調查(集賢)'!N194+'調查(集賢)'!O194+'調查(集賢)'!P194 -> 0 | O197: ='調查(集賢)'!AC194+'調查(集賢)'!AD194+'調查(集賢)'!AE194 -> 0 | P197: - | Q197: ='調查(集賢)'!BG194+'調查(集賢)'!BH194+'調查(集賢)'!BI194 -> 0 | R197: ='調查(集賢)'!BV194+'調查(集賢)'!BW194+'調查(集賢)'!BX194 -> 0
A198: C | B198: 0.010416667 | C198: 0.020833333 | D198: ='調查(集賢)'!D195+'調查(集賢)'!E195+'調查(集賢)'!F195+'調查(集賢)'!G195+'調查(集賢)'!H195+'調查(集賢)'!I195 -> 0 | E198: ='調查(集賢)'!S195+'調查(集賢)'!T195+'調查(集賢)'!U195+'調查(集賢)'!V195+'調查(集賢)'!W195+'調查(集賢)'!X195 -> 0 | F198: - | G198: ='調查(集賢)'!AW195+'調查(集賢)'!AX195+'調查(集賢)'!AY195+'調查(集賢)'!AZ195+'調查(集賢)'!BA195+'調查(集賢)'!BB195 -> 0 | H198: ='調查(集賢)'!BL195+'調查(集賢)'!BM195+'調查(集賢)'!BN195+'調查(集賢)'!BO195+'調查(集賢)'!BP195+'調查(集賢)'!BQ195 -> 0 | I198: ='調查(集賢)'!J195+'調查(集賢)'!K195+'調查(集賢)'!L195+'調查(集賢)'!M195 -> 0 | J198: ='調查(集賢)'!Y195+'調查(集賢)'!Z195+'調查(集賢)'!AA195+'調查(集賢)'!AB195 -> 0 | K198: - | L198: ='調查(集賢)'!BC195+'調查(集賢)'!BD195+'調查(集賢)'!BE195+'調查(集賢)'!BF195 -> 0 | M198: ='調查(集賢)'!BR195+'調查(集賢)'!BS195+'調查(集賢)'!BT195+'調查(集賢)'!BU195 -> 0 | N198: ='調查(集賢)'!N195+'調查(集賢)'!O195+'調查(集賢)'!P195 -> 0 | O198: ='調查(集賢)'!AC195+'調查(集賢)'!AD195+'調查(集賢)'!AE195 -> 0 | P198: - | Q198: ='調查(集賢)'!BG195+'調查(集賢)'!BH195+'調查(集賢)'!BI195 -> 0 | R198: ='調查(集賢)'!BV195+'調查(集賢)'!BW195+'調查(集賢)'!BX195 -> 0
A199: C | B199: 0.020833333 | C199: 0.03125 | D199: ='調查(集賢)'!D196+'調查(集賢)'!E196+'調查(集賢)'!F196+'調查(集賢)'!G196+'調查(集賢)'!H196+'調查(集賢)'!I196 -> 0 | E199: ='調查(集賢)'!S196+'調查(集賢)'!T196+'調查(集賢)'!U196+'調查(集賢)'!V196+'調查(集賢)'!W196+'調查(集賢)'!X196 -> 0 | F199: - | G199: ='調查(集賢)'!AW196+'調查(集賢)'!AX196+'調查(集賢)'!AY196+'調查(集賢)'!AZ196+'調查(集賢)'!BA196+'調查(集賢)'!BB196 -> 0 | H199: ='調查(集賢)'!BL196+'調查(集賢)'!BM196+'調查(集賢)'!BN196+'調查(集賢)'!BO196+'調查(集賢)'!BP196+'調查(集賢)'!BQ196 -> 0 | I199: ='調查(集賢)'!J196+'調查(集賢)'!K196+'調查(集賢)'!L196+'調查(集賢)'!M196 -> 0 | J199: ='調查(集賢)'!Y196+'調查(集賢)'!Z196+'調查(集賢)'!AA196+'調查(集賢)'!AB196 -> 0 | K199: - | L199: ='調查(集賢)'!BC196+'調查(集賢)'!BD196+'調查(集賢)'!BE196+'調查(集賢)'!BF196 -> 0 | M199: ='調查(集賢)'!BR196+'調查(集賢)'!BS196+'調查(集賢)'!BT196+'調查(集賢)'!BU196 -> 0 | N199: ='調查(集賢)'!N196+'調查(集賢)'!O196+'調查(集賢)'!P196 -> 0 | O199: ='調查(集賢)'!AC196+'調查(集賢)'!AD196+'調查(集賢)'!AE196 -> 0 | P199: - | Q199: ='調查(集賢)'!BG196+'調查(集賢)'!BH196+'調查(集賢)'!BI196 -> 0 | R199: ='調查(集賢)'!BV196+'調查(集賢)'!BW196+'調查(集賢)'!BX196 -> 0
A200: C | B200: 0.03125 | C200: 0.041666667 | D200: ='調查(集賢)'!D197+'調查(集賢)'!E197+'調查(集賢)'!F197+'調查(集賢)'!G197+'調查(集賢)'!H197+'調查(集賢)'!I197 -> 0 | E200: ='調查(集賢)'!S197+'調查(集賢)'!T197+'調查(集賢)'!U197+'調查(集賢)'!V197+'調查(集賢)'!W197+'調查(集賢)'!X197 -> 0 | F200: - | G200: ='調查(集賢)'!AW197+'調查(集賢)'!AX197+'調查(集賢)'!AY197+'調查(集賢)'!AZ197+'調查(集賢)'!BA197+'調查(集賢)'!BB197 -> 0 | H200: ='調查(集賢)'!BL197+'調查(集賢)'!BM197+'調查(集賢)'!BN197+'調查(集賢)'!BO197+'調查(集賢)'!BP197+'調查(集賢)'!BQ197 -> 0 | I200: ='調查(集賢)'!J197+'調查(集賢)'!K197+'調查(集賢)'!L197+'調查(集賢)'!M197 -> 0 | J200: ='調查(集賢)'!Y197+'調查(集賢)'!Z197+'調查(集賢)'!AA197+'調查(集賢)'!AB197 -> 0 | K200: - | L200: ='調查(集賢)'!BC197+'調查(集賢)'!BD197+'調查(集賢)'!BE197+'調查(集賢)'!BF197 -> 0 | M200: ='調查(集賢)'!BR197+'調查(集賢)'!BS197+'調查(集賢)'!BT197+'調查(集賢)'!BU197 -> 0 | N200: ='調查(集賢)'!N197+'調查(集賢)'!O197+'調查(集賢)'!P197 -> 0 | O200: ='調查(集賢)'!AC197+'調查(集賢)'!AD197+'調查(集賢)'!AE197 -> 0 | P200: - | Q200: ='調查(集賢)'!BG197+'調查(集賢)'!BH197+'調查(集賢)'!BI197 -> 0 | R200: ='調查(集賢)'!BV197+'調查(集賢)'!BW197+'調查(集賢)'!BX197 -> 0
A201: C | B201: 0.041666667 | C201: 0.052083333 | D201: ='調查(集賢)'!D198+'調查(集賢)'!E198+'調查(集賢)'!F198+'調查(集賢)'!G198+'調查(集賢)'!H198+'調查(集賢)'!I198 -> 0 | E201: ='調查(集賢)'!S198+'調查(集賢)'!T198+'調查(集賢)'!U198+'調查(集賢)'!V198+'調查(集賢)'!W198+'調查(集賢)'!X198 -> 0 | F201: - | G201: ='調查(集賢)'!AW198+'調查(集賢)'!AX198+'調查(集賢)'!AY198+'調查(集賢)'!AZ198+'調查(集賢)'!BA198+'調查(集賢)'!BB198 -> 0 | H201: ='調查(集賢)'!BL198+'調查(集賢)'!BM198+'調查(集賢)'!BN198+'調查(集賢)'!BO198+'調查(集賢)'!BP198+'調查(集賢)'!BQ198 -> 0 | I201: ='調查(集賢)'!J198+'調查(集賢)'!K198+'調查(集賢)'!L198+'調查(集賢)'!M198 -> 0 | J201: ='調查(集賢)'!Y198+'調查(集賢)'!Z198+'調查(集賢)'!AA198+'調查(集賢)'!AB198 -> 0 | K201: - | L201: ='調查(集賢)'!BC198+'調查(集賢)'!BD198+'調查(集賢)'!BE198+'調查(集賢)'!BF198 -> 0 | M201: ='調查(集賢)'!BR198+'調查(集賢)'!BS198+'調查(集賢)'!BT198+'調查(集賢)'!BU198 -> 0 | N201: ='調查(集賢)'!N198+'調查(集賢)'!O198+'調查(集賢)'!P198 -> 0 | O201: ='調查(集賢)'!AC198+'調查(集賢)'!AD198+'調查(集賢)'!AE198 -> 0 | P201: - | Q201: ='調查(集賢)'!BG198+'調查(集賢)'!BH198+'調查(集賢)'!BI198 -> 0 | R201: ='調查(集賢)'!BV198+'調查(集賢)'!BW198+'調查(集賢)'!BX198 -> 0
A202: C | B202: 0.052083333 | C202: 0.0625 | D202: ='調查(集賢)'!D199+'調查(集賢)'!E199+'調查(集賢)'!F199+'調查(集賢)'!G199+'調查(集賢)'!H199+'調查(集賢)'!I199 -> 0 | E202: ='調查(集賢)'!S199+'調查(集賢)'!T199+'調查(集賢)'!U199+'調查(集賢)'!V199+'調查(集賢)'!W199+'調查(集賢)'!X199 -> 0 | F202: - | G202: ='調查(集賢)'!AW199+'調查(集賢)'!AX199+'調查(集賢)'!AY199+'調查(集賢)'!AZ199+'調查(集賢)'!BA199+'調查(集賢)'!BB199 -> 0 | H202: ='調查(集賢)'!BL199+'調查(集賢)'!BM199+'調查(集賢)'!BN199+'調查(集賢)'!BO199+'調查(集賢)'!BP199+'調查(集賢)'!BQ199 -> 0 | I202: ='調查(集賢)'!J199+'調查(集賢)'!K199+'調查(集賢)'!L199+'調查(集賢)'!M199 -> 0 | J202: ='調查(集賢)'!Y199+'調查(集賢)'!Z199+'調查(集賢)'!AA199+'調查(集賢)'!AB199 -> 0 | K202: - | L202: ='調查(集賢)'!BC199+'調查(集賢)'!BD199+'調查(集賢)'!BE199+'調查(集賢)'!BF199 -> 0 | M202: ='調查(集賢)'!BR199+'調查(集賢)'!BS199+'調查(集賢)'!BT199+'調查(集賢)'!BU199 -> 0 | N202: ='調查(集賢)'!N199+'調查(集賢)'!O199+'調查(集賢)'!P199 -> 0 | O202: ='調查(集賢)'!AC199+'調查(集賢)'!AD199+'調查(集賢)'!AE199 -> 0 | P202: - | Q202: ='調查(集賢)'!BG199+'調查(集賢)'!BH199+'調查(集賢)'!BI199 -> 0 | R202: ='調查(集賢)'!BV199+'調查(集賢)'!BW199+'調查(集賢)'!BX199 -> 0
A203: C | B203: 0.0625 | C203: 0.072916667 | D203: ='調查(集賢)'!D200+'調查(集賢)'!E200+'調查(集賢)'!F200+'調查(集賢)'!G200+'調查(集賢)'!H200+'調查(集賢)'!I200 -> 0 | E203: ='調查(集賢)'!S200+'調查(集賢)'!T200+'調查(集賢)'!U200+'調查(集賢)'!V200+'調查(集賢)'!W200+'調查(集賢)'!X200 -> 0 | F203: - | G203: ='調查(集賢)'!AW200+'調查(集賢)'!AX200+'調查(集賢)'!AY200+'調查(集賢)'!AZ200+'調查(集賢)'!BA200+'調查(集賢)'!BB200 -> 0 | H203: ='調查(集賢)'!BL200+'調查(集賢)'!BM200+'調查(集賢)'!BN200+'調查(集賢)'!BO200+'調查(集賢)'!BP200+'調查(集賢)'!BQ200 -> 0 | I203: ='調查(集賢)'!J200+'調查(集賢)'!K200+'調查(集賢)'!L200+'調查(集賢)'!M200 -> 0 | J203: ='調查(集賢)'!Y200+'調查(集賢)'!Z200+'調查(集賢)'!AA200+'調查(集賢)'!AB200 -> 0 | K203: - | L203: ='調查(集賢)'!BC200+'調查(集賢)'!BD200+'調查(集賢)'!BE200+'調查(集賢)'!BF200 -> 0 | M203: ='調查(集賢)'!BR200+'調查(集賢)'!BS200+'調查(集賢)'!BT200+'調查(集賢)'!BU200 -> 0 | N203: ='調查(集賢)'!N200+'調查(集賢)'!O200+'調查(集賢)'!P200 -> 0 | O203: ='調查(集賢)'!AC200+'調查(集賢)'!AD200+'調查(集賢)'!AE200 -> 0 | P203: - | Q203: ='調查(集賢)'!BG200+'調查(集賢)'!BH200+'調查(集賢)'!BI200 -> 0 | R203: ='調查(集賢)'!BV200+'調查(集賢)'!BW200+'調查(集賢)'!BX200 -> 0
A204: C | B204: 0.072916667 | C204: 0.083333333 | D204: ='調查(集賢)'!D201+'調查(集賢)'!E201+'調查(集賢)'!F201+'調查(集賢)'!G201+'調查(集賢)'!H201+'調查(集賢)'!I201 -> 0 | E204: ='調查(集賢)'!S201+'調查(集賢)'!T201+'調查(集賢)'!U201+'調查(集賢)'!V201+'調查(集賢)'!W201+'調查(集賢)'!X201 -> 0 | F204: - | G204: ='調查(集賢)'!AW201+'調查(集賢)'!AX201+'調查(集賢)'!AY201+'調查(集賢)'!AZ201+'調查(集賢)'!BA201+'調查(集賢)'!BB201 -> 0 | H204: ='調查(集賢)'!BL201+'調查(集賢)'!BM201+'調查(集賢)'!BN201+'調查(集賢)'!BO201+'調查(集賢)'!BP201+'調查(集賢)'!BQ201 -> 0 | I204: ='調查(集賢)'!J201+'調查(集賢)'!K201+'調查(集賢)'!L201+'調查(集賢)'!M201 -> 0 | J204: ='調查(集賢)'!Y201+'調查(集賢)'!Z201+'調查(集賢)'!AA201+'調查(集賢)'!AB201 -> 0 | K204: - | L204: ='調查(集賢)'!BC201+'調查(集賢)'!BD201+'調查(集賢)'!BE201+'調查(集賢)'!BF201 -> 0 | M204: ='調查(集賢)'!BR201+'調查(集賢)'!BS201+'調查(集賢)'!BT201+'調查(集賢)'!BU201 -> 0 | N204: ='調查(集賢)'!N201+'調查(集賢)'!O201+'調查(集賢)'!P201 -> 0 | O204: ='調查(集賢)'!AC201+'調查(集賢)'!AD201+'調查(集賢)'!AE201 -> 0 | P204: - | Q204: ='調查(集賢)'!BG201+'調查(集賢)'!BH201+'調查(集賢)'!BI201 -> 0 | R204: ='調查(集賢)'!BV201+'調查(集賢)'!BW201+'調查(集賢)'!BX201 -> 0
A205: C | B205: 0.083333333 | C205: 0.09375 | D205: ='調查(集賢)'!D202+'調查(集賢)'!E202+'調查(集賢)'!F202+'調查(集賢)'!G202+'調查(集賢)'!H202+'調查(集賢)'!I202 -> 0 | E205: ='調查(集賢)'!S202+'調查(集賢)'!T202+'調查(集賢)'!U202+'調查(集賢)'!V202+'調查(集賢)'!W202+'調查(集賢)'!X202 -> 0 | F205: - | G205: ='調查(集賢)'!AW202+'調查(集賢)'!AX202+'調查(集賢)'!AY202+'調查(集賢)'!AZ202+'調查(集賢)'!BA202+'調查(集賢)'!BB202 -> 0 | H205: ='調查(集賢)'!BL202+'調查(集賢)'!BM202+'調查(集賢)'!BN202+'調查(集賢)'!BO202+'調查(集賢)'!BP202+'調查(集賢)'!BQ202 -> 0 | I205: ='調查(集賢)'!J202+'調查(集賢)'!K202+'調查(集賢)'!L202+'調查(集賢)'!M202 -> 0 | J205: ='調查(集賢)'!Y202+'調查(集賢)'!Z202+'調查(集賢)'!AA202+'調查(集賢)'!AB202 -> 0 | K205: - | L205: ='調查(集賢)'!BC202+'調查(集賢)'!BD202+'調查(集賢)'!BE202+'調查(集賢)'!BF202 -> 0 | M205: ='調查(集賢)'!BR202+'調查(集賢)'!BS202+'調查(集賢)'!BT202+'調查(集賢)'!BU202 -> 0 | N205: ='調查(集賢)'!N202+'調查(集賢)'!O202+'調查(集賢)'!P202 -> 0 | O205: ='調查(集賢)'!AC202+'調查(集賢)'!AD202+'調查(集賢)'!AE202 -> 0 | P205: - | Q205: ='調查(集賢)'!BG202+'調查(集賢)'!BH202+'調查(集賢)'!BI202 -> 0 | R205: ='調查(集賢)'!BV202+'調查(集賢)'!BW202+'調查(集賢)'!BX202 -> 0
...

Sheet 路口基本資料(IN)
A1: ※請填入 | B1: 黃底 | C1: 區域 | E1: 藍底 | F1: 區域進行清單篩選
A2: 版本號：
P3: 控制項
A4: 業主名稱： | G4: 簡圖： | I4: =E18 -> 0 | J4: =F18 -> 0 | L4: N | P4: 平日 | Q4: 1小時 | R4: 往西 | S4: 請選擇 | T4: 大型車 | U4: 小型車 | V4: 機車 | W4: 特殊
A5: 專案編號： | I5: D | J5: E | L5: ↑ | P5: 一般假日 | Q5: 2小時 | R5: 往北 | S5: 直行 | T5: 大型車 | U5: 小型車 | V5: 機車 | W5: 行人
P6: 連續假日 | Q6: 3小時 | R6: 往東 | S6: 右轉 | T6: 大客車 | U6: 小客車 | V6: 三輪車 | W6: 自行車
A7: TC編號： | Q7: 4小時 | R7: 往南 | S7: 左轉 | T7: 大貨車 | U7: 小貨車 | V7: 電動車
A8: 路口名稱： | G8: =D18 -> 0 | H8: C | K8: A | L8: =B18 -> 0 | Q8: 5小時 | R8: 往西南 | T8: 半聯結 | U8: 計程車 | V8: 代步器
A9: 行政區域： | Q9: 6小時 | R9: 往西北 | T9: 全聯結 | U9: 廂型車 | V9: 輔具
Q10: 7小時 | R10: 往東北 | T10: 公車
A11: 日期： | B11: YYYY/MM/DD | I11: B | Q11: 8小時 | R11: 往東南 | T11: 砂石車
A12: 平假日： | B12: 平日 | I12: =C18 -> 0 | J12: =C18 -> 0 | Q12: 9小時
A13: 調查時段： | B13: 16小時 | Q13: 10小時
A14: 天候： | Q14: 11小時
Q15: 12小時
A16: 路口類型： | B16: 五叉路口 | Q16: 13小時
A17: 方向： | B17: A | C17: B | D17: C | E17: D | F17: E | Q17: 14小時
A18: 路段名： | Q18: 15小時
A19: 車道數： | Q19: 16小時
A20: 行車方向： | B20: 往西 | C20: 往北 | D20: 往東 | E20: 往南 | F20: 往南 | Q20: 17小時
A21: 往A方向： | B21: - | C21: 請選擇 | D21: 請選擇 | E21: 請選擇 | F21: 請選擇 | Q21: 18小時
A22: 往B方向： | B22: 請選擇 | C22: - | D22: 請選擇 | E22: 請選擇 | F22: 請選擇 | Q22: 19小時
A23: 往C方向： | B23: 請選擇 | C23: 請選擇 | D23: - | E23: 請選擇 | F23: 請選擇 | Q23: 20小時
A24: 往D方向： | B24: 請選擇 | C24: 請選擇 | D24: 請選擇 | E24: - | F24: 請選擇 | Q24: 21小時
A25: 往E方向： | B25: 請選擇 | C25: 請選擇 | D25: 請選擇 | E25: 請選擇 | F25: - | Q25: 22小時
Q26: 23小時
A27: 車種設定 | Q27: 24小時
A28: 大型車1 | C28: 小型車1 | E28: 機車1 | G28: 特殊1
A29: 大型車2 | C29: 小型車2 | E29: 機車2 | G29: 特殊2
A30: 大型車3 | C30: 小型車3 | E30: 機車3
A31: 大型車4 | C31: 小型車4
A32: 大型車5
A33: 大型車6

Sheet 調查(集賢)
D1: A-大型車1 | E1: A-大型車2 | F1: A-大型車3 | G1: A-大型車4 | H1: A-大型車5 | I1: A-大型車6 | J1: A-小型車1 | K1: A-小型車2 | L1: A-小型車3 | M1: A-小型車4 | N1: A-機車1 | O1: A-機車2 | P1: A-機車3 | Q1: A-特殊1 | R1: A-特殊2 | S1: B-大型車1 | T1: B-大型車2 | U1: B-大型車3 | V1: B-大型車4 | W1: B-大型車5 | X1: B-大型車6 | Y1: B-小型車1 | Z1: B-小型車2 | AA1: B-小型車3 | AB1: B-小型車4 | AC1: B-機車1 | AD1: B-機車2 | AE1: B-機車3 | AF1: B-特殊1 | AG1: B-特殊2 | AH1: C-大型車1 | AI1: C-大型車2 | AJ1: C-大型車3 | AK1: C-大型車4 | AL1: C-大型車5 | AM1: C-大型車6 | AN1: C-小型車1 | AO1: C-小型車2 | AP1: C-小型車3 | AQ1: C-小型車4 | AR1: C-機車1 | AS1: C-機車2 | AT1: C-機車3 | AU1: C-特殊1 | AV1: C-特殊2 | AW1: D-大型車1 | AX1: D-大型車2 | AY1: D-大型車3 | AZ1: D-大型車4 | BA1: D-大型車5 | BB1: D-大型車6 | BC1: D-小型車1 | BD1: D-小型車2 | BE1: D-小型車3 | BF1: D-小型車4 | BG1: D-機車1 | BH1: D-機車2 | BI1: D-機車3 | BJ1: D-特殊1 | BK1: D-特殊2 | BL1: E-大型車1 | BM1: E-大型車2 | BN1: E-大型車3 | BO1: E-大型車4 | BP1: E-大型車5 | BQ1: E-大型車6 | BR1: E-小型車1 | BS1: E-小型車2 | BT1: E-小型車3 | BU1: E-小型車4 | BV1: E-機車1 | BW1: E-機車2 | BX1: E-機車3 | BY1: E-特殊1 | BZ1: E-特殊2
A2: A | B2: 0 | C2: 0.010416667 | S2: 0 | T2: 0 | U2: 0 | V2: 0 | W2: 0 | X2: 0 | Y2: 0 | Z2: 0 | AA2: 0 | AB2: 0 | AC2: 0 | AD2: 0 | AE2: 0 | AF2: 0 | AG2: 0 | AH2: 0 | AI2: 0 | AJ2: 0 | AK2: 0 | AL2: 0 | AM2: 0 | AN2: 0 | AO2: 0 | AP2: 0 | AQ2: 0 | AR2: 0 | AS2: 0 | AT2: 0 | AU2: 0 | AV2: 0 | AW2: 0 | AX2: 0 | AY2: 0 | AZ2: 0 | BA2: 0 | BB2: 0 | BC2: 0 | BD2: 0 | BE2: 0 | BF2: 0 | BG2: 0 | BH2: 0 | BI2: 0 | BJ2: 0 | BK2: 0 | BL2: 0 | BM2: 0 | BN2: 0 | BO2: 0 | BP2: 0 | BQ2: 0 | BR2: 0 | BS2: 0 | BT2: 0 | BU2: 0 | BV2: 0 | BW2: 0 | BX2: 0 | BY2: 0 | BZ2: 0
A3: A | B3: 0.010416667 | C3: 0.020833333 | S3: 0 | T3: 0 | U3: 0 | V3: 0 | W3: 0 | X3: 0 | Y3: 0 | Z3: 0 | AA3: 0 | AB3: 0 | AC3: 0 | AD3: 0 | AE3: 0 | AF3: 0 | AG3: 0 | AH3: 0 | AI3: 0 | AJ3: 0 | AK3: 0 | AL3: 0 | AM3: 0 | AN3: 0 | AO3: 0 | AP3: 0 | AQ3: 0 | AR3: 0 | AS3: 0 | AT3: 0 | AU3: 0 | AV3: 0 | AW3: 0 | AX3: 0 | AY3: 0 | AZ3: 0 | BA3: 0 | BB3: 0 | BC3: 0 | BD3: 0 | BE3: 0 | BF3: 0 | BG3: 0 | BH3: 0 | BI3: 0 | BJ3: 0 | BK3: 0 | BL3: 0 | BM3: 0 | BN3: 0 | BO3: 0 | BP3: 0 | BQ3: 0 | BR3: 0 | BS3: 0 | BT3: 0 | BU3: 0 | BV3: 0 | BW3: 0 | BX3: 0 | BY3: 0 | BZ3: 0
A4: A | B4: 0.020833333 | C4: 0.03125 | S4: 0 | T4: 0 | U4: 0 | V4: 0 | W4: 0 | X4: 0 | Y4: 0 | Z4: 0 | AA4: 0 | AB4: 0 | AC4: 0 | AD4: 0 | AE4: 0 | AF4: 0 | AG4: 0 | AH4: 0 | AI4: 0 | AJ4: 0 | AK4: 0 | AL4: 0 | AM4: 0 | AN4: 0 | AO4: 0 | AP4: 0 | AQ4: 0 | AR4: 0 | AS4: 0 | AT4: 0 | AU4: 0 | AV4: 0 | AW4: 0 | AX4: 0 | AY4: 0 | AZ4: 0 | BA4: 0 | BB4: 0 | BC4: 0 | BD4: 0 | BE4: 0 | BF4: 0 | BG4: 0 | BH4: 0 | BI4: 0 | BJ4: 0 | BK4: 0 | BL4: 0 | BM4: 0 | BN4: 0 | BO4: 0 | BP4: 0 | BQ4: 0 | BR4: 0 | BS4: 0 | BT4: 0 | BU4: 0 | BV4: 0 | BW4: 0 | BX4: 0 | BY4: 0 | BZ4: 0
A5: A | B5: 0.03125 | C5: 0.041666667 | S5: 0 | T5: 0 | U5: 0 | V5: 0 | W5: 0 | X5: 0 | Y5: 0 | Z5: 0 | AA5: 0 | AB5: 0 | AC5: 0 | AD5: 0 | AE5: 0 | AF5: 0 | AG5: 0 | AH5: 0 | AI5: 0 | AJ5: 0 | AK5: 0 | AL5: 0 | AM5: 0 | AN5: 0 | AO5: 0 | AP5: 0 | AQ5: 0 | AR5: 0 | AS5: 0 | AT5: 0 | AU5: 0 | AV5: 0 | AW5: 0 | AX5: 0 | AY5: 0 | AZ5: 0 | BA5: 0 | BB5: 0 | BC5: 0 | BD5: 0 | BE5: 0 | BF5: 0 | BG5: 0 | BH5: 0 | BI5: 0 | BJ5: 0 | BK5: 0 | BL5: 0 | BM5: 0 | BN5: 0 | BO5: 0 | BP5: 0 | BQ5: 0 | BR5: 0 | BS5: 0 | BT5: 0 | BU5: 0 | BV5: 0 | BW5: 0 | BX5: 0 | BY5: 0 | BZ5: 0
A6: A | B6: 0.041666667 | C6: 0.052083333 | S6: 0 | T6: 0 | U6: 0 | V6: 0 | W6: 0 | X6: 0 | Y6: 0 | Z6: 0 | AA6: 0 | AB6: 0 | AC6: 0 | AD6: 0 | AE6: 0 | AF6: 0 | AG6: 0 | AH6: 0 | AI6: 0 | AJ6: 0 | AK6: 0 | AL6: 0 | AM6: 0 | AN6: 0 | AO6: 0 | AP6: 0 | AQ6: 0 | AR6: 0 | AS6: 0 | AT6: 0 | AU6: 0 | AV6: 0 | AW6: 0 | AX6: 0 | AY6: 0 | AZ6: 0 | BA6: 0 | BB6: 0 | BC6: 0 | BD6: 0 | BE6: 0 | BF6: 0 | BG6: 0 | BH6: 0 | BI6: 0 | BJ6: 0 | BK6: 0 | BL6: 0 | BM6: 0 | BN6: 0 | BO6: 0 | BP6: 0 | BQ6: 0 | BR6: 0 | BS6: 0 | BT6: 0 | BU6: 0 | BV6: 0 | BW6: 0 | BX6: 0 | BY6: 0 | BZ6: 0
A7: A | B7: 0.052083333 | C7: 0.0625 | S7: 0 | T7: 0 | U7: 0 | V7: 0 | W7: 0 | X7: 0 | Y7: 0 | Z7: 0 | AA7: 0 | AB7: 0 | AC7: 0 | AD7: 0 | AE7: 0 | AF7: 0 | AG7: 0 | AH7: 0 | AI7: 0 | AJ7: 0 | AK7: 0 | AL7: 0 | AM7: 0 | AN7: 0 | AO7: 0 | AP7: 0 | AQ7: 0 | AR7: 0 | AS7: 0 | AT7: 0 | AU7: 0 | AV7: 0 | AW7: 0 | AX7: 0 | AY7: 0 | AZ7: 0 | BA7: 0 | BB7: 0 | BC7: 0 | BD7: 0 | BE7: 0 | BF7: 0 | BG7: 0 | BH7: 0 | BI7: 0 | BJ7: 0 | BK7: 0 | BL7: 0 | BM7: 0 | BN7: 0 | BO7: 0 | BP7: 0 | BQ7: 0 | BR7: 0 | BS7: 0 | BT7: 0 | BU7: 0 | BV7: 0 | BW7: 0 | BX7: 0 | BY7: 0 | BZ7: 0
A8: A | B8: 0.0625 | C8: 0.072916667 | S8: 0 | T8: 0 | U8: 0 | V8: 0 | W8: 0 | X8: 0 | Y8: 0 | Z8: 0 | AA8: 0 | AB8: 0 | AC8: 0 | AD8: 0 | AE8: 0 | AF8: 0 | AG8: 0 | AH8: 0 | AI8: 0 | AJ8: 0 | AK8: 0 | AL8: 0 | AM8: 0 | AN8: 0 | AO8: 0 | AP8: 0 | AQ8: 0 | AR8: 0 | AS8: 0 | AT8: 0 | AU8: 0 | AV8: 0 | AW8: 0 | AX8: 0 | AY8: 0 | AZ8: 0 | BA8: 0 | BB8: 0 | BC8: 0 | BD8: 0 | BE8: 0 | BF8: 0 | BG8: 0 | BH8: 0 | BI8: 0 | BJ8: 0 | BK8: 0 | BL8: 0 | BM8: 0 | BN8: 0 | BO8: 0 | BP8: 0 | BQ8: 0 | BR8: 0 | BS8: 0 | BT8: 0 | BU8: 0 | BV8: 0 | BW8: 0 | BX8: 0 | BY8: 0 | BZ8: 0
A9: A | B9: 0.072916667 | C9: 0.083333333 | S9: 0 | T9: 0 | U9: 0 | V9: 0 | W9: 0 | X9: 0 | Y9: 0 | Z9: 0 | AA9: 0 | AB9: 0 | AC9: 0 | AD9: 0 | AE9: 0 | AF9: 0 | AG9: 0 | AH9: 0 | AI9: 0 | AJ9: 0 | AK9: 0 | AL9: 0 | AM9: 0 | AN9: 0 | AO9: 0 | AP9: 0 | AQ9: 0 | AR9: 0 | AS9: 0 | AT9: 0 | AU9: 0 | AV9: 0 | AW9: 0 | AX9: 0 | AY9: 0 | AZ9: 0 | BA9: 0 | BB9: 0 | BC9: 0 | BD9: 0 | BE9: 0 | BF9: 0 | BG9: 0 | BH9: 0 | BI9: 0 | BJ9: 0 | BK9: 0 | BL9: 0 | BM9: 0 | BN9: 0 | BO9: 0 | BP9: 0 | BQ9: 0 | BR9: 0 | BS9: 0 | BT9: 0 | BU9: 0 | BV9: 0 | BW9: 0 | BX9: 0 | BY9: 0 | BZ9: 0
A10: A | B10: 0.083333333 | C10: 0.09375 | S10: 0 | T10: 0 | U10: 0 | V10: 0 | W10: 0 | X10: 0 | Y10: 0 | Z10: 0 | AA10: 0 | AB10: 0 | AC10: 0 | AD10: 0 | AE10: 0 | AF10: 0 | AG10: 0 | AH10: 0 | AI10: 0 | AJ10: 0 | AK10: 0 | AL10: 0 | AM10: 0 | AN10: 0 | AO10: 0 | AP10: 0 | AQ10: 0 | AR10: 0 | AS10: 0 | AT10: 0 | AU10: 0 | AV10: 0 | AW10: 0 | AX10: 0 | AY10: 0 | AZ10: 0 | BA10: 0 | BB10: 0 | BC10: 0 | BD10: 0 | BE10: 0 | BF10: 0 | BG10: 0 | BH10: 0 | BI10: 0 | BJ10: 0 | BK10: 0 | BL10: 0 | BM10: 0 | BN10: 0 | BO10: 0 | BP10: 0 | BQ10: 0 | BR10: 0 | BS10: 0 | BT10: 0 | BU10: 0 | BV10: 0 | BW10: 0 | BX10: 0 | BY10: 0 | BZ10: 0
A11: A | B11: 0.09375 | C11: 0.10416667 | S11: 0 | T11: 0 | U11: 0 | V11: 0 | W11: 0 | X11: 0 | Y11: 0 | Z11: 0 | AA11: 0 | AB11: 0 | AC11: 0 | AD11: 0 | AE11: 0 | AF11: 0 | AG11: 0 | AH11: 0 | AI11: 0 | AJ11: 0 | AK11: 0 | AL11: 0 | AM11: 0 | AN11: 0 | AO11: 0 | AP11: 0 | AQ11: 0 | AR11: 0 | AS11: 0 | AT11: 0 | AU11: 0 | AV11: 0 | AW11: 0 | AX11: 0 | AY11: 0 | AZ11: 0 | BA11: 0 | BB11: 0 | BC11: 0 | BD11: 0 | BE11: 0 | BF11: 0 | BG11: 0 | BH11: 0 | BI11: 0 | BJ11: 0 | BK11: 0 | BL11: 0 | BM11: 0 | BN11: 0 | BO11: 0 | BP11: 0 | BQ11: 0 | BR11: 0 | BS11: 0 | BT11: 0 | BU11: 0 | BV11: 0 | BW11: 0 | BX11: 0 | BY11: 0 | BZ11: 0
A12: A | B12: 0.10416667 | C12: 0.11458333 | S12: 0 | T12: 0 | U12: 0 | V12: 0 | W12: 0 | X12: 0 | Y12: 0 | Z12: 0 | AA12: 0 | AB12: 0 | AC12: 0 | AD12: 0 | AE12: 0 | AF12: 0 | AG12: 0 | AH12: 0 | AI12: 0 | AJ12: 0 | AK12: 0 | AL12: 0 | AM12: 0 | AN12: 0 | AO12: 0 | AP12: 0 | AQ12: 0 | AR12: 0 | AS12: 0 | AT12: 0 | AU12: 0 | AV12: 0 | AW12: 0 | AX12: 0 | AY12: 0 | AZ12: 0 | BA12: 0 | BB12: 0 | BC12: 0 | BD12: 0 | BE12: 0 | BF12: 0 | BG12: 0 | BH12: 0 | BI12: 0 | BJ12: 0 | BK12: 0 | BL12: 0 | BM12: 0 | BN12: 0 | BO12: 0 | BP12: 0 | BQ12: 0 | BR12: 0 | BS12: 0 | BT12: 0 | BU12: 0 | BV12: 0 | BW12: 0 | BX12: 0 | BY12: 0 | BZ12: 0
A13: A | B13: 0.11458333 | C13: 0.125 | S13: 0 | T13: 0 | U13: 0 | V13: 0 | W13: 0 | X13: 0 | Y13: 0 | Z13: 0 | AA13: 0 | AB13: 0 | AC13: 0 | AD13: 0 | AE13: 0 | AF13: 0 | AG13: 0 | AH13: 0 | AI13: 0 | AJ13: 0 | AK13: 0 | AL13: 0 | AM13: 0 | AN13: 0 | AO13: 0 | AP13: 0 | AQ13: 0 | AR13: 0 | AS13: 0 | AT13: 0 | AU13: 0 | AV13: 0 | AW13: 0 | AX13: 0 | AY13: 0 | AZ13: 0 | BA13: 0 | BB13: 0 | BC13: 0 | BD13: 0 | BE13: 0 | BF13: 0 | BG13: 0 | BH13: 0 | BI13: 0 | BJ13: 0 | BK13: 0 | BL13: 0 | BM13: 0 | BN13: 0 | BO13: 0 | BP13: 0 | BQ13: 0 | BR13: 0 | BS13: 0 | BT13: 0 | BU13: 0 | BV13: 0 | BW13: 0 | BX13: 0 | BY13: 0 | BZ13: 0
... A96: A | B96: 0.97916667 | C96: 0.98958333 | S96: 0 | T96: 0 | U96: 0 | V96: 0 | W96: 0 | X96: 0 | Y96: 0 | Z96: 0 | AA96: 0 | AB96: 0 | AC96: 0 | AD96: 0 | AE96: 0 | AF96: 0 | AG96: 0 | AH96: 0 | AI96: 0 | AJ96: 0 | AK96: 0 | AL96: 0 | AM96: 0 | AN96: 0 | AO96: 0 | AP96: 0 | AQ96: 0 | AR96: 0 | AS96: 0 | AT96: 0 | AU96: 0 | AV96: 0 | AW96: 0 | AX96: 0 | AY96: 0 | AZ96: 0 | BA96: 0 | BB96: 0 | BC96: 0 | BD96: 0 | BE96: 0 | BF96: 0 | BG96: 0 | BH96: 0 | BI96: 0 | BJ96: 0 | BK96: 0 | BL96: 0 | BM96: 0 | BN96: 0 | BO96: 0 | BP96: 0 | BQ96: 0 | BR96: 0 | BS96: 0 | BT96: 0 | BU96: 0 | BV96: 0 | BW96: 0 | BX96: 0 | BY96: 0 | BZ96: 0
A97: A | B97: 0.98958333 | C97: 24:00 | S97: 0 | T97: 0 | U97: 0 | V97: 0 | W97: 0 | X97: 0 | Y97: 0 | Z97: 0 | AA97: 0 | AB97: 0 | AC97: 0 | AD97: 0 | AE97: 0 | AF97: 0 | AG97: 0 | AH97: 0 | AI97: 0 | AJ97: 0 | AK97: 0 | AL97: 0 | AM97: 0 | AN97: 0 | AO97: 0 | AP97: 0 | AQ97: 0 | AR97: 0 | AS97: 0 | AT97: 0 | AU97: 0 | AV97: 0 | AW97: 0 | AX97: 0 | AY97: 0 | AZ97: 0 | BA97: 0 | BB97: 0 | BC97: 0 | BD97: 0 | BE97: 0 | BF97: 0 | BG97: 0 | BH97: 0 | BI97: 0 | BJ97: 0 | BK97: 0 | BL97: 0 | BM97: 0 | BN97: 0 | BO97: 0 | BP97: 0 | BQ97: 0 | BR97: 0 | BS97: 0 | BT97: 0 | BU97: 0 | BV97: 0 | BW97: 0 | BX97: 0 | BY97: 0 | BZ97: 0
A98: B | B98: 0 | C98: 0.010416667 | D98: 0 | E98: 0 | F98: 0 | G98: 0 | H98: 0 | I98: 0 | J98: 0 | K98: 0 | L98: 0 | M98: 0 | N98: 0 | O98: 0 | P98: 0 | Q98: 0 | R98: 0 | AH98: 0 | AI98: 0 | AJ98: 0 | AK98: 0 | AL98: 0 | AM98: 0 | AN98: 0 | AO98: 0 | AP98: 0 | AQ98: 0 | AR98: 0 | AS98: 0 | AT98: 0 | AU98: 0 | AV98: 0 | AW98: 0 | AX98: 0 | AY98: 0 | AZ98: 0 | BA98: 0 | BB98: 0 | BC98: 0 | BD98: 0 | BE98: 0 | BF98: 0 | BG98: 0 | BH98: 0 | BI98: 0 | BJ98: 0 | BK98: 0 | BL98: 0 | BM98: 0 | BN98: 0 | BO98: 0 | BP98: 0 | BQ98: 0 | BR98: 0 | BS98: 0 | BT98: 0 | BU98: 0 | BV98: 0 | BW98: 0 | BX98: 0 | BY98: 0 | BZ98: 0
A99: B | B99: 0.010416667 | C99: 0.020833333 | D99: 0 | E99: 0 | F99: 0 | G99: 0 | H99: 0 | I99: 0 | J99: 0 | K99: 0 | L99: 0 | M99: 0 | N99: 0 | O99: 0 | P99: 0 | Q99: 0 | R99: 0 | AH99: 0 | AI99: 0 | AJ99: 0 | AK99: 0 | AL99: 0 | AM99: 0 | AN99: 0 | AO99: 0 | AP99: 0 | AQ99: 0 | AR99: 0 | AS99: 0 | AT99: 0 | AU99: 0 | AV99: 0 | AW99: 0 | AX99: 0 | AY99: 0 | AZ99: 0 | BA99: 0 | BB99: 0 | BC99: 0 | BD99: 0 | BE99: 0 | BF99: 0 | BG99: 0 | BH99: 0 | BI99: 0 | BJ99: 0 | BK99: 0 | BL99: 0 | BM99: 0 | BN99: 0 | BO99: 0 | BP99: 0 | BQ99: 0 | BR99: 0 | BS99: 0 | BT99: 0 | BU99: 0 | BV99: 0 | BW99: 0 | BX99: 0 | BY99: 0 | BZ99: 0
A100: B | B100: 0.020833333 | C100: 0.03125 | D100: 0 | E100: 0 | F100: 0 | G100: 0 | H100: 0 | I100: 0 | J100: 0 | K100: 0 | L100: 0 | M100: 0 | N100: 0 | O100: 0 | P100: 0 | Q100: 0 | R100: 0 | AH100: 0 | AI100: 0 | AJ100: 0 | AK100: 0 | AL100: 0 | AM100: 0 | AN100: 0 | AO100: 0 | AP100: 0 | AQ100: 0 | AR100: 0 | AS100: 0 | AT100: 0 | AU100: 0 | AV100: 0 | AW100: 0 | AX100: 0 | AY100: 0 | AZ100: 0 | BA100: 0 | BB100: 0 | BC100: 0 | BD100: 0 | BE100: 0 | BF100: 0 | BG100: 0 | BH100: 0 | BI100: 0 | BJ100: 0 | BK100: 0 | BL100: 0 | BM100: 0 | BN100: 0 | BO100: 0 | BP100: 0 | BQ100: 0 | BR100: 0 | BS100: 0 | BT100: 0 | BU100: 0 | BV100: 0 | BW100: 0 | BX100: 0 | BY100: 0 | BZ100: 0
A101: B | B101: 0.03125 | C101: 0.041666667 | D101: 0 | E101: 0 | F101: 0 | G101: 0 | H101: 0 | I101: 0 | J101: 0 | K101: 0 | L101: 0 | M101: 0 | N101: 0 | O101: 0 | P101: 0 | Q101: 0 | R101: 0 | AH101: 0 | AI101: 0 | AJ101: 0 | AK101: 0 | AL101: 0 | AM101: 0 | AN101: 0 | AO101: 0 | AP101: 0 | AQ101: 0 | AR101: 0 | AS101: 0 | AT101: 0 | AU101: 0 | AV101: 0 | AW101: 0 | AX101: 0 | AY101: 0 | AZ101: 0 | BA101: 0 | BB101: 0 | BC101: 0 | BD101: 0 | BE101: 0 | BF101: 0 | BG101: 0 | BH101: 0 | BI101: 0 | BJ101: 0 | BK101: 0 | BL101: 0 | BM101: 0 | BN101: 0 | BO101: 0 | BP101: 0 | BQ101: 0 | BR101: 0 | BS101: 0 | BT101: 0 | BU101: 0 | BV101: 0 | BW101: 0 | BX101: 0 | BY101: 0 | BZ101: 0
A102: B | B102: 0.041666667 | C102: 0.052083333 | D102: 0 | E102: 0 | F102: 0 | G102: 0 | H102: 0 | I102: 0 | J102: 0 | K102: 0 | L102: 0 | M102: 0 | N102: 0 | O102: 0 | P102: 0 | Q102: 0 | R102: 0 | AH102: 0 | AI102: 0 | AJ102: 0 | AK102: 0 | AL102: 0 | AM102: 0 | AN102: 0 | AO102: 0 | AP102: 0 | AQ102: 0 | AR102: 0 | AS102: 0 | AT102: 0 | AU102: 0 | AV102: 0 | AW102: 0 | AX102: 0 | AY102: 0 | AZ102: 0 | BA102: 0 | BB102: 0 | BC102: 0 | BD102: 0 | BE102: 0 | BF102: 0 | BG102: 0 | BH102: 0 | BI102: 0 | BJ102: 0 | BK102: 0 | BL102: 0 | BM102: 0 | BN102: 0 | BO102: 0 | BP102: 0 | BQ102: 0 | BR102: 0 | BS102: 0 | BT102: 0 | BU102: 0 | BV102: 0 | BW102: 0 | BX102: 0 | BY102: 0 | BZ102: 0
A103: B | B103: 0.052083333 | C103: 0.0625 | D103: 0 | E103: 0 | F103: 0 | G103: 0 | H103: 0 | I103: 0 | J103: 0 | K103: 0 | L103: 0 | M103: 0 | N103: 0 | O103: 0 | P103: 0 | Q103: 0 | R103: 0 | AH103: 0 | AI103: 0 | AJ103: 0 | AK103: 0 | AL103: 0 | AM103: 0 | AN103: 0 | AO103: 0 | AP103: 0 | AQ103: 0 | AR103: 0 | AS103: 0 | AT103: 0 | AU103: 0 | AV103: 0 | AW103: 0 | AX103: 0 | AY103: 0 | AZ103: 0 | BA103: 0 | BB103: 0 | BC103: 0 | BD103: 0 | BE103: 0 | BF103: 0 | BG103: 0 | BH103: 0 | BI103: 0 | BJ103: 0 | BK103: 0 | BL103: 0 | BM103: 0 | BN103: 0 | BO103: 0 | BP103: 0 | BQ103: 0 | BR103: 0 | BS103: 0 | BT103: 0 | BU103: 0 | BV103: 0 | BW103: 0 | BX103: 0 | BY103: 0 | BZ103: 0
A104: B | B104: 0.0625 | C104: 0.072916667 | D104: 0 | E104: 0 | F104: 0 | G104: 0 | H104: 0 | I104: 0 | J104: 0 | K104: 0 | L104: 0 | M104: 0 | N104: 0 | O104: 0 | P104: 0 | Q104: 0 | R104: 0 | AH104: 0 | AI104: 0 | AJ104: 0 | AK104: 0 | AL104: 0 | AM104: 0 | AN104: 0 | AO104: 0 | AP104: 0 | AQ104: 0 | AR104: 0 | AS104: 0 | AT104: 0 | AU104: 0 | AV104: 0 | AW104: 0 | AX104: 0 | AY104: 0 | AZ104: 0 | BA104: 0 | BB104: 0 | BC104: 0 | BD104: 0 | BE104: 0 | BF104: 0 | BG104: 0 | BH104: 0 | BI104: 0 | BJ104: 0 | BK104: 0 | BL104: 0 | BM104: 0 | BN104: 0 | BO104: 0 | BP104: 0 | BQ104: 0 | BR104: 0 | BS104: 0 | BT104: 0 | BU104: 0 | BV104: 0 | BW104: 0 | BX104: 0 | BY104: 0 | BZ104: 0
A105: B | B105: 0.072916667 | C105: 0.083333333 | D105: 0 | E105: 0 | F105: 0 | G105: 0 | H105: 0 | I105: 0 | J105: 0 | K105: 0 | L105: 0 | M105: 0 | N105: 0 | O105: 0 | P105: 0 | Q105: 0 | R105: 0 | AH105: 0 | AI105: 0 | AJ105: 0 | AK105: 0 | AL105: 0 | AM105: 0 | AN105: 0 | AO105: 0 | AP105: 0 | AQ105: 0 | AR105: 0 | AS105: 0 | AT105: 0 | AU105: 0 | AV105: 0 | AW105: 0 | AX105: 0 | AY105: 0 | AZ105: 0 | BA105: 0 | BB105: 0 | BC105: 0 | BD105: 0 | BE105: 0 | BF105: 0 | BG105: 0 | BH105: 0 | BI105: 0 | BJ105: 0 | BK105: 0 | BL105: 0 | BM105: 0 | BN105: 0 | BO105: 0 | BP105: 0 | BQ105: 0 | BR105: 0 | BS105: 0 | BT105: 0 | BU105: 0 | BV105: 0 | BW105: 0 | BX105: 0 | BY105: 0 | BZ105: 0
A106: B | B106: 0.083333333 | C106: 0.09375 | D106: 0 | E106: 0 | F106: 0 | G106: 0 | H106: 0 | I106: 0 | J106: 0 | K106: 0 | L106: 0 | M106: 0 | N106: 0 | O106: 0 | P106: 0 | Q106: 0 | R106: 0 | AH106: 0 | AI106: 0 | AJ106: 0 | AK106: 0 | AL106: 0 | AM106: 0 | AN106: 0 | AO106: 0 | AP106: 0 | AQ106: 0 | AR106: 0 | AS106: 0 | AT106: 0 | AU106: 0 | AV106: 0 | AW106: 0 | AX106: 0 | AY106: 0 | AZ106: 0 | BA106: 0 | BB106: 0 | BC106: 0 | BD106: 0 | BE106: 0 | BF106: 0 | BG106: 0 | BH106: 0 | BI106: 0 | BJ106: 0 | BK106: 0 | BL106: 0 | BM106: 0 | BN106: 0 | BO106: 0 | BP106: 0 | BQ106: 0 | BR106: 0 | BS106: 0 | BT106: 0 | BU106: 0 | BV106: 0 | BW106: 0 | BX106: 0 | BY106: 0 | BZ106: 0
A107: B | B107: 0.09375 | C107: 0.10416667 | D107: 0 | E107: 0 | F107: 0 | G107: 0 | H107: 0 | I107: 0 | J107: 0 | K107: 0 | L107: 0 | M107: 0 | N107: 0 | O107: 0 | P107: 0 | Q107: 0 | R107: 0 | AH107: 0 | AI107: 0 | AJ107: 0 | AK107: 0 | AL107: 0 | AM107: 0 | AN107: 0 | AO107: 0 | AP107: 0 | AQ107: 0 | AR107: 0 | AS107: 0 | AT107: 0 | AU107: 0 | AV107: 0 | AW107: 0 | AX107: 0 | AY107: 0 | AZ107: 0 | BA107: 0 | BB107: 0 | BC107: 0 | BD107: 0 | BE107: 0 | BF107: 0 | BG107: 0 | BH107: 0 | BI107: 0 | BJ107: 0 | BK107: 0 | BL107: 0 | BM107: 0 | BN107: 0 | BO107: 0 | BP107: 0 | BQ107: 0 | BR107: 0 | BS107: 0 | BT107: 0 | BU107: 0 | BV107: 0 | BW107: 0 | BX107: 0 | BY107: 0 | BZ107: 0
A108: B | B108: 0.10416667 | C108: 0.11458333 | D108: 0 | E108: 0 | F108: 0 | G108: 0 | H108: 0 | I108: 0 | J108: 0 | K108: 0 | L108: 0 | M108: 0 | N108: 0 | O108: 0 | P108: 0 | Q108: 0 | R108: 0 | AH108: 0 | AI108: 0 | AJ108: 0 | AK108: 0 | AL108: 0 | AM108: 0 | AN108: 0 | AO108: 0 | AP108: 0 | AQ108: 0 | AR108: 0 | AS108: 0 | AT108: 0 | AU108: 0 | AV108: 0 | AW108: 0 | AX108: 0 | AY108: 0 | AZ108: 0 | BA108: 0 | BB108: 0 | BC108: 0 | BD108: 0 | BE108: 0 | BF108: 0 | BG108: 0 | BH108: 0 | BI108: 0 | BJ108: 0 | BK108: 0 | BL108: 0 | BM108: 0 | BN108: 0 | BO108: 0 | BP108: 0 | BQ108: 0 | BR108: 0 | BS108: 0 | BT108: 0 | BU108: 0 | BV108: 0 | BW108: 0 | BX108: 0 | BY108: 0 | BZ108: 0
A109: B | B109: 0.11458333 | C109: 0.125 | D109: 0 | E109: 0 | F109: 0 | G109: 0 | H109: 0 | I109: 0 | J109: 0 | K109: 0 | L109: 0 | M109: 0 | N109: 0 | O109: 0 | P109: 0 | Q109: 0 | R109: 0 | AH109: 0 | AI109: 0 | AJ109: 0 | AK109: 0 | AL109: 0 | AM109: 0 | AN109: 0 | AO109: 0 | AP109: 0 | AQ109: 0 | AR109: 0 | AS109: 0 | AT109: 0 | AU109: 0 | AV109: 0 | AW109: 0 | AX109: 0 | AY109: 0 | AZ109: 0 | BA109: 0 | BB109: 0 | BC109: 0 | BD109: 0 | BE109: 0 | BF109: 0 | BG109: 0 | BH109: 0 | BI109: 0 | BJ109: 0 | BK109: 0 | BL109: 0 | BM109: 0 | BN109: 0 | BO109: 0 | BP109: 0 | BQ109: 0 | BR109: 0 | BS109: 0 | BT109: 0 | BU109: 0 | BV109: 0 | BW109: 0 | BX109: 0 | BY109: 0 | BZ109: 0
... A192: B | B192: 0.97916667 | C192: 0.98958333 | D192: 0 | E192: 0 | F192: 0 | G192: 0 | H192: 0 | I192: 0 | J192: 0 | K192: 0 | L192: 0 | M192: 0 | N192: 0 | O192: 0 | P192: 0 | Q192: 0 | R192: 0 | AH192: 0 | AI192: 0 | AJ192: 0 | AK192: 0 | AL192: 0 | AM192: 0 | AN192: 0 | AO192: 0 | AP192: 0 | AQ192: 0 | AR192: 0 | AS192: 0 | AT192: 0 | AU192: 0 | AV192: 0 | AW192: 0 | AX192: 0 | AY192: 0 | AZ192: 0 | BA192: 0 | BB192: 0 | BC192: 0 | BD192: 0 | BE192: 0 | BF192: 0 | BG192: 0 | BH192: 0 | BI192: 0 | BJ192: 0 | BK192: 0 | BL192: 0 | BM192: 0 | BN192: 0 | BO192: 0 | BP192: 0 | BQ192: 0 | BR192: 0 | BS192: 0 | BT192: 0 | BU192: 0 | BV192: 0 | BW192: 0 | BX192: 0 | BY192: 0 | BZ192: 0
A193: B | B193: 0.98958333 | C193: 24:00 | D193: 0 | E193: 0 | F193: 0 | G193: 0 | H193: 0 | I193: 0 | J193: 0 | K193: 0 | L193: 0 | M193: 0 | N193: 0 | O193: 0 | P193: 0 | Q193: 0 | R193: 0 | AH193: 0 | AI193: 0 | AJ193: 0 | AK193: 0 | AL193: 0 | AM193: 0 | AN193: 0 | AO193: 0 | AP193: 0 | AQ193: 0 | AR193: 0 | AS193: 0 | AT193: 0 | AU193: 0 | AV193: 0 | AW193: 0 | AX193: 0 | AY193: 0 | AZ193: 0 | BA193: 0 | BB193: 0 | BC193: 0 | BD193: 0 | BE193: 0 | BF193: 0 | BG193: 0 | BH193: 0 | BI193: 0 | BJ193: 0 | BK193: 0 | BL193: 0 | BM193: 0 | BN193: 0 | BO193: 0 | BP193: 0 | BQ193: 0 | BR193: 0 | BS193: 0 | BT193: 0 | BU193: 0 | BV193: 0 | BW193: 0 | BX193: 0 | BY193: 0 | BZ193: 0
A194: C | B194: 0 | C194: 0.010416667 | D194: 0 | E194: 0 | F194: 0 | G194: 0 | H194: 0 | I194: 0 | J194: 0 | K194: 0 | L194: 0 | M194: 0 | N194: 0 | O194: 0 | P194: 0 | Q194: 0 | R194: 0 | S194: 0 | T194: 0 | U194: 0 | V194: 0 | W194: 0 | X194: 0 | Y194: 0 | Z194: 0 | AA194: 0 | AB194: 0 | AC194: 0 | AD194: 0 | AE194: 0 | AF194: 0 | AG194: 0 | AW194: 0 | AX194: 0 | AY194: 0 | AZ194: 0 | BA194: 0 | BB194: 0 | BC194: 0 | BD194: 0 | BE194: 0 | BF194: 0 | BG194: 0 | BH194: 0 | BI194: 0 | BJ194: 0 | BK194: 0 | BL194: 0 | BM194: 0 | BN194: 0 | BO194: 0 | BP194: 0 | BQ194: 0 | BR194: 0 | BS194: 0 | BT194: 0 | BU194: 0 | BV194: 0 | BW194: 0 | BX194: 0 | BY194: 0 | BZ194: 0
A195: C | B195: 0.010416667 | C195: 0.020833333 | D195: 0 | E195: 0 | F195: 0 | G195: 0 | H195: 0 | I195: 0 | J195: 0 | K195: 0 | L195: 0 | M195: 0 | N195: 0 | O195: 0 | P195: 0 | Q195: 0 | R195: 0 | S195: 0 | T195: 0 | U195: 0 | V195: 0 | W195: 0 | X195: 0 | Y195: 0 | Z195: 0 | AA195: 0 | AB195: 0 | AC195: 0 | AD195: 0 | AE195: 0 | AF195: 0 | AG195: 0 | AW195: 0 | AX195: 0 | AY195: 0 | AZ195: 0 | BA195: 0 | BB195: 0 | BC195: 0 | BD195: 0 | BE195: 0 | BF195: 0 | BG195: 0 | BH195: 0 | BI195: 0 | BJ195: 0 | BK195: 0 | BL195: 0 | BM195: 0 | BN195: 0 | BO195: 0 | BP195: 0 | BQ195: 0 | BR195: 0 | BS195: 0 | BT195: 0 | BU195: 0 | BV195: 0 | BW195: 0 | BX195: 0 | BY195: 0 | BZ195: 0
A196: C | B196: 0.020833333 | C196: 0.03125 | D196: 0 | E196: 0 | F196: 0 | G196: 0 | H196: 0 | I196: 0 | J196: 0 | K196: 0 | L196: 0 | M196: 0 | N196: 0 | O196: 0 | P196: 0 | Q196: 0 | R196: 0 | S196: 0 | T196: 0 | U196: 0 | V196: 0 | W196: 0 | X196: 0 | Y196: 0 | Z196: 0 | AA196: 0 | AB196: 0 | AC196: 0 | AD196: 0 | AE196: 0 | AF196: 0 | AG196: 0 | AW196: 0 | AX196: 0 | AY196: 0 | AZ196: 0 | BA196: 0 | BB196: 0 | BC196: 0 | BD196: 0 | BE196: 0 | BF196: 0 | BG196: 0 | BH196: 0 | BI196: 0 | BJ196: 0 | BK196: 0 | BL196: 0 | BM196: 0 | BN196: 0 | BO196: 0 | BP196: 0 | BQ196: 0 | BR196: 0 | BS196: 0 | BT196: 0 | BU196: 0 | BV196: 0 | BW196: 0 | BX196: 0 | BY196: 0 | BZ196: 0
