Workbook
Name _PCU11: [1]基本!$B$35
Name _PCU12: [1]基本!$C$35
Name _PCU13: [1]基本!$D$35
Name _PCU14: [1]基本!$E$35
Name _PCU21: [1]基本!$F$35
Name _PCU22: [1]基本!$G$35
Name _PCU23: [1]基本!$H$35
Name _PCU31: [1]基本!$I$35
Name _PCU32: [1]基本!$J$35
Name _PCU33: [1]基本!$K$35
Name GAM: #REF!
Name GINFO: #REF!
Name GPM: #REF!
Name GRAPH: #REF!
Name HN: [1]集賢!$M$1
Name ROADNAME: [2]基本!$I$5,[2]基本!$G$9,[2]基本!$E$5,[2]基本!$G$1
Name TABLE: #REF!
Name 尖峰: #REF!
Name 夜間: #REF!
Name 時制A: #REF!,#REF!,#REF!,#REF!,#REF!
Name 時制B: #REF!,#REF!,#REF!,#REF!,#REF!
Name 假日: #REF!
Name 週五夜: #REF!
Name 離峰: #REF!

Sheet 轉向量
A1: 套用PCE | E1: 大車左轉 | F1: 大車直行 | G1: 大車右轉 | I1: 小車左轉 | J1: 小車直行 | K1: 小車右轉 | N1: 機車二段左轉 | O1: 機車左轉 | Q1: 機車直行 | S1: 機車右轉
E2: 2 | F2: 1.8 | G2: 2.7 | I2: 1.05 | J2: 1 | K2: 1.08 | N2: 0 | O2: 0.43 | Q2: 0.42 | S2: 0.45
A4: 臨近路段 | B4: 起始時間 | C4: 結束時間 | D4: 大車A | E4: 大車B | F4: 大車C | G4: 大車D | H4: 小車A | I4: 小車B | J4: 小車C | K4: 小車D | L4: 機車兩段A | M4: 機車A | N4: 機車兩段B | O4: 機車B | P4: 機車兩段C | Q4: 機車C | R4: 機車兩段D | S4: 機車D | V4: 大車(左) | W4: 大車(直) | X4: 大車(右) | Z4: 小車(左) | AA4: 小車(直) | AB4: 小車(右) | AD4: 機車(左) | AE4: 機車(直) | AF4: 機車(右) | AH4: 機車二段
A5: A | B5: 0 | C5: 0.010416667 | D5: - | E5: ='調查(集賢)'!D2+'調查(集賢)'!E2+'調查(集賢)'!F2+'調查(集賢)'!G2+'調查(集賢)'!H2+'調查(集賢)'!I2+'調查(集賢)'!AR2+'調查(集賢)'!AS2+'調查(集賢)'!AT2+'調查(集賢)'!AU2+'調查(集賢)'!AV2+'調查(集賢)'!AW2+'調查(集賢)'!CF2+'調查(集賢)'!CG2+'調查(集賢)'!CH2+'調查(集賢)'!CI2+'調查(集賢)'!CJ2+'調查(集賢)'!CK2+'調查(集賢)'!DS2+'調查(集賢)'!DT2+'調查(集賢)'!DU2+'調查(集賢)'!DV2+'調查(集賢)'!DW2+'調查(集賢)'!DX2 -> 0 | F5: ='調查(集賢)'!R2+'調查(集賢)'!S2+'調查(集賢)'!T2+'調查(集賢)'!U2+'調查(集賢)'!V2+'調查(集賢)'!W2+'調查(集賢)'!BF2+'調查(集賢)'!BG2+'調查(集賢)'!BH2+'調查(集賢)'!BI2+'調查(集賢)'!BJ2+'調查(集賢)'!BK2+'調查(集賢)'!CS2+'調查(集賢)'!CT2+'調查(集賢)'!CU2+'調查(集賢)'!CV2+'調查(集賢)'!CW2+'調查(集賢)'!CX2+'調查(集賢)'!EF2+'調查(集賢)'!EG2+'調查(集賢)'!EH2+'調查(集賢)'!EI2+'調查(集賢)'!EJ2+'調查(集賢)'!EK2 -> 0 | G5: ='調查(集賢)'!AE2+'調查(集賢)'!AF2+'調查(集賢)'!AG2+'調查(集賢)'!AH2+'調查(集賢)'!AI2+'調查(集賢)'!AJ2+'調查(集賢)'!BS2+'調查(集賢)'!BT2+'調查(集賢)'!BU2+'調查(集賢)'!BV2+'調查(集賢)'!BW2+'調查(集賢)'!BX2+'調查(集賢)'!DF2+'調查(集賢)'!DG2+'調查(集賢)'!DH2+'調查(集賢)'!DI2+'調查(集賢)'!DJ2+'調查(集賢)'!DK2+'調查(集賢)'!ES2+'調查(集賢)'!ET2+'調查(集賢)'!EU2+'調查(集賢)'!EV2+'調查(集賢)'!EW2+'調查(集賢)'!EX2 -> 0 | H5: - | I5: ='調查(集賢)'!J2+'調查(集賢)'!K2+'調查(集賢)'!L2+'調查(集賢)'!M2+'調查(集賢)'!AX2+'調查(集賢)'!AY2+'調查(集賢)'!AZ2+'調查(集賢)'!BA2+'調查(集賢)'!CL2+'調查(集賢)'!CM2+'調查(集賢)'!CN2+'調查(集賢)'!CO2+'調查(集賢)'!DY2+'調查(集賢)'!DZ2+'調查(集賢)'!EA2+'調查(集賢)'!EB2 -> 0 | J5: ='調查(集賢)'!X2+'調查(集賢)'!Y2+'調查(集賢)'!Z2+'調查(集賢)'!AA2+'調查(集賢)'!BL2+'調查(集賢)'!BM2+'調查(集賢)'!BN2+'調查(集賢)'!BO2+'調查(集賢)'!CY2+'調查(集賢)'!CZ2+'調查(集賢)'!DA2+'調查(集賢)'!DB2+'調查(集賢)'!EL2+'調查(集賢)'!EM2+'調查(集賢)'!EN2+'調查(集賢)'!EO2 -> 0 | K5: ='調查(集賢)'!AK2+'調查(集賢)'!AL2+'調查(集賢)'!AM2+'調查(集賢)'!AN2+'調查(集賢)'!BY2+'調查(集賢)'!BZ2+'調查(集賢)'!CA2+'調查(集賢)'!CB2+'調查(集賢)'!DL2+'調查(集賢)'!DM2+'調查(集賢)'!DN2+'調查(集賢)'!DO2+'調查(集賢)'!EY2+'調查(集賢)'!EZ2+'調查(集賢)'!FA2+'調查(集賢)'!FB2 -> 0 | L5: - | M5: - | N5: ='調查(集賢)'!Q2+'調查(集賢)'!BE2 -> 0 | O5: ='調查(集賢)'!N2+'調查(集賢)'!O2+'調查(集賢)'!P2+'調查(集賢)'!BB2+'調查(集賢)'!BC2+'調查(集賢)'!BD2+'調查(集賢)'!CP2+'調查(集賢)'!CQ2+'調查(集賢)'!CR2+'調查(集賢)'!EC2+'調查(集賢)'!ED2+'調查(集賢)'!EE2 -> 0 | P5: - | Q5: =IF(AE5>0,AE5-AH5-AH101,0) -> 0 | R5: - | S5: ='調查(集賢)'!AO2+'調查(集賢)'!AP2+'調查(集賢)'!AQ2+'調查(集賢)'!CC2+'調查(集賢)'!CD2+'調查(集賢)'!CE2+'調查(集賢)'!DP2+'調查(集賢)'!DQ2+'調查(集賢)'!DR2+'調查(集賢)'!FC2+'調查(集賢)'!FD2+'調查(集賢)'!FE2 -> 0 | V5: ='調查(集賢)'!D2+'調查(集賢)'!E2+'調查(集賢)'!F2+'調查(集賢)'!G2+'調查(集賢)'!H2+'調查(集賢)'!I2+'調查(集賢)'!AR2+'調查(集賢)'!AS2+'調查(集賢)'!AT2+'調查(集賢)'!AU2+'調查(集賢)'!AV2+'調查(集賢)'!AW2+'調查(集賢)'!CF2+'調查(集賢)'!CG2+'調查(集賢)'!CH2+'調查(集賢)'!CI2+'調查(集賢)'!CJ2+'調查(集賢)'!CK2+'調查(集賢)'!DS2+'調查(集賢)'!DT2+'調查(集賢)'!DU2+'調查(集賢)'!DV2+'調查(集賢)'!DW2+'調查(集賢)'!DX2 -> 0 | W5: ='調查(集賢)'!R2+'調查(集賢)'!S2+'調查(集賢)'!T2+'調查(集賢)'!U2+'調查(集賢)'!V2+'調查(集賢)'!W2+'調查(集賢)'!BF2+'調查(集賢)'!BG2+'調查(集賢)'!BH2+'調查(集賢)'!BI2+'調查(集賢)'!BJ2+'調查(集賢)'!BK2+'調查(集賢)'!CS2+'調查(集賢)'!CT2+'調查(集賢)'!CU2+'調查(集賢)'!CV2+'調查(集賢)'!CW2+'調查(集賢)'!CX2+'調查(集賢)'!EF2+'調查(集賢)'!EG2+'調查(集賢)'!EH2+'調查(集賢)'!EI2+'調查(集賢)'!EJ2+'調查(集賢)'!EK2 -> 0 | X5: ='調查(集賢)'!AE2+'調查(集賢)'!AF2+'調查(集賢)'!AG2+'調查(集賢)'!AH2+'調查(集賢)'!AI2+'調查(集賢)'!AJ2+'調查(集賢)'!BS2+'調查(集賢)'!BT2+'調查(集賢)'!BU2+'調查(集賢)'!BV2+'調查(集賢)'!BW2+'調查(集賢)'!BX2+'調查(集賢)'!DF2+'調查(集賢)'!DG2+'調查(集賢)'!DH2+'調查(集賢)'!DI2+'調查(集賢)'!DJ2+'調查(集賢)'!DK2+'調查(集賢)'!ES2+'調查(集賢)'!ET2+'調查(集賢)'!EU2+'調查(集賢)'!EV2+'調查(集賢)'!EW2+'調查(集賢)'!EX2 -> 0 | Z5: ='調查(集賢)'!J2+'調查(集賢)'!K2+'調查(集賢)'!L2+'調查(集賢)'!M2+'調查(集賢)'!AX2+'調查(集賢)'!AY2+'調查(集賢)'!AZ2+'調查(集賢)'!BA2+'調查(集賢)'!CL2+'調查(集賢)'!CM2+'調查(集賢)'!CN2+'調查(集賢)'!CO2+'調查(集賢)'!DY2+'調查(集賢)'!DZ2+'調查(集賢)'!EA2+'調查(集賢)'!EB2 -> 0 | AA5: ='調查(集賢)'!X2+'調查(集賢)'!Y2+'調查(集賢)'!Z2+'調查(集賢)'!AA2+'調查(集賢)'!BL2+'調查(集賢)'!BM2+'調查(集賢)'!BN2+'調查(集賢)'!BO2+'調查(集賢)'!CY2+'調查(集賢)'!CZ2+'調查(集賢)'!DA2+'調查(集賢)'!DB2+'調查(集賢)'!EL2+'調查(集賢)'!EM2+'調查(集賢)'!EN2+'調查(集賢)'!EO2 -> 0 | AB5: ='調查(集賢)'!AK2+'調查(集賢)'!AL2+'調查(集賢)'!AM2+'調查(集賢)'!AN2+'調查(集賢)'!BY2+'調查(集賢)'!BZ2+'調查(集賢)'!CA2+'調查(集賢)'!CB2+'調查(集賢)'!DL2+'調查(集賢)'!DM2+'調查(集賢)'!DN2+'調查(集賢)'!DO2+'調查(集賢)'!EY2+'調查(集賢)'!EZ2+'調查(集賢)'!FA2+'調查(集賢)'!FB2 -> 0 | AD5: ='調查(集賢)'!N2+'調查(集賢)'!O2+'調查(集賢)'!P2+'調查(集賢)'!BB2+'調查(集賢)'!BC2+'調查(集賢)'!BD2+'調查(集賢)'!CP2+'調查(集賢)'!CQ2+'調查(集賢)'!CR2+'調查(集賢)'!EC2+'調查(集賢)'!ED2+'調查(集賢)'!EE2 -> 0 | AE5: ='調查(集賢)'!AB2+'調查(集賢)'!AC2+'調查(集賢)'!AD2+'調查(集賢)'!BP2+'調查(集賢)'!BQ2+'調查(集賢)'!BR2+'調查(集賢)'!DC2+'調查(集賢)'!DD2+'調查(集賢)'!DE2+'調查(集賢)'!EP2+'調查(集賢)'!EQ2+'調查(集賢)'!ER2 -> 0 | AF5: ='調查(集賢)'!AO2+'調查(集賢)'!AP2+'調查(集賢)'!AQ2+'調查(集賢)'!CC2+'調查(集賢)'!CD2+'調查(集賢)'!CE2+'調查(集賢)'!DP2+'調查(集賢)'!DQ2+'調查(集賢)'!DR2+'調查(集賢)'!FC2+'調查(集賢)'!FD2+'調查(集賢)'!FE2 -> 0 | AH5: ='調查(集賢)'!Q2+'調查(集賢)'!BE2 -> 0
A6: A | B6: 0.010416667 | C6: 0.020833333 | D6: - | E6: ='調查(集賢)'!D3+'調查(集賢)'!E3+'調查(集賢)'!F3+'調查(集賢)'!G3+'調查(集賢)'!H3+'調查(集賢)'!I3+'調查(集賢)'!AR3+'調查(集賢)'!AS3+'調查(集賢)'!AT3+'調查(集賢)'!AU3+'調查(集賢)'!AV3+'調查(集賢)'!AW3+'調查(集賢)'!CF3+'調查(集賢)'!CG3+'調查(集賢)'!CH3+'調查(集賢)'!CI3+'調查(集賢)'!CJ3+'調查(集賢)'!CK3+'調查(集賢)'!DS3+'調查(集賢)'!DT3+'調查(集賢)'!DU3+'調查(集賢)'!DV3+'調查(集賢)'!DW3+'調查(集賢)'!DX3 -> 0 | F6: ='調查(集賢)'!R3+'調查(集賢)'!S3+'調查(集賢)'!T3+'調查(集賢)'!U3+'調查(集賢)'!V3+'調查(集賢)'!W3+'調查(集賢)'!BF3+'調查(集賢)'!BG3+'調查(集賢)'!BH3+'調查(集賢)'!BI3+'調查(集賢)'!BJ3+'調查(集賢)'!BK3+'調查(集賢)'!CS3+'調查(集賢)'!CT3+'調查(集賢)'!CU3+'調查(集賢)'!CV3+'調查(集賢)'!CW3+'調查(集賢)'!CX3+'調查(集賢)'!EF3+'調查(集賢)'!EG3+'調查(集賢)'!EH3+'調查(集賢)'!EI3+'調查(集賢)'!EJ3+'調查(集賢)'!EK3 -> 0 | G6: ='調查(集賢)'!AE3+'調查(集賢)'!AF3+'調查(集賢)'!AG3+'調查(集賢)'!AH3+'調查(集賢)'!AI3+'調查(集賢)'!AJ3+'調查(集賢)'!BS3+'調查(集賢)'!BT3+'調查(集賢)'!BU3+'調查(集賢)'!BV3+'調查(集賢)'!BW3+'調查(集賢)'!BX3+'調查(集賢)'!DF3+'調查(集賢)'!DG3+'調查(集賢)'!DH3+'調查(集賢)'!DI3+'調查(集賢)'!DJ3+'調查(集賢)'!DK3+'調查(集賢)'!ES3+'調查(集賢)'!ET3+'調查(集賢)'!EU3+'調查(集賢)'!EV3+'調查(集賢)'!EW3+'調查(集賢)'!EX3 -> 0 | H6: - | I6: ='調查(集賢)'!J3+'調查(集賢)'!K3+'調查(集賢)'!L3+'調查(集賢)'!M3+'調查(集賢)'!AX3+'調查(集賢)'!AY3+'調查(集賢)'!AZ3+'調查(集賢)'!BA3+'調查(集賢)'!CL3+'調查(集賢)'!CM3+'調查(集賢)'!CN3+'調查(集賢)'!CO3+'調查(集賢)'!DY3+'調查(集賢)'!DZ3+'調查(集賢)'!EA3+'調查(集賢)'!EB3 -> 0 | J6: ='調查(集賢)'!X3+'調查(集賢)'!Y3+'調查(集賢)'!Z3+'調查(集賢)'!AA3+'調查(集賢)'!BL3+'調查(集賢)'!BM3+'調查(集賢)'!BN3+'調查(集賢)'!BO3+'調查(集賢)'!CY3+'調查(集賢)'!CZ3+'調查(集賢)'!DA3+'調查(集賢)'!DB3+'調查(集賢)'!EL3+'調查(集賢)'!EM3+'調查(集賢)'!EN3+'調查(集賢)'!EO3 -> 0 | K6: ='調查(集賢)'!AK3+'調查(集賢)'!AL3+'調查(集賢)'!AM3+'調查(集賢)'!AN3+'調查(集賢)'!BY3+'調查(集賢)'!BZ3+'調查(集賢)'!CA3+'調查(集賢)'!CB3+'調查(集賢)'!DL3+'調查(集賢)'!DM3+'調查(集賢)'!DN3+'調查(集賢)'!DO3+'調查(集賢)'!EY3+'調查(集賢)'!EZ3+'調查(集賢)'!FA3+'調查(集賢)'!FB3 -> 0 | L6: - | M6: - | N6: ='調查(集賢)'!Q3+'調查(集賢)'!BE3 -> 0 | O6: ='調查(集賢)'!N3+'調查(集賢)'!O3+'調查(集賢)'!P3+'調查(集賢)'!BB3+'調查(集賢)'!BC3+'調查(集賢)'!BD3+'調查(集賢)'!CP3+'調查(集賢)'!CQ3+'調查(集賢)'!CR3+'調查(集賢)'!EC3+'調查(集賢)'!ED3+'調查(集賢)'!EE3 -> 0 | P6: - | Q6: =IF(AE6>0,AE6-AH6-AH102,0) -> 0 | R6: - | S6: ='調查(集賢)'!AO3+'調查(集賢)'!AP3+'調查(集賢)'!AQ3+'調查(集賢)'!CC3+'調查(集賢)'!CD3+'調查(集賢)'!CE3+'調查(集賢)'!DP3+'調查(集賢)'!DQ3+'調查(集賢)'!DR3+'調查(集賢)'!FC3+'調查(集賢)'!FD3+'調查(集賢)'!FE3 -> 0 | V6: ='調查(集賢)'!D3+'調查(集賢)'!E3+'調查(集賢)'!F3+'調查(集賢)'!G3+'調查(集賢)'!H3+'調查(集賢)'!I3+'調查(集賢)'!AR3+'調查(集賢)'!AS3+'調查(集賢)'!AT3+'調查(集賢)'!AU3+'調查(集賢)'!AV3+'調查(集賢)'!AW3+'調查(集賢)'!CF3+'調查(集賢)'!CG3+'調查(集賢)'!CH3+'調查(集賢)'!CI3+'調查(集賢)'!CJ3+'調查(集賢)'!CK3+'調查(集賢)'!DS3+'調查(集賢)'!DT3+'調查(集賢)'!DU3+'調查(集賢)'!DV3+'調查(集賢)'!DW3+'調查(集賢)'!DX3 -> 0 | W6: ='調查(集賢)'!R3+'調查(集賢)'!S3+'調查(集賢)'!T3+'調查(集賢)'!U3+'調查(集賢)'!V3+'調查(集賢)'!W3+'調查(集賢)'!BF3+'調查(集賢)'!BG3+'調查(集賢)'!BH3+'調查(集賢)'!BI3+'調查(集賢)'!BJ3+'調查(集賢)'!BK3+'調查(集賢)'!CS3+'調查(集賢)'!CT3+'調查(集賢)'!CU3+'調查(集賢)'!CV3+'調查(集賢)'!CW3+'調查(集賢)'!CX3+'調查(集賢)'!EF3+'調查(集賢)'!EG3+'調查(集賢)'!EH3+'調查(集賢)'!EI3+'調查(集賢)'!EJ3+'調查(集賢)'!EK3 -> 0 | X6: ='調查(集賢)'!AE3+'調查(集賢)'!AF3+'調查(集賢)'!AG3+'調查(集賢)'!AH3+'調查(集賢)'!AI3+'調查(集賢)'!AJ3+'調查(集賢)'!BS3+'調查(集賢)'!BT3+'調查(集賢)'!BU3+'調查(集賢)'!BV3+'調查(集賢)'!BW3+'調查(集賢)'!BX3+'調查(集賢)'!DF3+'調查(集賢)'!DG3+'調查(集賢)'!DH3+'調查(集賢)'!DI3+'調查(集賢)'!DJ3+'調查(集賢)'!DK3+'調查(集賢)'!ES3+'調查(集賢)'!ET3+'調查(集賢)'!EU3+'調查(集賢)'!EV3+'調查(集賢)'!EW3+'調查(集賢)'!EX3 -> 0 | Z6: ='調查(集賢)'!J3+'調查(集賢)'!K3+'調查(集賢)'!L3+'調查(集賢)'!M3+'調查(集賢)'!AX3+'調查(集賢)'!AY3+'調查(集賢)'!AZ3+'調查(集賢)'!BA3+'調查(集賢)'!CL3+'調查(集賢)'!CM3+'調查(集賢)'!CN3+'調查(集賢)'!CO3+'調查(集賢)'!DY3+'調查(集賢)'!DZ3+'調查(集賢)'!EA3+'調查(集賢)'!EB3 -> 0 | AA6: ='調查(集賢)'!X3+'調查(集賢)'!Y3+'調查(集賢)'!Z3+'調查(集賢)'!AA3+'調查(集賢)'!BL3+'調查(集賢)'!BM3+'調查(集賢)'!BN3+'調查(集賢)'!BO3+'調查(集賢)'!CY3+'調查(集賢)'!CZ3+'調查(集賢)'!DA3+'調查(集賢)'!DB3+'調查(集賢)'!EL3+'調查(集賢)'!EM3+'調查(集賢)'!EN3+'調查(集賢)'!EO3 -> 0 | AB6: ='調查(集賢)'!AK3+'調查(集賢)'!AL3+'調查(集賢)'!AM3+'調查(集賢)'!AN3+'調查(集賢)'!BY3+'調查(集賢)'!BZ3+'調查(集賢)'!CA3+'調查(集賢)'!CB3+'調查(集賢)'!DL3+'調查(集賢)'!DM3+'調查(集賢)'!DN3+'調查(集賢)'!DO3+'調查(集賢)'!EY3+'調查(集賢)'!EZ3+'調查(集賢)'!FA3+'調查(集賢)'!FB3 -> 0 | AD6: ='調查(集賢)'!N3+'調查(集賢)'!O3+'調查(集賢)'!P3+'調查(集賢)'!BB3+'調查(集賢)'!BC3+'調查(集賢)'!BD3+'調查(集賢)'!CP3+'調查(集賢)'!CQ3+'調查(集賢)'!CR3+'調查(集賢)'!EC3+'調查(集賢)'!ED3+'調查(集賢)'!EE3 -> 0 | AE6: ='調查(集賢)'!AB3+'調查(集賢)'!AC3+'調查(集賢)'!AD3+'調查(集賢)'!BP3+'調查(集賢)'!BQ3+'調查(集賢)'!BR3+'調查(集賢)'!DC3+'調查(集賢)'!DD3+'調查(集賢)'!DE3+'調查(集賢)'!EP3+'調查(集賢)'!EQ3+'調查(集賢)'!ER3 -> 0 | AF6: ='調查(集賢)'!AO3+'調查(集賢)'!AP3+'調查(集賢)'!AQ3+'調查(集賢)'!CC3+'調查(集賢)'!CD3+'調查(集賢)'!CE3+'調查(集賢)'!DP3+'調查(集賢)'!DQ3+'調查(集賢)'!DR3+'調查(集賢)'!FC3+'調查(集賢)'!FD3+'調查(集賢)'!FE3 -> 0 | AH6: ='調查(集賢)'!Q3+'調查(集賢)'!BE3 -> 0
A7: A | B7: 0.020833333 | C7: 0.03125 | D7: - | E7: ='調查(集賢)'!D4+'調查(集賢)'!E4+'調查(集賢)'!F4+'調查(集賢)'!G4+'調查(集賢)'!H4+'調查(集賢)'!I4+'調查(集賢)'!AR4+'調查(集賢)'!AS4+'調查(集賢)'!AT4+'調查(集賢)'!AU4+'調查(集賢)'!AV4+'調查(集賢)'!AW4+'調查(集賢)'!CF4+'調查(集賢)'!CG4+'調查(集賢)'!CH4+'調查(集賢)'!CI4+'調查(集賢)'!CJ4+'調查(集賢)'!CK4+'調查(集賢)'!DS4+'調查(集賢)'!DT4+'調查(集賢)'!DU4+'調查(集賢)'!DV4+'調查(集賢)'!DW4+'調查(集賢)'!DX4 -> 0 | F7: ='調查(集賢)'!R4+'調查(集賢)'!S4+'調查(集賢)'!T4+'調查(集賢)'!U4+'調查(集賢)'!V4+'調查(集賢)'!W4+'調查(集賢)'!BF4+'調查(集賢)'!BG4+'調查(集賢)'!BH4+'調查(集賢)'!BI4+'調查(集賢)'!BJ4+'調查(集賢)'!BK4+'調查(集賢)'!CS4+'調查(集賢)'!CT4+'調查(集賢)'!CU4+'調查(集賢)'!CV4+'調查(集賢)'!CW4+'調查(集賢)'!CX4+'調查(集賢)'!EF4+'調查(集賢)'!EG4+'調查(集賢)'!EH4+'調查(集賢)'!EI4+'調查(集賢)'!EJ4+'調查(集賢)'!EK4 -> 0 | G7: ='調查(集賢)'!AE4+'調查(集賢)'!AF4+'調查(集賢)'!AG4+'調查(集賢)'!AH4+'調查(集賢)'!AI4+'調查(集賢)'!AJ4+'調查(集賢)'!BS4+'調查(集賢)'!BT4+'調查(集賢)'!BU4+'調查(集賢)'!BV4+'調查(集賢)'!BW4+'調查(集賢)'!BX4+'調查(集賢)'!DF4+'調查(集賢)'!DG4+'調查(集賢)'!DH4+'調查(集賢)'!DI4+'調查(集賢)'!DJ4+'調查(集賢)'!DK4+'調查(集賢)'!ES4+'調查(集賢)'!ET4+'調查(集賢)'!EU4+'調查(集賢)'!EV4+'調查(集賢)'!EW4+'調查(集賢)'!EX4 -> 0 | H7: - | I7: ='調查(集賢)'!J4+'調查(集賢)'!K4+'調查(集賢)'!L4+'調查(集賢)'!M4+'調查(集賢)'!AX4+'調查(集賢)'!AY4+'調查(集賢)'!AZ4+'調查(集賢)'!BA4+'調查(集賢)'!CL4+'調查(集賢)'!CM4+'調查(集賢)'!CN4+'調查(集賢)'!CO4+'調查(集賢)'!DY4+'調查(集賢)'!DZ4+'調查(集賢)'!EA4+'調查(集賢)'!EB4 -> 0 | J7: ='調查(集賢)'!X4+'調查(集賢)'!Y4+'調查(集賢)'!Z4+'調查(集賢)'!AA4+'調查(集賢)'!BL4+'調查(集賢)'!BM4+'調查(集賢)'!BN4+'調查(集賢)'!BO4+'調查(集賢)'!CY4+'調查(集賢)'!CZ4+'調查(集賢)'!DA4+'調查(集賢)'!DB4+'調查(集賢)'!EL4+'調查(集賢)'!EM4+'調查(集賢)'!EN4+'調查(集賢)'!EO4 -> 0 | K7: ='調查(集賢)'!AK4+'調查(集賢)'!AL4+'調查(集賢)'!AM4+'調查(集賢)'!AN4+'調查(集賢)'!BY4+'調查(集賢)'!BZ4+'調查(集賢)'!CA4+'調查(集賢)'!CB4+'調查(集賢)'!DL4+'調查(集賢)'!DM4+'調查(集賢)'!DN4+'調查(集賢)'!DO4+'調查(集賢)'!EY4+'調查(集賢)'!EZ4+'調查(集賢)'!FA4+'調查(集賢)'!FB4 -> 0 | L7: - | M7: - | N7: ='調查(集賢)'!Q4+'調查(集賢)'!BE4 -> 0 | O7: ='調查(集賢)'!N4+'調查(集賢)'!O4+'調查(集賢)'!P4+'調查(集賢)'!BB4+'調查(集賢)'!BC4+'調查(集賢)'!BD4+'調查(集賢)'!CP4+'調查(集賢)'!CQ4+'調查(集賢)'!CR4+'調查(集賢)'!EC4+'調查(集賢)'!ED4+'調查(集賢)'!EE4 -> 0 | P7: - | Q7: =IF(AE7>0,AE7-AH7-AH103,0) -> 0 | R7: - | S7: ='調查(集賢)'!AO4+'調查(集賢)'!AP4+'調查(集賢)'!AQ4+'調查(集賢)'!CC4+'調查(集賢)'!CD4+'調查(集賢)'!CE4+'調查(集賢)'!DP4+'調查(集賢)'!DQ4+'調查(集賢)'!DR4+'調查(集賢)'!FC4+'調查(集賢)'!FD4+'調查(集賢)'!FE4 -> 0 | V7: ='調查(集賢)'!D4+'調查(集賢)'!E4+'調查(集賢)'!F4+'調查(集賢)'!G4+'調查(集賢)'!H4+'調查(集賢)'!I4+'調查(集賢)'!AR4+'調查(集賢)'!AS4+'調查(集賢)'!AT4+'調查(集賢)'!AU4+'調查(集賢)'!AV4+'調查(集賢)'!AW4+'調查(集賢)'!CF4+'調查(集賢)'!CG4+'調查(集賢)'!CH4+'調查(集賢)'!CI4+'調查(集賢)'!CJ4+'調查(集賢)'!CK4+'調查(集賢)'!DS4+'調查(集賢)'!DT4+'調查(集賢)'!DU4+'調查(集賢)'!DV4+'調查(集賢)'!DW4+'調查(集賢)'!DX4 -> 0 | W7: ='調查(集賢)'!R4+'調查(集賢)'!S4+'調查(集賢)'!T4+'調查(集賢)'!U4+'調查(集賢)'!V4+'調查(集賢)'!W4+'調查(集賢)'!BF4+'調查(集賢)'!BG4+'調查(集賢)'!BH4+'調查(集賢)'!BI4+'調查(集賢)'!BJ4+'調查(集賢)'!BK4+'調查(集賢)'!CS4+'調查(集賢)'!CT4+'調查(集賢)'!CU4+'調查(集賢)'!CV4+'調查(集賢)'!CW4+'調查(集賢)'!CX4+'調查(集賢)'!EF4+'調查(集賢)'!EG4+'調查(集賢)'!EH4+'調查(集賢)'!EI4+'調查(集賢)'!EJ4+'調查(集賢)'!EK4 -> 0 | X7: ='調查(集賢)'!AE4+'調查(集賢)'!AF4+'調查(集賢)'!AG4+'調查(集賢)'!AH4+'調查(集賢)'!AI4+'調查(集賢)'!AJ4+'調查(集賢)'!BS4+'調查(集賢)'!BT4+'調查(集賢)'!BU4+'調查(集賢)'!BV4+'調查(集賢)'!BW4+'調查(集賢)'!BX4+'調查(集賢)'!DF4+'調查(集賢)'!DG4+'調查(集賢)'!DH4+'調查(集賢)'!DI4+'調查(集賢)'!DJ4+'調查(集賢)'!DK4+'調查(集賢)'!ES4+'調查(集賢)'!ET4+'調查(集賢)'!EU4+'調查(集賢)'!EV4+'調查(集賢)'!EW4+'調查(集賢)'!EX4 -> 0 | Z7: ='調查(集賢)'!J4+'調查(集賢)'!K4+'調查(集賢)'!L4+'調查(集賢)'!M4+'調查(集賢)'!AX4+'調查(集賢)'!AY4+'調查(集賢)'!AZ4+'調查(集賢)'!BA4+'調查(集賢)'!CL4+'調查(集賢)'!CM4+'調查(集賢)'!CN4+'調查(集賢)'!CO4+'調查(集賢)'!DY4+'調查(集賢)'!DZ4+'調查(集賢)'!EA4+'調查(集賢)'!EB4 -> 0 | AA7: ='調查(集賢)'!X4+'調查(集賢)'!Y4+'調查(集賢)'!Z4+'調查(集賢)'!AA4+'調查(集賢)'!BL4+'調查(集賢)'!BM4+'調查(集賢)'!BN4+'調查(集賢)'!BO4+'調查(集賢)'!CY4+'調查(集賢)'!CZ4+'調查(集賢)'!DA4+'調查(集賢)'!DB4+'調查(集賢)'!EL4+'調查(集賢)'!EM4+'調查(集賢)'!EN4+'調查(集賢)'!EO4 -> 0 | AB7: ='調查(集賢)'!AK4+'調查(集賢)'!AL4+'調查(集賢)'!AM4+'調查(集賢)'!AN4+'調查(集賢)'!BY4+'調查(集賢)'!BZ4+'調查(集賢)'!CA4+'調查(集賢)'!CB4+'調查(集賢)'!DL4+'調查(集賢)'!DM4+'調查(集賢)'!DN4+'調查(集賢)'!DO4+'調查(集賢)'!EY4+'調查(集賢)'!EZ4+'調查(集賢)'!FA4+'調查(集賢)'!FB4 -> 0 | AD7: ='調查(集賢)'!N4+'調查(集賢)'!O4+'調查(集賢)'!P4+'調查(集賢)'!BB4+'調查(集賢)'!BC4+'調查(集賢)'!BD4+'調查(集賢)'!CP4+'調查(集賢)'!CQ4+'調查(集賢)'!CR4+'調查(集賢)'!EC4+'調查(集賢)'!ED4+'調查(集賢)'!EE4 -> 0 | AE7: ='調查(集賢)'!AB4+'調查(集賢)'!AC4+'調查(集賢)'!AD4+'調查(集賢)'!BP4+'調查(集賢)'!BQ4+'調查(集賢)'!BR4+'調查(集賢)'!DC4+'調查(集賢)'!DD4+'調查(集賢)'!DE4+'調查(集賢)'!EP4+'調查(集賢)'!EQ4+'調查(集賢)'!ER4 -> 0 | AF7: ='調查(集賢)'!AO4+'調查(集賢)'!AP4+'調查(集賢)'!AQ4+'調查(集賢)'!CC4+'調查(集賢)'!CD4+'調查(集賢)'!CE4+'調查(集賢)'!DP4+'調查(集賢)'!DQ4+'調查(集賢)'!DR4+'調查(集賢)'!FC4+'調查(集賢)'!FD4+'調查(集賢)'!FE4 -> 0 | AH7: ='調查(集賢)'!Q4+'調查(集賢)'!BE4 -> 0
A8: A | B8: 0.03125 | C8: 0.041666667 | D8: - | E8: ='調查(集賢)'!D5+'調查(集賢)'!E5+'調查(集賢)'!F5+'調查(集賢)'!G5+'調查(集賢)'!H5+'調查(集賢)'!I5+'調查(集賢)'!AR5+'調查(集賢)'!AS5+'調查(集賢)'!AT5+'調查(集賢)'!AU5+'調查(集賢)'!AV5+'調查(集賢)'!AW5+'調查(集賢)'!CF5+'調查(集賢)'!CG5+'調查(集賢)'!CH5+'調查(集賢)'!CI5+'調查(集賢)'!CJ5+'調查(集賢)'!CK5+'調查(集賢)'!DS5+'調查(集賢)'!DT5+'調查(集賢)'!DU5+'調查(集賢)'!DV5+'調查(集賢)'!DW5+'調查(集賢)'!DX5 -> 0 | F8: ='調查(集賢)'!R5+'調查(集賢)'!S5+'調查(集賢)'!T5+'調查(集賢)'!U5+'調查(集賢)'!V5+'調查(集賢)'!W5+'調查(集賢)'!BF5+'調查(集賢)'!BG5+'調查(集賢)'!BH5+'調查(集賢)'!BI5+'調查(集賢)'!BJ5+'調查(集賢)'!BK5+'調查(集賢)'!CS5+'調查(集賢)'!CT5+'調查(集賢)'!CU5+'調查(集賢)'!CV5+'調查(集賢)'!CW5+'調查(集賢)'!CX5+'調查(集賢)'!EF5+'調查(集賢)'!EG5+'調查(集賢)'!EH5+'調查(集賢)'!EI5+'調查(集賢)'!EJ5+'調查(集賢)'!EK5 -> 0 | G8: ='調查(集賢)'!AE5+'調查(集賢)'!AF5+'調查(集賢)'!AG5+'調查(集賢)'!AH5+'調查(集賢)'!AI5+'調查(集賢)'!AJ5+'調查(集賢)'!BS5+'調查(集賢)'!BT5+'調查(集賢)'!BU5+'調查(集賢)'!BV5+'調查(集賢)'!BW5+'調查(集賢)'!BX5+'調查(集賢)'!DF5+'調查(集賢)'!DG5+'調查(集賢)'!DH5+'調查(集賢)'!DI5+'調查(集賢)'!DJ5+'調查(集賢)'!DK5+'調查(集賢)'!ES5+'調查(集賢)'!ET5+'調查(集賢)'!EU5+'調查(集賢)'!EV5+'調查(集賢)'!EW5+'調查(集賢)'!EX5 -> 0 | H8: - | I8: ='調查(集賢)'!J5+'調查(集賢)'!K5+'調查(集賢)'!L5+'調查(集賢)'!M5+'調查(集賢)'!AX5+'調查(集賢)'!AY5+'調查(集賢)'!AZ5+'調查(集賢)'!BA5+'調查(集賢)'!CL5+'調查(集賢)'!CM5+'調查(集賢)'!CN5+'調查(集賢)'!CO5+'調查(集賢)'!DY5+'調查(集賢)'!DZ5+'調查(集賢)'!EA5+'調查(集賢)'!EB5 -> 0 | J8: ='調查(集賢)'!X5+'調查(集賢)'!Y5+'調查(集賢)'!Z5+'調查(集賢)'!AA5+'調查(集賢)'!BL5+'調查(集賢)'!BM5+'調查(集賢)'!BN5+'調查(集賢)'!BO5+'調查(集賢)'!CY5+'調查(集賢)'!CZ5+'調查(集賢)'!DA5+'調查(集賢)'!DB5+'調查(集賢)'!EL5+'調查(集賢)'!EM5+'調查(集賢)'!EN5+'調查(集賢)'!EO5 -> 0 | K8: ='調查(集賢)'!AK5+'調查(集賢)'!AL5+'調查(集賢)'!AM5+'調查(集賢)'!AN5+'調查(集賢)'!BY5+'調查(集賢)'!BZ5+'調查(集賢)'!CA5+'調查(集賢)'!CB5+'調查(集賢)'!DL5+'調查(集賢)'!DM5+'調查(集賢)'!DN5+'調查(集賢)'!DO5+'調查(集賢)'!EY5+'調查(集賢)'!EZ5+'調查(集賢)'!FA5+'調查(集賢)'!FB5 -> 0 | L8: - | M8: - | N8: ='調查(集賢)'!Q5+'調查(集賢)'!BE5 -> 0 | O8: ='調查(集賢)'!N5+'調查(集賢)'!O5+'調查(集賢)'!P5+'調查(集賢)'!BB5+'調查(集賢)'!BC5+'調查(集賢)'!BD5+'調查(集賢)'!CP5+'調查(集賢)'!CQ5+'調查(集賢)'!CR5+'調查(集賢)'!EC5+'調查(集賢)'!ED5+'調查(集賢)'!EE5 -> 0 | P8: - | Q8: =IF(AE8>0,AE8-AH8-AH104,0) -> 0 | R8: - | S8: ='調查(集賢)'!AO5+'調查(集賢)'!AP5+'調查(集賢)'!AQ5+'調查(集賢)'!CC5+'調查(集賢)'!CD5+'調查(集賢)'!CE5+'調查(集賢)'!DP5+'調查(集賢)'!DQ5+'調查(集賢)'!DR5+'調查(集賢)'!FC5+'調查(集賢)'!FD5+'調查(集賢)'!FE5 -> 0 | V8: ='調查(集賢)'!D5+'調查(集賢)'!E5+'調查(集賢)'!F5+'調查(集賢)'!G5+'調查(集賢)'!H5+'調查(集賢)'!I5+'調查(集賢)'!AR5+'調查(集賢)'!AS5+'調查(集賢)'!AT5+'調查(集賢)'!AU5+'調查(集賢)'!AV5+'調查(集賢)'!AW5+'調查(集賢)'!CF5+'調查(集賢)'!CG5+'調查(集賢)'!CH5+'調查(集賢)'!CI5+'調查(集賢)'!CJ5+'調查(集賢)'!CK5+'調查(集賢)'!DS5+'調查(集賢)'!DT5+'調查(集賢)'!DU5+'調查(集賢)'!DV5+'調查(集賢)'!DW5+'調查(集賢)'!DX5 -> 0 | W8: ='調查(集賢)'!R5+'調查(集賢)'!S5+'調查(集賢)'!T5+'調查(集賢)'!U5+'調查(集賢)'!V5+'調查(集賢)'!W5+'調查(集賢)'!BF5+'調查(集賢)'!BG5+'調查(集賢)'!BH5+'調查(集賢)'!BI5+'調查(集賢)'!BJ5+'調查(集賢)'!BK5+'調查(集賢)'!CS5+'調查(集賢)'!CT5+'調查(集賢)'!CU5+'調查(集賢)'!CV5+'調查(集賢)'!CW5+'調查(集賢)'!CX5+'調查(集賢)'!EF5+'調查(集賢)'!EG5+'調查(集賢)'!EH5+'調查(集賢)'!EI5+'調查(集賢)'!EJ5+'調查(集賢)'!EK5 -> 0 | X8: ='調查(集賢)'!AE5+'調查(集賢)'!AF5+'調查(集賢)'!AG5+'調查(集賢)'!AH5+'調查(集賢)'!AI5+'調查(集賢)'!AJ5+'調查(集賢)'!BS5+'調查(集賢)'!BT5+'調查(集賢)'!BU5+'調查(集賢)'!BV5+'調查(集賢)'!BW5+'調查(集賢)'!BX5+'調查(集賢)'!DF5+'調查(集賢)'!DG5+'調查(集賢)'!DH5+'調查(集賢)'!DI5+'調查(集賢)'!DJ5+'調查(集賢)'!DK5+'調查(集賢)'!ES5+'調查(集賢)'!ET5+'調查(集賢)'!EU5+'調查(集賢)'!EV5+'調查(集賢)'!EW5+'調查(集賢)'!EX5 -> 0 | Z8: ='調查(集賢)'!J5+'調查(集賢)'!K5+'調查(集賢)'!L5+'調查(集賢)'!M5+'調查(集賢)'!AX5+'調查(集賢)'!AY5+'調查(集賢)'!AZ5+'調查(集賢)'!BA5+'調查(集賢)'!CL5+'調查(集賢)'!CM5+'調查(集賢)'!CN5+'調查(集賢)'!CO5+'調查(集賢)'!DY5+'調查(集賢)'!DZ5+'調查(集賢)'!EA5+'調查(集賢)'!EB5 -> 0 | AA8: ='調查(集賢)'!X5+'調查(集賢)'!Y5+'調查(集賢)'!Z5+'調查(集賢)'!AA5+'調查(集賢)'!BL5+'調查(集賢)'!BM5+'調查(集賢)'!BN5+'調查(集賢)'!BO5+'調查(集賢)'!CY5+'調查(集賢)'!CZ5+'調查(集賢)'!DA5+'調查(集賢)'!DB5+'調查(集賢)'!EL5+'調查(集賢)'!EM5+'調查(集賢)'!EN5+'調查(集賢)'!EO5 -> 0 | AB8: ='調查(集賢)'!AK5+'調查(集賢)'!AL5+'調查(集賢)'!AM5+'調查(集賢)'!AN5+'調查(集賢)'!BY5+'調查(集賢)'!BZ5+'調查(集賢)'!CA5+'調查(集賢)'!CB5+'調查(集賢)'!DL5+'調查(集賢)'!DM5+'調查(集賢)'!DN5+'調查(集賢)'!DO5+'調查(集賢)'!EY5+'調查(集賢)'!EZ5+'調查(集賢)'!FA5+'調查(集賢)'!FB5 -> 0 | AD8: ='調查(集賢)'!N5+'調查(集賢)'!O5+'調查(集賢)'!P5+'調查(集賢)'!BB5+'調查(集賢)'!BC5+'調查(集賢)'!BD5+'調查(集賢)'!CP5+'調查(集賢)'!CQ5+'調查(集賢)'!CR5+'調查(集賢)'!EC5+'調查(集賢)'!ED5+'調查(集賢)'!EE5 -> 0 | AE8: ='調查(集賢)'!AB5+'調查(集賢)'!AC5+'調查(集賢)'!AD5+'調查(集賢)'!BP5+'調查(集賢)'!BQ5+'調查(集賢)'!BR5+'調查(集賢)'!DC5+'調查(集賢)'!DD5+'調查(集賢)'!DE5+'調查(集賢)'!EP5+'調查(集賢)'!EQ5+'調查(集賢)'!ER5 -> 0 | AF8: ='調查(集賢)'!AO5+'調查(集賢)'!AP5+'調查(集賢)'!AQ5+'調查(集賢)'!CC5+'調查(集賢)'!CD5+'調查(集賢)'!CE5+'調查(集賢)'!DP5+'調查(集賢)'!DQ5+'調查(集賢)'!DR5+'調查(集賢)'!FC5+'調查(集賢)'!FD5+'調查(集賢)'!FE5 -> 0 | AH8: ='調查(集賢)'!Q5+'調查(集賢)'!BE5 -> 0
A9: A | B9: 0.041666667 | C9: 0.052083333 | D9: - | E9: ='調查(集賢)'!D6+'調查(集賢)'!E6+'調查(集賢)'!F6+'調查(集賢)'!G6+'調查(集賢)'!H6+'調查(集賢)'!I6+'調查(集賢)'!AR6+'調查(集賢)'!AS6+'調查(集賢)'!AT6+'調查(集賢)'!AU6+'調查(集賢)'!AV6+'調查(集賢)'!AW6+'調查(集賢)'!CF6+'調查(集賢)'!CG6+'調查(集賢)'!CH6+'調查(集賢)'!CI6+'調查(集賢)'!CJ6+'調查(集賢)'!CK6+'調查(集賢)'!DS6+'調查(集賢)'!DT6+'調查(集賢)'!DU6+'調查(集賢)'!DV6+'調查(集賢)'!DW6+'調查(集賢)'!DX6 -> 0 | F9: ='調查(集賢)'!R6+'調查(集賢)'!S6+'調查(集賢)'!T6+'調查(集賢)'!U6+'調查(集賢)'!V6+'調查(集賢)'!W6+'調查(集賢)'!BF6+'調查(集賢)'!BG6+'調查(集賢)'!BH6+'調查(集賢)'!BI6+'調查(集賢)'!BJ6+'調查(集賢)'!BK6+'調查(集賢)'!CS6+'調查(集賢)'!CT6+'調查(集賢)'!CU6+'調查(集賢)'!CV6+'調查(集賢)'!CW6+'調查(集賢)'!CX6+'調查(集賢)'!EF6+'調查(集賢)'!EG6+'調查(集賢)'!EH6+'調查(集賢)'!EI6+'調查(集賢)'!EJ6+'調查(集賢)'!EK6 -> 0 | G9: ='調查(集賢)'!AE6+'調查(集賢)'!AF6+'調查(集賢)'!AG6+'調查(集賢)'!AH6+'調查(集賢)'!AI6+'調查(集賢)'!AJ6+'調查(集賢)'!BS6+'調查(集賢)'!BT6+'調查(集賢)'!BU6+'調查(集賢)'!BV6+'調查(集賢)'!BW6+'調查(集賢)'!BX6+'調查(集賢)'!DF6+'調查(集賢)'!DG6+'調查(集賢)'!DH6+'調查(集賢)'!DI6+'調查(集賢)'!DJ6+'調查(集賢)'!DK6+'調查(集賢)'!ES6+'調查(集賢)'!ET6+'調查(集賢)'!EU6+'調查(集賢)'!EV6+'調查(集賢)'!EW6+'調查(集賢)'!EX6 -> 0 | H9: - | I9: ='調查(集賢)'!J6+'調查(集賢)'!K6+'調查(集賢)'!L6+'調查(集賢)'!M6+'調查(集賢)'!AX6+'調查(集賢)'!AY6+'調查(集賢)'!AZ6+'調查(集賢)'!BA6+'調查(集賢)'!CL6+'調查(集賢)'!CM6+'調查(集賢)'!CN6+'調查(集賢)'!CO6+'調查(集賢)'!DY6+'調查(集賢)'!DZ6+'調查(集賢)'!EA6+'調查(集賢)'!EB6 -> 0 | J9: ='調查(集賢)'!X6+'調查(集賢)'!Y6+'調查(集賢)'!Z6+'調查(集賢)'!AA6+'調查(集賢)'!BL6+'調查(集賢)'!BM6+'調查(集賢)'!BN6+'調查(集賢)'!BO6+'調查(集賢)'!CY6+'調查(集賢)'!CZ6+'調查(集賢)'!DA6+'調查(集賢)'!DB6+'調查(集賢)'!EL6+'調查(集賢)'!EM6+'調查(集賢)'!EN6+'調查(集賢)'!EO6 -> 0 | K9: ='調查(集賢)'!AK6+'調查(集賢)'!AL6+'調查(集賢)'!AM6+'調查(集賢)'!AN6+'調查(集賢)'!BY6+'調查(集賢)'!BZ6+'調查(集賢)'!CA6+'調查(集賢)'!CB6+'調查(集賢)'!DL6+'調查(集賢)'!DM6+'調查(集賢)'!DN6+'調查(集賢)'!DO6+'調查(集賢)'!EY6+'調查(集賢)'!EZ6+'調查(集賢)'!FA6+'調查(集賢)'!FB6 -> 0 | L9: - | M9: - | N9: ='調查(集賢)'!Q6+'調查(集賢)'!BE6 -> 0 | O9: ='調查(集賢)'!N6+'調查(集賢)'!O6+'調查(集賢)'!P6+'調查(集賢)'!BB6+'調查(集賢)'!BC6+'調查(集賢)'!BD6+'調查(集賢)'!CP6+'調查(集賢)'!CQ6+'調查(集賢)'!CR6+'調查(集賢)'!EC6+'調查(集賢)'!ED6+'調查(集賢)'!EE6 -> 0 | P9: - | Q9: =IF(AE9>0,AE9-AH9-AH105,0) -> 0 | R9: - | S9: ='調查(集賢)'!AO6+'調查(集賢)'!AP6+'調查(集賢)'!AQ6+'調查(集賢)'!CC6+'調查(集賢)'!CD6+'調查(集賢)'!CE6+'調查(集賢)'!DP6+'調查(集賢)'!DQ6+'調查(集賢)'!DR6+'調查(集賢)'!FC6+'調查(集賢)'!FD6+'調查(集賢)'!FE6 -> 0 | V9: ='調查(集賢)'!D6+'調查(集賢)'!E6+'調查(集賢)'!F6+'調查(集賢)'!G6+'調查(集賢)'!H6+'調查(集賢)'!I6+'調查(集賢)'!AR6+'調查(集賢)'!AS6+'調查(集賢)'!AT6+'調查(集賢)'!AU6+'調查(集賢)'!AV6+'調查(集賢)'!AW6+'調查(集賢)'!CF6+'調查(集賢)'!CG6+'調查(集賢)'!CH6+'調查(集賢)'!CI6+'調查(集賢)'!CJ6+'調查(集賢)'!CK6+'調查(集賢)'!DS6+'調查(集賢)'!DT6+'調查(集賢)'!DU6+'調查(集賢)'!DV6+'調查(集賢)'!DW6+'調查(集賢)'!DX6 -> 0 | W9: ='調查(集賢)'!R6+'調查(集賢)'!S6+'調查(集賢)'!T6+'調查(集賢)'!U6+'調查(集賢)'!V6+'調查(集賢)'!W6+'調查(集賢)'!BF6+'調查(集賢)'!BG6+'調查(集賢)'!BH6+'調查(集賢)'!BI6+'調查(集賢)'!BJ6+'調查(集賢)'!BK6+'調查(集賢)'!CS6+'調查(集賢)'!CT6+'調查(集賢)'!CU6+'調查(集賢)'!CV6+'調查(集賢)'!CW6+'調查(集賢)'!CX6+'調查(集賢)'!EF6+'調查(集賢)'!EG6+'調查(集賢)'!EH6+'調查(集賢)'!EI6+'調查(集賢)'!EJ6+'調查(集賢)'!EK6 -> 0 | X9: ='調查(集賢)'!AE6+'調查(集賢)'!AF6+'調查(集賢)'!AG6+'調查(集賢)'!AH6+'調查(集賢)'!AI6+'調查(集賢)'!AJ6+'調查(集賢)'!BS6+'調查(集賢)'!BT6+'調查(集賢)'!BU6+'調查(集賢)'!BV6+'調查(集賢)'!BW6+'調查(集賢)'!BX6+'調查(集賢)'!DF6+'調查(集賢)'!DG6+'調查(集賢)'!DH6+'調查(集賢)'!DI6+'調查(集賢)'!DJ6+'調查(集賢)'!DK6+'調查(集賢)'!ES6+'調查(集賢)'!ET6+'調查(集賢)'!EU6+'調查(集賢)'!EV6+'調查(集賢)'!EW6+'調查(集賢)'!EX6 -> 0 | Z9: ='調查(集賢)'!J6+'調查(集賢)'!K6+'調查(集賢)'!L6+'調查(集賢)'!M6+'調查(集賢)'!AX6+'調查(集賢)'!AY6+'調查(集賢)'!AZ6+'調查(集賢)'!BA6+'調查(集賢)'!CL6+'調查(集賢)'!CM6+'調查(集賢)'!CN6+'調查(集賢)'!CO6+'調查(集賢)'!DY6+'調查(集賢)'!DZ6+'調查(集賢)'!EA6+'調查(集賢)'!EB6 -> 0 | AA9: ='調查(集賢)'!X6+'調查(集賢)'!Y6+'調查(集賢)'!Z6+'調查(集賢)'!AA6+'調查(集賢)'!BL6+'調查(集賢)'!BM6+'調查(集賢)'!BN6+'調查(集賢)'!BO6+'調查(集賢)'!CY6+'調查(集賢)'!CZ6+'調查(集賢)'!DA6+'調查(集賢)'!DB6+'調查(集賢)'!EL6+'調查(集賢)'!EM6+'調查(集賢)'!EN6+'調查(集賢)'!EO6 -> 0 | AB9: ='調查(集賢)'!AK6+'調查(集賢)'!AL6+'調查(集賢)'!AM6+'調查(集賢)'!AN6+'調查(集賢)'!BY6+'調查(集賢)'!BZ6+'調查(集賢)'!CA6+'調查(集賢)'!CB6+'調查(集賢)'!DL6+'調查(集賢)'!DM6+'調查(集賢)'!DN6+'調查(集賢)'!DO6+'調查(集賢)'!EY6+'調查(集賢)'!EZ6+'調查(集賢)'!FA6+'調查(集賢)'!FB6 -> 0 | AD9: ='調查(集賢)'!N6+'調查(集賢)'!O6+'調查(集賢)'!P6+'調查(集賢)'!BB6+'調查(集賢)'!BC6+'調查(集賢)'!BD6+'調查(集賢)'!CP6+'調查(集賢)'!CQ6+'調查(集賢)'!CR6+'調查(集賢)'!EC6+'調查(集賢)'!ED6+'調查(集賢)'!EE6 -> 0 | AE9: ='調查(集賢)'!AB6+'調查(集賢)'!AC6+'調查(集賢)'!AD6+'調查(集賢)'!BP6+'調查(集賢)'!BQ6+'調查(集賢)'!BR6+'調查(集賢)'!DC6+'調查(集賢)'!DD6+'調查(集賢)'!DE6+'調查(集賢)'!EP6+'調查(集賢)'!EQ6+'調查(集賢)'!ER6 -> 0 | AF9: ='調查(集賢)'!AO6+'調查(集賢)'!AP6+'調查(集賢)'!AQ6+'調查(集賢)'!CC6+'調查(集賢)'!CD6+'調查(集賢)'!CE6+'調查(集賢)'!DP6+'調查(集賢)'!DQ6+'調查(集賢)'!DR6+'調查(集賢)'!FC6+'調查(集賢)'!FD6+'調查(集賢)'!FE6 -> 0 | AH9: ='調查(集賢)'!Q6+'調查(集賢)'!BE6 -> 0
A10: A | B10: 0.052083333 | C10: 0.0625 | D10: - | E10: ='調查(集賢)'!D7+'調查(集賢)'!E7+'調查(集賢)'!F7+'調查(集賢)'!G7+'調查(集賢)'!H7+'調查(集賢)'!I7+'調查(集賢)'!AR7+'調查(集賢)'!AS7+'調查(集賢)'!AT7+'調查(集賢)'!AU7+'調查(集賢)'!AV7+'調查(集賢)'!AW7+'調查(集賢)'!CF7+'調查(集賢)'!CG7+'調查(集賢)'!CH7+'調查(集賢)'!CI7+'調查(集賢)'!CJ7+'調查(集賢)'!CK7+'調查(集賢)'!DS7+'調查(集賢)'!DT7+'調查(集賢)'!DU7+'調查(集賢)'!DV7+'調查(集賢)'!DW7+'調查(集賢)'!DX7 -> 0 | F10: ='調查(集賢)'!R7+'調查(集賢)'!S7+'調查(集賢)'!T7+'調查(集賢)'!U7+'調查(集賢)'!V7+'調查(集賢)'!W7+'調查(集賢)'!BF7+'調查(集賢)'!BG7+'調查(集賢)'!BH7+'調查(集賢)'!BI7+'調查(集賢)'!BJ7+'調查(集賢)'!BK7+'調查(集賢)'!CS7+'調查(集賢)'!CT7+'調查(集賢)'!CU7+'調查(集賢)'!CV7+'調查(集賢)'!CW7+'調查(集賢)'!CX7+'調查(集賢)'!EF7+'調查(集賢)'!EG7+'調查(集賢)'!EH7+'調查(集賢)'!EI7+'調查(集賢)'!EJ7+'調查(集賢)'!EK7 -> 0 | G10: ='調查(集賢)'!AE7+'調查(集賢)'!AF7+'調查(集賢)'!AG7+'調查(集賢)'!AH7+'調查(集賢)'!AI7+'調查(集賢)'!AJ7+'調查(集賢)'!BS7+'調查(集賢)'!BT7+'調查(集賢)'!BU7+'調查(集賢)'!BV7+'調查(集賢)'!BW7+'調查(集賢)'!BX7+'調查(集賢)'!DF7+'調查(集賢)'!DG7+'調查(集賢)'!DH7+'調查(集賢)'!DI7+'調查(集賢)'!DJ7+'調查(集賢)'!DK7+'調查(集賢)'!ES7+'調查(集賢)'!ET7+'調查(集賢)'!EU7+'調查(集賢)'!EV7+'調查(集賢)'!EW7+'調查(集賢)'!EX7 -> 0 | H10: - | I10: ='調查(集賢)'!J7+'調查(集賢)'!K7+'調查(集賢)'!L7+'調查(集賢)'!M7+'調查(集賢)'!AX7+'調查(集賢)'!AY7+'調查(集賢)'!AZ7+'調查(集賢)'!BA7+'調查(集賢)'!CL7+'調查(集賢)'!CM7+'調查(集賢)'!CN7+'調查(集賢)'!CO7+'調查(集賢)'!DY7+'調查(集賢)'!DZ7+'調查(集賢)'!EA7+'調查(集賢)'!EB7 -> 0 | J10: ='調查(集賢)'!X7+'調查(集賢)'!Y7+'調查(集賢)'!Z7+'調查(集賢)'!AA7+'調查(集賢)'!BL7+'調查(集賢)'!BM7+'調查(集賢)'!BN7+'調查(集賢)'!BO7+'調查(集賢)'!CY7+'調查(集賢)'!CZ7+'調查(集賢)'!DA7+'調查(集賢)'!DB7+'調查(集賢)'!EL7+'調查(集賢)'!EM7+'調查(集賢)'!EN7+'調查(集賢)'!EO7 -> 0 | K10: ='調查(集賢)'!AK7+'調查(集賢)'!AL7+'調查(集賢)'!AM7+'調查(集賢)'!AN7+'調查(集賢)'!BY7+'調查(集賢)'!BZ7+'調查(集賢)'!CA7+'調查(集賢)'!CB7+'調查(集賢)'!DL7+'調查(集賢)'!DM7+'調查(集賢)'!DN7+'調查(集賢)'!DO7+'調查(集賢)'!EY7+'調查(集賢)'!EZ7+'調查(集賢)'!FA7+'調查(集賢)'!FB7 -> 0 | L10: - | M10: - | N10: ='調查(集賢)'!Q7+'調查(集賢)'!BE7 -> 0 | O10: ='調查(集賢)'!N7+'調查(集賢)'!O7+'調查(集賢)'!P7+'調查(集賢)'!BB7+'調查(集賢)'!BC7+'調查(集賢)'!BD7+'調查(集賢)'!CP7+'調查(集賢)'!CQ7+'調查(集賢)'!CR7+'調查(集賢)'!EC7+'調查(集賢)'!ED7+'調查(集賢)'!EE7 -> 0 | P10: - | Q10: =IF(AE10>0,AE10-AH10-AH106,0) -> 0 | R10: - | S10: ='調查(集賢)'!AO7+'調查(集賢)'!AP7+'調查(集賢)'!AQ7+'調查(集賢)'!CC7+'調查(集賢)'!CD7+'調查(集賢)'!CE7+'調查(集賢)'!DP7+'調查(集賢)'!DQ7+'調查(集賢)'!DR7+'調查(集賢)'!FC7+'調查(集賢)'!FD7+'調查(集賢)'!FE7 -> 0 | V10: ='調查(集賢)'!D7+'調查(集賢)'!E7+'調查(集賢)'!F7+'調查(集賢)'!G7+'調查(集賢)'!H7+'調查(集賢)'!I7+'調查(集賢)'!AR7+'調查(集賢)'!AS7+'調查(集賢)'!AT7+'調查(集賢)'!AU7+'調查(集賢)'!AV7+'調查(集賢)'!AW7+'調查(集賢)'!CF7+'調查(集賢)'!CG7+'調查(集賢)'!CH7+'調查(集賢)'!CI7+'調查(集賢)'!CJ7+'調查(集賢)'!CK7+'調查(集賢)'!DS7+'調查(集賢)'!DT7+'調查(集賢)'!DU7+'調查(集賢)'!DV7+'調查(集賢)'!DW7+'調查(集賢)'!DX7 -> 0 | W10: ='調查(集賢)'!R7+'調查(集賢)'!S7+'調查(集賢)'!T7+'調查(集賢)'!U7+'調查(集賢)'!V7+'調查(集賢)'!W7+'調查(集賢)'!BF7+'調查(集賢)'!BG7+'調查(集賢)'!BH7+'調查(集賢)'!BI7+'調查(集賢)'!BJ7+'調查(集賢)'!BK7+'調查(集賢)'!CS7+'調查(集賢)'!CT7+'調查(集賢)'!CU7+'調查(集賢)'!CV7+'調查(集賢)'!CW7+'調查(集賢)'!CX7+'調查(集賢)'!EF7+'調查(集賢)'!EG7+'調查(集賢)'!EH7+'調查(集賢)'!EI7+'調查(集賢)'!EJ7+'調查(集賢)'!EK7 -> 0 | X10: ='調查(集賢)'!AE7+'調查(集賢)'!AF7+'調查(集賢)'!AG7+'調查(集賢)'!AH7+'調查(集賢)'!AI7+'調查(集賢)'!AJ7+'調查(集賢)'!BS7+'調查(集賢)'!BT7+'調查(集賢)'!BU7+'調查(集賢)'!BV7+'調查(集賢)'!BW7+'調查(集賢)'!BX7+'調查(集賢)'!DF7+'調查(集賢)'!DG7+'調查(集賢)'!DH7+'調查(集賢)'!DI7+'調查(集賢)'!DJ7+'調查(集賢)'!DK7+'調查(集賢)'!ES7+'調查(集賢)'!ET7+'調查(集賢)'!EU7+'調查(集賢)'!EV7+'調查(集賢)'!EW7+'調查(集賢)'!EX7 -> 0 | Z10: ='調查(集賢)'!J7+'調查(集賢)'!K7+'調查(集賢)'!L7+'調查(集賢)'!M7+'調查(集賢)'!AX7+'調查(集賢)'!AY7+'調查(集賢)'!AZ7+'調查(集賢)'!BA7+'調查(集賢)'!CL7+'調查(集賢)'!CM7+'調查(集賢)'!CN7+'調查(集賢)'!CO7+'調查(集賢)'!DY7+'調查(集賢)'!DZ7+'調查(集賢)'!EA7+'調查(集賢)'!EB7 -> 0 | AA10: ='調查(集賢)'!X7+'調查(集賢)'!Y7+'調查(集賢)'!Z7+'調查(集賢)'!AA7+'調查(集賢)'!BL7+'調查(集賢)'!BM7+'調查(集賢)'!BN7+'調查(集賢)'!BO7+'調查(集賢)'!CY7+'調查(集賢)'!CZ7+'調查(集賢)'!DA7+'調查(集賢)'!DB7+'調查(集賢)'!EL7+'調查(集賢)'!EM7+'調查(集賢)'!EN7+'調查(集賢)'!EO7 -> 0 | AB10: ='調查(集賢)'!AK7+'調查(集賢)'!AL7+'調查(集賢)'!AM7+'調查(集賢)'!AN7+'調查(集賢)'!BY7+'調查(集賢)'!BZ7+'調查(集賢)'!CA7+'調查(集賢)'!CB7+'調查(集賢)'!DL7+'調查(集賢)'!DM7+'調查(集賢)'!DN7+'調查(集賢)'!DO7+'調查(集賢)'!EY7+'調查(集賢)'!EZ7+'調查(集賢)'!FA7+'調查(集賢)'!FB7 -> 0 | AD10: ='調查(集賢)'!N7+'調查(集賢)'!O7+'調查(集賢)'!P7+'調查(集賢)'!BB7+'調查(集賢)'!BC7+'調查(集賢)'!BD7+'調查(集賢)'!CP7+'調查(集賢)'!CQ7+'調查(集賢)'!CR7+'調查(集賢)'!EC7+'調查(集賢)'!ED7+'調查(集賢)'!EE7 -> 0 | AE10: ='調查(集賢)'!AB7+'調查(集賢)'!AC7+'調查(集賢)'!AD7+'調查(集賢)'!BP7+'調查(集賢)'!BQ7+'調查(集賢)'!BR7+'調查(集賢)'!DC7+'調查(集賢)'!DD7+'調查(集賢)'!DE7+'調查(集賢)'!EP7+'調查(集賢)'!EQ7+'調查(集賢)'!ER7 -> 0 | AF10: ='調查(集賢)'!AO7+'調查(集賢)'!AP7+'調查(集賢)'!AQ7+'調查(集賢)'!CC7+'調查(集賢)'!CD7+'調查(集賢)'!CE7+'調查(集賢)'!DP7+'調查(集賢)'!DQ7+'調查(集賢)'!DR7+'調查(集賢)'!FC7+'調查(集賢)'!FD7+'調查(集賢)'!FE7 -> 0 | AH10: ='調查(集賢)'!Q7+'調查(集賢)'!BE7 -> 0
A11: A | B11: 0.0625 | C11: 0.072916667 | D11: - | E11: ='調查(集賢)'!D8+'調查(集賢)'!E8+'調查(集賢)'!F8+'調查(集賢)'!G8+'調查(集賢)'!H8+'調查(集賢)'!I8+'調查(集賢)'!AR8+'調查(集賢)'!AS8+'調查(集賢)'!AT8+'調查(集賢)'!AU8+'調查(集賢)'!AV8+'調查(集賢)'!AW8+'調查(集賢)'!CF8+'調查(集賢)'!CG8+'調查(集賢)'!CH8+'調查(集賢)'!CI8+'調查(集賢)'!CJ8+'調查(集賢)'!CK8+'調查(集賢)'!DS8+'調查(集賢)'!DT8+'調查(集賢)'!DU8+'調查(集賢)'!DV8+'調查(集賢)'!DW8+'調查(集賢)'!DX8 -> 0 | F11: ='調查(集賢)'!R8+'調查(集賢)'!S8+'調查(集賢)'!T8+'調查(集賢)'!U8+'調查(集賢)'!V8+'調查(集賢)'!W8+'調查(集賢)'!BF8+'調查(集賢)'!BG8+'調查(集賢)'!BH8+'調查(集賢)'!BI8+'調查(集賢)'!BJ8+'調查(集賢)'!BK8+'調查(集賢)'!CS8+'調查(集賢)'!CT8+'調查(集賢)'!CU8+'調查(集賢)'!CV8+'調查(集賢)'!CW8+'調查(集賢)'!CX8+'調查(集賢)'!EF8+'調查(集賢)'!EG8+'調查(集賢)'!EH8+'調查(集賢)'!EI8+'調查(集賢)'!EJ8+'調查(集賢)'!EK8 -> 0 | G11: ='調查(集賢)'!AE8+'調查(集賢)'!AF8+'調查(集賢)'!AG8+'調查(集賢)'!AH8+'調查(集賢)'!AI8+'調查(集賢)'!AJ8+'調查(集賢)'!BS8+'調查(集賢)'!BT8+'調查(集賢)'!BU8+'調查(集賢)'!BV8+'調查(集賢)'!BW8+'調查(集賢)'!BX8+'調查(集賢)'!DF8+'調查(集賢)'!DG8+'調查(集賢)'!DH8+'調查(集賢)'!DI8+'調查(集賢)'!DJ8+'調查(集賢)'!DK8+'調查(集賢)'!ES8+'調查(集賢)'!ET8+'調查(集賢)'!EU8+'調查(集賢)'!EV8+'調查(集賢)'!EW8+'調查(集賢)'!EX8 -> 0 | H11: - | I11: ='調查(集賢)'!J8+'調查(集賢)'!K8+'調查(集賢)'!L8+'調查(集賢)'!M8+'調查(集賢)'!AX8+'調查(集賢)'!AY8+'調查(集賢)'!AZ8+'調查(集賢)'!BA8+'調查(集賢)'!CL8+'調查(集賢)'!CM8+'調查(集賢)'!CN8+'調查(集賢)'!CO8+'調查(集賢)'!DY8+'調查(集賢)'!DZ8+'調查(集賢)'!EA8+'調查(集賢)'!EB8 -> 0 | J11: ='調查(集賢)'!X8+'調查(集賢)'!Y8+'調查(集賢)'!Z8+'調查(集賢)'!AA8+'調查(集賢)'!BL8+'調查(集賢)'!BM8+'調查(集賢)'!BN8+'調查(集賢)'!BO8+'調查(集賢)'!CY8+'調查(集賢)'!CZ8+'調查(集賢)'!DA8+'調查(集賢)'!DB8+'調查(集賢)'!EL8+'調查(集賢)'!EM8+'調查(集賢)'!EN8+'調查(集賢)'!EO8 -> 0 | K11: ='調查(集賢)'!AK8+'調查(集賢)'!AL8+'調查(集賢)'!AM8+'調查(集賢)'!AN8+'調查(集賢)'!BY8+'調查(集賢)'!BZ8+'調查(集賢)'!CA8+'調查(集賢)'!CB8+'調查(集賢)'!DL8+'調查(集賢)'!DM8+'調查(集賢)'!DN8+'調查(集賢)'!DO8+'調查(集賢)'!EY8+'調查(集賢)'!EZ8+'調查(集賢)'!FA8+'調查(集賢)'!FB8 -> 0 | L11: - | M11: - | N11: ='調查(集賢)'!Q8+'調查(集賢)'!BE8 -> 0 | O11: ='調查(集賢)'!N8+'調查(集賢)'!O8+'調查(集賢)'!P8+'調查(集賢)'!BB8+'調查(集賢)'!BC8+'調查(集賢)'!BD8+'調查(集賢)'!CP8+'調查(集賢)'!CQ8+'調查(集賢)'!CR8+'調查(集賢)'!EC8+'調查(集賢)'!ED8+'調查(集賢)'!EE8 -> 0 | P11: - | Q11: =IF(AE11>0,AE11-AH11-AH107,0) -> 0 | R11: - | S11: ='調查(集賢)'!AO8+'調查(集賢)'!AP8+'調查(集賢)'!AQ8+'調查(集賢)'!CC8+'調查(集賢)'!CD8+'調查(集賢)'!CE8+'調查(集賢)'!DP8+'調查(集賢)'!DQ8+'調查(集賢)'!DR8+'調查(集賢)'!FC8+'調查(集賢)'!FD8+'調查(集賢)'!FE8 -> 0 | V11: ='調查(集賢)'!D8+'調查(集賢)'!E8+'調查(集賢)'!F8+'調查(集賢)'!G8+'調查(集賢)'!H8+'調查(集賢)'!I8+'調查(集賢)'!AR8+'調查(集賢)'!AS8+'調查(集賢)'!AT8+'調查(集賢)'!AU8+'調查(集賢)'!AV8+'調查(集賢)'!AW8+'調查(集賢)'!CF8+'調查(集賢)'!CG8+'調查(集賢)'!CH8+'調查(集賢)'!CI8+'調查(集賢)'!CJ8+'調查(集賢)'!CK8+'調查(集賢)'!DS8+'調查(集賢)'!DT8+'調查(集賢)'!DU8+'調查(集賢)'!DV8+'調查(集賢)'!DW8+'調查(集賢)'!DX8 -> 0 | W11: ='調查(集賢)'!R8+'調查(集賢)'!S8+'調查(集賢)'!T8+'調查(集賢)'!U8+'調查(集賢)'!V8+'調查(集賢)'!W8+'調查(集賢)'!BF8+'調查(集賢)'!BG8+'調查(集賢)'!BH8+'調查(集賢)'!BI8+'調查(集賢)'!BJ8+'調查(集賢)'!BK8+'調查(集賢)'!CS8+'調查(集賢)'!CT8+'調查(集賢)'!CU8+'調查(集賢)'!CV8+'調查(集賢)'!CW8+'調查(集賢)'!CX8+'調查(集賢)'!EF8+'調查(集賢)'!EG8+'調查(集賢)'!EH8+'調查(集賢)'!EI8+'調查(集賢)'!EJ8+'調查(集賢)'!EK8 -> 0 | X11: ='調查(集賢)'!AE8+'調查(集賢)'!AF8+'調查(集賢)'!AG8+'調查(集賢)'!AH8+'調查(集賢)'!AI8+'調查(集賢)'!AJ8+'調查(集賢)'!BS8+'調查(集賢)'!BT8+'調查(集賢)'!BU8+'調查(集賢)'!BV8+'調查(集賢)'!BW8+'調查(集賢)'!BX8+'調查(集賢)'!DF8+'調查(集賢)'!DG8+'調查(集賢)'!DH8+'調查(集賢)'!DI8+'調查(集賢)'!DJ8+'調查(集賢)'!DK8+'調查(集賢)'!ES8+'調查(集賢)'!ET8+'調查(集賢)'!EU8+'調查(集賢)'!EV8+'調查(集賢)'!EW8+'調查(集賢)'!EX8 -> 0 | Z11: ='調查(集賢)'!J8+'調查(集賢)'!K8+'調查(集賢)'!L8+'調查(集賢)'!M8+'調查(集賢)'!AX8+'調查(集賢)'!AY8+'調查(集賢)'!AZ8+'調查(集賢)'!BA8+'調查(集賢)'!CL8+'調查(集賢)'!CM8+'調查(集賢)'!CN8+'調查(集賢)'!CO8+'調查(集賢)'!DY8+'調查(集賢)'!DZ8+'調查(集賢)'!EA8+'調查(集賢)'!EB8 -> 0 | AA11: ='調查(集賢)'!X8+'調查(集賢)'!Y8+'調查(集賢)'!Z8+'調查(集賢)'!AA8+'調查(集賢)'!BL8+'調查(集賢)'!BM8+'調查(集賢)'!BN8+'調查(集賢)'!BO8+'調查(集賢)'!CY8+'調查(集賢)'!CZ8+'調查(集賢)'!DA8+'調查(集賢)'!DB8+'調查(集賢)'!EL8+'調查(集賢)'!EM8+'調查(集賢)'!EN8+'調查(集賢)'!EO8 -> 0 | AB11: ='調查(集賢)'!AK8+'調查(集賢)'!AL8+'調查(集賢)'!AM8+'調查(集賢)'!AN8+'調查(集賢)'!BY8+'調查(集賢)'!BZ8+'調查(集賢)'!CA8+'調查(集賢)'!CB8+'調查(集賢)'!DL8+'調查(集賢)'!DM8+'調查(集賢)'!DN8+'調查(集賢)'!DO8+'調查(集賢)'!EY8+'調查(集賢)'!EZ8+'調查(集賢)'!FA8+'調查(集賢)'!FB8 -> 0 | AD11: ='調查(集賢)'!N8+'調查(集賢)'!O8+'調查(集賢)'!P8+'調查(集賢)'!BB8+'調查(集賢)'!BC8+'調查(集賢)'!BD8+'調查(集賢)'!CP8+'調查(集賢)'!CQ8+'調查(集賢)'!CR8+'調查(集賢)'!EC8+'調查(集賢)'!ED8+'調查(集賢)'!EE8 -> 0 | AE11: ='調查(集賢)'!AB8+'調查(集賢)'!AC8+'調查(集賢)'!AD8+'調查(集賢)'!BP8+'調查(集賢)'!BQ8+'調查(集賢)'!BR8+'調查(集賢)'!DC8+'調查(集賢)'!DD8+'調查(集賢)'!DE8+'調查(集賢)'!EP8+'調查(集賢)'!EQ8+'調查(集賢)'!ER8 -> 0 | AF11: ='調查(集賢)'!AO8+'調查(集賢)'!AP8+'調查(集賢)'!AQ8+'調查(集賢)'!CC8+'調查(集賢)'!CD8+'調查(集賢)'!CE8+'調查(集賢)'!DP8+'調查(集賢)'!DQ8+'調查(集賢)'!DR8+'調查(集賢)'!FC8+'調查(集賢)'!FD8+'調查(集賢)'!FE8 -> 0 | AH11: ='調查(集賢)'!Q8+'調查(集賢)'!BE8 -> 0
A12: A | B12: 0.072916667 | C12: 0.083333333 | D12: - | E12: ='調查(集賢)'!D9+'調查(集賢)'!E9+'調查(集賢)'!F9+'調查(集賢)'!G9+'調查(集賢)'!H9+'調查(集賢)'!I9+'調查(集賢)'!AR9+'調查(集賢)'!AS9+'調查(集賢)'!AT9+'調查(集賢)'!AU9+'調查(集賢)'!AV9+'調查(集賢)'!AW9+'調查(集賢)'!CF9+'調查(集賢)'!CG9+'調查(集賢)'!CH9+'調查(集賢)'!CI9+'調查(集賢)'!CJ9+'調查(集賢)'!CK9+'調查(集賢)'!DS9+'調查(集賢)'!DT9+'調查(集賢)'!DU9+'調查(集賢)'!DV9+'調查(集賢)'!DW9+'調查(集賢)'!DX9 -> 0 | F12: ='調查(集賢)'!R9+'調查(集賢)'!S9+'調查(集賢)'!T9+'調查(集賢)'!U9+'調查(集賢)'!V9+'調查(集賢)'!W9+'調查(集賢)'!BF9+'調查(集賢)'!BG9+'調查(集賢)'!BH9+'調查(集賢)'!BI9+'調查(集賢)'!BJ9+'調查(集賢)'!BK9+'調查(集賢)'!CS9+'調查(集賢)'!CT9+'調查(集賢)'!CU9+'調查(集賢)'!CV9+'調查(集賢)'!CW9+'調查(集賢)'!CX9+'調查(集賢)'!EF9+'調查(集賢)'!EG9+'調查(集賢)'!EH9+'調查(集賢)'!EI9+'調查(集賢)'!EJ9+'調查(集賢)'!EK9 -> 0 | G12: ='調查(集賢)'!AE9+'調查(集賢)'!AF9+'調查(集賢)'!AG9+'調查(集賢)'!AH9+'調查(集賢)'!AI9+'調查(集賢)'!AJ9+'調查(集賢)'!BS9+'調查(集賢)'!BT9+'調查(集賢)'!BU9+'調查(集賢)'!BV9+'調查(集賢)'!BW9+'調查(集賢)'!BX9+'調查(集賢)'!DF9+'調查(集賢)'!DG9+'調查(集賢)'!DH9+'調查(集賢)'!DI9+'調查(集賢)'!DJ9+'調查(集賢)'!DK9+'調查(集賢)'!ES9+'調查(集賢)'!ET9+'調查(集賢)'!EU9+'調查(集賢)'!EV9+'調查(集賢)'!EW9+'調查(集賢)'!EX9 -> 0 | H12: - | I12: ='調查(集賢)'!J9+'調查(集賢)'!K9+'調查(集賢)'!L9+'調查(集賢)'!M9+'調查(集賢)'!AX9+'調查(集賢)'!AY9+'調查(集賢)'!AZ9+'調查(集賢)'!BA9+'調查(集賢)'!CL9+'調查(集賢)'!CM9+'調查(集賢)'!CN9+'調查(集賢)'!CO9+'調查(集賢)'!DY9+'調查(集賢)'!DZ9+'調查(集賢)'!EA9+'調查(集賢)'!EB9 -> 0 | J12: ='調查(集賢)'!X9+'調查(集賢)'!Y9+'調查(集賢)'!Z9+'調查(集賢)'!AA9+'調查(集賢)'!BL9+'調查(集賢)'!BM9+'調查(集賢)'!BN9+'調查(集賢)'!BO9+'調查(集賢)'!CY9+'調查(集賢)'!CZ9+'調查(集賢)'!DA9+'調查(集賢)'!DB9+'調查(集賢)'!EL9+'調查(集賢)'!EM9+'調查(集賢)'!EN9+'調查(集賢)'!EO9 -> 0 | K12: ='調查(集賢)'!AK9+'調查(集賢)'!AL9+'調查(集賢)'!AM9+'調查(集賢)'!AN9+'調查(集賢)'!BY9+'調查(集賢)'!BZ9+'調查(集賢)'!CA9+'調查(集賢)'!CB9+'調查(集賢)'!DL9+'調查(集賢)'!DM9+'調查(集賢)'!DN9+'調查(集賢)'!DO9+'調查(集賢)'!EY9+'調查(集賢)'!EZ9+'調查(集賢)'!FA9+'調查(集賢)'!FB9 -> 0 | L12: - | M12: - | N12: ='調查(集賢)'!Q9+'調查(集賢)'!BE9 -> 0 | O12: ='調查(集賢)'!N9+'調查(集賢)'!O9+'調查(集賢)'!P9+'調查(集賢)'!BB9+'調查(集賢)'!BC9+'調查(集賢)'!BD9+'調查(集賢)'!CP9+'調查(集賢)'!CQ9+'調查(集賢)'!CR9+'調查(集賢)'!EC9+'調查(集賢)'!ED9+'調查(集賢)'!EE9 -> 0 | P12: - | Q12: =IF(AE12>0,AE12-AH12-AH108,0) -> 0 | R12: - | S12: ='調查(集賢)'!AO9+'調查(集賢)'!AP9+'調查(集賢)'!AQ9+'調查(集賢)'!CC9+'調查(集賢)'!CD9+'調查(集賢)'!CE9+'調查(集賢)'!DP9+'調查(集賢)'!DQ9+'調查(集賢)'!DR9+'調查(集賢)'!FC9+'調查(集賢)'!FD9+'調查(集賢)'!FE9 -> 0 | V12: ='調查(集賢)'!D9+'調查(集賢)'!E9+'調查(集賢)'!F9+'調查(集賢)'!G9+'調查(集賢)'!H9+'調查(集賢)'!I9+'調查(集賢)'!AR9+'調查(集賢)'!AS9+'調查(集賢)'!AT9+'調查(集賢)'!AU9+'調查(集賢)'!AV9+'調查(集賢)'!AW9+'調查(集賢)'!CF9+'調查(集賢)'!CG9+'調查(集賢)'!CH9+'調查(集賢)'!CI9+'調查(集賢)'!CJ9+'調查(集賢)'!CK9+'調查(集賢)'!DS9+'調查(集賢)'!DT9+'調查(集賢)'!DU9+'調查(集賢)'!DV9+'調查(集賢)'!DW9+'調查(集賢)'!DX9 -> 0 | W12: ='調查(集賢)'!R9+'調查(集賢)'!S9+'調查(集賢)'!T9+'調查(集賢)'!U9+'調查(集賢)'!V9+'調查(集賢)'!W9+'調查(集賢)'!BF9+'調查(集賢)'!BG9+'調查(集賢)'!BH9+'調查(集賢)'!BI9+'調查(集賢)'!BJ9+'調查(集賢)'!BK9+'調查(集賢)'!CS9+'調查(集賢)'!CT9+'調查(集賢)'!CU9+'調查(集賢)'!CV9+'調查(集賢)'!CW9+'調查(集賢)'!CX9+'調查(集賢)'!EF9+'調查(集賢)'!EG9+'調查(集賢)'!EH9+'調查(集賢)'!EI9+'調查(集賢)'!EJ9+'調查(集賢)'!EK9 -> 0 | X12: ='調查(集賢)'!AE9+'調查(集賢)'!AF9+'調查(集賢)'!AG9+'調查(集賢)'!AH9+'調查(集賢)'!AI9+'調查(集賢)'!AJ9+'調查(集賢)'!BS9+'調查(集賢)'!BT9+'調查(集賢)'!BU9+'調查(集賢)'!BV9+'調查(集賢)'!BW9+'調查(集賢)'!BX9+'調查(集賢)'!DF9+'調查(集賢)'!DG9+'調查(集賢)'!DH9+'調查(集賢)'!DI9+'調查(集賢)'!DJ9+'調查(集賢)'!DK9+'調查(集賢)'!ES9+'調查(集賢)'!ET9+'調查(集賢)'!EU9+'調查(集賢)'!EV9+'調查(集賢)'!EW9+'調查(集賢)'!EX9 -> 0 | Z12: ='調查(集賢)'!J9+'調查(集賢)'!K9+'調查(集賢)'!L9+'調查(集賢)'!M9+'調查(集賢)'!AX9+'調查(集賢)'!AY9+'調查(集賢)'!AZ9+'調查(集賢)'!BA9+'調查(集賢)'!CL9+'調查(集賢)'!CM9+'調查(集賢)'!CN9+'調查(集賢)'!CO9+'調查(集賢)'!DY9+'調查(集賢)'!DZ9+'調查(集賢)'!EA9+'調查(集賢)'!EB9 -> 0 | AA12: ='調查(集賢)'!X9+'調查(集賢)'!Y9+'調查(集賢)'!Z9+'調查(集賢)'!AA9+'調查(集賢)'!BL9+'調查(集賢)'!BM9+'調查(集賢)'!BN9+'調查(集賢)'!BO9+'調查(集賢)'!CY9+'調查(集賢)'!CZ9+'調查(集賢)'!DA9+'調查(集賢)'!DB9+'調查(集賢)'!EL9+'調查(集賢)'!EM9+'調查(集賢)'!EN9+'調查(集賢)'!EO9 -> 0 | AB12: ='調查(集賢)'!AK9+'調查(集賢)'!AL9+'調查(集賢)'!AM9+'調查(集賢)'!AN9+'調查(集賢)'!BY9+'調查(集賢)'!BZ9+'調查(集賢)'!CA9+'調查(集賢)'!CB9+'調查(集賢)'!DL9+'調查(集賢)'!DM9+'調查(集賢)'!DN9+'調查(集賢)'!DO9+'調查(集賢)'!EY9+'調查(集賢)'!EZ9+'調查(集賢)'!FA9+'調查(集賢)'!FB9 -> 0 | AD12: ='調查(集賢)'!N9+'調查(集賢)'!O9+'調查(集賢)'!P9+'調查(集賢)'!BB9+'調查(集賢)'!BC9+'調查(集賢)'!BD9+'調查(集賢)'!CP9+'調查(集賢)'!CQ9+'調查(集賢)'!CR9+'調查(集賢)'!EC9+'調查(集賢)'!ED9+'調查(集賢)'!EE9 -> 0 | AE12: ='調查(集賢)'!AB9+'調查(集賢)'!AC9+'調查(集賢)'!AD9+'調查(集賢)'!BP9+'調查(集賢)'!BQ9+'調查(集賢)'!BR9+'調查(集賢)'!DC9+'調查(集賢)'!DD9+'調查(集賢)'!DE9+'調查(集賢)'!EP9+'調查(集賢)'!EQ9+'調查(集賢)'!ER9 -> 0 | AF12: ='調查(集賢)'!AO9+'調查(集賢)'!AP9+'調查(集賢)'!AQ9+'調查(集賢)'!CC9+'調查(集賢)'!CD9+'調查(集賢)'!CE9+'調查(集賢)'!DP9+'調查(集賢)'!DQ9+'調查(集賢)'!DR9+'調查(集賢)'!FC9+'調查(集賢)'!FD9+'調查(集賢)'!FE9 -> 0 | AH12: ='調查(集賢)'!Q9+'調查(集賢)'!BE9 -> 0
A13: A | B13: 0.083333333 | C13: 0.09375 | D13: - | E13: ='調查(集賢)'!D10+'調查(集賢)'!E10+'調查(集賢)'!F10+'調查(集賢)'!G10+'調查(集賢)'!H10+'調查(集賢)'!I10+'調查(集賢)'!AR10+'調查(集賢)'!AS10+'調查(集賢)'!AT10+'調查(集賢)'!AU10+'調查(集賢)'!AV10+'調查(集賢)'!AW10+'調查(集賢)'!CF10+'調查(集賢)'!CG10+'調查(集賢)'!CH10+'調查(集賢)'!CI10+'調查(集賢)'!CJ10+'調查(集賢)'!CK10+'調查(集賢)'!DS10+'調查(集賢)'!DT10+'調查(集賢)'!DU10+'調查(集賢)'!DV10+'調查(集賢)'!DW10+'調查(集賢)'!DX10 -> 0 | F13: ='調查(集賢)'!R10+'調查(集賢)'!S10+'調查(集賢)'!T10+'調查(集賢)'!U10+'調查(集賢)'!V10+'調查(集賢)'!W10+'調查(集賢)'!BF10+'調查(集賢)'!BG10+'調查(集賢)'!BH10+'調查(集賢)'!BI10+'調查(集賢)'!BJ10+'調查(集賢)'!BK10+'調查(集賢)'!CS10+'調查(集賢)'!CT10+'調查(集賢)'!CU10+'調查(集賢)'!CV10+'調查(集賢)'!CW10+'調查(集賢)'!CX10+'調查(集賢)'!EF10+'調查(集賢)'!EG10+'調查(集賢)'!EH10+'調查(集賢)'!EI10+'調查(集賢)'!EJ10+'調查(集賢)'!EK10 -> 0 | G13: ='調查(集賢)'!AE10+'調查(集賢)'!AF10+'調查(集賢)'!AG10+'調查(集賢)'!AH10+'調查(集賢)'!AI10+'調查(集賢)'!AJ10+'調查(集賢)'!BS10+'調查(集賢)'!BT10+'調查(集賢)'!BU10+'調查(集賢)'!BV10+'調查(集賢)'!BW10+'調查(集賢)'!BX10+'調查(集賢)'!DF10+'調查(集賢)'!DG10+'調查(集賢)'!DH10+'調查(集賢)'!DI10+'調查(集賢)'!DJ10+'調查(集賢)'!DK10+'調查(集賢)'!ES10+'調查(集賢)'!ET10+'調查(集賢)'!EU10+'調查(集賢)'!EV10+'調查(集賢)'!EW10+'調查(集賢)'!EX10 -> 0 | H13: - | I13: ='調查(集賢)'!J10+'調查(集賢)'!K10+'調查(集賢)'!L10+'調查(集賢)'!M10+'調查(集賢)'!AX10+'調查(集賢)'!AY10+'調查(集賢)'!AZ10+'調查(集賢)'!BA10+'調查(集賢)'!CL10+'調查(集賢)'!CM10+'調查(集賢)'!CN10+'調查(集賢)'!CO10+'調查(集賢)'!DY10+'調查(集賢)'!DZ10+'調查(集賢)'!EA10+'調查(集賢)'!EB10 -> 0 | J13: ='調查(集賢)'!X10+'調查(集賢)'!Y10+'調查(集賢)'!Z10+'調查(集賢)'!AA10+'調查(集賢)'!BL10+'調查(集賢)'!BM10+'調查(集賢)'!BN10+'調查(集賢)'!BO10+'調查(集賢)'!CY10+'調查(集賢)'!CZ10+'調查(集賢)'!DA10+'調查(集賢)'!DB10+'調查(集賢)'!EL10+'調查(集賢)'!EM10+'調查(集賢)'!EN10+'調查(集賢)'!EO10 -> 0 | K13: ='調查(集賢)'!AK10+'調查(集賢)'!AL10+'調查(集賢)'!AM10+'調查(集賢)'!AN10+'調查(集賢)'!BY10+'調查(集賢)'!BZ10+'調查(集賢)'!CA10+'調查(集賢)'!CB10+'調查(集賢)'!DL10+'調查(集賢)'!DM10+'調查(集賢)'!DN10+'調查(集賢)'!DO10+'調查(集賢)'!EY10+'調查(集賢)'!EZ10+'調查(集賢)'!FA10+'調查(集賢)'!FB10 -> 0 | L13: - | M13: - | N13: ='調查(集賢)'!Q10+'調查(集賢)'!BE10 -> 0 | O13: ='調查(集賢)'!N10+'調查(集賢)'!O10+'調查(集賢)'!P10+'調查(集賢)'!BB10+'調查(集賢)'!BC10+'調查(集賢)'!BD10+'調查(集賢)'!CP10+'調查(集賢)'!CQ10+'調查(集賢)'!CR10+'調查(集賢)'!EC10+'調查(集賢)'!ED10+'調查(集賢)'!EE10 -> 0 | P13: - | Q13: =IF(AE13>0,AE13-AH13-AH109,0) -> 0 | R13: - | S13: ='調查(集賢)'!AO10+'調查(集賢)'!AP10+'調查(集賢)'!AQ10+'調查(集賢)'!CC10+'調查(集賢)'!CD10+'調查(集賢)'!CE10+'調查(集賢)'!DP10+'調查(集賢)'!DQ10+'調查(集賢)'!DR10+'調查(集賢)'!FC10+'調查(集賢)'!FD10+'調查(集賢)'!FE10 -> 0 | V13: ='調查(集賢)'!D10+'調查(集賢)'!E10+'調查(集賢)'!F10+'調查(集賢)'!G10+'調查(集賢)'!H10+'調查(集賢)'!I10+'調查(集賢)'!AR10+'調查(集賢)'!AS10+'調查(集賢)'!AT10+'調查(集賢)'!AU10+'調查(集賢)'!AV10+'調查(集賢)'!AW10+'調查(集賢)'!CF10+'調查(集賢)'!CG10+'調查(集賢)'!CH10+'調查(集賢)'!CI10+'調查(集賢)'!CJ10+'調查(集賢)'!CK10+'調查(集賢)'!DS10+'調查(集賢)'!DT10+'調查(集賢)'!DU10+'調查(集賢)'!DV10+'調查(集賢)'!DW10+'調查(集賢)'!DX10 -> 0 | W13: ='調查(集賢)'!R10+'調查(集賢)'!S10+'調查(集賢)'!T10+'調查(集賢)'!U10+'調查(集賢)'!V10+'調查(集賢)'!W10+'調查(集賢)'!BF10+'調查(集賢)'!BG10+'調查(集賢)'!BH10+'調查(集賢)'!BI10+'調查(集賢)'!BJ10+'調查(集賢)'!BK10+'調查(集賢)'!CS10+'調查(集賢)'!CT10+'調查(集賢)'!CU10+'調查(集賢)'!CV10+'調查(集賢)'!CW10+'調查(集賢)'!CX10+'調查(集賢)'!EF10+'調查(集賢)'!EG10+'調查(集賢)'!EH10+'調查(集賢)'!EI10+'調查(集賢)'!EJ10+'調查(集賢)'!EK10 -> 0 | X13: ='調查(集賢)'!AE10+'調查(集賢)'!AF10+'調查(集賢)'!AG10+'調查(集賢)'!AH10+'調查(集賢)'!AI10+'調查(集賢)'!AJ10+'調查(集賢)'!BS10+'調查(集賢)'!BT10+'調查(集賢)'!BU10+'調查(集賢)'!BV10+'調查(集賢)'!BW10+'調查(集賢)'!BX10+'調查(集賢)'!DF10+'調查(集賢)'!DG10+'調查(集賢)'!DH10+'調查(集賢)'!DI10+'調查(集賢)'!DJ10+'調查(集賢)'!DK10+'調查(集賢)'!ES10+'調查(集賢)'!ET10+'調查(集賢)'!EU10+'調查(集賢)'!EV10+'調查(集賢)'!EW10+'調查(集賢)'!EX10 -> 0 | Z13: ='調查(集賢)'!J10+'調查(集賢)'!K10+'調查(集賢)'!L10+'調查(集賢)'!M10+'調查(集賢)'!AX10+'調查(集賢)'!AY10+'調查(集賢)'!AZ10+'調查(集賢)'!BA10+'調查(集賢)'!CL10+'調查(集賢)'!CM10+'調查(集賢)'!CN10+'調查(集賢)'!CO10+'調查(集賢)'!DY10+'調查(集賢)'!DZ10+'調查(集賢)'!EA10+'調查(集賢)'!EB10 -> 0 | AA13: ='調查(集賢)'!X10+'調查(集賢)'!Y10+'調查(集賢)'!Z10+'調查(集賢)'!AA10+'調查(集賢)'!BL10+'調查(集賢)'!BM10+'調查(集賢)'!BN10+'調查(集賢)'!BO10+'調查(集賢)'!CY10+'調查(集賢)'!CZ10+'調查(集賢)'!DA10+'調查(集賢)'!DB10+'調查(集賢)'!EL10+'調查(集賢)'!EM10+'調查(集賢)'!EN10+'調查(集賢)'!EO10 -> 0 | AB13: ='調查(集賢)'!AK10+'調查(集賢)'!AL10+'調查(集賢)'!AM10+'調查(集賢)'!AN10+'調查(集賢)'!BY10+'調查(集賢)'!BZ10+'調查(集賢)'!CA10+'調查(集賢)'!CB10+'調查(集賢)'!DL10+'調查(集賢)'!DM10+'調查(集賢)'!DN10+'調查(集賢)'!DO10+'調查(集賢)'!EY10+'調查(集賢)'!EZ10+'調查(集賢)'!FA10+'調查(集賢)'!FB10 -> 0 | AD13: ='調查(集賢)'!N10+'調查(集賢)'!O10+'調查(集賢)'!P10+'調查(集賢)'!BB10+'調查(集賢)'!BC10+'調查(集賢)'!BD10+'調查(集賢)'!CP10+'調查(集賢)'!CQ10+'調查(集賢)'!CR10+'調查(集賢)'!EC10+'調查(集賢)'!ED10+'調查(集賢)'!EE10 -> 0 | AE13: ='調查(集賢)'!AB10+'調查(集賢)'!AC10+'調查(集賢)'!AD10+'調查(集賢)'!BP10+'調查(集賢)'!BQ10+'調查(集賢)'!BR10+'調查(集賢)'!DC10+'調查(集賢)'!DD10+'調查(集賢)'!DE10+'調查(集賢)'!EP10+'調查(集賢)'!EQ10+'調查(集賢)'!ER10 -> 0 | AF13: ='調查(集賢)'!AO10+'調查(集賢)'!AP10+'調查(集賢)'!AQ10+'調查(集賢)'!CC10+'調查(集賢)'!CD10+'調查(集賢)'!CE10+'調查(集賢)'!DP10+'調查(集賢)'!DQ10+'調查(集賢)'!DR10+'調查(集賢)'!FC10+'調查(集賢)'!FD10+'調查(集賢)'!FE10 -> 0 | AH13: ='調查(集賢)'!Q10+'調查(集賢)'!BE10 -> 0
A14: A | B14: 0.09375 | C14: 0.10416667 | D14: - | E14: ='調查(集賢)'!D11+'調查(集賢)'!E11+'調查(集賢)'!F11+'調查(集賢)'!G11+'調查(集賢)'!H11+'調查(集賢)'!I11+'調查(集賢)'!AR11+'調查(集賢)'!AS11+'調查(集賢)'!AT11+'調查(集賢)'!AU11+'調查(集賢)'!AV11+'調查(集賢)'!AW11+'調查(集賢)'!CF11+'調查(集賢)'!CG11+'調查(集賢)'!CH11+'調查(集賢)'!CI11+'調查(集賢)'!CJ11+'調查(集賢)'!CK11+'調查(集賢)'!DS11+'調查(集賢)'!DT11+'調查(集賢)'!DU11+'調查(集賢)'!DV11+'調查(集賢)'!DW11+'調查(集賢)'!DX11 -> 0 | F14: ='調查(集賢)'!R11+'調查(集賢)'!S11+'調查(集賢)'!T11+'調查(集賢)'!U11+'調查(集賢)'!V11+'調查(集賢)'!W11+'調查(集賢)'!BF11+'調查(集賢)'!BG11+'調查(集賢)'!BH11+'調查(集賢)'!BI11+'調查(集賢)'!BJ11+'調查(集賢)'!BK11+'調查(集賢)'!CS11+'調查(集賢)'!CT11+'調查(集賢)'!CU11+'調查(集賢)'!CV11+'調查(集賢)'!CW11+'調查(集賢)'!CX11+'調查(集賢)'!EF11+'調查(集賢)'!EG11+'調查(集賢)'!EH11+'調查(集賢)'!EI11+'調查(集賢)'!EJ11+'調查(集賢)'!EK11 -> 0 | G14: ='調查(集賢)'!AE11+'調查(集賢)'!AF11+'調查(集賢)'!AG11+'調查(集賢)'!AH11+'調查(集賢)'!AI11+'調查(集賢)'!AJ11+'調查(集賢)'!BS11+'調查(集賢)'!BT11+'調查(集賢)'!BU11+'調查(集賢)'!BV11+'調查(集賢)'!BW11+'調查(集賢)'!BX11+'調查(集賢)'!DF11+'調查(集賢)'!DG11+'調查(集賢)'!DH11+'調查(集賢)'!DI11+'調查(集賢)'!DJ11+'調查(集賢)'!DK11+'調查(集賢)'!ES11+'調查(集賢)'!ET11+'調查(集賢)'!EU11+'調查(集賢)'!EV11+'調查(集賢)'!EW11+'調查(集賢)'!EX11 -> 0 | H14: - | I14: ='調查(集賢)'!J11+'調查(集賢)'!K11+'調查(集賢)'!L11+'調查(集賢)'!M11+'調查(集賢)'!AX11+'調查(集賢)'!AY11+'調查(集賢)'!AZ11+'調查(集賢)'!BA11+'調查(集賢)'!CL11+'調查(集賢)'!CM11+'調查(集賢)'!CN11+'調查(集賢)'!CO11+'調查(集賢)'!DY11+'調查(集賢)'!DZ11+'調查(集賢)'!EA11+'調查(集賢)'!EB11 -> 0 | J14: ='調查(集賢)'!X11+'調查(集賢)'!Y11+'調查(集賢)'!Z11+'調查(集賢)'!AA11+'調查(集賢)'!BL11+'調查(集賢)'!BM11+'調查(集賢)'!BN11+'調查(集賢)'!BO11+'調查(集賢)'!CY11+'調查(集賢)'!CZ11+'調查(集賢)'!DA11+'調查(集賢)'!DB11+'調查(集賢)'!EL11+'調查(集賢)'!EM11+'調查(集賢)'!EN11+'調查(集賢)'!EO11 -> 0 | K14: ='調查(集賢)'!AK11+'調查(集賢)'!AL11+'調查(集賢)'!AM11+'調查(集賢)'!AN11+'調查(集賢)'!BY11+'調查(集賢)'!BZ11+'調查(集賢)'!CA11+'調查(集賢)'!CB11+'調查(集賢)'!DL11+'調查(集賢)'!DM11+'調查(集賢)'!DN11+'調查(集賢)'!DO11+'調查(集賢)'!EY11+'調查(集賢)'!EZ11+'調查(集賢)'!FA11+'調查(集賢)'!FB11 -> 0 | L14: - | M14: - | N14: ='調查(集賢)'!Q11+'調查(集賢)'!BE11 -> 0 | O14: ='調查(集賢)'!N11+'調查(集賢)'!O11+'調查(集賢)'!P11+'調查(集賢)'!BB11+'調查(集賢)'!BC11+'調查(集賢)'!BD11+'調查(集賢)'!CP11+'調查(集賢)'!CQ11+'調查(集賢)'!CR11+'調查(集賢)'!EC11+'調查(集賢)'!ED11+'調查(集賢)'!EE11 -> 0 | P14: - | Q14: =IF(AE14>0,AE14-AH14-AH110,0) -> 0 | R14: - | S14: ='調查(集賢)'!AO11+'調查(集賢)'!AP11+'調查(集賢)'!AQ11+'調查(集賢)'!CC11+'調查(集賢)'!CD11+'調查(集賢)'!CE11+'調查(集賢)'!DP11+'調查(集賢)'!DQ11+'調查(集賢)'!DR11+'調查(集賢)'!FC11+'調查(集賢)'!FD11+'調查(集賢)'!FE11 -> 0 | V14: ='調查(集賢)'!D11+'調查(集賢)'!E11+'調查(集賢)'!F11+'調查(集賢)'!G11+'調查(集賢)'!H11+'調查(集賢)'!I11+'調查(集賢)'!AR11+'調查(集賢)'!AS11+'調查(集賢)'!AT11+'調查(集賢)'!AU11+'調查(集賢)'!AV11+'調查(集賢)'!AW11+'調查(集賢)'!CF11+'調查(集賢)'!CG11+'調查(集賢)'!CH11+'調查(集賢)'!CI11+'調查(集賢)'!CJ11+'調查(集賢)'!CK11+'調查(集賢)'!DS11+'調查(集賢)'!DT11+'調查(集賢)'!DU11+'調查(集賢)'!DV11+'調查(集賢)'!DW11+'調查(集賢)'!DX11 -> 0 | W14: ='調查(集賢)'!R11+'調查(集賢)'!S11+'調查(集賢)'!T11+'調查(集賢)'!U11+'調查(集賢)'!V11+'調查(集賢)'!W11+'調查(集賢)'!BF11+'調查(集賢)'!BG11+'調查(集賢)'!BH11+'調查(集賢)'!BI11+'調查(集賢)'!BJ11+'調查(集賢)'!BK11+'調查(集賢)'!CS11+'調查(集賢)'!CT11+'調查(集賢)'!CU11+'調查(集賢)'!CV11+'調查(集賢)'!CW11+'調查(集賢)'!CX11+'調查(集賢)'!EF11+'調查(集賢)'!EG11+'調查(集賢)'!EH11+'調查(集賢)'!EI11+'調查(集賢)'!EJ11+'調查(集賢)'!EK11 -> 0 | X14: ='調查(集賢)'!AE11+'調查(集賢)'!AF11+'調查(集賢)'!AG11+'調查(集賢)'!AH11+'調查(集賢)'!AI11+'調查(集賢)'!AJ11+'調查(集賢)'!BS11+'調查(集賢)'!BT11+'調查(集賢)'!BU11+'調查(集賢)'!BV11+'調查(集賢)'!BW11+'調查(集賢)'!BX11+'調查(集賢)'!DF11+'調查(集賢)'!DG11+'調查(集賢)'!DH11+'調查(集賢)'!DI11+'調查(集賢)'!DJ11+'調查(集賢)'!DK11+'調查(集賢)'!ES11+'調查(集賢)'!ET11+'調查(集賢)'!EU11+'調查(集賢)'!EV11+'調查(集賢)'!EW11+'調查(集賢)'!EX11 -> 0 | Z14: ='調查(集賢)'!J11+'調查(集賢)'!K11+'調查(集賢)'!L11+'調查(集賢)'!M11+'調查(集賢)'!AX11+'調查(集賢)'!AY11+'調查(集賢)'!AZ11+'調查(集賢)'!BA11+'調查(集賢)'!CL11+'調查(集賢)'!CM11+'調查(集賢)'!CN11+'調查(集賢)'!CO11+'調查(集賢)'!DY11+'調查(集賢)'!DZ11+'調查(集賢)'!EA11+'調查(集賢)'!EB11 -> 0 | AA14: ='調查(集賢)'!X11+'調查(集賢)'!Y11+'調查(集賢)'!Z11+'調查(集賢)'!AA11+'調查(集賢)'!BL11+'調查(集賢)'!BM11+'調查(集賢)'!BN11+'調查(集賢)'!BO11+'調查(集賢)'!CY11+'調查(集賢)'!CZ11+'調查(集賢)'!DA11+'調查(集賢)'!DB11+'調查(集賢)'!EL11+'調查(集賢)'!EM11+'調查(集賢)'!EN11+'調查(集賢)'!EO11 -> 0 | AB14: ='調查(集賢)'!AK11+'調查(集賢)'!AL11+'調查(集賢)'!AM11+'調查(集賢)'!AN11+'調查(集賢)'!BY11+'調查(集賢)'!BZ11+'調查(集賢)'!CA11+'調查(集賢)'!CB11+'調查(集賢)'!DL11+'調查(集賢)'!DM11+'調查(集賢)'!DN11+'調查(集賢)'!DO11+'調查(集賢)'!EY11+'調查(集賢)'!EZ11+'調查(集賢)'!FA11+'調查(集賢)'!FB11 -> 0 | AD14: ='調查(集賢)'!N11+'調查(集賢)'!O11+'調查(集賢)'!P11+'調查(集賢)'!BB11+'調查(集賢)'!BC11+'調查(集賢)'!BD11+'調查(集賢)'!CP11+'調查(集賢)'!CQ11+'調查(集賢)'!CR11+'調查(集賢)'!EC11+'調查(集賢)'!ED11+'調查(集賢)'!EE11 -> 0 | AE14: ='調查(集賢)'!AB11+'調查(集賢)'!AC11+'調查(集賢)'!AD11+'調查(集賢)'!BP11+'調查(集賢)'!BQ11+'調查(集賢)'!BR11+'調查(集賢)'!DC11+'調查(集賢)'!DD11+'調查(集賢)'!DE11+'調查(集賢)'!EP11+'調查(集賢)'!EQ11+'調查(集賢)'!ER11 -> 0 | AF14: ='調查(集賢)'!AO11+'調查(集賢)'!AP11+'調查(集賢)'!AQ11+'調查(集賢)'!CC11+'調查(集賢)'!CD11+'調查(集賢)'!CE11+'調查(集賢)'!DP11+'調查(集賢)'!DQ11+'調查(集賢)'!DR11+'調查(集賢)'!FC11+'調查(集賢)'!FD11+'調查(集賢)'!FE11 -> 0 | AH14: ='調查(集賢)'!Q11+'調查(集賢)'!BE11 -> 0
A15: A | B15: 0.10416667 | C15: 0.11458333 | D15: - | E15: ='調查(集賢)'!D12+'調查(集賢)'!E12+'調查(集賢)'!F12+'調查(集賢)'!G12+'調查(集賢)'!H12+'調查(集賢)'!I12+'調查(集賢)'!AR12+'調查(集賢)'!AS12+'調查(集賢)'!AT12+'調查(集賢)'!AU12+'調查(集賢)'!AV12+'調查(集賢)'!AW12+'調查(集賢)'!CF12+'調查(集賢)'!CG12+'調查(集賢)'!CH12+'調查(集賢)'!CI12+'調查(集賢)'!CJ12+'調查(集賢)'!CK12+'調查(集賢)'!DS12+'調查(集賢)'!DT12+'調查(集賢)'!DU12+'調查(集賢)'!DV12+'調查(集賢)'!DW12+'調查(集賢)'!DX12 -> 0 | F15: ='調查(集賢)'!R12+'調查(集賢)'!S12+'調查(集賢)'!T12+'調查(集賢)'!U12+'調查(集賢)'!V12+'調查(集賢)'!W12+'調查(集賢)'!BF12+'調查(集賢)'!BG12+'調查(集賢)'!BH12+'調查(集賢)'!BI12+'調查(集賢)'!BJ12+'調查(集賢)'!BK12+'調查(集賢)'!CS12+'調查(集賢)'!CT12+'調查(集賢)'!CU12+'調查(集賢)'!CV12+'調查(集賢)'!CW12+'調查(集賢)'!CX12+'調查(集賢)'!EF12+'調查(集賢)'!EG12+'調查(集賢)'!EH12+'調查(集賢)'!EI12+'調查(集賢)'!EJ12+'調查(集賢)'!EK12 -> 0 | G15: ='調查(集賢)'!AE12+'調查(集賢)'!AF12+'調查(集賢)'!AG12+'調查(集賢)'!AH12+'調查(集賢)'!AI12+'調查(集賢)'!AJ12+'調查(集賢)'!BS12+'調查(集賢)'!BT12+'調查(集賢)'!BU12+'調查(集賢)'!BV12+'調查(集賢)'!BW12+'調查(集賢)'!BX12+'調查(集賢)'!DF12+'調查(集賢)'!DG12+'調查(集賢)'!DH12+'調查(集賢)'!DI12+'調查(集賢)'!DJ12+'調查(集賢)'!DK12+'調查(集賢)'!ES12+'調查(集賢)'!ET12+'調查(集賢)'!EU12+'調查(集賢)'!EV12+'調查(集賢)'!EW12+'調查(集賢)'!EX12 -> 0 | H15: - | I15: ='調查(集賢)'!J12+'調查(集賢)'!K12+'調查(集賢)'!L12+'調查(集賢)'!M12+'調查(集賢)'!AX12+'調查(集賢)'!AY12+'調查(集賢)'!AZ12+'調查(集賢)'!BA12+'調查(集賢)'!CL12+'調查(集賢)'!CM12+'調查(集賢)'!CN12+'調查(集賢)'!CO12+'調查(集賢)'!DY12+'調查(集賢)'!DZ12+'調查(集賢)'!EA12+'調查(集賢)'!EB12 -> 0 | J15: ='調查(集賢)'!X12+'調查(集賢)'!Y12+'調查(集賢)'!Z12+'調查(集賢)'!AA12+'調查(集賢)'!BL12+'調查(集賢)'!BM12+'調查(集賢)'!BN12+'調查(集賢)'!BO12+'調查(集賢)'!CY12+'調查(集賢)'!CZ12+'調查(集賢)'!DA12+'調查(集賢)'!DB12+'調查(集賢)'!EL12+'調查(集賢)'!EM12+'調查(集賢)'!EN12+'調查(集賢)'!EO12 -> 0 | K15: ='調查(集賢)'!AK12+'調查(集賢)'!AL12+'調查(集賢)'!AM12+'調查(集賢)'!AN12+'調查(集賢)'!BY12+'調查(集賢)'!BZ12+'調查(集賢)'!CA12+'調查(集賢)'!CB12+'調查(集賢)'!DL12+'調查(集賢)'!DM12+'調查(集賢)'!DN12+'調查(集賢)'!DO12+'調查(集賢)'!EY12+'調查(集賢)'!EZ12+'調查(集賢)'!FA12+'調查(集賢)'!FB12 -> 0 | L15: - | M15: - | N15: ='調查(集賢)'!Q12+'調查(集賢)'!BE12 -> 0 | O15: ='調查(集賢)'!N12+'調查(集賢)'!O12+'調查(集賢)'!P12+'調查(集賢)'!BB12+'調查(集賢)'!BC12+'調查(集賢)'!BD12+'調查(集賢)'!CP12+'調查(集賢)'!CQ12+'調查(集賢)'!CR12+'調查(集賢)'!EC12+'調查(集賢)'!ED12+'調查(集賢)'!EE12 -> 0 | P15: - | Q15: =IF(AE15>0,AE15-AH15-AH111,0) -> 0 | R15: - | S15: ='調查(集賢)'!AO12+'調查(集賢)'!AP12+'調查(集賢)'!AQ12+'調查(集賢)'!CC12+'調查(集賢)'!CD12+'調查(集賢)'!CE12+'調查(集賢)'!DP12+'調查(集賢)'!DQ12+'調查(集賢)'!DR12+'調查(集賢)'!FC12+'調查(集賢)'!FD12+'調查(集賢)'!FE12 -> 0 | V15: ='調查(集賢)'!D12+'調查(集賢)'!E12+'調查(集賢)'!F12+'調查(集賢)'!G12+'調查(集賢)'!H12+'調查(集賢)'!I12+'調查(集賢)'!AR12+'調查(集賢)'!AS12+'調查(集賢)'!AT12+'調查(集賢)'!AU12+'調查(集賢)'!AV12+'調查(集賢)'!AW12+'調查(集賢)'!CF12+'調查(集賢)'!CG12+'調查(集賢)'!CH12+'調查(集賢)'!CI12+'調查(集賢)'!CJ12+'調查(集賢)'!CK12+'調查(集賢)'!DS12+'調查(集賢)'!DT12+'調查(集賢)'!DU12+'調查(集賢)'!DV12+'調查(集賢)'!DW12+'調查(集賢)'!DX12 -> 0 | W15: ='調查(集賢)'!R12+'調查(集賢)'!S12+'調查(集賢)'!T12+'調查(集賢)'!U12+'調查(集賢)'!V12+'調查(集賢)'!W12+'調查(集賢)'!BF12+'調查(集賢)'!BG12+'調查(集賢)'!BH12+'調查(集賢)'!BI12+'調查(集賢)'!BJ12+'調查(集賢)'!BK12+'調查(集賢)'!CS12+'調查(集賢)'!CT12+'調查(集賢)'!CU12+'調查(集賢)'!CV12+'調查(集賢)'!CW12+'調查(集賢)'!CX12+'調查(集賢)'!EF12+'調查(集賢)'!EG12+'調查(集賢)'!EH12+'調查(集賢)'!EI12+'調查(集賢)'!EJ12+'調查(集賢)'!EK12 -> 0 | X15: ='調查(集賢)'!AE12+'調查(集賢)'!AF12+'調查(集賢)'!AG12+'調查(集賢)'!AH12+'調查(集賢)'!AI12+'調查(集賢)'!AJ12+'調查(集賢)'!BS12+'調查(集賢)'!BT12+'調查(集賢)'!BU12+'調查(集賢)'!BV12+'調查(集賢)'!BW12+'調查(集賢)'!BX12+'調查(集賢)'!DF12+'調查(集賢)'!DG12+'調查(集賢)'!DH12+'調查(集賢)'!DI12+'調查(集賢)'!DJ12+'調查(集賢)'!DK12+'調查(集賢)'!ES12+'調查(集賢)'!ET12+'調查(集賢)'!EU12+'調查(集賢)'!EV12+'調查(集賢)'!EW12+'調查(集賢)'!EX12 -> 0 | Z15: ='調查(集賢)'!J12+'調查(集賢)'!K12+'調查(集賢)'!L12+'調查(集賢)'!M12+'調查(集賢)'!AX12+'調查(集賢)'!AY12+'調查(集賢)'!AZ12+'調查(集賢)'!BA12+'調查(集賢)'!CL12+'調查(集賢)'!CM12+'調查(集賢)'!CN12+'調查(集賢)'!CO12+'調查(集賢)'!DY12+'調查(集賢)'!DZ12+'調查(集賢)'!EA12+'調查(集賢)'!EB12 -> 0 | AA15: ='調查(集賢)'!X12+'調查(集賢)'!Y12+'調查(集賢)'!Z12+'調查(集賢)'!AA12+'調查(集賢)'!BL12+'調查(集賢)'!BM12+'調查(集賢)'!BN12+'調查(集賢)'!BO12+'調查(集賢)'!CY12+'調查(集賢)'!CZ12+'調查(集賢)'!DA12+'調查(集賢)'!DB12+'調查(集賢)'!EL12+'調查(集賢)'!EM12+'調查(集賢)'!EN12+'調查(集賢)'!EO12 -> 0 | AB15: ='調查(集賢)'!AK12+'調查(集賢)'!AL12+'調查(集賢)'!AM12+'調查(集賢)'!AN12+'調查(集賢)'!BY12+'調查(集賢)'!BZ12+'調查(集賢)'!CA12+'調查(集賢)'!CB12+'調查(集賢)'!DL12+'調查(集賢)'!DM12+'調查(集賢)'!DN12+'調查(集賢)'!DO12+'調查(集賢)'!EY12+'調查(集賢)'!EZ12+'調查(集賢)'!FA12+'調查(集賢)'!FB12 -> 0 | AD15: ='調查(集賢)'!N12+'調查(集賢)'!O12+'調查(集賢)'!P12+'調查(集賢)'!BB12+'調查(集賢)'!BC12+'調查(集賢)'!BD12+'調查(集賢)'!CP12+'調查(集賢)'!CQ12+'調查(集賢)'!CR12+'調查(集賢)'!EC12+'調查(集賢)'!ED12+'調查(集賢)'!EE12 -> 0 | AE15: ='調查(集賢)'!AB12+'調查(集賢)'!AC12+'調查(集賢)'!AD12+'調查(集賢)'!BP12+'調查(集賢)'!BQ12+'調查(集賢)'!BR12+'調查(集賢)'!DC12+'調查(集賢)'!DD12+'調查(集賢)'!DE12+'調查(集賢)'!EP12+'調查(集賢)'!EQ12+'調查(集賢)'!ER12 -> 0 | AF15: ='調查(集賢)'!AO12+'調查(集賢)'!AP12+'調查(集賢)'!AQ12+'調查(集賢)'!CC12+'調查(集賢)'!CD12+'調查(集賢)'!CE12+'調查(集賢)'!DP12+'調查(集賢)'!DQ12+'調查(集賢)'!DR12+'調查(集賢)'!FC12+'調查(集賢)'!FD12+'調查(集賢)'!FE12 -> 0 | AH15: ='調查(集賢)'!Q12+'調查(集賢)'!BE12 -> 0
A16: A | B16: 0.11458333 | C16: 0.125 | D16: - | E16: ='調查(集賢)'!D13+'調查(集賢)'!E13+'調查(集賢)'!F13+'調查(集賢)'!G13+'調查(集賢)'!H13+'調查(集賢)'!I13+'調查(集賢)'!AR13+'調查(集賢)'!AS13+'調查(集賢)'!AT13+'調查(集賢)'!AU13+'調查(集賢)'!AV13+'調查(集賢)'!AW13+'調查(集賢)'!CF13+'調查(集賢)'!CG13+'調查(集賢)'!CH13+'調查(集賢)'!CI13+'調查(集賢)'!CJ13+'調查(集賢)'!CK13+'調查(集賢)'!DS13+'調查(集賢)'!DT13+'調查(集賢)'!DU13+'調查(集賢)'!DV13+'調查(集賢)'!DW13+'調查(集賢)'!DX13 -> 0 | F16: ='調查(集賢)'!R13+'調查(集賢)'!S13+'調查(集賢)'!T13+'調查(集賢)'!U13+'調查(集賢)'!V13+'調查(集賢)'!W13+'調查(集賢)'!BF13+'調查(集賢)'!BG13+'調查(集賢)'!BH13+'調查(集賢)'!BI13+'調查(集賢)'!BJ13+'調查(集賢)'!BK13+'調查(集賢)'!CS13+'調查(集賢)'!CT13+'調查(集賢)'!CU13+'調查(集賢)'!CV13+'調查(集賢)'!CW13+'調查(集賢)'!CX13+'調查(集賢)'!EF13+'調查(集賢)'!EG13+'調查(集賢)'!EH13+'調查(集賢)'!EI13+'調查(集賢)'!EJ13+'調查(集賢)'!EK13 -> 0 | G16: ='調查(集賢)'!AE13+'調查(集賢)'!AF13+'調查(集賢)'!AG13+'調查(集賢)'!AH13+'調查(集賢)'!AI13+'調查(集賢)'!AJ13+'調查(集賢)'!BS13+'調查(集賢)'!BT13+'調查(集賢)'!BU13+'調查(集賢)'!BV13+'調查(集賢)'!BW13+'調查(集賢)'!BX13+'調查(集賢)'!DF13+'調查(集賢)'!DG13+'調查(集賢)'!DH13+'調查(集賢)'!DI13+'調查(集賢)'!DJ13+'調查(集賢)'!DK13+'調查(集賢)'!ES13+'調查(集賢)'!ET13+'調查(集賢)'!EU13+'調查(集賢)'!EV13+'調查(集賢)'!EW13+'調查(集賢)'!EX13 -> 0 | H16: - | I16: ='調查(集賢)'!J13+'調查(集賢)'!K13+'調查(集賢)'!L13+'調查(集賢)'!M13+'調查(集賢)'!AX13+'調查(集賢)'!AY13+'調查(集賢)'!AZ13+'調查(集賢)'!BA13+'調查(集賢)'!CL13+'調查(集賢)'!CM13+'調查(集賢)'!CN13+'調查(集賢)'!CO13+'調查(集賢)'!DY13+'調查(集賢)'!DZ13+'調查(集賢)'!EA13+'調查(集賢)'!EB13 -> 0 | J16: ='調查(集賢)'!X13+'調查(集賢)'!Y13+'調查(集賢)'!Z13+'調查(集賢)'!AA13+'調查(集賢)'!BL13+'調查(集賢)'!BM13+'調查(集賢)'!BN13+'調查(集賢)'!BO13+'調查(集賢)'!CY13+'調查(集賢)'!CZ13+'調查(集賢)'!DA13+'調查(集賢)'!DB13+'調查(集賢)'!EL13+'調查(集賢)'!EM13+'調查(集賢)'!EN13+'調查(集賢)'!EO13 -> 0 | K16: ='調查(集賢)'!AK13+'調查(集賢)'!AL13+'調查(集賢)'!AM13+'調查(集賢)'!AN13+'調查(集賢)'!BY13+'調查(集賢)'!BZ13+'調查(集賢)'!CA13+'調查(集賢)'!CB13+'調查(集賢)'!DL13+'調查(集賢)'!DM13+'調查(集賢)'!DN13+'調查(集賢)'!DO13+'調查(集賢)'!EY13+'調查(集賢)'!EZ13+'調查(集賢)'!FA13+'調查(集賢)'!FB13 -> 0 | L16: - | M16: - | N16: ='調查(集賢)'!Q13+'調查(集賢)'!BE13 -> 0 | O16: ='調查(集賢)'!N13+'調查(集賢)'!O13+'調查(集賢)'!P13+'調查(集賢)'!BB13+'調查(集賢)'!BC13+'調查(集賢)'!BD13+'調查(集賢)'!CP13+'調查(集賢)'!CQ13+'調查(集賢)'!CR13+'調查(集賢)'!EC13+'調查(集賢)'!ED13+'調查(集賢)'!EE13 -> 0 | P16: - | Q16: =IF(AE16>0,AE16-AH16-AH112,0) -> 0 | R16: - | S16: ='調查(集賢)'!AO13+'調查(集賢)'!AP13+'調查(集賢)'!AQ13+'調查(集賢)'!CC13+'調查(集賢)'!CD13+'調查(集賢)'!CE13+'調查(集賢)'!DP13+'調查(集賢)'!DQ13+'調查(集賢)'!DR13+'調查(集賢)'!FC13+'調查(集賢)'!FD13+'調查(集賢)'!FE13 -> 0 | V16: ='調查(集賢)'!D13+'調查(集賢)'!E13+'調查(集賢)'!F13+'調查(集賢)'!G13+'調查(集賢)'!H13+'調查(集賢)'!I13+'調查(集賢)'!AR13+'調查(集賢)'!AS13+'調查(集賢)'!AT13+'調查(集賢)'!AU13+'調查(集賢)'!AV13+'調查(集賢)'!AW13+'調查(集賢)'!CF13+'調查(集賢)'!CG13+'調查(集賢)'!CH13+'調查(集賢)'!CI13+'調查(集賢)'!CJ13+'調查(集賢)'!CK13+'調查(集賢)'!DS13+'調查(集賢)'!DT13+'調查(集賢)'!DU13+'調查(集賢)'!DV13+'調查(集賢)'!DW13+'調查(集賢)'!DX13 -> 0 | W16: ='調查(集賢)'!R13+'調查(集賢)'!S13+'調查(集賢)'!T13+'調查(集賢)'!U13+'調查(集賢)'!V13+'調查(集賢)'!W13+'調查(集賢)'!BF13+'調查(集賢)'!BG13+'調查(集賢)'!BH13+'調查(集賢)'!BI13+'調查(集賢)'!BJ13+'調查(集賢)'!BK13+'調查(集賢)'!CS13+'調查(集賢)'!CT13+'調查(集賢)'!CU13+'調查(集賢)'!CV13+'調查(集賢)'!CW13+'調查(集賢)'!CX13+'調查(集賢)'!EF13+'調查(集賢)'!EG13+'調查(集賢)'!EH13+'調查(集賢)'!EI13+'調查(集賢)'!EJ13+'調查(集賢)'!EK13 -> 0 | X16: ='調查(集賢)'!AE13+'調查(集賢)'!AF13+'調查(集賢)'!AG13+'調查(集賢)'!AH13+'調查(集賢)'!AI13+'調查(集賢)'!AJ13+'調查(集賢)'!BS13+'調查(集賢)'!BT13+'調查(集賢)'!BU13+'調查(集賢)'!BV13+'調查(集賢)'!BW13+'調查(集賢)'!BX13+'調查(集賢)'!DF13+'調查(集賢)'!DG13+'調查(集賢)'!DH13+'調查(集賢)'!DI13+'調查(集賢)'!DJ13+'調查(集賢)'!DK13+'調查(集賢)'!ES13+'調查(集賢)'!ET13+'調查(集賢)'!EU13+'調查(集賢)'!EV13+'調查(集賢)'!EW13+'調查(集賢)'!EX13 -> 0 | Z16: ='調查(集賢)'!J13+'調查(集賢)'!K13+'調查(集賢)'!L13+'調查(集賢)'!M13+'調查(集賢)'!AX13+'調查(集賢)'!AY13+'調查(集賢)'!AZ13+'調查(集賢)'!BA13+'調查(集賢)'!CL13+'調查(集賢)'!CM13+'調查(集賢)'!CN13+'調查(集賢)'!CO13+'調查(集賢)'!DY13+'調查(集賢)'!DZ13+'調查(集賢)'!EA13+'調查(集賢)'!EB13 -> 0 | AA16: ='調查(集賢)'!X13+'調查(集賢)'!Y13+'調查(集賢)'!Z13+'調查(集賢)'!AA13+'調查(集賢)'!BL13+'調查(集賢)'!BM13+'調查(集賢)'!BN13+'調查(集賢)'!BO13+'調查(集賢)'!CY13+'調查(集賢)'!CZ13+'調查(集賢)'!DA13+'調查(集賢)'!DB13+'調查(集賢)'!EL13+'調查(集賢)'!EM13+'調查(集賢)'!EN13+'調查(集賢)'!EO13 -> 0 | AB16: ='調查(集賢)'!AK13+'調查(集賢)'!AL13+'調查(集賢)'!AM13+'調查(集賢)'!AN13+'調查(集賢)'!BY13+'調查(集賢)'!BZ13+'調查(集賢)'!CA13+'調查(集賢)'!CB13+'調查(集賢)'!DL13+'調查(集賢)'!DM13+'調查(集賢)'!DN13+'調查(集賢)'!DO13+'調查(集賢)'!EY13+'調查(集賢)'!EZ13+'調查(集賢)'!FA13+'調查(集賢)'!FB13 -> 0 | AD16: ='調查(集賢)'!N13+'調查(集賢)'!O13+'調查(集賢)'!P13+'調查(集賢)'!BB13+'調查(集賢)'!BC13+'調查(集賢)'!BD13+'調查(集賢)'!CP13+'調查(集賢)'!CQ13+'調查(集賢)'!CR13+'調查(集賢)'!EC13+'調查(集賢)'!ED13+'調查(集賢)'!EE13 -> 0 | AE16: ='調查(集賢)'!AB13+'調查(集賢)'!AC13+'調查(集賢)'!AD13+'調查(集賢)'!BP13+'調查(集賢)'!BQ13+'調查(集賢)'!BR13+'調查(集賢)'!DC13+'調查(集賢)'!DD13+'調查(集賢)'!DE13+'調查(集賢)'!EP13+'調查(集賢)'!EQ13+'調查(集賢)'!ER13 -> 0 | AF16: ='調查(集賢)'!AO13+'調查(集賢)'!AP13+'調查(集賢)'!AQ13+'調查(集賢)'!CC13+'調查(集賢)'!CD13+'調查(集賢)'!CE13+'調查(集賢)'!DP13+'調查(集賢)'!DQ13+'調查(集賢)'!DR13+'調查(集賢)'!FC13+'調查(集賢)'!FD13+'調查(集賢)'!FE13 -> 0 | AH16: ='調查(集賢)'!Q13+'調查(集賢)'!BE13 -> 0
... A99: A | B99: 0.97916667 | C99: 0.98958333 | D99: - | E99: ='調查(集賢)'!D96+'調查(集賢)'!E96+'調查(集賢)'!F96+'調查(集賢)'!G96+'調查(集賢)'!H96+'調查(集賢)'!I96+'調查(集賢)'!AR96+'調查(集賢)'!AS96+'調查(集賢)'!AT96+'調查(集賢)'!AU96+'調查(集賢)'!AV96+'調查(集賢)'!AW96+'調查(集賢)'!CF96+'調查(集賢)'!CG96+'調查(集賢)'!CH96+'調查(集賢)'!CI96+'調查(集賢)'!CJ96+'調查(集賢)'!CK96+'調查(集賢)'!DS96+'調查(集賢)'!DT96+'調查(集賢)'!DU96+'調查(集賢)'!DV96+'調查(集賢)'!DW96+'調查(集賢)'!DX96 -> 0 | F99: ='調查(集賢)'!R96+'調查(集賢)'!S96+'調查(集賢)'!T96+'調查(集賢)'!U96+'調查(集賢)'!V96+'調查(集賢)'!W96+'調查(集賢)'!BF96+'調查(集賢)'!BG96+'調查(集賢)'!BH96+'調查(集賢)'!BI96+'調查(集賢)'!BJ96+'調查(集賢)'!BK96+'調查(集賢)'!CS96+'調查(集賢)'!CT96+'調查(集賢)'!CU96+'調查(集賢)'!CV96+'調查(集賢)'!CW96+'調查(集賢)'!CX96+'調查(集賢)'!EF96+'調查(集賢)'!EG96+'調查(集賢)'!EH96+'調查(集賢)'!EI96+'調查(集賢)'!EJ96+'調查(集賢)'!EK96 -> 0 | G99: ='調查(集賢)'!AE96+'調查(集賢)'!AF96+'調查(集賢)'!AG96+'調查(集賢)'!AH96+'調查(集賢)'!AI96+'調查(集賢)'!AJ96+'調查(集賢)'!BS96+'調查(集賢)'!BT96+'調查(集賢)'!BU96+'調查(集賢)'!BV96+'調查(集賢)'!BW96+'調查(集賢)'!BX96+'調查(集賢)'!DF96+'調查(集賢)'!DG96+'調查(集賢)'!DH96+'調查(集賢)'!DI96+'調查(集賢)'!DJ96+'調查(集賢)'!DK96+'調查(集賢)'!ES96+'調查(集賢)'!ET96+'調查(集賢)'!EU96+'調查(集賢)'!EV96+'調查(集賢)'!EW96+'調查(集賢)'!EX96 -> 0 | H99: - | I99: ='調查(集賢)'!J96+'調查(集賢)'!K96+'調查(集賢)'!L96+'調查(集賢)'!M96+'調查(集賢)'!AX96+'調查(集賢)'!AY96+'調查(集賢)'!AZ96+'調查(集賢)'!BA96+'調查(集賢)'!CL96+'調查(集賢)'!CM96+'調查(集賢)'!CN96+'調查(集賢)'!CO96+'調查(集賢)'!DY96+'調查(集賢)'!DZ96+'調查(集賢)'!EA96+'調查(集賢)'!EB96 -> 0 | J99: ='調查(集賢)'!X96+'調查(集賢)'!Y96+'調查(集賢)'!Z96+'調查(集賢)'!AA96+'調查(集賢)'!BL96+'調查(集賢)'!BM96+'調查(集賢)'!BN96+'調查(集賢)'!BO96+'調查(集賢)'!CY96+'調查(集賢)'!CZ96+'調查(集賢)'!DA96+'調查(集賢)'!DB96+'調查(集賢)'!EL96+'調查(集賢)'!EM96+'調查(集賢)'!EN96+'調查(集賢)'!EO96 -> 0 | K99: ='調查(集賢)'!AK96+'調查(集賢)'!AL96+'調查(集賢)'!AM96+'調查(集賢)'!AN96+'調查(集賢)'!BY96+'調查(集賢)'!BZ96+'調查(集賢)'!CA96+'調查(集賢)'!CB96+'調查(集賢)'!DL96+'調查(集賢)'!DM96+'調查(集賢)'!DN96+'調查(集賢)'!DO96+'調查(集賢)'!EY96+'調查(集賢)'!EZ96+'調查(集賢)'!FA96+'調查(集賢)'!FB96 -> 0 | L99: - | M99: - | N99: ='調查(集賢)'!Q96+'調查(集賢)'!BE96 -> 0 | O99: ='調查(集賢)'!N96+'調查(集賢)'!O96+'調查(集賢)'!P96+'調查(集賢)'!BB96+'調查(集賢)'!BC96+'調查(集賢)'!BD96+'調查(集賢)'!CP96+'調查(集賢)'!CQ96+'調查(集賢)'!CR96+'調查(集賢)'!EC96+'調查(集賢)'!ED96+'調查(集賢)'!EE96 -> 0 | P99: - | Q99: =IF(AE99>0,AE99-AH99-AH195,0) -> 0 | R99: - | S99: ='調查(集賢)'!AO96+'調查(集賢)'!AP96+'調查(集賢)'!AQ96+'調查(集賢)'!CC96+'調查(集賢)'!CD96+'調查(集賢)'!CE96+'調查(集賢)'!DP96+'調查(集賢)'!DQ96+'調查(集賢)'!DR96+'調查(集賢)'!FC96+'調查(集賢)'!FD96+'調查(集賢)'!FE96 -> 0 | V99: ='調查(集賢)'!D96+'調查(集賢)'!E96+'調查(集賢)'!F96+'調查(集賢)'!G96+'調查(集賢)'!H96+'調查(集賢)'!I96+'調查(集賢)'!AR96+'調查(集賢)'!AS96+'調查(集賢)'!AT96+'調查(集賢)'!AU96+'調查(集賢)'!AV96+'調查(集賢)'!AW96+'調查(集賢)'!CF96+'調查(集賢)'!CG96+'調查(集賢)'!CH96+'調查(集賢)'!CI96+'調查(集賢)'!CJ96+'調查(集賢)'!CK96+'調查(集賢)'!DS96+'調查(集賢)'!DT96+'調查(集賢)'!DU96+'調查(集賢)'!DV96+'調查(集賢)'!DW96+'調查(集賢)'!DX96 -> 0 | W99: ='調查(集賢)'!R96+'調查(集賢)'!S96+'調查(集賢)'!T96+'調查(集賢)'!U96+'調查(集賢)'!V96+'調查(集賢)'!W96+'調查(集賢)'!BF96+'調查(集賢)'!BG96+'調查(集賢)'!BH96+'調查(集賢)'!BI96+'調查(集賢)'!BJ96+'調查(集賢)'!BK96+'調查(集賢)'!CS96+'調查(集賢)'!CT96+'調查(集賢)'!CU96+'調查(集賢)'!CV96+'調查(集賢)'!CW96+'調查(集賢)'!CX96+'調查(集賢)'!EF96+'調查(集賢)'!EG96+'調查(集賢)'!EH96+'調查(集賢)'!EI96+'調查(集賢)'!EJ96+'調查(集賢)'!EK96 -> 0 | X99: ='調查(集賢)'!AE96+'調查(集賢)'!AF96+'調查(集賢)'!AG96+'調查(集賢)'!AH96+'調查(集賢)'!AI96+'調查(集賢)'!AJ96+'調查(集賢)'!BS96+'調查(集賢)'!BT96+'調查(集賢)'!BU96+'調查(集賢)'!BV96+'調查(集賢)'!BW96+'調查(集賢)'!BX96+'調查(集賢)'!DF96+'調查(集賢)'!DG96+'調查(集賢)'!DH96+'調查(集賢)'!DI96+'調查(集賢)'!DJ96+'調查(集賢)'!DK96+'調查(集賢)'!ES96+'調查(集賢)'!ET96+'調查(集賢)'!EU96+'調查(集賢)'!EV96+'調查(集賢)'!EW96+'調查(集賢)'!EX96 -> 0 | Z99: ='調查(集賢)'!J96+'調查(集賢)'!K96+'調查(集賢)'!L96+'調查(集賢)'!M96+'調查(集賢)'!AX96+'調查(集賢)'!AY96+'調查(集賢)'!AZ96+'調查(集賢)'!BA96+'調查(集賢)'!CL96+'調查(集賢)'!CM96+'調查(集賢)'!CN96+'調查(集賢)'!CO96+'調查(集賢)'!DY96+'調查(集賢)'!DZ96+'調查(集賢)'!EA96+'調查(集賢)'!EB96 -> 0 | AA99: ='調查(集賢)'!X96+'調查(集賢)'!Y96+'調查(集賢)'!Z96+'調查(集賢)'!AA96+'調查(集賢)'!BL96+'調查(集賢)'!BM96+'調查(集賢)'!BN96+'調查(集賢)'!BO96+'調查(集賢)'!CY96+'調查(集賢)'!CZ96+'調查(集賢)'!DA96+'調查(集賢)'!DB96+'調查(集賢)'!EL96+'調查(集賢)'!EM96+'調查(集賢)'!EN96+'調查(集賢)'!EO96 -> 0 | AB99: ='調查(集賢)'!AK96+'調查(集賢)'!AL96+'調查(集賢)'!AM96+'調查(集賢)'!AN96+'調查(集賢)'!BY96+'調查(集賢)'!BZ96+'調查(集賢)'!CA96+'調查(集賢)'!CB96+'調查(集賢)'!DL96+'調查(集賢)'!DM96+'調查(集賢)'!DN96+'調查(集賢)'!DO96+'調查(集賢)'!EY96+'調查(集賢)'!EZ96+'調查(集賢)'!FA96+'調查(集賢)'!FB96 -> 0 | AD99: ='調查(集賢)'!N96+'調查(集賢)'!O96+'調查(集賢)'!P96+'調查(集賢)'!BB96+'調查(集賢)'!BC96+'調查(集賢)'!BD96+'調查(集賢)'!CP96+'調查(集賢)'!CQ96+'調查(集賢)'!CR96+'調查(集賢)'!EC96+'調查(集賢)'!ED96+'調查(集賢)'!EE96 -> 0 | AE99: ='調查(集賢)'!AB96+'調查(集賢)'!AC96+'調查(集賢)'!AD96+'調查(集賢)'!BP96+'調查(集賢)'!BQ96+'調查(集賢)'!BR96+'調查(集賢)'!DC96+'調查(集賢)'!DD96+'調查(集賢)'!DE96+'調查(集賢)'!EP96+'調查(集賢)'!EQ96+'調查(集賢)'!ER96 -> 0 | AF99: ='調查(集賢)'!AO96+'調查(集賢)'!AP96+'調查(集賢)'!AQ96+'調查(集賢)'!CC96+'調查(集賢)'!CD96+'調查(集賢)'!CE96+'調查(集賢)'!DP96+'調查(集賢)'!DQ96+'調查(集賢)'!DR96+'調查(集賢)'!FC96+'調查(集賢)'!FD96+'調查(集賢)'!FE96 -> 0 | AH99: ='調查(集賢)'!Q96+'調查(集賢)'!BE96 -> 0
