Workbook

Sheet 資料儲存
A1: 時段 | B1: 臨近路段 | C1: 開始時刻 | D1: 停車在臨近車道上的車輛總數(0秒) | E1: 停車在臨近車道上的車輛總數(15秒) | F1: 停車在臨近車道上的車輛總數(30秒) | G1: 停車在臨近車道上的車輛總數(45秒) | H1: 臨近車道上的流量(總數) | I1: 臨近車道上的流量(未受阻) | J1: 臨近車道上的流量(受阻)
A2: 平日晨峰(0630-0830) | B2: A | C2: 0.27083333 | D2: ='平日晨峰(0630-0830)'!B6 -> 0 | E2: ='平日晨峰(0630-0830)'!C6 -> 0 | F2: ='平日晨峰(0630-0830)'!D6 -> 0 | G2: ='平日晨峰(0630-0830)'!E6 -> 0 | H2: ='平日晨峰(0630-0830)'!F6 -> 0 | I2: ='平日晨峰(0630-0830)'!G6 -> 0 | J2: ='平日晨峰(0630-0830)'!H6 -> 0
A3: 平日晨峰(0630-0830) | B3: A | C3: 0.27152778 | D3: ='平日晨峰(0630-0830)'!B7 -> 0 | E3: ='平日晨峰(0630-0830)'!C7 -> 0 | F3: ='平日晨峰(0630-0830)'!D7 -> 0 | G3: ='平日晨峰(0630-0830)'!E7 -> 0 | H3: ='平日晨峰(0630-0830)'!F7 -> 0 | I3: ='平日晨峰(0630-0830)'!G7 -> 0 | J3: ='平日晨峰(0630-0830)'!H7 -> 0
A4: 平日晨峰(0630-0830) | B4: A | C4: 0.27222222 | D4: ='平日晨峰(0630-0830)'!B8 -> 0 | E4: ='平日晨峰(0630-0830)'!C8 -> 0 | F4: ='平日晨峰(0630-0830)'!D8 -> 0 | G4: ='平日晨峰(0630-0830)'!E8 -> 0 | H4: ='平日晨峰(0630-0830)'!F8 -> 0 | I4: ='平日晨峰(0630-0830)'!G8 -> 0 | J4: ='平日晨峰(0630-0830)'!H8 -> 0
A5: 平日晨峰(0630-0830) | B5: A | C5: 0.27291667 | D5: ='平日晨峰(0630-0830)'!B9 -> 0 | E5: ='平日晨峰(0630-0830)'!C9 -> 0 | F5: ='平日晨峰(0630-0830)'!D9 -> 0 | G5: ='平日晨峰(0630-0830)'!E9 -> 0 | H5: ='平日晨峰(0630-0830)'!F9 -> 0 | I5: ='平日晨峰(0630-0830)'!G9 -> 0 | J5: ='平日晨峰(0630-0830)'!H9 -> 0
A6: 平日晨峰(0630-0830) | B6: A | C6: 0.27361111 | D6: ='平日晨峰(0630-0830)'!B10 -> 0 | E6: ='平日晨峰(0630-0830)'!C10 -> 0 | F6: ='平日晨峰(0630-0830)'!D10 -> 0 | G6: ='平日晨峰(0630-0830)'!E10 -> 0 | H6: ='平日晨峰(0630-0830)'!F10 -> 0 | I6: ='平日晨峰(0630-0830)'!G10 -> 0 | J6: ='平日晨峰(0630-0830)'!H10 -> 0
A7: 平日晨峰(0630-0830) | B7: A | C7: 0.27430556 | D7: ='平日晨峰(0630-0830)'!B11 -> 0 | E7: ='平日晨峰(0630-0830)'!C11 -> 0 | F7: ='平日晨峰(0630-0830)'!D11 -> 0 | G7: ='平日晨峰(0630-0830)'!E11 -> 0 | H7: ='平日晨峰(0630-0830)'!F11 -> 0 | I7: ='平日晨峰(0630-0830)'!G11 -> 0 | J7: ='平日晨峰(0630-0830)'!H11 -> 0
A8: 平日晨峰(0630-0830) | B8: A | C8: 0.275 | D8: ='平日晨峰(0630-0830)'!B12 -> 0 | E8: ='平日晨峰(0630-0830)'!C12 -> 0 | F8: ='平日晨峰(0630-0830)'!D12 -> 0 | G8: ='平日晨峰(0630-0830)'!E12 -> 0 | H8: ='平日晨峰(0630-0830)'!F12 -> 0 | I8: ='平日晨峰(0630-0830)'!G12 -> 0 | J8: ='平日晨峰(0630-0830)'!H12 -> 0
A9: 平日晨峰(0630-0830) | B9: A | C9: 0.27569444 | D9: ='平日晨峰(0630-0830)'!B13 -> 0 | E9: ='平日晨峰(0630-0830)'!C13 -> 0 | F9: ='平日晨峰(0630-0830)'!D13 -> 0 | G9: ='平日晨峰(0630-0830)'!E13 -> 0 | H9: ='平日晨峰(0630-0830)'!F13 -> 0 | I9: ='平日晨峰(0630-0830)'!G13 -> 0 | J9: ='平日晨峰(0630-0830)'!H13 -> 0
A10: 平日晨峰(0630-0830) | B10: A | C10: 0.27638889 | D10: ='平日晨峰(0630-0830)'!B14 -> 0 | E10: ='平日晨峰(0630-0830)'!C14 -> 0 | F10: ='平日晨峰(0630-0830)'!D14 -> 0 | G10: ='平日晨峰(0630-0830)'!E14 -> 0 | H10: ='平日晨峰(0630-0830)'!F14 -> 0 | I10: ='平日晨峰(0630-0830)'!G14 -> 0 | J10: ='平日晨峰(0630-0830)'!H14 -> 0
A11: 平日晨峰(0630-0830) | B11: A | C11: 0.27708333 | D11: ='平日晨峰(0630-0830)'!B15 -> 0 | E11: ='平日晨峰(0630-0830)'!C15 -> 0 | F11: ='平日晨峰(0630-0830)'!D15 -> 0 | G11: ='平日晨峰(0630-0830)'!E15 -> 0 | H11: ='平日晨峰(0630-0830)'!F15 -> 0 | I11: ='平日晨峰(0630-0830)'!G15 -> 0 | J11: ='平日晨峰(0630-0830)'!H15 -> 0
A12: 平日晨峰(0630-0830) | B12: A | C12: 0.27777778 | D12: ='平日晨峰(0630-0830)'!B16 -> 0 | E12: ='平日晨峰(0630-0830)'!C16 -> 0 | F12: ='平日晨峰(0630-0830)'!D16 -> 0 | G12: ='平日晨峰(0630-0830)'!E16 -> 0 | H12: ='平日晨峰(0630-0830)'!F16 -> 0 | I12: ='平日晨峰(0630-0830)'!G16 -> 0 | J12: ='平日晨峰(0630-0830)'!H16 -> 0
A13: 平日晨峰(0630-0830) | B13: A | C13: 0.27847222 | D13: ='平日晨峰(0630-0830)'!B17 -> 0 | E13: ='平日晨峰(0630-0830)'!C17 -> 0 | F13: ='平日晨峰(0630-0830)'!D17 -> 0 | G13: ='平日晨峰(0630-0830)'!E17 -> 0 | H13: ='平日晨峰(0630-0830)'!F17 -> 0 | I13: ='平日晨峰(0630-0830)'!G17 -> 0 | J13: ='平日晨峰(0630-0830)'!H17 -> 0
... A16: 平日晨峰(0630-0830) | B16: A | C16: 0.28055556 | D16: ='平日晨峰(0630-0830)'!B20 -> 0 | E16: ='平日晨峰(0630-0830)'!C20 -> 0 | F16: ='平日晨峰(0630-0830)'!D20 -> 0 | G16: ='平日晨峰(0630-0830)'!E20 -> 0 | H16: ='平日晨峰(0630-0830)'!F20 -> 0 | I16: ='平日晨峰(0630-0830)'!G20 -> 0 | J16: ='平日晨峰(0630-0830)'!H20 -> 0
A17: 平日晨峰(0630-0830) | B17: A | C17: 0.28125 | D17: ='平日晨峰(0630-0830)'!B25 -> 0 | E17: ='平日晨峰(0630-0830)'!C25 -> 0 | F17: ='平日晨峰(0630-0830)'!D25 -> 0 | G17: ='平日晨峰(0630-0830)'!E25 -> 0 | H17: ='平日晨峰(0630-0830)'!F25 -> 0 | I17: ='平日晨峰(0630-0830)'!G25 -> 0 | J17: ='平日晨峰(0630-0830)'!H25 -> 0
A18: 平日晨峰(0630-0830) | B18: A | C18: 0.28194444 | D18: ='平日晨峰(0630-0830)'!B26 -> 0 | E18: ='平日晨峰(0630-0830)'!C26 -> 0 | F18: ='平日晨峰(0630-0830)'!D26 -> 0 | G18: ='平日晨峰(0630-0830)'!E26 -> 0 | H18: ='平日晨峰(0630-0830)'!F26 -> 0 | I18: ='平日晨峰(0630-0830)'!G26 -> 0 | J18: ='平日晨峰(0630-0830)'!H26 -> 0
A19: 平日晨峰(0630-0830) | B19: A | C19: 0.28263889 | D19: ='平日晨峰(0630-0830)'!B27 -> 0 | E19: ='平日晨峰(0630-0830)'!C27 -> 0 | F19: ='平日晨峰(0630-0830)'!D27 -> 0 | G19: ='平日晨峰(0630-0830)'!E27 -> 0 | H19: ='平日晨峰(0630-0830)'!F27 -> 0 | I19: ='平日晨峰(0630-0830)'!G27 -> 0 | J19: ='平日晨峰(0630-0830)'!H27 -> 0
A20: 平日晨峰(0630-0830) | B20: A | C20: 0.28333333 | D20: ='平日晨峰(0630-0830)'!B28 -> 0 | E20: ='平日晨峰(0630-0830)'!C28 -> 0 | F20: ='平日晨峰(0630-0830)'!D28 -> 0 | G20: ='平日晨峰(0630-0830)'!E28 -> 0 | H20: ='平日晨峰(0630-0830)'!F28 -> 0 | I20: ='平日晨峰(0630-0830)'!G28 -> 0 | J20: ='平日晨峰(0630-0830)'!H28 -> 0
A21: 平日晨峰(0630-0830) | B21: A | C21: 0.28402778 | D21: ='平日晨峰(0630-0830)'!B29 -> 0 | E21: ='平日晨峰(0630-0830)'!C29 -> 0 | F21: ='平日晨峰(0630-0830)'!D29 -> 0 | G21: ='平日晨峰(0630-0830)'!E29 -> 0 | H21: ='平日晨峰(0630-0830)'!F29 -> 0 | I21: ='平日晨峰(0630-0830)'!G29 -> 0 | J21: ='平日晨峰(0630-0830)'!H29 -> 0
A22: 平日晨峰(0630-0830) | B22: A | C22: 0.28472222 | D22: ='平日晨峰(0630-0830)'!B30 -> 0 | E22: ='平日晨峰(0630-0830)'!C30 -> 0 | F22: ='平日晨峰(0630-0830)'!D30 -> 0 | G22: ='平日晨峰(0630-0830)'!E30 -> 0 | H22: ='平日晨峰(0630-0830)'!F30 -> 0 | I22: ='平日晨峰(0630-0830)'!G30 -> 0 | J22: ='平日晨峰(0630-0830)'!H30 -> 0
A23: 平日晨峰(0630-0830) | B23: A | C23: 0.28541667 | D23: ='平日晨峰(0630-0830)'!B31 -> 0 | E23: ='平日晨峰(0630-0830)'!C31 -> 0 | F23: ='平日晨峰(0630-0830)'!D31 -> 0 | G23: ='平日晨峰(0630-0830)'!E31 -> 0 | H23: ='平日晨峰(0630-0830)'!F31 -> 0 | I23: ='平日晨峰(0630-0830)'!G31 -> 0 | J23: ='平日晨峰(0630-0830)'!H31 -> 0
A24: 平日晨峰(0630-0830) | B24: A | C24: 0.28611111 | D24: ='平日晨峰(0630-0830)'!B32 -> 0 | E24: ='平日晨峰(0630-0830)'!C32 -> 0 | F24: ='平日晨峰(0630-0830)'!D32 -> 0 | G24: ='平日晨峰(0630-0830)'!E32 -> 0 | H24: ='平日晨峰(0630-0830)'!F32 -> 0 | I24: ='平日晨峰(0630-0830)'!G32 -> 0 | J24: ='平日晨峰(0630-0830)'!H32 -> 0
A25: 平日晨峰(0630-0830) | B25: A | C25: 0.28680556 | D25: ='平日晨峰(0630-0830)'!B33 -> 0 | E25: ='平日晨峰(0630-0830)'!C33 -> 0 | F25: ='平日晨峰(0630-0830)'!D33 -> 0 | G25: ='平日晨峰(0630-0830)'!E33 -> 0 | H25: ='平日晨峰(0630-0830)'!F33 -> 0 | I25: ='平日晨峰(0630-0830)'!G33 -> 0 | J25: ='平日晨峰(0630-0830)'!H33 -> 0
A26: 平日晨峰(0630-0830) | B26: A | C26: 0.2875 | D26: ='平日晨峰(0630-0830)'!B34 -> 0 | E26: ='平日晨峰(0630-0830)'!C34 -> 0 | F26: ='平日晨峰(0630-0830)'!D34 -> 0 | G26: ='平日晨峰(0630-0830)'!E34 -> 0 | H26: ='平日晨峰(0630-0830)'!F34 -> 0 | I26: ='平日晨峰(0630-0830)'!G34 -> 0 | J26: ='平日晨峰(0630-0830)'!H34 -> 0
A27: 平日晨峰(0630-0830) | B27: A | C27: 0.28819444 | D27: ='平日晨峰(0630-0830)'!B35 -> 0 | E27: ='平日晨峰(0630-0830)'!C35 -> 0 | F27: ='平日晨峰(0630-0830)'!D35 -> 0 | G27: ='平日晨峰(0630-0830)'!E35 -> 0 | H27: ='平日晨峰(0630-0830)'!F35 -> 0 | I27: ='平日晨峰(0630-0830)'!G35 -> 0 | J27: ='平日晨峰(0630-0830)'!H35 -> 0
A28: 平日晨峰(0630-0830) | B28: A | C28: 0.28888889 | D28: ='平日晨峰(0630-0830)'!B36 -> 0 | E28: ='平日晨峰(0630-0830)'!C36 -> 0 | F28: ='平日晨峰(0630-0830)'!D36 -> 0 | G28: ='平日晨峰(0630-0830)'!E36 -> 0 | H28: ='平日晨峰(0630-0830)'!F36 -> 0 | I28: ='平日晨峰(0630-0830)'!G36 -> 0 | J28: ='平日晨峰(0630-0830)'!H36 -> 0
... A31: 平日晨峰(0630-0830) | B31: A | C31: 0.29097222 | D31: ='平日晨峰(0630-0830)'!B39 -> 0 | E31: ='平日晨峰(0630-0830)'!C39 -> 0 | F31: ='平日晨峰(0630-0830)'!D39 -> 0 | G31: ='平日晨峰(0630-0830)'!E39 -> 0 | H31: ='平日晨峰(0630-0830)'!F39 -> 0 | I31: ='平日晨峰(0630-0830)'!G39 -> 0 | J31: ='平日晨峰(0630-0830)'!H39 -> 0
A32: 平日晨峰(0630-0830) | B32: A | C32: 0.29166667 | D32: ='平日晨峰(0630-0830)'!B44 -> 0 | E32: ='平日晨峰(0630-0830)'!C44 -> 0 | F32: ='平日晨峰(0630-0830)'!D44 -> 0 | G32: ='平日晨峰(0630-0830)'!E44 -> 0 | H32: ='平日晨峰(0630-0830)'!F44 -> 0 | I32: ='平日晨峰(0630-0830)'!G44 -> 0 | J32: ='平日晨峰(0630-0830)'!H44 -> 0
A33: 平日晨峰(0630-0830) | B33: A | C33: 0.29236111 | D33: ='平日晨峰(0630-0830)'!B45 -> 0 | E33: ='平日晨峰(0630-0830)'!C45 -> 0 | F33: ='平日晨峰(0630-0830)'!D45 -> 0 | G33: ='平日晨峰(0630-0830)'!E45 -> 0 | H33: ='平日晨峰(0630-0830)'!F45 -> 0 | I33: ='平日晨峰(0630-0830)'!G45 -> 0 | J33: ='平日晨峰(0630-0830)'!H45 -> 0
A34: 平日晨峰(0630-0830) | B34: A | C34: 0.29305556 | D34: ='平日晨峰(0630-0830)'!B46 -> 0 | E34: ='平日晨峰(0630-0830)'!C46 -> 0 | F34: ='平日晨峰(0630-0830)'!D46 -> 0 | G34: ='平日晨峰(0630-0830)'!E46 -> 0 | H34: ='平日晨峰(0630-0830)'!F46 -> 0 | I34: ='平日晨峰(0630-0830)'!G46 -> 0 | J34: ='平日晨峰(0630-0830)'!H46 -> 0
A35: 平日晨峰(0630-0830) | B35: A | C35: 0.29375 | D35: ='平日晨峰(0630-0830)'!B47 -> 0 | E35: ='平日晨峰(0630-0830)'!C47 -> 0 | F35: ='平日晨峰(0630-0830)'!D47 -> 0 | G35: ='平日晨峰(0630-0830)'!E47 -> 0 | H35: ='平日晨峰(0630-0830)'!F47 -> 0 | I35: ='平日晨峰(0630-0830)'!G47 -> 0 | J35: ='平日晨峰(0630-0830)'!H47 -> 0
A36: 平日晨峰(0630-0830) | B36: A | C36: 0.29444444 | D36: ='平日晨峰(0630-0830)'!B48 -> 0 | E36: ='平日晨峰(0630-0830)'!C48 -> 0 | F36: ='平日晨峰(0630-0830)'!D48 -> 0 | G36: ='平日晨峰(0630-0830)'!E48 -> 0 | H36: ='平日晨峰(0630-0830)'!F48 -> 0 | I36: ='平日晨峰(0630-0830)'!G48 -> 0 | J36: ='平日晨峰(0630-0830)'!H48 -> 0
A37: 平日晨峰(0630-0830) | B37: A | C37: 0.29513889 | D37: ='平日晨峰(0630-0830)'!B49 -> 0 | E37: ='平日晨峰(0630-0830)'!C49 -> 0 | F37: ='平日晨峰(0630-0830)'!D49 -> 0 | G37: ='平日晨峰(0630-0830)'!E49 -> 0 | H37: ='平日晨峰(0630-0830)'!F49 -> 0 | I37: ='平日晨峰(0630-0830)'!G49 -> 0 | J37: ='平日晨峰(0630-0830)'!H49 -> 0
A38: 平日晨峰(0630-0830) | B38: A | C38: 0.29583333 | D38: ='平日晨峰(0630-0830)'!B50 -> 0 | E38: ='平日晨峰(0630-0830)'!C50 -> 0 | F38: ='平日晨峰(0630-0830)'!D50 -> 0 | G38: ='平日晨峰(0630-0830)'!E50 -> 0 | H38: ='平日晨峰(0630-0830)'!F50 -> 0 | I38: ='平日晨峰(0630-0830)'!G50 -> 0 | J38: ='平日晨峰(0630-0830)'!H50 -> 0
A39: 平日晨峰(0630-0830) | B39: A | C39: 0.29652778 | D39: ='平日晨峰(0630-0830)'!B51 -> 0 | E39: ='平日晨峰(0630-0830)'!C51 -> 0 | F39: ='平日晨峰(0630-0830)'!D51 -> 0 | G39: ='平日晨峰(0630-0830)'!E51 -> 0 | H39: ='平日晨峰(0630-0830)'!F51 -> 0 | I39: ='平日晨峰(0630-0830)'!G51 -> 0 | J39: ='平日晨峰(0630-0830)'!H51 -> 0
A40: 平日晨峰(0630-0830) | B40: A | C40: 0.29722222 | D40: ='平日晨峰(0630-0830)'!B52 -> 0 | E40: ='平日晨峰(0630-0830)'!C52 -> 0 | F40: ='平日晨峰(0630-0830)'!D52 -> 0 | G40: ='平日晨峰(0630-0830)'!E52 -> 0 | H40: ='平日晨峰(0630-0830)'!F52 -> 0 | I40: ='平日晨峰(0630-0830)'!G52 -> 0 | J40: ='平日晨峰(0630-0830)'!H52 -> 0
A41: 平日晨峰(0630-0830) | B41: A | C41: 0.29791667 | D41: ='平日晨峰(0630-0830)'!B53 -> 0 | E41: ='平日晨峰(0630-0830)'!C53 -> 0 | F41: ='平日晨峰(0630-0830)'!D53 -> 0 | G41: ='平日晨峰(0630-0830)'!E53 -> 0 | H41: ='平日晨峰(0630-0830)'!F53 -> 0 | I41: ='平日晨峰(0630-0830)'!G53 -> 0 | J41: ='平日晨峰(0630-0830)'!H53 -> 0
A42: 平日晨峰(0630-0830) | B42: A | C42: 0.29861111 | D42: ='平日晨峰(0630-0830)'!B54 -> 0 | E42: ='平日晨峰(0630-0830)'!C54 -> 0 | F42: ='平日晨峰(0630-0830)'!D54 -> 0 | G42: ='平日晨峰(0630-0830)'!E54 -> 0 | H42: ='平日晨峰(0630-0830)'!F54 -> 0 | I42: ='平日晨峰(0630-0830)'!G54 -> 0 | J42: ='平日晨峰(0630-0830)'!H54 -> 0
A43: 平日晨峰(0630-0830) | B43: A | C43: 0.29930556 | D43: ='平日晨峰(0630-0830)'!B55 -> 0 | E43: ='平日晨峰(0630-0830)'!C55 -> 0 | F43: ='平日晨峰(0630-0830)'!D55 -> 0 | G43: ='平日晨峰(0630-0830)'!E55 -> 0 | H43: ='平日晨峰(0630-0830)'!F55 -> 0 | I43: ='平日晨峰(0630-0830)'!G55 -> 0 | J43: ='平日晨峰(0630-0830)'!H55 -> 0
... A46: 平日晨峰(0630-0830) | B46: A | C46: 0.30138889 | D46: ='平日晨峰(0630-0830)'!B58 -> 0 | E46: ='平日晨峰(0630-0830)'!C58 -> 0 | F46: ='平日晨峰(0630-0830)'!D58 -> 0 | G46: ='平日晨峰(0630-0830)'!E58 -> 0 | H46: ='平日晨峰(0630-0830)'!F58 -> 0 | I46: ='平日晨峰(0630-0830)'!G58 -> 0 | J46: ='平日晨峰(0630-0830)'!H58 -> 0
...

Sheet 基本資料
A1: ※請填入 | B1: 藍底 | C1: 區域
A2: 版本號： | B2: V25.8.1
A4: 業主名稱：
A5: 專案編號：
R6: 往北
A7: TC編號： | C7: (例：TC240) | R7: 往東
A8: 路口名稱： | R8: 往南
A9: 行政區域： | C9: (例：東區) | R9: 往西南
R10: 往西北
B11: 平日晨峰(0630-0830) | C11: 平日晨峰(07-09) | D11: 平日中午(11-13) | E11: 平日中午(12-14) | F11: 平日昏峰(17-19) | G11: 假日(11-12) | H11: 假日(1430-1530) | I11: 假日(1730-1830) | J11: 假日(16-18) | K11: 假日(17-19) | L11: 假日(16-20) | R11: 往東北
A12: 日期： | B12: YYYY/MM/DD | C12: YYYY/MM/DD | D12: YYYY/MM/DD | E12: YYYY/MM/DD | F12: YYYY/MM/DD | G12: YYYY/MM/DD | H12: YYYY/MM/DD | I12: YYYY/MM/DD | J12: YYYY/MM/DD | K12: YYYY/MM/DD | L12: YYYY/MM/DD | R12: 往東南
A13: 天候：
R14: 往西
A16: 路口類型： | B16: 六叉路口
A18: 方 向： | B18: A | C18: B | D18: C | E18: D | F18: E | G18: F
A19: 路段名：
A20: 行車方向：
A21: 車道數： | B21: - | C21: - | D21: - | E21: - | F21: - | G21: -
A25: 簡圖：
C26: =F20 -> 0 | E26: =G20 -> 0
C27: E | E27: E
A30: =E20 -> 0 | B30: D | F30: A | G30: =B20 -> 0
C33: C | E33: B
C34: =D20 -> 0 | E34: =C20 -> 0

Sheet 平日晨峰(0630-0830)
A1: =基本資料!B11 -> 平日晨峰(0630-0830) | J1: =基本資料!B11 -> 平日晨峰(0630-0830) | S1: =基本資料!B11 -> 平日晨峰(0630-0830) | AB1: =基本資料!B11 -> 平日晨峰(0630-0830) | AK1: =基本資料!B11 -> 平日晨峰(0630-0830) | AT1: =基本資料!B11 -> 平日晨峰(0630-0830)
A2: =CONCATENATE(基本資料!B18,"方向：",基本資料!B19,基本資料!B20) -> A方向： | J2: =CONCATENATE(基本資料!C18,"方向：",基本資料!C19,基本資料!C20) -> B方向： | S2: =CONCATENATE(基本資料!D18,"方向：",基本資料!D19,基本資料!D20) -> C方向： | AB2: =CONCATENATE(基本資料!E18,"方向：",基本資料!E19,基本資料!E20) -> D方向： | AK2: =CONCATENATE(基本資料!F18,"方向：",基本資料!F19,基本資料!F20) -> E方向： | AT2: =CONCATENATE(基本資料!G18,"方向：",基本資料!G19,基本資料!G20) -> F方向：
A3: 06:30~06:45 | J3: 06:30~06:45 | S3: 06:30~06:45 | AB3: 06:30~06:45 | AK3: 06:30~06:45 | AT3: 06:30~06:45
A4: 開始時刻 | B4: 停車在臨近車道上的車輛總數 | F4: 臨近車道上的流量 | J4: 開始時刻 | K4: 停車在臨近車道上的車輛總數 | O4: 臨近車道上的流量 | S4: 開始時刻 | T4: 停車在臨近車道上的車輛總數 | X4: 臨近車道上的流量 | AB4: 開始時刻 | AC4: 停車在臨近車道上的車輛總數 | AG4: 臨近車道上的流量 | AK4: 開始時刻 | AL4: 停車在臨近車道上的車輛總數 | AP4: 臨近車道上的流量 | AT4: 開始時刻 | AU4: 停車在臨近車道上的車輛總數 | AY4: 臨近車道上的流量
A5: 0.27083333 | B5: 0秒 | C5: 15秒 | D5: 30秒 | E5: 45秒 | F5: 總數 | G5: 未受阻 | H5: 受阻 | J5: 0.27083333 | K5: 0秒 | L5: 15秒 | M5: 30秒 | N5: 45秒 | O5: 總數 | P5: 未受阻 | Q5: 受阻 | S5: 0.27083333 | T5: 0秒 | U5: 15秒 | V5: 30秒 | W5: 45秒 | X5: 總數 | Y5: 未受阻 | Z5: 受阻 | AB5: 0.27083333 | AC5: 0秒 | AD5: 15秒 | AE5: 30秒 | AF5: 45秒 | AG5: 總數 | AH5: 未受阻 | AI5: 受阻 | AK5: 0.27083333 | AL5: 0秒 | AM5: 15秒 | AN5: 30秒 | AO5: 45秒 | AP5: 總數 | AQ5: 未受阻 | AR5: 受阻 | AT5: 0.27083333 | AU5: 0秒 | AV5: 15秒 | AW5: 30秒 | AX5: 45秒 | AY5: 總數 | AZ5: 未受阻 | BA5: 受阻
A6: 31 | J6: 31 | S6: 31 | AB6: 31 | AK6: 31 | AT6: 31
A7: 32 | J7: 32 | S7: 32 | AB7: 32 | AK7: 32 | AT7: 32
A8: 33 | J8: 33 | S8: 33 | AB8: 33 | AK8: 33 | AT8: 33
A9: 34 | J9: 34 | S9: 34 | AB9: 34 | AK9: 34 | AT9: 34
A10: 35 | J10: 35 | S10: 35 | AB10: 35 | AK10: 35 | AT10: 35
A11: 36 | J11: 36 | S11: 36 | AB11: 36 | AK11: 36 | AT11: 36
A12: 37 | J12: 37 | S12: 37 | AB12: 37 | AK12: 37 | AT12: 37
A13: 38 | J13: 38 | S13: 38 | AB13: 38 | AK13: 38 | AT13: 38
A14: 39 | J14: 39 | S14: 39 | AB14: 39 | AK14: 39 | AT14: 39
A15: 40 | J15: 40 | S15: 40 | AB15: 40 | AK15: 40 | AT15: 40
A16: 41 | J16: 41 | S16: 41 | AB16: 41 | AK16: 41 | AT16: 41
A17: 42 | J17: 42 | S17: 42 | AB17: 42 | AK17: 42 | AT17: 42
... A20: 45 | J20: 45 | S20: 45 | AB20: 45 | AK20: 45 | AT20: 45
A21: 總 計 | B21: =SUM(B6:E20) -> 0 | F21: =F20 -> 0 | G21: =G20 -> 0 | H21: =H20 -> 0 | J21: 總 計 | K21: =SUM(K6:N20) -> 0 | O21: =O20 -> 0 | P21: =P20 -> 0 | Q21: =Q20 -> 0 | S21: 總 計 | T21: =SUM(T6:W20) -> 0 | X21: =X20 -> 0 | Y21: =Y20 -> 0 | Z21: =Z20 -> 0 | AB21: 總 計 | AC21: =SUM(AC6:AF20) -> 0 | AG21: =AG20 -> 0 | AH21: =AH20 -> 0 | AI21: =AI20 -> 0 | AK21: 總 計 | AL21: =SUM(AL6:AO20) -> 0 | AP21: =AP20 -> 0 | AQ21: =AQ20 -> 0 | AR21: =AR20 -> 0 | AT21: 總 計 | AU21: =SUM(AU6:AX20) -> 0 | AY21: =AY20 -> 0 | AZ21: =AZ20 -> 0 | BA21: =BA20 -> 0
A22: 06:45~07:00 | J22: 06:45~07:00 | S22: 06:45~07:00 | AB22: 06:45~07:00 | AK22: 06:45~07:00 | AT22: 06:45~07:00
A23: 開始時刻 | B23: 停車在臨近車道上的車輛總數 | F23: 臨近車道上的流量 | J23: 開始時刻 | K23: 停車在臨近車道上的車輛總數 | O23: 臨近車道上的流量 | S23: 開始時刻 | T23: 停車在臨近車道上的車輛總數 | X23: 臨近車道上的流量 | AB23: 開始時刻 | AC23: 停車在臨近車道上的車輛總數 | AG23: 臨近車道上的流量 | AK23: 開始時刻 | AL23: 停車在臨近車道上的車輛總數 | AP23: 臨近車道上的流量 | AT23: 開始時刻 | AU23: 停車在臨近車道上的車輛總數 | AY23: 臨近車道上的流量
A24: 0.28125 | B24: 0秒 | C24: 15秒 | D24: 30秒 | E24: 45秒 | F24: 總數 | G24: 未受阻 | H24: 受阻 | J24: 0.28125 | K24: 0秒 | L24: 15秒 | M24: 30秒 | N24: 45秒 | O24: 總數 | P24: 未受阻 | Q24: 受阻 | S24: 0.28125 | T24: 0秒 | U24: 15秒 | V24: 30秒 | W24: 45秒 | X24: 總數 | Y24: 未受阻 | Z24: 受阻 | AB24: 0.28125 | AC24: 0秒 | AD24: 15秒 | AE24: 30秒 | AF24: 45秒 | AG24: 總數 | AH24: 未受阻 | AI24: 受阻 | AK24: 0.28125 | AL24: 0秒 | AM24: 15秒 | AN24: 30秒 | AO24: 45秒 | AP24: 總數 | AQ24: 未受阻 | AR24: 受阻 | AT24: 0.28125 | AU24: 0秒 | AV24: 15秒 | AW24: 30秒 | AX24: 45秒 | AY24: 總數 | AZ24: 未受阻 | BA24: 受阻
A25: 46 | J25: 46 | S25: 46 | AB25: 46 | AK25: 46 | AT25: 46
A26: 47 | J26: 47 | S26: 47 | AB26: 47 | AK26: 47 | AT26: 47
A27: 48 | J27: 48 | S27: 48 | AB27: 48 | AK27: 48 | AT27: 48
A28: 49 | J28: 49 | S28: 49 | AB28: 49 | AK28: 49 | AT28: 49
A29: 50 | J29: 50 | S29: 50 | AB29: 50 | AK29: 50 | AT29: 50
A30: 51 | J30: 51 | S30: 51 | AB30: 51 | AK30: 51 | AT30: 51
A31: 52 | J31: 52 | S31: 52 | AB31: 52 | AK31: 52 | AT31: 52
A32: 53 | J32: 53 | S32: 53 | AB32: 53 | AK32: 53 | AT32: 53
A33: 54 | J33: 54 | S33: 54 | AB33: 54 | AK33: 54 | AT33: 54
A34: 55 | J34: 55 | S34: 55 | AB34: 55 | AK34: 55 | AT34: 55
A35: 56 | J35: 56 | S35: 56 | AB35: 56 | AK35: 56 | AT35: 56
A36: 57 | J36: 57 | S36: 57 | AB36: 57 | AK36: 57 | AT36: 57
... A39: 60 | J39: 60 | S39: 60 | AB39: 60 | AK39: 60 | AT39: 60
A40: 總 計 | B40: =SUM(B25:E39) -> 0 | F40: =F39 -> 0 | G40: =G39 -> 0 | H40: =H39 -> 0 | J40: 總 計 | K40: =SUM(K25:N39) -> 0 | O40: =O39 -> 0 | P40: =P39 -> 0 | Q40: =Q39 -> 0 | S40: 總 計 | T40: =SUM(T25:W39) -> 0 | X40: =X39 -> 0 | Y40: =Y39 -> 0 | Z40: =Z39 -> 0 | AB40: 總 計 | AC40: =SUM(AC25:AF39) -> 0 | AG40: =AG39 -> 0 | AH40: =AH39 -> 0 | AI40: =AI39 -> 0 | AK40: 總 計 | AL40: =SUM(AL25:AO39) -> 0 | AP40: =AP39 -> 0 | AQ40: =AQ39 -> 0 | AR40: =AR39 -> 0 | AT40: 總 計 | AU40: =SUM(AU25:AX39) -> 0 | AY40: =AY39 -> 0 | AZ40: =AZ39 -> 0 | BA40: =BA39 -> 0
A41: 07:00~07:15 | J41: 07:00~07:15 | S41: 07:00~07:15 | AB41: 07:00~07:15 | AK41: 07:00~07:15 | AT41: 07:00~07:15
A42: 開始時刻 | B42: 停車在臨近車道上的車輛總數 | F42: 臨近車道上的流量 | J42: 開始時刻 | K42: 停車在臨近車道上的車輛總數 | O42: 臨近車道上的流量 | S42: 開始時刻 | T42: 停車在臨近車道上的車輛總數 | X42: 臨近車道上的流量 | AB42: 開始時刻 | AC42: 停車在臨近車道上的車輛總數 | AG42: 臨近車道上的流量 | AK42: 開始時刻 | AL42: 停車在臨近車道上的車輛總數 | AP42: 臨近車道上的流量 | AT42: 開始時刻 | AU42: 停車在臨近車道上的車輛總數 | AY42: 臨近車道上的流量
A43: 07:00 | B43: 0秒 | C43: 15秒 | D43: 30秒 | E43: 45秒 | F43: 總數 | G43: 未受阻 | H43: 受阻 | J43: 07:00 | K43: 0秒 | L43: 15秒 | M43: 30秒 | N43: 45秒 | O43: 總數 | P43: 未受阻 | Q43: 受阻 | S43: 07:00 | T43: 0秒 | U43: 15秒 | V43: 30秒 | W43: 45秒 | X43: 總數 | Y43: 未受阻 | Z43: 受阻 | AB43: 07:00 | AC43: 0秒 | AD43: 15秒 | AE43: 30秒 | AF43: 45秒 | AG43: 總數 | AH43: 未受阻 | AI43: 受阻 | AK43: 07:00 | AL43: 0秒 | AM43: 15秒 | AN43: 30秒 | AO43: 45秒 | AP43: 總數 | AQ43: 未受阻 | AR43: 受阻 | AT43: 07:00 | AU43: 0秒 | AV43: 15秒 | AW43: 30秒 | AX43: 45秒 | AY43: 總數 | AZ43: 未受阻 | BA43: 受阻
A44: 1 | J44: 1 | S44: 1 | AB44: 1 | AK44: 1 | AT44: 1
...

Sheet 平日晨峰(07-09)
A1: =基本資料!$C$11 -> 平日晨峰(07-09) | J1: =基本資料!$C$11 -> 平日晨峰(07-09) | S1: =基本資料!$C$11 -> 平日晨峰(07-09) | AB1: =基本資料!$C$11 -> 平日晨峰(07-09) | AK1: =基本資料!$C$11 -> 平日晨峰(07-09) | AT1: =基本資料!$C$11 -> 平日晨峰(07-09)
A2: =CONCATENATE(基本資料!B18,"方向：",基本資料!B19,基本資料!B20) -> A方向： | J2: =CONCATENATE(基本資料!C18,"方向：",基本資料!C19,基本資料!C20) -> B方向： | S2: =CONCATENATE(基本資料!D18,"方向：",基本資料!D19,基本資料!D20) -> C方向： | AB2: =CONCATENATE(基本資料!E18,"方向：",基本資料!E19,基本資料!E20) -> D方向： | AK2: =CONCATENATE(基本資料!F18,"方向：",基本資料!F19,基本資料!F20) -> E方向： | AT2: =CONCATENATE(基本資料!G18,"方向：",基本資料!G19,基本資料!G20) -> F方向：
A3: 07:00~07:15 | J3: 07:00~07:15 | S3: 07:00~07:15 | AB3: 07:00~07:15 | AK3: 07:00~07:15 | AT3: 07:00~07:15
A4: 開始時刻 | B4: 停車在臨近車道上的車輛總數 | F4: 臨近車道上的流量 | J4: 開始時刻 | K4: 停車在臨近車道上的車輛總數 | O4: 臨近車道上的流量 | S4: 開始時刻 | T4: 停車在臨近車道上的車輛總數 | X4: 臨近車道上的流量 | AB4: 開始時刻 | AC4: 停車在臨近車道上的車輛總數 | AG4: 臨近車道上的流量 | AK4: 開始時刻 | AL4: 停車在臨近車道上的車輛總數 | AP4: 臨近車道上的流量 | AT4: 開始時刻 | AU4: 停車在臨近車道上的車輛總數 | AY4: 臨近車道上的流量
A5: 07:00 | B5: 0秒 | C5: 15秒 | D5: 30秒 | E5: 45秒 | F5: 總數 | G5: 未受阻 | H5: 受阻 | J5: 07:00 | K5: 0秒 | L5: 15秒 | M5: 30秒 | N5: 45秒 | O5: 總數 | P5: 未受阻 | Q5: 受阻 | S5: 07:00 | T5: 0秒 | U5: 15秒 | V5: 30秒 | W5: 45秒 | X5: 總數 | Y5: 未受阻 | Z5: 受阻 | AB5: 07:00 | AC5: 0秒 | AD5: 15秒 | AE5: 30秒 | AF5: 45秒 | AG5: 總數 | AH5: 未受阻 | AI5: 受阻 | AK5: 07:00 | AL5: 0秒 | AM5: 15秒 | AN5: 30秒 | AO5: 45秒 | AP5: 總數 | AQ5: 未受阻 | AR5: 受阻 | AT5: 07:00 | AU5: 0秒 | AV5: 15秒 | AW5: 30秒 | AX5: 45秒 | AY5: 總數 | AZ5: 未受阻 | BA5: 受阻
A6: 1 | J6: 1 | S6: 1 | AB6: 1 | AK6: 1 | AT6: 1
A7: 2 | J7: 2 | S7: 2 | AB7: 2 | AK7: 2 | AT7: 2
A8: 3 | J8: 3 | S8: 3 | AB8: 3 | AK8: 3 | AT8: 3
A9: 4 | J9: 4 | S9: 4 | AB9: 4 | AK9: 4 | AT9: 4
A10: 5 | J10: 5 | S10: 5 | AB10: 5 | AK10: 5 | AT10: 5
A11: 6 | J11: 6 | S11: 6 | AB11: 6 | AK11: 6 | AT11: 6
A12: 7 | J12: 7 | S12: 7 | AB12: 7 | AK12: 7 | AT12: 7
A13: 8 | J13: 8 | S13: 8 | AB13: 8 | AK13: 8 | AT13: 8
A14: 9 | J14: 9 | S14: 9 | AB14: 9 | AK14: 9 | AT14: 9
A15: 10 | J15: 10 | S15: 10 | AB15: 10 | AK15: 10 | AT15: 10
A16: 11 | J16: 11 | S16: 11 | AB16: 11 | AK16: 11 | AT16: 11
A17: 12 | J17: 12 | S17: 12 | AB17: 12 | AK17: 12 | AT17: 12
... A20: 15 | J20: 15 | S20: 15 | AB20: 15 | AK20: 15 | AT20: 15
A21: 總 計 | B21: =SUM(B6:E20) -> 0 | F21: =F20 -> 0 | G21: =G20 -> 0 | H21: =H20 -> 0 | J21: 總 計 | K21: =SUM(K6:N20) -> 0 | O21: =O20 -> 0 | P21: =P20 -> 0 | Q21: =Q20 -> 0 | S21: 總 計 | T21: =SUM(T6:W20) -> 0 | X21: =X20 -> 0 | Y21: =Y20 -> 0 | Z21: =Z20 -> 0 | AB21: 總 計 | AC21: =SUM(AC6:AF20) -> 0 | AG21: =AG20 -> 0 | AH21: =AH20 -> 0 | AI21: =AI20 -> 0 | AK21: 總 計 | AL21: =SUM(AL6:AO20) -> 0 | AP21: =AP20 -> 0 | AQ21: =AQ20 -> 0 | AR21: =AR20 -> 0 | AT21: 總 計 | AU21: =SUM(AU6:AX20) -> 0 | AY21: =AY20 -> 0 | AZ21: =AZ20 -> 0 | BA21: =BA20 -> 0
A22: 07:15~07:30 | J22: 07:15~07:30 | S22: 07:15~07:30 | AB22: 07:15~07:30 | AK22: 07:15~07:30 | AT22: 07:15~07:30
A23: 開始時刻 | B23: 停車在臨近車道上的車輛總數 | F23: 臨近車道上的流量 | J23: 開始時刻 | K23: 停車在臨近車道上的車輛總數 | O23: 臨近車道上的流量 | S23: 開始時刻 | T23: 停車在臨近車道上的車輛總數 | X23: 臨近車道上的流量 | AB23: 開始時刻 | AC23: 停車在臨近車道上的車輛總數 | AG23: 臨近車道上的流量 | AK23: 開始時刻 | AL23: 停車在臨近車道上的車輛總數 | AP23: 臨近車道上的流量 | AT23: 開始時刻 | AU23: 停車在臨近車道上的車輛總數 | AY23: 臨近車道上的流量
A24: 07:15 | B24: 0秒 | C24: 15秒 | D24: 30秒 | E24: 45秒 | F24: 總數 | G24: 未受阻 | H24: 受阻 | J24: 07:15 | K24: 0秒 | L24: 15秒 | M24: 30秒 | N24: 45秒 | O24: 總數 | P24: 未受阻 | Q24: 受阻 | S24: 07:15 | T24: 0秒 | U24: 15秒 | V24: 30秒 | W24: 45秒 | X24: 總數 | Y24: 未受阻 | Z24: 受阻 | AB24: 07:15 | AC24: 0秒 | AD24: 15秒 | AE24: 30秒 | AF24: 45秒 | AG24: 總數 | AH24: 未受阻 | AI24: 受阻 | AK24: 07:15 | AL24: 0秒 | AM24: 15秒 | AN24: 30秒 | AO24: 45秒 | AP24: 總數 | AQ24: 未受阻 | AR24: 受阻 | AT24: 07:15 | AU24: 0秒 | AV24: 15秒 | AW24: 30秒 | AX24: 45秒 | AY24: 總數 | AZ24: 未受阻 | BA24: 受阻
A25: 16 | J25: 16 | S25: 16 | AB25: 16 | AK25: 16 | AT25: 16
A26: 17 | J26: 17 | S26: 17 | AB26: 17 | AK26: 17 | AT26: 17
A27: 18 | J27: 18 | S27: 18 | AB27: 18 | AK27: 18 | AT27: 18
A28: 19 | J28: 19 | S28: 19 | AB28: 19 | AK28: 19 | AT28: 19
A29: 20 | J29: 20 | S29: 20 | AB29: 20 | AK29: 20 | AT29: 20
A30: 21 | J30: 21 | S30: 21 | AB30: 21 | AK30: 21 | AT30: 21
A31: 22 | J31: 22 | S31: 22 | AB31: 22 | AK31: 22 | AT31: 22
A32: 23 | J32: 23 | S32: 23 | AB32: 23 | AK32: 23 | AT32: 23
A33: 24 | J33: 24 | S33: 24 | AB33: 24 | AK33: 24 | AT33: 24
A34: 25 | J34: 25 | S34: 25 | AB34: 25 | AK34: 25 | AT34: 25
A35: 26 | J35: 26 | S35: 26 | AB35: 26 | AK35: 26 | AT35: 26
A36: 27 | J36: 27 | S36: 27 | AB36: 27 | AK36: 27 | AT36: 27
... A39: 30 | J39: 30 | S39: 30 | AB39: 30 | AK39: 30 | AT39: 30
A40: 總 計 | B40: =SUM(B25:E39) -> 0 | F40: =F39 -> 0 | G40: =G39 -> 0 | H40: =H39 -> 0 | J40: 總 計 | K40: =SUM(K25:N39) -> 0 | O40: =O39 -> 0 | P40: =P39 -> 0 | Q40: =Q39 -> 0 | S40: 總 計 | T40: =SUM(T25:W39) -> 0 | X40: =X39 -> 0 | Y40: =Y39 -> 0 | Z40: =Z39 -> 0 | AB40: 總 計 | AC40: =SUM(AC25:AF39) -> 0 | AG40: =AG39 -> 0 | AH40: =AH39 -> 0 | AI40: =AI39 -> 0 | AK40: 總 計 | AL40: =SUM(AL25:AO39) -> 0 | AP40: =AP39 -> 0 | AQ40: =AQ39 -> 0 | AR40: =AR39 -> 0 | AT40: 總 計 | AU40: =SUM(AU25:AX39) -> 0 | AY40: =AY39 -> 0 | AZ40: =AZ39 -> 0 | BA40: =BA39 -> 0
A41: 07:30~07:45 | J41: 07:30~07:45 | S41: 07:30~07:45 | AB41: 07:30~07:45 | AK41: 07:30~07:45 | AT41: 07:30~07:45
A42: 開始時刻 | B42: 停車在臨近車道上的車輛總數 | F42: 臨近車道上的流量 | J42: 開始時刻 | K42: 停車在臨近車道上的車輛總數 | O42: 臨近車道上的流量 | S42: 開始時刻 | T42: 停車在臨近車道上的車輛總數 | X42: 臨近車道上的流量 | AB42: 開始時刻 | AC42: 停車在臨近車道上的車輛總數 | AG42: 臨近車道上的流量 | AK42: 開始時刻 | AL42: 停車在臨近車道上的車輛總數 | AP42: 臨近車道上的流量 | AT42: 開始時刻 | AU42: 停車在臨近車道上的車輛總數 | AY42: 臨近車道上的流量
A43: 07:30 | B43: 0秒 | C43: 15秒 | D43: 30秒 | E43: 45秒 | F43: 總數 | G43: 未受阻 | H43: 受阻 | J43: 07:30 | K43: 0秒 | L43: 15秒 | M43: 30秒 | N43: 45秒 | O43: 總數 | P43: 未受阻 | Q43: 受阻 | S43: 07:30 | T43: 0秒 | U43: 15秒 | V43: 30秒 | W43: 45秒 | X43: 總數 | Y43: 未受阻 | Z43: 受阻 | AB43: 07:30 | AC43: 0秒 | AD43: 15秒 | AE43: 30秒 | AF43: 45秒 | AG43: 總數 | AH43: 未受阻 | AI43: 受阻 | AK43: 07:30 | AL43: 0秒 | AM43: 15秒 | AN43: 30秒 | AO43: 45秒 | AP43: 總數 | AQ43: 未受阻 | AR43: 受阻 | AT43: 07:30 | AU43: 0秒 | AV43: 15秒 | AW43: 30秒 | AX43: 45秒 | AY43: 總數 | AZ43: 未受阻 | BA43: 受阻
A44: 31 | J44: 31 | S44: 31 | AB44: 31 | AK44: 31 | AT44: 31
...

Sheet 平日中午(11-13)
A1: =基本資料!$D$11 -> 平日中午(11-13) | J1: =基本資料!$D$11 -> 平日中午(11-13) | S1: =基本資料!$D$11 -> 平日中午(11-13) | AB1: =基本資料!$D$11 -> 平日中午(11-13) | AK1: =基本資料!$D$11 -> 平日中午(11-13) | AT1: =基本資料!$D$11 -> 平日中午(11-13)
A2: =CONCATENATE(基本資料!B18,"方向：",基本資料!B19,基本資料!B20) -> A方向： | J2: =CONCATENATE(基本資料!C18,"方向：",基本資料!C19,基本資料!C20) -> B方向： | S2: =CONCATENATE(基本資料!D18,"方向：",基本資料!D19,基本資料!D20) -> C方向： | AB2: =CONCATENATE(基本資料!E18,"方向：",基本資料!E19,基本資料!E20) -> D方向： | AK2: =CONCATENATE(基本資料!F18,"方向：",基本資料!F19,基本資料!F20) -> E方向： | AT2: =CONCATENATE(基本資料!G18,"方向：",基本資料!G19,基本資料!G20) -> F方向：
A3: 11:00~11:15 | J3: 11:00~11:15 | S3: 11:00~11:15 | AB3: 11:00~11:15 | AK3: 11:00~11:15 | AT3: 11:00~11:15
A4: 開始時刻 | B4: 停車在臨近車道上的車輛總數 | F4: 臨近車道上的流量 | J4: 開始時刻 | K4: 停車在臨近車道上的車輛總數 | O4: 臨近車道上的流量 | S4: 開始時刻 | T4: 停車在臨近車道上的車輛總數 | X4: 臨近車道上的流量 | AB4: 開始時刻 | AC4: 停車在臨近車道上的車輛總數 | AG4: 臨近車道上的流量 | AK4: 開始時刻 | AL4: 停車在臨近車道上的車輛總數 | AP4: 臨近車道上的流量 | AT4: 開始時刻 | AU4: 停車在臨近車道上的車輛總數 | AY4: 臨近車道上的流量
A5: 0.45833333 | B5: 0秒 | C5: 15秒 | D5: 30秒 | E5: 45秒 | F5: 總數 | G5: 未受阻 | H5: 受阻 | J5: 0.45833333 | K5: 0秒 | L5: 15秒 | M5: 30秒 | N5: 45秒 | O5: 總數 | P5: 未受阻 | Q5: 受阻 | S5: 0.45833333 | T5: 0秒 | U5: 15秒 | V5: 30秒 | W5: 45秒 | X5: 總數 | Y5: 未受阻 | Z5: 受阻 | AB5: 0.45833333 | AC5: 0秒 | AD5: 15秒 | AE5: 30秒 | AF5: 45秒 | AG5: 總數 | AH5: 未受阻 | AI5: 受阻 | AK5: 0.45833333 | AL5: 0秒 | AM5: 15秒 | AN5: 30秒 | AO5: 45秒 | AP5: 總數 | AQ5: 未受阻 | AR5: 受阻 | AT5: 0.45833333 | AU5: 0秒 | AV5: 15秒 | AW5: 30秒 | AX5: 45秒 | AY5: 總數 | AZ5: 未受阻 | BA5: 受阻
A6: 1 | J6: 1 | S6: 1 | AB6: 1 | AK6: 1 | AT6: 1
A7: 2 | J7: 2 | S7: 2 | AB7: 2 | AK7: 2 | AT7: 2
A8: 3 | J8: 3 | S8: 3 | AB8: 3 | AK8: 3 | AT8: 3
A9: 4 | J9: 4 | S9: 4 | AB9: 4 | AK9: 4 | AT9: 4
A10: 5 | J10: 5 | S10: 5 | AB10: 5 | AK10: 5 | AT10: 5
A11: 6 | J11: 6 | S11: 6 | AB11: 6 | AK11: 6 | AT11: 6
A12: 7 | J12: 7 | S12: 7 | AB12: 7 | AK12: 7 | AT12: 7
A13: 8 | J13: 8 | S13: 8 | AB13: 8 | AK13: 8 | AT13: 8
A14: 9 | J14: 9 | S14: 9 | AB14: 9 | AK14: 9 | AT14: 9
A15: 10 | J15: 10 | S15: 10 | AB15: 10 | AK15: 10 | AT15: 10
A16: 11 | J16: 11 | S16: 11 | AB16: 11 | AK16: 11 | AT16: 11
A17: 12 | J17: 12 | S17: 12 | AB17: 12 | AK17: 12 | AT17: 12
... A20: 15 | J20: 15 | S20: 15 | AB20: 15 | AK20: 15 | AT20: 15
A21: 總 計 | B21: =SUM(B6:E20) -> 0 | F21: =F20 -> 0 | G21: =G20 -> 0 | H21: =H20 -> 0 | J21: 總 計 | K21: =SUM(K6:N20) -> 0 | O21: =O20 -> 0 | P21: =P20 -> 0 | Q21: =Q20 -> 0 | S21: 總 計 | T21: =SUM(T6:W20) -> 0 | X21: =X20 -> 0 | Y21: =Y20 -> 0 | Z21: =Z20 -> 0 | AB21: 總 計 | AC21: =SUM(AC6:AF20) -> 0 | AG21: =AG20 -> 0 | AH21: =AH20 -> 0 | AI21: =AI20 -> 0 | AK21: 總 計 | AL21: =SUM(AL6:AO20) -> 0 | AP21: =AP20 -> 0 | AQ21: =AQ20 -> 0 | AR21: =AR20 -> 0 | AT21: 總 計 | AU21: =SUM(AU6:AX20) -> 0 | AY21: =AY20 -> 0 | AZ21: =AZ20 -> 0 | BA21: =BA20 -> 0
A22: 11:15~11:30 | J22: 11:15~11:30 | S22: 11:15~11:30 | AB22: 11:15~11:30 | AK22: 11:15~11:30 | AT22: 11:15~11:30
A23: 開始時刻 | B23: 停車在臨近車道上的車輛總數 | F23: 臨近車道上的流量 | J23: 開始時刻 | K23: 停車在臨近車道上的車輛總數 | O23: 臨近車道上的流量 | S23: 開始時刻 | T23: 停車在臨近車道上的車輛總數 | X23: 臨近車道上的流量 | AB23: 開始時刻 | AC23: 停車在臨近車道上的車輛總數 | AG23: 臨近車道上的流量 | AK23: 開始時刻 | AL23: 停車在臨近車道上的車輛總數 | AP23: 臨近車道上的流量 | AT23: 開始時刻 | AU23: 停車在臨近車道上的車輛總數 | AY23: 臨近車道上的流量
A24: 0.46875 | B24: 0秒 | C24: 15秒 | D24: 30秒 | E24: 45秒 | F24: 總數 | G24: 未受阻 | H24: 受阻 | J24: 0.46875 | K24: 0秒 | L24: 15秒 | M24: 30秒 | N24: 45秒 | O24: 總數 | P24: 未受阻 | Q24: 受阻 | S24: 0.46875 | T24: 0秒 | U24: 15秒 | V24: 30秒 | W24: 45秒 | X24: 總數 | Y24: 未受阻 | Z24: 受阻 | AB24: 0.46875 | AC24: 0秒 | AD24: 15秒 | AE24: 30秒 | AF24: 45秒 | AG24: 總數 | AH24: 未受阻 | AI24: 受阻 | AK24: 0.46875 | AL24: 0秒 | AM24: 15秒 | AN24: 30秒 | AO24: 45秒 | AP24: 總數 | AQ24: 未受阻 | AR24: 受阻 | AT24: 0.46875 | AU24: 0秒 | AV24: 15秒 | AW24: 30秒 | AX24: 45秒 | AY24: 總數 | AZ24: 未受阻 | BA24: 受阻
A25: 16 | J25: 16 | S25: 16 | AB25: 16 | AK25: 16 | AT25: 16
A26: 17 | J26: 17 | S26: 17 | AB26: 17 | AK26: 17 | AT26: 17
A27: 18 | J27: 18 | S27: 18 | AB27: 18 | AK27: 18 | AT27: 18
A28: 19 | J28: 19 | S28: 19 | AB28: 19 | AK28: 19 | AT28: 19
A29: 20 | J29: 20 | S29: 20 | AB29: 20 | AK29: 20 | AT29: 20
A30: 21 | J30: 21 | S30: 21 | AB30: 21 | AK30: 21 | AT30: 21
A31: 22 | J31: 22 | S31: 22 | AB31: 22 | AK31: 22 | AT31: 22
A32: 23 | J32: 23 | S32: 23 | AB32: 23 | AK32: 23 | AT32: 23
A33: 24 | J33: 24 | S33: 24 | AB33: 24 | AK33: 24 | AT33: 24
A34: 25 | J34: 25 | S34: 25 | AB34: 25 | AK34: 25 | AT34: 25
A35: 26 | J35: 26 | S35: 26 | AB35: 26 | AK35: 26 | AT35: 26
A36: 27 | J36: 27 | S36: 27 | AB36: 27 | AK36: 27 | AT36: 27
... A39: 30 | J39: 30 | S39: 30 | AB39: 30 | AK39: 30 | AT39: 30
A40: 總 計 | B40: =SUM(B25:E39) -> 0 | F40: =F39 -> 0 | G40: =G39 -> 0 | H40: =H39 -> 0 | J40: 總 計 | K40: =SUM(K25:N39) -> 0 | O40: =O39 -> 0 | P40: =P39 -> 0 | Q40: =Q39 -> 0 | S40: 總 計 | T40: =SUM(T25:W39) -> 0 | X40: =X39 -> 0 | Y40: =Y39 -> 0 | Z40: =Z39 -> 0 | AB40: 總 計 | AC40: =SUM(AC25:AF39) -> 0 | AG40: =AG39 -> 0 | AH40: =AH39 -> 0 | AI40: =AI39 -> 0 | AK40: 總 計 | AL40: =SUM(AL25:AO39) -> 0 | AP40: =AP39 -> 0 | AQ40: =AQ39 -> 0 | AR40: =AR39 -> 0 | AT40: 總 計 | AU40: =SUM(AU25:AX39) -> 0 | AY40: =AY39 -> 0 | AZ40: =AZ39 -> 0 | BA40: =BA39 -> 0
A41: 11:30~11:45 | J41: 11:30~11:45 | S41: 11:30~11:45 | AB41: 11:30~11:45 | AK41: 11:30~11:45 | AT41: 11:30~11:45
A42: 開始時刻 | B42: 停車在臨近車道上的車輛總數 | F42: 臨近車道上的流量 | J42: 開始時刻 | K42: 停車在臨近車道上的車輛總數 | O42: 臨近車道上的流量 | S42: 開始時刻 | T42: 停車在臨近車道上的車輛總數 | X42: 臨近車道上的流量 | AB42: 開始時刻 | AC42: 停車在臨近車道上的車輛總數 | AG42: 臨近車道上的流量 | AK42: 開始時刻 | AL42: 停車在臨近車道上的車輛總數 | AP42: 臨近車道上的流量 | AT42: 開始時刻 | AU42: 停車在臨近車道上的車輛總數 | AY42: 臨近車道上的流量
A43: 0.47916667 | B43: 0秒 | C43: 15秒 | D43: 30秒 | E43: 45秒 | F43: 總數 | G43: 未受阻 | H43: 受阻 | J43: 0.47916667 | K43: 0秒 | L43: 15秒 | M43: 30秒 | N43: 45秒 | O43: 總數 | P43: 未受阻 | Q43: 受阻 | S43: 0.47916667 | T43: 0秒 | U43: 15秒 | V43: 30秒 | W43: 45秒 | X43: 總數 | Y43: 未受阻 | Z43: 受阻 | AB43: 0.47916667 | AC43: 0秒 | AD43: 15秒 | AE43: 30秒 | AF43: 45秒 | AG43: 總數 | AH43: 未受阻 | AI43: 受阻 | AK43: 0.47916667 | AL43: 0秒 | AM43: 15秒 | AN43: 30秒 | AO43: 45秒 | AP43: 總數 | AQ43: 未受阻 | AR43: 受阻 | AT43: 0.47916667 | AU43: 0秒 | AV43: 15秒 | AW43: 30秒 | AX43: 45秒 | AY43: 總數 | AZ43: 未受阻 | BA43: 受阻
A44: 31 | J44: 31 | S44: 31 | AB44: 31 | AK44: 31 | AT44: 31
...

Sheet 平日中午(12-14)
A1: =基本資料!$E$11 -> 平日中午(12-14) | J1: =基本資料!$E$11 -> 平日中午(12-14) | S1: =基本資料!$E$11 -> 平日中午(12-14) | AB1: =基本資料!$E$11 -> 平日中午(12-14) | AK1: =基本資料!$E$11 -> 平日中午(12-14) | AT1: =基本資料!$E$11 -> 平日中午(12-14)
A2: =CONCATENATE(基本資料!B18,"方向：",基本資料!B19,基本資料!B20) -> A方向： | J2: =CONCATENATE(基本資料!C18,"方向：",基本資料!C19,基本資料!C20) -> B方向： | S2: =CONCATENATE(基本資料!D18,"方向：",基本資料!D19,基本資料!D20) -> C方向： | AB2: =CONCATENATE(基本資料!E18,"方向：",基本資料!E19,基本資料!E20) -> D方向： | AK2: =CONCATENATE(基本資料!F18,"方向：",基本資料!F19,基本資料!F20) -> E方向： | AT2: =CONCATENATE(基本資料!G18,"方向：",基本資料!G19,基本資料!G20) -> F方向：
A3: 12:00~12:15 | J3: 12:00~12:15 | S3: 12:00~12:15 | AB3: 12:00~12:15 | AK3: 12:00~12:15 | AT3: 12:00~12:15
A4: 開始時刻 | B4: 停車在臨近車道上的車輛總數 | F4: 臨近車道上的流量 | J4: 開始時刻 | K4: 停車在臨近車道上的車輛總數 | O4: 臨近車道上的流量 | S4: 開始時刻 | T4: 停車在臨近車道上的車輛總數 | X4: 臨近車道上的流量 | AB4: 開始時刻 | AC4: 停車在臨近車道上的車輛總數 | AG4: 臨近車道上的流量 | AK4: 開始時刻 | AL4: 停車在臨近車道上的車輛總數 | AP4: 臨近車道上的流量 | AT4: 開始時刻 | AU4: 停車在臨近車道上的車輛總數 | AY4: 臨近車道上的流量
A5: 0.5 | B5: 0秒 | C5: 15秒 | D5: 30秒 | E5: 45秒 | F5: 總數 | G5: 未受阻 | H5: 受阻 | J5: 0.5 | K5: 0秒 | L5: 15秒 | M5: 30秒 | N5: 45秒 | O5: 總數 | P5: 未受阻 | Q5: 受阻 | S5: 0.5 | T5: 0秒 | U5: 15秒 | V5: 30秒 | W5: 45秒 | X5: 總數 | Y5: 未受阻 | Z5: 受阻 | AB5: 0.5 | AC5: 0秒 | AD5: 15秒 | AE5: 30秒 | AF5: 45秒 | AG5: 總數 | AH5: 未受阻 | AI5: 受阻 | AK5: 0.5 | AL5: 0秒 | AM5: 15秒 | AN5: 30秒 | AO5: 45秒 | AP5: 總數 | AQ5: 未受阻 | AR5: 受阻 | AT5: 0.5 | AU5: 0秒 | AV5: 15秒 | AW5: 30秒 | AX5: 45秒 | AY5: 總數 | AZ5: 未受阻 | BA5: 受阻
A6: 1 | J6: 1 | S6: 1 | AB6: 1 | AK6: 1 | AT6: 1
A7: 2 | J7: 2 | S7: 2 | AB7: 2 | AK7: 2 | AT7: 2
A8: 3 | J8: 3 | S8: 3 | AB8: 3 | AK8: 3 | AT8: 3
A9: 4 | J9: 4 | S9: 4 | AB9: 4 | AK9: 4 | AT9: 4
A10: 5 | J10: 5 | S10: 5 | AB10: 5 | AK10: 5 | AT10: 5
A11: 6 | J11: 6 | S11: 6 | AB11: 6 | AK11: 6 | AT11: 6
A12: 7 | J12: 7 | S12: 7 | AB12: 7 | AK12: 7 | AT12: 7
A13: 8 | J13: 8 | S13: 8 | AB13: 8 | AK13: 8 | AT13: 8
A14: 9 | J14: 9 | S14: 9 | AB14: 9 | AK14: 9 | AT14: 9
A15: 10 | J15: 10 | S15: 10 | AB15: 10 | AK15: 10 | AT15: 10
A16: 11 | J16: 11 | S16: 11 | AB16: 11 | AK16: 11 | AT16: 11
A17: 12 | J17: 12 | S17: 12 | AB17: 12 | AK17: 12 | AT17: 12
... A20: 15 | J20: 15 | S20: 15 | AB20: 15 | AK20: 15 | AT20: 15
A21: 總 計 | B21: =SUM(B6:E20) -> 0 | F21: =F20 -> 0 | G21: =G20 -> 0 | H21: =H20 -> 0 | J21: 總 計 | K21: =SUM(K6:N20) -> 0 | O21: =O20 -> 0 | P21: =P20 -> 0 | Q21: =Q20 -> 0 | S21: 總 計 | T21: =SUM(T6:W20) -> 0 | X21: =X20 -> 0 | Y21: =Y20 -> 0 | Z21: =Z20 -> 0 | AB21: 總 計 | AC21: =SUM(AC6:AF20) -> 0 | AG21: =AG20 -> 0 | AH21: =AH20 -> 0 | AI21: =AI20 -> 0 | AK21: 總 計 | AL21: =SUM(AL6:AO20) -> 0 | AP21: =AP20 -> 0 | AQ21: =AQ20 -> 0 | AR21: =AR20 -> 0 | AT21: 總 計 | AU21: =SUM(AU6:AX20) -> 0 | AY21: =AY20 -> 0 | AZ21: =AZ20 -> 0 | BA21: =BA20 -> 0
A22: 12:15~12:30 | J22: 12:15~12:30 | S22: 12:15~12:30 | AB22: 12:15~12:30 | AK22: 12:15~12:30 | AT22: 12:15~12:30
A23: 開始時刻 | B23: 停車在臨近車道上的車輛總數 | F23: 臨近車道上的流量 | J23: 開始時刻 | K23: 停車在臨近車道上的車輛總數 | O23: 臨近車道上的流量 | S23: 開始時刻 | T23: 停車在臨近車道上的車輛總數 | X23: 臨近車道上的流量 | AB23: 開始時刻 | AC23: 停車在臨近車道上的車輛總數 | AG23: 臨近車道上的流量 | AK23: 開始時刻 | AL23: 停車在臨近車道上的車輛總數 | AP23: 臨近車道上的流量 | AT23: 開始時刻 | AU23: 停車在臨近車道上的車輛總數 | AY23: 臨近車道上的流量
A24: 0.51041667 | B24: 0秒 | C24: 15秒 | D24: 30秒 | E24: 45秒 | F24: 總數 | G24: 未受阻 | H24: 受阻 | J24: 0.51041667 | K24: 0秒 | L24: 15秒 | M24: 30秒 | N24: 45秒 | O24: 總數 | P24: 未受阻 | Q24: 受阻 | S24: 0.51041667 | T24: 0秒 | U24: 15秒 | V24: 30秒 | W24: 45秒 | X24: 總數 | Y24: 未受阻 | Z24: 受阻 | AB24: 0.51041667 | AC24: 0秒 | AD24: 15秒 | AE24: 30秒 | AF24: 45秒 | AG24: 總數 | AH24: 未受阻 | AI24: 受阻 | AK24: 0.51041667 | AL24: 0秒 | AM24: 15秒 | AN24: 30秒 | AO24: 45秒 | AP24: 總數 | AQ24: 未受阻 | AR24: 受阻 | AT24: 0.51041667 | AU24: 0秒 | AV24: 15秒 | AW24: 30秒 | AX24: 45秒 | AY24: 總數 | AZ24: 未受阻 | BA24: 受阻
A25: 16 | J25: 16 | S25: 16 | AB25: 16 | AK25: 16 | AT25: 16
A26: 17 | J26: 17 | S26: 17 | AB26: 17 | AK26: 17 | AT26: 17
A27: 18 | J27: 18 | S27: 18 | AB27: 18 | AK27: 18 | AT27: 18
A28: 19 | J28: 19 | S28: 19 | AB28: 19 | AK28: 19 | AT28: 19
A29: 20 | J29: 20 | S29: 20 | AB29: 20 | AK29: 20 | AT29: 20
A30: 21 | J30: 21 | S30: 21 | AB30: 21 | AK30: 21 | AT30: 21
A31: 22 | J31: 22 | S31: 22 | AB31: 22 | AK31: 22 | AT31: 22
A32: 23 | J32: 23 | S32: 23 | AB32: 23 | AK32: 23 | AT32: 23
A33: 24 | J33: 24 | S33: 24 | AB33: 24 | AK33: 24 | AT33: 24
A34: 25 | J34: 25 | S34: 25 | AB34: 25 | AK34: 25 | AT34: 25
A35: 26 | J35: 26 | S35: 26 | AB35: 26 | AK35: 26 | AT35: 26
A36: 27 | J36: 27 | S36: 27 | AB36: 27 | AK36: 27 | AT36: 27
... A39: 30 | J39: 30 | S39: 30 | AB39: 30 | AK39: 30 | AT39: 30
A40: 總 計 | B40: =SUM(B25:E39) -> 0 | F40: =F39 -> 0 | G40: =G39 -> 0 | H40: =H39 -> 0 | J40: 總 計 | K40: =SUM(K25:N39) -> 0 | O40: =O39 -> 0 | P40: =P39 -> 0 | Q40: =Q39 -> 0 | S40: 總 計 | T40: =SUM(T25:W39) -> 0 | X40: =X39 -> 0 | Y40: =Y39 -> 0 | Z40: =Z39 -> 0 | AB40: 總 計 | AC40: =SUM(AC25:AF39) -> 0 | AG40: =AG39 -> 0 | AH40: =AH39 -> 0 | AI40: =AI39 -> 0 | AK40: 總 計 | AL40: =SUM(AL25:AO39) -> 0 | AP40: =AP39 -> 0 | AQ40: =AQ39 -> 0 | AR40: =AR39 -> 0 | AT40: 總 計 | AU40: =SUM(AU25:AX39) -> 0 | AY40: =AY39 -> 0 | AZ40: =AZ39 -> 0 | BA40: =BA39 -> 0
A41: 12:30~12:45 | J41: 12:30~12:45 | S41: 12:30~12:45 | AB41: 12:30~12:45 | AK41: 12:30~12:45 | AT41: 12:30~12:45
A42: 開始時刻 | B42: 停車在臨近車道上的車輛總數 | F42: 臨近車道上的流量 | J42: 開始時刻 | K42: 停車在臨近車道上的車輛總數 | O42: 臨近車道上的流量 | S42: 開始時刻 | T42: 停車在臨近車道上的車輛總數 | X42: 臨近車道上的流量 | AB42: 開始時刻 | AC42: 停車在臨近車道上的車輛總數 | AG42: 臨近車道上的流量 | AK42: 開始時刻 | AL42: 停車在臨近車道上的車輛總數 | AP42: 臨近車道上的流量 | AT42: 開始時刻 | AU42: 停車在臨近車道上的車輛總數 | AY42: 臨近車道上的流量
A43: 0.52083333 | B43: 0秒 | C43: 15秒 | D43: 30秒 | E43: 45秒 | F43: 總數 | G43: 未受阻 | H43: 受阻 | J43: 0.52083333 | K43: 0秒 | L43: 15秒 | M43: 30秒 | N43: 45秒 | O43: 總數 | P43: 未受阻 | Q43: 受阻 | S43: 0.52083333 | T43: 0秒 | U43: 15秒 | V43: 30秒 | W43: 45秒 | X43: 總數 | Y43: 未受阻 | Z43: 受阻 | AB43: 0.52083333 | AC43: 0秒 | AD43: 15秒 | AE43: 30秒 | AF43: 45秒 | AG43: 總數 | AH43: 未受阻 | AI43: 受阻 | AK43: 0.52083333 | AL43: 0秒 | AM43: 15秒 | AN43: 30秒 | AO43: 45秒 | AP43: 總數 | AQ43: 未受阻 | AR43: 受阻 | AT43: 0.52083333 | AU43: 0秒 | AV43: 15秒 | AW43: 30秒 | AX43: 45秒 | AY43: 總數 | AZ43: 未受阻 | BA43: 受阻
A44: 31 | J44: 31 | S44: 31 | AB44: 31 | AK44: 31 | AT44: 31
...

Sheet 平日昏峰(17-19)
A1: =基本資料!$F$11 -> 平日昏峰(17-19) | J1: =基本資料!$F$11 -> 平日昏峰(17-19) | S1: =基本資料!$F$11 -> 平日昏峰(17-19) | AB1: =基本資料!$F$11 -> 平日昏峰(17-19) | AK1: =基本資料!$F$11 -> 平日昏峰(17-19) | AT1: =基本資料!$F$11 -> 平日昏峰(17-19)
A2: =CONCATENATE(基本資料!B18,"方向：",基本資料!B19,基本資料!B20) -> A方向： | J2: =CONCATENATE(基本資料!C18,"方向：",基本資料!C19,基本資料!C20) -> B方向： | S2: =CONCATENATE(基本資料!D18,"方向：",基本資料!D19,基本資料!D20) -> C方向： | AB2: =CONCATENATE(基本資料!E18,"方向：",基本資料!E19,基本資料!E20) -> D方向： | AK2: =CONCATENATE(基本資料!F18,"方向：",基本資料!F19,基本資料!F20) -> E方向： | AT2: =CONCATENATE(基本資料!G18,"方向：",基本資料!G19,基本資料!G20) -> F方向：
A3: 17:00~17:15 | J3: 17:00~17:15 | S3: 17:00~17:15 | AB3: 17:00~17:15 | AK3: 17:00~17:15 | AT3: 17:00~17:15
A4: 開始時刻 | B4: 停車在臨近車道上的車輛總數 | F4: 臨近車道上的流量 | J4: 開始時刻 | K4: 停車在臨近車道上的車輛總數 | O4: 臨近車道上的流量 | S4: 開始時刻 | T4: 停車在臨近車道上的車輛總數 | X4: 臨近車道上的流量 | AB4: 開始時刻 | AC4: 停車在臨近車道上的車輛總數 | AG4: 臨近車道上的流量 | AK4: 開始時刻 | AL4: 停車在臨近車道上的車輛總數 | AP4: 臨近車道上的流量 | AT4: 開始時刻 | AU4: 停車在臨近車道上的車輛總數 | AY4: 臨近車道上的流量
A5: 17:00 | B5: 0秒 | C5: 15秒 | D5: 30秒 | E5: 45秒 | F5: 總數 | G5: 未受阻 | H5: 受阻 | J5: 17:00 | K5: 0秒 | L5: 15秒 | M5: 30秒 | N5: 45秒 | O5: 總數 | P5: 未受阻 | Q5: 受阻 | S5: 17:00 | T5: 0秒 | U5: 15秒 | V5: 30秒 | W5: 45秒 | X5: 總數 | Y5: 未受阻 | Z5: 受阻 | AB5: 17:00 | AC5: 0秒 | AD5: 15秒 | AE5: 30秒 | AF5: 45秒 | AG5: 總數 | AH5: 未受阻 | AI5: 受阻 | AK5: 17:00 | AL5: 0秒 | AM5: 15秒 | AN5: 30秒 | AO5: 45秒 | AP5: 總數 | AQ5: 未受阻 | AR5: 受阻 | AT5: 17:00 | AU5: 0秒 | AV5: 15秒 | AW5: 30秒 | AX5: 45秒 | AY5: 總數 | AZ5: 未受阻 | BA5: 受阻
A6: 1 | J6: 1 | S6: 1 | AB6: 1 | AK6: 1 | AT6: 1
A7: 2 | J7: 2 | S7: 2 | AB7: 2 | AK7: 2 | AT7: 2
A8: 3 | J8: 3 | S8: 3 | AB8: 3 | AK8: 3 | AT8: 3
A9: 4 | J9: 4 | S9: 4 | AB9: 4 | AK9: 4 | AT9: 4
A10: 5 | J10: 5 | S10: 5 | AB10: 5 | AK10: 5 | AT10: 5
A11: 6 | J11: 6 | S11: 6 | AB11: 6 | AK11: 6 | AT11: 6
A12: 7 | J12: 7 | S12: 7 | AB12: 7 | AK12: 7 | AT12: 7
A13: 8 | J13: 8 | S13: 8 | AB13: 8 | AK13: 8 | AT13: 8
A14: 9 | J14: 9 | S14: 9 | AB14: 9 | AK14: 9 | AT14: 9
A15: 10 | J15: 10 | S15: 10 | AB15: 10 | AK15: 10 | AT15: 10
A16: 11 | J16: 11 | S16: 11 | AB16: 11 | AK16: 11 | AT16: 11
A17: 12 | J17: 12 | S17: 12 | AB17: 12 | AK17: 12 | AT17: 12
... A20: 15 | J20: 15 | S20: 15 | AB20: 15 | AK20: 15 | AT20: 15
A21: 總 計 | B21: =SUM(B6:E20) -> 0 | F21: =F20 -> 0 | G21: =G20 -> 0 | H21: =H20 -> 0 | J21: 總 計 | K21: =SUM(K6:N20) -> 0 | O21: =O20 -> 0 | P21: =P20 -> 0 | Q21: =Q20 -> 0 | S21: 總 計 | T21: =SUM(T6:W20) -> 0 | X21: =X20 -> 0 | Y21: =Y20 -> 0 | Z21: =Z20 -> 0 | AB21: 總 計 | AC21: =SUM(AC6:AF20) -> 0 | AG21: =AG20 -> 0 | AH21: =AH20 -> 0 | AI21: =AI20 -> 0 | AK21: 總 計 | AL21: =SUM(AL6:AO20) -> 0 | AP21: =AP20 -> 0 | AQ21: =AQ20 -> 0 | AR21: =AR20 -> 0 | AT21: 總 計 | AU21: =SUM(AU6:AX20) -> 0 | AY21: =AY20 -> 0 | AZ21: =AZ20 -> 0 | BA21: =BA20 -> 0
A22: 17:15~17:30 | J22: 17:15~17:30 | S22: 17:15~17:30 | AB22: 17:15~17:30 | AK22: 17:15~17:30 | AT22: 17:15~17:30
A23: 開始時刻 | B23: 停車在臨近車道上的車輛總數 | F23: 臨近車道上的流量 | J23: 開始時刻 | K23: 停車在臨近車道上的車輛總數 | O23: 臨近車道上的流量 | S23: 開始時刻 | T23: 停車在臨近車道上的車輛總數 | X23: 臨近車道上的流量 | AB23: 開始時刻 | AC23: 停車在臨近車道上的車輛總數 | AG23: 臨近車道上的流量 | AK23: 開始時刻 | AL23: 停車在臨近車道上的車輛總數 | AP23: 臨近車道上的流量 | AT23: 開始時刻 | AU23: 停車在臨近車道上的車輛總數 | AY23: 臨近車道上的流量
A24: 17:15 | B24: 0秒 | C24: 15秒 | D24: 30秒 | E24: 45秒 | F24: 總數 | G24: 未受阻 | H24: 受阻 | J24: 17:15 | K24: 0秒 | L24: 15秒 | M24: 30秒 | N24: 45秒 | O24: 總數 | P24: 未受阻 | Q24: 受阻 | S24: 17:15 | T24: 0秒 | U24: 15秒 | V24: 30秒 | W24: 45秒 | X24: 總數 | Y24: 未受阻 | Z24: 受阻 | AB24: 17:15 | AC24: 0秒 | AD24: 15秒 | AE24: 30秒 | AF24: 45秒 | AG24: 總數 | AH24: 未受阻 | AI24: 受阻 | AK24: 17:15 | AL24: 0秒 | AM24: 15秒 | AN24: 30秒 | AO24: 45秒 | AP24: 總數 | AQ24: 未受阻 | AR24: 受阻 | AT24: 17:15 | AU24: 0秒 | AV24: 15秒 | AW24: 30秒 | AX24: 45秒 | AY24: 總數 | AZ24: 未受阻 | BA24: 受阻
A25: 16 | J25: 16 | S25: 16 | AB25: 16 | AK25: 16 | AT25: 16
A26: 17 | J26: 17 | S26: 17 | AB26: 17 | AK26: 17 | AT26: 17
A27: 18 | J27: 18 | S27: 18 | AB27: 18 | AK27: 18 | AT27: 18
A28: 19 | J28: 19 | S28: 19 | AB28: 19 | AK28: 19 | AT28: 19
A29: 20 | J29: 20 | S29: 20 | AB29: 20 | AK29: 20 | AT29: 20
A30: 21 | J30: 21 | S30: 21 | AB30: 21 | AK30: 21 | AT30: 21
A31: 22 | J31: 22 | S31: 22 | AB31: 22 | AK31: 22 | AT31: 22
A32: 23 | J32: 23 | S32: 23 | AB32: 23 | AK32: 23 | AT32: 23
A33: 24 | J33: 24 | S33: 24 | AB33: 24 | AK33: 24 | AT33: 24
A34: 25 | J34: 25 | S34: 25 | AB34: 25 | AK34: 25 | AT34: 25
A35: 26 | J35: 26 | S35: 26 | AB35: 26 | AK35: 26 | AT35: 26
A36: 27 | J36: 27 | S36: 27 | AB36: 27 | AK36: 27 | AT36: 27
... A39: 30 | J39: 30 | S39: 30 | AB39: 30 | AK39: 30 | AT39: 30
A40: 總 計 | B40: =SUM(B25:E39) -> 0 | F40: =F39 -> 0 | G40: =G39 -> 0 | H40: =H39 -> 0 | J40: 總 計 | K40: =SUM(K25:N39) -> 0 | O40: =O39 -> 0 | P40: =P39 -> 0 | Q40: =Q39 -> 0 | S40: 總 計 | T40: =SUM(T25:W39) -> 0 | X40: =X39 -> 0 | Y40: =Y39 -> 0 | Z40: =Z39 -> 0 | AB40: 總 計 | AC40: =SUM(AC25:AF39) -> 0 | AG40: =AG39 -> 0 | AH40: =AH39 -> 0 | AI40: =AI39 -> 0 | AK40: 總 計 | AL40: =SUM(AL25:AO39) -> 0 | AP40: =AP39 -> 0 | AQ40: =AQ39 -> 0 | AR40: =AR39 -> 0 | AT40: 總 計 | AU40: =SUM(AU25:AX39) -> 0 | AY40: =AY39 -> 0 | AZ40: =AZ39 -> 0 | BA40: =BA39 -> 0
A41: 17:30~17:45 | J41: 17:30~17:45 | S41: 17:30~17:45 | AB41: 17:30~17:45 | AK41: 17:30~17:45 | AT41: 17:30~17:45
A42: 開始時刻 | B42: 停車在臨近車道上的車輛總數 | F42: 臨近車道上的流量 | J42: 開始時刻 | K42: 停車在臨近車道上的車輛總數 | O42: 臨近車道上的流量 | S42: 開始時刻 | T42: 停車在臨近車道上的車輛總數 | X42: 臨近車道上的流量 | AB42: 開始時刻 | AC42: 停車在臨近車道上的車輛總數 | AG42: 臨近車道上的流量 | AK42: 開始時刻 | AL42: 停車在臨近車道上的車輛總數 | AP42: 臨近車道上的流量 | AT42: 開始時刻 | AU42: 停車在臨近車道上的車輛總數 | AY42: 臨近車道上的流量
A43: 17:30 | B43: 0秒 | C43: 15秒 | D43: 30秒 | E43: 45秒 | F43: 總數 | G43: 未受阻 | H43: 受阻 | J43: 17:30 | K43: 0秒 | L43: 15秒 | M43: 30秒 | N43: 45秒 | O43: 總數 | P43: 未受阻 | Q43: 受阻 | S43: 17:30 | T43: 0秒 | U43: 15秒 | V43: 30秒 | W43: 45秒 | X43: 總數 | Y43: 未受阻 | Z43: 受阻 | AB43: 17:30 | AC43: 0秒 | AD43: 15秒 | AE43: 30秒 | AF43: 45秒 | AG43: 總數 | AH43: 未受阻 | AI43: 受阻 | AK43: 17:30 | AL43: 0秒 | AM43: 15秒 | AN43: 30秒 | AO43: 45秒 | AP43: 總數 | AQ43: 未受阻 | AR43: 受阻 | AT43: 17:30 | AU43: 0秒 | AV43: 15秒 | AW43: 30秒 | AX43: 45秒 | AY43: 總數 | AZ43: 未受阻 | BA43: 受阻
A44: 31 | J44: 31 | S44: 31 | AB44: 31 | AK44: 31 | AT44: 31
...

Sheet 假日(11-12)
A1: =基本資料!$G$11 -> 假日(11-12) | J1: =基本資料!$G$11 -> 假日(11-12) | S1: =基本資料!$G$11 -> 假日(11-12) | AB1: =基本資料!$G$11 -> 假日(11-12) | AK1: =基本資料!$G$11 -> 假日(11-12) | AT1: =基本資料!$G$11 -> 假日(11-12)
A2: =CONCATENATE(基本資料!B18,"方向：",基本資料!B19,基本資料!B20) -> A方向： | J2: =CONCATENATE(基本資料!C18,"方向：",基本資料!C19,基本資料!C20) -> B方向： | S2: =CONCATENATE(基本資料!D18,"方向：",基本資料!D19,基本資料!D20) -> C方向： | AB2: =CONCATENATE(基本資料!E18,"方向：",基本資料!E19,基本資料!E20) -> D方向： | AK2: =CONCATENATE(基本資料!F18,"方向：",基本資料!F19,基本資料!F20) -> E方向： | AT2: =CONCATENATE(基本資料!G18,"方向：",基本資料!G19,基本資料!G20) -> F方向：
A3: 11:00~11:15 | J3: 11:00~11:15 | S3: 11:00~11:15 | AB3: 11:00~11:15 | AK3: 11:00~11:15 | AT3: 11:00~11:15
A4: 開始時刻 | B4: 停車在臨近車道上的車輛總數 | F4: 臨近車道上的流量 | J4: 開始時刻 | K4: 停車在臨近車道上的車輛總數 | O4: 臨近車道上的流量 | S4: 開始時刻 | T4: 停車在臨近車道上的車輛總數 | X4: 臨近車道上的流量 | AB4: 開始時刻 | AC4: 停車在臨近車道上的車輛總數 | AG4: 臨近車道上的流量 | AK4: 開始時刻 | AL4: 停車在臨近車道上的車輛總數 | AP4: 臨近車道上的流量 | AT4: 開始時刻 | AU4: 停車在臨近車道上的車輛總數 | AY4: 臨近車道上的流量
A5: 0.45833333 | B5: 0秒 | C5: 15秒 | D5: 30秒 | E5: 45秒 | F5: 總數 | G5: 未受阻 | H5: 受阻 | J5: 0.45833333 | K5: 0秒 | L5: 15秒 | M5: 30秒 | N5: 45秒 | O5: 總數 | P5: 未受阻 | Q5: 受阻 | S5: 0.45833333 | T5: 0秒 | U5: 15秒 | V5: 30秒 | W5: 45秒 | X5: 總數 | Y5: 未受阻 | Z5: 受阻 | AB5: 0.45833333 | AC5: 0秒 | AD5: 15秒 | AE5: 30秒 | AF5: 45秒 | AG5: 總數 | AH5: 未受阻 | AI5: 受阻 | AK5: 0.45833333 | AL5: 0秒 | AM5: 15秒 | AN5: 30秒 | AO5: 45秒 | AP5: 總數 | AQ5: 未受阻 | AR5: 受阻 | AT5: 0.45833333 | AU5: 0秒 | AV5: 15秒 | AW5: 30秒 | AX5: 45秒 | AY5: 總數 | AZ5: 未受阻 | BA5: 受阻
A6: 1 | J6: 1 | S6: 1 | AB6: 1 | AK6: 1 | AT6: 1
A7: 2 | J7: 2 | S7: 2 | AB7: 2 | AK7: 2 | AT7: 2
A8: 3 | J8: 3 | S8: 3 | AB8: 3 | AK8: 3 | AT8: 3
A9: 4 | J9: 4 | S9: 4 | AB9: 4 | AK9: 4 | AT9: 4
A10: 5 | J10: 5 | S10: 5 | AB10: 5 | AK10: 5 | AT10: 5
A11: 6 | J11: 6 | S11: 6 | AB11: 6 | AK11: 6 | AT11: 6
A12: 7 | J12: 7 | S12: 7 | AB12: 7 | AK12: 7 | AT12: 7
A13: 8 | J13: 8 | S13: 8 | AB13: 8 | AK13: 8 | AT13: 8
A14: 9 | J14: 9 | S14: 9 | AB14: 9 | AK14: 9 | AT14: 9
A15: 10 | J15: 10 | S15: 10 | AB15: 10 | AK15: 10 | AT15: 10
A16: 11 | J16: 11 | S16: 11 | AB16: 11 | AK16: 11 | AT16: 11
A17: 12 | J17: 12 | S17: 12 | AB17: 12 | AK17: 12 | AT17: 12
... A20: 15 | J20: 15 | S20: 15 | AB20: 15 | AK20: 15 | AT20: 15
A21: 總 計 | B21: =SUM(B6:E20) -> 0 | F21: =F20 -> 0 | G21: =G20 -> 0 | H21: =H20 -> 0 | J21: 總 計 | K21: =SUM(K6:N20) -> 0 | O21: =O20 -> 0 | P21: =P20 -> 0 | Q21: =Q20 -> 0 | S21: 總 計 | T21: =SUM(T6:W20) -> 0 | X21: =X20 -> 0 | Y21: =Y20 -> 0 | Z21: =Z20 -> 0 | AB21: 總 計 | AC21: =SUM(AC6:AF20) -> 0 | AG21: =AG20 -> 0 | AH21: =AH20 -> 0 | AI21: =AI20 -> 0 | AK21: 總 計 | AL21: =SUM(AL6:AO20) -> 0 | AP21: =AP20 -> 0 | AQ21: =AQ20 -> 0 | AR21: =AR20 -> 0 | AT21: 總 計 | AU21: =SUM(AU6:AX20) -> 0 | AY21: =AY20 -> 0 | AZ21: =AZ20 -> 0 | BA21: =BA20 -> 0
A22: 11:15~11:30 | J22: 11:15~11:30 | S22: 11:15~11:30 | AB22: 11:15~11:30 | AK22: 11:15~11:30 | AT22: 11:15~11:30
A23: 開始時刻 | B23: 停車在臨近車道上的車輛總數 | F23: 臨近車道上的流量 | J23: 開始時刻 | K23: 停車在臨近車道上的車輛總數 | O23: 臨近車道上的流量 | S23: 開始時刻 | T23: 停車在臨近車道上的車輛總數 | X23: 臨近車道上的流量 | AB23: 開始時刻 | AC23: 停車在臨近車道上的車輛總數 | AG23: 臨近車道上的流量 | AK23: 開始時刻 | AL23: 停車在臨近車道上的車輛總數 | AP23: 臨近車道上的流量 | AT23: 開始時刻 | AU23: 停車在臨近車道上的車輛總數 | AY23: 臨近車道上的流量
A24: 0.46875 | B24: 0秒 | C24: 15秒 | D24: 30秒 | E24: 45秒 | F24: 總數 | G24: 未受阻 | H24: 受阻 | J24: 0.46875 | K24: 0秒 | L24: 15秒 | M24: 30秒 | N24: 45秒 | O24: 總數 | P24: 未受阻 | Q24: 受阻 | S24: 0.46875 | T24: 0秒 | U24: 15秒 | V24: 30秒 | W24: 45秒 | X24: 總數 | Y24: 未受阻 | Z24: 受阻 | AB24: 0.46875 | AC24: 0秒 | AD24: 15秒 | AE24: 30秒 | AF24: 45秒 | AG24: 總數 | AH24: 未受阻 | AI24: 受阻 | AK24: 0.46875 | AL24: 0秒 | AM24: 15秒 | AN24: 30秒 | AO24: 45秒 | AP24: 總數 | AQ24: 未受阻 | AR24: 受阻 | AT24: 0.46875 | AU24: 0秒 | AV24: 15秒 | AW24: 30秒 | AX24: 45秒 | AY24: 總數 | AZ24: 未受阻 | BA24: 受阻
A25: 16 | J25: 16 | S25: 16 | AB25: 16 | AK25: 16 | AT25: 16
A26: 17 | J26: 17 | S26: 17 | AB26: 17 | AK26: 17 | AT26: 17
A27: 18 | J27: 18 | S27: 18 | AB27: 18 | AK27: 18 | AT27: 18
A28: 19 | J28: 19 | S28: 19 | AB28: 19 | AK28: 19 | AT28: 19
A29: 20 | J29: 20 | S29: 20 | AB29: 20 | AK29: 20 | AT29: 20
A30: 21 | J30: 21 | S30: 21 | AB30: 21 | AK30: 21 | AT30: 21
A31: 22 | J31: 22 | S31: 22 | AB31: 22 | AK31: 22 | AT31: 22
A32: 23 | J32: 23 | S32: 23 | AB32: 23 | AK32: 23 | AT32: 23
A33: 24 | J33: 24 | S33: 24 | AB33: 24 | AK33: 24 | AT33: 24
A34: 25 | J34: 25 | S34: 25 | AB34: 25 | AK34: 25 | AT34: 25
A35: 26 | J35: 26 | S35: 26 | AB35: 26 | AK35: 26 | AT35: 26
A36: 27 | J36: 27 | S36: 27 | AB36: 27 | AK36: 27 | AT36: 27
... A39: 30 | J39: 30 | S39: 30 | AB39: 30 | AK39: 30 | AT39: 30
A40: 總 計 | B40: =SUM(B25:E39) -> 0 | F40: =F39 -> 0 | G40: =G39 -> 0 | H40: =H39 -> 0 | J40: 總 計 | K40: =SUM(K25:N39) -> 0 | O40: =O39 -> 0 | P40: =P39 -> 0 | Q40: =Q39 -> 0 | S40: 總 計 | T40: =SUM(T25:W39) -> 0 | X40: =X39 -> 0 | Y40: =Y39 -> 0 | Z40: =Z39 -> 0 | AB40: 總 計 | AC40: =SUM(AC25:AF39) -> 0 | AG40: =AG39 -> 0 | AH40: =AH39 -> 0 | AI40: =AI39 -> 0 | AK40: 總 計 | AL40: =SUM(AL25:AO39) -> 0 | AP40: =AP39 -> 0 | AQ40: =AQ39 -> 0 | AR40: =AR39 -> 0 | AT40: 總 計 | AU40: =SUM(AU25:AX39) -> 0 | AY40: =AY39 -> 0 | AZ40: =AZ39 -> 0 | BA40: =BA39 -> 0
A41: 11:30~11:45 | J41: 11:30~11:45 | S41: 11:30~11:45 | AB41: 11:30~11:45 | AK41: 11:30~11:45 | AT41: 11:30~11:45
A42: 開始時刻 | B42: 停車在臨近車道上的車輛總數 | F42: 臨近車道上的流量 | J42: 開始時刻 | K42: 停車在臨近車道上的車輛總數 | O42: 臨近車道上的流量 | S42: 開始時刻 | T42: 停車在臨近車道上的車輛總數 | X42: 臨近車道上的流量 | AB42: 開始時刻 | AC42: 停車在臨近車道上的車輛總數 | AG42: 臨近車道上的流量 | AK42: 開始時刻 | AL42: 停車在臨近車道上的車輛總數 | AP42: 臨近車道上的流量 | AT42: 開始時刻 | AU42: 停車在臨近車道上的車輛總數 | AY42: 臨近車道上的流量
A43: 0.47916667 | B43: 0秒 | C43: 15秒 | D43: 30秒 | E43: 45秒 | F43: 總數 | G43: 未受阻 | H43: 受阻 | J43: 0.47916667 | K43: 0秒 | L43: 15秒 | M43: 30秒 | N43: 45秒 | O43: 總數 | P43: 未受阻 | Q43: 受阻 | S43: 0.47916667 | T43: 0秒 | U43: 15秒 | V43: 30秒 | W43: 45秒 | X43: 總數 | Y43: 未受阻 | Z43: 受阻 | AB43: 0.47916667 | AC43: 0秒 | AD43: 15秒 | AE43: 30秒 | AF43: 45秒 | AG43: 總數 | AH43: 未受阻 | AI43: 受阻 | AK43: 0.47916667 | AL43: 0秒 | AM43: 15秒 | AN43: 30秒 | AO43: 45秒 | AP43: 總數 | AQ43: 未受阻 | AR43: 受阻 | AT43: 0.47916667 | AU43: 0秒 | AV43: 15秒 | AW43: 30秒 | AX43: 45秒 | AY43: 總數 | AZ43: 未受阻 | BA43: 受阻
A44: 31 | J44: 31 | S44: 31 | AB44: 31 | AK44: 31 | AT44: 31
...

Sheet 假日(1430-1530)
A1: =基本資料!$H$11 -> 假日(1430-1530) | J1: =基本資料!$H$11 -> 假日(1430-1530) | S1: =基本資料!$H$11 -> 假日(1430-1530) | AB1: =基本資料!$H$11 -> 假日(1430-1530) | AK1: =基本資料!$H$11 -> 假日(1430-1530) | AT1: =基本資料!$H$11 -> 假日(1430-1530)
A2: =CONCATENATE(基本資料!B18,"方向：",基本資料!B19,基本資料!B20) -> A方向： | J2: =CONCATENATE(基本資料!C18,"方向：",基本資料!C19,基本資料!C20) -> B方向： | S2: =CONCATENATE(基本資料!D18,"方向：",基本資料!D19,基本資料!D20) -> C方向： | AB2: =CONCATENATE(基本資料!E18,"方向：",基本資料!E19,基本資料!E20) -> D方向： | AK2: =CONCATENATE(基本資料!F18,"方向：",基本資料!F19,基本資料!F20) -> E方向： | AT2: =CONCATENATE(基本資料!G18,"方向：",基本資料!G19,基本資料!G20) -> F方向：
A3: 14:30~14:45 | J3: 14:30~14:45 | S3: 14:30~14:45 | AB3: 14:30~14:45 | AK3: 14:30~14:45 | AT3: 14:30~14:45
A4: 開始時刻 | B4: 停車在臨近車道上的車輛總數 | F4: 臨近車道上的流量 | J4: 開始時刻 | K4: 停車在臨近車道上的車輛總數 | O4: 臨近車道上的流量 | S4: 開始時刻 | T4: 停車在臨近車道上的車輛總數 | X4: 臨近車道上的流量 | AB4: 開始時刻 | AC4: 停車在臨近車道上的車輛總數 | AG4: 臨近車道上的流量 | AK4: 開始時刻 | AL4: 停車在臨近車道上的車輛總數 | AP4: 臨近車道上的流量 | AT4: 開始時刻 | AU4: 停車在臨近車道上的車輛總數 | AY4: 臨近車道上的流量
A5: 0.60416667 | B5: 0秒 | C5: 15秒 | D5: 30秒 | E5: 45秒 | F5: 總數 | G5: 未受阻 | H5: 受阻 | J5: 0.60416667 | K5: 0秒 | L5: 15秒 | M5: 30秒 | N5: 45秒 | O5: 總數 | P5: 未受阻 | Q5: 受阻 | S5: 0.60416667 | T5: 0秒 | U5: 15秒 | V5: 30秒 | W5: 45秒 | X5: 總數 | Y5: 未受阻 | Z5: 受阻 | AB5: 0.60416667 | AC5: 0秒 | AD5: 15秒 | AE5: 30秒 | AF5: 45秒 | AG5: 總數 | AH5: 未受阻 | AI5: 受阻 | AK5: 0.60416667 | AL5: 0秒 | AM5: 15秒 | AN5: 30秒 | AO5: 45秒 | AP5: 總數 | AQ5: 未受阻 | AR5: 受阻 | AT5: 0.60416667 | AU5: 0秒 | AV5: 15秒 | AW5: 30秒 | AX5: 45秒 | AY5: 總數 | AZ5: 未受阻 | BA5: 受阻
A6: 31 | J6: 31 | S6: 31 | AB6: 31 | AK6: 31 | AT6: 31
A7: 32 | J7: 32 | S7: 32 | AB7: 32 | AK7: 32 | AT7: 32
A8: 33 | J8: 33 | S8: 33 | AB8: 33 | AK8: 33 | AT8: 33
A9: 34 | J9: 34 | S9: 34 | AB9: 34 | AK9: 34 | AT9: 34
A10: 35 | J10: 35 | S10: 35 | AB10: 35 | AK10: 35 | AT10: 35
A11: 36 | J11: 36 | S11: 36 | AB11: 36 | AK11: 36 | AT11: 36
A12: 37 | J12: 37 | S12: 37 | AB12: 37 | AK12: 37 | AT12: 37
A13: 38 | J13: 38 | S13: 38 | AB13: 38 | AK13: 38 | AT13: 38
A14: 39 | J14: 39 | S14: 39 | AB14: 39 | AK14: 39 | AT14: 39
A15: 40 | J15: 40 | S15: 40 | AB15: 40 | AK15: 40 | AT15: 40
A16: 41 | J16: 41 | S16: 41 | AB16: 41 | AK16: 41 | AT16: 41
A17: 42 | J17: 42 | S17: 42 | AB17: 42 | AK17: 42 | AT17: 42
... A20: 45 | J20: 45 | S20: 45 | AB20: 45 | AK20: 45 | AT20: 45
A21: 總 計 | B21: =SUM(B6:E20) -> 0 | F21: =F20 -> 0 | G21: =G20 -> 0 | H21: =H20 -> 0 | J21: 總 計 | K21: =SUM(K6:N20) -> 0 | O21: =O20 -> 0 | P21: =P20 -> 0 | Q21: =Q20 -> 0 | S21: 總 計 | T21: =SUM(T6:W20) -> 0 | X21: =X20 -> 0 | Y21: =Y20 -> 0 | Z21: =Z20 -> 0 | AB21: 總 計 | AC21: =SUM(AC6:AF20) -> 0 | AG21: =AG20 -> 0 | AH21: =AH20 -> 0 | AI21: =AI20 -> 0 | AK21: 總 計 | AL21: =SUM(AL6:AO20) -> 0 | AP21: =AP20 -> 0 | AQ21: =AQ20 -> 0 | AR21: =AR20 -> 0 | AT21: 總 計 | AU21: =SUM(AU6:AX20) -> 0 | AY21: =AY20 -> 0 | AZ21: =AZ20 -> 0 | BA21: =BA20 -> 0
A22: 14:45~15:00 | J22: 14:45~15:00 | S22: 14:45~15:00 | AB22: 14:45~15:00 | AK22: 14:45~15:00 | AT22: 14:45~15:00
A23: 開始時刻 | B23: 停車在臨近車道上的車輛總數 | F23: 臨近車道上的流量 | J23: 開始時刻 | K23: 停車在臨近車道上的車輛總數 | O23: 臨近車道上的流量 | S23: 開始時刻 | T23: 停車在臨近車道上的車輛總數 | X23: 臨近車道上的流量 | AB23: 開始時刻 | AC23: 停車在臨近車道上的車輛總數 | AG23: 臨近車道上的流量 | AK23: 開始時刻 | AL23: 停車在臨近車道上的車輛總數 | AP23: 臨近車道上的流量 | AT23: 開始時刻 | AU23: 停車在臨近車道上的車輛總數 | AY23: 臨近車道上的流量
A24: 0.61458333 | B24: 0秒 | C24: 15秒 | D24: 30秒 | E24: 45秒 | F24: 總數 | G24: 未受阻 | H24: 受阻 | J24: 0.61458333 | K24: 0秒 | L24: 15秒 | M24: 30秒 | N24: 45秒 | O24: 總數 | P24: 未受阻 | Q24: 受阻 | S24: 0.61458333 | T24: 0秒 | U24: 15秒 | V24: 30秒 | W24: 45秒 | X24: 總數 | Y24: 未受阻 | Z24: 受阻 | AB24: 0.61458333 | AC24: 0秒 | AD24: 15秒 | AE24: 30秒 | AF24: 45秒 | AG24: 總數 | AH24: 未受阻 | AI24: 受阻 | AK24: 0.61458333 | AL24: 0秒 | AM24: 15秒 | AN24: 30秒 | AO24: 45秒 | AP24: 總數 | AQ24: 未受阻 | AR24: 受阻 | AT24: 0.61458333 | AU24: 0秒 | AV24: 15秒 | AW24: 30秒 | AX24: 45秒 | AY24: 總數 | AZ24: 未受阻 | BA24: 受阻
A25: 46 | J25: 46 | S25: 46 | AB25: 46 | AK25: 46 | AT25: 46
A26: 47 | J26: 47 | S26: 47 | AB26: 47 | AK26: 47 | AT26: 47
A27: 48 | J27: 48 | S27: 48 | AB27: 48 | AK27: 48 | AT27: 48
A28: 49 | J28: 49 | S28: 49 | AB28: 49 | AK28: 49 | AT28: 49
A29: 50 | J29: 50 | S29: 50 | AB29: 50 | AK29: 50 | AT29: 50
A30: 51 | J30: 51 | S30: 51 | AB30: 51 | AK30: 51 | AT30: 51
A31: 52 | J31: 52 | S31: 52 | AB31: 52 | AK31: 52 | AT31: 52
A32: 53 | J32: 53 | S32: 53 | AB32: 53 | AK32: 53 | AT32: 53
A33: 54 | J33: 54 | S33: 54 | AB33: 54 | AK33: 54 | AT33: 54
A34: 55 | J34: 55 | S34: 55 | AB34: 55 | AK34: 55 | AT34: 55
A35: 56 | J35: 56 | S35: 56 | AB35: 56 | AK35: 56 | AT35: 56
A36: 57 | J36: 57 | S36: 57 | AB36: 57 | AK36: 57 | AT36: 57
... A39: 60 | J39: 60 | S39: 60 | AB39: 60 | AK39: 60 | AT39: 60
A40: 總 計 | B40: =SUM(B25:E39) -> 0 | F40: =F39 -> 0 | G40: =G39 -> 0 | H40: =H39 -> 0 | J40: 總 計 | K40: =SUM(K25:N39) -> 0 | O40: =O39 -> 0 | P40: =P39 -> 0 | Q40: =Q39 -> 0 | S40: 總 計 | T40: =SUM(T25:W39) -> 0 | X40: =X39 -> 0 | Y40: =Y39 -> 0 | Z40: =Z39 -> 0 | AB40: 總 計 | AC40: =SUM(AC25:AF39) -> 0 | AG40: =AG39 -> 0 | AH40: =AH39 -> 0 | AI40: =AI39 -> 0 | AK40: 總 計 | AL40: =SUM(AL25:AO39) -> 0 | AP40: =AP39 -> 0 | AQ40: =AQ39 -> 0 | AR40: =AR39 -> 0 | AT40: 總 計 | AU40: =SUM(AU25:AX39) -> 0 | AY40: =AY39 -> 0 | AZ40: =AZ39 -> 0 | BA40: =BA39 -> 0
A41: 15:00~15:15 | J41: 15:00~15:15 | S41: 15:00~15:15 | AB41: 15:00~15:15 | AK41: 15:00~15:15 | AT41: 15:00~15:15
A42: 開始時刻 | B42: 停車在臨近車道上的車輛總數 | F42: 臨近車道上的流量 | J42: 開始時刻 | K42: 停車在臨近車道上的車輛總數 | O42: 臨近車道上的流量 | S42: 開始時刻 | T42: 停車在臨近車道上的車輛總數 | X42: 臨近車道上的流量 | AB42: 開始時刻 | AC42: 停車在臨近車道上的車輛總數 | AG42: 臨近車道上的流量 | AK42: 開始時刻 | AL42: 停車在臨近車道上的車輛總數 | AP42: 臨近車道上的流量 | AT42: 開始時刻 | AU42: 停車在臨近車道上的車輛總數 | AY42: 臨近車道上的流量
A43: 0.625 | B43: 0秒 | C43: 15秒 | D43: 30秒 | E43: 45秒 | F43: 總數 | G43: 未受阻 | H43: 受阻 | J43: 0.625 | K43: 0秒 | L43: 15秒 | M43: 30秒 | N43: 45秒 | O43: 總數 | P43: 未受阻 | Q43: 受阻 | S43: 0.625 | T43: 0秒 | U43: 15秒 | V43: 30秒 | W43: 45秒 | X43: 總數 | Y43: 未受阻 | Z43: 受阻 | AB43: 0.625 | AC43: 0秒 | AD43: 15秒 | AE43: 30秒 | AF43: 45秒 | AG43: 總數 | AH43: 未受阻 | AI43: 受阻 | AK43: 0.625 | AL43: 0秒 | AM43: 15秒 | AN43: 30秒 | AO43: 45秒 | AP43: 總數 | AQ43: 未受阻 | AR43: 受阻 | AT43: 0.625 | AU43: 0秒 | AV43: 15秒 | AW43: 30秒 | AX43: 45秒 | AY43: 總數 | AZ43: 未受阻 | BA43: 受阻
A44: 1 | J44: 1 | S44: 1 | AB44: 1 | AK44: 1 | AT44: 1
...

Sheet 假日(1730-1830)
A1: =基本資料!$I$11 -> 假日(1730-1830) | J1: =基本資料!$I$11 -> 假日(1730-1830) | S1: =基本資料!$I$11 -> 假日(1730-1830) | AB1: =基本資料!$I$11 -> 假日(1730-1830) | AK1: =基本資料!$I$11 -> 假日(1730-1830) | AT1: =基本資料!$I$11 -> 假日(1730-1830)
A2: =CONCATENATE(基本資料!B18,"方向：",基本資料!B19,基本資料!B20) -> A方向： | J2: =CONCATENATE(基本資料!C18,"方向：",基本資料!C19,基本資料!C20) -> B方向： | S2: =CONCATENATE(基本資料!D18,"方向：",基本資料!D19,基本資料!D20) -> C方向： | AB2: =CONCATENATE(基本資料!E18,"方向：",基本資料!E19,基本資料!E20) -> D方向： | AK2: =CONCATENATE(基本資料!F18,"方向：",基本資料!F19,基本資料!F20) -> E方向： | AT2: =CONCATENATE(基本資料!G18,"方向：",基本資料!G19,基本資料!G20) -> F方向：
A3: 17:30~17:45 | J3: 17:30~17:45 | S3: 17:30~17:45 | AB3: 17:30~17:45 | AK3: 17:30~17:45 | AT3: 17:30~17:45
A4: 開始時刻 | B4: 停車在臨近車道上的車輛總數 | F4: 臨近車道上的流量 | J4: 開始時刻 | K4: 停車在臨近車道上的車輛總數 | O4: 臨近車道上的流量 | S4: 開始時刻 | T4: 停車在臨近車道上的車輛總數 | X4: 臨近車道上的流量 | AB4: 開始時刻 | AC4: 停車在臨近車道上的車輛總數 | AG4: 臨近車道上的流量 | AK4: 開始時刻 | AL4: 停車在臨近車道上的車輛總數 | AP4: 臨近車道上的流量 | AT4: 開始時刻 | AU4: 停車在臨近車道上的車輛總數 | AY4: 臨近車道上的流量
A5: 0.72916667 | B5: 0秒 | C5: 15秒 | D5: 30秒 | E5: 45秒 | F5: 總數 | G5: 未受阻 | H5: 受阻 | J5: 0.72916667 | K5: 0秒 | L5: 15秒 | M5: 30秒 | N5: 45秒 | O5: 總數 | P5: 未受阻 | Q5: 受阻 | S5: 0.72916667 | T5: 0秒 | U5: 15秒 | V5: 30秒 | W5: 45秒 | X5: 總數 | Y5: 未受阻 | Z5: 受阻 | AB5: 0.72916667 | AC5: 0秒 | AD5: 15秒 | AE5: 30秒 | AF5: 45秒 | AG5: 總數 | AH5: 未受阻 | AI5: 受阻 | AK5: 0.72916667 | AL5: 0秒 | AM5: 15秒 | AN5: 30秒 | AO5: 45秒 | AP5: 總數 | AQ5: 未受阻 | AR5: 受阻 | AT5: 0.72916667 | AU5: 0秒 | AV5: 15秒 | AW5: 30秒 | AX5: 45秒 | AY5: 總數 | AZ5: 未受阻 | BA5: 受阻
A6: 31 | J6: 31 | S6: 31 | AB6: 31 | AK6: 31 | AT6: 31
A7: 32 | J7: 32 | S7: 32 | AB7: 32 | AK7: 32 | AT7: 32
A8: 33 | J8: 33 | S8: 33 | AB8: 33 | AK8: 33 | AT8: 33
A9: 34 | J9: 34 | S9: 34 | AB9: 34 | AK9: 34 | AT9: 34
A10: 35 | J10: 35 | S10: 35 | AB10: 35 | AK10: 35 | AT10: 35
A11: 36 | J11: 36 | S11: 36 | AB11: 36 | AK11: 36 | AT11: 36
A12: 37 | J12: 37 | S12: 37 | AB12: 37 | AK12: 37 | AT12: 37
A13: 38 | J13: 38 | S13: 38 | AB13: 38 | AK13: 38 | AT13: 38
A14: 39 | J14: 39 | S14: 39 | AB14: 39 | AK14: 39 | AT14: 39
A15: 40 | J15: 40 | S15: 40 | AB15: 40 | AK15: 40 | AT15: 40
A16: 41 | J16: 41 | S16: 41 | AB16: 41 | AK16: 41 | AT16: 41
A17: 42 | J17: 42 | S17: 42 | AB17: 42 | AK17: 42 | AT17: 42
... A20: 45 | J20: 45 | S20: 45 | AB20: 45 | AK20: 45 | AT20: 45
A21: 總 計 | B21: =SUM(B6:E20) -> 0 | F21: =F20 -> 0 | G21: =G20 -> 0 | H21: =H20 -> 0 | J21: 總 計 | K21: =SUM(K6:N20) -> 0 | O21: =O20 -> 0 | P21: =P20 -> 0 | Q21: =Q20 -> 0 | S21: 總 計 | T21: =SUM(T6:W20) -> 0 | X21: =X20 -> 0 | Y21: =Y20 -> 0 | Z21: =Z20 -> 0 | AB21: 總 計 | AC21: =SUM(AC6:AF20) -> 0 | AG21: =AG20 -> 0 | AH21: =AH20 -> 0 | AI21: =AI20 -> 0 | AK21: 總 計 | AL21: =SUM(AL6:AO20) -> 0 | AP21: =AP20 -> 0 | AQ21: =AQ20 -> 0 | AR21: =AR20 -> 0 | AT21: 總 計 | AU21: =SUM(AU6:AX20) -> 0 | AY21: =AY20 -> 0 | AZ21: =AZ20 -> 0 | BA21: =BA20 -> 0
A22: 17:45~18:00 | J22: 17:45~18:00 | S22: 17:45~18:00 | AB22: 17:45~18:00 | AK22: 17:45~18:00 | AT22: 17:45~18:00
A23: 開始時刻 | B23: 停車在臨近車道上的車輛總數 | F23: 臨近車道上的流量 | J23: 開始時刻 | K23: 停車在臨近車道上的車輛總數 | O23: 臨近車道上的流量 | S23: 開始時刻 | T23: 停車在臨近車道上的車輛總數 | X23: 臨近車道上的流量 | AB23: 開始時刻 | AC23: 停車在臨近車道上的車輛總數 | AG23: 臨近車道上的流量 | AK23: 開始時刻 | AL23: 停車在臨近車道上的車輛總數 | AP23: 臨近車道上的流量 | AT23: 開始時刻 | AU23: 停車在臨近車道上的車輛總數 | AY23: 臨近車道上的流量
A24: 0.73958333 | B24: 0秒 | C24: 15秒 | D24: 30秒 | E24: 45秒 | F24: 總數 | G24: 未受阻 | H24: 受阻 | J24: 0.73958333 | K24: 0秒 | L24: 15秒 | M24: 30秒 | N24: 45秒 | O24: 總數 | P24: 未受阻 | Q24: 受阻 | S24: 0.73958333 | T24: 0秒 | U24: 15秒 | V24: 30秒 | W24: 45秒 | X24: 總數 | Y24: 未受阻 | Z24: 受阻 | AB24: 0.73958333 | AC24: 0秒 | AD24: 15秒 | AE24: 30秒 | AF24: 45秒 | AG24: 總數 | AH24: 未受阻 | AI24: 受阻 | AK24: 0.73958333 | AL24: 0秒 | AM24: 15秒 | AN24: 30秒 | AO24: 45秒 | AP24: 總數 | AQ24: 未受阻 | AR24: 受阻 | AT24: 0.73958333 | AU24: 0秒 | AV24: 15秒 | AW24: 30秒 | AX24: 45秒 | AY24: 總數 | AZ24: 未受阻 | BA24: 受阻
A25: 46 | J25: 46 | S25: 46 | AB25: 46 | AK25: 46 | AT25: 46
A26: 47 | J26: 47 | S26: 47 | AB26: 47 | AK26: 47 | AT26: 47
A27: 48 | J27: 48 | S27: 48 | AB27: 48 | AK27: 48 | AT27: 48
A28: 49 | J28: 49 | S28: 49 | AB28: 49 | AK28: 49 | AT28: 49
A29: 50 | J29: 50 | S29: 50 | AB29: 50 | AK29: 50 | AT29: 50
A30: 51 | J30: 51 | S30: 51 | AB30: 51 | AK30: 51 | AT30: 51
A31: 52 | J31: 52 | S31: 52 | AB31: 52 | AK31: 52 | AT31: 52
A32: 53 | J32: 53 | S32: 53 | AB32: 53 | AK32: 53 | AT32: 53
A33: 54 | J33: 54 | S33: 54 | AB33: 54 | AK33: 54 | AT33: 54
A34: 55 | J34: 55 | S34: 55 | AB34: 55 | AK34: 55 | AT34: 55
A35: 56 | J35: 56 | S35: 56 | AB35: 56 | AK35: 56 | AT35: 56
