Workbook
Name _PCU11: [1]基本!$B$35
Name _PCU12: [1]基本!$C$35
Name _PCU13: [1]基本!$D$35
Name _PCU14: [1]基本!$E$35
Name _PCU21: [1]基本!$F$35
Name _PCU22: [1]基本!$G$35
Name _PCU23: [1]基本!$H$35
Name _PCU31: [1]基本!$I$35
Name _PCU32: [1]基本!$J$35
Name _PCU33: [1]基本!$K$35
Name GAM: #REF!
Name GINFO: #REF!
Name GPM: #REF!
Name GRAPH: #REF!
Name HN: [1]集賢!$M$1
Name ROADNAME: [2]基本!$I$5,[2]基本!$G$9,[2]基本!$E$5,[2]基本!$G$1
Name TABLE: #REF!
Name 尖峰: #REF!
Name 夜間: #REF!
Name 時制A: #REF!,#REF!,#REF!,#REF!,#REF!
Name 時制B: #REF!,#REF!,#REF!,#REF!,#REF!
Name 假日: #REF!
Name 週五夜: #REF!
Name 離峰: #REF!

Sheet 轉向量
A1: 臨近路段 | B1: 起始時間 | C1: 結束時間 | D1: 大車A | E1: 大車B | F1: 大車C | G1: 大車D | H1: 大車E | I1: 小車A | J1: 小車B | K1: 小車C | L1: 小車D | M1: 小車E | N1: 機車A | O1: 機車B | P1: 機車C | Q1: 機車D | R1: 機車E
A2: A | B2: 0 | C2: 0.010416667 | D2: - | I2: - | N2: -
A3: A | B3: 0.010416667 | C3: 0.020833333 | D3: - | I3: - | N3: -
A4: A | B4: 0.020833333 | C4: 0.03125 | D4: - | I4: - | N4: -
A5: A | B5: 0.03125 | C5: 0.041666667 | D5: - | I5: - | N5: -
A6: A | B6: 0.041666667 | C6: 0.052083333 | D6: - | I6: - | N6: -
A7: A | B7: 0.052083333 | C7: 0.0625 | D7: - | I7: - | N7: -
A8: A | B8: 0.0625 | C8: 0.072916667 | D8: - | I8: - | N8: -
A9: A | B9: 0.072916667 | C9: 0.083333333 | D9: - | I9: - | N9: -
A10: A | B10: 0.083333333 | C10: 0.09375 | D10: - | I10: - | N10: -
A11: A | B11: 0.09375 | C11: 0.10416667 | D11: - | I11: - | N11: -
A12: A | B12: 0.10416667 | C12: 0.11458333 | D12: - | I12: - | N12: -
A13: A | B13: 0.11458333 | C13: 0.125 | D13: - | I13: - | N13: -
... A96: A | B96: 0.97916667 | C96: 0.98958333 | D96: - | I96: - | N96: -
A97: A | B97: 0.98958333 | C97: 24:00 | D97: - | I97: - | N97: -
A98: B | B98: 0 | C98: 0.010416667 | E98: - | J98: - | O98: -
A99: B | B99: 0.010416667 | C99: 0.020833333 | E99: - | J99: - | O99: -
A100: B | B100: 0.020833333 | C100: 0.03125 | E100: - | J100: - | O100: -
A101: B | B101: 0.03125 | C101: 0.041666667 | E101: - | J101: - | O101: -
A102: B | B102: 0.041666667 | C102: 0.052083333 | E102: - | J102: - | O102: -
A103: B | B103: 0.052083333 | C103: 0.0625 | E103: - | J103: - | O103: -
A104: B | B104: 0.0625 | C104: 0.072916667 | E104: - | J104: - | O104: -
A105: B | B105: 0.072916667 | C105: 0.083333333 | E105: - | J105: - | O105: -
A106: B | B106: 0.083333333 | C106: 0.09375 | E106: - | J106: - | O106: -
A107: B | B107: 0.09375 | C107: 0.10416667 | E107: - | J107: - | O107: -
A108: B | B108: 0.10416667 | C108: 0.11458333 | E108: - | J108: - | O108: -
A109: B | B109: 0.11458333 | C109: 0.125 | E109: - | J109: - | O109: -
... A192: B | B192: 0.97916667 | C192: 0.98958333 | E192: - | J192: - | O192: -
A193: B | B193: 0.98958333 | C193: 24:00 | E193: - | J193: - | O193: -
A194: C | B194: 0 | C194: 0.010416667 | F194: - | K194: - | P194: -
A195: C | B195: 0.010416667 | C195: 0.020833333 | F195: - | K195: - | P195: -
A196: C | B196: 0.020833333 | C196: 0.03125 | F196: - | K196: - | P196: -
A197: C | B197: 0.03125 | C197: 0.041666667 | F197: - | K197: - | P197: -
A198: C | B198: 0.041666667 | C198: 0.052083333 | F198: - | K198: - | P198: -
A199: C | B199: 0.052083333 | C199: 0.0625 | F199: - | K199: - | P199: -
A200: C | B200: 0.0625 | C200: 0.072916667 | F200: - | K200: - | P200: -
A201: C | B201: 0.072916667 | C201: 0.083333333 | F201: - | K201: - | P201: -
A202: C | B202: 0.083333333 | C202: 0.09375 | F202: - | K202: - | P202: -
A203: C | B203: 0.09375 | C203: 0.10416667 | F203: - | K203: - | P203: -
A204: C | B204: 0.10416667 | C204: 0.11458333 | F204: - | K204: - | P204: -
...

Sheet 路口基本資料
A1: 業主名稱： | G1: 簡圖： | I1: =E15 -> 0 | J1: =F15 -> 0 | L1: N
A2: 專案編號： | I2: D | J2: E | L2: ↑
A4: TC編號：
A5: 路口名稱： | G5: =D15 -> 0 | H5: C | K5: A | L5: =B15 -> 0
A6: 行政區域：
A8: 日期： | B8: YYYY/MM/DD | I8: B
A9: 平假日： | I9: =C15 -> 0 | J9: =C15 -> 0
A10: 調查時段：
A11: 天候：
A13: 路口類型： | B13: 五叉路口
A14: 方向： | B14: A | C14: B | D14: C | E14: D | F14: E
A15: 路段名：
A16: 車道數：
A17: 行車方向： | B17: 往西 | C17: 往北 | D17: 往東 | E17: 往南 | F17: 往南
A18: 往A方向： | B18: - | C18: 請選擇 | D18: 請選擇 | E18: 請選擇 | F18: 請選擇
A19: 往B方向： | B19: 請選擇 | C19: - | D19: 請選擇 | E19: 請選擇 | F19: 請選擇
A20: 往C方向： | B20: 請選擇 | C20: 請選擇 | D20: - | E20: 請選擇 | F20: 請選擇
A21: 往D方向： | B21: 請選擇 | C21: 請選擇 | D21: 請選擇 | E21: - | F21: 請選擇
A22: 往E方向： | B22: 請選擇 | C22: 請選擇 | D22: 請選擇 | E22: 請選擇 | F22: -
A24: 車種設定
A25: 大型車1 | C25: 小型車1 | E25: 機車1 | G25: 特殊1
A26: 大型車2 | C26: 小型車2 | E26: 機車2 | G26: 特殊2
A27: 大型車3 | C27: 小型車3 | E27: 機車3
A28: 大型車4 | C28: 小型車4
A29: 大型車5
A30: 大型車6

Sheet 調查資料(OUT)
A1: 套用PCE | B1: =IF(路口基本資料!$B$13="左轉",1.9, IF(路口基本資料!$B$13="右轉",2.5,1.8)) -> 1.8 | C1: =IF(路口基本資料!$B$14="左轉",1.9, IF(路口基本資料!$B$14="右轉",2.5,1.8)) -> 1.8 | D1: =IF(路口基本資料!$B$15="左轉",1.9, IF(路口基本資料!$B$15="右轉",2.5,1.8)) -> 1.8 | E1: =IF(路口基本資料!$B$16="左轉",1.9, IF(路口基本資料!$B$16="右轉",2.5,1.8)) -> 1.8 | F1: 1 | G1: 1 | H1: 1 | I1: 1 | J1: =IF(路口基本資料!$B$13="左轉",0.41,0.42) -> 0.42 | K1: =IF(路口基本資料!$B$14="左轉",0.41,0.42) -> 0.42 | L1: =IF(路口基本資料!$B$15="左轉",0.41,0.42) -> 0.42 | M1: =IF(路口基本資料!$B$16="左轉",0.41,0.42) -> 0.42 | N1: =IF(路口基本資料!$C$12="左轉",1.9, IF(路口基本資料!$C$12="右轉",2.5,1.8)) -> 1.8 | O1: =IF(路口基本資料!$C$14="左轉",1.9, IF(路口基本資料!$C$14="右轉",2.5,1.8)) -> 1.8 | P1: =IF(路口基本資料!$C$15="左轉",1.9, IF(路口基本資料!$C$15="右轉",2.5,1.8)) -> 1.8 | Q1: =IF(路口基本資料!$C$16="左轉",1.9, IF(路口基本資料!$C$16="右轉",2.5,1.8)) -> 1.8 | R1: 1 | S1: 1 | T1: 1 | U1: 1 | V1: =IF(路口基本資料!$C$12="左轉",0.41,0.42) -> 0.42 | W1: =IF(路口基本資料!$C$14="左轉",0.41,0.42) -> 0.42 | X1: =IF(路口基本資料!$C$15="左轉",0.41,0.42) -> 0.42 | Y1: =IF(路口基本資料!$C$16="左轉",0.41,0.42) -> 0.42 | Z1: =IF(路口基本資料!$D$12="左轉",1.9, IF(路口基本資料!$D$12="右轉",2.5,1.8)) -> 1.8 | AA1: =IF(路口基本資料!$D$13="左轉",1.9, IF(路口基本資料!$D$13="右轉",2.5,1.8)) -> 1.8 | AB1: =IF(路口基本資料!$D$15="左轉",1.9, IF(路口基本資料!$D$15="右轉",2.5,1.8)) -> 1.8 | AC1: =IF(路口基本資料!$D$16="左轉",1.9, IF(路口基本資料!$D$16="右轉",2.5,1.8)) -> 1.8 | AD1: 1 | AE1: 1 | AF1: 1 | AG1: 1 | AH1: =IF(路口基本資料!$D$12="左轉",0.41,0.42) -> 0.42 | AI1: =IF(路口基本資料!$D$13="左轉",0.41,0.42) -> 0.42 | AJ1: =IF(路口基本資料!$D$15="左轉",0.41,0.42) -> 0.42 | AK1: =IF(路口基本資料!$D$16="左轉",0.41,0.42) -> 0.42 | AL1: =IF(路口基本資料!$E$12="左轉",1.9, IF(路口基本資料!$E$12="右轉",2.5,1.8)) -> 1.8 | AM1: =IF(路口基本資料!$E$13="左轉",1.9, IF(路口基本資料!$E$13="右轉",2.5,1.8)) -> 1.8 | AN1: =IF(路口基本資料!$E$14="左轉",1.9, IF(路口基本資料!$E$14="右轉",2.5,1.8)) -> 1.8 | AO1: =IF(路口基本資料!$E$16="左轉",1.9, IF(路口基本資料!$E$16="右轉",2.5,1.8)) -> 1.8 | AP1: 1 | AQ1: 1 | AR1: 1 | AS1: 1 | AT1: =IF(路口基本資料!$E$12="左轉",0.41,0.42) -> 0.42 | AU1: =IF(路口基本資料!$E$13="左轉",0.41,0.42) -> 0.42 | AV1: =IF(路口基本資料!$E$14="左轉",0.41,0.42) -> 0.42 | AW1: =IF(路口基本資料!$E$16="左轉",0.41,0.42) -> 0.42 | AX1: =IF(路口基本資料!$F$12="左轉",1.9, IF(路口基本資料!$F$12="右轉",2.5,1.8)) -> 1.8 | AY1: =IF(路口基本資料!$F$13="左轉",1.9, IF(路口基本資料!$F$13="右轉",2.5,1.8)) -> 1.8 | AZ1: =IF(路口基本資料!$F$14="左轉",1.9, IF(路口基本資料!$F$14="右轉",2.5,1.8)) -> 1.8 | BA1: =IF(路口基本資料!$F$15="左轉",1.9, IF(路口基本資料!$F$15="右轉",2.5,1.8)) -> 1.8 | BB1: 1 | BC1: 1 | BD1: 1 | BE1: 1 | BF1: =IF(路口基本資料!$F$12="左轉",0.41,0.42) -> 0.42 | BG1: =IF(路口基本資料!$F$13="左轉",0.41,0.42) -> 0.42 | BH1: =IF(路口基本資料!$F$14="左轉",0.41,0.42) -> 0.42 | BI1: =IF(路口基本資料!$F$15="左轉",0.41,0.42) -> 0.42
B3: ※註： 1. 行車方向若無車輛通過，表示為"0" 2. 若該行車方向為禁行方向，或為非調查時段，表示為"-"
EL5: =IF($W5="N","N",SUM('調查資料(OUT)'!#REF!)) -> #REF!
B8: ←A | C8: =路口基本資料!$B$9 -> 0 | F8: 車道數 | G8: =路口基本資料!$B$10 -> 0 | N8: ↑B | O8: =路口基本資料!$C$9 -> 0 | R8: 車道數 | S8: =路口基本資料!$C$10 -> 0 | Z8: →C | AA8: =路口基本資料!$D$9 -> 0 | AD8: 車道數 | AE8: =路口基本資料!$D$10 -> 0 | AL8: ↓D | AM8: =路口基本資料!$E$9 -> 0 | AP8: 車道數 | AQ8: =路口基本資料!$E$10 -> 0 | AX8: ↓E | AY8: =路口基本資料!$F$9 -> 0 | BB8: 車道數 | BC8: =路口基本資料!$F$10 -> 0
A9: 調查 開始時間 | B9: 大型車 | F9: 小型車 | J9: 機車 | N9: 大型車 | R9: 小型車 | V9: 機車 | Z9: 大型車 | AD9: 小型車 | AH9: 機車 | AL9: 大型車 | AP9: 小型車 | AT9: 機車 | AX9: 大型車 | BB9: 小型車 | BF9: 機車
B10: B | C10: C | D10: D | E10: E | F10: B | G10: C | H10: D | I10: E | J10: B | K10: C | L10: D | M10: E | N10: A | O10: C | P10: D | Q10: E | R10: A | S10: C | T10: D | U10: E | V10: A | W10: C | X10: D | Y10: E | Z10: A | AA10: B | AB10: D | AC10: E | AD10: A | AE10: B | AF10: D | AG10: E | AH10: A | AI10: B | AJ10: D | AK10: E | AL10: A | AM10: B | AN10: C | AO10: E | AP10: A | AQ10: B | AR10: C | AS10: E | AT10: A | AU10: B | AV10: C | AW10: E | AX10: A | AY10: B | AZ10: C | BA10: D | BB10: A | BC10: B | BD10: C | BE10: D | BF10: A | BG10: B | BH10: C | BI10: D
A11: 0 | B11: =轉向量!E2 -> 0 | C11: =轉向量!F2 -> 0 | D11: =轉向量!G2 -> 0 | E11: =轉向量!H2 -> 0 | F11: =轉向量!J2 -> 0 | G11: =轉向量!K2 -> 0 | H11: =轉向量!L2 -> 0 | I11: =轉向量!M2 -> 0 | J11: =轉向量!O2 -> 0 | K11: =轉向量!P2 -> 0 | L11: =轉向量!Q2 -> 0 | M11: =轉向量!R2 -> 0 | N11: =轉向量!D98 -> 0 | O11: =轉向量!F98 -> 0 | P11: =轉向量!G98 -> 0 | Q11: =轉向量!H98 -> 0 | R11: =轉向量!I98 -> 0 | S11: =轉向量!K98 -> 0 | T11: =轉向量!L98 -> 0 | U11: =轉向量!M98 -> 0 | V11: =轉向量!N98 -> 0 | W11: =轉向量!P98 -> 0 | X11: =轉向量!Q98 -> 0 | Y11: =轉向量!R98 -> 0 | Z11: =轉向量!D194 -> 0 | AA11: =轉向量!E194 -> 0 | AB11: =轉向量!G194 -> 0 | AC11: =轉向量!H194 -> 0 | AD11: =轉向量!I194 -> 0 | AE11: =轉向量!J194 -> 0 | AF11: =轉向量!L194 -> 0 | AG11: =轉向量!M194 -> 0 | AH11: =轉向量!N194 -> 0 | AI11: =轉向量!O194 -> 0 | AJ11: =轉向量!Q194 -> 0 | AK11: =轉向量!R194 -> 0 | AL11: =轉向量!D290 -> 0 | AM11: =轉向量!E290 -> 0 | AN11: =轉向量!F290 -> 0 | AO11: =轉向量!H290 -> 0 | AP11: =轉向量!I290 -> 0 | AQ11: =轉向量!J290 -> 0 | AR11: =轉向量!K290 -> 0 | AS11: =轉向量!M290 -> 0 | AT11: =轉向量!N290 -> 0 | AU11: =轉向量!O290 -> 0 | AV11: =轉向量!P290 -> 0 | AW11: =轉向量!R290 -> 0 | AX11: =轉向量!D386 -> 0 | AY11: =轉向量!E386 -> 0 | AZ11: =轉向量!F386 -> 0 | BA11: =轉向量!G386 -> 0 | BB11: =轉向量!I386 -> 0 | BC11: =轉向量!J386 -> 0 | BD11: =轉向量!K386 -> 0 | BE11: =轉向量!L386 -> 0 | BF11: =轉向量!N386 -> 0 | BG11: =轉向量!O386 -> 0 | BH11: =轉向量!P386 -> 0 | BI11: =轉向量!Q386 -> 0
A12: 15 | B12: =轉向量!E3 -> 0 | C12: =轉向量!F3 -> 0 | D12: =轉向量!G3 -> 0 | E12: =轉向量!H3 -> 0 | F12: =轉向量!J3 -> 0 | G12: =轉向量!K3 -> 0 | H12: =轉向量!L3 -> 0 | I12: =轉向量!M3 -> 0 | J12: =轉向量!O3 -> 0 | K12: =轉向量!P3 -> 0 | L12: =轉向量!Q3 -> 0 | M12: =轉向量!R3 -> 0 | N12: =轉向量!D99 -> 0 | O12: =轉向量!F99 -> 0 | P12: =轉向量!G99 -> 0 | Q12: =轉向量!H99 -> 0 | R12: =轉向量!I99 -> 0 | S12: =轉向量!K99 -> 0 | T12: =轉向量!L99 -> 0 | U12: =轉向量!M99 -> 0 | V12: =轉向量!N99 -> 0 | W12: =轉向量!P99 -> 0 | X12: =轉向量!Q99 -> 0 | Y12: =轉向量!R99 -> 0 | Z12: =轉向量!D195 -> 0 | AA12: =轉向量!E195 -> 0 | AB12: =轉向量!G195 -> 0 | AC12: =轉向量!H195 -> 0 | AD12: =轉向量!I195 -> 0 | AE12: =轉向量!J195 -> 0 | AF12: =轉向量!L195 -> 0 | AG12: =轉向量!M195 -> 0 | AH12: =轉向量!N195 -> 0 | AI12: =轉向量!O195 -> 0 | AJ12: =轉向量!Q195 -> 0 | AK12: =轉向量!R195 -> 0 | AL12: =轉向量!D291 -> 0 | AM12: =轉向量!E291 -> 0 | AN12: =轉向量!F291 -> 0 | AO12: =轉向量!H291 -> 0 | AP12: =轉向量!I291 -> 0 | AQ12: =轉向量!J291 -> 0 | AR12: =轉向量!K291 -> 0 | AS12: =轉向量!M291 -> 0 | AT12: =轉向量!N291 -> 0 | AU12: =轉向量!O291 -> 0 | AV12: =轉向量!P291 -> 0 | AW12: =轉向量!R291 -> 0 | AX12: =轉向量!D387 -> 0 | AY12: =轉向量!E387 -> 0 | AZ12: =轉向量!F387 -> 0 | BA12: =轉向量!G387 -> 0 | BB12: =轉向量!I387 -> 0 | BC12: =轉向量!J387 -> 0 | BD12: =轉向量!K387 -> 0 | BE12: =轉向量!L387 -> 0 | BF12: =轉向量!N387 -> 0 | BG12: =轉向量!O387 -> 0 | BH12: =轉向量!P387 -> 0 | BI12: =轉向量!Q387 -> 0
A13: 30 | B13: =轉向量!E4 -> 0 | C13: =轉向量!F4 -> 0 | D13: =轉向量!G4 -> 0 | E13: =轉向量!H4 -> 0 | F13: =轉向量!J4 -> 0 | G13: =轉向量!K4 -> 0 | H13: =轉向量!L4 -> 0 | I13: =轉向量!M4 -> 0 | J13: =轉向量!O4 -> 0 | K13: =轉向量!P4 -> 0 | L13: =轉向量!Q4 -> 0 | M13: =轉向量!R4 -> 0 | N13: =轉向量!D100 -> 0 | O13: =轉向量!F100 -> 0 | P13: =轉向量!G100 -> 0 | Q13: =轉向量!H100 -> 0 | R13: =轉向量!I100 -> 0 | S13: =轉向量!K100 -> 0 | T13: =轉向量!L100 -> 0 | U13: =轉向量!M100 -> 0 | V13: =轉向量!N100 -> 0 | W13: =轉向量!P100 -> 0 | X13: =轉向量!Q100 -> 0 | Y13: =轉向量!R100 -> 0 | Z13: =轉向量!D196 -> 0 | AA13: =轉向量!E196 -> 0 | AB13: =轉向量!G196 -> 0 | AC13: =轉向量!H196 -> 0 | AD13: =轉向量!I196 -> 0 | AE13: =轉向量!J196 -> 0 | AF13: =轉向量!L196 -> 0 | AG13: =轉向量!M196 -> 0 | AH13: =轉向量!N196 -> 0 | AI13: =轉向量!O196 -> 0 | AJ13: =轉向量!Q196 -> 0 | AK13: =轉向量!R196 -> 0 | AL13: =轉向量!D292 -> 0 | AM13: =轉向量!E292 -> 0 | AN13: =轉向量!F292 -> 0 | AO13: =轉向量!H292 -> 0 | AP13: =轉向量!I292 -> 0 | AQ13: =轉向量!J292 -> 0 | AR13: =轉向量!K292 -> 0 | AS13: =轉向量!M292 -> 0 | AT13: =轉向量!N292 -> 0 | AU13: =轉向量!O292 -> 0 | AV13: =轉向量!P292 -> 0 | AW13: =轉向量!R292 -> 0 | AX13: =轉向量!D388 -> 0 | AY13: =轉向量!E388 -> 0 | AZ13: =轉向量!F388 -> 0 | BA13: =轉向量!G388 -> 0 | BB13: =轉向量!I388 -> 0 | BC13: =轉向量!J388 -> 0 | BD13: =轉向量!K388 -> 0 | BE13: =轉向量!L388 -> 0 | BF13: =轉向量!N388 -> 0 | BG13: =轉向量!O388 -> 0 | BH13: =轉向量!P388 -> 0 | BI13: =轉向量!Q388 -> 0
A14: 45 | B14: =轉向量!E5 -> 0 | C14: =轉向量!F5 -> 0 | D14: =轉向量!G5 -> 0 | E14: =轉向量!H5 -> 0 | F14: =轉向量!J5 -> 0 | G14: =轉向量!K5 -> 0 | H14: =轉向量!L5 -> 0 | I14: =轉向量!M5 -> 0 | J14: =轉向量!O5 -> 0 | K14: =轉向量!P5 -> 0 | L14: =轉向量!Q5 -> 0 | M14: =轉向量!R5 -> 0 | N14: =轉向量!D101 -> 0 | O14: =轉向量!F101 -> 0 | P14: =轉向量!G101 -> 0 | Q14: =轉向量!H101 -> 0 | R14: =轉向量!I101 -> 0 | S14: =轉向量!K101 -> 0 | T14: =轉向量!L101 -> 0 | U14: =轉向量!M101 -> 0 | V14: =轉向量!N101 -> 0 | W14: =轉向量!P101 -> 0 | X14: =轉向量!Q101 -> 0 | Y14: =轉向量!R101 -> 0 | Z14: =轉向量!D197 -> 0 | AA14: =轉向量!E197 -> 0 | AB14: =轉向量!G197 -> 0 | AC14: =轉向量!H197 -> 0 | AD14: =轉向量!I197 -> 0 | AE14: =轉向量!J197 -> 0 | AF14: =轉向量!L197 -> 0 | AG14: =轉向量!M197 -> 0 | AH14: =轉向量!N197 -> 0 | AI14: =轉向量!O197 -> 0 | AJ14: =轉向量!Q197 -> 0 | AK14: =轉向量!R197 -> 0 | AL14: =轉向量!D293 -> 0 | AM14: =轉向量!E293 -> 0 | AN14: =轉向量!F293 -> 0 | AO14: =轉向量!H293 -> 0 | AP14: =轉向量!I293 -> 0 | AQ14: =轉向量!J293 -> 0 | AR14: =轉向量!K293 -> 0 | AS14: =轉向量!M293 -> 0 | AT14: =轉向量!N293 -> 0 | AU14: =轉向量!O293 -> 0 | AV14: =轉向量!P293 -> 0 | AW14: =轉向量!R293 -> 0 | AX14: =轉向量!D389 -> 0 | AY14: =轉向量!E389 -> 0 | AZ14: =轉向量!F389 -> 0 | BA14: =轉向量!G389 -> 0 | BB14: =轉向量!I389 -> 0 | BC14: =轉向量!J389 -> 0 | BD14: =轉向量!K389 -> 0 | BE14: =轉向量!L389 -> 0 | BF14: =轉向量!N389 -> 0 | BG14: =轉向量!O389 -> 0 | BH14: =轉向量!P389 -> 0 | BI14: =轉向量!Q389 -> 0
A15: 100 | B15: =轉向量!E6 -> 0 | C15: =轉向量!F6 -> 0 | D15: =轉向量!G6 -> 0 | E15: =轉向量!H6 -> 0 | F15: =轉向量!J6 -> 0 | G15: =轉向量!K6 -> 0 | H15: =轉向量!L6 -> 0 | I15: =轉向量!M6 -> 0 | J15: =轉向量!O6 -> 0 | K15: =轉向量!P6 -> 0 | L15: =轉向量!Q6 -> 0 | M15: =轉向量!R6 -> 0 | N15: =轉向量!D102 -> 0 | O15: =轉向量!F102 -> 0 | P15: =轉向量!G102 -> 0 | Q15: =轉向量!H102 -> 0 | R15: =轉向量!I102 -> 0 | S15: =轉向量!K102 -> 0 | T15: =轉向量!L102 -> 0 | U15: =轉向量!M102 -> 0 | V15: =轉向量!N102 -> 0 | W15: =轉向量!P102 -> 0 | X15: =轉向量!Q102 -> 0 | Y15: =轉向量!R102 -> 0 | Z15: =轉向量!D198 -> 0 | AA15: =轉向量!E198 -> 0 | AB15: =轉向量!G198 -> 0 | AC15: =轉向量!H198 -> 0 | AD15: =轉向量!I198 -> 0 | AE15: =轉向量!J198 -> 0 | AF15: =轉向量!L198 -> 0 | AG15: =轉向量!M198 -> 0 | AH15: =轉向量!N198 -> 0 | AI15: =轉向量!O198 -> 0 | AJ15: =轉向量!Q198 -> 0 | AK15: =轉向量!R198 -> 0 | AL15: =轉向量!D294 -> 0 | AM15: =轉向量!E294 -> 0 | AN15: =轉向量!F294 -> 0 | AO15: =轉向量!H294 -> 0 | AP15: =轉向量!I294 -> 0 | AQ15: =轉向量!J294 -> 0 | AR15: =轉向量!K294 -> 0 | AS15: =轉向量!M294 -> 0 | AT15: =轉向量!N294 -> 0 | AU15: =轉向量!O294 -> 0 | AV15: =轉向量!P294 -> 0 | AW15: =轉向量!R294 -> 0 | AX15: =轉向量!D390 -> 0 | AY15: =轉向量!E390 -> 0 | AZ15: =轉向量!F390 -> 0 | BA15: =轉向量!G390 -> 0 | BB15: =轉向量!I390 -> 0 | BC15: =轉向量!J390 -> 0 | BD15: =轉向量!K390 -> 0 | BE15: =轉向量!L390 -> 0 | BF15: =轉向量!N390 -> 0 | BG15: =轉向量!O390 -> 0 | BH15: =轉向量!P390 -> 0 | BI15: =轉向量!Q390 -> 0
A16: 115 | B16: =轉向量!E7 -> 0 | C16: =轉向量!F7 -> 0 | D16: =轉向量!G7 -> 0 | E16: =轉向量!H7 -> 0 | F16: =轉向量!J7 -> 0 | G16: =轉向量!K7 -> 0 | H16: =轉向量!L7 -> 0 | I16: =轉向量!M7 -> 0 | J16: =轉向量!O7 -> 0 | K16: =轉向量!P7 -> 0 | L16: =轉向量!Q7 -> 0 | M16: =轉向量!R7 -> 0 | N16: =轉向量!D103 -> 0 | O16: =轉向量!F103 -> 0 | P16: =轉向量!G103 -> 0 | Q16: =轉向量!H103 -> 0 | R16: =轉向量!I103 -> 0 | S16: =轉向量!K103 -> 0 | T16: =轉向量!L103 -> 0 | U16: =轉向量!M103 -> 0 | V16: =轉向量!N103 -> 0 | W16: =轉向量!P103 -> 0 | X16: =轉向量!Q103 -> 0 | Y16: =轉向量!R103 -> 0 | Z16: =轉向量!D199 -> 0 | AA16: =轉向量!E199 -> 0 | AB16: =轉向量!G199 -> 0 | AC16: =轉向量!H199 -> 0 | AD16: =轉向量!I199 -> 0 | AE16: =轉向量!J199 -> 0 | AF16: =轉向量!L199 -> 0 | AG16: =轉向量!M199 -> 0 | AH16: =轉向量!N199 -> 0 | AI16: =轉向量!O199 -> 0 | AJ16: =轉向量!Q199 -> 0 | AK16: =轉向量!R199 -> 0 | AL16: =轉向量!D295 -> 0 | AM16: =轉向量!E295 -> 0 | AN16: =轉向量!F295 -> 0 | AO16: =轉向量!H295 -> 0 | AP16: =轉向量!I295 -> 0 | AQ16: =轉向量!J295 -> 0 | AR16: =轉向量!K295 -> 0 | AS16: =轉向量!M295 -> 0 | AT16: =轉向量!N295 -> 0 | AU16: =轉向量!O295 -> 0 | AV16: =轉向量!P295 -> 0 | AW16: =轉向量!R295 -> 0 | AX16: =轉向量!D391 -> 0 | AY16: =轉向量!E391 -> 0 | AZ16: =轉向量!F391 -> 0 | BA16: =轉向量!G391 -> 0 | BB16: =轉向量!I391 -> 0 | BC16: =轉向量!J391 -> 0 | BD16: =轉向量!K391 -> 0 | BE16: =轉向量!L391 -> 0 | BF16: =轉向量!N391 -> 0 | BG16: =轉向量!O391 -> 0 | BH16: =轉向量!P391 -> 0 | BI16: =轉向量!Q391 -> 0
A17: 130 | B17: =轉向量!E8 -> 0 | C17: =轉向量!F8 -> 0 | D17: =轉向量!G8 -> 0 | E17: =轉向量!H8 -> 0 | F17: =轉向量!J8 -> 0 | G17: =轉向量!K8 -> 0 | H17: =轉向量!L8 -> 0 | I17: =轉向量!M8 -> 0 | J17: =轉向量!O8 -> 0 | K17: =轉向量!P8 -> 0 | L17: =轉向量!Q8 -> 0 | M17: =轉向量!R8 -> 0 | N17: =轉向量!D104 -> 0 | O17: =轉向量!F104 -> 0 | P17: =轉向量!G104 -> 0 | Q17: =轉向量!H104 -> 0 | R17: =轉向量!I104 -> 0 | S17: =轉向量!K104 -> 0 | T17: =轉向量!L104 -> 0 | U17: =轉向量!M104 -> 0 | V17: =轉向量!N104 -> 0 | W17: =轉向量!P104 -> 0 | X17: =轉向量!Q104 -> 0 | Y17: =轉向量!R104 -> 0 | Z17: =轉向量!D200 -> 0 | AA17: =轉向量!E200 -> 0 | AB17: =轉向量!G200 -> 0 | AC17: =轉向量!H200 -> 0 | AD17: =轉向量!I200 -> 0 | AE17: =轉向量!J200 -> 0 | AF17: =轉向量!L200 -> 0 | AG17: =轉向量!M200 -> 0 | AH17: =轉向量!N200 -> 0 | AI17: =轉向量!O200 -> 0 | AJ17: =轉向量!Q200 -> 0 | AK17: =轉向量!R200 -> 0 | AL17: =轉向量!D296 -> 0 | AM17: =轉向量!E296 -> 0 | AN17: =轉向量!F296 -> 0 | AO17: =轉向量!H296 -> 0 | AP17: =轉向量!I296 -> 0 | AQ17: =轉向量!J296 -> 0 | AR17: =轉向量!K296 -> 0 | AS17: =轉向量!M296 -> 0 | AT17: =轉向量!N296 -> 0 | AU17: =轉向量!O296 -> 0 | AV17: =轉向量!P296 -> 0 | AW17: =轉向量!R296 -> 0 | AX17: =轉向量!D392 -> 0 | AY17: =轉向量!E392 -> 0 | AZ17: =轉向量!F392 -> 0 | BA17: =轉向量!G392 -> 0 | BB17: =轉向量!I392 -> 0 | BC17: =轉向量!J392 -> 0 | BD17: =轉向量!K392 -> 0 | BE17: =轉向量!L392 -> 0 | BF17: =轉向量!N392 -> 0 | BG17: =轉向量!O392 -> 0 | BH17: =轉向量!P392 -> 0 | BI17: =轉向量!Q392 -> 0
A18: 145 | B18: =轉向量!E9 -> 0 | C18: =轉向量!F9 -> 0 | D18: =轉向量!G9 -> 0 | E18: =轉向量!H9 -> 0 | F18: =轉向量!J9 -> 0 | G18: =轉向量!K9 -> 0 | H18: =轉向量!L9 -> 0 | I18: =轉向量!M9 -> 0 | J18: =轉向量!O9 -> 0 | K18: =轉向量!P9 -> 0 | L18: =轉向量!Q9 -> 0 | M18: =轉向量!R9 -> 0 | N18: =轉向量!D105 -> 0 | O18: =轉向量!F105 -> 0 | P18: =轉向量!G105 -> 0 | Q18: =轉向量!H105 -> 0 | R18: =轉向量!I105 -> 0 | S18: =轉向量!K105 -> 0 | T18: =轉向量!L105 -> 0 | U18: =轉向量!M105 -> 0 | V18: =轉向量!N105 -> 0 | W18: =轉向量!P105 -> 0 | X18: =轉向量!Q105 -> 0 | Y18: =轉向量!R105 -> 0 | Z18: =轉向量!D201 -> 0 | AA18: =轉向量!E201 -> 0 | AB18: =轉向量!G201 -> 0 | AC18: =轉向量!H201 -> 0 | AD18: =轉向量!I201 -> 0 | AE18: =轉向量!J201 -> 0 | AF18: =轉向量!L201 -> 0 | AG18: =轉向量!M201 -> 0 | AH18: =轉向量!N201 -> 0 | AI18: =轉向量!O201 -> 0 | AJ18: =轉向量!Q201 -> 0 | AK18: =轉向量!R201 -> 0 | AL18: =轉向量!D297 -> 0 | AM18: =轉向量!E297 -> 0 | AN18: =轉向量!F297 -> 0 | AO18: =轉向量!H297 -> 0 | AP18: =轉向量!I297 -> 0 | AQ18: =轉向量!J297 -> 0 | AR18: =轉向量!K297 -> 0 | AS18: =轉向量!M297 -> 0 | AT18: =轉向量!N297 -> 0 | AU18: =轉向量!O297 -> 0 | AV18: =轉向量!P297 -> 0 | AW18: =轉向量!R297 -> 0 | AX18: =轉向量!D393 -> 0 | AY18: =轉向量!E393 -> 0 | AZ18: =轉向量!F393 -> 0 | BA18: =轉向量!G393 -> 0 | BB18: =轉向量!I393 -> 0 | BC18: =轉向量!J393 -> 0 | BD18: =轉向量!K393 -> 0 | BE18: =轉向量!L393 -> 0 | BF18: =轉向量!N393 -> 0 | BG18: =轉向量!O393 -> 0 | BH18: =轉向量!P393 -> 0 | BI18: =轉向量!Q393 -> 0
A19: 200 | B19: =轉向量!E10 -> 0 | C19: =轉向量!F10 -> 0 | D19: =轉向量!G10 -> 0 | E19: =轉向量!H10 -> 0 | F19: =轉向量!J10 -> 0 | G19: =轉向量!K10 -> 0 | H19: =轉向量!L10 -> 0 | I19: =轉向量!M10 -> 0 | J19: =轉向量!O10 -> 0 | K19: =轉向量!P10 -> 0 | L19: =轉向量!Q10 -> 0 | M19: =轉向量!R10 -> 0 | N19: =轉向量!D106 -> 0 | O19: =轉向量!F106 -> 0 | P19: =轉向量!G106 -> 0 | Q19: =轉向量!H106 -> 0 | R19: =轉向量!I106 -> 0 | S19: =轉向量!K106 -> 0 | T19: =轉向量!L106 -> 0 | U19: =轉向量!M106 -> 0 | V19: =轉向量!N106 -> 0 | W19: =轉向量!P106 -> 0 | X19: =轉向量!Q106 -> 0 | Y19: =轉向量!R106 -> 0 | Z19: =轉向量!D202 -> 0 | AA19: =轉向量!E202 -> 0 | AB19: =轉向量!G202 -> 0 | AC19: =轉向量!H202 -> 0 | AD19: =轉向量!I202 -> 0 | AE19: =轉向量!J202 -> 0 | AF19: =轉向量!L202 -> 0 | AG19: =轉向量!M202 -> 0 | AH19: =轉向量!N202 -> 0 | AI19: =轉向量!O202 -> 0 | AJ19: =轉向量!Q202 -> 0 | AK19: =轉向量!R202 -> 0 | AL19: =轉向量!D298 -> 0 | AM19: =轉向量!E298 -> 0 | AN19: =轉向量!F298 -> 0 | AO19: =轉向量!H298 -> 0 | AP19: =轉向量!I298 -> 0 | AQ19: =轉向量!J298 -> 0 | AR19: =轉向量!K298 -> 0 | AS19: =轉向量!M298 -> 0 | AT19: =轉向量!N298 -> 0 | AU19: =轉向量!O298 -> 0 | AV19: =轉向量!P298 -> 0 | AW19: =轉向量!R298 -> 0 | AX19: =轉向量!D394 -> 0 | AY19: =轉向量!E394 -> 0 | AZ19: =轉向量!F394 -> 0 | BA19: =轉向量!G394 -> 0 | BB19: =轉向量!I394 -> 0 | BC19: =轉向量!J394 -> 0 | BD19: =轉向量!K394 -> 0 | BE19: =轉向量!L394 -> 0 | BF19: =轉向量!N394 -> 0 | BG19: =轉向量!O394 -> 0 | BH19: =轉向量!P394 -> 0 | BI19: =轉向量!Q394 -> 0
A20: 215 | B20: =轉向量!E11 -> 0 | C20: =轉向量!F11 -> 0 | D20: =轉向量!G11 -> 0 | E20: =轉向量!H11 -> 0 | F20: =轉向量!J11 -> 0 | G20: =轉向量!K11 -> 0 | H20: =轉向量!L11 -> 0 | I20: =轉向量!M11 -> 0 | J20: =轉向量!O11 -> 0 | K20: =轉向量!P11 -> 0 | L20: =轉向量!Q11 -> 0 | M20: =轉向量!R11 -> 0 | N20: =轉向量!D107 -> 0 | O20: =轉向量!F107 -> 0 | P20: =轉向量!G107 -> 0 | Q20: =轉向量!H107 -> 0 | R20: =轉向量!I107 -> 0 | S20: =轉向量!K107 -> 0 | T20: =轉向量!L107 -> 0 | U20: =轉向量!M107 -> 0 | V20: =轉向量!N107 -> 0 | W20: =轉向量!P107 -> 0 | X20: =轉向量!Q107 -> 0 | Y20: =轉向量!R107 -> 0 | Z20: =轉向量!D203 -> 0 | AA20: =轉向量!E203 -> 0 | AB20: =轉向量!G203 -> 0 | AC20: =轉向量!H203 -> 0 | AD20: =轉向量!I203 -> 0 | AE20: =轉向量!J203 -> 0 | AF20: =轉向量!L203 -> 0 | AG20: =轉向量!M203 -> 0 | AH20: =轉向量!N203 -> 0 | AI20: =轉向量!O203 -> 0 | AJ20: =轉向量!Q203 -> 0 | AK20: =轉向量!R203 -> 0 | AL20: =轉向量!D299 -> 0 | AM20: =轉向量!E299 -> 0 | AN20: =轉向量!F299 -> 0 | AO20: =轉向量!H299 -> 0 | AP20: =轉向量!I299 -> 0 | AQ20: =轉向量!J299 -> 0 | AR20: =轉向量!K299 -> 0 | AS20: =轉向量!M299 -> 0 | AT20: =轉向量!N299 -> 0 | AU20: =轉向量!O299 -> 0 | AV20: =轉向量!P299 -> 0 | AW20: =轉向量!R299 -> 0 | AX20: =轉向量!D395 -> 0 | AY20: =轉向量!E395 -> 0 | AZ20: =轉向量!F395 -> 0 | BA20: =轉向量!G395 -> 0 | BB20: =轉向量!I395 -> 0 | BC20: =轉向量!J395 -> 0 | BD20: =轉向量!K395 -> 0 | BE20: =轉向量!L395 -> 0 | BF20: =轉向量!N395 -> 0 | BG20: =轉向量!O395 -> 0 | BH20: =轉向量!P395 -> 0 | BI20: =轉向量!Q395 -> 0
A21: 230 | B21: =轉向量!E12 -> 0 | C21: =轉向量!F12 -> 0 | D21: =轉向量!G12 -> 0 | E21: =轉向量!H12 -> 0 | F21: =轉向量!J12 -> 0 | G21: =轉向量!K12 -> 0 | H21: =轉向量!L12 -> 0 | I21: =轉向量!M12 -> 0 | J21: =轉向量!O12 -> 0 | K21: =轉向量!P12 -> 0 | L21: =轉向量!Q12 -> 0 | M21: =轉向量!R12 -> 0 | N21: =轉向量!D108 -> 0 | O21: =轉向量!F108 -> 0 | P21: =轉向量!G108 -> 0 | Q21: =轉向量!H108 -> 0 | R21: =轉向量!I108 -> 0 | S21: =轉向量!K108 -> 0 | T21: =轉向量!L108 -> 0 | U21: =轉向量!M108 -> 0 | V21: =轉向量!N108 -> 0 | W21: =轉向量!P108 -> 0 | X21: =轉向量!Q108 -> 0 | Y21: =轉向量!R108 -> 0 | Z21: =轉向量!D204 -> 0 | AA21: =轉向量!E204 -> 0 | AB21: =轉向量!G204 -> 0 | AC21: =轉向量!H204 -> 0 | AD21: =轉向量!I204 -> 0 | AE21: =轉向量!J204 -> 0 | AF21: =轉向量!L204 -> 0 | AG21: =轉向量!M204 -> 0 | AH21: =轉向量!N204 -> 0 | AI21: =轉向量!O204 -> 0 | AJ21: =轉向量!Q204 -> 0 | AK21: =轉向量!R204 -> 0 | AL21: =轉向量!D300 -> 0 | AM21: =轉向量!E300 -> 0 | AN21: =轉向量!F300 -> 0 | AO21: =轉向量!H300 -> 0 | AP21: =轉向量!I300 -> 0 | AQ21: =轉向量!J300 -> 0 | AR21: =轉向量!K300 -> 0 | AS21: =轉向量!M300 -> 0 | AT21: =轉向量!N300 -> 0 | AU21: =轉向量!O300 -> 0 | AV21: =轉向量!P300 -> 0 | AW21: =轉向量!R300 -> 0 | AX21: =轉向量!D396 -> 0 | AY21: =轉向量!E396 -> 0 | AZ21: =轉向量!F396 -> 0 | BA21: =轉向量!G396 -> 0 | BB21: =轉向量!I396 -> 0 | BC21: =轉向量!J396 -> 0 | BD21: =轉向量!K396 -> 0 | BE21: =轉向量!L396 -> 0 | BF21: =轉向量!N396 -> 0 | BG21: =轉向量!O396 -> 0 | BH21: =轉向量!P396 -> 0 | BI21: =轉向量!Q396 -> 0
A22: 245 | B22: =轉向量!E13 -> 0 | C22: =轉向量!F13 -> 0 | D22: =轉向量!G13 -> 0 | E22: =轉向量!H13 -> 0 | F22: =轉向量!J13 -> 0 | G22: =轉向量!K13 -> 0 | H22: =轉向量!L13 -> 0 | I22: =轉向量!M13 -> 0 | J22: =轉向量!O13 -> 0 | K22: =轉向量!P13 -> 0 | L22: =轉向量!Q13 -> 0 | M22: =轉向量!R13 -> 0 | N22: =轉向量!D109 -> 0 | O22: =轉向量!F109 -> 0 | P22: =轉向量!G109 -> 0 | Q22: =轉向量!H109 -> 0 | R22: =轉向量!I109 -> 0 | S22: =轉向量!K109 -> 0 | T22: =轉向量!L109 -> 0 | U22: =轉向量!M109 -> 0 | V22: =轉向量!N109 -> 0 | W22: =轉向量!P109 -> 0 | X22: =轉向量!Q109 -> 0 | Y22: =轉向量!R109 -> 0 | Z22: =轉向量!D205 -> 0 | AA22: =轉向量!E205 -> 0 | AB22: =轉向量!G205 -> 0 | AC22: =轉向量!H205 -> 0 | AD22: =轉向量!I205 -> 0 | AE22: =轉向量!J205 -> 0 | AF22: =轉向量!L205 -> 0 | AG22: =轉向量!M205 -> 0 | AH22: =轉向量!N205 -> 0 | AI22: =轉向量!O205 -> 0 | AJ22: =轉向量!Q205 -> 0 | AK22: =轉向量!R205 -> 0 | AL22: =轉向量!D301 -> 0 | AM22: =轉向量!E301 -> 0 | AN22: =轉向量!F301 -> 0 | AO22: =轉向量!H301 -> 0 | AP22: =轉向量!I301 -> 0 | AQ22: =轉向量!J301 -> 0 | AR22: =轉向量!K301 -> 0 | AS22: =轉向量!M301 -> 0 | AT22: =轉向量!N301 -> 0 | AU22: =轉向量!O301 -> 0 | AV22: =轉向量!P301 -> 0 | AW22: =轉向量!R301 -> 0 | AX22: =轉向量!D397 -> 0 | AY22: =轉向量!E397 -> 0 | AZ22: =轉向量!F397 -> 0 | BA22: =轉向量!G397 -> 0 | BB22: =轉向量!I397 -> 0 | BC22: =轉向量!J397 -> 0 | BD22: =轉向量!K397 -> 0 | BE22: =轉向量!L397 -> 0 | BF22: =轉向量!N397 -> 0 | BG22: =轉向量!O397 -> 0 | BH22: =轉向量!P397 -> 0 | BI22: =轉向量!Q397 -> 0
... A106: 2345 | B106: =轉向量!E97 -> 0 | C106: =轉向量!F97 -> 0 | D106: =轉向量!G97 -> 0 | E106: =轉向量!H97 -> 0 | F106: =轉向量!J97 -> 0 | G106: =轉向量!K97 -> 0 | H106: =轉向量!L97 -> 0 | I106: =轉向量!M97 -> 0 | J106: =轉向量!O97 -> 0 | K106: =轉向量!P97 -> 0 | L106: =轉向量!Q97 -> 0 | M106: =轉向量!R97 -> 0 | N106: =轉向量!D193 -> 0 | O106: =轉向量!F193 -> 0 | P106: =轉向量!G193 -> 0 | Q106: =轉向量!H193 -> 0 | R106: =轉向量!I193 -> 0 | S106: =轉向量!K193 -> 0 | T106: =轉向量!L193 -> 0 | U106: =轉向量!M193 -> 0 | V106: =轉向量!N193 -> 0 | W106: =轉向量!P193 -> 0 | X106: =轉向量!Q193 -> 0 | Y106: =轉向量!R193 -> 0 | Z106: =轉向量!D289 -> 0 | AA106: =轉向量!E289 -> 0 | AB106: =轉向量!G289 -> 0 | AC106: =轉向量!H289 -> 0 | AD106: =轉向量!I289 -> 0 | AE106: =轉向量!J289 -> 0 | AF106: =轉向量!L289 -> 0 | AG106: =轉向量!M289 -> 0 | AH106: =轉向量!N289 -> 0 | AI106: =轉向量!O289 -> 0 | AJ106: =轉向量!Q289 -> 0 | AK106: =轉向量!R289 -> 0 | AL106: =轉向量!D385 -> 0 | AM106: =轉向量!E385 -> 0 | AN106: =轉向量!F385 -> 0 | AO106: =轉向量!H385 -> 0 | AP106: =轉向量!I385 -> 0 | AQ106: =轉向量!J385 -> 0 | AR106: =轉向量!K385 -> 0 | AS106: =轉向量!M385 -> 0 | AT106: =轉向量!N385 -> 0 | AU106: =轉向量!O385 -> 0 | AV106: =轉向量!P385 -> 0 | AW106: =轉向量!R385 -> 0 | AX106: =轉向量!D481 -> 0 | AY106: =轉向量!E481 -> 0 | AZ106: =轉向量!F481 -> 0 | BA106: =轉向量!G481 -> 0 | BB106: =轉向量!I481 -> 0 | BC106: =轉向量!J481 -> 0 | BD106: =轉向量!K481 -> 0 | BE106: =轉向量!L481 -> 0 | BF106: =轉向量!N481 -> 0 | BG106: =轉向量!O481 -> 0 | BH106: =轉向量!P481 -> 0 | BI106: =轉向量!Q481 -> 0

Sheet PHF及轉向比
AP1: ←A | BJ1: 合計 | BQ1: ↑B | CK1: 合計 | CR1: →C | DL1: 合計 | DS1: ↓D | EM1: 合計 | ET1: ↓E | FN1: 合計
B2: ←A | G2: ↑B | L2: →C | Q2: ↓D | V2: ↓E | AA2: 路口 | AE2: 每小時 | AF2: 尖峰小時 | AG2: 最大15分鐘 | AH2: A尖峰小時 | AI2: B尖峰小時 | AJ2: C尖峰小時 | AK2: D尖峰小時 | AL2: E尖峰小時 | AM2: 尖峰小時 | AN2: 尖峰 | AO2: 小時 | AP2: B | AT2: 轉向 | AU2: C | AY2: 轉向 | AZ2: D | BD2: 轉向 | BE2: E | BI2: 轉向 | BK2: 車種 | BM2: 車種 | BO2: 車種 | BQ2: A | BU2: 轉向 | BV2: C | BZ2: 轉向 | CA2: D | CE2: 轉向 | CF2: E | CJ2: 轉向 | CL2: 車種 | CN2: 車種 | CP2: 車種 | CR2: A | CV2: 轉向 | CW2: B | DA2: 轉向 | DB2: D | DF2: 轉向 | DG2: E | DK2: 轉向 | DM2: 車種 | DO2: 車種 | DQ2: 車種 | DS2: A | DW2: 轉向 | DX2: B | EB2: 轉向 | EC2: C | EG2: 轉向 | EH2: E | EL2: 轉向 | EN2: 車種 | EP2: 車種 | ER2: 車種 | ET2: A | EX2: 轉向 | EY2: B | FC2: 轉向 | FD2: C | FH2: 轉向 | FI2: D | FM2: 轉向 | FO2: 車種 | FQ2: 車種 | FS2: 車種
B3: 小計 | C3: B | D3: C | E3: D | F3: E | G3: 小計 | H3: A | I3: C | J3: D | K3: E | L3: 小計 | M3: A | N3: B | O3: D | P3: E | Q3: 小計 | R3: A | S3: B | T3: C | U3: E | V3: 小計 | W3: A | X3: B | Y3: C | Z3: D | AA3: 總計 | AE3: 交通量 | AF3: 交通量 | AG3: 交通量 | AH3: 係數 | AI3: 係數 | AJ3: 係數 | AK3: 係數 | AL3: 係數 | AM3: 係數 | AN3: 起 | AO3: 迄 | AP3: 小計 | AQ3: 大型車 | AR3: 小型車 | AS3: 機車 | AT3: 百分比 | AU3: 小計 | AV3: 大型車 | AW3: 小型車 | AX3: 機車 | AY3: 百分比 | AZ3: 小計 | BA3: 大型車 | BB3: 小型車 | BC3: 機車 | BD3: 百分比 | BE3: 小計 | BF3: 大型車 | BG3: 小型車 | BH3: 機車 | BI3: 百分比 | BJ3: 大型車 | BK3: 百分比 | BL3: 小型車 | BM3: 百分比 | BN3: 機車 | BO3: 百分比 | BP3: 合計 | BQ3: 小計 | BR3: 大型車 | BS3: 小型車 | BT3: 機車 | BU3: 百分比 | BV3: 小計 | BW3: 大型車 | BX3: 小型車 | BY3: 機車 | BZ3: 百分比 | CA3: 小計 | CB3: 大型車 | CC3: 小型車 | CD3: 機車 | CE3: 百分比 | CF3: 小計 | CG3: 大型車 | CH3: 小型車 | CI3: 機車 | CJ3: 百分比 | CK3: 大型車 | CL3: 百分比 | CM3: 小型車 | CN3: 百分比 | CO3: 機車 | CP3: 百分比 | CQ3: 合計 | CR3: 小計 | CS3: 大型車 | CT3: 小型車 | CU3: 機車 | CV3: 百分比 | CW3: 小計 | CX3: 大型車 | CY3: 小型車 | CZ3: 機車 | DA3: 百分比 | DB3: 小計 | DC3: 大型車 | DD3: 小型車 | DE3: 機車 | DF3: 百分比 | DG3: 小計 | DH3: 大型車 | DI3: 小型車 | DJ3: 機車 | DK3: 百分比 | DL3: 大型車 | DM3: 百分比 | DN3: 小型車 | DO3: 百分比 | DP3: 機車 | DQ3: 百分比 | DR3: 合計 | DS3: 小計 | DT3: 大型車 | DU3: 小型車 | DV3: 機車 | DW3: 百分比 | DX3: 小計 | DY3: 大型車 | DZ3: 小型車 | EA3: 機車 | EB3: 百分比 | EC3: 小計 | ED3: 大型車 | EE3: 小型車 | EF3: 機車 | EG3: 百分比 | EH3: 小計 | EI3: 大型車 | EJ3: 小型車 | EK3: 機車 | EL3: 百分比 | EM3: 大型車 | EN3: 百分比 | EO3: 小型車 | EP3: 百分比 | EQ3: 機車 | ER3: 百分比 | ES3: 合計 | ET3: 小計 | EU3: 大型車 | EV3: 小型車 | EW3: 機車 | EX3: 百分比 | EY3: 小計 | EZ3: 大型車 | FA3: 小型車 | FB3: 機車 | FC3: 百分比 | FD3: 小計 | FE3: 大型車 | FF3: 小型車 | FG3: 機車 | FH3: 百分比 | FI3: 小計 | FJ3: 大型車 | FK3: 小型車 | FL3: 機車 | FM3: 百分比 | FN3: 大型車 | FO3: 百分比 | FP3: 小型車 | FQ3: 百分比 | FR3: 機車 | FS3: 百分比 | FT3: 合計
B4: (PCU) | C4: (PCU) | D4: (PCU) | E4: (PCU) | F4: (PCU) | G4: (PCU) | H4: (PCU) | I4: (PCU) | J4: (PCU) | K4: (PCU) | L4: (PCU) | M4: (PCU) | N4: (PCU) | O4: (PCU) | P4: (PCU) | Q4: (PCU) | R4: (PCU) | S4: (PCU) | T4: (PCU) | U4: (PCU) | V4: (PCU) | W4: (PCU) | X4: (PCU) | Y4: (PCU) | Z4: (PCU) | AA4: (PCU) | AE4: （PCU） | AF4: （PCU） | AG4: （PCU） | AH4: （PHF） | AI4: （PHF） | AJ4: （PHF） | AK4: （PHF） | AL4: （PHF） | AM4: （PHF） | AP4: （PCU） | AQ4: （輛） | AR4: （輛） | AS4: （輛） | AT4: （％） | AU4: （PCU） | AV4: （輛） | AW4: （輛） | AX4: （輛） | AY4: （％） | AZ4: （PCU） | BA4: （輛） | BB4: （輛） | BC4: （輛） | BD4: （％） | BE4: （PCU） | BF4: （輛） | BG4: （輛） | BH4: （輛） | BI4: （％） | BJ4: （輛） | BK4: （％） | BL4: （輛） | BM4: （％） | BN4: （輛） | BO4: （％） | BP4: （PCU） | BQ4: （PCU） | BR4: （輛） | BS4: （輛） | BT4: （輛） | BU4: （％） | BV4: （PCU） | BW4: （輛） | BX4: （輛） | BY4: （輛） | BZ4: （％） | CA4: （PCU） | CB4: （輛） | CC4: （輛） | CD4: （輛） | CE4: （％） | CF4: （PCU） | CG4: （輛） | CH4: （輛） | CI4: （輛） | CJ4: （％） | CK4: （輛） | CL4: （％） | CM4: （輛） | CN4: （％） | CO4: （輛） | CP4: （％） | CQ4: （PCU） | CR4: （PCU） | CS4: （輛） | CT4: （輛） | CU4: （輛） | CV4: （％） | CW4: （PCU） | CX4: （輛） | CY4: （輛） | CZ4: （輛） | DA4: （％） | DB4: （PCU） | DC4: （輛） | DD4: （輛） | DE4: （輛） | DF4: （％） | DG4: （PCU） | DH4: （輛） | DI4: （輛） | DJ4: （輛） | DK4: （％） | DL4: （輛） | DM4: （％） | DN4: （輛） | DO4: （％） | DP4: （輛） | DQ4: （％） | DR4: （PCU） | DS4: （PCU） | DT4: （輛） | DU4: （輛） | DV4: （輛） | DW4: （％） | DX4: （PCU） | DY4: （輛） | DZ4: （輛） | EA4: （輛） | EB4: （％） | EC4: （PCU） | ED4: （輛） | EE4: （輛） | EF4: （輛） | EG4: （％） | EH4: （PCU） | EI4: （輛） | EJ4: （輛） | EK4: （輛） | EL4: （％） | EM4: （輛） | EN4: （％） | EO4: （輛） | EP4: （％） | EQ4: （輛） | ER4: （％） | ES4: （PCU） | ET4: （PCU） | EU4: （輛） | EV4: （輛） | EW4: （輛） | EX4: （％） | EY4: （PCU） | EZ4: （輛） | FA4: （輛） | FB4: （輛） | FC4: （％） | FD4: （PCU） | FE4: （輛） | FF4: （輛） | FG4: （輛） | FH4: （％） | FI4: （PCU） | FJ4: （輛） | FK4: （輛） | FL4: （輛） | FM4: （％） | FN4: （輛） | FO4: （％） | FP4: （輛） | FQ4: （％） | FR4: （輛） | FS4: （％） | FT4: （PCU）
A5: ='調查資料(OUT)'!A11 -> 0 | B5: =SUM(C5:F5) -> 0 | C5: =IFERROR('調查資料(OUT)'!$B$1*'調查資料(OUT)'!B11,0)+IFERROR('調查資料(OUT)'!$F$1*'調查資料(OUT)'!F11,0)+IFERROR('調查資料(OUT)'!$J$1*'調查資料(OUT)'!J11,0) -> 0 | D5: =IFERROR('調查資料(OUT)'!$C$1*'調查資料(OUT)'!C11,0)+IFERROR('調查資料(OUT)'!$G$1*'調查資料(OUT)'!G11,0)+IFERROR('調查資料(OUT)'!$K$1*'調查資料(OUT)'!K11,0) -> 0 | E5: =IFERROR('調查資料(OUT)'!$D$1*'調查資料(OUT)'!D11,0)+IFERROR('調查資料(OUT)'!$H$1*'調查資料(OUT)'!H11,0)+IFERROR('調查資料(OUT)'!$L$1*'調查資料(OUT)'!L11,0) -> 0 | F5: =IFERROR('調查資料(OUT)'!$E$1*'調查資料(OUT)'!E11,0)+IFERROR('調查資料(OUT)'!$I$1*'調查資料(OUT)'!I11,0)+IFERROR('調查資料(OUT)'!$M$1*'調查資料(OUT)'!M11,0) -> 0 | G5: =SUM(H5:K5) -> 0 | H5: =IFERROR('調查資料(OUT)'!$N$1*'調查資料(OUT)'!N11,0)+IFERROR('調查資料(OUT)'!$R$1*'調查資料(OUT)'!R11,0)+IFERROR('調查資料(OUT)'!$V$1*'調查資料(OUT)'!V11,0) -> 0 | I5: =IFERROR('調查資料(OUT)'!$O$1*'調查資料(OUT)'!O11,0)+IFERROR('調查資料(OUT)'!$S$1*'調查資料(OUT)'!S11,0)+IFERROR('調查資料(OUT)'!$W$1*'調查資料(OUT)'!W11,0) -> 0 | J5: =IFERROR('調查資料(OUT)'!$P$1*'調查資料(OUT)'!P11,0)+IFERROR('調查資料(OUT)'!$T$1*'調查資料(OUT)'!T11,0)+IFERROR('調查資料(OUT)'!$X$1*'調查資料(OUT)'!X11,0) -> 0 | K5: =IFERROR('調查資料(OUT)'!$Q$1*'調查資料(OUT)'!Q11,0)+IFERROR('調查資料(OUT)'!$U$1*'調查資料(OUT)'!U11,0)+IFERROR('調查資料(OUT)'!$Y$1*'調查資料(OUT)'!Y11,0) -> 0 | L5: =SUM(M5:P5) -> 0 | M5: =IFERROR('調查資料(OUT)'!$Z$1*'調查資料(OUT)'!Z11,0)+IFERROR('調查資料(OUT)'!$AD$1*'調查資料(OUT)'!AD11,0)+IFERROR('調查資料(OUT)'!$AH$1*'調查資料(OUT)'!AH11,0) -> 0 | N5: =IFERROR('調查資料(OUT)'!$AA$1*'調查資料(OUT)'!AA11,0)+IFERROR('調查資料(OUT)'!$AE$1*'調查資料(OUT)'!AE11,0)+IFERROR('調查資料(OUT)'!$AI$1*'調查資料(OUT)'!AI11,0) -> 0 | O5: =IFERROR('調查資料(OUT)'!$AB$1*'調查資料(OUT)'!AB11,0)+IFERROR('調查資料(OUT)'!$AF$1*'調查資料(OUT)'!AF11,0)+IFERROR('調查資料(OUT)'!$AJ$1*'調查資料(OUT)'!AJ11,0) -> 0 | P5: =IFERROR('調查資料(OUT)'!$AC$1*'調查資料(OUT)'!AC11,0)+IFERROR('調查資料(OUT)'!$AG$1*'調查資料(OUT)'!AG11,0)+IFERROR('調查資料(OUT)'!$AK$1*'調查資料(OUT)'!AK11,0) -> 0 | Q5: =SUM(R5:U5) -> 0 | R5: =IFERROR('調查資料(OUT)'!$AL$1*'調查資料(OUT)'!AL11,0)+IFERROR('調查資料(OUT)'!$AP$1*'調查資料(OUT)'!AP11,0)+IFERROR('調查資料(OUT)'!$AT$1*'調查資料(OUT)'!AT11,0) -> 0 | S5: =IFERROR('調查資料(OUT)'!$AM$1*'調查資料(OUT)'!AM11,0)+IFERROR('調查資料(OUT)'!$AQ$1*'調查資料(OUT)'!AQ11,0)+IFERROR('調查資料(OUT)'!$AU$1*'調查資料(OUT)'!AU11,0) -> 0 | T5: =IFERROR('調查資料(OUT)'!$AN$1*'調查資料(OUT)'!AN11,0)+IFERROR('調查資料(OUT)'!$AR$1*'調查資料(OUT)'!AR11,0)+IFERROR('調查資料(OUT)'!$AV$1*'調查資料(OUT)'!AV11,0) -> 0 | U5: =IFERROR('調查資料(OUT)'!$AO$1*'調查資料(OUT)'!AO11,0)+IFERROR('調查資料(OUT)'!$AS$1*'調查資料(OUT)'!AS11,0)+IFERROR('調查資料(OUT)'!$AW$1*'調查資料(OUT)'!AW11,0) -> 0 | V5: =SUM(W5:Z5) -> 0 | W5: =IFERROR('調查資料(OUT)'!$AX$1*'調查資料(OUT)'!AX11,0)+IFERROR('調查資料(OUT)'!$BB$1*'調查資料(OUT)'!BB11,0)+IFERROR('調查資料(OUT)'!$BF$1*'調查資料(OUT)'!BF11,0) -> 0 | X5: =IFERROR('調查資料(OUT)'!$AY$1*'調查資料(OUT)'!AY11,0)+IFERROR('調查資料(OUT)'!$BC$1*'調查資料(OUT)'!BC11,0)+IFERROR('調查資料(OUT)'!$BG$1*'調查資料(OUT)'!BG11,0) -> 0 | Y5: =IFERROR('調查資料(OUT)'!$AZ$1*'調查資料(OUT)'!AZ11,0)+IFERROR('調查資料(OUT)'!$BD$1*'調查資料(OUT)'!BD11,0)+IFERROR('調查資料(OUT)'!$BH$1*'調查資料(OUT)'!BH11,0) -> 0 | Z5: =IFERROR('調查資料(OUT)'!$BA$1*'調查資料(OUT)'!BA11,0)+IFERROR('調查資料(OUT)'!$BE$1*'調查資料(OUT)'!BE11,0)+IFERROR('調查資料(OUT)'!$BI$1*'調查資料(OUT)'!BI11,0) -> 0 | AA5: =B5+G5+L5+Q5+V5 -> 0 | AC5: ='調查資料(OUT)'!A11 -> 0 | AD5: =AC5+100 -> 100 | AE5: =SUM(AA5:AA8) -> 0 | AF5: =MAX(AE29:AE41) -> 0 | AG5: =IF($AE5=$AF$5,MAX(AA5:AA8),0) -> 0 | AH5: =IF($AE5=AF$5,SUM(B5:B8)/(4*(MAX(B5:B8))),0) -> #DIV/0! | AI5: =IF($AE5=AF$5,SUM(G5:G8)/(4*(MAX(G5:G8))),0) -> #DIV/0! | AJ5: =IF($AE5=AF$5,SUM(L5:L8)/(4*(MAX(L5:L8))),0) -> #DIV/0! | AK5: =IF($AE5=AF$5,SUM(Q5:Q8)/(4*(MAX(Q5:Q8))),0) -> #DIV/0! | AL5: =IF($AE5=AF$5,SUM(V5:V8)/(4*(MAX(V5:V8))),0) -> #DIV/0! | AM5: =$AF$5/(4*MAX(AG5:AG17)) -> #DIV/0! | AN5: =IF(AE5=AF$5,$AC5,"N") -> 0 | AO5: =IF(AE5=AF$5,$AD5,"N") -> 100 | AP5: =IF($AN5="N","N",SUM(C5:C8)) -> 0 | AQ5: =IF($AN5="N","N",SUM('調查資料(OUT)'!B11:B14)) -> 0 | AR5: =IF($AN5="N","N",SUM('調查資料(OUT)'!F11:F14)) -> 0 | AS5: =IF($AN5="N","N",SUM('調查資料(OUT)'!J11:J14)) -> 0 | AT5: =IF($AN5="N","N",(AP5/$BP5)*100) -> #DIV/0! | AU5: =IF($AN5="N","N",SUM(D5:D8)) -> 0 | AV5: =IF($AN5="N","N",SUM('調查資料(OUT)'!C11:C14)) -> 0 | AW5: =IF($AN5="N","N",SUM('調查資料(OUT)'!G11:G14)) -> 0 | AX5: =IF($AN5="N","N",SUM('調查資料(OUT)'!K11:K14)) -> 0 | AY5: =IF($AN5="N","N",(AU5/$BP5)*100) -> #DIV/0! | AZ5: =IF($AN5="N","N",SUM(E5:E8)) -> 0 | BA5: =IF($AN5="N","N",SUM('調查資料(OUT)'!D11:D14)) -> 0 | BB5: =IF($AN5="N","N",SUM('調查資料(OUT)'!H11:H14)) -> 0 | BC5: =IF($AN5="N","N",SUM('調查資料(OUT)'!L11:L14)) -> 0 | BD5: =IF($AN5="N","N",(AZ5/$BP5)*100) -> #DIV/0! | BE5: =IF($AN5="N","N",SUM(F5:F8)) -> 0 | BF5: =IF($AN5="N","N",SUM('調查資料(OUT)'!E11:E14)) -> 0 | BG5: =IF($AN5="N","N",SUM('調查資料(OUT)'!I11:I14)) -> 0 | BH5: =IF($AN5="N","N",SUM('調查資料(OUT)'!M11:M14)) -> 0 | BI5: =IF($AN5="N","N",(BE5/$BP5)*100) -> #DIV/0! | BJ5: =IF($AN5="N","N",AQ5+AV5+BA5+BF5) -> 0 | BK5: =IF($AN5="N","N",(BJ5/($BJ5+$BL5+$BN5))*100) -> #DIV/0! | BL5: =IF($AN5="N","N",AR5+AW5+BB5+BG5) -> 0 | BM5: =IF($AN5="N","N",(BL5/($BJ5+$BL5+$BN5))*100) -> #DIV/0! | BN5: =IF($AN5="N","N",AS5+AX5+BC5+BH5) -> 0 | BO5: =IF($AN5="N","N",(BN5/($BJ5+$BL5+$BN5))*100) -> #DIV/0! | BP5: =IF($AN5="N","N",AP5+AU5+AZ5+BE5) -> 0 | BQ5: =IF($AN5="N","N",SUM(H5:H8)) -> 0 | BR5: =IF($AN5="N","N",SUM('調查資料(OUT)'!N11:N14)) -> 0 | BS5: =IF($AN5="N","N",SUM('調查資料(OUT)'!R11:R14)) -> 0 | BT5: =IF($AN5="N","N",SUM('調查資料(OUT)'!V11:V14)) -> 0 | BU5: =IF($AN5="N","N",(BQ5/CQ5)*100) -> #DIV/0! | BV5: =IF($AN5="N","N",SUM(I5:I8)) -> 0 | BW5: =IF($AN5="N","N",SUM('調查資料(OUT)'!O11:O14)) -> 0 | BX5: =IF($AN5="N","N",SUM('調查資料(OUT)'!S11:S14)) -> 0 | BY5: =IF($AN5="N","N",SUM('調查資料(OUT)'!W11:W14)) -> 0 | BZ5: =IF($AN5="N","N",(BV5/$CQ5)*100) -> #DIV/0! | CA5: =IF($AN5="N","N",SUM(J5:J8)) -> 0 | CB5: =IF($AN5="N","N",SUM('調查資料(OUT)'!P11:P14)) -> 0 | CC5: =IF($AN5="N","N",SUM('調查資料(OUT)'!T11:T14)) -> 0 | CD5: =IF($AN5="N","N",SUM('調查資料(OUT)'!X11:X14)) -> 0 | CE5: =IF($AN5="N","N",(CA5/$CQ5)*100) -> #DIV/0! | CF5: =IF($AN5="N","N",SUM(K5:K8)) -> 0 | CG5: =IF($AN5="N","N",SUM('調查資料(OUT)'!Q11:Q14)) -> 0 | CH5: =IF($AN5="N","N",SUM('調查資料(OUT)'!U11:U14)) -> 0 | CI5: =IF($AN5="N","N",SUM('調查資料(OUT)'!Y11:Y14)) -> 0 | CJ5: =IF($AN5="N","N",(CF5/CQ5)*100) -> #DIV/0! | CK5: =IF($AN5="N","N",BR5+BW5+CB5+CG5) -> 0 | CL5: =IF($AN5="N","N",(CK5/($CK5+$CM5+$CO5))*100) -> #DIV/0! | CM5: =IF($AN5="N","N",BS5+BX5+CC5+CH5) -> 0 | CN5: =IF($AN5="N","N",(CM5/($CK5+$CM5+$CO5))*100) -> #DIV/0! | CO5: =IF($AN5="N","N",BT5+BY5+CD5+CI5) -> 0 | CP5: =IF($AN5="N","N",(CO5/($CK5+$CM5+$CO5))*100) -> #DIV/0! | CQ5: =IF($AN5="N","N",BQ5+BV5+CA5+CF5) -> 0 | CR5: =IF($AN5="N","N",SUM(M5:M8)) -> 0 | CS5: =IF($AN5="N","N",SUM('調查資料(OUT)'!Z11:Z14)) -> 0 | CT5: =IF($AN5="N","N",SUM('調查資料(OUT)'!AD11:AD14)) -> 0 | CU5: =IF($AN5="N","N",SUM('調查資料(OUT)'!AH11:AH14)) -> 0 | CV5: =IF($AN5="N","N",(CR5/DR5)*100) -> #DIV/0! | CW5: =IF($AN5="N","N",SUM(N5:N8)) -> 0 | CX5: =IF($AN5="N","N",SUM('調查資料(OUT)'!AA11:AA14)) -> 0 | CY5: =IF($AN5="N","N",SUM('調查資料(OUT)'!AE11:AE14)) -> 0 | CZ5: =IF($AN5="N","N",SUM('調查資料(OUT)'!AI11:AI14)) -> 0 | DA5: =IF($AN5="N","N",(CW5/$DR5)*100) -> #DIV/0! | DB5: =IF($AN5="N","N",SUM(O5:O8)) -> 0 | DC5: =IF($AN5="N","N",SUM('調查資料(OUT)'!AB11:AB14)) -> 0 | DD5: =IF($AN5="N","N",SUM('調查資料(OUT)'!AF11:AF14)) -> 0 | DE5: =IF($AN5="N","N",SUM('調查資料(OUT)'!AJ11:AJ14)) -> 0 | DF5: =IF($AN5="N","N",(DB5/$DR5)*100) -> #DIV/0! | DG5: =IF($AN5="N","N",SUM(P5:P8)) -> 0 | DH5: =IF($AN5="N","N",SUM('調查資料(OUT)'!AC11:AC14)) -> 0 | DI5: =IF($AN5="N","N",SUM('調查資料(OUT)'!AG11:AG14)) -> 0 | DJ5: =IF($AN5="N","N",SUM('調查資料(OUT)'!AK11:AK14)) -> 0 | DK5: =IF($AN5="N","N",(DG5/DR5)*100) -> #DIV/0! | DL5: =IF($AN5="N","N",CS5+CX5+DC5+DH5) -> 0 | DM5: =IF($AN5="N","N",(DL5/($DL5+$DN5+$DP5))*100) -> #DIV/0! | DN5: =IF($AN5="N","N",CT5+CY5+DD5+DI5) -> 0 | DO5: =IF($AN5="N","N",(DN5/($DL5+$DN5+$DP5))*100) -> #DIV/0! | DP5: =IF($AN5="N","N",CU5+CZ5+DE5+DJ5) -> 0 | DQ5: =IF($AN5="N","N",(DP5/($DL5+$DN5+$DP5))*100) -> #DIV/0! | DR5: =IF($AN5="N","N",CR5+CW5+DB5+DG5) -> 0 | DS5: =IF($AN5="N","N",SUM(R5:R8)) -> 0 | DT5: =IF($AN5="N","N",SUM('調查資料(OUT)'!AL11:AL14)) -> 0 | DU5: =IF($AN5="N","N",SUM('調查資料(OUT)'!AP11:AP14)) -> 0 | DV5: =IF($AN5="N","N",SUM('調查資料(OUT)'!AT11:AT14)) -> 0 | DW5: =IF($AN5="N","N",(DS5/ES5)*100) -> #DIV/0! | DX5: =IF($AN5="N","N",SUM(S5:S8)) -> 0 | DY5: =IF($AN5="N","N",SUM('調查資料(OUT)'!AM11:AM14)) -> 0 | DZ5: =IF($AN5="N","N",SUM('調查資料(OUT)'!AQ11:AQ14)) -> 0 | EA5: =IF($AN5="N","N",SUM('調查資料(OUT)'!AU11:AU14)) -> 0 | EB5: =IF($AN5="N","N",(DX5/$ES5)*100) -> #DIV/0! | EC5: =IF($AN5="N","N",SUM(T5:T8)) -> 0 | ED5: =IF($AN5="N","N",SUM('調查資料(OUT)'!AN11:AN14)) -> 0 | EE5: =IF($AN5="N","N",SUM('調查資料(OUT)'!AR11:AR14)) -> 0 | EF5: =IF($AN5="N","N",SUM('調查資料(OUT)'!AV11:AV14)) -> 0 | EG5: =IF($AN5="N","N",(EC5/$ES5)*100) -> #DIV/0! | EH5: =IF($AN5="N","N",SUM(U5:U8)) -> 0 | EI5: =IF($AN5="N","N",SUM('調查資料(OUT)'!AO11:AO14)) -> 0 | EJ5: =IF($AN5="N","N",SUM('調查資料(OUT)'!AS11:AS14)) -> 0 | EK5: =IF($AN5="N","N",SUM('調查資料(OUT)'!AW11:AW14)) -> 0 | EL5: =IF($AN5="N","N",(EH5/ES5)*100) -> #DIV/0! | EM5: =IF($AN5="N","N",DT5+DY5+ED5+EI5) -> 0 | EN5: =IF($AN5="N","N",(EM5/($EM5+$EO5+$EQ5))*100) -> #DIV/0! | EO5: =IF($AN5="N","N",DU5+DZ5+EE5+EJ5) -> 0 | EP5: =IF($AN5="N","N",(EO5/($EM5+$EO5+$EQ5))*100) -> #DIV/0! | EQ5: =IF($AN5="N","N",DV5+EA5+EF5+EK5) -> 0 | ER5: =IF($AN5="N","N",(EQ5/($EM5+$EO5+$EQ5))*100) -> #DIV/0! | ES5: =IF($AN5="N","N",DS5+DX5+EC5+EH5) -> 0 | ET5: =IF($AN5="N","N",SUM(W5:W8)) -> 0 | EU5: =IF($AN5="N","N",SUM('調查資料(OUT)'!AX11:AX14)) -> 0 | EV5: =IF($AN5="N","N",SUM('調查資料(OUT)'!BB11:BB14)) -> 0 | EW5: =IF($AN5="N","N",SUM('調查資料(OUT)'!BF11:BF14)) -> 0 | EX5: =IF($AN5="N","N",(ET5/FT5)*100) -> #DIV/0! | EY5: =IF($AN5="N","N",SUM(X5:X8)) -> 0 | EZ5: =IF($AN5="N","N",SUM('調查資料(OUT)'!AY11:AY14)) -> 0 | FA5: =IF($AN5="N","N",SUM('調查資料(OUT)'!BC11:BC14)) -> 0 | FB5: =IF($AN5="N","N",SUM('調查資料(OUT)'!BG11:BG14)) -> 0 | FC5: =IF($AN5="N","N",(EY5/$FT5)*100) -> #DIV/0! | FD5: =IF($AN5="N","N",SUM(Y5:Y8)) -> 0 | FE5: =IF($AN5="N","N",SUM('調查資料(OUT)'!AZ11:AZ14)) -> 0 | FF5: =IF($AN5="N","N",SUM('調查資料(OUT)'!BD11:BD14)) -> 0 | FG5: =IF($AN5="N","N",SUM('調查資料(OUT)'!BH11:BH14)) -> 0 | FH5: =IF($AN5="N","N",(FD5/$FT5)*100) -> #DIV/0! | FI5: =IF($AN5="N","N",SUM(Z5:Z8)) -> 0 | FJ5: =IF($AN5="N","N",SUM('調查資料(OUT)'!BA11:BA14)) -> 0 | FK5: =IF($AN5="N","N",SUM('調查資料(OUT)'!BE11:BE14)) -> 0 | FL5: =IF($AN5="N","N",SUM('調查資料(OUT)'!BI11:BI14)) -> 0 | FM5: =IF($AN5="N","N",(FI5/FT5)*100) -> #DIV/0! | FN5: =IF($AN5="N","N",EU5+EZ5+FE5+FJ5) -> 0 | FO5: =IF($AN5="N","N",(FN5/($FN5+$FP5+$FR5))*100) -> #DIV/0! | FP5: =IF($AN5="N","N",EV5+FA5+FF5+FK5) -> 0 | FQ5: =IF($AN5="N","N",(FP5/($FN5+$FP5+$FR5))*100) -> #DIV/0! | FR5: =IF($AN5="N","N",EW5+FB5+FG5+FL5) -> 0 | FS5: =IF($AN5="N","N",(FR5/($FN5+$FP5+$FR5))*100) -> #DIV/0! | FT5: =IF($AN5="N","N",ET5+EY5+FD5+FI5) -> 0
A6: ='調查資料(OUT)'!A12 -> 15 | B6: =SUM(C6:F6) -> 0 | C6: =IFERROR('調查資料(OUT)'!$B$1*'調查資料(OUT)'!B12,0)+IFERROR('調查資料(OUT)'!$F$1*'調查資料(OUT)'!F12,0)+IFERROR('調查資料(OUT)'!$J$1*'調查資料(OUT)'!J12,0) -> 0 | D6: =IFERROR('調查資料(OUT)'!$C$1*'調查資料(OUT)'!C12,0)+IFERROR('調查資料(OUT)'!$G$1*'調查資料(OUT)'!G12,0)+IFERROR('調查資料(OUT)'!$K$1*'調查資料(OUT)'!K12,0) -> 0 | E6: =IFERROR('調查資料(OUT)'!$D$1*'調查資料(OUT)'!D12,0)+IFERROR('調查資料(OUT)'!$H$1*'調查資料(OUT)'!H12,0)+IFERROR('調查資料(OUT)'!$L$1*'調查資料(OUT)'!L12,0) -> 0 | F6: =IFERROR('調查資料(OUT)'!$E$1*'調查資料(OUT)'!E12,0)+IFERROR('調查資料(OUT)'!$I$1*'調查資料(OUT)'!I12,0)+IFERROR('調查資料(OUT)'!$M$1*'調查資料(OUT)'!M12,0) -> 0 | G6: =SUM(H6:K6) -> 0 | H6: =IFERROR('調查資料(OUT)'!$N$1*'調查資料(OUT)'!N12,0)+IFERROR('調查資料(OUT)'!$R$1*'調查資料(OUT)'!R12,0)+IFERROR('調查資料(OUT)'!$V$1*'調查資料(OUT)'!V12,0) -> 0 | I6: =IFERROR('調查資料(OUT)'!$O$1*'調查資料(OUT)'!O12,0)+IFERROR('調查資料(OUT)'!$S$1*'調查資料(OUT)'!S12,0)+IFERROR('調查資料(OUT)'!$W$1*'調查資料(OUT)'!W12,0) -> 0 | J6: =IFERROR('調查資料(OUT)'!$P$1*'調查資料(OUT)'!P12,0)+IFERROR('調查資料(OUT)'!$T$1*'調查資料(OUT)'!T12,0)+IFERROR('調查資料(OUT)'!$X$1*'調查資料(OUT)'!X12,0) -> 0 | K6: =IFERROR('調查資料(OUT)'!$Q$1*'調查資料(OUT)'!Q12,0)+IFERROR('調查資料(OUT)'!$U$1*'調查資料(OUT)'!U12,0)+IFERROR('調查資料(OUT)'!$Y$1*'調查資料(OUT)'!Y12,0) -> 0 | L6: =SUM(M6:P6) -> 0 | M6: =IFERROR('調查資料(OUT)'!$Z$1*'調查資料(OUT)'!Z12,0)+IFERROR('調查資料(OUT)'!$AD$1*'調查資料(OUT)'!AD12,0)+IFERROR('調查資料(OUT)'!$AH$1*'調查資料(OUT)'!AH12,0) -> 0 | N6: =IFERROR('調查資料(OUT)'!$AA$1*'調查資料(OUT)'!AA12,0)+IFERROR('調查資料(OUT)'!$AE$1*'調查資料(OUT)'!AE12,0)+IFERROR('調查資料(OUT)'!$AI$1*'調查資料(OUT)'!AI12,0) -> 0 | O6: =IFERROR('調查資料(OUT)'!$AB$1*'調查資料(OUT)'!AB12,0)+IFERROR('調查資料(OUT)'!$AF$1*'調查資料(OUT)'!AF12,0)+IFERROR('調查資料(OUT)'!$AJ$1*'調查資料(OUT)'!AJ12,0) -> 0 | P6: =IFERROR('調查資料(OUT)'!$AC$1*'調查資料(OUT)'!AC12,0)+IFERROR('調查資料(OUT)'!$AG$1*'調查資料(OUT)'!AG12,0)+IFERROR('調查資料(OUT)'!$AK$1*'調查資料(OUT)'!AK12,0) -> 0 | Q6: =SUM(R6:U6) -> 0 | R6: =IFERROR('調查資料(OUT)'!$AL$1*'調查資料(OUT)'!AL12,0)+IFERROR('調查資料(OUT)'!$AP$1*'調查資料(OUT)'!AP12,0)+IFERROR('調查資料(OUT)'!$AT$1*'調查資料(OUT)'!AT12,0) -> 0 | S6: =IFERROR('調查資料(OUT)'!$AM$1*'調查資料(OUT)'!AM12,0)+IFERROR('調查資料(OUT)'!$AQ$1*'調查資料(OUT)'!AQ12,0)+IFERROR('調查資料(OUT)'!$AU$1*'調查資料(OUT)'!AU12,0) -> 0 | T6: =IFERROR('調查資料(OUT)'!$AN$1*'調查資料(OUT)'!AN12,0)+IFERROR('調查資料(OUT)'!$AR$1*'調查資料(OUT)'!AR12,0)+IFERROR('調查資料(OUT)'!$AV$1*'調查資料(OUT)'!AV12,0) -> 0 | U6: =IFERROR('調查資料(OUT)'!$AO$1*'調查資料(OUT)'!AO12,0)+IFERROR('調查資料(OUT)'!$AS$1*'調查資料(OUT)'!AS12,0)+IFERROR('調查資料(OUT)'!$AW$1*'調查資料(OUT)'!AW12,0) -> 0 | V6: =SUM(W6:Z6) -> 0 | W6: =IFERROR('調查資料(OUT)'!$AX$1*'調查資料(OUT)'!AX12,0)+IFERROR('調查資料(OUT)'!$BB$1*'調查資料(OUT)'!BB12,0)+IFERROR('調查資料(OUT)'!$BF$1*'調查資料(OUT)'!BF12,0) -> 0 | X6: =IFERROR('調查資料(OUT)'!$AY$1*'調查資料(OUT)'!AY12,0)+IFERROR('調查資料(OUT)'!$BC$1*'調查資料(OUT)'!BC12,0)+IFERROR('調查資料(OUT)'!$BG$1*'調查資料(OUT)'!BG12,0) -> 0 | Y6: =IFERROR('調查資料(OUT)'!$AZ$1*'調查資料(OUT)'!AZ12,0)+IFERROR('調查資料(OUT)'!$BD$1*'調查資料(OUT)'!BD12,0)+IFERROR('調查資料(OUT)'!$BH$1*'調查資料(OUT)'!BH12,0) -> 0 | Z6: =IFERROR('調查資料(OUT)'!$BA$1*'調查資料(OUT)'!BA12,0)+IFERROR('調查資料(OUT)'!$BE$1*'調查資料(OUT)'!BE12,0)+IFERROR('調查資料(OUT)'!$BI$1*'調查資料(OUT)'!BI12,0) -> 0 | AA6: =B6+G6+L6+Q6+V6 -> 0 | AC6: ='調查資料(OUT)'!A12 -> 15 | AD6: =AC6+100 -> 115 | AE6: =SUM(AA6:AA9) -> 0 | AG6: =IF($AE6=$AF$5,MAX(AA6:AA9),0) -> 0 | AH6: =IF($AE6=AF$5,SUM(B6:B9)/(4*(MAX(B6:B9))),0) -> #DIV/0! | AI6: =IF($AE6=AF$5,SUM(G6:G9)/(4*(MAX(G6:G9))),0) -> #DIV/0! | AJ6: =IF($AE6=AF$5,SUM(L6:L9)/(4*(MAX(L6:L9))),0) -> #DIV/0! | AK6: =IF($AE6=AF$5,SUM(Q6:Q9)/(4*(MAX(Q6:Q9))),0) -> #DIV/0! | AL6: =IF($AE6=AF$5,SUM(V6:V9)/(4*(MAX(V6:V9))),0) -> #DIV/0! | AN6: =IF(AE6=AF$5,$AC6,"N") -> 15 | AO6: =IF(AE6=AF$5,$AD6,"N") -> 115 | AP6: =IF($AN6="N","N",SUM(C6:C9)) -> 0 | AQ6: =IF($AN6="N","N",SUM('調查資料(OUT)'!B12:B15)) -> 0 | AR6: =IF($AN6="N","N",SUM('調查資料(OUT)'!F12:F15)) -> 0 | AS6: =IF($AN6="N","N",SUM('調查資料(OUT)'!J12:J15)) -> 0 | AT6: =IF($AN6="N","N",(AP6/$BP6)*100) -> #DIV/0! | AU6: =IF($AN6="N","N",SUM(D6:D9)) -> 0 | AV6: =IF($AN6="N","N",SUM('調查資料(OUT)'!C12:C15)) -> 0 | AW6: =IF($AN6="N","N",SUM('調查資料(OUT)'!G12:G15)) -> 0 | AX6: =IF($AN6="N","N",SUM('調查資料(OUT)'!K12:K15)) -> 0 | AY6: =IF($AN6="N","N",(AU6/$BP6)*100) -> #DIV/0! | AZ6: =IF($AN6="N","N",SUM(E6:E9)) -> 0 | BA6: =IF($AN6="N","N",SUM('調查資料(OUT)'!D12:D15)) -> 0 | BB6: =IF($AN6="N","N",SUM('調查資料(OUT)'!H12:H15)) -> 0 | BC6: =IF($AN6="N","N",SUM('調查資料(OUT)'!L12:L15)) -> 0 | BD6: =IF($AN6="N","N",(AZ6/$BP6)*100) -> #DIV/0! | BE6: =IF($AN6="N","N",SUM(F6:F9)) -> 0 | BF6: =IF($AN6="N","N",SUM('調查資料(OUT)'!E12:E15)) -> 0 | BG6: =IF($AN6="N","N",SUM('調查資料(OUT)'!I12:I15)) -> 0 | BH6: =IF($AN6="N","N",SUM('調查資料(OUT)'!M12:M15)) -> 0 | BI6: =IF($AN6="N","N",(BE6/$BP6)*100) -> #DIV/0! | BJ6: =IF($AN6="N","N",AQ6+AV6+BA6+BF6) -> 0 | BK6: =IF($AN6="N","N",(BJ6/($BJ6+$BL6+$BN6))*100) -> #DIV/0! | BL6: =IF($AN6="N","N",AR6+AW6+BB6+BG6) -> 0 | BM6: =IF($AN6="N","N",(BL6/($BJ6+$BL6+$BN6))*100) -> #DIV/0! | BN6: =IF($AN6="N","N",AS6+AX6+BC6+BH6) -> 0 | BO6: =IF($AN6="N","N",(BN6/($BJ6+$BL6+$BN6))*100) -> #DIV/0! | BP6: =IF($AN6="N","N",AP6+AU6+AZ6+BE6) -> 0 | BQ6: =IF($AN6="N","N",SUM(H6:H9)) -> 0 | BR6: =IF($AN6="N","N",SUM('調查資料(OUT)'!N12:N15)) -> 0 | BS6: =IF($AN6="N","N",SUM('調查資料(OUT)'!R12:R15)) -> 0 | BT6: =IF($AN6="N","N",SUM('調查資料(OUT)'!V12:V15)) -> 0 | BU6: =IF($AN6="N","N",(BQ6/CQ6)*100) -> #DIV/0! | BV6: =IF($AN6="N","N",SUM(I6:I9)) -> 0 | BW6: =IF($AN6="N","N",SUM('調查資料(OUT)'!O12:O15)) -> 0 | BX6: =IF($AN6="N","N",SUM('調查資料(OUT)'!S12:S15)) -> 0 | BY6: =IF($AN6="N","N",SUM('調查資料(OUT)'!W12:W15)) -> 0 | BZ6: =IF($AN6="N","N",(BV6/$CQ6)*100) -> #DIV/0! | CA6: =IF($AN6="N","N",SUM(J6:J9)) -> 0 | CB6: =IF($AN6="N","N",SUM('調查資料(OUT)'!P12:P15)) -> 0 | CC6: =IF($AN6="N","N",SUM('調查資料(OUT)'!T12:T15)) -> 0 | CD6: =IF($AN6="N","N",SUM('調查資料(OUT)'!X12:X15)) -> 0 | CE6: =IF($AN6="N","N",(CA6/$CQ6)*100) -> #DIV/0! | CF6: =IF($AN6="N","N",SUM(K6:K9)) -> 0 | CG6: =IF($AN6="N","N",SUM('調查資料(OUT)'!Q12:Q15)) -> 0 | CH6: =IF($AN6="N","N",SUM('調查資料(OUT)'!U12:U15)) -> 0 | CI6: =IF($AN6="N","N",SUM('調查資料(OUT)'!Y12:Y15)) -> 0 | CJ6: =IF($AN6="N","N",(CF6/CQ6)*100) -> #DIV/0! | CK6: =IF($AN6="N","N",BR6+BW6+CB6+CG6) -> 0 | CL6: =IF($AN6="N","N",(CK6/($CK6+$CM6+$CO6))*100) -> #DIV/0! | CM6: =IF($AN6="N","N",BS6+BX6+CC6+CH6) -> 0 | CN6: =IF($AN6="N","N",(CM6/($CK6+$CM6+$CO6))*100) -> #DIV/0! | CO6: =IF($AN6="N","N",BT6+BY6+CD6+CI6) -> 0 | CP6: =IF($AN6="N","N",(CO6/($CK6+$CM6+$CO6))*100) -> #DIV/0! | CQ6: =IF($AN6="N","N",BQ6+BV6+CA6+CF6) -> 0 | CR6: =IF($AN6="N","N",SUM(M6:M9)) -> 0 | CS6: =IF($AN6="N","N",SUM('調查資料(OUT)'!Z12:Z15)) -> 0 | CT6: =IF($AN6="N","N",SUM('調查資料(OUT)'!AD12:AD15)) -> 0 | CU6: =IF($AN6="N","N",SUM('調查資料(OUT)'!AH12:AH15)) -> 0 | CV6: =IF($AN6="N","N",(CR6/DR6)*100) -> #DIV/0! | CW6: =IF($AN6="N","N",SUM(N6:N9)) -> 0 | CX6: =IF($AN6="N","N",SUM('調查資料(OUT)'!AA12:AA15)) -> 0 | CY6: =IF($AN6="N","N",SUM('調查資料(OUT)'!AE12:AE15)) -> 0 | CZ6: =IF($AN6="N","N",SUM('調查資料(OUT)'!AI12:AI15)) -> 0 | DA6: =IF($AN6="N","N",(CW6/$DR6)*100) -> #DIV/0! | DB6: =IF($AN6="N","N",SUM(O6:O9)) -> 0 | DC6: =IF($AN6="N","N",SUM('調查資料(OUT)'!AB12:AB15)) -> 0 | DD6: =IF($AN6="N","N",SUM('調查資料(OUT)'!AF12:AF15)) -> 0 | DE6: =IF($AN6="N","N",SUM('調查資料(OUT)'!AJ12:AJ15)) -> 0 | DF6: =IF($AN6="N","N",(DB6/$DR6)*100) -> #DIV/0! | DG6: =IF($AN6="N","N",SUM(P6:P9)) -> 0 | DH6: =IF($AN6="N","N",SUM('調查資料(OUT)'!AC12:AC15)) -> 0 | DI6: =IF($AN6="N","N",SUM('調查資料(OUT)'!AG12:AG15)) -> 0 | DJ6: =IF($AN6="N","N",SUM('調查資料(OUT)'!AK12:AK15)) -> 0 | DK6: =IF($AN6="N","N",(DG6/DR6)*100) -> #DIV/0! | DL6: =IF($AN6="N","N",CS6+CX6+DC6+DH6) -> 0 | DM6: =IF($AN6="N","N",(DL6/($DL6+$DN6+$DP6))*100) -> #DIV/0! | DN6: =IF($AN6="N","N",CT6+CY6+DD6+DI6) -> 0 | DO6: =IF($AN6="N","N",(DN6/($DL6+$DN6+$DP6))*100) -> #DIV/0! | DP6: =IF($AN6="N","N",CU6+CZ6+DE6+DJ6) -> 0 | DQ6: =IF($AN6="N","N",(DP6/($DL6+$DN6+$DP6))*100) -> #DIV/0! | DR6: =IF($AN6="N","N",CR6+CW6+DB6+DG6) -> 0 | DS6: =IF($AN6="N","N",SUM(R6:R9)) -> 0 | DT6: =IF($AN6="N","N",SUM('調查資料(OUT)'!AL12:AL15)) -> 0 | DU6: =IF($AN6="N","N",SUM('調查資料(OUT)'!AP12:AP15)) -> 0 | DV6: =IF($AN6="N","N",SUM('調查資料(OUT)'!AT12:AT15)) -> 0 | DW6: =IF($AN6="N","N",(DS6/ES6)*100) -> #DIV/0! | DX6: =IF($AN6="N","N",SUM(S6:S9)) -> 0 | DY6: =IF($AN6="N","N",SUM('調查資料(OUT)'!AM12:AM15)) -> 0 | DZ6: =IF($AN6="N","N",SUM('調查資料(OUT)'!AQ12:AQ15)) -> 0 | EA6: =IF($AN6="N","N",SUM('調查資料(OUT)'!AU12:AU15)) -> 0 | EB6: =IF($AN6="N","N",(DX6/$ES6)*100) -> #DIV/0! | EC6: =IF($AN6="N","N",SUM(T6:T9)) -> 0 | ED6: =IF($AN6="N","N",SUM('調查資料(OUT)'!AN12:AN15)) -> 0 | EE6: =IF($AN6="N","N",SUM('調查資料(OUT)'!AR12:AR15)) -> 0 | EF6: =IF($AN6="N","N",SUM('調查資料(OUT)'!AV12:AV15)) -> 0 | EG6: =IF($AN6="N","N",(EC6/$ES6)*100) -> #DIV/0! | EH6: =IF($AN6="N","N",SUM(U6:U9)) -> 0 | EI6: =IF($AN6="N","N",SUM('調查資料(OUT)'!AO12:AO15)) -> 0 | EJ6: =IF($AN6="N","N",SUM('調查資料(OUT)'!AS12:AS15)) -> 0 | EK6: =IF($AN6="N","N",SUM('調查資料(OUT)'!AW12:AW15)) -> 0 | EL6: =IF($AN6="N","N",(EH6/ES6)*100) -> #DIV/0! | EM6: =IF($AN6="N","N",DT6+DY6+ED6+EI6) -> 0 | EN6: =IF($AN6="N","N",(EM6/($EM6+$EO6+$EQ6))*100) -> #DIV/0! | EO6: =IF($AN6="N","N",DU6+DZ6+EE6+EJ6) -> 0 | EP6: =IF($AN6="N","N",(EO6/($EM6+$EO6+$EQ6))*100) -> #DIV/0! | EQ6: =IF($AN6="N","N",DV6+EA6+EF6+EK6) -> 0 | ER6: =IF($AN6="N","N",(EQ6/($EM6+$EO6+$EQ6))*100) -> #DIV/0! | ES6: =IF($AN6="N","N",DS6+DX6+EC6+EH6) -> 0 | ET6: =IF($AN6="N","N",SUM(W6:W9)) -> 0 | EU6: =IF($AN6="N","N",SUM('調查資料(OUT)'!AX12:AX15)) -> 0 | EV6: =IF($AN6="N","N",SUM('調查資料(OUT)'!BB12:BB15)) -> 0 | EW6: =IF($AN6="N","N",SUM('調查資料(OUT)'!BF12:BF15)) -> 0 | EX6: =IF($AN6="N","N",(ET6/FT6)*100) -> #DIV/0! | EY6: =IF($AN6="N","N",SUM(X6:X9)) -> 0 | EZ6: =IF($AN6="N","N",SUM('調查資料(OUT)'!AY12:AY15)) -> 0 | FA6: =IF($AN6="N","N",SUM('調查資料(OUT)'!BC12:BC15)) -> 0 | FB6: =IF($AN6="N","N",SUM('調查資料(OUT)'!BG12:BG15)) -> 0 | FC6: =IF($AN6="N","N",(EY6/$FT6)*100) -> #DIV/0! | FD6: =IF($AN6="N","N",SUM(Y6:Y9)) -> 0 | FE6: =IF($AN6="N","N",SUM('調查資料(OUT)'!AZ12:AZ15)) -> 0 | FF6: =IF($AN6="N","N",SUM('調查資料(OUT)'!BD12:BD15)) -> 0 | FG6: =IF($AN6="N","N",SUM('調查資料(OUT)'!BH12:BH15)) -> 0 | FH6: =IF($AN6="N","N",(FD6/$FT6)*100) -> #DIV/0! | FI6: =IF($AN6="N","N",SUM(Z6:Z9)) -> 0 | FJ6: =IF($AN6="N","N",SUM('調查資料(OUT)'!BA12:BA15)) -> 0 | FK6: =IF($AN6="N","N",SUM('調查資料(OUT)'!BE12:BE15)) -> 0 | FL6: =IF($AN6="N","N",SUM('調查資料(OUT)'!BI12:BI15)) -> 0 | FM6: =IF($AN6="N","N",(FI6/FT6)*100) -> #DIV/0! | FN6: =IF($AN6="N","N",EU6+EZ6+FE6+FJ6) -> 0 | FO6: =IF($AN6="N","N",(FN6/($FN6+$FP6+$FR6))*100) -> #DIV/0! | FP6: =IF($AN6="N","N",EV6+FA6+FF6+FK6) -> 0 | FQ6: =IF($AN6="N","N",(FP6/($FN6+$FP6+$FR6))*100) -> #DIV/0! | FR6: =IF($AN6="N","N",EW6+FB6+FG6+FL6) -> 0 | FS6: =IF($AN6="N","N",(FR6/($FN6+$FP6+$FR6))*100) -> #DIV/0! | FT6: =IF($AN6="N","N",ET6+EY6+FD6+FI6) -> 0
