Workbook
Name _PCU11: [1]基本!$B$35
Name _PCU12: [1]基本!$C$35
Name _PCU13: [1]基本!$D$35
Name _PCU14: [1]基本!$E$35
Name _PCU21: [1]基本!$F$35
Name _PCU22: [1]基本!$G$35
Name _PCU23: [1]基本!$H$35
Name _PCU31: [1]基本!$I$35
Name _PCU32: [1]基本!$J$35
Name _PCU33: [1]基本!$K$35
Name GAM: #REF!
Name GINFO: #REF!
Name GPM: #REF!
Name GRAPH: #REF!
Name HN: [1]集賢!$M$1
Name ROADNAME: [2]基本!$I$5,[2]基本!$G$9,[2]基本!$E$5,[2]基本!$G$1
Name TABLE: #REF!
Name 尖峰: #REF!
Name 夜間: #REF!
Name 時制A: #REF!,#REF!,#REF!,#REF!,#REF!
Name 時制B: #REF!,#REF!,#REF!,#REF!,#REF!
Name 假日: #REF!
Name 週五夜: #REF!
Name 離峰: #REF!

Sheet 轉向量
A1: 臨近路段 | B1: 起始時間 | C1: 結束時間 | D1: 大車A | E1: 大車B | F1: 大車C | G1: 大車D | H1: 大車E | I1: 大車F | J1: 小車A | K1: 小車B | L1: 小車C | M1: 小車D | N1: 小車E | O1: 小車F | P1: 機車A | Q1: 機車B | R1: 機車C | S1: 機車D | T1: 機車E | U1: 機車F
A2: A | B2: 0 | C2: 0.010416667 | D2: - | J2: - | P2: -
A3: A | B3: 0.010416667 | C3: 0.020833333 | D3: - | J3: - | P3: -
A4: A | B4: 0.020833333 | C4: 0.03125 | D4: - | J4: - | P4: -
A5: A | B5: 0.03125 | C5: 0.041666667 | D5: - | J5: - | P5: -
A6: A | B6: 0.041666667 | C6: 0.052083333 | D6: - | J6: - | P6: -
A7: A | B7: 0.052083333 | C7: 0.0625 | D7: - | J7: - | P7: -
A8: A | B8: 0.0625 | C8: 0.072916667 | D8: - | J8: - | P8: -
A9: A | B9: 0.072916667 | C9: 0.083333333 | D9: - | J9: - | P9: -
A10: A | B10: 0.083333333 | C10: 0.09375 | D10: - | J10: - | P10: -
A11: A | B11: 0.09375 | C11: 0.10416667 | D11: - | J11: - | P11: -
A12: A | B12: 0.10416667 | C12: 0.11458333 | D12: - | J12: - | P12: -
A13: A | B13: 0.11458333 | C13: 0.125 | D13: - | J13: - | P13: -
... A96: A | B96: 0.97916667 | C96: 0.98958333 | D96: - | J96: - | P96: -
A97: A | B97: 0.98958333 | C97: 24:00 | D97: - | J97: - | P97: -
A98: B | B98: 0 | C98: 0.010416667 | E98: - | K98: - | Q98: -
A99: B | B99: 0.010416667 | C99: 0.020833333 | E99: - | K99: - | Q99: -
A100: B | B100: 0.020833333 | C100: 0.03125 | E100: - | K100: - | Q100: -
A101: B | B101: 0.03125 | C101: 0.041666667 | E101: - | K101: - | Q101: -
A102: B | B102: 0.041666667 | C102: 0.052083333 | E102: - | K102: - | Q102: -
A103: B | B103: 0.052083333 | C103: 0.0625 | E103: - | K103: - | Q103: -
A104: B | B104: 0.0625 | C104: 0.072916667 | E104: - | K104: - | Q104: -
A105: B | B105: 0.072916667 | C105: 0.083333333 | E105: - | K105: - | Q105: -
A106: B | B106: 0.083333333 | C106: 0.09375 | E106: - | K106: - | Q106: -
A107: B | B107: 0.09375 | C107: 0.10416667 | E107: - | K107: - | Q107: -
A108: B | B108: 0.10416667 | C108: 0.11458333 | E108: - | K108: - | Q108: -
A109: B | B109: 0.11458333 | C109: 0.125 | E109: - | K109: - | Q109: -
... A192: B | B192: 0.97916667 | C192: 0.98958333 | E192: - | K192: - | Q192: -
A193: B | B193: 0.98958333 | C193: 24:00 | E193: - | K193: - | Q193: -
A194: C | B194: 0 | C194: 0.010416667 | F194: - | L194: - | R194: -
A195: C | B195: 0.010416667 | C195: 0.020833333 | F195: - | L195: - | R195: -
A196: C | B196: 0.020833333 | C196: 0.03125 | F196: - | L196: - | R196: -
A197: C | B197: 0.03125 | C197: 0.041666667 | F197: - | L197: - | R197: -
A198: C | B198: 0.041666667 | C198: 0.052083333 | F198: - | L198: - | R198: -
A199: C | B199: 0.052083333 | C199: 0.0625 | F199: - | L199: - | R199: -
A200: C | B200: 0.0625 | C200: 0.072916667 | F200: - | L200: - | R200: -
A201: C | B201: 0.072916667 | C201: 0.083333333 | F201: - | L201: - | R201: -
A202: C | B202: 0.083333333 | C202: 0.09375 | F202: - | L202: - | R202: -
A203: C | B203: 0.09375 | C203: 0.10416667 | F203: - | L203: - | R203: -
A204: C | B204: 0.10416667 | C204: 0.11458333 | F204: - | L204: - | R204: -
...

Sheet 路口基本資料
A1: 業主名稱： | G1: 簡圖： | I1: =F15 -> 0 | J1: =G15 -> 0 | L1: N
A2: 專案編號： | I2: E | J2: F | L2: ↑
A4: TC編號：
A5: 路口名稱： | G5: =E15 -> 0 | H5: D | K5: A | L5: =B15 -> 0
A6: 行政區域：
A8: 日期： | B8: YYYY/MM/DD | I8: C | J8: B
A9: 平假日： | I9: =D15 -> 0 | J9: =C15 -> 0
A10: 調查時段：
A11: 天候：
A13: 路口類型： | B13: 六叉路口
A14: 方向： | B14: A | C14: B | D14: C | E14: D | F14: E | G14: F
A15: 路段名：
A16: 車道數：
A17: 行車方向： | B17: 往西 | C17: 往西北 | D17: 往東北 | E17: 往東 | F17: 往東南 | G17: 往西南
A18: 往A方向： | B18: - | C18: 請選擇 | D18: 請選擇 | E18: 請選擇 | F18: 請選擇 | G18: 請選擇
A19: 往B方向： | B19: 請選擇 | C19: - | D19: 請選擇 | E19: 請選擇 | F19: 請選擇 | G19: 請選擇
A20: 往C方向： | B20: 請選擇 | C20: 請選擇 | D20: - | E20: 請選擇 | F20: 請選擇 | G20: 請選擇
A21: 往D方向： | B21: 請選擇 | C21: 請選擇 | D21: 請選擇 | E21: - | F21: 請選擇 | G21: 請選擇
A22: 往E方向： | B22: 請選擇 | C22: 請選擇 | D22: 請選擇 | E22: 請選擇 | F22: - | G22: 請選擇
A23: 往F方向： | B23: 請選擇 | C23: 請選擇 | D23: 請選擇 | E23: 請選擇 | F23: 請選擇 | G23: -
A24: 車種設定
A25: 大型車1 | C25: 小型車1 | E25: 機車1 | G25: 特殊1
A26: 大型車2 | C26: 小型車2 | E26: 機車2 | G26: 特殊2
A27: 大型車3 | C27: 小型車3 | E27: 機車3
A28: 大型車4 | C28: 小型車4
A29: 大型車5
A30: 大型車6

Sheet 調查資料(OUT)
A1: 套用PCE | B1: =IF(路口基本資料!$B$16="左轉",1.9, IF(路口基本資料!$B$16="右轉",2.5,1.8)) -> 1.8 | C1: =IF(路口基本資料!$B$17="左轉",1.9, IF(路口基本資料!$B$17="右轉",2.5,1.8)) -> 1.8 | D1: =IF(路口基本資料!$B$18="左轉",1.9, IF(路口基本資料!$B$18="右轉",2.5,1.8)) -> 1.8 | E1: =IF(路口基本資料!$B$19="左轉",1.9, IF(路口基本資料!$B$19="右轉",2.5,1.8)) -> 1.8 | F1: =IF(路口基本資料!$B$20="左轉",1.9, IF(路口基本資料!$B$20="右轉",2.5,1.8)) -> 1.8 | G1: 1 | H1: 1 | I1: 1 | J1: 1 | K1: 1 | L1: =IF(路口基本資料!$B$16="左轉",0.41,0.42) -> 0.42 | M1: =IF(路口基本資料!$B$17="左轉",0.41,0.42) -> 0.42 | N1: =IF(路口基本資料!$B$18="左轉",0.41,0.42) -> 0.42 | O1: =IF(路口基本資料!$B$19="左轉",0.41,0.42) -> 0.42 | P1: =IF(路口基本資料!$B$20="左轉",0.41,0.42) -> 0.42 | Q1: =IF(路口基本資料!$C$15="左轉",1.9, IF(路口基本資料!$C$15="右轉",2.5,1.8)) -> 1.8 | R1: =IF(路口基本資料!$C$17="左轉",1.9, IF(路口基本資料!$C$17="右轉",2.5,1.8)) -> 1.8 | S1: =IF(路口基本資料!$C$18="左轉",1.9, IF(路口基本資料!$C$18="右轉",2.5,1.8)) -> 1.8 | T1: =IF(路口基本資料!$C$19="左轉",1.9, IF(路口基本資料!$C$19="右轉",2.5,1.8)) -> 1.8 | U1: =IF(路口基本資料!$C$20="左轉",1.9, IF(路口基本資料!$C$20="右轉",2.5,1.8)) -> 1.8 | V1: 1 | W1: 1 | X1: 1 | Y1: 1 | Z1: 1 | AA1: =IF(路口基本資料!$C$15="左轉",0.41,0.42) -> 0.42 | AB1: =IF(路口基本資料!$C$17="左轉",0.41,0.42) -> 0.42 | AC1: =IF(路口基本資料!$C$18="左轉",0.41,0.42) -> 0.42 | AD1: =IF(路口基本資料!$C$19="左轉",0.41,0.42) -> 0.42 | AE1: =IF(路口基本資料!$C$20="左轉",0.41,0.42) -> 0.42 | AF1: =IF(路口基本資料!$D$15="左轉",1.9, IF(路口基本資料!$D$15="右轉",2.5,1.8)) -> 1.8 | AG1: =IF(路口基本資料!$D$16="左轉",1.9, IF(路口基本資料!$D$16="右轉",2.5,1.8)) -> 1.8 | AH1: =IF(路口基本資料!$D$18="左轉",1.9, IF(路口基本資料!$D$18="右轉",2.5,1.8)) -> 1.8 | AI1: =IF(路口基本資料!$D$19="左轉",1.9, IF(路口基本資料!$D$19="右轉",2.5,1.8)) -> 1.8 | AJ1: =IF(路口基本資料!$D$20="左轉",1.9, IF(路口基本資料!$D$20="右轉",2.5,1.8)) -> 1.8 | AK1: 1 | AL1: 1 | AM1: 1 | AN1: 1 | AO1: 1 | AP1: =IF(路口基本資料!$D$15="左轉",0.41,0.42) -> 0.42 | AQ1: =IF(路口基本資料!$D$16="左轉",0.41,0.42) -> 0.42 | AR1: =IF(路口基本資料!$D$18="左轉",0.41,0.42) -> 0.42 | AS1: =IF(路口基本資料!$D$19="左轉",0.41,0.42) -> 0.42 | AT1: =IF(路口基本資料!$D$20="左轉",0.41,0.42) -> 0.42 | AU1: =IF(路口基本資料!$E$15="左轉",1.9, IF(路口基本資料!$E$15="右轉",2.5,1.8)) -> 1.8 | AV1: =IF(路口基本資料!$E$16="左轉",1.9, IF(路口基本資料!$E$16="右轉",2.5,1.8)) -> 1.8 | AW1: =IF(路口基本資料!$E$17="左轉",1.9, IF(路口基本資料!$E$17="右轉",2.5,1.8)) -> 1.8 | AX1: =IF(路口基本資料!$E$19="左轉",1.9, IF(路口基本資料!$E$19="右轉",2.5,1.8)) -> 1.8 | AY1: =IF(路口基本資料!$E$20="左轉",1.9, IF(路口基本資料!$E$20="右轉",2.5,1.8)) -> 1.8 | AZ1: 1 | BA1: 1 | BB1: 1 | BC1: 1 | BD1: 1 | BE1: =IF(路口基本資料!$E$15="左轉",0.41,0.42) -> 0.42 | BF1: =IF(路口基本資料!$E$16="左轉",0.41,0.42) -> 0.42 | BG1: =IF(路口基本資料!$E$17="左轉",0.41,0.42) -> 0.42 | BH1: =IF(路口基本資料!$E$19="左轉",0.41,0.42) -> 0.42 | BI1: =IF(路口基本資料!$E$20="左轉",0.41,0.42) -> 0.42 | BJ1: =IF(路口基本資料!$F$15="左轉",1.9, IF(路口基本資料!$F$15="右轉",2.5,1.8)) -> 1.8 | BK1: =IF(路口基本資料!$F$16="左轉",1.9, IF(路口基本資料!$F$16="右轉",2.5,1.8)) -> 1.8 | BL1: =IF(路口基本資料!$F$17="左轉",1.9, IF(路口基本資料!$F$17="右轉",2.5,1.8)) -> 1.8 | BM1: =IF(路口基本資料!$F$18="左轉",1.9, IF(路口基本資料!$F$18="右轉",2.5,1.8)) -> 1.8 | BN1: =IF(路口基本資料!$F$20="左轉",1.9, IF(路口基本資料!$F$20="右轉",2.5,1.8)) -> 1.8 | BO1: 1 | BP1: 1 | BQ1: 1 | BR1: 1 | BS1: 1 | BT1: =IF(路口基本資料!$F$15="左轉",0.41,0.42) -> 0.42 | BU1: =IF(路口基本資料!$F$16="左轉",0.41,0.42) -> 0.42 | BV1: =IF(路口基本資料!$F$17="左轉",0.41,0.42) -> 0.42 | BW1: =IF(路口基本資料!$F$18="左轉",0.41,0.42) -> 0.42 | BX1: =IF(路口基本資料!$F$20="左轉",0.41,0.42) -> 0.42 | BY1: =IF(路口基本資料!$G$15="左轉",1.9, IF(路口基本資料!$G$15="右轉",2.5,1.8)) -> 1.8 | BZ1: =IF(路口基本資料!$G$16="左轉",1.9, IF(路口基本資料!$G$16="右轉",2.5,1.8)) -> 1.8 | CA1: =IF(路口基本資料!$G$17="左轉",1.9, IF(路口基本資料!$G$17="右轉",2.5,1.8)) -> 1.8 | CB1: =IF(路口基本資料!$G$18="左轉",1.9, IF(路口基本資料!$G$18="右轉",2.5,1.8)) -> 1.8 | CC1: =IF(路口基本資料!$G$19="左轉",1.9, IF(路口基本資料!$G$19="右轉",2.5,1.8)) -> 1.8 | CD1: 1 | CE1: 1 | CF1: 1 | CG1: 1 | CH1: 1 | CI1: =IF(路口基本資料!$G$15="左轉",0.41,0.42) -> 0.42 | CJ1: =IF(路口基本資料!$G$16="左轉",0.41,0.42) -> 0.42 | CK1: =IF(路口基本資料!$G$17="左轉",0.41,0.42) -> 0.42 | CL1: =IF(路口基本資料!$G$18="左轉",0.41,0.42) -> 0.42 | CM1: =IF(路口基本資料!$G$19="左轉",0.41,0.42) -> 0.42
B3: ※註： 1. 行車方向若無車輛通過，表示為"0" 2. 若該行車方向為禁行方向，或為非調查時段，表示為"-"
EZ5: =IF($AB5="N","N",SUM('調查資料(OUT)'!#REF!)) -> #REF!
B8: ←A | C8: =路口基本資料!$B$12 -> 0 | G8: 車道數 | H8: =路口基本資料!$B$13 -> 六叉路口 | Q8: ↑B | R8: =路口基本資料!$C$12 -> 0 | V8: 車道數 | W8: =路口基本資料!$C$13 -> 0 | AF8: ↑C | AG8: =路口基本資料!$D$12 -> 0 | AK8: 車道數 | AL8: =路口基本資料!$D$13 -> 0 | AU8: →D | AV8: =路口基本資料!$E$12 -> 0 | AZ8: 車道數 | BA8: =路口基本資料!$E$13 -> 0 | BJ8: ↓E | BK8: =路口基本資料!$F$12 -> 0 | BO8: 車道數 | BP8: =路口基本資料!$F$13 -> 0 | BY8: ↓F | BZ8: =路口基本資料!$G$12 -> 0 | CD8: 車道數 | CE8: =路口基本資料!$G$13 -> 0
A9: 調查 開始時間 | B9: 大型車 | G9: 小型車 | L9: 機車 | Q9: 大型車 | V9: 小型車 | AA9: 機車 | AF9: 大型車 | AK9: 小型車 | AP9: 機車 | AU9: 大型車 | AZ9: 小型車 | BE9: 機車 | BJ9: 大型車 | BO9: 小型車 | BT9: 機車 | BY9: 大型車 | CD9: 小型車 | CI9: 機車
B10: B | C10: C | D10: D | E10: E | F10: F | G10: B | H10: C | I10: D | J10: E | K10: F | L10: B | M10: C | N10: D | O10: E | P10: F | Q10: A | R10: C | S10: D | T10: E | U10: F | V10: A | W10: C | X10: D | Y10: E | Z10: F | AA10: A | AB10: C | AC10: D | AD10: E | AE10: F | AF10: A | AG10: B | AH10: D | AI10: E | AJ10: F | AK10: A | AL10: B | AM10: D | AN10: E | AO10: F | AP10: A | AQ10: B | AR10: D | AS10: E | AT10: F | AU10: A | AV10: B | AW10: C | AX10: E | AY10: F | AZ10: A | BA10: B | BB10: C | BC10: E | BD10: F | BE10: A | BF10: B | BG10: C | BH10: E | BI10: F | BJ10: A | BK10: B | BL10: C | BM10: D | BN10: F | BO10: A | BP10: B | BQ10: C | BR10: D | BS10: F | BT10: A | BU10: B | BV10: C | BW10: D | BX10: F | BY10: A | BZ10: B | CA10: C | CB10: D | CC10: F | CD10: A | CE10: B | CF10: C | CG10: D | CH10: F | CI10: A | CJ10: B | CK10: C | CL10: D | CM10: F
A11: 0 | B11: =轉向量!E2 -> 0 | C11: =轉向量!F2 -> 0 | D11: =轉向量!G2 -> 0 | E11: =轉向量!H2 -> 0 | F11: =轉向量!I2 -> 0 | G11: =轉向量!K2 -> 0 | H11: =轉向量!L2 -> 0 | I11: =轉向量!M2 -> 0 | J11: =轉向量!N2 -> 0 | K11: =轉向量!O2 -> 0 | L11: =轉向量!Q2 -> 0 | M11: =轉向量!R2 -> 0 | N11: =轉向量!S2 -> 0 | O11: =轉向量!T2 -> 0 | P11: =轉向量!U2 -> 0 | Q11: =轉向量!D98 -> 0 | R11: =轉向量!F98 -> 0 | S11: =轉向量!G98 -> 0 | T11: =轉向量!H98 -> 0 | U11: =轉向量!I98 -> 0 | V11: =轉向量!J98 -> 0 | W11: =轉向量!L98 -> 0 | X11: =轉向量!M98 -> 0 | Y11: =轉向量!N98 -> 0 | Z11: =轉向量!O98 -> 0 | AA11: =轉向量!P98 -> 0 | AB11: =轉向量!R98 -> 0 | AC11: =轉向量!S98 -> 0 | AD11: =轉向量!T98 -> 0 | AE11: =轉向量!U98 -> 0 | AF11: =轉向量!D194 -> 0 | AG11: =轉向量!E194 -> 0 | AH11: =轉向量!G194 -> 0 | AI11: =轉向量!H194 -> 0 | AJ11: =轉向量!I194 -> 0 | AK11: =轉向量!J194 -> 0 | AL11: =轉向量!K194 -> 0 | AM11: =轉向量!M194 -> 0 | AN11: =轉向量!N194 -> 0 | AO11: =轉向量!O194 -> 0 | AP11: =轉向量!P194 -> 0 | AQ11: =轉向量!Q194 -> 0 | AR11: =轉向量!S194 -> 0 | AS11: =轉向量!T194 -> 0 | AT11: =轉向量!U194 -> 0 | AU11: =轉向量!D290 -> 0 | AV11: =轉向量!E290 -> 0 | AW11: =轉向量!F290 -> 0 | AX11: =轉向量!H290 -> 0 | AY11: =轉向量!I290 -> 0 | AZ11: =轉向量!J290 -> 0 | BA11: =轉向量!K290 -> 0 | BB11: =轉向量!L290 -> 0 | BC11: =轉向量!N290 -> 0 | BD11: =轉向量!O290 -> 0 | BE11: =轉向量!P290 -> 0 | BF11: =轉向量!Q290 -> 0 | BG11: =轉向量!R290 -> 0 | BH11: =轉向量!T290 -> 0 | BI11: =轉向量!U290 -> 0 | BJ11: =轉向量!D386 -> 0 | BK11: =轉向量!E386 -> 0 | BL11: =轉向量!F386 -> 0 | BM11: =轉向量!G386 -> 0 | BN11: =轉向量!I386 -> 0 | BO11: =轉向量!J386 -> 0 | BP11: =轉向量!K386 -> 0 | BQ11: =轉向量!L386 -> 0 | BR11: =轉向量!M386 -> 0 | BS11: =轉向量!O386 -> 0 | BT11: =轉向量!P386 -> 0 | BU11: =轉向量!Q386 -> 0 | BV11: =轉向量!R386 -> 0 | BW11: =轉向量!S386 -> 0 | BX11: =轉向量!U386 -> 0 | BY11: =轉向量!D482 -> 0 | BZ11: =轉向量!E482 -> 0 | CA11: =轉向量!F482 -> 0 | CB11: =轉向量!G482 -> 0 | CC11: =轉向量!H482 -> 0 | CD11: =轉向量!J482 -> 0 | CE11: =轉向量!K482 -> 0 | CF11: =轉向量!L482 -> 0 | CG11: =轉向量!M482 -> 0 | CH11: =轉向量!N482 -> 0 | CI11: =轉向量!P482 -> 0 | CJ11: =轉向量!Q482 -> 0 | CK11: =轉向量!R482 -> 0 | CL11: =轉向量!S482 -> 0 | CM11: =轉向量!T482 -> 0
A12: 15 | B12: =轉向量!E3 -> 0 | C12: =轉向量!F3 -> 0 | D12: =轉向量!G3 -> 0 | E12: =轉向量!H3 -> 0 | F12: =轉向量!I3 -> 0 | G12: =轉向量!K3 -> 0 | H12: =轉向量!L3 -> 0 | I12: =轉向量!M3 -> 0 | J12: =轉向量!N3 -> 0 | K12: =轉向量!O3 -> 0 | L12: =轉向量!Q3 -> 0 | M12: =轉向量!R3 -> 0 | N12: =轉向量!S3 -> 0 | O12: =轉向量!T3 -> 0 | P12: =轉向量!U3 -> 0 | Q12: =轉向量!D99 -> 0 | R12: =轉向量!F99 -> 0 | S12: =轉向量!G99 -> 0 | T12: =轉向量!H99 -> 0 | U12: =轉向量!I99 -> 0 | V12: =轉向量!J99 -> 0 | W12: =轉向量!L99 -> 0 | X12: =轉向量!M99 -> 0 | Y12: =轉向量!N99 -> 0 | Z12: =轉向量!O99 -> 0 | AA12: =轉向量!P99 -> 0 | AB12: =轉向量!R99 -> 0 | AC12: =轉向量!S99 -> 0 | AD12: =轉向量!T99 -> 0 | AE12: =轉向量!U99 -> 0 | AF12: =轉向量!D195 -> 0 | AG12: =轉向量!E195 -> 0 | AH12: =轉向量!G195 -> 0 | AI12: =轉向量!H195 -> 0 | AJ12: =轉向量!I195 -> 0 | AK12: =轉向量!J195 -> 0 | AL12: =轉向量!K195 -> 0 | AM12: =轉向量!M195 -> 0 | AN12: =轉向量!N195 -> 0 | AO12: =轉向量!O195 -> 0 | AP12: =轉向量!P195 -> 0 | AQ12: =轉向量!Q195 -> 0 | AR12: =轉向量!S195 -> 0 | AS12: =轉向量!T195 -> 0 | AT12: =轉向量!U195 -> 0 | AU12: =轉向量!D291 -> 0 | AV12: =轉向量!E291 -> 0 | AW12: =轉向量!F291 -> 0 | AX12: =轉向量!H291 -> 0 | AY12: =轉向量!I291 -> 0 | AZ12: =轉向量!J291 -> 0 | BA12: =轉向量!K291 -> 0 | BB12: =轉向量!L291 -> 0 | BC12: =轉向量!N291 -> 0 | BD12: =轉向量!O291 -> 0 | BE12: =轉向量!P291 -> 0 | BF12: =轉向量!Q291 -> 0 | BG12: =轉向量!R291 -> 0 | BH12: =轉向量!T291 -> 0 | BI12: =轉向量!U291 -> 0 | BJ12: =轉向量!D387 -> 0 | BK12: =轉向量!E387 -> 0 | BL12: =轉向量!F387 -> 0 | BM12: =轉向量!G387 -> 0 | BN12: =轉向量!I387 -> 0 | BO12: =轉向量!J387 -> 0 | BP12: =轉向量!K387 -> 0 | BQ12: =轉向量!L387 -> 0 | BR12: =轉向量!M387 -> 0 | BS12: =轉向量!O387 -> 0 | BT12: =轉向量!P387 -> 0 | BU12: =轉向量!Q387 -> 0 | BV12: =轉向量!R387 -> 0 | BW12: =轉向量!S387 -> 0 | BX12: =轉向量!U387 -> 0 | BY12: =轉向量!D483 -> 0 | BZ12: =轉向量!E483 -> 0 | CA12: =轉向量!F483 -> 0 | CB12: =轉向量!G483 -> 0 | CC12: =轉向量!H483 -> 0 | CD12: =轉向量!J483 -> 0 | CE12: =轉向量!K483 -> 0 | CF12: =轉向量!L483 -> 0 | CG12: =轉向量!M483 -> 0 | CH12: =轉向量!N483 -> 0 | CI12: =轉向量!P483 -> 0 | CJ12: =轉向量!Q483 -> 0 | CK12: =轉向量!R483 -> 0 | CL12: =轉向量!S483 -> 0 | CM12: =轉向量!T483 -> 0
A13: 30 | B13: =轉向量!E4 -> 0 | C13: =轉向量!F4 -> 0 | D13: =轉向量!G4 -> 0 | E13: =轉向量!H4 -> 0 | F13: =轉向量!I4 -> 0 | G13: =轉向量!K4 -> 0 | H13: =轉向量!L4 -> 0 | I13: =轉向量!M4 -> 0 | J13: =轉向量!N4 -> 0 | K13: =轉向量!O4 -> 0 | L13: =轉向量!Q4 -> 0 | M13: =轉向量!R4 -> 0 | N13: =轉向量!S4 -> 0 | O13: =轉向量!T4 -> 0 | P13: =轉向量!U4 -> 0 | Q13: =轉向量!D100 -> 0 | R13: =轉向量!F100 -> 0 | S13: =轉向量!G100 -> 0 | T13: =轉向量!H100 -> 0 | U13: =轉向量!I100 -> 0 | V13: =轉向量!J100 -> 0 | W13: =轉向量!L100 -> 0 | X13: =轉向量!M100 -> 0 | Y13: =轉向量!N100 -> 0 | Z13: =轉向量!O100 -> 0 | AA13: =轉向量!P100 -> 0 | AB13: =轉向量!R100 -> 0 | AC13: =轉向量!S100 -> 0 | AD13: =轉向量!T100 -> 0 | AE13: =轉向量!U100 -> 0 | AF13: =轉向量!D196 -> 0 | AG13: =轉向量!E196 -> 0 | AH13: =轉向量!G196 -> 0 | AI13: =轉向量!H196 -> 0 | AJ13: =轉向量!I196 -> 0 | AK13: =轉向量!J196 -> 0 | AL13: =轉向量!K196 -> 0 | AM13: =轉向量!M196 -> 0 | AN13: =轉向量!N196 -> 0 | AO13: =轉向量!O196 -> 0 | AP13: =轉向量!P196 -> 0 | AQ13: =轉向量!Q196 -> 0 | AR13: =轉向量!S196 -> 0 | AS13: =轉向量!T196 -> 0 | AT13: =轉向量!U196 -> 0 | AU13: =轉向量!D292 -> 0 | AV13: =轉向量!E292 -> 0 | AW13: =轉向量!F292 -> 0 | AX13: =轉向量!H292 -> 0 | AY13: =轉向量!I292 -> 0 | AZ13: =轉向量!J292 -> 0 | BA13: =轉向量!K292 -> 0 | BB13: =轉向量!L292 -> 0 | BC13: =轉向量!N292 -> 0 | BD13: =轉向量!O292 -> 0 | BE13: =轉向量!P292 -> 0 | BF13: =轉向量!Q292 -> 0 | BG13: =轉向量!R292 -> 0 | BH13: =轉向量!T292 -> 0 | BI13: =轉向量!U292 -> 0 | BJ13: =轉向量!D388 -> 0 | BK13: =轉向量!E388 -> 0 | BL13: =轉向量!F388 -> 0 | BM13: =轉向量!G388 -> 0 | BN13: =轉向量!I388 -> 0 | BO13: =轉向量!J388 -> 0 | BP13: =轉向量!K388 -> 0 | BQ13: =轉向量!L388 -> 0 | BR13: =轉向量!M388 -> 0 | BS13: =轉向量!O388 -> 0 | BT13: =轉向量!P388 -> 0 | BU13: =轉向量!Q388 -> 0 | BV13: =轉向量!R388 -> 0 | BW13: =轉向量!S388 -> 0 | BX13: =轉向量!U388 -> 0 | BY13: =轉向量!D484 -> 0 | BZ13: =轉向量!E484 -> 0 | CA13: =轉向量!F484 -> 0 | CB13: =轉向量!G484 -> 0 | CC13: =轉向量!H484 -> 0 | CD13: =轉向量!J484 -> 0 | CE13: =轉向量!K484 -> 0 | CF13: =轉向量!L484 -> 0 | CG13: =轉向量!M484 -> 0 | CH13: =轉向量!N484 -> 0 | CI13: =轉向量!P484 -> 0 | CJ13: =轉向量!Q484 -> 0 | CK13: =轉向量!R484 -> 0 | CL13: =轉向量!S484 -> 0 | CM13: =轉向量!T484 -> 0
A14: 45 | B14: =轉向量!E5 -> 0 | C14: =轉向量!F5 -> 0 | D14: =轉向量!G5 -> 0 | E14: =轉向量!H5 -> 0 | F14: =轉向量!I5 -> 0 | G14: =轉向量!K5 -> 0 | H14: =轉向量!L5 -> 0 | I14: =轉向量!M5 -> 0 | J14: =轉向量!N5 -> 0 | K14: =轉向量!O5 -> 0 | L14: =轉向量!Q5 -> 0 | M14: =轉向量!R5 -> 0 | N14: =轉向量!S5 -> 0 | O14: =轉向量!T5 -> 0 | P14: =轉向量!U5 -> 0 | Q14: =轉向量!D101 -> 0 | R14: =轉向量!F101 -> 0 | S14: =轉向量!G101 -> 0 | T14: =轉向量!H101 -> 0 | U14: =轉向量!I101 -> 0 | V14: =轉向量!J101 -> 0 | W14: =轉向量!L101 -> 0 | X14: =轉向量!M101 -> 0 | Y14: =轉向量!N101 -> 0 | Z14: =轉向量!O101 -> 0 | AA14: =轉向量!P101 -> 0 | AB14: =轉向量!R101 -> 0 | AC14: =轉向量!S101 -> 0 | AD14: =轉向量!T101 -> 0 | AE14: =轉向量!U101 -> 0 | AF14: =轉向量!D197 -> 0 | AG14: =轉向量!E197 -> 0 | AH14: =轉向量!G197 -> 0 | AI14: =轉向量!H197 -> 0 | AJ14: =轉向量!I197 -> 0 | AK14: =轉向量!J197 -> 0 | AL14: =轉向量!K197 -> 0 | AM14: =轉向量!M197 -> 0 | AN14: =轉向量!N197 -> 0 | AO14: =轉向量!O197 -> 0 | AP14: =轉向量!P197 -> 0 | AQ14: =轉向量!Q197 -> 0 | AR14: =轉向量!S197 -> 0 | AS14: =轉向量!T197 -> 0 | AT14: =轉向量!U197 -> 0 | AU14: =轉向量!D293 -> 0 | AV14: =轉向量!E293 -> 0 | AW14: =轉向量!F293 -> 0 | AX14: =轉向量!H293 -> 0 | AY14: =轉向量!I293 -> 0 | AZ14: =轉向量!J293 -> 0 | BA14: =轉向量!K293 -> 0 | BB14: =轉向量!L293 -> 0 | BC14: =轉向量!N293 -> 0 | BD14: =轉向量!O293 -> 0 | BE14: =轉向量!P293 -> 0 | BF14: =轉向量!Q293 -> 0 | BG14: =轉向量!R293 -> 0 | BH14: =轉向量!T293 -> 0 | BI14: =轉向量!U293 -> 0 | BJ14: =轉向量!D389 -> 0 | BK14: =轉向量!E389 -> 0 | BL14: =轉向量!F389 -> 0 | BM14: =轉向量!G389 -> 0 | BN14: =轉向量!I389 -> 0 | BO14: =轉向量!J389 -> 0 | BP14: =轉向量!K389 -> 0 | BQ14: =轉向量!L389 -> 0 | BR14: =轉向量!M389 -> 0 | BS14: =轉向量!O389 -> 0 | BT14: =轉向量!P389 -> 0 | BU14: =轉向量!Q389 -> 0 | BV14: =轉向量!R389 -> 0 | BW14: =轉向量!S389 -> 0 | BX14: =轉向量!U389 -> 0 | BY14: =轉向量!D485 -> 0 | BZ14: =轉向量!E485 -> 0 | CA14: =轉向量!F485 -> 0 | CB14: =轉向量!G485 -> 0 | CC14: =轉向量!H485 -> 0 | CD14: =轉向量!J485 -> 0 | CE14: =轉向量!K485 -> 0 | CF14: =轉向量!L485 -> 0 | CG14: =轉向量!M485 -> 0 | CH14: =轉向量!N485 -> 0 | CI14: =轉向量!P485 -> 0 | CJ14: =轉向量!Q485 -> 0 | CK14: =轉向量!R485 -> 0 | CL14: =轉向量!S485 -> 0 | CM14: =轉向量!T485 -> 0
A15: 100 | B15: =轉向量!E6 -> 0 | C15: =轉向量!F6 -> 0 | D15: =轉向量!G6 -> 0 | E15: =轉向量!H6 -> 0 | F15: =轉向量!I6 -> 0 | G15: =轉向量!K6 -> 0 | H15: =轉向量!L6 -> 0 | I15: =轉向量!M6 -> 0 | J15: =轉向量!N6 -> 0 | K15: =轉向量!O6 -> 0 | L15: =轉向量!Q6 -> 0 | M15: =轉向量!R6 -> 0 | N15: =轉向量!S6 -> 0 | O15: =轉向量!T6 -> 0 | P15: =轉向量!U6 -> 0 | Q15: =轉向量!D102 -> 0 | R15: =轉向量!F102 -> 0 | S15: =轉向量!G102 -> 0 | T15: =轉向量!H102 -> 0 | U15: =轉向量!I102 -> 0 | V15: =轉向量!J102 -> 0 | W15: =轉向量!L102 -> 0 | X15: =轉向量!M102 -> 0 | Y15: =轉向量!N102 -> 0 | Z15: =轉向量!O102 -> 0 | AA15: =轉向量!P102 -> 0 | AB15: =轉向量!R102 -> 0 | AC15: =轉向量!S102 -> 0 | AD15: =轉向量!T102 -> 0 | AE15: =轉向量!U102 -> 0 | AF15: =轉向量!D198 -> 0 | AG15: =轉向量!E198 -> 0 | AH15: =轉向量!G198 -> 0 | AI15: =轉向量!H198 -> 0 | AJ15: =轉向量!I198 -> 0 | AK15: =轉向量!J198 -> 0 | AL15: =轉向量!K198 -> 0 | AM15: =轉向量!M198 -> 0 | AN15: =轉向量!N198 -> 0 | AO15: =轉向量!O198 -> 0 | AP15: =轉向量!P198 -> 0 | AQ15: =轉向量!Q198 -> 0 | AR15: =轉向量!S198 -> 0 | AS15: =轉向量!T198 -> 0 | AT15: =轉向量!U198 -> 0 | AU15: =轉向量!D294 -> 0 | AV15: =轉向量!E294 -> 0 | AW15: =轉向量!F294 -> 0 | AX15: =轉向量!H294 -> 0 | AY15: =轉向量!I294 -> 0 | AZ15: =轉向量!J294 -> 0 | BA15: =轉向量!K294 -> 0 | BB15: =轉向量!L294 -> 0 | BC15: =轉向量!N294 -> 0 | BD15: =轉向量!O294 -> 0 | BE15: =轉向量!P294 -> 0 | BF15: =轉向量!Q294 -> 0 | BG15: =轉向量!R294 -> 0 | BH15: =轉向量!T294 -> 0 | BI15: =轉向量!U294 -> 0 | BJ15: =轉向量!D390 -> 0 | BK15: =轉向量!E390 -> 0 | BL15: =轉向量!F390 -> 0 | BM15: =轉向量!G390 -> 0 | BN15: =轉向量!I390 -> 0 | BO15: =轉向量!J390 -> 0 | BP15: =轉向量!K390 -> 0 | BQ15: =轉向量!L390 -> 0 | BR15: =轉向量!M390 -> 0 | BS15: =轉向量!O390 -> 0 | BT15: =轉向量!P390 -> 0 | BU15: =轉向量!Q390 -> 0 | BV15: =轉向量!R390 -> 0 | BW15: =轉向量!S390 -> 0 | BX15: =轉向量!U390 -> 0 | BY15: =轉向量!D486 -> 0 | BZ15: =轉向量!E486 -> 0 | CA15: =轉向量!F486 -> 0 | CB15: =轉向量!G486 -> 0 | CC15: =轉向量!H486 -> 0 | CD15: =轉向量!J486 -> 0 | CE15: =轉向量!K486 -> 0 | CF15: =轉向量!L486 -> 0 | CG15: =轉向量!M486 -> 0 | CH15: =轉向量!N486 -> 0 | CI15: =轉向量!P486 -> 0 | CJ15: =轉向量!Q486 -> 0 | CK15: =轉向量!R486 -> 0 | CL15: =轉向量!S486 -> 0 | CM15: =轉向量!T486 -> 0
A16: 115 | B16: =轉向量!E7 -> 0 | C16: =轉向量!F7 -> 0 | D16: =轉向量!G7 -> 0 | E16: =轉向量!H7 -> 0 | F16: =轉向量!I7 -> 0 | G16: =轉向量!K7 -> 0 | H16: =轉向量!L7 -> 0 | I16: =轉向量!M7 -> 0 | J16: =轉向量!N7 -> 0 | K16: =轉向量!O7 -> 0 | L16: =轉向量!Q7 -> 0 | M16: =轉向量!R7 -> 0 | N16: =轉向量!S7 -> 0 | O16: =轉向量!T7 -> 0 | P16: =轉向量!U7 -> 0 | Q16: =轉向量!D103 -> 0 | R16: =轉向量!F103 -> 0 | S16: =轉向量!G103 -> 0 | T16: =轉向量!H103 -> 0 | U16: =轉向量!I103 -> 0 | V16: =轉向量!J103 -> 0 | W16: =轉向量!L103 -> 0 | X16: =轉向量!M103 -> 0 | Y16: =轉向量!N103 -> 0 | Z16: =轉向量!O103 -> 0 | AA16: =轉向量!P103 -> 0 | AB16: =轉向量!R103 -> 0 | AC16: =轉向量!S103 -> 0 | AD16: =轉向量!T103 -> 0 | AE16: =轉向量!U103 -> 0 | AF16: =轉向量!D199 -> 0 | AG16: =轉向量!E199 -> 0 | AH16: =轉向量!G199 -> 0 | AI16: =轉向量!H199 -> 0 | AJ16: =轉向量!I199 -> 0 | AK16: =轉向量!J199 -> 0 | AL16: =轉向量!K199 -> 0 | AM16: =轉向量!M199 -> 0 | AN16: =轉向量!N199 -> 0 | AO16: =轉向量!O199 -> 0 | AP16: =轉向量!P199 -> 0 | AQ16: =轉向量!Q199 -> 0 | AR16: =轉向量!S199 -> 0 | AS16: =轉向量!T199 -> 0 | AT16: =轉向量!U199 -> 0 | AU16: =轉向量!D295 -> 0 | AV16: =轉向量!E295 -> 0 | AW16: =轉向量!F295 -> 0 | AX16: =轉向量!H295 -> 0 | AY16: =轉向量!I295 -> 0 | AZ16: =轉向量!J295 -> 0 | BA16: =轉向量!K295 -> 0 | BB16: =轉向量!L295 -> 0 | BC16: =轉向量!N295 -> 0 | BD16: =轉向量!O295 -> 0 | BE16: =轉向量!P295 -> 0 | BF16: =轉向量!Q295 -> 0 | BG16: =轉向量!R295 -> 0 | BH16: =轉向量!T295 -> 0 | BI16: =轉向量!U295 -> 0 | BJ16: =轉向量!D391 -> 0 | BK16: =轉向量!E391 -> 0 | BL16: =轉向量!F391 -> 0 | BM16: =轉向量!G391 -> 0 | BN16: =轉向量!I391 -> 0 | BO16: =轉向量!J391 -> 0 | BP16: =轉向量!K391 -> 0 | BQ16: =轉向量!L391 -> 0 | BR16: =轉向量!M391 -> 0 | BS16: =轉向量!O391 -> 0 | BT16: =轉向量!P391 -> 0 | BU16: =轉向量!Q391 -> 0 | BV16: =轉向量!R391 -> 0 | BW16: =轉向量!S391 -> 0 | BX16: =轉向量!U391 -> 0 | BY16: =轉向量!D487 -> 0 | BZ16: =轉向量!E487 -> 0 | CA16: =轉向量!F487 -> 0 | CB16: =轉向量!G487 -> 0 | CC16: =轉向量!H487 -> 0 | CD16: =轉向量!J487 -> 0 | CE16: =轉向量!K487 -> 0 | CF16: =轉向量!L487 -> 0 | CG16: =轉向量!M487 -> 0 | CH16: =轉向量!N487 -> 0 | CI16: =轉向量!P487 -> 0 | CJ16: =轉向量!Q487 -> 0 | CK16: =轉向量!R487 -> 0 | CL16: =轉向量!S487 -> 0 | CM16: =轉向量!T487 -> 0
A17: 130 | B17: =轉向量!E8 -> 0 | C17: =轉向量!F8 -> 0 | D17: =轉向量!G8 -> 0 | E17: =轉向量!H8 -> 0 | F17: =轉向量!I8 -> 0 | G17: =轉向量!K8 -> 0 | H17: =轉向量!L8 -> 0 | I17: =轉向量!M8 -> 0 | J17: =轉向量!N8 -> 0 | K17: =轉向量!O8 -> 0 | L17: =轉向量!Q8 -> 0 | M17: =轉向量!R8 -> 0 | N17: =轉向量!S8 -> 0 | O17: =轉向量!T8 -> 0 | P17: =轉向量!U8 -> 0 | Q17: =轉向量!D104 -> 0 | R17: =轉向量!F104 -> 0 | S17: =轉向量!G104 -> 0 | T17: =轉向量!H104 -> 0 | U17: =轉向量!I104 -> 0 | V17: =轉向量!J104 -> 0 | W17: =轉向量!L104 -> 0 | X17: =轉向量!M104 -> 0 | Y17: =轉向量!N104 -> 0 | Z17: =轉向量!O104 -> 0 | AA17: =轉向量!P104 -> 0 | AB17: =轉向量!R104 -> 0 | AC17: =轉向量!S104 -> 0 | AD17: =轉向量!T104 -> 0 | AE17: =轉向量!U104 -> 0 | AF17: =轉向量!D200 -> 0 | AG17: =轉向量!E200 -> 0 | AH17: =轉向量!G200 -> 0 | AI17: =轉向量!H200 -> 0 | AJ17: =轉向量!I200 -> 0 | AK17: =轉向量!J200 -> 0 | AL17: =轉向量!K200 -> 0 | AM17: =轉向量!M200 -> 0 | AN17: =轉向量!N200 -> 0 | AO17: =轉向量!O200 -> 0 | AP17: =轉向量!P200 -> 0 | AQ17: =轉向量!Q200 -> 0 | AR17: =轉向量!S200 -> 0 | AS17: =轉向量!T200 -> 0 | AT17: =轉向量!U200 -> 0 | AU17: =轉向量!D296 -> 0 | AV17: =轉向量!E296 -> 0 | AW17: =轉向量!F296 -> 0 | AX17: =轉向量!H296 -> 0 | AY17: =轉向量!I296 -> 0 | AZ17: =轉向量!J296 -> 0 | BA17: =轉向量!K296 -> 0 | BB17: =轉向量!L296 -> 0 | BC17: =轉向量!N296 -> 0 | BD17: =轉向量!O296 -> 0 | BE17: =轉向量!P296 -> 0 | BF17: =轉向量!Q296 -> 0 | BG17: =轉向量!R296 -> 0 | BH17: =轉向量!T296 -> 0 | BI17: =轉向量!U296 -> 0 | BJ17: =轉向量!D392 -> 0 | BK17: =轉向量!E392 -> 0 | BL17: =轉向量!F392 -> 0 | BM17: =轉向量!G392 -> 0 | BN17: =轉向量!I392 -> 0 | BO17: =轉向量!J392 -> 0 | BP17: =轉向量!K392 -> 0 | BQ17: =轉向量!L392 -> 0 | BR17: =轉向量!M392 -> 0 | BS17: =轉向量!O392 -> 0 | BT17: =轉向量!P392 -> 0 | BU17: =轉向量!Q392 -> 0 | BV17: =轉向量!R392 -> 0 | BW17: =轉向量!S392 -> 0 | BX17: =轉向量!U392 -> 0 | BY17: =轉向量!D488 -> 0 | BZ17: =轉向量!E488 -> 0 | CA17: =轉向量!F488 -> 0 | CB17: =轉向量!G488 -> 0 | CC17: =轉向量!H488 -> 0 | CD17: =轉向量!J488 -> 0 | CE17: =轉向量!K488 -> 0 | CF17: =轉向量!L488 -> 0 | CG17: =轉向量!M488 -> 0 | CH17: =轉向量!N488 -> 0 | CI17: =轉向量!P488 -> 0 | CJ17: =轉向量!Q488 -> 0 | CK17: =轉向量!R488 -> 0 | CL17: =轉向量!S488 -> 0 | CM17: =轉向量!T488 -> 0
A18: 145 | B18: =轉向量!E9 -> 0 | C18: =轉向量!F9 -> 0 | D18: =轉向量!G9 -> 0 | E18: =轉向量!H9 -> 0 | F18: =轉向量!I9 -> 0 | G18: =轉向量!K9 -> 0 | H18: =轉向量!L9 -> 0 | I18: =轉向量!M9 -> 0 | J18: =轉向量!N9 -> 0 | K18: =轉向量!O9 -> 0 | L18: =轉向量!Q9 -> 0 | M18: =轉向量!R9 -> 0 | N18: =轉向量!S9 -> 0 | O18: =轉向量!T9 -> 0 | P18: =轉向量!U9 -> 0 | Q18: =轉向量!D105 -> 0 | R18: =轉向量!F105 -> 0 | S18: =轉向量!G105 -> 0 | T18: =轉向量!H105 -> 0 | U18: =轉向量!I105 -> 0 | V18: =轉向量!J105 -> 0 | W18: =轉向量!L105 -> 0 | X18: =轉向量!M105 -> 0 | Y18: =轉向量!N105 -> 0 | Z18: =轉向量!O105 -> 0 | AA18: =轉向量!P105 -> 0 | AB18: =轉向量!R105 -> 0 | AC18: =轉向量!S105 -> 0 | AD18: =轉向量!T105 -> 0 | AE18: =轉向量!U105 -> 0 | AF18: =轉向量!D201 -> 0 | AG18: =轉向量!E201 -> 0 | AH18: =轉向量!G201 -> 0 | AI18: =轉向量!H201 -> 0 | AJ18: =轉向量!I201 -> 0 | AK18: =轉向量!J201 -> 0 | AL18: =轉向量!K201 -> 0 | AM18: =轉向量!M201 -> 0 | AN18: =轉向量!N201 -> 0 | AO18: =轉向量!O201 -> 0 | AP18: =轉向量!P201 -> 0 | AQ18: =轉向量!Q201 -> 0 | AR18: =轉向量!S201 -> 0 | AS18: =轉向量!T201 -> 0 | AT18: =轉向量!U201 -> 0 | AU18: =轉向量!D297 -> 0 | AV18: =轉向量!E297 -> 0 | AW18: =轉向量!F297 -> 0 | AX18: =轉向量!H297 -> 0 | AY18: =轉向量!I297 -> 0 | AZ18: =轉向量!J297 -> 0 | BA18: =轉向量!K297 -> 0 | BB18: =轉向量!L297 -> 0 | BC18: =轉向量!N297 -> 0 | BD18: =轉向量!O297 -> 0 | BE18: =轉向量!P297 -> 0 | BF18: =轉向量!Q297 -> 0 | BG18: =轉向量!R297 -> 0 | BH18: =轉向量!T297 -> 0 | BI18: =轉向量!U297 -> 0 | BJ18: =轉向量!D393 -> 0 | BK18: =轉向量!E393 -> 0 | BL18: =轉向量!F393 -> 0 | BM18: =轉向量!G393 -> 0 | BN18: =轉向量!I393 -> 0 | BO18: =轉向量!J393 -> 0 | BP18: =轉向量!K393 -> 0 | BQ18: =轉向量!L393 -> 0 | BR18: =轉向量!M393 -> 0 | BS18: =轉向量!O393 -> 0 | BT18: =轉向量!P393 -> 0 | BU18: =轉向量!Q393 -> 0 | BV18: =轉向量!R393 -> 0 | BW18: =轉向量!S393 -> 0 | BX18: =轉向量!U393 -> 0 | BY18: =轉向量!D489 -> 0 | BZ18: =轉向量!E489 -> 0 | CA18: =轉向量!F489 -> 0 | CB18: =轉向量!G489 -> 0 | CC18: =轉向量!H489 -> 0 | CD18: =轉向量!J489 -> 0 | CE18: =轉向量!K489 -> 0 | CF18: =轉向量!L489 -> 0 | CG18: =轉向量!M489 -> 0 | CH18: =轉向量!N489 -> 0 | CI18: =轉向量!P489 -> 0 | CJ18: =轉向量!Q489 -> 0 | CK18: =轉向量!R489 -> 0 | CL18: =轉向量!S489 -> 0 | CM18: =轉向量!T489 -> 0
A19: 200 | B19: =轉向量!E10 -> 0 | C19: =轉向量!F10 -> 0 | D19: =轉向量!G10 -> 0 | E19: =轉向量!H10 -> 0 | F19: =轉向量!I10 -> 0 | G19: =轉向量!K10 -> 0 | H19: =轉向量!L10 -> 0 | I19: =轉向量!M10 -> 0 | J19: =轉向量!N10 -> 0 | K19: =轉向量!O10 -> 0 | L19: =轉向量!Q10 -> 0 | M19: =轉向量!R10 -> 0 | N19: =轉向量!S10 -> 0 | O19: =轉向量!T10 -> 0 | P19: =轉向量!U10 -> 0 | Q19: =轉向量!D106 -> 0 | R19: =轉向量!F106 -> 0 | S19: =轉向量!G106 -> 0 | T19: =轉向量!H106 -> 0 | U19: =轉向量!I106 -> 0 | V19: =轉向量!J106 -> 0 | W19: =轉向量!L106 -> 0 | X19: =轉向量!M106 -> 0 | Y19: =轉向量!N106 -> 0 | Z19: =轉向量!O106 -> 0 | AA19: =轉向量!P106 -> 0 | AB19: =轉向量!R106 -> 0 | AC19: =轉向量!S106 -> 0 | AD19: =轉向量!T106 -> 0 | AE19: =轉向量!U106 -> 0 | AF19: =轉向量!D202 -> 0 | AG19: =轉向量!E202 -> 0 | AH19: =轉向量!G202 -> 0 | AI19: =轉向量!H202 -> 0 | AJ19: =轉向量!I202 -> 0 | AK19: =轉向量!J202 -> 0 | AL19: =轉向量!K202 -> 0 | AM19: =轉向量!M202 -> 0 | AN19: =轉向量!N202 -> 0 | AO19: =轉向量!O202 -> 0 | AP19: =轉向量!P202 -> 0 | AQ19: =轉向量!Q202 -> 0 | AR19: =轉向量!S202 -> 0 | AS19: =轉向量!T202 -> 0 | AT19: =轉向量!U202 -> 0 | AU19: =轉向量!D298 -> 0 | AV19: =轉向量!E298 -> 0 | AW19: =轉向量!F298 -> 0 | AX19: =轉向量!H298 -> 0 | AY19: =轉向量!I298 -> 0 | AZ19: =轉向量!J298 -> 0 | BA19: =轉向量!K298 -> 0 | BB19: =轉向量!L298 -> 0 | BC19: =轉向量!N298 -> 0 | BD19: =轉向量!O298 -> 0 | BE19: =轉向量!P298 -> 0 | BF19: =轉向量!Q298 -> 0 | BG19: =轉向量!R298 -> 0 | BH19: =轉向量!T298 -> 0 | BI19: =轉向量!U298 -> 0 | BJ19: =轉向量!D394 -> 0 | BK19: =轉向量!E394 -> 0 | BL19: =轉向量!F394 -> 0 | BM19: =轉向量!G394 -> 0 | BN19: =轉向量!I394 -> 0 | BO19: =轉向量!J394 -> 0 | BP19: =轉向量!K394 -> 0 | BQ19: =轉向量!L394 -> 0 | BR19: =轉向量!M394 -> 0 | BS19: =轉向量!O394 -> 0 | BT19: =轉向量!P394 -> 0 | BU19: =轉向量!Q394 -> 0 | BV19: =轉向量!R394 -> 0 | BW19: =轉向量!S394 -> 0 | BX19: =轉向量!U394 -> 0 | BY19: =轉向量!D490 -> 0 | BZ19: =轉向量!E490 -> 0 | CA19: =轉向量!F490 -> 0 | CB19: =轉向量!G490 -> 0 | CC19: =轉向量!H490 -> 0 | CD19: =轉向量!J490 -> 0 | CE19: =轉向量!K490 -> 0 | CF19: =轉向量!L490 -> 0 | CG19: =轉向量!M490 -> 0 | CH19: =轉向量!N490 -> 0 | CI19: =轉向量!P490 -> 0 | CJ19: =轉向量!Q490 -> 0 | CK19: =轉向量!R490 -> 0 | CL19: =轉向量!S490 -> 0 | CM19: =轉向量!T490 -> 0
A20: 215 | B20: =轉向量!E11 -> 0 | C20: =轉向量!F11 -> 0 | D20: =轉向量!G11 -> 0 | E20: =轉向量!H11 -> 0 | F20: =轉向量!I11 -> 0 | G20: =轉向量!K11 -> 0 | H20: =轉向量!L11 -> 0 | I20: =轉向量!M11 -> 0 | J20: =轉向量!N11 -> 0 | K20: =轉向量!O11 -> 0 | L20: =轉向量!Q11 -> 0 | M20: =轉向量!R11 -> 0 | N20: =轉向量!S11 -> 0 | O20: =轉向量!T11 -> 0 | P20: =轉向量!U11 -> 0 | Q20: =轉向量!D107 -> 0 | R20: =轉向量!F107 -> 0 | S20: =轉向量!G107 -> 0 | T20: =轉向量!H107 -> 0 | U20: =轉向量!I107 -> 0 | V20: =轉向量!J107 -> 0 | W20: =轉向量!L107 -> 0 | X20: =轉向量!M107 -> 0 | Y20: =轉向量!N107 -> 0 | Z20: =轉向量!O107 -> 0 | AA20: =轉向量!P107 -> 0 | AB20: =轉向量!R107 -> 0 | AC20: =轉向量!S107 -> 0 | AD20: =轉向量!T107 -> 0 | AE20: =轉向量!U107 -> 0 | AF20: =轉向量!D203 -> 0 | AG20: =轉向量!E203 -> 0 | AH20: =轉向量!G203 -> 0 | AI20: =轉向量!H203 -> 0 | AJ20: =轉向量!I203 -> 0 | AK20: =轉向量!J203 -> 0 | AL20: =轉向量!K203 -> 0 | AM20: =轉向量!M203 -> 0 | AN20: =轉向量!N203 -> 0 | AO20: =轉向量!O203 -> 0 | AP20: =轉向量!P203 -> 0 | AQ20: =轉向量!Q203 -> 0 | AR20: =轉向量!S203 -> 0 | AS20: =轉向量!T203 -> 0 | AT20: =轉向量!U203 -> 0 | AU20: =轉向量!D299 -> 0 | AV20: =轉向量!E299 -> 0 | AW20: =轉向量!F299 -> 0 | AX20: =轉向量!H299 -> 0 | AY20: =轉向量!I299 -> 0 | AZ20: =轉向量!J299 -> 0 | BA20: =轉向量!K299 -> 0 | BB20: =轉向量!L299 -> 0 | BC20: =轉向量!N299 -> 0 | BD20: =轉向量!O299 -> 0 | BE20: =轉向量!P299 -> 0 | BF20: =轉向量!Q299 -> 0 | BG20: =轉向量!R299 -> 0 | BH20: =轉向量!T299 -> 0 | BI20: =轉向量!U299 -> 0 | BJ20: =轉向量!D395 -> 0 | BK20: =轉向量!E395 -> 0 | BL20: =轉向量!F395 -> 0 | BM20: =轉向量!G395 -> 0 | BN20: =轉向量!I395 -> 0 | BO20: =轉向量!J395 -> 0 | BP20: =轉向量!K395 -> 0 | BQ20: =轉向量!L395 -> 0 | BR20: =轉向量!M395 -> 0 | BS20: =轉向量!O395 -> 0 | BT20: =轉向量!P395 -> 0 | BU20: =轉向量!Q395 -> 0 | BV20: =轉向量!R395 -> 0 | BW20: =轉向量!S395 -> 0 | BX20: =轉向量!U395 -> 0 | BY20: =轉向量!D491 -> 0 | BZ20: =轉向量!E491 -> 0 | CA20: =轉向量!F491 -> 0 | CB20: =轉向量!G491 -> 0 | CC20: =轉向量!H491 -> 0 | CD20: =轉向量!J491 -> 0 | CE20: =轉向量!K491 -> 0 | CF20: =轉向量!L491 -> 0 | CG20: =轉向量!M491 -> 0 | CH20: =轉向量!N491 -> 0 | CI20: =轉向量!P491 -> 0 | CJ20: =轉向量!Q491 -> 0 | CK20: =轉向量!R491 -> 0 | CL20: =轉向量!S491 -> 0 | CM20: =轉向量!T491 -> 0
A21: 230 | B21: =轉向量!E12 -> 0 | C21: =轉向量!F12 -> 0 | D21: =轉向量!G12 -> 0 | E21: =轉向量!H12 -> 0 | F21: =轉向量!I12 -> 0 | G21: =轉向量!K12 -> 0 | H21: =轉向量!L12 -> 0 | I21: =轉向量!M12 -> 0 | J21: =轉向量!N12 -> 0 | K21: =轉向量!O12 -> 0 | L21: =轉向量!Q12 -> 0 | M21: =轉向量!R12 -> 0 | N21: =轉向量!S12 -> 0 | O21: =轉向量!T12 -> 0 | P21: =轉向量!U12 -> 0 | Q21: =轉向量!D108 -> 0 | R21: =轉向量!F108 -> 0 | S21: =轉向量!G108 -> 0 | T21: =轉向量!H108 -> 0 | U21: =轉向量!I108 -> 0 | V21: =轉向量!J108 -> 0 | W21: =轉向量!L108 -> 0 | X21: =轉向量!M108 -> 0 | Y21: =轉向量!N108 -> 0 | Z21: =轉向量!O108 -> 0 | AA21: =轉向量!P108 -> 0 | AB21: =轉向量!R108 -> 0 | AC21: =轉向量!S108 -> 0 | AD21: =轉向量!T108 -> 0 | AE21: =轉向量!U108 -> 0 | AF21: =轉向量!D204 -> 0 | AG21: =轉向量!E204 -> 0 | AH21: =轉向量!G204 -> 0 | AI21: =轉向量!H204 -> 0 | AJ21: =轉向量!I204 -> 0 | AK21: =轉向量!J204 -> 0 | AL21: =轉向量!K204 -> 0 | AM21: =轉向量!M204 -> 0 | AN21: =轉向量!N204 -> 0 | AO21: =轉向量!O204 -> 0 | AP21: =轉向量!P204 -> 0 | AQ21: =轉向量!Q204 -> 0 | AR21: =轉向量!S204 -> 0 | AS21: =轉向量!T204 -> 0 | AT21: =轉向量!U204 -> 0 | AU21: =轉向量!D300 -> 0 | AV21: =轉向量!E300 -> 0 | AW21: =轉向量!F300 -> 0 | AX21: =轉向量!H300 -> 0 | AY21: =轉向量!I300 -> 0 | AZ21: =轉向量!J300 -> 0 | BA21: =轉向量!K300 -> 0 | BB21: =轉向量!L300 -> 0 | BC21: =轉向量!N300 -> 0 | BD21: =轉向量!O300 -> 0 | BE21: =轉向量!P300 -> 0 | BF21: =轉向量!Q300 -> 0 | BG21: =轉向量!R300 -> 0 | BH21: =轉向量!T300 -> 0 | BI21: =轉向量!U300 -> 0 | BJ21: =轉向量!D396 -> 0 | BK21: =轉向量!E396 -> 0 | BL21: =轉向量!F396 -> 0 | BM21: =轉向量!G396 -> 0 | BN21: =轉向量!I396 -> 0 | BO21: =轉向量!J396 -> 0 | BP21: =轉向量!K396 -> 0 | BQ21: =轉向量!L396 -> 0 | BR21: =轉向量!M396 -> 0 | BS21: =轉向量!O396 -> 0 | BT21: =轉向量!P396 -> 0 | BU21: =轉向量!Q396 -> 0 | BV21: =轉向量!R396 -> 0 | BW21: =轉向量!S396 -> 0 | BX21: =轉向量!U396 -> 0 | BY21: =轉向量!D492 -> 0 | BZ21: =轉向量!E492 -> 0 | CA21: =轉向量!F492 -> 0 | CB21: =轉向量!G492 -> 0 | CC21: =轉向量!H492 -> 0 | CD21: =轉向量!J492 -> 0 | CE21: =轉向量!K492 -> 0 | CF21: =轉向量!L492 -> 0 | CG21: =轉向量!M492 -> 0 | CH21: =轉向量!N492 -> 0 | CI21: =轉向量!P492 -> 0 | CJ21: =轉向量!Q492 -> 0 | CK21: =轉向量!R492 -> 0 | CL21: =轉向量!S492 -> 0 | CM21: =轉向量!T492 -> 0
A22: 245 | B22: =轉向量!E13 -> 0 | C22: =轉向量!F13 -> 0 | D22: =轉向量!G13 -> 0 | E22: =轉向量!H13 -> 0 | F22: =轉向量!I13 -> 0 | G22: =轉向量!K13 -> 0 | H22: =轉向量!L13 -> 0 | I22: =轉向量!M13 -> 0 | J22: =轉向量!N13 -> 0 | K22: =轉向量!O13 -> 0 | L22: =轉向量!Q13 -> 0 | M22: =轉向量!R13 -> 0 | N22: =轉向量!S13 -> 0 | O22: =轉向量!T13 -> 0 | P22: =轉向量!U13 -> 0 | Q22: =轉向量!D109 -> 0 | R22: =轉向量!F109 -> 0 | S22: =轉向量!G109 -> 0 | T22: =轉向量!H109 -> 0 | U22: =轉向量!I109 -> 0 | V22: =轉向量!J109 -> 0 | W22: =轉向量!L109 -> 0 | X22: =轉向量!M109 -> 0 | Y22: =轉向量!N109 -> 0 | Z22: =轉向量!O109 -> 0 | AA22: =轉向量!P109 -> 0 | AB22: =轉向量!R109 -> 0 | AC22: =轉向量!S109 -> 0 | AD22: =轉向量!T109 -> 0 | AE22: =轉向量!U109 -> 0 | AF22: =轉向量!D205 -> 0 | AG22: =轉向量!E205 -> 0 | AH22: =轉向量!G205 -> 0 | AI22: =轉向量!H205 -> 0 | AJ22: =轉向量!I205 -> 0 | AK22: =轉向量!J205 -> 0 | AL22: =轉向量!K205 -> 0 | AM22: =轉向量!M205 -> 0 | AN22: =轉向量!N205 -> 0 | AO22: =轉向量!O205 -> 0 | AP22: =轉向量!P205 -> 0 | AQ22: =轉向量!Q205 -> 0 | AR22: =轉向量!S205 -> 0 | AS22: =轉向量!T205 -> 0 | AT22: =轉向量!U205 -> 0 | AU22: =轉向量!D301 -> 0 | AV22: =轉向量!E301 -> 0 | AW22: =轉向量!F301 -> 0 | AX22: =轉向量!H301 -> 0 | AY22: =轉向量!I301 -> 0 | AZ22: =轉向量!J301 -> 0 | BA22: =轉向量!K301 -> 0 | BB22: =轉向量!L301 -> 0 | BC22: =轉向量!N301 -> 0 | BD22: =轉向量!O301 -> 0 | BE22: =轉向量!P301 -> 0 | BF22: =轉向量!Q301 -> 0 | BG22: =轉向量!R301 -> 0 | BH22: =轉向量!T301 -> 0 | BI22: =轉向量!U301 -> 0 | BJ22: =轉向量!D397 -> 0 | BK22: =轉向量!E397 -> 0 | BL22: =轉向量!F397 -> 0 | BM22: =轉向量!G397 -> 0 | BN22: =轉向量!I397 -> 0 | BO22: =轉向量!J397 -> 0 | BP22: =轉向量!K397 -> 0 | BQ22: =轉向量!L397 -> 0 | BR22: =轉向量!M397 -> 0 | BS22: =轉向量!O397 -> 0 | BT22: =轉向量!P397 -> 0 | BU22: =轉向量!Q397 -> 0 | BV22: =轉向量!R397 -> 0 | BW22: =轉向量!S397 -> 0 | BX22: =轉向量!U397 -> 0 | BY22: =轉向量!D493 -> 0 | BZ22: =轉向量!E493 -> 0 | CA22: =轉向量!F493 -> 0 | CB22: =轉向量!G493 -> 0 | CC22: =轉向量!H493 -> 0 | CD22: =轉向量!J493 -> 0 | CE22: =轉向量!K493 -> 0 | CF22: =轉向量!L493 -> 0 | CG22: =轉向量!M493 -> 0 | CH22: =轉向量!N493 -> 0 | CI22: =轉向量!P493 -> 0 | CJ22: =轉向量!Q493 -> 0 | CK22: =轉向量!R493 -> 0 | CL22: =轉向量!S493 -> 0 | CM22: =轉向量!T493 -> 0
... A106: 2345 | B106: =轉向量!E97 -> 0 | C106: =轉向量!F97 -> 0 | D106: =轉向量!G97 -> 0 | E106: =轉向量!H97 -> 0 | F106: =轉向量!I97 -> 0 | G106: =轉向量!K97 -> 0 | H106: =轉向量!L97 -> 0 | I106: =轉向量!M97 -> 0 | J106: =轉向量!N97 -> 0 | K106: =轉向量!O97 -> 0 | L106: =轉向量!Q97 -> 0 | M106: =轉向量!R97 -> 0 | N106: =轉向量!S97 -> 0 | O106: =轉向量!T97 -> 0 | P106: =轉向量!U97 -> 0 | Q106: =轉向量!D193 -> 0 | R106: =轉向量!F193 -> 0 | S106: =轉向量!G193 -> 0 | T106: =轉向量!H193 -> 0 | U106: =轉向量!I193 -> 0 | V106: =轉向量!J193 -> 0 | W106: =轉向量!L193 -> 0 | X106: =轉向量!M193 -> 0 | Y106: =轉向量!N193 -> 0 | Z106: =轉向量!O193 -> 0 | AA106: =轉向量!P193 -> 0 | AB106: =轉向量!R193 -> 0 | AC106: =轉向量!S193 -> 0 | AD106: =轉向量!T193 -> 0 | AE106: =轉向量!U193 -> 0 | AF106: =轉向量!D289 -> 0 | AG106: =轉向量!E289 -> 0 | AH106: =轉向量!G289 -> 0 | AI106: =轉向量!H289 -> 0 | AJ106: =轉向量!I289 -> 0 | AK106: =轉向量!J289 -> 0 | AL106: =轉向量!K289 -> 0 | AM106: =轉向量!M289 -> 0 | AN106: =轉向量!N289 -> 0 | AO106: =轉向量!O289 -> 0 | AP106: =轉向量!P289 -> 0 | AQ106: =轉向量!Q289 -> 0 | AR106: =轉向量!S289 -> 0 | AS106: =轉向量!T289 -> 0 | AT106: =轉向量!U289 -> 0 | AU106: =轉向量!D385 -> 0 | AV106: =轉向量!E385 -> 0 | AW106: =轉向量!F385 -> 0 | AX106: =轉向量!H385 -> 0 | AY106: =轉向量!I385 -> 0 | AZ106: =轉向量!J385 -> 0 | BA106: =轉向量!K385 -> 0 | BB106: =轉向量!L385 -> 0 | BC106: =轉向量!N385 -> 0 | BD106: =轉向量!O385 -> 0 | BE106: =轉向量!P385 -> 0 | BF106: =轉向量!Q385 -> 0 | BG106: =轉向量!R385 -> 0 | BH106: =轉向量!T385 -> 0 | BI106: =轉向量!U385 -> 0 | BJ106: =轉向量!D481 -> 0 | BK106: =轉向量!E481 -> 0 | BL106: =轉向量!F481 -> 0 | BM106: =轉向量!G481 -> 0 | BN106: =轉向量!I481 -> 0 | BO106: =轉向量!J481 -> 0 | BP106: =轉向量!K481 -> 0 | BQ106: =轉向量!L481 -> 0 | BR106: =轉向量!M481 -> 0 | BS106: =轉向量!O481 -> 0 | BT106: =轉向量!P481 -> 0 | BU106: =轉向量!Q481 -> 0 | BV106: =轉向量!R481 -> 0 | BW106: =轉向量!S481 -> 0 | BX106: =轉向量!U481 -> 0 | BY106: =轉向量!D577 -> 0 | BZ106: =轉向量!E577 -> 0 | CA106: =轉向量!F577 -> 0 | CB106: =轉向量!G577 -> 0 | CC106: =轉向量!H577 -> 0 | CD106: =轉向量!J577 -> 0 | CE106: =轉向量!K577 -> 0 | CF106: =轉向量!L577 -> 0 | CG106: =轉向量!M577 -> 0 | CH106: =轉向量!N577 -> 0 | CI106: =轉向量!P577 -> 0 | CJ106: =轉向量!Q577 -> 0 | CK106: =轉向量!R577 -> 0 | CL106: =轉向量!S577 -> 0 | CM106: =轉向量!T577 -> 0

Sheet PHF及轉向比
BB1: ←A | CA1: 合計 | CH1: ↑B | DG1: 合計 | DN1: ↑C | EM1: 合計 | ET1: →D | FS1: 合計 | FZ1: ↓E | GY1: 合計 | HF1: ↓F | IE1: 合計
B2: ←A | H2: ↑B | N2: ↑C | T2: →D | Z2: ↓E | AF2: ↓F | AL2: 路口 | AP2: 每小時 | AQ2: 尖峰小時 | AR2: 最大15分鐘 | AS2: A尖峰小時 | AT2: B尖峰小時 | AU2: C尖峰小時 | AV2: D尖峰小時 | AW2: E尖峰小時 | AX2: F尖峰小時 | AY2: 尖峰小時 | AZ2: 尖峰 | BA2: 小時 | BB2: B | BF2: 轉向 | BG2: C | BK2: 轉向 | BL2: D | BP2: 轉向 | BQ2: E | BU2: 轉向 | BV2: F | BZ2: 轉向 | CB2: 車種 | CD2: 車種 | CF2: 車種 | CH2: A | CL2: 轉向 | CM2: C | CQ2: 轉向 | CR2: D | CV2: 轉向 | CW2: E | DA2: 轉向 | DB2: F | DF2: 轉向 | DH2: 車種 | DJ2: 車種 | DL2: 車種 | DN2: A | DR2: 轉向 | DS2: B | DW2: 轉向 | DX2: D | EB2: 轉向 | EC2: E | EG2: 轉向 | EH2: F | EL2: 轉向 | EN2: 車種 | EP2: 車種 | ER2: 車種 | ET2: A | EX2: 轉向 | EY2: B | FC2: 轉向 | FD2: C | FH2: 轉向 | FI2: E | FM2: 轉向 | FN2: F | FR2: 轉向 | FT2: 車種 | FV2: 車種 | FX2: 車種 | FZ2: A | GD2: 轉向 | GE2: B | GI2: 轉向 | GJ2: C | GN2: 轉向 | GO2: D | GS2: 轉向 | GT2: F | GX2: 轉向 | GZ2: 車種 | HB2: 車種 | HD2: 車種 | HF2: A | HJ2: 轉向 | HK2: B | HO2: 轉向 | HP2: C | HT2: 轉向 | HU2: D | HY2: 轉向 | HZ2: E | ID2: 轉向 | IF2: 車種 | IH2: 車種 | IJ2: 車種
B3: 小計 | C3: B | D3: C | E3: D | F3: E | G3: F | H3: 小計 | I3: A | J3: C | K3: D | L3: E | M3: F | N3: 小計 | O3: A | P3: B | Q3: D | R3: E | S3: F | T3: 小計 | U3: A | V3: B | W3: C | X3: E | Y3: F | Z3: 小計 | AA3: A | AB3: B | AC3: C | AD3: D | AE3: F | AF3: 小計 | AG3: A | AH3: B | AI3: C | AJ3: D | AK3: E | AL3: 總計 | AP3: 交通量 | AQ3: 交通量 | AR3: 交通量 | AS3: 係數 | AT3: 係數 | AU3: 係數 | AV3: 係數 | AW3: 係數 | AX3: 係數 | AY3: 係數 | AZ3: 起 | BA3: 迄 | BB3: 小計 | BC3: 大型車 | BD3: 小型車 | BE3: 機車 | BF3: 百分比 | BG3: 小計 | BH3: 大型車 | BI3: 小型車 | BJ3: 機車 | BK3: 百分比 | BL3: 小計 | BM3: 大型車 | BN3: 小型車 | BO3: 機車 | BP3: 百分比 | BQ3: 小計 | BR3: 大型車 | BS3: 小型車 | BT3: 機車 | BU3: 百分比 | BV3: 小計 | BW3: 大型車 | BX3: 小型車 | BY3: 機車 | BZ3: 百分比 | CA3: 大型車 | CB3: 百分比 | CC3: 小型車 | CD3: 百分比 | CE3: 機車 | CF3: 百分比 | CG3: 合計 | CH3: 小計 | CI3: 大型車 | CJ3: 小型車 | CK3: 機車 | CL3: 百分比 | CM3: 小計 | CN3: 大型車 | CO3: 小型車 | CP3: 機車 | CQ3: 百分比 | CR3: 小計 | CS3: 大型車 | CT3: 小型車 | CU3: 機車 | CV3: 百分比 | CW3: 小計 | CX3: 大型車 | CY3: 小型車 | CZ3: 機車 | DA3: 百分比 | DB3: 小計 | DC3: 大型車 | DD3: 小型車 | DE3: 機車 | DF3: 百分比 | DG3: 大型車 | DH3: 百分比 | DI3: 小型車 | DJ3: 百分比 | DK3: 機車 | DL3: 百分比 | DM3: 合計 | DN3: 小計 | DO3: 大型車 | DP3: 小型車 | DQ3: 機車 | DR3: 百分比 | DS3: 小計 | DT3: 大型車 | DU3: 小型車 | DV3: 機車 | DW3: 百分比 | DX3: 小計 | DY3: 大型車 | DZ3: 小型車 | EA3: 機車 | EB3: 百分比 | EC3: 小計 | ED3: 大型車 | EE3: 小型車 | EF3: 機車 | EG3: 百分比 | EH3: 小計 | EI3: 大型車 | EJ3: 小型車 | EK3: 機車 | EL3: 百分比 | EM3: 大型車 | EN3: 百分比 | EO3: 小型車 | EP3: 百分比 | EQ3: 機車 | ER3: 百分比 | ES3: 合計 | ET3: 小計 | EU3: 大型車 | EV3: 小型車 | EW3: 機車 | EX3: 百分比 | EY3: 小計 | EZ3: 大型車 | FA3: 小型車 | FB3: 機車 | FC3: 百分比 | FD3: 小計 | FE3: 大型車 | FF3: 小型車 | FG3: 機車 | FH3: 百分比 | FI3: 小計 | FJ3: 大型車 | FK3: 小型車 | FL3: 機車 | FM3: 百分比 | FN3: 小計 | FO3: 大型車 | FP3: 小型車 | FQ3: 機車 | FR3: 百分比 | FS3: 大型車 | FT3: 百分比 | FU3: 小型車 | FV3: 百分比 | FW3: 機車 | FX3: 百分比 | FY3: 合計 | FZ3: 小計 | GA3: 大型車 | GB3: 小型車 | GC3: 機車 | GD3: 百分比 | GE3: 小計 | GF3: 大型車 | GG3: 小型車 | GH3: 機車 | GI3: 百分比 | GJ3: 小計 | GK3: 大型車 | GL3: 小型車 | GM3: 機車 | GN3: 百分比 | GO3: 小計 | GP3: 大型車 | GQ3: 小型車 | GR3: 機車 | GS3: 百分比 | GT3: 小計 | GU3: 大型車 | GV3: 小型車 | GW3: 機車 | GX3: 百分比 | GY3: 大型車 | GZ3: 百分比 | HA3: 小型車 | HB3: 百分比 | HC3: 機車 | HD3: 百分比 | HE3: 合計 | HF3: 小計 | HG3: 大型車 | HH3: 小型車 | HI3: 機車 | HJ3: 百分比 | HK3: 小計 | HL3: 大型車 | HM3: 小型車 | HN3: 機車 | HO3: 百分比 | HP3: 小計 | HQ3: 大型車 | HR3: 小型車 | HS3: 機車 | HT3: 百分比 | HU3: 小計 | HV3: 大型車 | HW3: 小型車 | HX3: 機車 | HY3: 百分比 | HZ3: 小計 | IA3: 大型車 | IB3: 小型車 | IC3: 機車 | ID3: 百分比 | IE3: 大型車 | IF3: 百分比 | IG3: 小型車 | IH3: 百分比 | II3: 機車 | IJ3: 百分比 | IK3: 合計
B4: (PCU) | C4: (PCU) | D4: (PCU) | E4: (PCU) | F4: (PCU) | G4: (PCU) | H4: (PCU) | I4: (PCU) | J4: (PCU) | K4: (PCU) | L4: (PCU) | M4: (PCU) | N4: (PCU) | O4: (PCU) | P4: (PCU) | Q4: (PCU) | R4: (PCU) | S4: (PCU) | T4: (PCU) | U4: (PCU) | V4: (PCU) | W4: (PCU) | X4: (PCU) | Y4: (PCU) | Z4: (PCU) | AA4: (PCU) | AB4: (PCU) | AC4: (PCU) | AD4: (PCU) | AE4: (PCU) | AF4: (PCU) | AG4: (PCU) | AH4: (PCU) | AI4: (PCU) | AJ4: (PCU) | AK4: (PCU) | AL4: (PCU) | AP4: （PCU） | AQ4: （PCU） | AR4: （PCU） | AS4: （PHF） | AT4: （PHF） | AU4: （PHF） | AV4: （PHF） | AW4: （PHF） | AX4: （PHF） | AY4: （PHF） | BB4: （PCU） | BC4: （輛） | BD4: （輛） | BE4: （輛） | BF4: （％） | BG4: （PCU） | BH4: （輛） | BI4: （輛） | BJ4: （輛） | BK4: （％） | BL4: （PCU） | BM4: （輛） | BN4: （輛） | BO4: （輛） | BP4: （％） | BQ4: （PCU） | BR4: （輛） | BS4: （輛） | BT4: （輛） | BU4: （％） | BV4: （PCU） | BW4: （輛） | BX4: （輛） | BY4: （輛） | BZ4: （％） | CA4: （輛） | CB4: （％） | CC4: （輛） | CD4: （％） | CE4: （輛） | CF4: （％） | CG4: （PCU） | CH4: （PCU） | CI4: （輛） | CJ4: （輛） | CK4: （輛） | CL4: （％） | CM4: （PCU） | CN4: （輛） | CO4: （輛） | CP4: （輛） | CQ4: （％） | CR4: （PCU） | CS4: （輛） | CT4: （輛） | CU4: （輛） | CV4: （％） | CW4: （PCU） | CX4: （輛） | CY4: （輛） | CZ4: （輛） | DA4: （％） | DB4: （PCU） | DC4: （輛） | DD4: （輛） | DE4: （輛） | DF4: （％） | DG4: （輛） | DH4: （％） | DI4: （輛） | DJ4: （％） | DK4: （輛） | DL4: （％） | DM4: （PCU） | DN4: （PCU） | DO4: （輛） | DP4: （輛） | DQ4: （輛） | DR4: （％） | DS4: （PCU） | DT4: （輛） | DU4: （輛） | DV4: （輛） | DW4: （％） | DX4: （PCU） | DY4: （輛） | DZ4: （輛） | EA4: （輛） | EB4: （％） | EC4: （PCU） | ED4: （輛） | EE4: （輛） | EF4: （輛） | EG4: （％） | EH4: （PCU） | EI4: （輛） | EJ4: （輛） | EK4: （輛） | EL4: （％） | EM4: （輛） | EN4: （％） | EO4: （輛） | EP4: （％） | EQ4: （輛） | ER4: （％） | ES4: （PCU） | ET4: （PCU） | EU4: （輛） | EV4: （輛） | EW4: （輛） | EX4: （％） | EY4: （PCU） | EZ4: （輛） | FA4: （輛） | FB4: （輛） | FC4: （％） | FD4: （PCU） | FE4: （輛） | FF4: （輛） | FG4: （輛） | FH4: （％） | FI4: （PCU） | FJ4: （輛） | FK4: （輛） | FL4: （輛） | FM4: （％） | FN4: （PCU） | FO4: （輛） | FP4: （輛） | FQ4: （輛） | FR4: （％） | FS4: （輛） | FT4: （％） | FU4: （輛） | FV4: （％） | FW4: （輛） | FX4: （％） | FY4: （PCU） | FZ4: （PCU） | GA4: （輛） | GB4: （輛） | GC4: （輛） | GD4: （％） | GE4: （PCU） | GF4: （輛） | GG4: （輛） | GH4: （輛） | GI4: （％） | GJ4: （PCU） | GK4: （輛） | GL4: （輛） | GM4: （輛） | GN4: （％） | GO4: （PCU） | GP4: （輛） | GQ4: （輛） | GR4: （輛） | GS4: （％） | GT4: （PCU） | GU4: （輛） | GV4: （輛） | GW4: （輛） | GX4: （％） | GY4: （輛） | GZ4: （％） | HA4: （輛） | HB4: （％） | HC4: （輛） | HD4: （％） | HE4: （PCU） | HF4: （PCU） | HG4: （輛） | HH4: （輛） | HI4: （輛） | HJ4: （％） | HK4: （PCU） | HL4: （輛） | HM4: （輛） | HN4: （輛） | HO4: （％） | HP4: （PCU） | HQ4: （輛） | HR4: （輛） | HS4: （輛） | HT4: （％） | HU4: （PCU） | HV4: （輛） | HW4: （輛） | HX4: （輛） | HY4: （％） | HZ4: （PCU） | IA4: （輛） | IB4: （輛） | IC4: （輛） | ID4: （％） | IE4: （輛） | IF4: （％） | IG4: （輛） | IH4: （％） | II4: （輛） | IJ4: （％） | IK4: （PCU）
A5: ='[4]調查資料(OUT)'!A11 -> 0 | B5: =SUM(C5:G5) -> 0 | C5: =IFERROR('調查資料(OUT)'!$B$1*'調查資料(OUT)'!B11,0)+IFERROR('調查資料(OUT)'!$G$1*'調查資料(OUT)'!G11,0)+IFERROR('調查資料(OUT)'!$L$1*'調查資料(OUT)'!L11,0) -> 0 | D5: =IFERROR('調查資料(OUT)'!$C$1*'調查資料(OUT)'!C11,0)+IFERROR('調查資料(OUT)'!$H$1*'調查資料(OUT)'!H11,0)+IFERROR('調查資料(OUT)'!$M$1*'調查資料(OUT)'!M11,0) -> 0 | E5: =IFERROR('調查資料(OUT)'!$D$1*'調查資料(OUT)'!D11,0)+IFERROR('調查資料(OUT)'!$I$1*'調查資料(OUT)'!I11,0)+IFERROR('調查資料(OUT)'!$N$1*'調查資料(OUT)'!N11,0) -> 0 | F5: =IFERROR('調查資料(OUT)'!$E$1*'調查資料(OUT)'!E11,0)+IFERROR('調查資料(OUT)'!$J$1*'調查資料(OUT)'!J11,0)+IFERROR('調查資料(OUT)'!$O$1*'調查資料(OUT)'!O11,0) -> 0 | G5: =IFERROR('調查資料(OUT)'!$F$1*'調查資料(OUT)'!F11,0)+IFERROR('調查資料(OUT)'!$K$1*'調查資料(OUT)'!K11,0)+IFERROR('調查資料(OUT)'!$P$1*'調查資料(OUT)'!P11,0) -> 0 | H5: =SUM(I5:M5) -> 0 | I5: =IFERROR('調查資料(OUT)'!$Q$1*'調查資料(OUT)'!Q11,0)+IFERROR('調查資料(OUT)'!$V$1*'調查資料(OUT)'!V11,0)+IFERROR('調查資料(OUT)'!$AA$1*'調查資料(OUT)'!AA11,0) -> 0 | J5: =IFERROR('調查資料(OUT)'!$R$1*'調查資料(OUT)'!R11,0)+IFERROR('調查資料(OUT)'!$W$1*'調查資料(OUT)'!W11,0)+IFERROR('調查資料(OUT)'!$AB$1*'調查資料(OUT)'!AB11,0) -> 0 | K5: =IFERROR('調查資料(OUT)'!$S$1*'調查資料(OUT)'!S11,0)+IFERROR('調查資料(OUT)'!$X$1*'調查資料(OUT)'!X11,0)+IFERROR('調查資料(OUT)'!$AC$1*'調查資料(OUT)'!AC11,0) -> 0 | L5: =IFERROR('調查資料(OUT)'!$T$1*'調查資料(OUT)'!T11,0)+IFERROR('調查資料(OUT)'!$Y$1*'調查資料(OUT)'!Y11,0)+IFERROR('調查資料(OUT)'!$AD$1*'調查資料(OUT)'!AD11,0) -> 0 | M5: =IFERROR('調查資料(OUT)'!$U$1*'調查資料(OUT)'!U11,0)+IFERROR('調查資料(OUT)'!$Z$1*'調查資料(OUT)'!Z11,0)+IFERROR('調查資料(OUT)'!$AE$1*'調查資料(OUT)'!AE11,0) -> 0 | N5: =SUM(O5:S5) -> 0 | O5: =IFERROR('調查資料(OUT)'!$AF$1*'調查資料(OUT)'!AF11,0)+IFERROR('調查資料(OUT)'!$AK$1*'調查資料(OUT)'!AK11,0)+IFERROR('調查資料(OUT)'!$AP$1*'調查資料(OUT)'!AP11,0) -> 0 | P5: =IFERROR('調查資料(OUT)'!$AG$1*'調查資料(OUT)'!AG11,0)+IFERROR('調查資料(OUT)'!$AL$1*'調查資料(OUT)'!AL11,0)+IFERROR('調查資料(OUT)'!$AQ$1*'調查資料(OUT)'!AQ11,0) -> 0 | Q5: =IFERROR('調查資料(OUT)'!$AH$1*'調查資料(OUT)'!AH11,0)+IFERROR('調查資料(OUT)'!$AM$1*'調查資料(OUT)'!AM11,0)+IFERROR('調查資料(OUT)'!$AR$1*'調查資料(OUT)'!AR11,0) -> 0 | R5: =IFERROR('調查資料(OUT)'!$AI$1*'調查資料(OUT)'!AI11,0)+IFERROR('調查資料(OUT)'!$AN$1*'調查資料(OUT)'!AN11,0)+IFERROR('調查資料(OUT)'!$AS$1*'調查資料(OUT)'!AS11,0) -> 0 | S5: =IFERROR('調查資料(OUT)'!$AJ$1*'調查資料(OUT)'!AJ11,0)+IFERROR('調查資料(OUT)'!$AO$1*'調查資料(OUT)'!AO11,0)+IFERROR('調查資料(OUT)'!$AT$1*'調查資料(OUT)'!AT11,0) -> 0 | T5: =SUM(U5:Y5) -> 0 | U5: =IFERROR('調查資料(OUT)'!$AU$1*'調查資料(OUT)'!AU11,0)+IFERROR('調查資料(OUT)'!$AZ$1*'調查資料(OUT)'!AZ11,0)+IFERROR('調查資料(OUT)'!$BE$1*'調查資料(OUT)'!BE11,0) -> 0 | V5: =IFERROR('調查資料(OUT)'!$AV$1*'調查資料(OUT)'!AV11,0)+IFERROR('調查資料(OUT)'!$BA$1*'調查資料(OUT)'!BA11,0)+IFERROR('調查資料(OUT)'!$BF$1*'調查資料(OUT)'!BF11,0) -> 0 | W5: =IFERROR('調查資料(OUT)'!$AW$1*'調查資料(OUT)'!AW11,0)+IFERROR('調查資料(OUT)'!$BB$1*'調查資料(OUT)'!BB11,0)+IFERROR('調查資料(OUT)'!$BG$1*'調查資料(OUT)'!BG11,0) -> 0 | X5: =IFERROR('調查資料(OUT)'!$AX$1*'調查資料(OUT)'!AX11,0)+IFERROR('調查資料(OUT)'!$BC$1*'調查資料(OUT)'!BC11,0)+IFERROR('調查資料(OUT)'!$BH$1*'調查資料(OUT)'!BH11,0) -> 0 | Y5: =IFERROR('調查資料(OUT)'!$AY$1*'調查資料(OUT)'!AY11,0)+IFERROR('調查資料(OUT)'!$BD$1*'調查資料(OUT)'!BD11,0)+IFERROR('調查資料(OUT)'!$BI$1*'調查資料(OUT)'!BI11,0) -> 0 | Z5: =SUM(AA5:AE5) -> 0 | AA5: =IFERROR('調查資料(OUT)'!$BJ$1*'調查資料(OUT)'!BJ11,0)+IFERROR('調查資料(OUT)'!$BO$1*'調查資料(OUT)'!BO11,0)+IFERROR('調查資料(OUT)'!$BT$1*'調查資料(OUT)'!BT11,0) -> 0 | AB5: =IFERROR('調查資料(OUT)'!$BK$1*'調查資料(OUT)'!BK11,0)+IFERROR('調查資料(OUT)'!$BP$1*'調查資料(OUT)'!BP11,0)+IFERROR('調查資料(OUT)'!$BU$1*'調查資料(OUT)'!BU11,0) -> 0 | AC5: =IFERROR('調查資料(OUT)'!$BL$1*'調查資料(OUT)'!BL11,0)+IFERROR('調查資料(OUT)'!$BQ$1*'調查資料(OUT)'!BQ11,0)+IFERROR('調查資料(OUT)'!$BV$1*'調查資料(OUT)'!BV11,0) -> 0 | AD5: =IFERROR('調查資料(OUT)'!$BM$1*'調查資料(OUT)'!BM11,0)+IFERROR('調查資料(OUT)'!$BR$1*'調查資料(OUT)'!BR11,0)+IFERROR('調查資料(OUT)'!$BW$1*'調查資料(OUT)'!BW11,0) -> 0 | AE5: =IFERROR('調查資料(OUT)'!$BN$1*'調查資料(OUT)'!BN11,0)+IFERROR('調查資料(OUT)'!$BS$1*'調查資料(OUT)'!BS11,0)+IFERROR('調查資料(OUT)'!$BX$1*'調查資料(OUT)'!BX11,0) -> 0 | AF5: =SUM(AG5:AK5) -> 0 | AG5: =IFERROR('調查資料(OUT)'!$BY$1*'調查資料(OUT)'!BY11,0)+IFERROR('調查資料(OUT)'!$CD$1*'調查資料(OUT)'!CD11,0)+IFERROR('調查資料(OUT)'!$CI$1*'調查資料(OUT)'!CI11,0) -> 0 | AH5: =IFERROR('調查資料(OUT)'!$BZ$1*'調查資料(OUT)'!BZ11,0)+IFERROR('調查資料(OUT)'!$CE$1*'調查資料(OUT)'!CE11,0)+IFERROR('調查資料(OUT)'!$CJ$1*'調查資料(OUT)'!CJ11,0) -> 0 | AI5: =IFERROR('調查資料(OUT)'!$CA$1*'調查資料(OUT)'!CA11,0)+IFERROR('調查資料(OUT)'!$CF$1*'調查資料(OUT)'!CF11,0)+IFERROR('調查資料(OUT)'!$CK$1*'調查資料(OUT)'!CK11,0) -> 0 | AJ5: =IFERROR('調查資料(OUT)'!$CB$1*'調查資料(OUT)'!CB11,0)+IFERROR('調查資料(OUT)'!$CG$1*'調查資料(OUT)'!CG11,0)+IFERROR('調查資料(OUT)'!$CL$1*'調查資料(OUT)'!CL11,0) -> 0 | AK5: =IFERROR('調查資料(OUT)'!$CC$1*'調查資料(OUT)'!CC11,0)+IFERROR('調查資料(OUT)'!$CH$1*'調查資料(OUT)'!CH11,0)+IFERROR('調查資料(OUT)'!$CM$1*'調查資料(OUT)'!CM11,0) -> 0 | AL5: =B5+H5+N5+T5+Z5+AF5 -> 0 | AN5: ='調查資料(OUT)'!A11 -> 0 | AO5: =AN5+100 -> 100 | AP5: =SUM(AL5:AL8) -> 0 | AQ5: =MAX(AP5:AP17) -> 0 | AR5: =IF($AP5=$AQ$5,MAX(AL5:AL8),0) -> 0 | AS5: =IF($AP5=AQ$5,SUM(B5:B8)/(4*(MAX(B5:B8))),0) -> #DIV/0! | AT5: =IF($AP5=AQ$5,SUM(H5:H8)/(4*(MAX(H5:H8))),0) -> #DIV/0! | AU5: =IF($AP5=AQ$5,SUM(N5:N8)/(4*(MAX(N5:N8))),0) -> #DIV/0! | AV5: =IF($AP5=AQ$5,SUM(T5:T8)/(4*(MAX(T5:T8))),0) -> #DIV/0! | AW5: =IF($AP5=AQ$5,SUM(Z5:Z8)/(4*(MAX(Z5:Z8))),0) -> #DIV/0! | AX5: =IF($AP5=AQ$5,SUM(AF5:AF8)/(4*(MAX(AF5:AF8))),0) -> #DIV/0! | AY5: =$AQ$5/(4*MAX(AR5:AR17)) -> #DIV/0! | AZ5: =IF(AP5=AQ$5,$AN5,"N") -> 0 | BA5: =IF(AP5=AQ$5,$AO5,"N") -> 100 | BB5: =IF($AZ5="N","N",SUM(C5:C8)) -> 0 | BC5: =IF($AZ5="N","N",SUM('調查資料(OUT)'!B11:B14)) -> 0 | BD5: =IF($AZ5="N","N",SUM('調查資料(OUT)'!G11:G14)) -> 0 | BE5: =IF($AZ5="N","N",SUM('調查資料(OUT)'!L11:L14)) -> 0 | BF5: =IF($AZ5="N","N",(BB5/$CG5)*100) -> #DIV/0! | BG5: =IF($AZ5="N","N",SUM(D5:D8)) -> 0 | BH5: =IF($AZ5="N","N",SUM('調查資料(OUT)'!C11:C14)) -> 0 | BI5: =IF($AZ5="N","N",SUM('調查資料(OUT)'!H11:H14)) -> 0 | BJ5: =IF($AZ5="N","N",SUM('調查資料(OUT)'!M11:M14)) -> 0 | BK5: =IF($AZ5="N","N",(BG5/$CG5)*100) -> #DIV/0! | BL5: =IF($AZ5="N","N",SUM(E5:E8)) -> 0 | BM5: =IF($AZ5="N","N",SUM('調查資料(OUT)'!D11:D14)) -> 0 | BN5: =IF($AZ5="N","N",SUM('調查資料(OUT)'!I11:I14)) -> 0 | BO5: =IF($AZ5="N","N",SUM('調查資料(OUT)'!N11:N14)) -> 0 | BP5: =IF($AZ5="N","N",(BL5/$CG5)*100) -> #DIV/0! | BQ5: =IF($AZ5="N","N",SUM(F5:F8)) -> 0 | BR5: =IF($AZ5="N","N",SUM('調查資料(OUT)'!E11:E14)) -> 0 | BS5: =IF($AZ5="N","N",SUM('調查資料(OUT)'!J11:J14)) -> 0 | BT5: =IF($AZ5="N","N",SUM('調查資料(OUT)'!O11:O14)) -> 0 | BU5: =IF($AZ5="N","N",(BQ5/$CG5)*100) -> #DIV/0! | BV5: =IF($AZ5="N","N",SUM(G5:G8)) -> 0 | BW5: =IF($AZ5="N","N",SUM('調查資料(OUT)'!F11:F14)) -> 0 | BX5: =IF($AZ5="N","N",SUM('調查資料(OUT)'!K11:K14)) -> 0 | BY5: =IF($AZ5="N","N",SUM('調查資料(OUT)'!P11:P14)) -> 0 | BZ5: =IF($AZ5="N","N",(BV5/$CG5)*100) -> #DIV/0! | CA5: =IF($AZ5="N","N",BC5+BH5+BM5+BR5+BW5) -> 0 | CB5: =IF($AZ5="N","N",(CA5/($CA5+$CC5+$CE5))*100) -> #DIV/0! | CC5: =IF($AZ5="N","N",BD5+BI5+BN5+BS5+BX5) -> 0 | CD5: =IF($AZ5="N","N",(CC5/($CA5+$CC5+$CE5))*100) -> #DIV/0! | CE5: =IF($AZ5="N","N",BE5+BJ5+BO5+BT5+BY5) -> 0 | CF5: =IF($AZ5="N","N",(CE5/($CA5+$CC5+$CE5))*100) -> #DIV/0! | CG5: =IF($AZ5="N","N",BB5+BG5+BL5+BQ5+BV5) -> 0 | CH5: =IF($AZ5="N","N",SUM(I5:I8)) -> 0 | CI5: =IF($AZ5="N","N",SUM('調查資料(OUT)'!Q11:Q14)) -> 0 | CJ5: =IF($AZ5="N","N",SUM('調查資料(OUT)'!V11:V14)) -> 0 | CK5: =IF($AZ5="N","N",SUM('調查資料(OUT)'!AA11:AA14)) -> 0 | CL5: =IF($AZ5="N","N",(CH5/DM5)*100) -> #DIV/0! | CM5: =IF($AZ5="N","N",SUM(J5:J8)) -> 0 | CN5: =IF($AZ5="N","N",SUM('調查資料(OUT)'!R11:R14)) -> 0 | CO5: =IF($AZ5="N","N",SUM('調查資料(OUT)'!W11:W14)) -> 0 | CP5: =IF($AZ5="N","N",SUM('調查資料(OUT)'!AB11:AB14)) -> 0 | CQ5: =IF($AZ5="N","N",(CM5/$DM5)*100) -> #DIV/0! | CR5: =IF($AZ5="N","N",SUM(K5:K8)) -> 0 | CS5: =IF($AZ5="N","N",SUM('調查資料(OUT)'!S11:S14)) -> 0 | CT5: =IF($AZ5="N","N",SUM('調查資料(OUT)'!X11:X14)) -> 0 | CU5: =IF($AZ5="N","N",SUM('調查資料(OUT)'!AC11:AC14)) -> 0 | CV5: =IF($AZ5="N","N",(CR5/$DM5)*100) -> #DIV/0! | CW5: =IF($AZ5="N","N",SUM(L5:L8)) -> 0 | CX5: =IF($AZ5="N","N",SUM('調查資料(OUT)'!T11:T14)) -> 0 | CY5: =IF($AZ5="N","N",SUM('調查資料(OUT)'!Y11:Y14)) -> 0 | CZ5: =IF($AZ5="N","N",SUM('調查資料(OUT)'!AD11:AD14)) -> 0 | DA5: =IF($AZ5="N","N",(CW5/$DM5)*100) -> #DIV/0! | DB5: =IF($AZ5="N","N",SUM(M5:M8)) -> 0 | DC5: =IF($AZ5="N","N",SUM('調查資料(OUT)'!U11:U14)) -> 0 | DD5: =IF($AZ5="N","N",SUM('調查資料(OUT)'!Z11:Z14)) -> 0 | DE5: =IF($AZ5="N","N",SUM('調查資料(OUT)'!AE11:AE14)) -> 0 | DF5: =IF($AZ5="N","N",(DB5/$DM5)*100) -> #DIV/0! | DG5: =IF($AZ5="N","N",CI5+CN5+CS5+CX5+DC5) -> 0 | DH5: =IF($AZ5="N","N",(DG5/($DG5+$DI5+$DK5))*100) -> #DIV/0! | DI5: =IF($AZ5="N","N",CJ5+CO5+CT5+CY5+DD5) -> 0 | DJ5: =IF($AZ5="N","N",(DI5/($DG5+$DI5+$DK5))*100) -> #DIV/0! | DK5: =IF($AZ5="N","N",CK5+CP5+CU5+CZ5+DE5) -> 0 | DL5: =IF($AZ5="N","N",(DK5/($DG5+$DI5+$DK5))*100) -> #DIV/0! | DM5: =IF($AZ5="N","N",CH5+CM5+CR5+CW5+DB5) -> 0 | DN5: =IF($AZ5="N","N",SUM(O5:O8)) -> 0 | DO5: =IF($AZ5="N","N",SUM('調查資料(OUT)'!AF11:AF14)) -> 0 | DP5: =IF($AZ5="N","N",SUM('調查資料(OUT)'!AK11:AK14)) -> 0 | DQ5: =IF($AZ5="N","N",SUM('調查資料(OUT)'!AP11:AP14)) -> 0 | DR5: =IF($AZ5="N","N",(DN5/ES5)*100) -> #DIV/0! | DS5: =IF($AZ5="N","N",SUM(P5:P8)) -> 0 | DT5: =IF($AZ5="N","N",SUM('調查資料(OUT)'!AG11:AG14)) -> 0 | DU5: =IF($AZ5="N","N",SUM('調查資料(OUT)'!AL11:AL14)) -> 0 | DV5: =IF($AZ5="N","N",SUM('調查資料(OUT)'!AQ11:AQ14)) -> 0 | DW5: =IF($AZ5="N","N",(DS5/$ES5)*100) -> #DIV/0! | DX5: =IF($AZ5="N","N",SUM(Q5:Q8)) -> 0 | DY5: =IF($AZ5="N","N",SUM('調查資料(OUT)'!AH11:AH14)) -> 0 | DZ5: =IF($AZ5="N","N",SUM('調查資料(OUT)'!AM11:AM14)) -> 0 | EA5: =IF($AZ5="N","N",SUM('調查資料(OUT)'!AR11:AR14)) -> 0 | EB5: =IF($AZ5="N","N",(DX5/$ES5)*100) -> #DIV/0! | EC5: =IF($AZ5="N","N",SUM(R5:R8)) -> 0 | ED5: =IF($AZ5="N","N",SUM('調查資料(OUT)'!AI11:AI14)) -> 0 | EE5: =IF($AZ5="N","N",SUM('調查資料(OUT)'!AN11:AN14)) -> 0 | EF5: =IF($AZ5="N","N",SUM('調查資料(OUT)'!AS11:AS14)) -> 0 | EG5: =IF($AZ5="N","N",(EC5/$ES5)*100) -> #DIV/0! | EH5: =IF($AZ5="N","N",SUM(S5:S8)) -> 0 | EI5: =IF($AZ5="N","N",SUM('調查資料(OUT)'!AJ11:AJ14)) -> 0 | EJ5: =IF($AZ5="N","N",SUM('調查資料(OUT)'!AO11:AO14)) -> 0 | EK5: =IF($AZ5="N","N",SUM('調查資料(OUT)'!AT11:AT14)) -> 0 | EL5: =IF($AZ5="N","N",(EH5/$ES5)*100) -> #DIV/0! | EM5: =IF($AZ5="N","N",DO5+DT5+DY5+ED5+EI5) -> 0 | EN5: =IF($AZ5="N","N",(EM5/($EM5+$EO5+$EQ5))*100) -> #DIV/0! | EO5: =IF($AZ5="N","N",DP5+DU5+DZ5+EE5+EJ5) -> 0 | EP5: =IF($AZ5="N","N",(EO5/($EM5+$EO5+$EQ5))*100) -> #DIV/0! | EQ5: =IF($AZ5="N","N",DQ5+DV5+EA5+EF5+EK5) -> 0 | ER5: =IF($AZ5="N","N",(EQ5/($EM5+$EO5+$EQ5))*100) -> #DIV/0! | ES5: =IF($AZ5="N","N",DN5+DS5+DX5+EC5+EH5) -> 0 | ET5: =IF($AZ5="N","N",SUM(U5:U8)) -> 0 | EU5: =IF($AZ5="N","N",SUM('調查資料(OUT)'!AU11:AU14)) -> 0 | EV5: =IF($AZ5="N","N",SUM('調查資料(OUT)'!AZ11:AZ14)) -> 0 | EW5: =IF($AZ5="N","N",SUM('調查資料(OUT)'!BE11:BE14)) -> 0 | EX5: =IF($AZ5="N","N",(ET5/FY5)*100) -> #DIV/0! | EY5: =IF($AZ5="N","N",SUM(V5:V8)) -> 0 | EZ5: =IF($AZ5="N","N",SUM('調查資料(OUT)'!AV11:AV14)) -> 0 | FA5: =IF($AZ5="N","N",SUM('調查資料(OUT)'!BA11:BA14)) -> 0 | FB5: =IF($AZ5="N","N",SUM('調查資料(OUT)'!BF11:BF14)) -> 0 | FC5: =IF($AZ5="N","N",(EY5/$FY5)*100) -> #DIV/0! | FD5: =IF($AZ5="N","N",SUM(W5:W8)) -> 0 | FE5: =IF($AZ5="N","N",SUM('調查資料(OUT)'!AW11:AW14)) -> 0 | FF5: =IF($AZ5="N","N",SUM('調查資料(OUT)'!BB11:BB14)) -> 0 | FG5: =IF($AZ5="N","N",SUM('調查資料(OUT)'!BG11:BG14)) -> 0 | FH5: =IF($AZ5="N","N",(FD5/$FY5)*100) -> #DIV/0! | FI5: =IF($AZ5="N","N",SUM(X5:X8)) -> 0 | FJ5: =IF($AZ5="N","N",SUM('調查資料(OUT)'!AX11:AX14)) -> 0 | FK5: =IF($AZ5="N","N",SUM('調查資料(OUT)'!BC11:BC14)) -> 0 | FL5: =IF($AZ5="N","N",SUM('調查資料(OUT)'!BH11:BH14)) -> 0 | FM5: =IF($AZ5="N","N",(FI5/$FY5)*100) -> #DIV/0! | FN5: =IF($AZ5="N","N",SUM(Y5:Y8)) -> 0 | FO5: =IF($AZ5="N","N",SUM('調查資料(OUT)'!AY11:AY14)) -> 0 | FP5: =IF($AZ5="N","N",SUM('調查資料(OUT)'!BD11:BD14)) -> 0 | FQ5: =IF($AZ5="N","N",SUM('調查資料(OUT)'!BI11:BI14)) -> 0 | FR5: =IF($AZ5="N","N",(FN5/$FY5)*100) -> #DIV/0! | FS5: =IF($AZ5="N","N",EU5+EZ5+FE5+FJ5+FO5) -> 0 | FT5: =IF($AZ5="N","N",(FS5/($FS5+$FU5+$FW5))*100) -> #DIV/0! | FU5: =IF($AZ5="N","N",EV5+FA5+FF5+FK5+FP5) -> 0 | FV5: =IF($AZ5="N","N",(FU5/($FS5+$FU5+$FW5))*100) -> #DIV/0! | FW5: =IF($AZ5="N","N",EW5+FB5+FG5+FL5+FQ5) -> 0 | FX5: =IF($AZ5="N","N",(FW5/($FS5+$FU5+$FW5))*100) -> #DIV/0! | FY5: =IF($AZ5="N","N",ET5+EY5+FD5+FI5+FN5) -> 0 | FZ5: =IF($AZ5="N","N",SUM(AA5:AA8)) -> 0 | GA5: =IF($AZ5="N","N",SUM('調查資料(OUT)'!BJ11:BJ14)) -> 0 | GB5: =IF($AZ5="N","N",SUM('調查資料(OUT)'!BO11:BO14)) -> 0 | GC5: =IF($AZ5="N","N",SUM('調查資料(OUT)'!BT11:BT14)) -> 0 | GD5: =IF($AZ5="N","N",(FZ5/HE5)*100) -> #DIV/0! | GE5: =IF($AZ5="N","N",SUM(AB5:AB8)) -> 0 | GF5: =IF($AZ5="N","N",SUM('調查資料(OUT)'!BK11:BK14)) -> 0 | GG5: =IF($AZ5="N","N",SUM('調查資料(OUT)'!BP11:BP14)) -> 0 | GH5: =IF($AZ5="N","N",SUM('調查資料(OUT)'!BU11:BU14)) -> 0 | GI5: =IF($AZ5="N","N",(GE5/$HE5)*100) -> #DIV/0! | GJ5: =IF($AZ5="N","N",SUM(AC5:AC8)) -> 0 | GK5: =IF($AZ5="N","N",SUM('調查資料(OUT)'!BL11:BL14)) -> 0 | GL5: =IF($AZ5="N","N",SUM('調查資料(OUT)'!BQ11:BQ14)) -> 0 | GM5: =IF($AZ5="N","N",SUM('調查資料(OUT)'!BV11:BV14)) -> 0 | GN5: =IF($AZ5="N","N",(GJ5/$HE5)*100) -> #DIV/0! | GO5: =IF($AZ5="N","N",SUM(AD5:AD8)) -> 0 | GP5: =IF($AZ5="N","N",SUM('調查資料(OUT)'!BM11:BM14)) -> 0 | GQ5: =IF($AZ5="N","N",SUM('調查資料(OUT)'!BR11:BR14)) -> 0 | GR5: =IF($AZ5="N","N",SUM('調查資料(OUT)'!BW11:BW14)) -> 0 | GS5: =IF($AZ5="N","N",(GO5/$HE5)*100) -> #DIV/0! | GT5: =IF($AZ5="N","N",SUM(AE5:AE8)) -> 0 | GU5: =IF($AZ5="N","N",SUM('調查資料(OUT)'!BN11:BN14)) -> 0 | GV5: =IF($AZ5="N","N",SUM('調查資料(OUT)'!BS11:BS14)) -> 0 | GW5: =IF($AZ5="N","N",SUM('調查資料(OUT)'!BX11:BX14)) -> 0 | GX5: =IF($AZ5="N","N",(GT5/$HE5)*100) -> #DIV/0! | GY5: =IF($AZ5="N","N",GA5+GF5+GK5+GP5+GU5) -> 0 | GZ5: =IF($AZ5="N","N",(GY5/($GY5+$HA5+$HC5))*100) -> #DIV/0! | HA5: =IF($AZ5="N","N",GB5+GG5+GL5+GQ5+GV5) -> 0 | HB5: =IF($AZ5="N","N",(HA5/($GY5+$HA5+$HC5))*100) -> #DIV/0! | HC5: =IF($AZ5="N","N",GC5+GH5+GM5+GR5+GW5) -> 0 | HD5: =IF($AZ5="N","N",(HC5/($GY5+$HA5+$HC5))*100) -> #DIV/0! | HE5: =IF($AZ5="N","N",FZ5+GE5+GJ5+GO5+GT5) -> 0 | HF5: =IF($AZ5="N","N",SUM(AG5:AG8)) -> 0 | HG5: =IF($AZ5="N","N",SUM('調查資料(OUT)'!BY11:BY14)) -> 0 | HH5: =IF($AZ5="N","N",SUM('調查資料(OUT)'!CD11:CD14)) -> 0 | HI5: =IF($AZ5="N","N",SUM('調查資料(OUT)'!CI11:CI14)) -> 0 | HJ5: =IF($AZ5="N","N",(HF5/$IK5)*100) -> #DIV/0! | HK5: =IF($AZ5="N","N",SUM(AH5:AH8)) -> 0 | HL5: =IF($AZ5="N","N",SUM('調查資料(OUT)'!BZ11:BZ14)) -> 0 | HM5: =IF($AZ5="N","N",SUM('調查資料(OUT)'!CE11:CE14)) -> 0 | HN5: =IF($AZ5="N","N",SUM('調查資料(OUT)'!CJ11:CJ14)) -> 0 | HO5: =IF($AZ5="N","N",(HK5/$IK5)*100) -> #DIV/0! | HP5: =IF($AZ5="N","N",SUM(AI5:AI8)) -> 0 | HQ5: =IF($AZ5="N","N",SUM('調查資料(OUT)'!CA11:CA14)) -> 0 | HR5: =IF($AZ5="N","N",SUM('調查資料(OUT)'!CF11:CF14)) -> 0 | HS5: =IF($AZ5="N","N",SUM('調查資料(OUT)'!CK11:CK14)) -> 0 | HT5: =IF($AZ5="N","N",(HP5/$IK5)*100) -> #DIV/0! | HU5: =IF($AZ5="N","N",SUM(AJ5:AJ8)) -> 0 | HV5: =IF($AZ5="N","N",SUM('調查資料(OUT)'!CB11:CB14)) -> 0 | HW5: =IF($AZ5="N","N",SUM('調查資料(OUT)'!CG11:CG14)) -> 0 | HX5: =IF($AZ5="N","N",SUM('調查資料(OUT)'!CL11:CL14)) -> 0 | HY5: =IF($AZ5="N","N",(HU5/$IK5)*100) -> #DIV/0! | HZ5: =IF($AZ5="N","N",SUM(AK5:AK8)) -> 0 | IA5: =IF($AZ5="N","N",SUM('調查資料(OUT)'!CC11:CC14)) -> 0 | IB5: =IF($AZ5="N","N",SUM('調查資料(OUT)'!CH11:CH14)) -> 0 | IC5: =IF($AZ5="N","N",SUM('調查資料(OUT)'!CM11:CM14)) -> 0 | ID5: =IF($AZ5="N","N",(HZ5/$IK5)*100) -> #DIV/0! | IE5: =IF($AZ5="N","N",HG5+HL5+HQ5+HV5+IA5) -> 0 | IF5: =IF($AZ5="N","N",(IE5/($IE5+$IG5+$II5))*100) -> #DIV/0! | IG5: =IF($AZ5="N","N",HH5+HM5+HR5+HW5+IB5) -> 0 | IH5: =IF($AZ5="N","N",(IG5/($IE5+$IG5+$II5))*100) -> #DIV/0! | II5: =IF($AZ5="N","N",HI5+HN5+HS5+HX5+IC5) -> 0 | IJ5: =IF($AZ5="N","N",(II5/($IE5+$IG5+$II5))*100) -> #DIV/0! | IK5: =IF($AZ5="N","N",HF5+HK5+HP5+HU5+HZ5) -> 0
