Workbook
Name _PCU11: [1]基本!$B$35
Name _PCU12: [1]基本!$C$35
Name _PCU13: [1]基本!$D$35
Name _PCU14: [1]基本!$E$35
Name _PCU21: [1]基本!$F$35
Name _PCU22: [1]基本!$G$35
Name _PCU23: [1]基本!$H$35
Name _PCU31: [1]基本!$I$35
Name _PCU32: [1]基本!$J$35
Name _PCU33: [1]基本!$K$35
Name GAM: #REF!
Name GINFO: #REF!
Name GPM: #REF!
Name GRAPH: #REF!
Name HN: [1]集賢!$M$1
Name ROADNAME: [2]基本!$I$5,[2]基本!$G$9,[2]基本!$E$5,[2]基本!$G$1
Name TABLE: #REF!
Name 尖峰: #REF!
Name 夜間: #REF!
Name 時制A: #REF!,#REF!,#REF!,#REF!,#REF!
Name 時制B: #REF!,#REF!,#REF!,#REF!,#REF!
Name 假日: #REF!
Name 週五夜: #REF!
Name 離峰: #REF!

Sheet 轉向量
A1: 臨近路段 | B1: 起始時間 | C1: 結束時間 | D1: 大車A | E1: 大車B | F1: 大車C | G1: 大車D | H1: 小車A | I1: 小車B | J1: 小車C | K1: 小車D | L1: 機車兩段A | M1: 機車A | N1: 機車兩段B | O1: 機車B | P1: 機車兩段C | Q1: 機車C | R1: 機車兩段D | S1: 機車D
A2: A | B2: 0 | C2: 0.010416667 | D2: - | H2: - | L2: - | M2: - | P2: - | R2: -
A3: A | B3: 0.010416667 | C3: 0.020833333 | D3: - | H3: - | L3: - | M3: - | P3: - | R3: -
A4: A | B4: 0.020833333 | C4: 0.03125 | D4: - | H4: - | L4: - | M4: - | P4: - | R4: -
A5: A | B5: 0.03125 | C5: 0.041666667 | D5: - | H5: - | L5: - | M5: - | P5: - | R5: -
A6: A | B6: 0.041666667 | C6: 0.052083333 | D6: - | H6: - | L6: - | M6: - | P6: - | R6: -
A7: A | B7: 0.052083333 | C7: 0.0625 | D7: - | H7: - | L7: - | M7: - | P7: - | R7: -
A8: A | B8: 0.0625 | C8: 0.072916667 | D8: - | H8: - | L8: - | M8: - | P8: - | R8: -
A9: A | B9: 0.072916667 | C9: 0.083333333 | D9: - | H9: - | L9: - | M9: - | P9: - | R9: -
A10: A | B10: 0.083333333 | C10: 0.09375 | D10: - | H10: - | L10: - | M10: - | P10: - | R10: -
A11: A | B11: 0.09375 | C11: 0.10416667 | D11: - | H11: - | L11: - | M11: - | P11: - | R11: -
A12: A | B12: 0.10416667 | C12: 0.11458333 | D12: - | H12: - | L12: - | M12: - | P12: - | R12: -
A13: A | B13: 0.11458333 | C13: 0.125 | D13: - | H13: - | L13: - | M13: - | P13: - | R13: -
... A96: A | B96: 0.97916667 | C96: 0.98958333 | D96: - | H96: - | L96: - | M96: - | P96: - | R96: -
A97: A | B97: 0.98958333 | C97: 24:00 | D97: - | H97: - | L97: - | M97: - | P97: - | R97: -
A98: B | B98: 0 | C98: 0.010416667 | E98: - | I98: - | L98: - | N98: - | O98: - | R98: -
A99: B | B99: 0.010416667 | C99: 0.020833333 | E99: - | I99: - | L99: - | N99: - | O99: - | R99: -
A100: B | B100: 0.020833333 | C100: 0.03125 | E100: - | I100: - | L100: - | N100: - | O100: - | R100: -
A101: B | B101: 0.03125 | C101: 0.041666667 | E101: - | I101: - | L101: - | N101: - | O101: - | R101: -
A102: B | B102: 0.041666667 | C102: 0.052083333 | E102: - | I102: - | L102: - | N102: - | O102: - | R102: -
A103: B | B103: 0.052083333 | C103: 0.0625 | E103: - | I103: - | L103: - | N103: - | O103: - | R103: -
A104: B | B104: 0.0625 | C104: 0.072916667 | E104: - | I104: - | L104: - | N104: - | O104: - | R104: -
A105: B | B105: 0.072916667 | C105: 0.083333333 | E105: - | I105: - | L105: - | N105: - | O105: - | R105: -
A106: B | B106: 0.083333333 | C106: 0.09375 | E106: - | I106: - | L106: - | N106: - | O106: - | R106: -
A107: B | B107: 0.09375 | C107: 0.10416667 | E107: - | I107: - | L107: - | N107: - | O107: - | R107: -
A108: B | B108: 0.10416667 | C108: 0.11458333 | E108: - | I108: - | L108: - | N108: - | O108: - | R108: -
A109: B | B109: 0.11458333 | C109: 0.125 | E109: - | I109: - | L109: - | N109: - | O109: - | R109: -
... A192: B | B192: 0.97916667 | C192: 0.98958333 | E192: - | I192: - | L192: - | N192: - | O192: - | R192: -
A193: B | B193: 0.98958333 | C193: 24:00 | E193: - | I193: - | L193: - | N193: - | O193: - | R193: -
A194: C | B194: 0 | C194: 0.010416667 | F194: - | J194: - | L194: - | N194: - | P194: - | Q194: -
A195: C | B195: 0.010416667 | C195: 0.020833333 | F195: - | J195: - | L195: - | N195: - | P195: - | Q195: -
A196: C | B196: 0.020833333 | C196: 0.03125 | F196: - | J196: - | L196: - | N196: - | P196: - | Q196: -
A197: C | B197: 0.03125 | C197: 0.041666667 | F197: - | J197: - | L197: - | N197: - | P197: - | Q197: -
A198: C | B198: 0.041666667 | C198: 0.052083333 | F198: - | J198: - | L198: - | N198: - | P198: - | Q198: -
A199: C | B199: 0.052083333 | C199: 0.0625 | F199: - | J199: - | L199: - | N199: - | P199: - | Q199: -
A200: C | B200: 0.0625 | C200: 0.072916667 | F200: - | J200: - | L200: - | N200: - | P200: - | Q200: -
A201: C | B201: 0.072916667 | C201: 0.083333333 | F201: - | J201: - | L201: - | N201: - | P201: - | Q201: -
A202: C | B202: 0.083333333 | C202: 0.09375 | F202: - | J202: - | L202: - | N202: - | P202: - | Q202: -
A203: C | B203: 0.09375 | C203: 0.10416667 | F203: - | J203: - | L203: - | N203: - | P203: - | Q203: -
A204: C | B204: 0.10416667 | C204: 0.11458333 | F204: - | J204: - | L204: - | N204: - | P204: - | Q204: -
...

Sheet 路口基本資料
A1: 業主名稱： | G1: 簡圖： | I1: =E15 -> 0 | K1: N
A2: 專案編號： | I2: D | K2: ↑
A4: TC編號：
A5: 路口名稱： | G5: =D15 -> 0 | H5: C | J5: A | K5: =B15 -> 0
A6: 行政區域：
A8: 日期： | B8: YYYY/MM/DD | I8: B
A9: 平假日： | I9: =C15 -> 0
A10: 調查時段：
A11: 天候：
A13: 路口類型： | B13: 正交四叉路口
A14: 方向： | B14: A | C14: B | D14: C | E14: D
A15: 路段名：
A16: 車道數：
A17: 行車方向： | B17: 往西 | C17: 往北 | D17: 往東 | E17: 往南
A18: 機車兩段式左轉： | B18: =IF(SUM('調查資料(OUT)'!H11:H74)>0,TRUE,FALSE) -> FALSE | C18: =IF(SUM('調查資料(OUT)'!R11:R74)>0,TRUE,FALSE) -> FALSE | D18: =IF(SUM('調查資料(OUT)'!AB11:AB74)>0,TRUE,FALSE) -> FALSE | E18: =IF(SUM('調查資料(OUT)'!AL11:AL74)>0,TRUE,FALSE) -> FALSE
A21: 車種設定
A22: 大型車1 | C22: 小型車1 | E22: 機車1 | G22: 特殊1
A23: 大型車2 | C23: 小型車2 | E23: 機車2 | G23: 特殊2
A24: 大型車3 | C24: 小型車3 | E24: 機車3
A25: 大型車4 | C25: 小型車4
A26: 大型車5
A27: 大型車6

Sheet 調查資料(OUT)
A1: 套用PCE | B1: E2 | C1: F2 | D1: G2 | E1: I2 | F1: J2 | G1: K2 | H1: N2 | I1: O2 | J1: Q2 | K1: S2 | L1: E2 | M1: F2 | N1: G2 | O1: I2 | P1: J2 | Q1: K2 | R1: N2 | S1: O2 | T1: Q2 | U1: S2 | V1: E2 | W1: F2 | X1: G2 | Y1: I2 | Z1: J2 | AA1: K2 | AB1: N2 | AC1: O2 | AD1: Q2 | AE1: S2 | AF1: E2 | AG1: F2 | AH1: G2 | AI1: I2 | AJ1: J2 | AK1: K2 | AL1: N2 | AM1: O2 | AN1: Q2 | AO1: S2
B3: ※註： 1. 行車方向若無車輛通過，表示為"0" 2. 若該行車方向為禁行方向，或為非調查時段，表示為"-" 3. 機車兩段左轉，不論是否有待轉區，若無機車兩段左轉，皆表示為"0"
B8: ←A | C8: =路口基本資料!B15 -> 0 | E8: 車道數 | F8: =路口基本資料!$B$16 -> 0 | L8: ↑B | M8: =路口基本資料!C15 -> 0 | O8: 車道數 | P8: =路口基本資料!$C$16 -> 0 | V8: →C | W8: =路口基本資料!D15 -> 0 | Y8: 車道數 | Z8: =路口基本資料!$D$16 -> 0 | AF8: ↓D | AG8: =路口基本資料!E15 -> 0 | AI8: 車道數 | AJ8: =路口基本資料!$E$16 -> 0
A9: 調查 開始時間 | B9: 大型車 | E9: 小型車 | H9: 機車 | L9: 大型車 | O9: 小型車 | R9: 機車 | V9: 大型車 | Y9: 小型車 | AB9: 機車 | AF9: 大型車 | AI9: 小型車 | AL9: 機車
B10: B | C10: C | D10: D | E10: B | F10: C | G10: D | H10: 兩段左轉B | I10: B | J10: C | K10: D | L10: C | M10: D | N10: A | O10: C | P10: D | Q10: A | R10: 兩段左轉C | S10: C | T10: D | U10: A | V10: D | W10: A | X10: B | Y10: D | Z10: A | AA10: B | AB10: 兩段左轉D | AC10: D | AD10: A | AE10: B | AF10: A | AG10: B | AH10: C | AI10: A | AJ10: B | AK10: C | AL10: 兩段左轉A | AM10: A | AN10: B | AO10: C
A11: 0 | B11: =轉向量!E2 -> 0 | C11: =轉向量!F2 -> 0 | D11: =轉向量!G2 -> 0 | E11: =轉向量!I2 -> 0 | F11: =轉向量!J2 -> 0 | G11: =轉向量!K2 -> 0 | H11: =轉向量!N2 -> 0 | I11: =轉向量!O2 -> 0 | J11: =轉向量!Q2 -> 0 | K11: =轉向量!S2 -> 0 | L11: =轉向量!F98 -> 0 | M11: =轉向量!G98 -> 0 | N11: =轉向量!D98 -> 0 | O11: =轉向量!J98 -> 0 | P11: =轉向量!K98 -> 0 | Q11: =轉向量!H98 -> 0 | R11: =轉向量!P98 -> 0 | S11: =轉向量!Q98 -> 0 | T11: =轉向量!S98 -> 0 | U11: =轉向量!M98 -> 0 | V11: =轉向量!G194 -> 0 | W11: =轉向量!D194 -> 0 | X11: =轉向量!E194 -> 0 | Y11: =轉向量!K194 -> 0 | Z11: =轉向量!H194 -> 0 | AA11: =轉向量!I194 -> 0 | AB11: =轉向量!R194 -> 0 | AC11: =轉向量!S194 -> 0 | AD11: =轉向量!M194 -> 0 | AE11: =轉向量!O194 -> 0 | AF11: =轉向量!D290 -> 0 | AG11: =轉向量!E290 -> 0 | AH11: =轉向量!F290 -> 0 | AI11: =轉向量!H290 -> 0 | AJ11: =轉向量!I290 -> 0 | AK11: =轉向量!J290 -> 0 | AL11: =轉向量!L290 -> 0 | AM11: =轉向量!M290 -> 0 | AN11: =轉向量!O290 -> 0 | AO11: =轉向量!Q290 -> 0
A12: 15 | B12: =轉向量!E3 -> 0 | C12: =轉向量!F3 -> 0 | D12: =轉向量!G3 -> 0 | E12: =轉向量!I3 -> 0 | F12: =轉向量!J3 -> 0 | G12: =轉向量!K3 -> 0 | H12: =轉向量!N3 -> 0 | I12: =轉向量!O3 -> 0 | J12: =轉向量!Q3 -> 0 | K12: =轉向量!S3 -> 0 | L12: =轉向量!F99 -> 0 | M12: =轉向量!G99 -> 0 | N12: =轉向量!D99 -> 0 | O12: =轉向量!J99 -> 0 | P12: =轉向量!K99 -> 0 | Q12: =轉向量!H99 -> 0 | R12: =轉向量!P99 -> 0 | S12: =轉向量!Q99 -> 0 | T12: =轉向量!S99 -> 0 | U12: =轉向量!M99 -> 0 | V12: =轉向量!G195 -> 0 | W12: =轉向量!D195 -> 0 | X12: =轉向量!E195 -> 0 | Y12: =轉向量!K195 -> 0 | Z12: =轉向量!H195 -> 0 | AA12: =轉向量!I195 -> 0 | AB12: =轉向量!R195 -> 0 | AC12: =轉向量!S195 -> 0 | AD12: =轉向量!M195 -> 0 | AE12: =轉向量!O195 -> 0 | AF12: =轉向量!D291 -> 0 | AG12: =轉向量!E291 -> 0 | AH12: =轉向量!F291 -> 0 | AI12: =轉向量!H291 -> 0 | AJ12: =轉向量!I291 -> 0 | AK12: =轉向量!J291 -> 0 | AL12: =轉向量!L291 -> 0 | AM12: =轉向量!M291 -> 0 | AN12: =轉向量!O291 -> 0 | AO12: =轉向量!Q291 -> 0
A13: 30 | B13: =轉向量!E4 -> 0 | C13: =轉向量!F4 -> 0 | D13: =轉向量!G4 -> 0 | E13: =轉向量!I4 -> 0 | F13: =轉向量!J4 -> 0 | G13: =轉向量!K4 -> 0 | H13: =轉向量!N4 -> 0 | I13: =轉向量!O4 -> 0 | J13: =轉向量!Q4 -> 0 | K13: =轉向量!S4 -> 0 | L13: =轉向量!F100 -> 0 | M13: =轉向量!G100 -> 0 | N13: =轉向量!D100 -> 0 | O13: =轉向量!J100 -> 0 | P13: =轉向量!K100 -> 0 | Q13: =轉向量!H100 -> 0 | R13: =轉向量!P100 -> 0 | S13: =轉向量!Q100 -> 0 | T13: =轉向量!S100 -> 0 | U13: =轉向量!M100 -> 0 | V13: =轉向量!G196 -> 0 | W13: =轉向量!D196 -> 0 | X13: =轉向量!E196 -> 0 | Y13: =轉向量!K196 -> 0 | Z13: =轉向量!H196 -> 0 | AA13: =轉向量!I196 -> 0 | AB13: =轉向量!R196 -> 0 | AC13: =轉向量!S196 -> 0 | AD13: =轉向量!M196 -> 0 | AE13: =轉向量!O196 -> 0 | AF13: =轉向量!D292 -> 0 | AG13: =轉向量!E292 -> 0 | AH13: =轉向量!F292 -> 0 | AI13: =轉向量!H292 -> 0 | AJ13: =轉向量!I292 -> 0 | AK13: =轉向量!J292 -> 0 | AL13: =轉向量!L292 -> 0 | AM13: =轉向量!M292 -> 0 | AN13: =轉向量!O292 -> 0 | AO13: =轉向量!Q292 -> 0
A14: 45 | B14: =轉向量!E5 -> 0 | C14: =轉向量!F5 -> 0 | D14: =轉向量!G5 -> 0 | E14: =轉向量!I5 -> 0 | F14: =轉向量!J5 -> 0 | G14: =轉向量!K5 -> 0 | H14: =轉向量!N5 -> 0 | I14: =轉向量!O5 -> 0 | J14: =轉向量!Q5 -> 0 | K14: =轉向量!S5 -> 0 | L14: =轉向量!F101 -> 0 | M14: =轉向量!G101 -> 0 | N14: =轉向量!D101 -> 0 | O14: =轉向量!J101 -> 0 | P14: =轉向量!K101 -> 0 | Q14: =轉向量!H101 -> 0 | R14: =轉向量!P101 -> 0 | S14: =轉向量!Q101 -> 0 | T14: =轉向量!S101 -> 0 | U14: =轉向量!M101 -> 0 | V14: =轉向量!G197 -> 0 | W14: =轉向量!D197 -> 0 | X14: =轉向量!E197 -> 0 | Y14: =轉向量!K197 -> 0 | Z14: =轉向量!H197 -> 0 | AA14: =轉向量!I197 -> 0 | AB14: =轉向量!R197 -> 0 | AC14: =轉向量!S197 -> 0 | AD14: =轉向量!M197 -> 0 | AE14: =轉向量!O197 -> 0 | AF14: =轉向量!D293 -> 0 | AG14: =轉向量!E293 -> 0 | AH14: =轉向量!F293 -> 0 | AI14: =轉向量!H293 -> 0 | AJ14: =轉向量!I293 -> 0 | AK14: =轉向量!J293 -> 0 | AL14: =轉向量!L293 -> 0 | AM14: =轉向量!M293 -> 0 | AN14: =轉向量!O293 -> 0 | AO14: =轉向量!Q293 -> 0
A15: 100 | B15: =轉向量!E6 -> 0 | C15: =轉向量!F6 -> 0 | D15: =轉向量!G6 -> 0 | E15: =轉向量!I6 -> 0 | F15: =轉向量!J6 -> 0 | G15: =轉向量!K6 -> 0 | H15: =轉向量!N6 -> 0 | I15: =轉向量!O6 -> 0 | J15: =轉向量!Q6 -> 0 | K15: =轉向量!S6 -> 0 | L15: =轉向量!F102 -> 0 | M15: =轉向量!G102 -> 0 | N15: =轉向量!D102 -> 0 | O15: =轉向量!J102 -> 0 | P15: =轉向量!K102 -> 0 | Q15: =轉向量!H102 -> 0 | R15: =轉向量!P102 -> 0 | S15: =轉向量!Q102 -> 0 | T15: =轉向量!S102 -> 0 | U15: =轉向量!M102 -> 0 | V15: =轉向量!G198 -> 0 | W15: =轉向量!D198 -> 0 | X15: =轉向量!E198 -> 0 | Y15: =轉向量!K198 -> 0 | Z15: =轉向量!H198 -> 0 | AA15: =轉向量!I198 -> 0 | AB15: =轉向量!R198 -> 0 | AC15: =轉向量!S198 -> 0 | AD15: =轉向量!M198 -> 0 | AE15: =轉向量!O198 -> 0 | AF15: =轉向量!D294 -> 0 | AG15: =轉向量!E294 -> 0 | AH15: =轉向量!F294 -> 0 | AI15: =轉向量!H294 -> 0 | AJ15: =轉向量!I294 -> 0 | AK15: =轉向量!J294 -> 0 | AL15: =轉向量!L294 -> 0 | AM15: =轉向量!M294 -> 0 | AN15: =轉向量!O294 -> 0 | AO15: =轉向量!Q294 -> 0
A16: 115 | B16: =轉向量!E7 -> 0 | C16: =轉向量!F7 -> 0 | D16: =轉向量!G7 -> 0 | E16: =轉向量!I7 -> 0 | F16: =轉向量!J7 -> 0 | G16: =轉向量!K7 -> 0 | H16: =轉向量!N7 -> 0 | I16: =轉向量!O7 -> 0 | J16: =轉向量!Q7 -> 0 | K16: =轉向量!S7 -> 0 | L16: =轉向量!F103 -> 0 | M16: =轉向量!G103 -> 0 | N16: =轉向量!D103 -> 0 | O16: =轉向量!J103 -> 0 | P16: =轉向量!K103 -> 0 | Q16: =轉向量!H103 -> 0 | R16: =轉向量!P103 -> 0 | S16: =轉向量!Q103 -> 0 | T16: =轉向量!S103 -> 0 | U16: =轉向量!M103 -> 0 | V16: =轉向量!G199 -> 0 | W16: =轉向量!D199 -> 0 | X16: =轉向量!E199 -> 0 | Y16: =轉向量!K199 -> 0 | Z16: =轉向量!H199 -> 0 | AA16: =轉向量!I199 -> 0 | AB16: =轉向量!R199 -> 0 | AC16: =轉向量!S199 -> 0 | AD16: =轉向量!M199 -> 0 | AE16: =轉向量!O199 -> 0 | AF16: =轉向量!D295 -> 0 | AG16: =轉向量!E295 -> 0 | AH16: =轉向量!F295 -> 0 | AI16: =轉向量!H295 -> 0 | AJ16: =轉向量!I295 -> 0 | AK16: =轉向量!J295 -> 0 | AL16: =轉向量!L295 -> 0 | AM16: =轉向量!M295 -> 0 | AN16: =轉向量!O295 -> 0 | AO16: =轉向量!Q295 -> 0
A17: 130 | B17: =轉向量!E8 -> 0 | C17: =轉向量!F8 -> 0 | D17: =轉向量!G8 -> 0 | E17: =轉向量!I8 -> 0 | F17: =轉向量!J8 -> 0 | G17: =轉向量!K8 -> 0 | H17: =轉向量!N8 -> 0 | I17: =轉向量!O8 -> 0 | J17: =轉向量!Q8 -> 0 | K17: =轉向量!S8 -> 0 | L17: =轉向量!F104 -> 0 | M17: =轉向量!G104 -> 0 | N17: =轉向量!D104 -> 0 | O17: =轉向量!J104 -> 0 | P17: =轉向量!K104 -> 0 | Q17: =轉向量!H104 -> 0 | R17: =轉向量!P104 -> 0 | S17: =轉向量!Q104 -> 0 | T17: =轉向量!S104 -> 0 | U17: =轉向量!M104 -> 0 | V17: =轉向量!G200 -> 0 | W17: =轉向量!D200 -> 0 | X17: =轉向量!E200 -> 0 | Y17: =轉向量!K200 -> 0 | Z17: =轉向量!H200 -> 0 | AA17: =轉向量!I200 -> 0 | AB17: =轉向量!R200 -> 0 | AC17: =轉向量!S200 -> 0 | AD17: =轉向量!M200 -> 0 | AE17: =轉向量!O200 -> 0 | AF17: =轉向量!D296 -> 0 | AG17: =轉向量!E296 -> 0 | AH17: =轉向量!F296 -> 0 | AI17: =轉向量!H296 -> 0 | AJ17: =轉向量!I296 -> 0 | AK17: =轉向量!J296 -> 0 | AL17: =轉向量!L296 -> 0 | AM17: =轉向量!M296 -> 0 | AN17: =轉向量!O296 -> 0 | AO17: =轉向量!Q296 -> 0
A18: 145 | B18: =轉向量!E9 -> 0 | C18: =轉向量!F9 -> 0 | D18: =轉向量!G9 -> 0 | E18: =轉向量!I9 -> 0 | F18: =轉向量!J9 -> 0 | G18: =轉向量!K9 -> 0 | H18: =轉向量!N9 -> 0 | I18: =轉向量!O9 -> 0 | J18: =轉向量!Q9 -> 0 | K18: =轉向量!S9 -> 0 | L18: =轉向量!F105 -> 0 | M18: =轉向量!G105 -> 0 | N18: =轉向量!D105 -> 0 | O18: =轉向量!J105 -> 0 | P18: =轉向量!K105 -> 0 | Q18: =轉向量!H105 -> 0 | R18: =轉向量!P105 -> 0 | S18: =轉向量!Q105 -> 0 | T18: =轉向量!S105 -> 0 | U18: =轉向量!M105 -> 0 | V18: =轉向量!G201 -> 0 | W18: =轉向量!D201 -> 0 | X18: =轉向量!E201 -> 0 | Y18: =轉向量!K201 -> 0 | Z18: =轉向量!H201 -> 0 | AA18: =轉向量!I201 -> 0 | AB18: =轉向量!R201 -> 0 | AC18: =轉向量!S201 -> 0 | AD18: =轉向量!M201 -> 0 | AE18: =轉向量!O201 -> 0 | AF18: =轉向量!D297 -> 0 | AG18: =轉向量!E297 -> 0 | AH18: =轉向量!F297 -> 0 | AI18: =轉向量!H297 -> 0 | AJ18: =轉向量!I297 -> 0 | AK18: =轉向量!J297 -> 0 | AL18: =轉向量!L297 -> 0 | AM18: =轉向量!M297 -> 0 | AN18: =轉向量!O297 -> 0 | AO18: =轉向量!Q297 -> 0
A19: 200 | B19: =轉向量!E10 -> 0 | C19: =轉向量!F10 -> 0 | D19: =轉向量!G10 -> 0 | E19: =轉向量!I10 -> 0 | F19: =轉向量!J10 -> 0 | G19: =轉向量!K10 -> 0 | H19: =轉向量!N10 -> 0 | I19: =轉向量!O10 -> 0 | J19: =轉向量!Q10 -> 0 | K19: =轉向量!S10 -> 0 | L19: =轉向量!F106 -> 0 | M19: =轉向量!G106 -> 0 | N19: =轉向量!D106 -> 0 | O19: =轉向量!J106 -> 0 | P19: =轉向量!K106 -> 0 | Q19: =轉向量!H106 -> 0 | R19: =轉向量!P106 -> 0 | S19: =轉向量!Q106 -> 0 | T19: =轉向量!S106 -> 0 | U19: =轉向量!M106 -> 0 | V19: =轉向量!G202 -> 0 | W19: =轉向量!D202 -> 0 | X19: =轉向量!E202 -> 0 | Y19: =轉向量!K202 -> 0 | Z19: =轉向量!H202 -> 0 | AA19: =轉向量!I202 -> 0 | AB19: =轉向量!R202 -> 0 | AC19: =轉向量!S202 -> 0 | AD19: =轉向量!M202 -> 0 | AE19: =轉向量!O202 -> 0 | AF19: =轉向量!D298 -> 0 | AG19: =轉向量!E298 -> 0 | AH19: =轉向量!F298 -> 0 | AI19: =轉向量!H298 -> 0 | AJ19: =轉向量!I298 -> 0 | AK19: =轉向量!J298 -> 0 | AL19: =轉向量!L298 -> 0 | AM19: =轉向量!M298 -> 0 | AN19: =轉向量!O298 -> 0 | AO19: =轉向量!Q298 -> 0
A20: 215 | B20: =轉向量!E11 -> 0 | C20: =轉向量!F11 -> 0 | D20: =轉向量!G11 -> 0 | E20: =轉向量!I11 -> 0 | F20: =轉向量!J11 -> 0 | G20: =轉向量!K11 -> 0 | H20: =轉向量!N11 -> 0 | I20: =轉向量!O11 -> 0 | J20: =轉向量!Q11 -> 0 | K20: =轉向量!S11 -> 0 | L20: =轉向量!F107 -> 0 | M20: =轉向量!G107 -> 0 | N20: =轉向量!D107 -> 0 | O20: =轉向量!J107 -> 0 | P20: =轉向量!K107 -> 0 | Q20: =轉向量!H107 -> 0 | R20: =轉向量!P107 -> 0 | S20: =轉向量!Q107 -> 0 | T20: =轉向量!S107 -> 0 | U20: =轉向量!M107 -> 0 | V20: =轉向量!G203 -> 0 | W20: =轉向量!D203 -> 0 | X20: =轉向量!E203 -> 0 | Y20: =轉向量!K203 -> 0 | Z20: =轉向量!H203 -> 0 | AA20: =轉向量!I203 -> 0 | AB20: =轉向量!R203 -> 0 | AC20: =轉向量!S203 -> 0 | AD20: =轉向量!M203 -> 0 | AE20: =轉向量!O203 -> 0 | AF20: =轉向量!D299 -> 0 | AG20: =轉向量!E299 -> 0 | AH20: =轉向量!F299 -> 0 | AI20: =轉向量!H299 -> 0 | AJ20: =轉向量!I299 -> 0 | AK20: =轉向量!J299 -> 0 | AL20: =轉向量!L299 -> 0 | AM20: =轉向量!M299 -> 0 | AN20: =轉向量!O299 -> 0 | AO20: =轉向量!Q299 -> 0
A21: 230 | B21: =轉向量!E12 -> 0 | C21: =轉向量!F12 -> 0 | D21: =轉向量!G12 -> 0 | E21: =轉向量!I12 -> 0 | F21: =轉向量!J12 -> 0 | G21: =轉向量!K12 -> 0 | H21: =轉向量!N12 -> 0 | I21: =轉向量!O12 -> 0 | J21: =轉向量!Q12 -> 0 | K21: =轉向量!S12 -> 0 | L21: =轉向量!F108 -> 0 | M21: =轉向量!G108 -> 0 | N21: =轉向量!D108 -> 0 | O21: =轉向量!J108 -> 0 | P21: =轉向量!K108 -> 0 | Q21: =轉向量!H108 -> 0 | R21: =轉向量!P108 -> 0 | S21: =轉向量!Q108 -> 0 | T21: =轉向量!S108 -> 0 | U21: =轉向量!M108 -> 0 | V21: =轉向量!G204 -> 0 | W21: =轉向量!D204 -> 0 | X21: =轉向量!E204 -> 0 | Y21: =轉向量!K204 -> 0 | Z21: =轉向量!H204 -> 0 | AA21: =轉向量!I204 -> 0 | AB21: =轉向量!R204 -> 0 | AC21: =轉向量!S204 -> 0 | AD21: =轉向量!M204 -> 0 | AE21: =轉向量!O204 -> 0 | AF21: =轉向量!D300 -> 0 | AG21: =轉向量!E300 -> 0 | AH21: =轉向量!F300 -> 0 | AI21: =轉向量!H300 -> 0 | AJ21: =轉向量!I300 -> 0 | AK21: =轉向量!J300 -> 0 | AL21: =轉向量!L300 -> 0 | AM21: =轉向量!M300 -> 0 | AN21: =轉向量!O300 -> 0 | AO21: =轉向量!Q300 -> 0
A22: 245 | B22: =轉向量!E13 -> 0 | C22: =轉向量!F13 -> 0 | D22: =轉向量!G13 -> 0 | E22: =轉向量!I13 -> 0 | F22: =轉向量!J13 -> 0 | G22: =轉向量!K13 -> 0 | H22: =轉向量!N13 -> 0 | I22: =轉向量!O13 -> 0 | J22: =轉向量!Q13 -> 0 | K22: =轉向量!S13 -> 0 | L22: =轉向量!F109 -> 0 | M22: =轉向量!G109 -> 0 | N22: =轉向量!D109 -> 0 | O22: =轉向量!J109 -> 0 | P22: =轉向量!K109 -> 0 | Q22: =轉向量!H109 -> 0 | R22: =轉向量!P109 -> 0 | S22: =轉向量!Q109 -> 0 | T22: =轉向量!S109 -> 0 | U22: =轉向量!M109 -> 0 | V22: =轉向量!G205 -> 0 | W22: =轉向量!D205 -> 0 | X22: =轉向量!E205 -> 0 | Y22: =轉向量!K205 -> 0 | Z22: =轉向量!H205 -> 0 | AA22: =轉向量!I205 -> 0 | AB22: =轉向量!R205 -> 0 | AC22: =轉向量!S205 -> 0 | AD22: =轉向量!M205 -> 0 | AE22: =轉向量!O205 -> 0 | AF22: =轉向量!D301 -> 0 | AG22: =轉向量!E301 -> 0 | AH22: =轉向量!F301 -> 0 | AI22: =轉向量!H301 -> 0 | AJ22: =轉向量!I301 -> 0 | AK22: =轉向量!J301 -> 0 | AL22: =轉向量!L301 -> 0 | AM22: =轉向量!M301 -> 0 | AN22: =轉向量!O301 -> 0 | AO22: =轉向量!Q301 -> 0
... A106: 2345 | B106: =轉向量!E97 -> 0 | C106: =轉向量!F97 -> 0 | D106: =轉向量!G97 -> 0 | E106: =轉向量!I97 -> 0 | F106: =轉向量!J97 -> 0 | G106: =轉向量!K97 -> 0 | H106: =轉向量!N97 -> 0 | I106: =轉向量!O97 -> 0 | J106: =轉向量!Q97 -> 0 | K106: =轉向量!S97 -> 0 | L106: =轉向量!F193 -> 0 | M106: =轉向量!G193 -> 0 | N106: =轉向量!D193 -> 0 | O106: =轉向量!J193 -> 0 | P106: =轉向量!K193 -> 0 | Q106: =轉向量!H193 -> 0 | R106: =轉向量!P193 -> 0 | S106: =轉向量!Q193 -> 0 | T106: =轉向量!S193 -> 0 | U106: =轉向量!M193 -> 0 | V106: =轉向量!G289 -> 0 | W106: =轉向量!D289 -> 0 | X106: =轉向量!E289 -> 0 | Y106: =轉向量!K289 -> 0 | Z106: =轉向量!H289 -> 0 | AA106: =轉向量!I289 -> 0 | AB106: =轉向量!R289 -> 0 | AC106: =轉向量!S289 -> 0 | AD106: =轉向量!M289 -> 0 | AE106: =轉向量!O289 -> 0 | AF106: =轉向量!D385 -> 0 | AG106: =轉向量!E385 -> 0 | AH106: =轉向量!F385 -> 0 | AI106: =轉向量!H385 -> 0 | AJ106: =轉向量!I385 -> 0 | AK106: =轉向量!J385 -> 0 | AL106: =轉向量!L385 -> 0 | AM106: =轉向量!M385 -> 0 | AN106: =轉向量!O385 -> 0 | AO106: =轉向量!Q385 -> 0

Sheet PHF及轉向比
AF1: ←A | AV1: 合計 | BC1: ↑B | BS1: 合計 | BZ1: →C | CP1: 合計 | CW1: ↓D | DM1: 合計
B2: ←A | C2: 左轉 | D2: 直行 | E2: 右轉 | F2: ↑B | G2: 左轉 | H2: 直行 | I2: 右轉 | J2: →C | K2: 左轉 | L2: 直行 | M2: 右轉 | N2: ↓D | O2: 左轉 | P2: 直行 | Q2: 右轉 | R2: 路口 | V2: 每小時 | W2: 尖峰小時 | X2: 最大15分鐘 | Y2: A尖峰小時 | Z2: B尖峰小時 | AA2: C尖峰小時 | AB2: D尖峰小時 | AC2: 尖峰小時 | AD2: 尖峰 | AE2: 小時 | AF2: 左轉B | AJ2: 機車 | AK2: 轉向 | AL2: 直行C | AP2: 轉向 | AQ2: 右轉D | AU2: 轉向 | AW2: 車種 | AY2: 車種 | BA2: 車種 | BC2: 左轉C | BG2: 機車 | BH2: 轉向 | BI2: 直行D | BM2: 轉向 | BN2: 右轉A | BR2: 轉向 | BT2: 車種 | BV2: 車種 | BX2: 車種 | BZ2: 左轉D | CD2: 機車 | CE2: 轉向 | CF2: 直行A | CJ2: 轉向 | CK2: 右轉B | CO2: 轉向 | CQ2: 車種 | CS2: 車種 | CU2: 車種 | CW2: 左轉A | DA2: 機車 | DB2: 轉向 | DC2: 直行B | DG2: 轉向 | DH2: 右轉C | DL2: 轉向 | DN2: 車種 | DP2: 車種 | DR2: 車種
B3: 小計 | C3: B | D3: C | E3: D | F3: 小計 | G3: C | H3: D | I3: A | J3: 小計 | K3: D | L3: A | M3: B | N3: 小計 | O3: A | P3: B | Q3: C | R3: 總計 | V3: 交通量 | W3: 交通量 | X3: 交通量 | Y3: 係數 | Z3: 係數 | AA3: 係數 | AB3: 係數 | AC3: 係數 | AD3: 起 | AE3: 迄 | AF3: 小計 | AG3: 大型車 | AH3: 小型車 | AI3: 機車 | AJ3: 兩段左轉 | AK3: 百分比 | AL3: 小計 | AM3: 大型車 | AN3: 小型車 | AO3: 機車 | AP3: 百分比 | AQ3: 小計 | AR3: 大型車 | AS3: 小型車 | AT3: 機車 | AU3: 百分比 | AV3: 大型車 | AW3: 百分比 | AX3: 小型車 | AY3: 百分比 | AZ3: 機車 | BA3: 百分比 | BB3: 合計 | BC3: 小計 | BD3: 大型車 | BE3: 小型車 | BF3: 機車 | BG3: 兩段左轉 | BH3: 百分比 | BI3: 小計 | BJ3: 大型車 | BK3: 小型車 | BL3: 機車 | BM3: 百分比 | BN3: 小計 | BO3: 大型車 | BP3: 小型車 | BQ3: 機車 | BR3: 百分比 | BS3: 大型車 | BT3: 百分比 | BU3: 小型車 | BV3: 百分比 | BW3: 機車 | BX3: 百分比 | BY3: 合計 | BZ3: 小計 | CA3: 大型車 | CB3: 小型車 | CC3: 機車 | CD3: 兩段左轉 | CE3: 百分比 | CF3: 小計 | CG3: 大型車 | CH3: 小型車 | CI3: 機車 | CJ3: 百分比 | CK3: 小計 | CL3: 大型車 | CM3: 小型車 | CN3: 機車 | CO3: 百分比 | CP3: 大型車 | CQ3: 百分比 | CR3: 小型車 | CS3: 百分比 | CT3: 機車 | CU3: 百分比 | CV3: 合計 | CW3: 小計 | CX3: 大型車 | CY3: 小型車 | CZ3: 機車 | DA3: 兩段左轉 | DB3: 百分比 | DC3: 小計 | DD3: 大型車 | DE3: 小型車 | DF3: 機車 | DG3: 百分比 | DH3: 小計 | DI3: 大型車 | DJ3: 小型車 | DK3: 機車 | DL3: 百分比 | DM3: 大型車 | DN3: 百分比 | DO3: 小型車 | DP3: 百分比 | DQ3: 機車 | DR3: 百分比 | DS3: 合計
B4: (PCU) | C4: (PCU) | D4: (PCU) | E4: (PCU) | F4: (PCU) | G4: (PCU) | H4: (PCU) | I4: (PCU) | J4: (PCU) | K4: (PCU) | L4: (PCU) | M4: (PCU) | N4: (PCU) | O4: (PCU) | P4: (PCU) | Q4: (PCU) | R4: (PCU) | V4: （PCU） | W4: （PCU） | X4: （PCU） | Y4: （PHF） | Z4: （PHF） | AA4: （PHF） | AB4: （PHF） | AC4: （PHF） | AF4: （PCU） | AG4: （輛） | AH4: （輛） | AI4: （輛） | AJ4: （輛） | AK4: （％） | AL4: （PCU） | AM4: （輛） | AN4: （輛） | AO4: （輛） | AP4: （％） | AQ4: （PCU） | AR4: （輛） | AS4: （輛） | AT4: （輛） | AU4: （％） | AV4: （輛） | AW4: （％） | AX4: （輛） | AY4: （％） | AZ4: （輛） | BA4: （％） | BB4: （PCU） | BC4: （PCU） | BD4: （輛） | BE4: （輛） | BF4: （輛） | BG4: （輛） | BH4: （％） | BI4: （PCU） | BJ4: （輛） | BK4: （輛） | BL4: （輛） | BM4: （％） | BN4: （PCU） | BO4: （輛） | BP4: （輛） | BQ4: （輛） | BR4: （％） | BS4: （輛） | BT4: （％） | BU4: （輛） | BV4: （％） | BW4: （輛） | BX4: （％） | BY4: （PCU） | BZ4: （PCU） | CA4: （輛） | CB4: （輛） | CC4: （輛） | CD4: （輛） | CE4: （％） | CF4: （PCU） | CG4: （輛） | CH4: （輛） | CI4: （輛） | CJ4: （％） | CK4: （PCU） | CL4: （輛） | CM4: （輛） | CN4: （輛） | CO4: （％） | CP4: （輛） | CQ4: （％） | CR4: （輛） | CS4: （％） | CT4: （輛） | CU4: （％） | CV4: （PCU） | CW4: （PCU） | CX4: （輛） | CY4: （輛） | CZ4: （輛） | DA4: （輛） | DB4: （％） | DC4: （PCU） | DD4: （輛） | DE4: （輛） | DF4: （輛） | DG4: （％） | DH4: （PCU） | DI4: （輛） | DJ4: （輛） | DK4: （輛） | DL4: （％） | DM4: （輛） | DN4: （％） | DO4: （輛） | DP4: （％） | DQ4: （輛） | DR4: （％） | DS4: （PCU）
A5: ='調查資料(OUT)'!A11 -> 0 | B5: =SUM(C5:E5) -> 0 | C5: =IFERROR('調查資料(OUT)'!B$1*'調查資料(OUT)'!B11,0)+IFERROR('調查資料(OUT)'!E$1*'調查資料(OUT)'!E11,0)+IFERROR('調查資料(OUT)'!H$1*'調查資料(OUT)'!H11,0)+IFERROR('調查資料(OUT)'!I$1*'調查資料(OUT)'!I11,0) -> 0 | D5: =IFERROR('調查資料(OUT)'!C$1*'調查資料(OUT)'!C11,0)+IFERROR('調查資料(OUT)'!F$1*'調查資料(OUT)'!F11,0)+IFERROR('調查資料(OUT)'!J$1*'調查資料(OUT)'!J11,0) -> 0 | E5: =IFERROR('調查資料(OUT)'!D$1*'調查資料(OUT)'!D11,0)+IFERROR('調查資料(OUT)'!G$1*'調查資料(OUT)'!G11,0)+IFERROR('調查資料(OUT)'!K$1*'調查資料(OUT)'!K11,0) -> 0 | F5: =SUM(G5:I5) -> 0 | G5: =IFERROR('調查資料(OUT)'!L$1*'調查資料(OUT)'!L11,0)+IFERROR('調查資料(OUT)'!O$1*'調查資料(OUT)'!O11,0)+IFERROR('調查資料(OUT)'!R$1*'調查資料(OUT)'!R11,0)+IFERROR('調查資料(OUT)'!S$1*'調查資料(OUT)'!S11,0) -> 0 | H5: =IFERROR('調查資料(OUT)'!M$1*'調查資料(OUT)'!M11,0)+IFERROR('調查資料(OUT)'!P$1*'調查資料(OUT)'!P11,0)+IFERROR('調查資料(OUT)'!T$1*'調查資料(OUT)'!T11,0) -> 0 | I5: =IFERROR('調查資料(OUT)'!N$1*'調查資料(OUT)'!N11,0)+IFERROR('調查資料(OUT)'!Q$1*'調查資料(OUT)'!Q11,0)+IFERROR('調查資料(OUT)'!U$1*'調查資料(OUT)'!U11,0) -> 0 | J5: =SUM(K5:M5) -> 0 | K5: =IFERROR('調查資料(OUT)'!V$1*'調查資料(OUT)'!V11,0)+IFERROR('調查資料(OUT)'!Y$1*'調查資料(OUT)'!Y11,0)+IFERROR('調查資料(OUT)'!AB$1*'調查資料(OUT)'!AB11,0)+IFERROR('調查資料(OUT)'!AC$1*'調查資料(OUT)'!AC11,0) -> 0 | L5: =IFERROR('調查資料(OUT)'!W$1*'調查資料(OUT)'!W11,0)+IFERROR('調查資料(OUT)'!Z$1*'調查資料(OUT)'!Z11,0)+IFERROR('調查資料(OUT)'!AD$1*'調查資料(OUT)'!AD11,0) -> 0 | M5: =IFERROR('調查資料(OUT)'!X$1*'調查資料(OUT)'!X11,0)+IFERROR('調查資料(OUT)'!AA$1*'調查資料(OUT)'!AA11,0)+IFERROR('調查資料(OUT)'!AE$1*'調查資料(OUT)'!AE11,0) -> 0 | N5: =SUM(O5:Q5) -> 0 | O5: =IFERROR('調查資料(OUT)'!AF$1*'調查資料(OUT)'!AF11,0)+IFERROR('調查資料(OUT)'!AI$1*'調查資料(OUT)'!AI11,0)+IFERROR('調查資料(OUT)'!AL$1*'調查資料(OUT)'!AL11,0)+IFERROR('調查資料(OUT)'!AM$1*'調查資料(OUT)'!AM11,0) -> 0 | P5: =IFERROR('調查資料(OUT)'!AG$1*'調查資料(OUT)'!AG11,0)+IFERROR('調查資料(OUT)'!AJ$1*'調查資料(OUT)'!AJ11,0)+IFERROR('調查資料(OUT)'!AN$1*'調查資料(OUT)'!AN11,0) -> 0 | Q5: =IFERROR('調查資料(OUT)'!AH$1*'調查資料(OUT)'!AH11,0)+IFERROR('調查資料(OUT)'!AK$1*'調查資料(OUT)'!AK11,0)+IFERROR('調查資料(OUT)'!AO$1*'調查資料(OUT)'!AO11,0) -> 0 | R5: =B5+F5+J5+N5 -> 0 | T5: ='調查資料(OUT)'!A11 -> 0 | U5: =T5+100 -> 100 | V5: =SUM(R5:R8) -> 0 | X5: =IF($V5=$W$29,MAX(R5:R8),0) -> 0 | Y5: =IF($V5=W$5,SUM(B5:B8)/(4*(MAX(B5:B8))),0) -> #DIV/0! | Z5: =IF($V5=W$5,SUM(F5:F8)/(4*(MAX(F5:F8))),0) -> #DIV/0! | AA5: =IF($V5=W$5,SUM(J5:J8)/(4*(MAX(J5:J8))),0) -> #DIV/0! | AB5: =IF($V5=W$5,SUM(N5:N8)/(4*(MAX(N5:N8))),0) -> #DIV/0! | AD5: =IF(V5=W$5,$T5,"N") -> 0 | AE5: =IF(V5=W$5,$U5,"N") -> 100 | AF5: =IF($AD5="N","N",SUM(C5:C8)) -> 0 | AG5: =IF($AD5="N","N",SUM('調查資料(OUT)'!B11:B14)) -> 0 | AH5: =IF($AD5="N","N",SUM('調查資料(OUT)'!E11:E14)) -> 0 | AI5: =IF($AD5="N","N",SUM('調查資料(OUT)'!I11:I14)) -> 0 | AJ5: =IF($AD5="N","N",SUM('調查資料(OUT)'!H11:H14)) -> 0 | AK5: =IF($AD5="N","N",(AF5/$BB5)*100) -> #DIV/0! | AL5: =IF($AD5="N","N",SUM(D5:D8)) -> 0 | AM5: =IF($AD5="N","N",SUM('調查資料(OUT)'!C11:C14)) -> 0 | AN5: =IF($AD5="N","N",SUM('調查資料(OUT)'!F11:F14)) -> 0 | AO5: =IF($AD5="N","N",SUM('調查資料(OUT)'!J11:J14)) -> 0 | AP5: =IF($AD5="N","N",(AL5/$BB5)*100) -> #DIV/0! | AQ5: =IF($AD5="N","N",SUM(E5:E8)) -> 0 | AR5: =IF($AD5="N","N",SUM('調查資料(OUT)'!D11:D14)) -> 0 | AS5: =IF($AD5="N","N",SUM('調查資料(OUT)'!G11:G14)) -> 0 | AT5: =IF($AD5="N","N",SUM('調查資料(OUT)'!K11:K14)) -> 0 | AU5: =IF($AD5="N","N",(AQ5/$BB5)*100) -> #DIV/0! | AV5: =IF($AD5="N","N",AG5+AM5+AR5) -> 0 | AW5: =IF($AD5="N","N",(AV5/($AV5+$AX5+$AZ5))*100) -> #DIV/0! | AX5: =IF($AD5="N","N",AH5+AN5+AS5) -> 0 | AY5: =IF($AD5="N","N",(AX5/($AV5+$AX5+$AZ5))*100) -> #DIV/0! | AZ5: =IF($AD5="N","N",AI5+AJ5+AO5+AT5) -> 0 | BA5: =IF($AD5="N","N",(AZ5/($AV5+$AX5+$AZ5))*100) -> #DIV/0! | BB5: =IF($AD5="N","N",AF5+AL5+AQ5) -> 0 | BC5: =IF($AD5="N","N",SUM(G5:G8)) -> 0 | BD5: =IF($AD5="N","N",SUM('調查資料(OUT)'!L11:L14)) -> 0 | BE5: =IF($AD5="N","N",SUM('調查資料(OUT)'!O11:O14)) -> 0 | BF5: =IF($AD5="N","N",SUM('調查資料(OUT)'!S11:S14)) -> 0 | BG5: =IF($AD5="N","N",SUM('調查資料(OUT)'!R11:R14)) -> 0 | BH5: =IF($AD5="N","N",(BC5/BY5)*100) -> #DIV/0! | BI5: =IF($AD5="N","N",SUM(H5:H8)) -> 0 | BJ5: =IF($AD5="N","N",SUM('調查資料(OUT)'!M11:M14)) -> 0 | BK5: =IF($AD5="N","N",SUM('調查資料(OUT)'!P11:P14)) -> 0 | BL5: =IF($AD5="N","N",SUM('調查資料(OUT)'!T11:T14)) -> 0 | BM5: =IF($AD5="N","N",(BI5/BY5)*100) -> #DIV/0! | BN5: =IF($AD5="N","N",SUM(I5:I8)) -> 0 | BO5: =IF($AD5="N","N",SUM('調查資料(OUT)'!N11:N14)) -> 0 | BP5: =IF($AD5="N","N",SUM('調查資料(OUT)'!Q11:Q14)) -> 0 | BQ5: =IF($AD5="N","N",SUM('調查資料(OUT)'!U11:U14)) -> 0 | BR5: =IF($AD5="N","N",(BN5/BY5)*100) -> #DIV/0! | BS5: =IF($AD5="N","N",BD5+BJ5+BO5) -> 0 | BT5: =IF($AD5="N","N",(BS5/($BS5+$BU5+$BW5))*100) -> #DIV/0! | BU5: =IF($AD5="N","N",BE5+BK5+BP5) -> 0 | BV5: =IF($AD5="N","N",(BU5/($BS5+$BU5+$BW5))*100) -> #DIV/0! | BW5: =IF($AD5="N","N",BF5+BG5+BL5+BQ5) -> 0 | BX5: =IF($AD5="N","N",(BW5/($BS5+$BU5+$BW5))*100) -> #DIV/0! | BY5: =IF($AD5="N","N",BC5+BI5+BN5) -> 0 | BZ5: =IF($AD5="N","N",SUM(K5:K8)) -> 0 | CA5: =IF($AD5="N","N",SUM('調查資料(OUT)'!V11:V14)) -> 0 | CB5: =IF($AD5="N","N",SUM('調查資料(OUT)'!Y11:Y14)) -> 0 | CC5: =IF($AD5="N","N",SUM('調查資料(OUT)'!AC11:AC14)) -> 0 | CD5: =IF($AD5="N","N",SUM('調查資料(OUT)'!AB11:AB14)) -> 0 | CE5: =IF($AD5="N","N",(BZ5/CV5)*100) -> #DIV/0! | CF5: =IF($AD5="N","N",SUM(L5:L8)) -> 0 | CG5: =IF($AD5="N","N",SUM('調查資料(OUT)'!W11:W14)) -> 0 | CH5: =IF($AD5="N","N",SUM('調查資料(OUT)'!Z11:Z14)) -> 0 | CI5: =IF($AD5="N","N",SUM('調查資料(OUT)'!AD11:AD14)) -> 0 | CJ5: =IF($AD5="N","N",(CF5/CV5)*100) -> #DIV/0! | CK5: =IF($AD5="N","N",SUM(M5:M8)) -> 0 | CL5: =IF($AD5="N","N",SUM('調查資料(OUT)'!X11:X14)) -> 0 | CM5: =IF($AD5="N","N",SUM('調查資料(OUT)'!AA11:AA14)) -> 0 | CN5: =IF($AD5="N","N",SUM('調查資料(OUT)'!AE11:AE14)) -> 0 | CO5: =IF($AD5="N","N",(CK5/CV5)*100) -> #DIV/0! | CP5: =IF($AD5="N","N",CA5+CG5+CL5) -> 0 | CQ5: =IF($AD5="N","N",(CP5/($CP5+$CR5+$CT5))*100) -> #DIV/0! | CR5: =IF($AD5="N","N",CB5+CH5+CM5) -> 0 | CS5: =IF($AD5="N","N",(CR5/($CP5+$CR5+$CT5))*100) -> #DIV/0! | CT5: =IF($AD5="N","N",CC5+CD5+CI5+CN5) -> 0 | CU5: =IF($AD5="N","N",(CT5/($CP5+$CR5+$CT5))*100) -> #DIV/0! | CV5: =IF($AD5="N","N",BZ5+CF5+CK5) -> 0 | CW5: =IF($AD5="N","N",SUM(O5:O8)) -> 0 | CX5: =IF($AD5="N","N",SUM('調查資料(OUT)'!AF11:AF14)) -> 0 | CY5: =IF($AD5="N","N",SUM('調查資料(OUT)'!AI11:AI14)) -> 0 | CZ5: =IF($AD5="N","N",SUM('調查資料(OUT)'!AM11:AM14)) -> 0 | DA5: =IF($AD5="N","N",SUM('調查資料(OUT)'!AL11:AL14)) -> 0 | DB5: =IF($AD5="N","N",(CW5/DS5)*100) -> #DIV/0! | DC5: =IF($AD5="N","N",SUM(P5:P8)) -> 0 | DD5: =IF($AD5="N","N",SUM('調查資料(OUT)'!AG11:AG14)) -> 0 | DE5: =IF($AD5="N","N",SUM('調查資料(OUT)'!AJ11:AJ14)) -> 0 | DF5: =IF($AD5="N","N",SUM('調查資料(OUT)'!AN11:AN14)) -> 0 | DG5: =IF($AD5="N","N",(DC5/DS5)*100) -> #DIV/0! | DH5: =IF($AD5="N","N",SUM(Q5:Q8)) -> 0 | DI5: =IF($AD5="N","N",SUM('調查資料(OUT)'!AH11:AH14)) -> 0 | DJ5: =IF($AD5="N","N",SUM('調查資料(OUT)'!AK11:AK14)) -> 0 | DK5: =IF($AD5="N","N",SUM('調查資料(OUT)'!AO11:AO14)) -> 0 | DL5: =IF($AD5="N","N",(DH5/DS5)*100) -> #DIV/0! | DM5: =IF($AD5="N","N",CX5+DD5+DI5) -> 0 | DN5: =IF($AD5="N","N",(DM5/($DM5+$DO5+$DQ5))*100) -> #DIV/0! | DO5: =IF($AD5="N","N",CY5+DE5+DJ5) -> 0 | DP5: =IF($AD5="N","N",(DO5/($DM5+$DO5+$DQ5))*100) -> #DIV/0! | DQ5: =IF($AD5="N","N",CZ5+DA5+DF5+DK5) -> 0 | DR5: =IF($AD5="N","N",(DQ5/($DM5+$DO5+$DQ5))*100) -> #DIV/0! | DS5: =IF($AD5="N","N",CW5+DC5+DH5) -> 0
A6: ='調查資料(OUT)'!A12 -> 15 | B6: =SUM(C6:E6) -> 0 | C6: =IFERROR('調查資料(OUT)'!B$1*'調查資料(OUT)'!B12,0)+IFERROR('調查資料(OUT)'!E$1*'調查資料(OUT)'!E12,0)+IFERROR('調查資料(OUT)'!H$1*'調查資料(OUT)'!H12,0)+IFERROR('調查資料(OUT)'!I$1*'調查資料(OUT)'!I12,0) -> 0 | D6: =IFERROR('調查資料(OUT)'!C$1*'調查資料(OUT)'!C12,0)+IFERROR('調查資料(OUT)'!F$1*'調查資料(OUT)'!F12,0)+IFERROR('調查資料(OUT)'!J$1*'調查資料(OUT)'!J12,0) -> 0 | E6: =IFERROR('調查資料(OUT)'!D$1*'調查資料(OUT)'!D12,0)+IFERROR('調查資料(OUT)'!G$1*'調查資料(OUT)'!G12,0)+IFERROR('調查資料(OUT)'!K$1*'調查資料(OUT)'!K12,0) -> 0 | F6: =SUM(G6:I6) -> 0 | G6: =IFERROR('調查資料(OUT)'!L$1*'調查資料(OUT)'!L12,0)+IFERROR('調查資料(OUT)'!O$1*'調查資料(OUT)'!O12,0)+IFERROR('調查資料(OUT)'!R$1*'調查資料(OUT)'!R12,0)+IFERROR('調查資料(OUT)'!S$1*'調查資料(OUT)'!S12,0) -> 0 | H6: =IFERROR('調查資料(OUT)'!M$1*'調查資料(OUT)'!M12,0)+IFERROR('調查資料(OUT)'!P$1*'調查資料(OUT)'!P12,0)+IFERROR('調查資料(OUT)'!T$1*'調查資料(OUT)'!T12,0) -> 0 | I6: =IFERROR('調查資料(OUT)'!N$1*'調查資料(OUT)'!N12,0)+IFERROR('調查資料(OUT)'!Q$1*'調查資料(OUT)'!Q12,0)+IFERROR('調查資料(OUT)'!U$1*'調查資料(OUT)'!U12,0) -> 0 | J6: =SUM(K6:M6) -> 0 | K6: =IFERROR('調查資料(OUT)'!V$1*'調查資料(OUT)'!V12,0)+IFERROR('調查資料(OUT)'!Y$1*'調查資料(OUT)'!Y12,0)+IFERROR('調查資料(OUT)'!AB$1*'調查資料(OUT)'!AB12,0)+IFERROR('調查資料(OUT)'!AC$1*'調查資料(OUT)'!AC12,0) -> 0 | L6: =IFERROR('調查資料(OUT)'!W$1*'調查資料(OUT)'!W12,0)+IFERROR('調查資料(OUT)'!Z$1*'調查資料(OUT)'!Z12,0)+IFERROR('調查資料(OUT)'!AD$1*'調查資料(OUT)'!AD12,0) -> 0 | M6: =IFERROR('調查資料(OUT)'!X$1*'調查資料(OUT)'!X12,0)+IFERROR('調查資料(OUT)'!AA$1*'調查資料(OUT)'!AA12,0)+IFERROR('調查資料(OUT)'!AE$1*'調查資料(OUT)'!AE12,0) -> 0 | N6: =SUM(O6:Q6) -> 0 | O6: =IFERROR('調查資料(OUT)'!AF$1*'調查資料(OUT)'!AF12,0)+IFERROR('調查資料(OUT)'!AI$1*'調查資料(OUT)'!AI12,0)+IFERROR('調查資料(OUT)'!AL$1*'調查資料(OUT)'!AL12,0)+IFERROR('調查資料(OUT)'!AM$1*'調查資料(OUT)'!AM12,0) -> 0 | P6: =IFERROR('調查資料(OUT)'!AG$1*'調查資料(OUT)'!AG12,0)+IFERROR('調查資料(OUT)'!AJ$1*'調查資料(OUT)'!AJ12,0)+IFERROR('調查資料(OUT)'!AN$1*'調查資料(OUT)'!AN12,0) -> 0 | Q6: =IFERROR('調查資料(OUT)'!AH$1*'調查資料(OUT)'!AH12,0)+IFERROR('調查資料(OUT)'!AK$1*'調查資料(OUT)'!AK12,0)+IFERROR('調查資料(OUT)'!AO$1*'調查資料(OUT)'!AO12,0) -> 0 | R6: =B6+F6+J6+N6 -> 0 | T6: ='調查資料(OUT)'!A12 -> 15 | U6: =T6+100 -> 115 | V6: =SUM(R6:R9) -> 0 | X6: =IF($V6=$W$29,MAX(R6:R9),0) -> 0 | Y6: =IF($V6=W$5,SUM(B6:B9)/(4*(MAX(B6:B9))),0) -> #DIV/0! | Z6: =IF($V6=W$5,SUM(F6:F9)/(4*(MAX(F6:F9))),0) -> #DIV/0! | AA6: =IF($V6=W$5,SUM(J6:J9)/(4*(MAX(J6:J9))),0) -> #DIV/0! | AB6: =IF($V6=W$5,SUM(N6:N9)/(4*(MAX(N6:N9))),0) -> #DIV/0! | AD6: =IF(V6=W$5,$T6,"N") -> 15 | AE6: =IF(V6=W$5,$U6,"N") -> 115 | AF6: =IF($AD6="N","N",SUM(C6:C9)) -> 0 | AG6: =IF($AD6="N","N",SUM('調查資料(OUT)'!B12:B15)) -> 0 | AH6: =IF($AD6="N","N",SUM('調查資料(OUT)'!E12:E15)) -> 0 | AI6: =IF($AD6="N","N",SUM('調查資料(OUT)'!I12:I15)) -> 0 | AJ6: =IF($AD6="N","N",SUM('調查資料(OUT)'!H12:H15)) -> 0 | AK6: =IF($AD6="N","N",(AF6/$BB6)*100) -> #DIV/0! | AL6: =IF($AD6="N","N",SUM(D6:D9)) -> 0 | AM6: =IF($AD6="N","N",SUM('調查資料(OUT)'!C12:C15)) -> 0 | AN6: =IF($AD6="N","N",SUM('調查資料(OUT)'!F12:F15)) -> 0 | AO6: =IF($AD6="N","N",SUM('調查資料(OUT)'!J12:J15)) -> 0 | AP6: =IF($AD6="N","N",(AL6/$BB6)*100) -> #DIV/0! | AQ6: =IF($AD6="N","N",SUM(E6:E9)) -> 0 | AR6: =IF($AD6="N","N",SUM('調查資料(OUT)'!D12:D15)) -> 0 | AS6: =IF($AD6="N","N",SUM('調查資料(OUT)'!G12:G15)) -> 0 | AT6: =IF($AD6="N","N",SUM('調查資料(OUT)'!K12:K15)) -> 0 | AU6: =IF($AD6="N","N",(AQ6/$BB6)*100) -> #DIV/0! | AV6: =IF($AD6="N","N",AG6+AM6+AR6) -> 0 | AW6: =IF($AD6="N","N",(AV6/($AV6+$AX6+$AZ6))*100) -> #DIV/0! | AX6: =IF($AD6="N","N",AH6+AN6+AS6) -> 0 | AY6: =IF($AD6="N","N",(AX6/($AV6+$AX6+$AZ6))*100) -> #DIV/0! | AZ6: =IF($AD6="N","N",AI6+AJ6+AO6+AT6) -> 0 | BA6: =IF($AD6="N","N",(AZ6/($AV6+$AX6+$AZ6))*100) -> #DIV/0! | BB6: =IF($AD6="N","N",AF6+AL6+AQ6) -> 0 | BC6: =IF($AD6="N","N",SUM(G6:G9)) -> 0 | BD6: =IF($AD6="N","N",SUM('調查資料(OUT)'!L12:L15)) -> 0 | BE6: =IF($AD6="N","N",SUM('調查資料(OUT)'!O12:O15)) -> 0 | BF6: =IF($AD6="N","N",SUM('調查資料(OUT)'!S12:S15)) -> 0 | BG6: =IF($AD6="N","N",SUM('調查資料(OUT)'!R12:R15)) -> 0 | BH6: =IF($AD6="N","N",(BC6/BY6)*100) -> #DIV/0! | BI6: =IF($AD6="N","N",SUM(H6:H9)) -> 0 | BJ6: =IF($AD6="N","N",SUM('調查資料(OUT)'!M12:M15)) -> 0 | BK6: =IF($AD6="N","N",SUM('調查資料(OUT)'!P12:P15)) -> 0 | BL6: =IF($AD6="N","N",SUM('調查資料(OUT)'!T12:T15)) -> 0 | BM6: =IF($AD6="N","N",(BI6/BY6)*100) -> #DIV/0! | BN6: =IF($AD6="N","N",SUM(I6:I9)) -> 0 | BO6: =IF($AD6="N","N",SUM('調查資料(OUT)'!N12:N15)) -> 0 | BP6: =IF($AD6="N","N",SUM('調查資料(OUT)'!Q12:Q15)) -> 0 | BQ6: =IF($AD6="N","N",SUM('調查資料(OUT)'!U12:U15)) -> 0 | BR6: =IF($AD6="N","N",(BN6/BY6)*100) -> #DIV/0! | BS6: =IF($AD6="N","N",BD6+BJ6+BO6) -> 0 | BT6: =IF($AD6="N","N",(BS6/($BS6+$BU6+$BW6))*100) -> #DIV/0! | BU6: =IF($AD6="N","N",BE6+BK6+BP6) -> 0 | BV6: =IF($AD6="N","N",(BU6/($BS6+$BU6+$BW6))*100) -> #DIV/0! | BW6: =IF($AD6="N","N",BF6+BG6+BL6+BQ6) -> 0 | BX6: =IF($AD6="N","N",(BW6/($BS6+$BU6+$BW6))*100) -> #DIV/0! | BY6: =IF($AD6="N","N",BC6+BI6+BN6) -> 0 | BZ6: =IF($AD6="N","N",SUM(K6:K9)) -> 0 | CA6: =IF($AD6="N","N",SUM('調查資料(OUT)'!V12:V15)) -> 0 | CB6: =IF($AD6="N","N",SUM('調查資料(OUT)'!Y12:Y15)) -> 0 | CC6: =IF($AD6="N","N",SUM('調查資料(OUT)'!AC12:AC15)) -> 0 | CD6: =IF($AD6="N","N",SUM('調查資料(OUT)'!AB12:AB15)) -> 0 | CE6: =IF($AD6="N","N",(BZ6/CV6)*100) -> #DIV/0! | CF6: =IF($AD6="N","N",SUM(L6:L9)) -> 0 | CG6: =IF($AD6="N","N",SUM('調查資料(OUT)'!W12:W15)) -> 0 | CH6: =IF($AD6="N","N",SUM('調查資料(OUT)'!Z12:Z15)) -> 0 | CI6: =IF($AD6="N","N",SUM('調查資料(OUT)'!AD12:AD15)) -> 0 | CJ6: =IF($AD6="N","N",(CF6/CV6)*100) -> #DIV/0! | CK6: =IF($AD6="N","N",SUM(M6:M9)) -> 0 | CL6: =IF($AD6="N","N",SUM('調查資料(OUT)'!X12:X15)) -> 0 | CM6: =IF($AD6="N","N",SUM('調查資料(OUT)'!AA12:AA15)) -> 0 | CN6: =IF($AD6="N","N",SUM('調查資料(OUT)'!AE12:AE15)) -> 0 | CO6: =IF($AD6="N","N",(CK6/CV6)*100) -> #DIV/0! | CP6: =IF($AD6="N","N",CA6+CG6+CL6) -> 0 | CQ6: =IF($AD6="N","N",(CP6/($CP6+$CR6+$CT6))*100) -> #DIV/0! | CR6: =IF($AD6="N","N",CB6+CH6+CM6) -> 0 | CS6: =IF($AD6="N","N",(CR6/($CP6+$CR6+$CT6))*100) -> #DIV/0! | CT6: =IF($AD6="N","N",CC6+CD6+CI6+CN6) -> 0 | CU6: =IF($AD6="N","N",(CT6/($CP6+$CR6+$CT6))*100) -> #DIV/0! | CV6: =IF($AD6="N","N",BZ6+CF6+CK6) -> 0 | CW6: =IF($AD6="N","N",SUM(O6:O9)) -> 0 | CX6: =IF($AD6="N","N",SUM('調查資料(OUT)'!AF12:AF15)) -> 0 | CY6: =IF($AD6="N","N",SUM('調查資料(OUT)'!AI12:AI15)) -> 0 | CZ6: =IF($AD6="N","N",SUM('調查資料(OUT)'!AM12:AM15)) -> 0 | DA6: =IF($AD6="N","N",SUM('調查資料(OUT)'!AL12:AL15)) -> 0 | DB6: =IF($AD6="N","N",(CW6/DS6)*100) -> #DIV/0! | DC6: =IF($AD6="N","N",SUM(P6:P9)) -> 0 | DD6: =IF($AD6="N","N",SUM('調查資料(OUT)'!AG12:AG15)) -> 0 | DE6: =IF($AD6="N","N",SUM('調查資料(OUT)'!AJ12:AJ15)) -> 0 | DF6: =IF($AD6="N","N",SUM('調查資料(OUT)'!AN12:AN15)) -> 0 | DG6: =IF($AD6="N","N",(DC6/DS6)*100) -> #DIV/0! | DH6: =IF($AD6="N","N",SUM(Q6:Q9)) -> 0 | DI6: =IF($AD6="N","N",SUM('調查資料(OUT)'!AH12:AH15)) -> 0 | DJ6: =IF($AD6="N","N",SUM('調查資料(OUT)'!AK12:AK15)) -> 0 | DK6: =IF($AD6="N","N",SUM('調查資料(OUT)'!AO12:AO15)) -> 0 | DL6: =IF($AD6="N","N",(DH6/DS6)*100) -> #DIV/0! | DM6: =IF($AD6="N","N",CX6+DD6+DI6) -> 0 | DN6: =IF($AD6="N","N",(DM6/($DM6+$DO6+$DQ6))*100) -> #DIV/0! | DO6: =IF($AD6="N","N",CY6+DE6+DJ6) -> 0 | DP6: =IF($AD6="N","N",(DO6/($DM6+$DO6+$DQ6))*100) -> #DIV/0! | DQ6: =IF($AD6="N","N",CZ6+DA6+DF6+DK6) -> 0 | DR6: =IF($AD6="N","N",(DQ6/($DM6+$DO6+$DQ6))*100) -> #DIV/0! | DS6: =IF($AD6="N","N",CW6+DC6+DH6) -> 0
A7: ='調查資料(OUT)'!A13 -> 30 | B7: =SUM(C7:E7) -> 0 | C7: =IFERROR('調查資料(OUT)'!B$1*'調查資料(OUT)'!B13,0)+IFERROR('調查資料(OUT)'!E$1*'調查資料(OUT)'!E13,0)+IFERROR('調查資料(OUT)'!H$1*'調查資料(OUT)'!H13,0)+IFERROR('調查資料(OUT)'!I$1*'調查資料(OUT)'!I13,0) -> 0 | D7: =IFERROR('調查資料(OUT)'!C$1*'調查資料(OUT)'!C13,0)+IFERROR('調查資料(OUT)'!F$1*'調查資料(OUT)'!F13,0)+IFERROR('調查資料(OUT)'!J$1*'調查資料(OUT)'!J13,0) -> 0 | E7: =IFERROR('調查資料(OUT)'!D$1*'調查資料(OUT)'!D13,0)+IFERROR('調查資料(OUT)'!G$1*'調查資料(OUT)'!G13,0)+IFERROR('調查資料(OUT)'!K$1*'調查資料(OUT)'!K13,0) -> 0 | F7: =SUM(G7:I7) -> 0 | G7: =IFERROR('調查資料(OUT)'!L$1*'調查資料(OUT)'!L13,0)+IFERROR('調查資料(OUT)'!O$1*'調查資料(OUT)'!O13,0)+IFERROR('調查資料(OUT)'!R$1*'調查資料(OUT)'!R13,0)+IFERROR('調查資料(OUT)'!S$1*'調查資料(OUT)'!S13,0) -> 0 | H7: =IFERROR('調查資料(OUT)'!M$1*'調查資料(OUT)'!M13,0)+IFERROR('調查資料(OUT)'!P$1*'調查資料(OUT)'!P13,0)+IFERROR('調查資料(OUT)'!T$1*'調查資料(OUT)'!T13,0) -> 0 | I7: =IFERROR('調查資料(OUT)'!N$1*'調查資料(OUT)'!N13,0)+IFERROR('調查資料(OUT)'!Q$1*'調查資料(OUT)'!Q13,0)+IFERROR('調查資料(OUT)'!U$1*'調查資料(OUT)'!U13,0) -> 0 | J7: =SUM(K7:M7) -> 0 | K7: =IFERROR('調查資料(OUT)'!V$1*'調查資料(OUT)'!V13,0)+IFERROR('調查資料(OUT)'!Y$1*'調查資料(OUT)'!Y13,0)+IFERROR('調查資料(OUT)'!AB$1*'調查資料(OUT)'!AB13,0)+IFERROR('調查資料(OUT)'!AC$1*'調查資料(OUT)'!AC13,0) -> 0 | L7: =IFERROR('調查資料(OUT)'!W$1*'調查資料(OUT)'!W13,0)+IFERROR('調查資料(OUT)'!Z$1*'調查資料(OUT)'!Z13,0)+IFERROR('調查資料(OUT)'!AD$1*'調查資料(OUT)'!AD13,0) -> 0 | M7: =IFERROR('調查資料(OUT)'!X$1*'調查資料(OUT)'!X13,0)+IFERROR('調查資料(OUT)'!AA$1*'調查資料(OUT)'!AA13,0)+IFERROR('調查資料(OUT)'!AE$1*'調查資料(OUT)'!AE13,0) -> 0 | N7: =SUM(O7:Q7) -> 0 | O7: =IFERROR('調查資料(OUT)'!AF$1*'調查資料(OUT)'!AF13,0)+IFERROR('調查資料(OUT)'!AI$1*'調查資料(OUT)'!AI13,0)+IFERROR('調查資料(OUT)'!AL$1*'調查資料(OUT)'!AL13,0)+IFERROR('調查資料(OUT)'!AM$1*'調查資料(OUT)'!AM13,0) -> 0 | P7: =IFERROR('調查資料(OUT)'!AG$1*'調查資料(OUT)'!AG13,0)+IFERROR('調查資料(OUT)'!AJ$1*'調查資料(OUT)'!AJ13,0)+IFERROR('調查資料(OUT)'!AN$1*'調查資料(OUT)'!AN13,0) -> 0 | Q7: =IFERROR('調查資料(OUT)'!AH$1*'調查資料(OUT)'!AH13,0)+IFERROR('調查資料(OUT)'!AK$1*'調查資料(OUT)'!AK13,0)+IFERROR('調查資料(OUT)'!AO$1*'調查資料(OUT)'!AO13,0) -> 0 | R7: =B7+F7+J7+N7 -> 0 | T7: ='調查資料(OUT)'!A13 -> 30 | U7: =T7+100 -> 130 | V7: =SUM(R7:R10) -> 0 | X7: =IF($V7=$W$29,MAX(R7:R10),0) -> 0 | Y7: =IF($V7=W$5,SUM(B7:B10)/(4*(MAX(B7:B10))),0) -> #DIV/0! | Z7: =IF($V7=W$5,SUM(F7:F10)/(4*(MAX(F7:F10))),0) -> #DIV/0! | AA7: =IF($V7=W$5,SUM(J7:J10)/(4*(MAX(J7:J10))),0) -> #DIV/0! | AB7: =IF($V7=W$5,SUM(N7:N10)/(4*(MAX(N7:N10))),0) -> #DIV/0! | AD7: =IF(V7=W$5,$T7,"N") -> 30 | AE7: =IF(V7=W$5,$U7,"N") -> 130 | AF7: =IF($AD7="N","N",SUM(C7:C10)) -> 0 | AG7: =IF($AD7="N","N",SUM('調查資料(OUT)'!B13:B16)) -> 0 | AH7: =IF($AD7="N","N",SUM('調查資料(OUT)'!E13:E16)) -> 0 | AI7: =IF($AD7="N","N",SUM('調查資料(OUT)'!I13:I16)) -> 0 | AJ7: =IF($AD7="N","N",SUM('調查資料(OUT)'!H13:H16)) -> 0 | AK7: =IF($AD7="N","N",(AF7/$BB7)*100) -> #DIV/0! | AL7: =IF($AD7="N","N",SUM(D7:D10)) -> 0 | AM7: =IF($AD7="N","N",SUM('調查資料(OUT)'!C13:C16)) -> 0 | AN7: =IF($AD7="N","N",SUM('調查資料(OUT)'!F13:F16)) -> 0 | AO7: =IF($AD7="N","N",SUM('調查資料(OUT)'!J13:J16)) -> 0 | AP7: =IF($AD7="N","N",(AL7/$BB7)*100) -> #DIV/0! | AQ7: =IF($AD7="N","N",SUM(E7:E10)) -> 0 | AR7: =IF($AD7="N","N",SUM('調查資料(OUT)'!D13:D16)) -> 0 | AS7: =IF($AD7="N","N",SUM('調查資料(OUT)'!G13:G16)) -> 0 | AT7: =IF($AD7="N","N",SUM('調查資料(OUT)'!K13:K16)) -> 0 | AU7: =IF($AD7="N","N",(AQ7/$BB7)*100) -> #DIV/0! | AV7: =IF($AD7="N","N",AG7+AM7+AR7) -> 0 | AW7: =IF($AD7="N","N",(AV7/($AV7+$AX7+$AZ7))*100) -> #DIV/0! | AX7: =IF($AD7="N","N",AH7+AN7+AS7) -> 0 | AY7: =IF($AD7="N","N",(AX7/($AV7+$AX7+$AZ7))*100) -> #DIV/0! | AZ7: =IF($AD7="N","N",AI7+AJ7+AO7+AT7) -> 0 | BA7: =IF($AD7="N","N",(AZ7/($AV7+$AX7+$AZ7))*100) -> #DIV/0! | BB7: =IF($AD7="N","N",AF7+AL7+AQ7) -> 0 | BC7: =IF($AD7="N","N",SUM(G7:G10)) -> 0 | BD7: =IF($AD7="N","N",SUM('調查資料(OUT)'!L13:L16)) -> 0 | BE7: =IF($AD7="N","N",SUM('調查資料(OUT)'!O13:O16)) -> 0 | BF7: =IF($AD7="N","N",SUM('調查資料(OUT)'!S13:S16)) -> 0 | BG7: =IF($AD7="N","N",SUM('調查資料(OUT)'!R13:R16)) -> 0 | BH7: =IF($AD7="N","N",(BC7/BY7)*100) -> #DIV/0! | BI7: =IF($AD7="N","N",SUM(H7:H10)) -> 0 | BJ7: =IF($AD7="N","N",SUM('調查資料(OUT)'!M13:M16)) -> 0 | BK7: =IF($AD7="N","N",SUM('調查資料(OUT)'!P13:P16)) -> 0 | BL7: =IF($AD7="N","N",SUM('調查資料(OUT)'!T13:T16)) -> 0 | BM7: =IF($AD7="N","N",(BI7/BY7)*100) -> #DIV/0! | BN7: =IF($AD7="N","N",SUM(I7:I10)) -> 0 | BO7: =IF($AD7="N","N",SUM('調查資料(OUT)'!N13:N16)) -> 0 | BP7: =IF($AD7="N","N",SUM('調查資料(OUT)'!Q13:Q16)) -> 0 | BQ7: =IF($AD7="N","N",SUM('調查資料(OUT)'!U13:U16)) -> 0 | BR7: =IF($AD7="N","N",(BN7/BY7)*100) -> #DIV/0! | BS7: =IF($AD7="N","N",BD7+BJ7+BO7) -> 0 | BT7: =IF($AD7="N","N",(BS7/($BS7+$BU7+$BW7))*100) -> #DIV/0! | BU7: =IF($AD7="N","N",BE7+BK7+BP7) -> 0 | BV7: =IF($AD7="N","N",(BU7/($BS7+$BU7+$BW7))*100) -> #DIV/0! | BW7: =IF($AD7="N","N",BF7+BG7+BL7+BQ7) -> 0 | BX7: =IF($AD7="N","N",(BW7/($BS7+$BU7+$BW7))*100) -> #DIV/0! | BY7: =IF($AD7="N","N",BC7+BI7+BN7) -> 0 | BZ7: =IF($AD7="N","N",SUM(K7:K10)) -> 0 | CA7: =IF($AD7="N","N",SUM('調查資料(OUT)'!V13:V16)) -> 0 | CB7: =IF($AD7="N","N",SUM('調查資料(OUT)'!Y13:Y16)) -> 0 | CC7: =IF($AD7="N","N",SUM('調查資料(OUT)'!AC13:AC16)) -> 0 | CD7: =IF($AD7="N","N",SUM('調查資料(OUT)'!AB13:AB16)) -> 0 | CE7: =IF($AD7="N","N",(BZ7/CV7)*100) -> #DIV/0! | CF7: =IF($AD7="N","N",SUM(L7:L10)) -> 0 | CG7: =IF($AD7="N","N",SUM('調查資料(OUT)'!W13:W16)) -> 0 | CH7: =IF($AD7="N","N",SUM('調查資料(OUT)'!Z13:Z16)) -> 0 | CI7: =IF($AD7="N","N",SUM('調查資料(OUT)'!AD13:AD16)) -> 0 | CJ7: =IF($AD7="N","N",(CF7/CV7)*100) -> #DIV/0! | CK7: =IF($AD7="N","N",SUM(M7:M10)) -> 0 | CL7: =IF($AD7="N","N",SUM('調查資料(OUT)'!X13:X16)) -> 0 | CM7: =IF($AD7="N","N",SUM('調查資料(OUT)'!AA13:AA16)) -> 0 | CN7: =IF($AD7="N","N",SUM('調查資料(OUT)'!AE13:AE16)) -> 0 | CO7: =IF($AD7="N","N",(CK7/CV7)*100) -> #DIV/0! | CP7: =IF($AD7="N","N",CA7+CG7+CL7) -> 0 | CQ7: =IF($AD7="N","N",(CP7/($CP7+$CR7+$CT7))*100) -> #DIV/0! | CR7: =IF($AD7="N","N",CB7+CH7+CM7) -> 0 | CS7: =IF($AD7="N","N",(CR7/($CP7+$CR7+$CT7))*100) -> #DIV/0! | CT7: =IF($AD7="N","N",CC7+CD7+CI7+CN7) -> 0 | CU7: =IF($AD7="N","N",(CT7/($CP7+$CR7+$CT7))*100) -> #DIV/0! | CV7: =IF($AD7="N","N",BZ7+CF7+CK7) -> 0 | CW7: =IF($AD7="N","N",SUM(O7:O10)) -> 0 | CX7: =IF($AD7="N","N",SUM('調查資料(OUT)'!AF13:AF16)) -> 0 | CY7: =IF($AD7="N","N",SUM('調查資料(OUT)'!AI13:AI16)) -> 0 | CZ7: =IF($AD7="N","N",SUM('調查資料(OUT)'!AM13:AM16)) -> 0 | DA7: =IF($AD7="N","N",SUM('調查資料(OUT)'!AL13:AL16)) -> 0 | DB7: =IF($AD7="N","N",(CW7/DS7)*100) -> #DIV/0! | DC7: =IF($AD7="N","N",SUM(P7:P10)) -> 0 | DD7: =IF($AD7="N","N",SUM('調查資料(OUT)'!AG13:AG16)) -> 0 | DE7: =IF($AD7="N","N",SUM('調查資料(OUT)'!AJ13:AJ16)) -> 0 | DF7: =IF($AD7="N","N",SUM('調查資料(OUT)'!AN13:AN16)) -> 0 | DG7: =IF($AD7="N","N",(DC7/DS7)*100) -> #DIV/0! | DH7: =IF($AD7="N","N",SUM(Q7:Q10)) -> 0 | DI7: =IF($AD7="N","N",SUM('調查資料(OUT)'!AH13:AH16)) -> 0 | DJ7: =IF($AD7="N","N",SUM('調查資料(OUT)'!AK13:AK16)) -> 0 | DK7: =IF($AD7="N","N",SUM('調查資料(OUT)'!AO13:AO16)) -> 0 | DL7: =IF($AD7="N","N",(DH7/DS7)*100) -> #DIV/0! | DM7: =IF($AD7="N","N",CX7+DD7+DI7) -> 0 | DN7: =IF($AD7="N","N",(DM7/($DM7+$DO7+$DQ7))*100) -> #DIV/0! | DO7: =IF($AD7="N","N",CY7+DE7+DJ7) -> 0 | DP7: =IF($AD7="N","N",(DO7/($DM7+$DO7+$DQ7))*100) -> #DIV/0! | DQ7: =IF($AD7="N","N",CZ7+DA7+DF7+DK7) -> 0 | DR7: =IF($AD7="N","N",(DQ7/($DM7+$DO7+$DQ7))*100) -> #DIV/0! | DS7: =IF($AD7="N","N",CW7+DC7+DH7) -> 0
A8: ='調查資料(OUT)'!A14 -> 45 | B8: =SUM(C8:E8) -> 0 | C8: =IFERROR('調查資料(OUT)'!B$1*'調查資料(OUT)'!B14,0)+IFERROR('調查資料(OUT)'!E$1*'調查資料(OUT)'!E14,0)+IFERROR('調查資料(OUT)'!H$1*'調查資料(OUT)'!H14,0)+IFERROR('調查資料(OUT)'!I$1*'調查資料(OUT)'!I14,0) -> 0 | D8: =IFERROR('調查資料(OUT)'!C$1*'調查資料(OUT)'!C14,0)+IFERROR('調查資料(OUT)'!F$1*'調查資料(OUT)'!F14,0)+IFERROR('調查資料(OUT)'!J$1*'調查資料(OUT)'!J14,0) -> 0 | E8: =IFERROR('調查資料(OUT)'!D$1*'調查資料(OUT)'!D14,0)+IFERROR('調查資料(OUT)'!G$1*'調查資料(OUT)'!G14,0)+IFERROR('調查資料(OUT)'!K$1*'調查資料(OUT)'!K14,0) -> 0 | F8: =SUM(G8:I8) -> 0 | G8: =IFERROR('調查資料(OUT)'!L$1*'調查資料(OUT)'!L14,0)+IFERROR('調查資料(OUT)'!O$1*'調查資料(OUT)'!O14,0)+IFERROR('調查資料(OUT)'!R$1*'調查資料(OUT)'!R14,0)+IFERROR('調查資料(OUT)'!S$1*'調查資料(OUT)'!S14,0) -> 0 | H8: =IFERROR('調查資料(OUT)'!M$1*'調查資料(OUT)'!M14,0)+IFERROR('調查資料(OUT)'!P$1*'調查資料(OUT)'!P14,0)+IFERROR('調查資料(OUT)'!T$1*'調查資料(OUT)'!T14,0) -> 0 | I8: =IFERROR('調查資料(OUT)'!N$1*'調查資料(OUT)'!N14,0)+IFERROR('調查資料(OUT)'!Q$1*'調查資料(OUT)'!Q14,0)+IFERROR('調查資料(OUT)'!U$1*'調查資料(OUT)'!U14,0) -> 0 | J8: =SUM(K8:M8) -> 0 | K8: =IFERROR('調查資料(OUT)'!V$1*'調查資料(OUT)'!V14,0)+IFERROR('調查資料(OUT)'!Y$1*'調查資料(OUT)'!Y14,0)+IFERROR('調查資料(OUT)'!AB$1*'調查資料(OUT)'!AB14,0)+IFERROR('調查資料(OUT)'!AC$1*'調查資料(OUT)'!AC14,0) -> 0 | L8: =IFERROR('調查資料(OUT)'!W$1*'調查資料(OUT)'!W14,0)+IFERROR('調查資料(OUT)'!Z$1*'調查資料(OUT)'!Z14,0)+IFERROR('調查資料(OUT)'!AD$1*'調查資料(OUT)'!AD14,0) -> 0 | M8: =IFERROR('調查資料(OUT)'!X$1*'調查資料(OUT)'!X14,0)+IFERROR('調查資料(OUT)'!AA$1*'調查資料(OUT)'!AA14,0)+IFERROR('調查資料(OUT)'!AE$1*'調查資料(OUT)'!AE14,0) -> 0 | N8: =SUM(O8:Q8) -> 0 | O8: =IFERROR('調查資料(OUT)'!AF$1*'調查資料(OUT)'!AF14,0)+IFERROR('調查資料(OUT)'!AI$1*'調查資料(OUT)'!AI14,0)+IFERROR('調查資料(OUT)'!AL$1*'調查資料(OUT)'!AL14,0)+IFERROR('調查資料(OUT)'!AM$1*'調查資料(OUT)'!AM14,0) -> 0 | P8: =IFERROR('調查資料(OUT)'!AG$1*'調查資料(OUT)'!AG14,0)+IFERROR('調查資料(OUT)'!AJ$1*'調查資料(OUT)'!AJ14,0)+IFERROR('調查資料(OUT)'!AN$1*'調查資料(OUT)'!AN14,0) -> 0 | Q8: =IFERROR('調查資料(OUT)'!AH$1*'調查資料(OUT)'!AH14,0)+IFERROR('調查資料(OUT)'!AK$1*'調查資料(OUT)'!AK14,0)+IFERROR('調查資料(OUT)'!AO$1*'調查資料(OUT)'!AO14,0) -> 0 | R8: =B8+F8+J8+N8 -> 0 | T8: ='調查資料(OUT)'!A14 -> 45 | U8: =T8+100 -> 145 | V8: =SUM(R8:R11) -> 0 | X8: =IF($V8=$W$29,MAX(R8:R11),0) -> 0 | Y8: =IF($V8=W$5,SUM(B8:B11)/(4*(MAX(B8:B11))),0) -> #DIV/0! | Z8: =IF($V8=W$5,SUM(F8:F11)/(4*(MAX(F8:F11))),0) -> #DIV/0! | AA8: =IF($V8=W$5,SUM(J8:J11)/(4*(MAX(J8:J11))),0) -> #DIV/0! | AB8: =IF($V8=W$5,SUM(N8:N11)/(4*(MAX(N8:N11))),0) -> #DIV/0! | AD8: =IF(V8=W$5,$T8,"N") -> 45 | AE8: =IF(V8=W$5,$U8,"N") -> 145 | AF8: =IF($AD8="N","N",SUM(C8:C11)) -> 0 | AG8: =IF($AD8="N","N",SUM('調查資料(OUT)'!B14:B17)) -> 0 | AH8: =IF($AD8="N","N",SUM('調查資料(OUT)'!E14:E17)) -> 0 | AI8: =IF($AD8="N","N",SUM('調查資料(OUT)'!I14:I17)) -> 0 | AJ8: =IF($AD8="N","N",SUM('調查資料(OUT)'!H14:H17)) -> 0 | AK8: =IF($AD8="N","N",(AF8/$BB8)*100) -> #DIV/0! | AL8: =IF($AD8="N","N",SUM(D8:D11)) -> 0 | AM8: =IF($AD8="N","N",SUM('調查資料(OUT)'!C14:C17)) -> 0 | AN8: =IF($AD8="N","N",SUM('調查資料(OUT)'!F14:F17)) -> 0 | AO8: =IF($AD8="N","N",SUM('調查資料(OUT)'!J14:J17)) -> 0 | AP8: =IF($AD8="N","N",(AL8/$BB8)*100) -> #DIV/0! | AQ8: =IF($AD8="N","N",SUM(E8:E11)) -> 0 | AR8: =IF($AD8="N","N",SUM('調查資料(OUT)'!D14:D17)) -> 0 | AS8: =IF($AD8="N","N",SUM('調查資料(OUT)'!G14:G17)) -> 0 | AT8: =IF($AD8="N","N",SUM('調查資料(OUT)'!K14:K17)) -> 0 | AU8: =IF($AD8="N","N",(AQ8/$BB8)*100) -> #DIV/0! | AV8: =IF($AD8="N","N",AG8+AM8+AR8) -> 0 | AW8: =IF($AD8="N","N",(AV8/($AV8+$AX8+$AZ8))*100) -> #DIV/0! | AX8: =IF($AD8="N","N",AH8+AN8+AS8) -> 0 | AY8: =IF($AD8="N","N",(AX8/($AV8+$AX8+$AZ8))*100) -> #DIV/0! | AZ8: =IF($AD8="N","N",AI8+AJ8+AO8+AT8) -> 0 | BA8: =IF($AD8="N","N",(AZ8/($AV8+$AX8+$AZ8))*100) -> #DIV/0! | BB8: =IF($AD8="N","N",AF8+AL8+AQ8) -> 0 | BC8: =IF($AD8="N","N",SUM(G8:G11)) -> 0 | BD8: =IF($AD8="N","N",SUM('調查資料(OUT)'!L14:L17)) -> 0 | BE8: =IF($AD8="N","N",SUM('調查資料(OUT)'!O14:O17)) -> 0 | BF8: =IF($AD8="N","N",SUM('調查資料(OUT)'!S14:S17)) -> 0 | BG8: =IF($AD8="N","N",SUM('調查資料(OUT)'!R14:R17)) -> 0 | BH8: =IF($AD8="N","N",(BC8/BY8)*100) -> #DIV/0! | BI8: =IF($AD8="N","N",SUM(H8:H11)) -> 0 | BJ8: =IF($AD8="N","N",SUM('調查資料(OUT)'!M14:M17)) -> 0 | BK8: =IF($AD8="N","N",SUM('調查資料(OUT)'!P14:P17)) -> 0 | BL8: =IF($AD8="N","N",SUM('調查資料(OUT)'!T14:T17)) -> 0 | BM8: =IF($AD8="N","N",(BI8/BY8)*100) -> #DIV/0! | BN8: =IF($AD8="N","N",SUM(I8:I11)) -> 0 | BO8: =IF($AD8="N","N",SUM('調查資料(OUT)'!N14:N17)) -> 0 | BP8: =IF($AD8="N","N",SUM('調查資料(OUT)'!Q14:Q17)) -> 0 | BQ8: =IF($AD8="N","N",SUM('調查資料(OUT)'!U14:U17)) -> 0 | BR8: =IF($AD8="N","N",(BN8/BY8)*100) -> #DIV/0! | BS8: =IF($AD8="N","N",BD8+BJ8+BO8) -> 0 | BT8: =IF($AD8="N","N",(BS8/($BS8+$BU8+$BW8))*100) -> #DIV/0! | BU8: =IF($AD8="N","N",BE8+BK8+BP8) -> 0 | BV8: =IF($AD8="N","N",(BU8/($BS8+$BU8+$BW8))*100) -> #DIV/0! | BW8: =IF($AD8="N","N",BF8+BG8+BL8+BQ8) -> 0 | BX8: =IF($AD8="N","N",(BW8/($BS8+$BU8+$BW8))*100) -> #DIV/0! | BY8: =IF($AD8="N","N",BC8+BI8+BN8) -> 0 | BZ8: =IF($AD8="N","N",SUM(K8:K11)) -> 0 | CA8: =IF($AD8="N","N",SUM('調查資料(OUT)'!V14:V17)) -> 0 | CB8: =IF($AD8="N","N",SUM('調查資料(OUT)'!Y14:Y17)) -> 0 | CC8: =IF($AD8="N","N",SUM('調查資料(OUT)'!AC14:AC17)) -> 0 | CD8: =IF($AD8="N","N",SUM('調查資料(OUT)'!AB14:AB17)) -> 0 | CE8: =IF($AD8="N","N",(BZ8/CV8)*100) -> #DIV/0! | CF8: =IF($AD8="N","N",SUM(L8:L11)) -> 0 | CG8: =IF($AD8="N","N",SUM('調查資料(OUT)'!W14:W17)) -> 0 | CH8: =IF($AD8="N","N",SUM('調查資料(OUT)'!Z14:Z17)) -> 0 | CI8: =IF($AD8="N","N",SUM('調查資料(OUT)'!AD14:AD17)) -> 0 | CJ8: =IF($AD8="N","N",(CF8/CV8)*100) -> #DIV/0! | CK8: =IF($AD8="N","N",SUM(M8:M11)) -> 0 | CL8: =IF($AD8="N","N",SUM('調查資料(OUT)'!X14:X17)) -> 0 | CM8: =IF($AD8="N","N",SUM('調查資料(OUT)'!AA14:AA17)) -> 0 | CN8: =IF($AD8="N","N",SUM('調查資料(OUT)'!AE14:AE17)) -> 0 | CO8: =IF($AD8="N","N",(CK8/CV8)*100) -> #DIV/0! | CP8: =IF($AD8="N","N",CA8+CG8+CL8) -> 0 | CQ8: =IF($AD8="N","N",(CP8/($CP8+$CR8+$CT8))*100) -> #DIV/0! | CR8: =IF($AD8="N","N",CB8+CH8+CM8) -> 0 | CS8: =IF($AD8="N","N",(CR8/($CP8+$CR8+$CT8))*100) -> #DIV/0! | CT8: =IF($AD8="N","N",CC8+CD8+CI8+CN8) -> 0 | CU8: =IF($AD8="N","N",(CT8/($CP8+$CR8+$CT8))*100) -> #DIV/0! | CV8: =IF($AD8="N","N",BZ8+CF8+CK8) -> 0 | CW8: =IF($AD8="N","N",SUM(O8:O11)) -> 0 | CX8: =IF($AD8="N","N",SUM('調查資料(OUT)'!AF14:AF17)) -> 0 | CY8: =IF($AD8="N","N",SUM('調查資料(OUT)'!AI14:AI17)) -> 0 | CZ8: =IF($AD8="N","N",SUM('調查資料(OUT)'!AM14:AM17)) -> 0 | DA8: =IF($AD8="N","N",SUM('調查資料(OUT)'!AL14:AL17)) -> 0 | DB8: =IF($AD8="N","N",(CW8/DS8)*100) -> #DIV/0! | DC8: =IF($AD8="N","N",SUM(P8:P11)) -> 0 | DD8: =IF($AD8="N","N",SUM('調查資料(OUT)'!AG14:AG17)) -> 0 | DE8: =IF($AD8="N","N",SUM('調查資料(OUT)'!AJ14:AJ17)) -> 0 | DF8: =IF($AD8="N","N",SUM('調查資料(OUT)'!AN14:AN17)) -> 0 | DG8: =IF($AD8="N","N",(DC8/DS8)*100) -> #DIV/0! | DH8: =IF($AD8="N","N",SUM(Q8:Q11)) -> 0 | DI8: =IF($AD8="N","N",SUM('調查資料(OUT)'!AH14:AH17)) -> 0 | DJ8: =IF($AD8="N","N",SUM('調查資料(OUT)'!AK14:AK17)) -> 0 | DK8: =IF($AD8="N","N",SUM('調查資料(OUT)'!AO14:AO17)) -> 0 | DL8: =IF($AD8="N","N",(DH8/DS8)*100) -> #DIV/0! | DM8: =IF($AD8="N","N",CX8+DD8+DI8) -> 0 | DN8: =IF($AD8="N","N",(DM8/($DM8+$DO8+$DQ8))*100) -> #DIV/0! | DO8: =IF($AD8="N","N",CY8+DE8+DJ8) -> 0 | DP8: =IF($AD8="N","N",(DO8/($DM8+$DO8+$DQ8))*100) -> #DIV/0! | DQ8: =IF($AD8="N","N",CZ8+DA8+DF8+DK8) -> 0 | DR8: =IF($AD8="N","N",(DQ8/($DM8+$DO8+$DQ8))*100) -> #DIV/0! | DS8: =IF($AD8="N","N",CW8+DC8+DH8) -> 0
A9: ='調查資料(OUT)'!A15 -> 100 | B9: =SUM(C9:E9) -> 0 | C9: =IFERROR('調查資料(OUT)'!B$1*'調查資料(OUT)'!B15,0)+IFERROR('調查資料(OUT)'!E$1*'調查資料(OUT)'!E15,0)+IFERROR('調查資料(OUT)'!H$1*'調查資料(OUT)'!H15,0)+IFERROR('調查資料(OUT)'!I$1*'調查資料(OUT)'!I15,0) -> 0 | D9: =IFERROR('調查資料(OUT)'!C$1*'調查資料(OUT)'!C15,0)+IFERROR('調查資料(OUT)'!F$1*'調查資料(OUT)'!F15,0)+IFERROR('調查資料(OUT)'!J$1*'調查資料(OUT)'!J15,0) -> 0 | E9: =IFERROR('調查資料(OUT)'!D$1*'調查資料(OUT)'!D15,0)+IFERROR('調查資料(OUT)'!G$1*'調查資料(OUT)'!G15,0)+IFERROR('調查資料(OUT)'!K$1*'調查資料(OUT)'!K15,0) -> 0 | F9: =SUM(G9:I9) -> 0 | G9: =IFERROR('調查資料(OUT)'!L$1*'調查資料(OUT)'!L15,0)+IFERROR('調查資料(OUT)'!O$1*'調查資料(OUT)'!O15,0)+IFERROR('調查資料(OUT)'!R$1*'調查資料(OUT)'!R15,0)+IFERROR('調查資料(OUT)'!S$1*'調查資料(OUT)'!S15,0) -> 0 | H9: =IFERROR('調查資料(OUT)'!M$1*'調查資料(OUT)'!M15,0)+IFERROR('調查資料(OUT)'!P$1*'調查資料(OUT)'!P15,0)+IFERROR('調查資料(OUT)'!T$1*'調查資料(OUT)'!T15,0) -> 0 | I9: =IFERROR('調查資料(OUT)'!N$1*'調查資料(OUT)'!N15,0)+IFERROR('調查資料(OUT)'!Q$1*'調查資料(OUT)'!Q15,0)+IFERROR('調查資料(OUT)'!U$1*'調查資料(OUT)'!U15,0) -> 0 | J9: =SUM(K9:M9) -> 0 | K9: =IFERROR('調查資料(OUT)'!V$1*'調查資料(OUT)'!V15,0)+IFERROR('調查資料(OUT)'!Y$1*'調查資料(OUT)'!Y15,0)+IFERROR('調查資料(OUT)'!AB$1*'調查資料(OUT)'!AB15,0)+IFERROR('調查資料(OUT)'!AC$1*'調查資料(OUT)'!AC15,0) -> 0 | L9: =IFERROR('調查資料(OUT)'!W$1*'調查資料(OUT)'!W15,0)+IFERROR('調查資料(OUT)'!Z$1*'調查資料(OUT)'!Z15,0)+IFERROR('調查資料(OUT)'!AD$1*'調查資料(OUT)'!AD15,0) -> 0 | M9: =IFERROR('調查資料(OUT)'!X$1*'調查資料(OUT)'!X15,0)+IFERROR('調查資料(OUT)'!AA$1*'調查資料(OUT)'!AA15,0)+IFERROR('調查資料(OUT)'!AE$1*'調查資料(OUT)'!AE15,0) -> 0 | N9: =SUM(O9:Q9) -> 0 | O9: =IFERROR('調查資料(OUT)'!AF$1*'調查資料(OUT)'!AF15,0)+IFERROR('調查資料(OUT)'!AI$1*'調查資料(OUT)'!AI15,0)+IFERROR('調查資料(OUT)'!AL$1*'調查資料(OUT)'!AL15,0)+IFERROR('調查資料(OUT)'!AM$1*'調查資料(OUT)'!AM15,0) -> 0 | P9: =IFERROR('調查資料(OUT)'!AG$1*'調查資料(OUT)'!AG15,0)+IFERROR('調查資料(OUT)'!AJ$1*'調查資料(OUT)'!AJ15,0)+IFERROR('調查資料(OUT)'!AN$1*'調查資料(OUT)'!AN15,0) -> 0 | Q9: =IFERROR('調查資料(OUT)'!AH$1*'調查資料(OUT)'!AH15,0)+IFERROR('調查資料(OUT)'!AK$1*'調查資料(OUT)'!AK15,0)+IFERROR('調查資料(OUT)'!AO$1*'調查資料(OUT)'!AO15,0) -> 0 | R9: =B9+F9+J9+N9 -> 0 | T9: ='調查資料(OUT)'!A15 -> 100 | U9: =T9+100 -> 200 | V9: =SUM(R9:R12) -> 0 | X9: =IF($V9=$W$29,MAX(R9:R12),0) -> 0 | Y9: =IF($V9=W$5,SUM(B9:B12)/(4*(MAX(B9:B12))),0) -> #DIV/0! | Z9: =IF($V9=W$5,SUM(F9:F12)/(4*(MAX(F9:F12))),0) -> #DIV/0! | AA9: =IF($V9=W$5,SUM(J9:J12)/(4*(MAX(J9:J12))),0) -> #DIV/0! | AB9: =IF($V9=W$5,SUM(N9:N12)/(4*(MAX(N9:N12))),0) -> #DIV/0! | AD9: =IF(V9=W$5,$T9,"N") -> 100 | AE9: =IF(V9=W$5,$U9,"N") -> 200 | AF9: =IF($AD9="N","N",SUM(C9:C12)) -> 0 | AG9: =IF($AD9="N","N",SUM('調查資料(OUT)'!B15:B18)) -> 0 | AH9: =IF($AD9="N","N",SUM('調查資料(OUT)'!E15:E18)) -> 0 | AI9: =IF($AD9="N","N",SUM('調查資料(OUT)'!I15:I18)) -> 0 | AJ9: =IF($AD9="N","N",SUM('調查資料(OUT)'!H15:H18)) -> 0 | AK9: =IF($AD9="N","N",(AF9/$BB9)*100) -> #DIV/0! | AL9: =IF($AD9="N","N",SUM(D9:D12)) -> 0 | AM9: =IF($AD9="N","N",SUM('調查資料(OUT)'!C15:C18)) -> 0 | AN9: =IF($AD9="N","N",SUM('調查資料(OUT)'!F15:F18)) -> 0 | AO9: =IF($AD9="N","N",SUM('調查資料(OUT)'!J15:J18)) -> 0 | AP9: =IF($AD9="N","N",(AL9/$BB9)*100) -> #DIV/0! | AQ9: =IF($AD9="N","N",SUM(E9:E12)) -> 0 | AR9: =IF($AD9="N","N",SUM('調查資料(OUT)'!D15:D18)) -> 0 | AS9: =IF($AD9="N","N",SUM('調查資料(OUT)'!G15:G18)) -> 0 | AT9: =IF($AD9="N","N",SUM('調查資料(OUT)'!K15:K18)) -> 0 | AU9: =IF($AD9="N","N",(AQ9/$BB9)*100) -> #DIV/0! | AV9: =IF($AD9="N","N",AG9+AM9+AR9) -> 0 | AW9: =IF($AD9="N","N",(AV9/($AV9+$AX9+$AZ9))*100) -> #DIV/0! | AX9: =IF($AD9="N","N",AH9+AN9+AS9) -> 0 | AY9: =IF($AD9="N","N",(AX9/($AV9+$AX9+$AZ9))*100) -> #DIV/0! | AZ9: =IF($AD9="N","N",AI9+AJ9+AO9+AT9) -> 0 | BA9: =IF($AD9="N","N",(AZ9/($AV9+$AX9+$AZ9))*100) -> #DIV/0! | BB9: =IF($AD9="N","N",AF9+AL9+AQ9) -> 0 | BC9: =IF($AD9="N","N",SUM(G9:G12)) -> 0 | BD9: =IF($AD9="N","N",SUM('調查資料(OUT)'!L15:L18)) -> 0 | BE9: =IF($AD9="N","N",SUM('調查資料(OUT)'!O15:O18)) -> 0 | BF9: =IF($AD9="N","N",SUM('調查資料(OUT)'!S15:S18)) -> 0 | BG9: =IF($AD9="N","N",SUM('調查資料(OUT)'!R15:R18)) -> 0 | BH9: =IF($AD9="N","N",(BC9/BY9)*100) -> #DIV/0! | BI9: =IF($AD9="N","N",SUM(H9:H12)) -> 0 | BJ9: =IF($AD9="N","N",SUM('調查資料(OUT)'!M15:M18)) -> 0 | BK9: =IF($AD9="N","N",SUM('調查資料(OUT)'!P15:P18)) -> 0 | BL9: =IF($AD9="N","N",SUM('調查資料(OUT)'!T15:T18)) -> 0 | BM9: =IF($AD9="N","N",(BI9/BY9)*100) -> #DIV/0! | BN9: =IF($AD9="N","N",SUM(I9:I12)) -> 0 | BO9: =IF($AD9="N","N",SUM('調查資料(OUT)'!N15:N18)) -> 0 | BP9: =IF($AD9="N","N",SUM('調查資料(OUT)'!Q15:Q18)) -> 0 | BQ9: =IF($AD9="N","N",SUM('調查資料(OUT)'!U15:U18)) -> 0 | BR9: =IF($AD9="N","N",(BN9/BY9)*100) -> #DIV/0! | BS9: =IF($AD9="N","N",BD9+BJ9+BO9) -> 0 | BT9: =IF($AD9="N","N",(BS9/($BS9+$BU9+$BW9))*100) -> #DIV/0! | BU9: =IF($AD9="N","N",BE9+BK9+BP9) -> 0 | BV9: =IF($AD9="N","N",(BU9/($BS9+$BU9+$BW9))*100) -> #DIV/0! | BW9: =IF($AD9="N","N",BF9+BG9+BL9+BQ9) -> 0 | BX9: =IF($AD9="N","N",(BW9/($BS9+$BU9+$BW9))*100) -> #DIV/0! | BY9: =IF($AD9="N","N",BC9+BI9+BN9) -> 0 | BZ9: =IF($AD9="N","N",SUM(K9:K12)) -> 0 | CA9: =IF($AD9="N","N",SUM('調查資料(OUT)'!V15:V18)) -> 0 | CB9: =IF($AD9="N","N",SUM('調查資料(OUT)'!Y15:Y18)) -> 0 | CC9: =IF($AD9="N","N",SUM('調查資料(OUT)'!AC15:AC18)) -> 0 | CD9: =IF($AD9="N","N",SUM('調查資料(OUT)'!AB15:AB18)) -> 0 | CE9: =IF($AD9="N","N",(BZ9/CV9)*100) -> #DIV/0! | CF9: =IF($AD9="N","N",SUM(L9:L12)) -> 0 | CG9: =IF($AD9="N","N",SUM('調查資料(OUT)'!W15:W18)) -> 0 | CH9: =IF($AD9="N","N",SUM('調查資料(OUT)'!Z15:Z18)) -> 0 | CI9: =IF($AD9="N","N",SUM('調查資料(OUT)'!AD15:AD18)) -> 0 | CJ9: =IF($AD9="N","N",(CF9/CV9)*100) -> #DIV/0! | CK9: =IF($AD9="N","N",SUM(M9:M12)) -> 0 | CL9: =IF($AD9="N","N",SUM('調查資料(OUT)'!X15:X18)) -> 0 | CM9: =IF($AD9="N","N",SUM('調查資料(OUT)'!AA15:AA18)) -> 0 | CN9: =IF($AD9="N","N",SUM('調查資料(OUT)'!AE15:AE18)) -> 0 | CO9: =IF($AD9="N","N",(CK9/CV9)*100) -> #DIV/0! | CP9: =IF($AD9="N","N",CA9+CG9+CL9) -> 0 | CQ9: =IF($AD9="N","N",(CP9/($CP9+$CR9+$CT9))*100) -> #DIV/0! | CR9: =IF($AD9="N","N",CB9+CH9+CM9) -> 0 | CS9: =IF($AD9="N","N",(CR9/($CP9+$CR9+$CT9))*100) -> #DIV/0! | CT9: =IF($AD9="N","N",CC9+CD9+CI9+CN9) -> 0 | CU9: =IF($AD9="N","N",(CT9/($CP9+$CR9+$CT9))*100) -> #DIV/0! | CV9: =IF($AD9="N","N",BZ9+CF9+CK9) -> 0 | CW9: =IF($AD9="N","N",SUM(O9:O12)) -> 0 | CX9: =IF($AD9="N","N",SUM('調查資料(OUT)'!AF15:AF18)) -> 0 | CY9: =IF($AD9="N","N",SUM('調查資料(OUT)'!AI15:AI18)) -> 0 | CZ9: =IF($AD9="N","N",SUM('調查資料(OUT)'!AM15:AM18)) -> 0 | DA9: =IF($AD9="N","N",SUM('調查資料(OUT)'!AL15:AL18)) -> 0 | DB9: =IF($AD9="N","N",(CW9/DS9)*100) -> #DIV/0! | DC9: =IF($AD9="N","N",SUM(P9:P12)) -> 0 | DD9: =IF($AD9="N","N",SUM('調查資料(OUT)'!AG15:AG18)) -> 0 | DE9: =IF($AD9="N","N",SUM('調查資料(OUT)'!AJ15:AJ18)) -> 0 | DF9: =IF($AD9="N","N",SUM('調查資料(OUT)'!AN15:AN18)) -> 0 | DG9: =IF($AD9="N","N",(DC9/DS9)*100) -> #DIV/0! | DH9: =IF($AD9="N","N",SUM(Q9:Q12)) -> 0 | DI9: =IF($AD9="N","N",SUM('調查資料(OUT)'!AH15:AH18)) -> 0 | DJ9: =IF($AD9="N","N",SUM('調查資料(OUT)'!AK15:AK18)) -> 0 | DK9: =IF($AD9="N","N",SUM('調查資料(OUT)'!AO15:AO18)) -> 0 | DL9: =IF($AD9="N","N",(DH9/DS9)*100) -> #DIV/0! | DM9: =IF($AD9="N","N",CX9+DD9+DI9) -> 0 | DN9: =IF($AD9="N","N",(DM9/($DM9+$DO9+$DQ9))*100) -> #DIV/0! | DO9: =IF($AD9="N","N",CY9+DE9+DJ9) -> 0 | DP9: =IF($AD9="N","N",(DO9/($DM9+$DO9+$DQ9))*100) -> #DIV/0! | DQ9: =IF($AD9="N","N",CZ9+DA9+DF9+DK9) -> 0 | DR9: =IF($AD9="N","N",(DQ9/($DM9+$DO9+$DQ9))*100) -> #DIV/0! | DS9: =IF($AD9="N","N",CW9+DC9+DH9) -> 0
